File: powder_X-ray_diffraction/room_temperature_experiments/NaNbO2F2/raw_data/NaNbO2F2_rt.xrdml
<?xml version="1.0" encoding="UTF-8"?>
<xrdMeasurements xmlns="http://www.xrdml.com/XRDMeasurement/1.7" xmlns:xsi="http://www.w3.org/2001/XMLSchema-instance" xsi:schemaLocation="http://www.xrdml.com/XRDMeasurement/1.7 http://www.xrdml.com/XRDMeasurement/1.7/XRDMeasurement.xsd" status="Completed">
	<comment>
		<entry>Configuration=Reflection-transmission Spinner, Owner=User-1, Creation date=12/01/2015 16:50:12</entry>
		<entry>Goniometer=Theta/Theta; Minimum step size 2Theta:0.0001; Minimum step size Omega:0.0001</entry>
		<entry>Sample stage=Reflection-transmission spinner; Minimum step size Phi:0.1</entry>
		<entry>Diffractometer system=EMPYREAN</entry>
		<entry>Measurement program=C:\PANalytical\Data Collector\Programs\Ouail\lent_135.xrdmp, Identifier={73BE8ABF-D663-43FC-B999-33872D7EC5FC}</entry>
		<entry>Batch program=C:\PANalytical\Data Collector\Programs\Batch_nuit1.xrdmp, Identifier={C02E4D90-D25A-499F-A0A1-2D3538350A60}</entry>
	</comment>
	<sample type="To be analyzed">
		<id>NaNbO2F2_th-diff_n3_5-135_tamisé</id>
		<name></name>
		<preparedBy></preparedBy>
	</sample>
	<xrdMeasurement measurementType="Scan" status="Completed" sampleMode="Reflection">
		<comment>
			<entry>PHD Lower Level = 4.02 (keV), PHD Upper Level = 12.07 (keV)</entry>
		</comment>
		<usedWavelength intended="K-Alpha 1">
			<kAlpha1 unit="Angstrom">1.5405980</kAlpha1>
			<kAlpha2 unit="Angstrom">1.5444260</kAlpha2>
			<kBeta unit="Angstrom">1.3922500</kBeta>
			<ratioKAlpha2KAlpha1>0.5000</ratioKAlpha2KAlpha1>
		</usedWavelength>
		<incidentBeamPath>
			<radius unit="mm">240.00</radius>
			<xRayTube id="1010048" name="Empyrean Cu LFF HR (9430 033 7310x) DK434948">
				<tension unit="kV">45.0</tension>
				<current unit="mA">30.0</current>
				<anodeMaterial>Cu</anodeMaterial>
				<focus type="Line">
					<length unit="mm">12.0</length>
					<width unit="mm">0.4</width>
					<takeOffAngle unit="deg">6.0</takeOffAngle>
				</focus>
			</xRayTube>
			<sollerSlit id="21010001" name="Soller slits 0.02 rad.">
				<opening unit="rad">0.0200</opening>
			</sollerSlit>
			<mask id="22030010" name="Fixed mask 20 mm">
				<width unit="mm">20.00</width>
			</mask>
			<antiScatterSlit id="22010003" name="Fixed slit 1°" xsi:type="fixedAntiScatterSlitType">
				<height unit="mm">1.52</height>
			</antiScatterSlit>
			<divergenceSlit id="22010012" name="Programmable divergence slit" xsi:type="fixedDivergenceSlitType">
				<distanceToSample unit="mm">140.00</distanceToSample>
				<angle unit="deg">0.5</angle>
			</divergenceSlit>
		</incidentBeamPath>
		<sampleMovement xsi:type="spinningSampleMovementType">
			<spinnerRevolutionTime unit="seconds">4.0</spinnerRevolutionTime>
		</sampleMovement>
		<diffractedBeamPath>
			<radius unit="mm">240.00</radius>
			<antiScatterSlit id="22090010" name="AS slit 8.0 mm (PIXcel)" xsi:type="fixedAntiScatterSlitType">
				<height unit="mm">8.00</height>
			</antiScatterSlit>
			<sollerSlit id="21010001" name="Soller slits 0.02 rad.">
				<opening unit="rad">0.0200</opening>
			</sollerSlit>
			<filter id="20010004" name="Beta-filter Nickel">
				<material>Ni</material>
				<thickness unit="mm">0.020</thickness>
			</filter>
			<detector id="7010019" name="PIXcel1D-Medipix3 detector" xsi:type="rtmsDetectorType">
				<phd unit="%">
					<lowerLevel>25.0</lowerLevel>
					<upperLevel>75.0</upperLevel>
				</phd>
				<mode>Scanning</mode>
				<activeLength unit="deg">3.3482</activeLength>
			</detector>
		</diffractedBeamPath>
		<scan appendNumber="0" mode="Continuous" scanAxis="Gonio" status="Completed">
			<header>
				<startTimeStamp>2023-01-20T00:48:03+01:00</startTimeStamp>
				<endTimeStamp>2023-01-20T08:18:38+01:00</endTimeStamp>
				<author>
					<name>User</name>
				</author>
				<source>
					<applicationSoftware version="5.5a">Data Collector</applicationSoftware>
					<instrumentControlSoftware version="8.2  20201204">EMPYREAN</instrumentControlSoftware>
					<instrumentID>0000000011159748</instrumentID>
				</source>
			</header>
			<dataPoints>
				<positions axis="2Theta" unit="deg">
					<startPosition>5.01676514</startPosition>
					<endPosition>134.99343336</endPosition>
				</positions>
				<positions axis="Omega" unit="deg">
					<startPosition>2.50838257</startPosition>
					<endPosition>67.49671668</endPosition>
				</positions>
				<positions axis="Phi" unit="deg">
					<commonPosition>255.5</commonPosition>
				</positions>
				<commonCountingTime unit="seconds">676.770</commonCountingTime>
				<intensities 25758 25788 25924 25865 25697 25539 25395 25369 25643 25603 25484 25375 25935 25160 25555 25534 25787 25375 25650 25382 25561 25098 25248 25583 25312 25313 25697 25798 25149 25300 25220 25089 25614 25315 25434 25402 25334 25232 25392 25321 25484 25465 25532 25538 25390 25701 25512 25562 25710 25366 25356 25762 25561 25178 25625 25553 25290 25406 25564 25531 25454 25764 25720 25629 25767 25377 25576 25697 25591 25776 25571 25671 25369 25745 25402 25663 25822 25857 25996 25929 25816 25982 25807 25783 25739 26086 25579 25929 25758 25546 25460 25680 25334 25748 25743 25631 25807 25620 25624 25773 26057 26099 25695 25613 26066 25563 26049 25742 25811 25362 25332 25915 25556 25633 25786 25743 25737 25958 25924 25465 25790 25846 25545 25652 25848 25878 25940 25706 25767 25904 25800 25881 26110 26215 26274 26148 26261 26485 26181 26347 25890 26043 26182 26187 25847 26019 26039 25993 26029 26002 26110 26063 25967 25828 25928 26078 25665 25820 25706 25837 26100 25614 25870 25620 25625 25564 25523 25048 25687 25478 25343 25869 25494 25333 25222 25455 25480 25248 25087 25338 25420 25236 25092 25194 25028 25040 25014 24729 24856 24790 25034 24740 24862 25370 24868 25200 24997 25138 25145 25058 25069 25162 24983 25095 24784 24720 24872 24834 24956 24754 24384 24798 24551 24315 24206 24579 24520 24417 24190 24322 24133 23917 23981 24329 24529 24444 25018 25126 25254 25242 25618 25679 26769 28462 31482 36540 45882 61662 87285 121963 164699 170873 111792 55176 32908 27262 26397 25406 25112 24200 24242 23647 23227 23058 23202 23237 23183 23355 23307 23332 23851 23280 23206 23554 23057 23293 23460 23188 23209 23098 23254 22852 23082 23361 23062 23058 23223 23271 23267 23234 23044 22943 23154 23197 23075 22930 23065 22834 23016 22461 22655 22675 22311 22540 22537 22661 22320 22252 22678 22043 21979 22334 22328 22209 22161 22012 22091 22214 22143 22266 21721 22088 21742 22050 21857 21550 21708 21781 21698 21538 21422 21712 21476 21505 21266 21439 21629 21427 21229 21422 21641 21573 21965 22319 21772 21844 21200 21170 21217 20949 20647 20812 21072 21125 20971 20604 21037 21093 21092 20667 20741 20821 20933 20583 20757 20607 20835 20969 21002 20936 21678 22649 24823 27475 29583 28929 25615 23111 21369 20863 20496 20480 19983 20277 19900 20091 20002 19897 19654 19881 19733 20004 19869 19832 19710 19612 19668 19658 19426 19576 19473 19319 19279 19413 19483 19196 19321 19274 19357 19338 19145 19136 18989 18968 18964 19195 19160 18764 18687 18880 18933 18847 19182 18778 18532 18970 18821 18670 18664 18707 18635 18992 18739 18741 18685 18272 18562 18604 18125 18443 18283 18285 18333 18363 18242 18211 18668 18462 18314 18367 18199 18404 18041 18196 18428 18217 18393 18469 19000 19340 20414 20937 20391 19345 18463 18118 18098 17842 17744 17754 17696 17483 17540 17781 17520 17577 17431 17634 17590 17292 17602 17348 17444 17387 17224 17508 17514 17627 17267 17423 17197 17021 17122 17207 17447 16938 17334 17164 16756 17031 17238 16992 17310 17184 17336 17632 17703 17732 17248 16993 16954 17014 17019 16846 16850 17051 16764 16561 16853 16734 16907 16752 16861 16752 16569 16571 16895 16706 16457 16764 16308 16607 16544 16604 16417 16336 16466 16294 16138 16342 16294 16596 16419 16242 16369 16534 16171 16382 16118 16199 16512 16466 16513 16538 16806 17124 17315 17214 17125 17051 17182 17474 17551 17548 17571 17810 18026 18405 19022 19498 20250 21366 22878 26066 30350 38320 55447 92489 161377 254462 295331 237109 160660 86143 44248 30306 25074 22786 20936 19773 19031 18794 18706 18395 17950 17407 17041 16848 16770 16583 16305 16466 16384 16086 16215 16298 16044 16188 15964 15994 16292 16179 16209 15872 15900 16017 15958 15632 15680 15831 15931 15744 15906 15788 15851 15700 15554 15861 15586 15597 15558 15375 15462 15915 15490 15569 15585 15538 15641 15747 15598 15571 15491 15313 15570 15622 15275 15532 15495 15546 15407 15556 15904 15360 15526 15567 15480 15961 16085 16015 15890 15618 15471 15325 15466 15253 15281 15278 15226 15267 15157 15221 15389 15513 15685 16079 15835 16048 17366 17823 18706 20809 26094 37339 54896 62727 51838 41546 29352 20438 17353 16339 15817 15387 15242 14982 15122 15025 15197 15067 15324 15054 15112 14992 14966 15069 15072 14619 14898 15200 15142 15256 15314 15259 15580 15249 15518 15577 16094 16218 16346 16803 17390 18693 21298 29041 47195 82081 113753 96838 76217 55789 32982 23010 20394 19837 20335 21862 26643 39068 69986 119867 148908 118034 93012 63587 33858 22783 19777 18791 18174 17624 17603 17029 16674 16090 15206 15144 14682 15014 14762 14914 14544 14805 14345 14597 14421 14481 14268 14420 14336 14570 14360 14223 14346 14422 14140 14305 14052 14249 14245 14204 14449 14288 14646 14598 15031 14556 14413 14455 14274 14014 14046 13954 14057 14224 14024 14006 13677 13795 14154 13812 14274 14298 14209 14078 14351 14091 13823 14385 14303 14255 14386 14259 14180 13980 13822 13837 14219 13955 14194 13857 13545 13493 13765 13692 13553 13646 13690 13545 13709 13562 13239 13364 13498 13608 13536 13506 13346 13345 13381 13430 13350 13586 13341 13416 13573 13305 13497 13483 13274 13533 13712 13668 13760 14021 13851 14174 13914 14060 13909 14087 14216 14068 14003 14238 14189 14257 14042 14267 14029 14199 14534 14354 14656 14743 14943 15561 16364 17442 19465 22243 22266 22105 24124 26845 31803 44524 71555 123997 199485 252705 230872 185109 146383 97058 54730 33829 25588 21922 19574 17937 17172 16600 16503 17737 19319 19920 18550 17650 17808 16693 16378 15766 15693 15628 15577 15701 15831 16203 16849 18019 20184 24646 37226 68956 121209 150829 120896 95685 83264 52065 29553 22682 22364 25030 30691 36541 42025 42868 42825 44904 41937 32580 27102 23617 19184 16280 14784 14316 13750 13716 13262 13391 13378 13772 13953 13795 13653 13317 13306 13133 12828 12783 12671 12898 12609 12842 12688 12736 12713 12667 12538 12703 12521 12579 12683 12519 12291 12407 12406 12677 12674 12721 12524 12459 12445 12461 12648 12533 12513 12371 12352 12350 12228 12410 12062 12360 12466 12516 12279 12086 12324 12080 12341 12243 12014 12015 12226 12031 12096 12000 12345 11950 11993 12008 11900 11727 11803 11983 12123 12232 12051 11770 12082 12046 11936 12118 11920 11833 11821 11891 11676 11834 12025 11792 12044 11899 11962 11967 11904 11815 11886 11740 12109 11816 11798 12017 12018 12234 11930 12008 12085 12011 12085 12281 12729 12169 12213 12082 11812 11942 11858 11957 11994 11907 12132 12204 11909 12257 12606 13028 13347 13904 15243 16011 18068 24791 40384 64708 82333 77320 64078 54995 46192 32220 21185 16004 14646 14004 13736 13080 12423 12461 12295 12159 12097 11896 12079 11902 12186 12271 12411 12543 13072 13733 14889 17598 23361 33693 42380 41630 34895 31827 30531 25146 19756 16587 15381 14245 13822 12853 12667 12397 12843 14074 16956 21180 22425 19936 17996 17147 15775 13595 12306 11707 11587 11607 11194 11381 11531 11615 11372 11472 11212 11402 11331 11391 11610 11744 11833 12033 12739 14140 17432 23305 28517 27752 23790 21604 20907 17554 15311 14916 15254 14034 13213 12998 12529 11802 11306 10878 11037 10783 10748 10853 10537 10548 10597 10609 10661 10944 10546 10702 10851 10717 10684 10439 10458 10412 10562 10663 10766 10510 10516 10543 10531 10549 10553 10656 10616 10538 10807 10892 11048 11117 11338 11718 13120 16291 20876 21525 17742 16195 16482 15312 12927 11533 10891 10952 10780 10777 10752 10622 10394 10446 10632 10267 10342 10387 10342 10218 10473 10441 10418 10434 10277 10326 10453 10355 10436 10414 10268 10217 10385 10191 10302 10339 10579 10489 10567 10664 10690 10845 11113 11795 12859 13849 13759 13767 15113 17851 22330 28279 32624 33180 30129 26222 23576 20699 17080 13782 12427 11434 10998 10797 10697 10630 10551 10396 10337 10490 10221 10099 10159 10096 10021 10093 9913 9869 9858 9959 9915 9844 10060 10065 9723 9748 10023 9753 10004 9702 9875 10047 9811 10175 9819 10088 9910 10077 10002 10138 10225 10467 10762 11220 13238 17551 23198 23920 19246 16677 17207 16825 13823 11508 10574 10172 10054 10171 9952 9709 9708 9830 9518 9846 9894 9994 9899 9892 9810 9801 9867 9761 9829 9826 9904 9847 9936 10070 10126 10736 11650 12459 12161 11482 11360 11807 11764 11702 12340 14004 16373 17769 17142 15413 14441 14539 13385 12081 10935 10356 10063 9862 9691 9853 9718 9725 9739 9920 9885 9885 10011 10000 10111 10285 10833 11806 13926 16169 16219 14465 14695 16879 19932 23528 28889 32678 32069 27286 23815 22441 20336 16784 13256 11260 10735 10252 9836 10047 9822 9636 9650 9548 9665 9659 9557 9669 9691 9773 9714 9857 9869 9612 9639 9574 9537 9697 9663 9584 9593 9677 9462 9517 9578 9556 9593 9250 9169 9308 9294 9207 9089 9219 9292 9164 9406 9192 9432 9269 9332 9324 9090 9450 9126 9283 9268 9069 9297 9178 9060 9229 9307 9397 9179 9289 9175 9442 9182 9372 9139 9268 9381 9098 9321 9470 9296 9365 9467 9485 9462 9473 10024 10893 11704 12405 13397 13804 13743 12714 11989 11968 11283 10572 10067 9669 9486 9295 9303 9066 9212 9139 9329 9466 9653 10030 10386 10039 9669 9629 9755 9621 9626 9279 9410 9361 9441 10002 10486 10521 10542 10861 11123 11334 11874 12750 14227 18319 24498 31809 33736 29034 23064 22083 22708 20701 16232 12653 11124 10276 9896 9526 9387 9366 9201 9274 9148 9055 8853 9033 9173 9096 8991 8979 8974 8913 9026 8883 9164 8953 9074 8776 9046 9070 9019 9040 9099 8949 9096 9135 9195 9085 9318 9592 9623 9390 9682 10130 10266 10226 10702 11635 14418 19360 26793 31987 30942 24590 21149 21302 21684 18742 14887 12078 10574 10088 9633 9603 9357 9377 9415 9250 9127 9213 9065 9105 9127 8976 9016 9003 9033 9078 9199 9120 9053 8901 9048 8995 8766 8971 9093 8993 9332 9007 9379 9371 9457 9870 9873 9919 10113 10525 11290 12545 16319 25417 37171 39263 31069 27014 28606 30498 26826 20433 16665 14940 13461 11918 11450 11324 10899 10592 10370 10569 10849 10782 10941 11266 11617 12519 14002 17145 21860 30166 36978 38927 36110 30568 27794 27382 26101 22501 17967 14563 12783 12416 12407 14059 15620 15873 14952 14496 15025 15474 14891 13474 12508 11830 11320 10775 10415 9947 9893 10178 10139 10297 10472 10881 11496 12362 13428 15719 19793 26340 31800 32277 31326 31712 33084 29708 24787 21313 19351 18001 15144 12705 11413 11119 10678 11114 11278 11515 12043 13014 15015 19427 27954 40572 50280 47826 36216 29290 29921 32114 29726 23090 16692 13439 12009 11184 10469 10243 9975 9771 9845 9527 9488 9550 9735 9780 10343 11551 13871 16741 17244 15911 14962 14749 15444 15268 14415 13903 14695 16467 18060 18155 16794 15168 14297 14355 14250 13337 12115 11157 10216 9768 9572 9412 9384 9252 9288 9369 9366 9468 9407 9814 9879 9907 10456 11444 13685 19559 29751 38903 34212 23221 19137 21214 26281 26683 22589 19330 17021 14824 13847 14450 16031 16375 14384 12057 10916 11163 11224 10877 10017 9336 9359 9152 8907 9179 8885 8851 8881 9083 9790 11165 13503 15166 13743 11435 10749 11185 11901 11825 10462 9477 8967 8898 8812 8913 8915 8981 8750 8630 8690 8724 8740 8540 8563 8565 8592 8409 8507 8518 8746 8561 8920 9211 9179 8967 8730 8714 8711 8611 8845 8442 8341 8475 8274 8389 8175 8390 8394 8289 8161 8262 8307 8270 8230 8593 8508 8850 8901 8725 8618 8495 8492 8744 8667 8465 8378 8118 8300 8222 8144 8238 8232 8260 8055 8077 8168 8264 8196 8171 8223 8045 8113 8133 7910 8279 8165 8001 8220 8346 8310 8241 8423 8475 8492 8440 8512 8554 8409 8517 8321 8507 8552 8407 8642 8693 8697 8768 8917 9636 11146 13282 16151 16029 13261 11290 11124 12136 13113 12325 10758 9853 9514 9579 9598 9590 10024 10542 11275 12929 15314 18560 23108 27479 27913 25176 21519 18947 18535 19318 18656 16492 13949 12333 12030 12195 11666 11206 10945 10765 10805 12171 13703 16912 19556 18888 15432 12722 12657 14162 15666 15482 14473 13476 15039 18517 22959 23895 20049 15793 13821 14741 16133 16062 14166 12113 11182 11164 11280 11233 10941 10352 9993 10049 9916 9922 9652 9330 8965 8764 8725 8495 8551 8490 8660 8725 8733 8714 8947 9221 9496 10248 10941 11793 12587 13396 14656 16483 19233 22607 24916 23783 20652 17534 16464 16557 16534 15825 13556 11795 10141 9269 9307 8846 8753 8526 8498 8250 8312 8357 8364 8339 8435 8835 8821 9043 9407 9339 9804 10317 10800 11062 12156 13105 14628 15742 16853 18225 18021 16543 15328 16013 18077 22010 25151 24684 22413 20516 19299 18318 18316 17942 16833 16920 17276 18812 21008 22588 20684 17442 14543 13808 14188 15364 14564 12979 11459 10298 9748 9579 9493 9690 10021 10561 11663 13911 17848 21862 23328 21051 17135 15065 14770 15818 16207 14992 12961 11204 9725 8977 8917 8553 8262 8472 8356 8382 8414 8596 8423 8917 9182 9636 10243 11616 14241 16882 17643 15712 13123 11822 12114 13385 14210 13849 11949 10238 9253 9190 9083 9226 9062 8857 8613 8584 8682 9005 9174 9508 10485 11659 13819 16011 18278 19112 21036 22543 23716 23128 20779 17854 16133 15661 15738 15029 13590 11468 10010 9129 8507 8143 7999 8048 7855 7889 7680 7752 7648 7636 7661 7411 7645 7543 7421 7571 7438 7620 7358 7403 7570 7361 7327 7286 7562 7128 7410 7404 7445 7416 7442 7592 7595 7732 7799 7783 7649 7661 7872 7619 7756 7405 7531 7366 7500 7407 7524 7367 7552 7736 8037 8055 7786 7787 7713 8085 7996 8310 8702 9452 10908 13090 16342 18435 18400 17023 14653 12927 12745 13173 13566 13100 12079 10864 9807 9095 8768 8409 8197 7848 7787 7867 7804 7574 7735 7564 7572 7395 7314 7521 7473 7320 7357 7472 7606 7434 7363 7627 7489 7619 7620 8040 8260 8839 9796 10692 11234 11252 10619 10126 9219 9394 9752 9892 9620 8937 8528 7837 7735 7720 7285 7373 7419 7149 7313 7151 7343 7073 7391 7598 7665 7567 7545 7723 7524 7531 7376 7479 7710 7488 7705 7443 7173 7347 7430 7460 7522 7464 7181 7121 7293 7040 7204 7212 7225 6902 6990 6981 7020 6925 7031 7060 6946 7101 7107 7134 6935 7086 7002 7068 7271 7454 7434 7331 7548 7639 7942 7903 7942 7522 7653 7312 7310 7371 7421 7379 7115 7086 6863 6818 6854 6988 6984 6991 6979 6929 6881 6874 6998 6904 6779 6766 6832 7057 7261 7329 7500 7463 7077 7063 7118 6967 7059 7162 7144 7059 6965 6956 6895 6864 6957 6973 6990 7011 7044 7093 7026 7200 7078 7137 6915 7094 7133 7195 7110 7105 7000 7063 7107 7184 7320 7297 6951 7205 7161 7201 7035 7015 7196 7289 7353 7228 7001 6889 6856 6895 7010 6990 7040 6941 6882 6951 6982 6851 7176 6985 7076 7351 7290 7221 7284 7378 7510 7668 8025 8338 8978 9601 10999 13649 15953 17093 16428 15182 14345 13263 12538 12502 13058 12924 12791 12680 12461 11794 10573 9692 9382 9777 11055 13290 15452 16316 15235 13433 11838 10670 10287 10699 11314 11282 10505 9568 8885 8061 7630 7350 7259 6959 7119 6983 6862 6915 7048 6907 7017 6945 7097 7321 7320 7335 7431 7438 7586 7620 7777 7587 7616 7621 7627 7635 8200 8396 8835 8964 8854 8753 8313 8142 7845 7975 8237 8297 8280 8261 8021 7789 7861 7854 8001 8167 7969 7947 7679 7637 7514 7542 7566 7599 7390 7245 7244 7020 7051 7185 7325 7275 7183 7140 7204 7260 7669 8000 8695 9316 9213 8831 8913 8964 9059 9381 10208 10983 11592 12064 11821 11226 10965 9866 9407 9314 9269 9124 8965 8714 8367 8031 7431 7317 7282 7249 7000 7207 7301 7762 8524 9085 8943 8439 7657 7298 7605 7474 7745 8089 7897 7596 7399 7034 7153 6713 6898 6825 6861 7231 7167 7582 7816 7593 7541 7301 7048 7250 7439 7266 7672 7891 7935 8272 8896 9293 9638 9940 9815 9537 8720 8539 8445 8440 8557 8566 8748 8692 8244 8029 7627 7462 7497 7275 7573 7580 7695 7778 8047 7704 7691 7790 7934 8463 9438 10208 10376 10354 10188 10621 11633 12934 13127 12410 10761 9816 9121 8898 8942 9683 9602 9195 8437 7808 7593 7371 7655 7601 7334 7099 6887 6666 6897 6760 6834 6962 7001 6799 6551 6591 6558 6567 6602 6579 6475 6451 6520 6423 6454 6608 6440 6587 6628 6640 6588 7004 7128 7122 6962 7241 7339 7549 7665 7146 7124 6723 7014 6671 6883 6959 6958 7183 7147 6880 6965 7146 7173 7287 7595 8040 8147 7738 7525 7341 7214 7296 7286 7626 7578 7573 7403 7030 6905 6954 7228 7315 7319 7830 8298 9656 11322 13146 12519 11225 10869 10987 11498 12235 12942 13241 12624 11330 10205 9433 9497 9988 11028 11981 12731 12705 11090 9328 8285 7833 7714 7917 8602 9018 9318 8924 8506 8788 8806 8054 7618 7230 6939 6995 7044 7174 7263 7405 7049 6705 6633 6671 6441 6325 6510 6524 6281 6211 6389 6492 6393 6411 6435 6503 6254 6422 6413 6466 6363 6373 6497 6375 6642 6649 6553 6922 6912 7082 6995 6796 7029 6903 7082 7104 7166 7441 7252 7068 7291 7460 7394 7475 7376 7396 7526 7427 7508 7776 8100 8622 9300 9713 9904 9967 9600 9050 8403 8425 8441 8830 9218 9427 9546 9541 9657 9656 9865 9909 10085 10378 10015 9630 9018 8763 8487 8442 8275 8459 8360 8140 8017 7620 7425 7218 7310 7351 7255 7517 7630 7736 8135 7938 7749 7405 7233 7094 6970 7056 7223 7422 7394 7444 6969 7136 7113 7367 7651 8111 8783 9325 9167 8913 8469 8368 7928 8362 8725 9181 9396 10051 10112 10002 9735 8989 8417 8005 7964 7896 8065 8250 8282 8305 8047 7908 8063 8283 8506 8832 9013 9107 8884 8497 8174 7738 7630 7785 7684 7898 7763 7552 7365 7162 6991 6624 6624 6651 6570 6681 6821 7036 6779 6943 6841 6757 6684 6469 6568 6756 6722 6788 6721 6818 7025 7123 7197 7931 8361 8347 8195 8204 8078 8086 7806 7490 7620 7807 8161 8414 8832 9370 9579 9589 8805 8390 7774 7408 7337 7168 7406 7535 7636 7852 7312 7041 6673 6636 6490 6655 6376 6480 6355 6397 6543 6273 6329 6255 6174 6152 6123 6214 6151 6391 6309 6229 6097 6179 6106 6003 6190 6153 6039 6134 5959 6152 6154 5926 6179 6126 6252 6255 6218 6469 6470 6917 6935 6902 6491 6262 6371 6332 6185 6360 6486 6425 6739 6528 6427 6425 6677 6441 6622 6937 7285 7672 8214 8296 8372 7714 7485 6989 6873 6659 6875 6997 7203 7330 7383 7137 6783 6664 6700 6548 6498 6199 6235 6381 6329 6200 6307 6414 6489 6691 6594 6936 7460 7157 6897 6627 6505 6269 6350 6282 6298 6389 6689 6547 6580 6413 6231 6064 6076 6201 6135 6152 6141 6145 6234 6122 6277 6008 6140 6272 6137 6464 6158 6351 6628 6635 7148 7376 7743 8654 9000 8930 8866 8382 7727 7577 7547 7427 7538 7991 8429 9040 9460 9818 9456 8999 8013 7480 7228 7138 7259 7722 8212 8762 9197 9256 9026 8593 8356 7908 7654 7431 7013 7074 7340 7335 7384 7382 7234 6943 6786 6881 6729 6690 6755 6860 6890 6951 7105 7014 6951 6707 6520 6570 6513 6599 6641 6821 6782 7114 7096 7395 7852 8346 8786 8799 8477 8178 7803 7627 7712 7695 8153 8417 8817 9120 8875 8374 7816 7572 7251 7208 7461 7704 8033 8493 8530 8019 7777 7440 7346 7450 7505 7377 7567 7932 8167 8046 8284 8483 8940 8519 8102 7435 7208 7106 7199 7213 7362 7686 8068 8728 9155 9920 10820 10865 10846 9838 9442 8773 7964 7598 7570 7653 7920 8387 8441 8322 7835 7534 7019 6893 6418 6206 6118 6048 6132 6074 6042 5852 6075 6067 5940 5930 5802 6008 5956 5864 5852 5888 5944 5804 5959 6061 6223 6133 6217 6259 6060 6159 6021 5966 6095 6133 6165 6051 5988 6159 6112 6073 6146 6190 6176 6285 6210 6245 6055 6050 6135 6073 6124 6281 6324 6549 6325 6567 6806 6901 6857 7073 7091 7017 6883 6759 6772 6517 6866 6745 7248 7113 7569 7559 7878 7967 8320 8087 7832 7756 7735 8043 8492 8678 9021 9257 9544 9692 9382 9128 8637 8309 8239 8049 7835 7901 7779 7698 7561 7660 7263 7185 7107 6776 6603 6374 6413 6414 6216 6063 6128 6107 6121 6072 5940 5943 6139 6187 6246 6253 6383 6364 6415 6280 6554 6381 6534 6414 6282 6282 6065 6132 6071 6158 6061 6173 6163 6117 6111 5997 6009 5933 5869 6080 5865 5895 5798 5965 5946 5989 5976 6245 6205 6216 6354 6495 6707 7027 7153 7233 7176 7163 6939 6778 6605 6522 6600 6364 6472 6603 6437 6617 6500 6408 6292 6377 6022 6041 6138 6015 5992 6114 6195 6062 6290 6357 6705 6648 7069 7219 7407 7187 7200 7193 7094 7405 7615 7740 7585 7845 7749 7680 7737 7796 7813 7958 8429 8598 8591 9027 9122 8858 8176 7625 7191 7012 7013 6977 7014 6949 7176 7138 7377 7265 7324 7124 6991 7234 7264 7119 6863 6850 6775 6838 6391 6393 6177 6288 6441 6474 6471 6224 6145 6228 5955 6110 6027 5908 5793 5962 5742 5709 5579 5674 5656 5656 5564 5499 5545 5926 5749 5709 5855 5619 5830 5761 5661 5856 5989 5900 6025 6061 6148 6232 6345 6384 6620 6713 7118 7446 7371 7718 7599 7765 7727 7845 7712 7601 7195 6858 6858 6799 6786 6840 6662 6867 6874 6813 6738 6827 6848 6630 6642 6648 6444 6242 6148 6040 6010 5950 5883 5859 6073 6257 6069 6381 6151 6479 6461 6346 6281 6381 6296 6352 6307 6607 6745 7163 6925 7221 6893 6850 6530 6337 6331 6367 6349 6424 6534 6669 6685 6927 7128 7064 7058 6908 6601 6476 6300 6312 5958 6305 6010 6081 6172 6076 6203 6288 6219 6098 5940 5915 5946 5898 5975 5873 5861 5909 5666 5844 5596 5805 5840 5827 5798 5808 5814 5672 5578 5646 5562 5447 5818 5590 5491 5753 5491 5630 5650 5553 5647 5537 5723 5605 5768 5692 5807 5778 5621 6074 5919 6110 6183 6158 6413 6404 6564 6693 6610 6635 6507 6240 6169 6216 5989 6111 6133 6083 6135 6181 6492 6291 6281 6290 6265 6205 6110 6229 6127 6127 6102 6227 6243 6187 6158 5985 5980 6057 6043 6072 6135 6142 6242 6170 6086 6063 5893 6002 5787 5843 5845 5801 5869 5700 5906 5914 5736 5945 5910 5951 5802 5895 6060 5953 5948 6020 5945 6076 5905 5881 6034 5740 5728 5705 5811 5944 6073 6082 6061 6192 6088 6350 6227 6080 5971 5822 5849 5862 5678 5928 5843 5576 5821 5908 5931 5977 5884 6024 5976 5949 5789 5861 5580 5613 5688 5722 5723 5700 5723 5740 5732 5827 5708 5850 5704 6047 6119 6022 6244 6332 6290 6282 5992 6135 6117 6086 5962 6077 5957 5924 5922 6021 6072 6225 6442 6175 6244 6230 6108 6182 6127 6409 6270 6326 6237 6118 6155 6101 6274 6300 6429 6429 6410 6250 6077 6019 6015 5810 5775 5884 5645 5952 5968 5917 5946 5917 5836 5732 5846 5618 5736 5605 5808 5656 5797 5729 5761 5484 5687 5668 5584 5707 5702 5500 5617 5587 5656 5574 5787 5679 5699 5653 5867 5872 5818 6036 5925 6191 6252 6516 6723 7204 7613 8542 8780 8929 9020 8835 8653 8169 7598 7302 6896 6731 6697 6640 6952 7022 7323 7514 7382 7262 7112 6830 6756 6476 6273 6075 6069 5940 5948 5942 5834 5908 5922 5622 5759 5550 5588 5583 5610 5771 5793 5599 5579 5641 5786 5747 5819 5789 5795 5909 5770 5933 6177 6119 6491 6580 6581 6445 6278 6632 6682 6644 6687 6672 6887 6780 7051 6924 6899 7142 7114 7062 7268 7614 7718 7910 8023 8013 7755 7753 7537 7472 7358 7136 7092 7110 7125 7175 7397 7415 7565 7458 7105 6932 6790 6855 6677 6585 6548 6437 6540 6464 6723 6979 7067 7252 7202 7145 7153 7104 6925 6881 6550 6161 6197 6155 6269 6037 6121 6478 6274 6240 6162 6415 6477 6196 6185 6053 6074 5947 5909 5987 6125 5994 6070 6166 6286 6429 6288 5954 5988 5959 5929 5856 6084 6111 6102 6267 6219 6294 6180 6300 6491 6475 6668 6562 6686 6527 6712 6917 6925 7357 7402 7305 7279 6908 6785 6907 6810 6760 6921 6937 6949 6929 7206 7222 7585 7609 7912 8066 7974 7960 7887 7682 7476 7022 6846 6734 6775 6651 6570 6424 6747 6702 6937 7099 7113 7402 7687 7671 7669 7769 7323 7101 6949 6603 6404 6228 6360 6354 6299 6378 6422 6443 6682 6623 6684 6478 6485 6233 6421 6236 6022 5988 5969 5938 5855 6007 6076 6244 6408 6184 6252 6147 6287 6190 6153 5897 5981 5965 5925 5969 5941 5823 5828 5860 5840 6052 6159 5993 6025 5790 5843 5958 5745 5886 5775 5763 5693 5824 5909 5968 5902 5855 6023 6061 5985 6184 6159 6364 6228 6286 6315 6072 5975 5988 5954 5897 6064 6093 5949 6124 5949 6127 6390 6504 6343 6460 6469 6307 6434 6572 6699 6746 6792 6666 6852 6829 6922 6620 6593 6418 6366 6363 6448 6340 6383 6309 6338 6482 6452 6327 6400 6348 6452 6456 6322 6209 6193 6442 6530 6674 6799 6910 7117 7033 7076 6894 6810 6847 6808 6644 6655 6666 6675 6430 6474 6713 6669 6631 6452 6568 6527 6272 6282 6330 6360 6196 6091 6432 6354 6378 6324 6409 6253 6251 6269 6299 6143 6264 6168 6188 6129 6370 6251 6392 6390 6546 6352 6462 6287 6413 6433 6432 6300 6641 6457 6534 6754 6812 7038 7406 7194 7263 7068 6669 6639 6508 6397 6305 6156 6301 6197 6312 6442 6552 6556 6637 6665 6582 6439 6412 6391 6217 6269 6089 6129 6185 6081 6084 6083 6316 6130 6037 6199 6233 6238 6346 6299 6527 6591 6831 6986 7143 7423 7119 6972 6825 6691 6764 6778 6480 6435 6364 6429 6487 6346 6457 6444 6327 6420 6494 6518 6422 6543 6308 6349 6287 6253 6200 6273 6235 6399 6364 6465 6366 6352 6269 6333 6458 6684 6905 6702 6894 6919 7105 7088 7206 7419 7534 7414 7560 7711 7826 7965 8157 8208 8045 7869 7790 7614 7396 7706 7569 7486 7647 7591 7678 7588 7694 7754 7664 7777 7954 8341 8203 8163 7780 7670 7368 7403 7158 7297 7485 7589 7694 7976 8333 8260 7959 7770 7798 7578 7605 7666 7293 7396 7390 7587 7459 7688 7923 8254 8536 8695 9139 9312 9582 9646 9357 9092 8735 8304 7855 7865 7571 7471 7269 7418 7214 7210 7218 7177 7469 7363 7385 7562 7557 7373 7306 7037 6908 6751 6660 6551 6580 6408 6477 6257 6388 6167 6266 6266 6427 6492 6499 6442 6669 6647 6697 6793 6766 6866 6640 6775 6601 6387 6405 6362 6484 6270 6355 6392 6431 6226 6337 6497 6556 6722 6554 6723 6871 6995 7049 7005 7337 7281 7414 7362 7085 6854 6810 6891 6820 6912 7041 7270 7336 7330 7463 7491 7606 7465 7473 7479 7441 7228 7098 7289 6923 6835 6985 6946 6845 6909 6842 6907 7117 7259 7318 7193 7456 7332 7708 7413 7701 7750 7699 7854 7937 7894 8124 7806 7634 7552 7662 7588 7666 7386 7359 7311 7370 7568 7711 7576 7546 7516 7695 7476 7813 7658 7740 7905 7977 8181 8418 8276 8511 8211 8241 7743 7774 7609 7342 7309 7328 6978 6835 6885 6983 6855 6938 7046 6951 7159 7138 7511 7391 7349 7262 7318 7610 7364 7361 7535 7558 7613 7663 7753 7612 7769 7767 7603 7634 7395 7630 7447 7365 7242 7026 6938 6918 6830 6824 6708 6644 6846 6861 6869 6872 6939 7030 7034 6984 7079 7015 6981 6841 6732 6602 6645 6472 6183 6217 6201 6277 6275 6005 6022 6130 5957 6116 6135 5991 5986 6023 6075 6050 5964 6077 6016 5978 5950 5998 5897 5991 5931 5981 6036 6054 6182 6161 6183 6181 6125 6121 6223 6168 6163 6068 6151 6090 6158 6119 6065 6117 6253 6451 6301 6218 6310 6414 6342 6453 6630 6391 6565 6534 6573 6439 6727 6670 6710 6735 6869 6852 7008 7230 7386 7495 7672 7754 7932 7805 7902 7840 7626 7693 7401 7392 7341 7259 7211 6958 7087 6979 6935 6839 6884 6921 7200 6880 6845 6940 7098 7131 7190 7166 7036 7136 7042 6947 7066 7061 6955 6925 6967 6897 7026 6958 6833 6704 6739 6781 6843 6764 6754 6762 6660 6629 6754 6896 6481 6614 6471 6554 6368 6438 6430 6492 6437 6532 6498 6594 6660 6510 6653 6556 6561 6601 6725 6722 6736 6688 6884 6805 6765 6707 6647 6664 6549 6655 6419 6625 6394 6480 6590 6458 6535 6524 6322 6599 6515 6576 6633 6505 6688 6522 6504 6485 6667 6618 6705 6729 6749 6869 6887 7203 6944 7357 7441 7153 7451 7318 7501 7459 7336 7202 7420 7353 7381 7330 7375 7255 7516 7374 7371 7434 7290 7277 7124 7194 7141 7225 7015 7064 6998 6878 6798 6871 6792 7031 6955 6928 7197 7015 7259 7224 7237 7181 7222 7227 7348 7332 7242 7270 7268 6980 7036 6948 6759 6763 6521 6503 6488 6707 6439 6292 6481 6502 6571 6367 6345 6602 6561 6756 6664 6814 6645 6550 6618 6518 6722 6702 6600 6566 6565 6527 6355 6423 6527 6513 6640 6679 6704 6685 6994 6823 7077 6821 6818 6804 6478 6675 6570 6571 6527 6463 6597 6571 6485 6458 6462 6496 6624 6428 6469 6703 6686 6862 6944 7051 7038 6986 6883 6883 6810 6702 6808 6649 6730 6618 6715 6494 6483 6538 6825 6623 6637 6477 6581 6715 6795 6748 6727 6838 6702 6723 6744 6781 6832 6654 6702 6606 6815 6448 6416 6581 6637 6574 6591 6698 6753 6793 6706 6770 6914 6819 6875 6872 7006 6935 6843 6911 6637 6765 6892 6756 6776 6571 6623 6673 6521 6641 6671 6733 6526 6669 6730 6652 6526 6444 6496 6645 6500 6406 6446 6687</intensities>
			</dataPoints>
		</scan>
	</xrdMeasurement>
</xrdMeasurements>