File: powder_X-ray_diffraction/variable-temperature_experiments/NaTaO2F2/raw_data/100°C.xrdml
<?xml version="1.0" encoding="UTF-8"?>
<xrdMeasurements xmlns="http://www.xrdml.com/XRDMeasurement/1.7" xmlns:xsi="http://www.w3.org/2001/XMLSchema-instance" xsi:schemaLocation="http://www.xrdml.com/XRDMeasurement/1.7 http://www.xrdml.com/XRDMeasurement/1.7/XRDMeasurement.xsd" status="Completed">
	<comment>
		<entry>Configuration=XRK900, Owner=User-1, Creation date=12/01/2015 16:52:44</entry>
		<entry>Goniometer=Theta/Theta; Minimum step size 2Theta:0.0001; Minimum step size Omega:0.0001</entry>
		<entry>Sample stage=AP XRK-900 with z-axis; Minimum step size Z:0.001</entry>
		<entry>Diffractometer system=EMPYREAN</entry>
		<entry>Measurement program=C:\PANalytical\Data Collector\Programs\Gwen\NaTaO2F2\NaTaO2F2-Lent.xrdmp, Identifier={FF50B583-C5FF-42DA-A01D-A1FB659EF29A}</entry>
		<entry>Batch program=C:\PANalytical\Data Collector\Programs\Gwen\NaTaO2F2\Thermodiff-Ouail.xrdmp, Identifier={5D65A6B1-42FC-480C-9FBB-D7D88D55EA08}</entry>
	</comment>
	<sample type="To be analyzed">
		<id></id>
		<name></name>
		<preparedBy></preparedBy>
	</sample>
	<xrdMeasurement measurementType="Scan" status="Completed" sampleMode="Reflection">
		<comment>
			<entry>PHD Lower Level = 4.02 (keV), PHD Upper Level = 12.07 (keV)</entry>
		</comment>
		<usedWavelength intended="K-Alpha 1">
			<kAlpha1 unit="Angstrom">1.5405980</kAlpha1>
			<kAlpha2 unit="Angstrom">1.5444260</kAlpha2>
			<kBeta unit="Angstrom">1.3922500</kBeta>
			<ratioKAlpha2KAlpha1>0.5000</ratioKAlpha2KAlpha1>
		</usedWavelength>
		<incidentBeamPath>
			<radius unit="mm">240.00</radius>
			<xRayTube id="1010048" name="Empyrean Cu LFF HR (9430 033 7310x) DK434948">
				<tension unit="kV">45.0</tension>
				<current unit="mA">30.0</current>
				<anodeMaterial>Cu</anodeMaterial>
				<focus type="Line">
					<length unit="mm">12.0</length>
					<width unit="mm">0.4</width>
					<takeOffAngle unit="deg">6.0</takeOffAngle>
				</focus>
			</xRayTube>
			<sollerSlit id="21010001" name="Soller slits 0.02 rad.">
				<opening unit="rad">0.0200</opening>
			</sollerSlit>
			<mask id="22030010" name="Fixed mask 20 mm">
				<width unit="mm">20.00</width>
			</mask>
			<antiScatterSlit id="22010003" name="Fixed slit 1Â°" xsi:type="fixedAntiScatterSlitType">
				<height unit="mm">1.52</height>
			</antiScatterSlit>
			<divergenceSlit id="22010012" name="Programmable divergence slit" xsi:type="fixedDivergenceSlitType">
				<distanceToSample unit="mm">140.00</distanceToSample>
				<angle unit="deg">0.5</angle>
			</divergenceSlit>
		</incidentBeamPath>
		<diffractedBeamPath>
			<radius unit="mm">240.00</radius>
			<antiScatterSlit id="22090010" name="AS slit 8.0 mm (PIXcel)" xsi:type="fixedAntiScatterSlitType">
				<height unit="mm">8.00</height>
			</antiScatterSlit>
			<sollerSlit id="21010001" name="Soller slits 0.02 rad.">
				<opening unit="rad">0.0200</opening>
			</sollerSlit>
			<filter id="20030001" name="Large beta-filter Nickel">
				<material>Ni</material>
				<thickness unit="mm">0.020</thickness>
			</filter>
			<detector id="7010019" name="PIXcel1D-Medipix3 detector" xsi:type="rtmsDetectorType">
				<phd unit="%">
					<lowerLevel>25.0</lowerLevel>
					<upperLevel>75.0</upperLevel>
				</phd>
				<mode>Scanning</mode>
				<activeLength unit="deg">3.3482</activeLength>
			</detector>
		</diffractedBeamPath>
		<scan appendNumber="0" mode="Continuous" scanAxis="Gonio" status="Completed">
			<header>
				<startTimeStamp>2023-01-21T06:59:21+01:00</startTimeStamp>
				<endTimeStamp>2023-01-21T09:59:49+01:00</endTimeStamp>
				<author>
					<name>User</name>
				</author>
				<source>
					<applicationSoftware version="5.5a">Data Collector</applicationSoftware>
					<instrumentControlSoftware version="8.2  20201204">EMPYREAN</instrumentControlSoftware>
					<instrumentID>0000000011159748</instrumentID>
				</source>
			</header>
			<dataPoints>
				<positions axis="2Theta" unit="deg">
					<startPosition>9.99846514</startPosition>
					<endPosition>99.99342261</endPosition>
				</positions>
				<positions axis="Omega" unit="deg">
					<startPosition>4.99923257</startPosition>
					<endPosition>49.99671130</endPosition>
				</positions>
				<positions axis="Z" unit="mm">
					<commonPosition>8.846</commonPosition>
				</positions>
				<commonCountingTime unit="seconds">386.070</commonCountingTime>
				<intensities unit="counts">7167 7149 7167 7013 6916 7047 7064 7027 6989 6938 6908 6928 6986 6933 7182 6898 6917 6912 6802 7003 6887 7009 7067 6837 6840 6878 6747 6912 6893 6889 6894 6855 6841 6777 6815 6941 6791 6825 6866 6842 6762 6715 6744 6673 6805 6868 6667 6629 6826 6773 6818 6813 6914 6818 6752 6853 6786 6956 6915 6837 6833 6988 7149 6954 7113 7093 7148 6953 7184 7167 7383 7479 7510 7839 8103 8798 9346 10361 11327 13088 16334 21279 27314 34549 43930 50902 51315 48096 40734 33494 27312 20676 16266 12543 10032 8613 8080 7478 7147 7126 7004 7091 6697 6858 6792 6687 6588 6638 6638 6591 6500 6518 6543 6480 6718 6531 6553 6609 6404 6370 6341 6344 6518 6593 6354 6573 6349 6386 6286 6411 6370 6250 6240 6412 6344 6359 6380 6229 6294 6424 6287 6351 6402 6313 6234 6194 6105 6108 6202 6273 6299 6204 6275 6126 6273 6216 6332 6096 6333 6390 6275 6182 6370 6090 6075 6114 6234 6105 6076 6169 6118 6157 5992 6022 6083 6128 6123 6134 6099 6064 6158 6031 6043 6009 6019 6123 5997 6024 5987 6001 5959 5997 5981 6092 6091 6065 6032 6056 5974 6089 5894 5836 6019 5825 5978 5916 5805 5855 5930 5834 5992 5895 5933 5857 5888 5731 6012 5755 5886 5883 6012 5900 5899 5977 5756 5680 5861 5932 5906 5818 5709 5914 5873 5763 5759 5730 5833 5791 5744 5891 5844 5669 5882 5825 5868 5818 5912 5729 5778 5632 5856 5791 5784 5652 5805 5801 5708 5654 5700 5674 5820 5579 5611 5651 5694 5667 5696 5766 5788 5715 5420 5754 5562 5826 5643 5552 5657 5683 5628 5727 5475 5539 5415 5556 5554 5477 5585 5459 5531 5432 5436 5432 5611 5487 5492 5471 5608 5482 5434 5486 5378 5476 5467 5335 5570 5432 5357 5512 5556 5389 5390 5516 5461 5374 5378 5390 5482 5399 5439 5384 5434 5305 5450 5408 5299 5514 5507 5398 5419 5524 5338 5454 5335 5439 5442 5377 5244 5324 5427 5210 5309 5229 5244 5342 5347 5314 5271 5548 5293 5265 5236 5351 5197 5412 5375 5171 5271 5274 5141 5195 5379 5241 5273 5267 5126 5285 5328 5141 5413 5200 5320 5279 5196 5144 5162 5122 5150 5215 5411 5185 5179 5229 5424 5449 5179 5068 5217 5146 5068 5253 5161 5233 5096 5199 4994 5041 5110 5130 5234 5195 5126 5136 5243 4975 5160 5171 5155 5239 5250 5034 5072 5127 5148 5054 5143 5151 5073 5172 5173 5181 5279 5109 5075 4996 5189 5130 5105 5088 4987 5049 5012 4988 5044 5011 5014 5038 5008 5076 4998 5096 5032 5115 4981 5103 5054 4917 5090 5103 5060 4972 4980 5049 4896 5090 4968 4978 4969 4876 5019 4999 5030 4993 5019 5062 4997 4998 5179 5086 5051 5133 5032 5252 5053 5051 5148 5115 5196 5125 5097 5150 5072 5226 5034 5139 5063 5124 5087 5072 5083 5166 5144 5172 5043 5291 5114 5145 5121 5112 4998 5045 5191 4977 5004 4876 4865 4958 4988 4971 4826 4821 4839 4724 4891 4914 4905 4970 4881 4839 4940 4782 4776 4853 4765 4780 4784 4769 4951 4728 4820 4982 4735 4743 4708 4744 4773 4841 4823 4752 4869 4805 4845 4908 4775 4748 4771 4889 4706 4922 4837 4941 5007 4964 4999 4959 4990 4913 5052 4898 5000 4887 4914 4726 4930 4726 4831 4742 4684 4677 4763 4706 4694 4876 4630 4595 4631 4603 4764 4730 4772 4609 4645 4630 4656 4759 4624 4590 4709 4496 4605 4813 4857 4776 4880 4915 4806 4972 4839 4621 4749 4711 4604 4616 4689 4475 4508 4563 4526 4524 4511 4638 4462 4522 4713 4709 4586 4515 4531 4586 4497 4492 4490 4434 4523 4452 4598 4625 4447 4538 4602 4614 4475 4507 4355 4400 4492 4483 4492 4483 4487 4341 4446 4393 4382 4411 4319 4449 4398 4487 4528 4523 4509 4407 4413 4516 4509 4609 4668 4581 4703 4529 4507 4559 4385 4394 4389 4434 4482 4437 4448 4437 4292 4369 4370 4379 4459 4386 4365 4230 4394 4340 4344 4318 4376 4333 4372 4387 4455 4411 4446 4723 4814 4732 4806 4670 4531 4627 4710 4749 4652 4630 4766 4743 4723 4680 4740 4746 4894 4640 4744 4778 4782 4742 4809 4776 4832 4896 4953 4918 5003 5136 5187 5496 5312 5464 5644 5921 6018 6560 6791 7430 8359 9632 12089 15214 20675 29513 42928 63354 87785 109533 121003 118298 107380 97644 84713 66227 47447 34254 24237 17633 12806 9859 8153 7145 6653 6233 5895 5500 5321 5192 4957 4910 4895 4766 4736 4805 4784 4816 4567 4637 4581 4641 4635 4587 4783 4884 4700 4837 4742 4848 4935 4679 4817 4694 4544 4580 4517 4487 4538 4258 4436 4351 4237 4350 4227 4290 4288 4330 4259 4269 4306 4245 4369 4406 4232 4243 4306 4365 4272 4180 4208 4356 4305 4239 4351 4257 4267 4270 4196 4068 4172 4177 4231 4195 4183 4147 4152 4188 4105 4183 4234 4123 4081 4087 4169 4059 4064 4110 4138 4197 4194 4133 4119 4171 4090 4064 4120 4240 4157 4131 4083 4063 4093 4181 4101 4052 4140 4108 4202 4140 4027 4056 4046 4126 4164 4056 3988 4018 4114 4037 4097 4006 3999 3988 4073 4079 3998 4027 4071 4104 4024 4018 4088 4025 4004 4002 4172 4073 4003 4052 4044 4123 4066 3971 4009 4009 4043 3953 4126 4073 4151 4263 4295 4339 4272 4293 4381 4361 4254 4384 4265 4139 4152 3990 4083 4128 4118 4181 4225 4270 4015 4091 4014 4008 4051 4033 4094 4087 3992 4062 4220 4244 4336 4368 4613 4672 5158 5942 6791 8394 10987 14362 18586 20055 19338 17702 16640 16578 14332 10703 8547 7310 6422 5287 4555 4450 4263 4331 4157 4053 4029 4029 3960 3937 4072 3944 3918 4013 3873 3889 3993 3899 4074 4108 3980 3916 4010 4023 3955 3888 3896 3892 3918 3933 3876 3831 3942 3931 3890 3782 3881 3880 3827 3871 3912 3797 3734 3816 3721 3868 3890 3799 3873 3851 3828 3715 3768 3665 3781 3818 3849 3743 3837 3848 3720 3825 3782 3796 3848 3973 3851 3772 3974 3938 3877 3854 3865 3857 3862 3867 4021 3844 4013 3969 3979 3936 4072 4019 4102 3919 4114 4122 4111 3958 4155 4052 4053 4073 4039 3917 4084 4085 4035 4088 4114 4016 4103 4072 4104 4306 4381 4370 4302 4555 4512 4575 4698 4669 4787 4827 4925 4848 5378 5504 5928 6430 7433 9694 13689 19409 26057 34728 43194 47603 45280 40328 35750 33642 29142 23808 18490 14610 12523 11870 13368 17532 24826 34650 41316 45897 48742 47534 43827 38511 33998 28569 22286 16917 12783 9838 7433 5958 5140 5057 4704 4582 4373 4320 4271 4047 4114 3953 3991 3899 3858 3944 3889 3861 3787 3847 3792 3750 3753 3842 3827 3799 3766 3854 3762 3898 3790 3815 3742 3894 3964 3989 4027 4056 3948 3775 3809 3910 3831 3727 3747 3675 3791 3694 3582 3743 3692 3656 3709 3650 3659 3766 3627 3651 3750 3599 3736 3660 3649 3706 3677 3707 3651 3630 3624 3598 3732 3655 3589 3693 3644 3754 3619 3605 3602 3498 3608 3616 3558 3517 3649 3580 3544 3598 3543 3481 3476 3480 3592 3464 3621 3642 3598 3585 3499 3503 3538 3624 3614 3522 3578 3545 3674 3556 3571 3797 3713 3596 3827 3882 3981 4067 4159 3941 3996 3891 4041 3784 3877 3725 3649 3812 3629 3579 3536 3625 3518 3561 3455 3572 3622 3584 3602 3637 3607 3560 3579 3628 3552 3554 3487 3511 3572 3506 3446 3525 3607 3572 3585 3570 3537 3474 3530 3503 3517 3494 3423 3320 3415 3447 3499 3520 3540 3503 3567 3628 3621 3608 3625 3715 3701 3777 3650 3710 3796 3607 3744 3644 3676 3646 3611 3577 3643 3642 3708 3701 3733 3705 3606 3710 3667 3694 3642 3702 3663 3704 3851 3797 3619 3773 3722 3704 3672 3728 3640 3765 3682 3789 3703 3750 3721 3782 3886 3808 3840 3995 3972 4055 4247 4262 4399 4455 4618 4675 5005 5117 5296 5733 6162 6654 7313 8198 9532 11903 15527 21982 31950 47275 63721 76990 81595 77751 69389 62563 57113 51663 45205 35625 26752 19203 13719 10170 8155 6897 6298 5685 5053 4977 4620 4426 4276 4175 4024 3988 3891 3931 3837 3847 3745 3737 3776 3607 3612 3643 3662 3803 3687 3689 3675 3804 3828 3873 3907 4082 4068 4032 4042 3937 3930 4010 3763 3693 3901 3795 3639 3674 3697 3673 3546 3599 3657 3551 3496 3645 3728 3565 3608 3562 3600 3559 3573 3511 3516 3469 3449 3502 3517 3440 3609 3532 3528 3461 3590 3510 3509 3528 3416 3638 3540 3687 3498 3530 3593 3623 3818 3840 3714 3768 3894 3955 3965 4091 4073 4226 4486 4525 4649 4914 5434 5908 7195 9480 13497 19738 26598 32425 34940 31852 27144 24703 23775 23417 21585 18117 15471 13781 13495 15022 16725 18391 19242 18480 16656 15270 13443 12614 11465 10103 8586 7036 5517 4764 4182 4133 3911 3758 3601 3589 3634 3600 3528 3434 3462 3566 3502 3507 3371 3378 3406 3486 3498 3284 3321 3358 3370 3409 3395 3446 3360 3436 3405 3399 3381 3328 3449 3327 3331 3190 3315 3284 3408 3229 3311 3351 3471 3432 3345 3313 3357 3362 3369 3239 3373 3283 3400 3297 3232 3263 3277 3261 3323 3349 3325 3309 3370 3337 3346 3256 3245 3286 3318 3207 3212 3245 3130 3145 3256 3326 3234 3260 3276 3200 3150 3241 3314 3254 3241 3217 3136 3183 3155 3256 3208 3201 3119 3253 3253 3267 3170 3214 3103 3180 3137 3199 3098 3313 3216 3181 3167 3229 3137 3168 3173 3173 3127 3215 3162 3177 3175 3190 3095 3151 3176 3149 3102 3129 3131 3158 3151 3076 3148 3107 3070 3083 3069 3145 3109 3214 2989 3172 3084 3133 3105 3158 3123 3119 3144 3083 3115 3147 3028 3074 3162 3174 3098 2994 3032 3176 3078 3099 3074 3204 3109 3135 3109 3119 3206 3242 3136 3044 3123 3106 3066 3104 3016 2979 3112 3058 3144 3069 3127 3176 3018 3181 3146 3115 3185 3081 3087 3184 3190 3162 3148 3081 3156 3116 3197 3118 3212 3204 3281 3286 3283 3172 3266 3170 3159 3215 3198 3170 3167 3198 3088 3128 3183 3201 3199 3230 3176 3290 3145 3239 3219 3305 3323 3291 3345 3517 3474 3692 3789 3751 3829 3904 3938 4026 4404 4972 6270 8710 12994 18592 22713 21947 17927 14466 12834 12726 13940 13600 11830 9320 7044 5829 4787 4385 4139 3971 3896 3822 3946 3969 3939 3751 3966 4030 4146 4250 4432 4416 4551 4898 5166 5995 7573 10157 14849 21264 29183 35330 35839 31654 27019 24275 22467 22107 21434 19337 15797 12878 10015 7443 5756 5045 4763 4482 4332 4159 4161 4129 4086 4208 4222 4344 4426 4514 4697 4977 5318 5600 6588 7796 9867 13235 17706 22133 26706 29512 30458 28945 27078 26987 28215 30945 30916 27761 22714 18183 15342 13484 12709 11124 9402 7677 6499 5528 4514 4159 3996 3750 3718 3432 3623 3423 3450 3347 3254 3261 3266 3229 3276 3305 3284 3306 3317 3228 3250 3228 3276 3102 3177 3106 3166 3150 3077 3149 3196 3237 3054 3199 3176 3330 3188 3320 3232 3324 3300 3472 3449 3485 3469 3663 3504 3707 3964 4365 5143 6490 8735 11572 14211 14111 12670 10369 8938 8573 8848 9234 8825 7618 6196 5300 4410 4099 3727 3477 3413 3317 3152 3272 3168 3374 3480 3574 3845 3768 3859 3565 3388 3362 3417 3436 3430 3449 3250 3127 3017 2995 2864 3012 2955 2896 3100 3021 2970 2954 2987 2948 3034 2931 2953 2796 3037 3008 2903 3018 2944 2957 2953 3013 2986 2956 3002 2906 2928 2864 2991 2940 2964 2902 2962 2935 2846 2824 2859 2951 2867 2981 2931 2968 2969 2985 2923 2867 2931 2949 2904 2855 2850 2992 2946 2939 2841 2855 3006 2919 2904 2912 2955 2893 2912 2987 3144 2996 3005 3085 3070 3145 3096 3024 3052 2943 2897 2894 2960 2885 2916 2882 2997 2921 2978 2882 2817 2792 2900 2817 2853 2828 2890 2963 2972 3027 2995 3060 3080 3092 3033 3065 3084 3059 3224 3243 3467 3808 4427 5496 6957 8684 9680 9712 8699 7441 6515 5969 6240 6738 6557 5975 5275 4434 3696 3504 3232 3309 3053 3052 3102 3107 2940 2896 3052 3002 2994 2899 2885 2881 2889 3052 2879 2996 2940 2915 2922 2980 2921 2977 3053 2938 3029 3048 3133 3132 3232 3081 3301 3304 3319 3360 3709 3999 4516 5626 6717 8103 9116 9914 10000 9594 8575 7756 7221 6820 6795 6522 6442 5658 4882 4349 3694 3396 3263 3154 3196 3250 3207 3465 3587 3883 3736 3598 3496 3301 3306 3367 3366 3406 3363 3204 3095 3019 2936 2942 2790 2821 2825 2766 2868 2848 2782 2762 2821 2742 2765 2718 2726 2764 2753 2763 2819 2671 2663 2675 2662 2790 2735 2704 2782 2663 2716 2729 2838 2780 2819 2806 2815 2704 2698 2719 2733 2847 2666 2715 2797 2771 2736 2689 2665 2658 2748 2735 2787 2654 2555 2759 2716 2807 2717 2688 2796 2745 2842 2663 2780 2677 2723 2719 2677 2774 2783 2783 2698 2755 2791 2736 2781 2750 2646 2791 2765 2840 2734 2734 2673 2719 2774 2757 2799 2677 2680 2753 2707 2726 2626 2723 2795 2722 2680 2783 2762 2688 2679 2763 2737 2675 2692 2707 2685 2690 2701 2695 2782 2736 2681 2577 2724 2780 2727 2683 2702 2699 2697 2816 2664 2719 2694 2783 2801 2962 2834 2761 2746 2795 2810 2883 2993 3061 3154 3461 3996 4387 4898 5034 5246 4937 4756 4291 4066 4108 4077 4128 4036 4051 3721 3424 3266 3257 3159 3030 3054 3308 3264 3382 3675 4018 4847 5862 6926 7584 7403 6866 6189 5607 5274 5201 5403 5550 5413 4963 4770 4228 4005 3850 4048 4265 4909 5969 7587 9056 9729 9031 7892 6573 5771 5606 5806 6504 6644 6153 5345 4616 3964 3640 3413 3335 3129 3036 3002 2946 2913 2963 2846 2855 2922 2964 2956 2849 2883 2834 2849 2937 2877 2888 2905 2988 2967 2944 2994 3039 3052 3149 3287 3268 3469 3787 3879 4316 4925 5829 7295 8638 10042 11060 10990 10400 9244 8199 7703 7815 9180 10576 12688 14561 15269 14437 12802 10699 8862 8108 8876 10591 12937 14770 15724 15781 14396 11780 9551 8144 7264 7449 7704 8005 7775 6878 5805 4898 4183 3601 3390 3193 3088 3030 3041 2918 2941 2886 2825 2833 2879 2735 2853 2783 2758 2737 2708 2708 2808 2707 2728 2730 2673 2730 2718 2765 2674 2633 2684 2723 2602 2730 2635 2621 2642 2612 2656 2715 2722 2673 2667 2806 2642 2643 2689 2671 2676 2681 2629 2608 2652 2629 2773 2653 2712 2736 2616 2749 2706 2595 2698 2643 2709 2590 2726 2645 2693 2653 2567 2595 2668 2684 2576 2534 2592 2677 2713 2601 2688 2581 2652 2621 2722 2576 2686 2664 2626 2642 2551 2612 2703 2583 2655 2689 2674 2588 2658 2655 2726 2647 2714 2685 2652 2579 2716 2726 2753 2624 2552 2723 2759 2736 2609 2659 2683 2693 2679 2632 2652 2586 2548 2610 2577 2685 2518 2536 2758 2635 2656 2600 2653 2529 2658 2591 2610 2587 2613 2677 2682 2734 2691 2842 2889 2774 3025 3193 3452 3464 3484 3438 3194 3120 3092 3020 3022 2982 3086 3049 2960 2983 2723 2714 2653 2704 2614 2630 2618 2652 2614 2658 2595 2650 2651 2765 2702 2602 2744 2627 2656 2540 2588 2592 2570 2592 2650 2683 2624 2592 2733 2587 2693 2530 2699 2639 2641 2608 2685 2662 2751 2737 2902 3069 3036 3351 3405 3728 3702 3856 3934 3677 3548 3345 3163 3067 3127 3291 3197 3234 3047 3099 2846 2901 2792 2837 2737 2786 2931 2821 2934 3002 3224 3401 3553 4042 4405 5122 5595 5884 5724 5185 4972 4346 4040 3986 4029 4236 4438 4160 3862 3661 3311 3114 3044 2904 2761 2701 2665 2777 2834 2669 2807 2751 2655 2637 2692 2560 2585 2639 2665 2598 2506 2616 2579 2681 2587 2619 2624 2566 2693 2634 2619 2621 2520 2621 2611 2649 2645 2582 2571 2663 2525 2634 2665 2704 2639 2700 2608 2654 2721 2776 2765 2839 2776 2820 2849 2854 2920 2832 3058 2968 3126 3229 3355 3865 4462 5659 7825 10382 12196 12093 10177 7787 6119 5355 5108 5631 6582 7472 7370 6610 5398 4673 3775 3284 3118 3053 2875 2804 2848 2782 2693 2701 2801 2767 2656 2828 2698 2687 2728 2769 2745 2768 2844 2793 2672 2919 2815 2896 2986 3054 3107 3309 3776 4343 5342 6820 7543 7291 6378 5477 4343 4045 4022 4157 4730 5100 5146 4730 4129 3679 3307 3050 2937 2811 2746 2874 2727 2721 2753 2714 2721 2737 2730 2664 2778 2727 2672 2611 2748 2705 2686 2595 2780 2715 2686 2654 2662 2708 2669 2691 2746 2654 2694 2823 2769 2857 2872 2964 2874 2946 2903 2974 2935 3020 3233 3344 3544 3840 4335 4998 5884 6951 7982 8793 8849 8411 7359 5731 5228 5228 5405 5505 5850 5943 5863 5247 4586 3942 3619 3354 3154 3037 3029 2986 2957 2943 2966 3001 2939 3101 3092 3217 3195 3179 3309 3353 3355 3386 3519 3597 3607 3717 3771 4034 4410 4732 5292 6202 7500 9393 11992 15589 18397 20093 19463 16865 13928 11524 10049 9569 10179 11153 12132 12232 11059 9439 7811 6392 5378 4872 4176 4069 3693 3523 3480 3350 3363 3258 3341 3358 3343 3400 3250 3328 3422 3361 3521 3555 3787 4125 4942 6160 7710 9876 11818 12534 12599 12867 12816 12290 11728 10762 10312 9905 9501 8845 8396 8220 8151 7702 6836 6462 5668 4882 4406 3898 3955 3836 4155 4385 5022 5839 7309 9126 11498 12803 13253 11591 9688 7731 6452 6057 6229 7105 7737 8207 8065 7036 6043 5038 4318 3721 3512 3330 3348 3140 3072 2977 2957 2997 2881 2865 2866 2892 2903 2657 2913 2880 2738 2814 2841 2824 2847 2785 2749 2863 2922 2890 3069 3268 3349 3558 3365 3360 3278 3208 3106 3165 3171 3159 3325 3355 3345 3286 3121 3238 3259 3419 3296 3236 3197 3155 3111 3075 3083 3125 3164 3159 3296 3460 3428 3441 3327 3428 3354 3454 3483 3679 3892 4174 4684 5290 6369 8052 10477 13895 17084 18687 18828 16956 14066 11605 10214 9596 10171 11110 12241 12825 12708 11352 9316 7736 6355 5815 5259 4851 4801 4482 4212 3891 3613 3444 3440 3345 3291 3292 3187 3274 3267 3400 3425 3436 3573 3743 4009 4251 4549 5263 6002 7207 8520 9749 10761 11198 10643 9282 7798 6736 6170 6104 6328 6757 7159 7111 6902 6310 5501 4789 4084 3836 3464 3299 3240 3153 3002 2836 2965 2878 2834 2920 2836 2780 2797 2774 2842 2668 2739 2808 2816 2763 2769 2719 2779 2766 2780 2851 2666 2789 2743 2747 2842 2784 2934 2859 2978 2991 2776 2970 2867 2985 3014 3168 3385 3394 3539 3847 4335 4982 5955 7309 8772 9216 8687 7237 5868 4932 4248 4215 4555 5035 5672 5941 5847 5419 4942 4257 3886 3840 3801 3691 3639 3305 3161 3087 3038 2858 2995 2986 3113 3153 3208 3072 2964 2907 2977 2872 2770 2735 2751 2779 2802 2739 2770 2728 2689 2697 2781 2647 2686 2773 2817 2746 2776 2699 2717 2731 2721 2807 2739 2833 2693 2916 2716 2843 2908 2924 2975 3012 2943 2888 3089 3181 3300 3417 3771 4150 4859 6041 7351 8526 9621 10322 10801 10728 9721 8323 7064 6134 5684 5844 6329 6556 6782 6827 6510 5980 5256 4544 4010 3506 3189 3186 3119 2969 2985 2992 3087 3049 3339 3305 3688 4154 4536 4916 5261 5447 5484 5637 5715 5474 5318 4770 4440 4405 4104 4177 4126 4189 4233 4087 3962 3761 3558 3325 3144 2969 2832 2780 2687 2702 2759 2702 2773 2725 2666 2663 2754 2835 2890 2902 2982 3198 3475 3725 4090 4368 4454 4334 4045 3546 3560 3426 3142 3211 3354 3583 3533 3665 3636 3601 3294 3222 3027 2874 2886 2743 2753 2773 2711 2733 2669 2695 2726 2637 2606 2622 2617 2566 2602 2655 2577 2556 2760 2570 2518 2582 2590 2539 2527 2608 2578 2598 2566 2527 2539 2658 2562 2610 2561 2591 2593 2548 2587 2616 2646 2619 2695 2692 2700 2768 2846 2917 2893 2971 2940 3024 2876 2961 2824 2933 2871 2775 2854 2875 2736 2869 2792 2806 2761 2758 2733 2720 2650 2631 2683 2704 2513 2593 2655 2602 2516 2621 2600 2615 2635 2628 2625 2620 2525 2623 2722 2488 2588 2766 2653 2651 2628 2607 2638 2577 2651 2592 2600 2576 2686 2596 2633 2651 2660 2636 2683 2722 2730 2701 2827 2759 2783 2822 2859 2851 2861 2841 2903 2942 3095 3033 3102 3167 3305 3485 3797 4057 4358 5107 6161 7546 9317 10898 11949 11501 10486 8898 7368 6251 5664 5606 5762 6522 7193 7700 7810 7160 6360 5588 4709 4144 3884 3622 3480 3385 3506 3441 3564 3709 3629 3501 3384 3227 3138 3044 2905 2820 3047 3129 3122 3208 3291 3129 3151 2996 3115 3041 2971 3075 2968 3061 3049 3027 3106 3384 3628 3770 4176 5070 5958 7458 8833 10341 11391 11444 11065 10010 9017 8315 8167 8275 8401 8553 8501 8627 8731 8841 8631 8120 7687 7207 6761 6071 5487 4828 4494 4058 4025 3953 4036 4123 3978 3806 3708 3320 3248 3039 3051 2938 2928 2822 2841 2914 2874 2895 2970 2948 2916 2946 2873 2861 2930 3017 3027 3113 3116 3214 3237 3273 3548 3907 4267 4537 5234 6029 6718 7722 8303 8961 9481 9943 10138 10222 9797 9217 8128 7525 7016 7014 7310 7866 8266 8879 9705 9920 9462 8696 7482 6261 5384 4759 4342 4279 4366 4465 4725 4908 4793 4487 4173 3810 3538 3548 3231 3081 3161 3119 3121 2988 3074 3077 3003 3008 3241 3219 3267 3267 3370 3661 3899 4272 5067 5937 6831 7934 8612 8379 7457 6402 5663 4991 4730 4652 4700 5084 5645 6445 6641 6580 6024 5211 4590 4246 3895 3899 3961 3761 3870 3860 3945 3881 3531 3393 3177 3117 3166 3193 3205 3137 3324 3177 3085 3135 3074 3088 2976 3059 3004 3109 3094 3262 3245 3366 3476 3860 4024 4328 4760 5347 5990 6855 7482 8102 8203 8309 7709 6821 6124 5703 5515 5606 6158 6689 7506 8870 9990 10955 11424 10884 9830 8024 6600 5557 4936 4835 5036 5128 5638 6185 6457 6599 6375 5816 5354 5195 5075 5186 6018 6798 7748 8753 9597 9671 9238 8156 6915 5806 5050 4868 4876 4991 5388 5680 6144 6256 6037 5607 5000 4345 3931 3622 3420 3320 3180 3157 3125 3226 3149 3170 3134 3041 3175 3272 3324 3319 3654 3949 4422 4897 5690 6595 7355 8296 9323 9898 10277 10023 9545 8807 8164 7693 7500 7898 8980 10795 12928 14046 14265 13240 11505 9450 7948 6717 5925 5370 5433 5811 6276 6897 7225 6623 5926 5124 4599 4140 3732 3529 3160 3142 3006 3032 2959 2884 2870 2790 2857 2832 2722 2704 2766 2802 2792 2780 2790 2807 2758 2826 2905 2887 2828 2752 2823 2889 2969 2904 2969 3090 3104 3161 3246 3378 3580 3647 3883 4381 4915 5956 7119 8457 9769 10123 10000 9568 8758 8263 8375 8834 9182 9773 10045 10201 10014 9448 8944 8199 7325 6754 6831 6608 7135 7287 7297 7424 7208 6675 6331 5886 5432 5286 4986 5066 5072 5414 5531 5654 5746 5805 5719 5511 5163 4520 4184 3883 3775 3589 3730 3707 3798 3771 3708 3630 3537 3394 3082 2893 2763 2786 2717 2653 2602 2672 2535 2586 2616 2644 2641 2564 2623 2563 2515 2510 2531 2547 2590 2497 2592 2499 2470 2529 2440 2510 2494 2537 2472 2590 2505 2592 2435 2522 2482 2544 2529 2415 2566 2512 2523 2403 2445 2514 2558 2559 2426 2432 2555 2425 2486 2493 2448 2415 2562 2525 2429 2503 2477 2442 2502 2415 2386 2403 2468 2403 2485 2576 2481 2621 2667 2659 2558 2636 2540 2438 2527 2406 2406 2505 2434 2473 2482 2490 2499 2505 2470 2490 2506 2431 2492 2431 2404 2446 2450 2472 2461 2393 2468 2447 2493 2388 2465 2433 2362 2411 2357 2390 2519 2519 2400 2368 2421 2397 2416 2479 2433 2392 2389 2387 2417 2393 2386 2427 2365 2368 2373 2429 2350 2321 2570 2468 2421 2470 2422 2397 2393 2401 2476 2368 2435 2466 2363 2404 2471 2509 2406 2407 2347 2527 2535 2454 2497 2493 2493 2664 2622 2623 2668 2768 2763 2795 2879 3030 3070 3221 3456 3650 3840 4106 4062 3994 3778 3481 3236 3154 2927 3028 2976 2950 3150 3239 3260 3403 3286 3142 3078 2825 2771 2740 2697 2695 2652 2616 2720 2624 2565 2627 2716 2707 2918 2981 3118 3287 3572 3941 4387 4954 5233 5503 5516 5350 5022 4689 4157 3787 3535 3478 3396 3509 3615 3819 4041 4125 4029 3863 3726 3468 3148 2895 2867 2675 2740 2608 2458 2525 2438 2434 2387 2454 2468 2506 2500 2382 2411 2440 2341 2371 2417 2302 2357 2342 2349 2431 2418 2351 2375 2380 2381 2390 2327 2423 2406 2471 2482 2425 2462 2461 2566 2678 2576 2635 2539 2550 2602 2609 2716 2672 2541 2562 2596 2681 2692 2794 2858 2785 2743 2569 2604 2657 2648 2574 2484 2505 2467 2474 2538 2473 2385 2431 2444 2386 2360 2386 2433 2347 2383 2295 2353 2434 2311 2439 2409 2321 2376 2324 2453 2422 2367 2362 2414 2343 2331 2316 2321 2357 2400 2318 2366 2394 2351 2441 2383 2413 2342 2490 2455 2436 2304 2317 2379 2353 2336 2373 2381 2370 2462 2364 2375 2349 2378 2471 2340 2370 2306 2224 2384 2287 2351 2325 2325 2311 2408 2330 2365 2350 2352 2345 2283 2309 2385 2317 2318 2398 2283 2329 2355 2372 2343 2355 2382 2326 2396 2464 2435 2528 2445 2495 2584 2399 2433 2415 2359 2412 2509 2431 2522 2419 2434 2531 2539 2559 2583 2549 2557 2421 2493 2351 2399 2352 2341 2459 2377 2389 2416 2525 2448 2413 2367 2412 2432 2396 2314 2341 2396 2339 2328 2364 2415 2331 2316 2373 2368 2413 2375 2326 2373 2266 2388 2286 2365 2272 2275 2423 2330 2321 2357 2276 2223 2312 2332 2314 2379 2347 2301 2320 2336 2335 2295 2412 2374 2342 2296 2363 2312 2395 2360 2336 2392 2296 2384 2358 2381 2371 2201 2326 2420 2351 2355 2303 2391 2358 2441 2400 2402 2456 2411 2339 2421 2460 2500 2490 2495 2646 2563 2772 2987 3261 3355 3606 3522 3451 3305 3079 2804 2762 2741 2648 2573 2678 2653 2801 2874 2859 3004 2996 2921 2885 2789 2802 2716 2790 2792 2819 2926 2810 2804 2703 2742 2739 2723 2621 2726 2694 2696 2736 2750 2708 2654 2730 2733 2722 2658 2703 2635 2662 2722 2677 2751 2733 2851 3013 3281 3503 3950 4672 5181 5437 5155 4447 3901 3412 3108 2917 2865 2759 2813 2948 3198 3324 3628 3907 3819 3812 3374 3162 2987 2775 2650 2695 2661 2549 2687 2458 2509 2636 2608 2590 2846 2833 2957 3368 3771 3966 4009 3709 3567 3303 2985 2826 2806 2709 2657 2818 2738 2942 3091 3164 3369 3384 3355 3333 3355 3372 3390 3507 3494 3638 3826 3786 3755 3614 3763 3427 3377 3147 3093 3057 3131 3206 3274 3291 3400 3302 3479 3562 3982 4221 4604 4976 5505 6285 6689 7385 7189 6679 5975 5453 4710 4186 3912 3800 3723 3805 4106 4477 4853 5209 5717 6048 6108 5829 5521 5208 4595 4164 3859 3707 3383 3409 3398 3512 3409 3577 3754 3836 3893 3999 3992 4068 4044 4068 4253 4639 4859 5315 5091 5031 4487 4166 3924 3587 3393 3274 3314 3225 3384 3529 3875 3840 4035 4137 4039 3828 3578 3363 3256 3166 3090 2989 3003 2981 2818 2901 2946 2811 2750 2768 2848 2945 2903 3040 2961 3072 3249 3418 3680 3910 3905 3961 4196 4259 4174 4270 4331 4201 3985 3909 3647 3589 3572 3710 3949 4177 4785 5540 5959 6061 5803 5386 4750 4335 3904 3535 3274 3211 3000 2980 3185 3267 3516 3728 3800 3876 3681 3482 3160 2970 2823 2860 2911 2756 2883 3043 3139 3370 3606 3887 4086 4164 3985 3754 3503 3184 2944 2996 2915 2895 2902 2923 3065 3116 3355 3444 3567 3594 3659 3572 3485 3523 3461 3504 3524 3558 3577 3595 3502 3423 3239 3109 2938 2946 2916 2897 2861 2880 2898 2932 2897 2930 2995 2938 2916 2871 2824 2748 2686 2591 2520 2551 2588 2535 2582 2532 2576 2480 2493 2498 2488 2548 2540 2511 2539 2515 2530 2553 2581 2545 2575 2621 2671 2765 2911 3015 3182 3457 3582 3876 4149 4184 4174 4024 3734 3525 3178 3005 2919 2841 2816 3005 2901 3019 3119 3333 3265 3404 3365 3213 3023 3003 2869 2772 2688 2637 2584 2641 2630 2679 2818 2962 3155 3292 3544 3870 3970 4127 4154 4257 3975 3750 3563 3373 3280 3238 3356 3264 3189 3387 3312 3351 3410 3508 3684 3418 3363 3396 3261 3261 3195 3347 3382 3646 3685 3889 4106 4075 4098 4261 4233 3956 3839 3635 3308 3257 3108 3178 3087 3239 3135 3313 3239 3321 3357 3407 3362 3379 3222 3103 2937 2964 2860 2726 2869 2873 2818 2905 2900 3121 3298 3683 4113 4648 4932 5182 5304 5208 5096 4942 5075 5388 5358 5345 5095 4685 4280 3938 3840 3901 3911 3971 3869 4012 3805 3788 3743 3810 3887 3783 3705 3564 3288 3024 2944 2711 2629 2615 2597 2466 2475 2451 2525 2335 2414 2385 2462 2515 2505 2402 2347 2413 2335 2333 2439 2341 2238 2352 2311 2419 2409 2345 2363 2413 2429 2316 2265 2348 2387 2258 2440 2285 2291 2394 2315 2364 2330 2318 2299 2308 2394 2379 2399 2399 2297 2368 2319 2362 2338 2322 2281 2311 2324 2253 2265 2399 2367 2386 2316 2347 2332 2310 2454 2301 2335 2305 2315 2353 2290 2347 2310 2325 2249 2375 2304 2415 2286 2381 2447 2292 2408 2454 2571 2437 2549 2532 2536 2534 2595 2477 2431 2461 2441 2437 2446 2454 2507 2450 2482 2441 2523 2438 2446 2405 2508 2450 2455 2393 2474 2412 2518 2590 2614 2660 2611 2652 2653 2786 2757 2777 2857 2872 2824 2866 2845 2854 2811 2672 2782 2853 3025 3088 3340 3301 3550 3866 4050 4246 4678 4831 4775 4698 4636 4370 4033 3805 3593 3344 3212 3152 3184 3161 3211 3202 3316 3470 3500 3514 3574 3412 3319 3190 3102 2918 2806 2793 2706 2639 2522 2506 2540 2617 2646 2576 2565 2498 2516 2554 2561 2616 2605 2571 2533 2685 2705 2741 2784 2873 3052 3173 3290 3587 3771 4052 4209 4469 4423 4439 4394 4460 4294 3980 3750 3413 3215 3236 3227 3101 3173 3303 3291 3338 3435 3486 3440 3375 3403 3185 3299 3130 2922 2921 2841 2678 2664 2687 2737 2799 2776 2912 3003 3278 3233 3115 2950 2936 2758 2668 2671 2638 2504 2538 2525 2445 2561 2707 2619 2700 2776 2875 2768 2657 2617 2722 2628 2582 2524 2614 2613 2667 2734 2837 2962 2921 3037 2945 2851 2685 2605 2590 2513 2507 2537 2531 2444 2494 2527 2561 2557 2778 2674 2731 2702 2654 2671 2683 2758 2746 2729 3003 3043 3098 3284 3347 3372 3551 3589 3441 3479 3467 3434 3503 3383 3272 3140 3112 2988 3018 2994 3051 3080 3184 3204 3165 3278 3353 3426 3402 3533 3606 3643 3565 3550 3504 3361 3531 3412 3377 3455 3528 3808 3890 4006 4107 4010 3996 3852 3816 3946 3943 3843 4002 4058 3799 3995 4054 3924 4085 4028 3976 3820 3744 3558 3462 3288 3290 3230 3237 3185 3229 3205 3227 3217 3221 3160 3180 3231 3324 3220 3216 3218 3304 3460 3614 3803 4050 4216 4199 4089 3875 3616 3519 3186 3129 3148 2982 3011 2972 2908 2937 3035 3171 3337 3372 3471 3478 3490 3474 3355 3303 3128 3207 2976 2928 2921 2738 2728 2777 2712 2689 2759 2726 2595 2665 2742 2730 2791 2867 2853 2861 2897 2910 3024 3114 3091 3219 3348 3470 3672 3826 4064 4260 4422 4705 4923 5166 5421 5741 6060 6508 6798 6716 6537 6084 5813 5521 5170 5078 4832 4870 4735 4726 4729 4709 5029 5332 5747 6048 5956 6049 5987 5606 5170 5030 4981 4887 4893 4801 4695 4604 4301 4027 4005 3760 3694 3711 3653 3515 3635 3426 3386 3298 3341 3297 3407 3450 3513 3606 3529 3609 3587 3630 3547 3617 3541 3639 3486 3398 3408 3356 3295 3322 3257 3215 3347 3391 3573 3497 3600 3631 3594 3554 3584 3427 3433 3385 3170 3102 2963 2868 2850 2798 2869 2818 2820 2785 2807 2921 2903 2956 2840 2850 2741 2646 2603 2652 2598 2472 2484 2502 2552 2463 2517 2459 2492 2474 2453 2403 2453 2471 2410 2469 2434 2453 2545 2388 2467 2366 2575 2590 2563 2582 2594 2542 2620 2580 2749 2628 2705 2765 2793 2887 3062 3198 3383 3563 3678 3770 4055 4168 4287 4151 4368 4101 4055 3932 3627 3481 3203 3263 3090 3020 3078 2914 3093 3203 3273 3361 3343 3392 3410 3501 3410 3378 3496 3274 3424 3547 3671 3794 3861 3928 3664 3288 3113 2901 2849 2683 2718 2594 2576 2617 2643 2632 2676 2722 2873 3002 3033 3169 3137 3100 2950 2888 2830 2556 2651 2575 2468 2471 2496 2515 2419 2344 2381 2412 2478 2536 2393 2542 2441 2403 2341 2408 2435 2457 2438 2448 2437 2481 2427 2387 2412 2419 2323 2409 2371 2514 2449 2403 2520 2565 2534 2591 2655 2795 2686 2676 2651 2647 2545 2592 2692 2599 2590 2593 2619 2705 2770 2683 2676 2675 2699 2683 2773 2752 2848 2957 3053 3215 3305 3406 3377 3370 3166 3052 2897 2803 2679 2643 2624 2577 2563 2593 2526 2625 2612 2685 2737 2768 2767 2802 2799 2803 2681 2621 2657 2565 2437 2413 2347 2488 2400 2349 2408 2420 2454 2326 2340 2417 2407 2315 2393 2385 2417 2367 2408 2504 2482 2539 2471 2452 2495 2508 2485 2494 2498 2578 2486 2529 2528 2566 2407 2365 2481 2453 2322 2345 2346 2456 2336 2318 2344 2437 2481 2399 2459 2402 2430 2401 2497 2458 2497 2419 2425 2348 2400 2405 2540 2468 2367 2456 2383 2396 2391 2294 2424 2302 2349 2388 2342 2443 2431 2330 2445 2537 2307 2391 2412 2417 2401 2397 2504 2480 2582 2530 2540 2635 2663 2826 2851 2689 2863 2785 2914 2858 2897 2921 3105 3059 2983 2989 2951 2869 2798 2863 2948 2974 3071 3189 3302 3472 3662 3800 3943 4123 4187 4034 3999 4032 3887 3958 3768 3622 3623 3396 3416 3282 3332 3262 3359 3473 3555 3472 3657 3604 3490 3488 3346 3231 3253 3168 3095 3039 2932 2827 2765 2755 2720 2776 2735 2806 2565 2685 2716 2749 2646 2579 2602 2551 2477 2515 2491 2549 2438 2465 2434 2427 2474 2400 2424 2408 2469 2489 2446 2574 2573 2632 2758 2698 2859 2895 2862 3019 3086 3077 2956 2943 2860 2725 2640 2634 2626 2523 2497 2565 2572 2501 2582 2571 2621 2670 2713 2684 2730 2705 2760 2772 2732 2799 2819 2741 2816 2794 2770 3050 2999 3218 3164 3310 3292 3245 3015 2938 2892 2833 2776 2691 2710 2731 2754 2767 2832 2846 3036 3008 3097 3265 3246 3268 3177 3021 2909 2900 2710 2725 2729 2763 2701 2643 2616 2593 2621 2565 2634 2811 2649 2749 2850 2873 2949 2830 3016 3044 3036 3154 3297 3313 3401 3327 3098 3211 3048 2956 2870 2826 2718 2691 2742 2847 2825 2852 3013 2967 3162 3379 3416 3672 3819 4023 3903 3856 3593 3563 3255 3219 3019 2903 3038 2842 2903 2908 2960 2940 2880 2884 2919 3016 3079 3134 3123 3076 3131 2996 2925 2914 2821 2781 2604 2691 2753 2877 2862 2961 3014 2929 3022 3034 3078 2998 3009 3178 3245 3380 3468 3633 3666 3924 3860 3899 3665 3514 3341 3183 3069 2937 2899 2719 2845 2809 2754 2780 2825 2790 2868 2954 2956 3084 3014 3092 2978 3074 2942 2861 2813 2734 2550 2623 2605 2582 2565 2714 2618 2758 2731 2809 2915 3044 3310 3264 3292 3332 3306 3151 3072 2915 2877 2670 2660 2564 2600 2469 2606 2661 2500 2537 2700 2621 2778 2816 2857 2942 2796 2920 2861 2799 2692 2683 2647 2518 2604 2488 2551 2511 2437 2458 2386 2397 2479 2444 2554 2476 2565 2637 2676 2715 2815 2908 3136 3196 3518 3706 3851 3885 3822 3535 3301 3140 3026 2823 2828 2691 2725 2661 2574 2534 2661 2750 2667 2765 2912 2935 3092 3166 3181 3163 3081 3091 2937 3045 3008 3004 3037 2875 3119 3218 3105 3203 3343 3253 3182 3153 2971 2968 2995 3024 3009 2857 3018 3058 3148 3019 2971 2878 2955 2988 3040 3058 2958 3142 3174 3160 3221 3091 3162 3237 3123 3103 3006 2970 2961 3006 2890 2948 2951 2790 2850 2781 2819 2771 2793 2962 2926 3098 3308 3264 3347 3477 3332 3237 3339 2982 2920 2815 2765 2758 2687 2701 2635 2736 2714 2878 2823 2734 2768 2965 2970 3154 3214 3330 3557 3562 3717 3804 3827 3962 3991 4035 4162 3955 3929 3774 3692 3624 3524 3475 3176 3046 2866 2901 2902 2930 3044 3064 3095 3136 3363 3289 3483 3295 3422 3510 3580 3565 3626 3766 3793 3935 3996 3959 3820 3655 3496 3359 3380 3053 2964 2836 2919 2843 2840 2962 2876 2832 2965 3055 2999 3143 3129 3304 3382 3426 3348 3346 3301 3103 3111 2919 2940 2856 2844 2830 2772 2796 2709 2789 2795 2749 2700 2735 2670 2550 2638 2654 2542 2689 2566 2661 2567 2559 2543 2602 2629 2642 2673 2765 2673 2616 2779 2962 2884 2810 2779 2818 2727 2681 2708 2712 2648 2832 2857 2786 2773 2927 2719 2868 2948 2868 2896 2923 3004 3129 3089 3251 3392 3372 3456 3681 3751 3817 3758 3725 3643 3493 3277 3217 3094 2864 2851 2759 2816 2793 2693 2690 2686 2725 2744 2771 2761 2935 2925 2984 2924 3017 3020 2887 2943 2772 2638 2642 2516 2499 2511 2511 2465 2451 2521 2473 2449 2447 2449 2379 2343 2380 2292 2349 2341 2393 2390 2406 2424 2339 2416 2310 2393 2407 2350 2312 2403 2275 2357 2291 2386 2287 2377 2339 2360 2289 2317 2350 2353 2295 2387 2439 2357 2299 2342 2337 2290 2370 2383 2457 2422 2455 2494 2447 2597 2665 2706 2735 2974 2918 3086 3134 3258 3232 3084 3180 3024 2974 2817 2896 2802 2729 2873 2870 2809 2856 2758 2737 2878 2770 2678 2851 2871 2866 2969 2993 2917 2897 2810 2803 2742 2583 2662 2686 2697 2691 2717 2708 2648 2628 2661 2628 2720 2733 2830 2838 2839 3017 3063 3093 3289 3379 3421 3465 3354 3443 3389 3244 3270 3172 3064 3122 3018 2887 2910 2844 2837 2777 2781 2722 2727 2676 2808 2717 2799 2831 2906 2893 2805 2791 2880 2700 2716 2679 2636 2598 2528 2497 2513 2647 2404 2502 2489 2440 2389 2351 2371 2393 2328 2321 2387 2414 2274 2289 2339 2294 2329 2321 2363 2404 2338 2371 2295 2324 2263 2320 2390 2412 2331 2266 2324 2366 2338 2273 2371 2363 2332 2270 2550 2335 2344 2336 2310 2244 2372 2217 2326 2296 2279 2354 2277 2289 2351 2319 2290 2277 2297 2392 2294 2346 2275 2279 2298 2332 2290 2323 2308 2403 2401 2290 2372 2390 2398 2364 2370 2434 2409 2372 2452 2519 2500 2495 2612 2556 2468 2455 2514 2490 2510 2373 2370 2474 2437 2457 2398 2457 2395 2481 2372 2438 2526 2373 2498 2531 2541 2494 2594 2698 2841 2800 2788 2749 2885 2916 2897 2934 3024 2960 2985 3111 3141 3213 3299 3431 3469 3536 3508 3439 3471 3342 3207 3071 3052 2943 2883 2851 2995 2827 2914 2904 2997 3011 3099 3356 3337 3463 3444 3517 3555 3601 3611 3407 3341 3187 3028 3006 2834 2747 2764 2647 2755 2666 2764 2776 2712 2749 2932 3071 3126 3243 3249 3193 3354 3238 3356 3285 3299 3120 3092 3005 3085 2962 2967 3097 3045 3033 2996 3174 3189 3311 3120 3130 2943 2869 2822 2887 2928 2867 2785 2772 2717 2766 2743 2677 2570 2686 2710 2693 2693 2618 2682 2704 2708 2687 2765 2659 2672 2623 2483 2557 2473 2480 2505 2440 2317 2343 2488 2436 2401 2397 2348 2424 2388 2353 2464 2474 2470 2431 2434 2407 2429 2483 2432 2395 2527 2539 2569 2602 2665 2727 2705 2690 2776 2988 3103 3250 3322 3604 3470 3660 3757 3759 3627 3697 3579 3572 3649 3547 3494 3484 3406 3429 3394 3501 3560 3557 3682 3858 3928 4024 4250 4212 4361 4427 4540 4621 4688 4688 4666 4537 4414 4414 4103 4092 3824 3600 3526 3567 3260 3290 3312 3367 3384 3428 3403 3385 3351 3544 3473 3622 3767 3745 3742 3842 3898 3822 3921 3849 3813 3758 3927 3673 3846 3740 3601 3712 3726 3619 3558 3526 3463 3374 3328 3344 3260 3083 3034 2993 2876 2960 2904 2897 2865 2969 3110 3061 3016 3110 3179 3114 3367 3372 3573</intensities>
			</dataPoints>
			<nonAmbientPoints type="Temperature" unit="K">
[...]
			</nonAmbientPoints>
		</scan>
	</xrdMeasurement>
</xrdMeasurements>