File: powder_X-ray_diffraction/variable-temperature_experiments/NaTaO2F2/raw_data/120°C.xrdml
<?xml version="1.0" encoding="UTF-8"?>
<xrdMeasurements xmlns="http://www.xrdml.com/XRDMeasurement/1.7" xmlns:xsi="http://www.w3.org/2001/XMLSchema-instance" xsi:schemaLocation="http://www.xrdml.com/XRDMeasurement/1.7 http://www.xrdml.com/XRDMeasurement/1.7/XRDMeasurement.xsd" status="Completed">
	<comment>
		<entry>Configuration=XRK900, Owner=User-1, Creation date=12/01/2015 16:52:44</entry>
		<entry>Goniometer=Theta/Theta; Minimum step size 2Theta:0.0001; Minimum step size Omega:0.0001</entry>
		<entry>Sample stage=AP XRK-900 with z-axis; Minimum step size Z:0.001</entry>
		<entry>Diffractometer system=EMPYREAN</entry>
		<entry>Measurement program=C:\PANalytical\Data Collector\Programs\Gwen\NaTaO2F2\NaTaO2F2-Lent.xrdmp, Identifier={FF50B583-C5FF-42DA-A01D-A1FB659EF29A}</entry>
		<entry>Batch program=C:\PANalytical\Data Collector\Programs\Gwen\NaTaO2F2\Thermodiff-Ouail.xrdmp, Identifier={5D65A6B1-42FC-480C-9FBB-D7D88D55EA08}</entry>
	</comment>
	<sample type="To be analyzed">
		<id></id>
		<name></name>
		<preparedBy></preparedBy>
	</sample>
	<xrdMeasurement measurementType="Scan" status="Completed" sampleMode="Reflection">
		<comment>
			<entry>PHD Lower Level = 4.02 (keV), PHD Upper Level = 12.07 (keV)</entry>
		</comment>
		<usedWavelength intended="K-Alpha 1">
			<kAlpha1 unit="Angstrom">1.5405980</kAlpha1>
			<kAlpha2 unit="Angstrom">1.5444260</kAlpha2>
			<kBeta unit="Angstrom">1.3922500</kBeta>
			<ratioKAlpha2KAlpha1>0.5000</ratioKAlpha2KAlpha1>
		</usedWavelength>
		<incidentBeamPath>
			<radius unit="mm">240.00</radius>
			<xRayTube id="1010048" name="Empyrean Cu LFF HR (9430 033 7310x) DK434948">
				<tension unit="kV">45.0</tension>
				<current unit="mA">30.0</current>
				<anodeMaterial>Cu</anodeMaterial>
				<focus type="Line">
					<length unit="mm">12.0</length>
					<width unit="mm">0.4</width>
					<takeOffAngle unit="deg">6.0</takeOffAngle>
				</focus>
			</xRayTube>
			<sollerSlit id="21010001" name="Soller slits 0.02 rad.">
				<opening unit="rad">0.0200</opening>
			</sollerSlit>
			<mask id="22030010" name="Fixed mask 20 mm">
				<width unit="mm">20.00</width>
			</mask>
			<antiScatterSlit id="22010003" name="Fixed slit 1Â°" xsi:type="fixedAntiScatterSlitType">
				<height unit="mm">1.52</height>
			</antiScatterSlit>
			<divergenceSlit id="22010012" name="Programmable divergence slit" xsi:type="fixedDivergenceSlitType">
				<distanceToSample unit="mm">140.00</distanceToSample>
				<angle unit="deg">0.5</angle>
			</divergenceSlit>
		</incidentBeamPath>
		<diffractedBeamPath>
			<radius unit="mm">240.00</radius>
			<antiScatterSlit id="22090010" name="AS slit 8.0 mm (PIXcel)" xsi:type="fixedAntiScatterSlitType">
				<height unit="mm">8.00</height>
			</antiScatterSlit>
			<sollerSlit id="21010001" name="Soller slits 0.02 rad.">
				<opening unit="rad">0.0200</opening>
			</sollerSlit>
			<filter id="20030001" name="Large beta-filter Nickel">
				<material>Ni</material>
				<thickness unit="mm">0.020</thickness>
			</filter>
			<detector id="7010019" name="PIXcel1D-Medipix3 detector" xsi:type="rtmsDetectorType">
				<phd unit="%">
					<lowerLevel>25.0</lowerLevel>
					<upperLevel>75.0</upperLevel>
				</phd>
				<mode>Scanning</mode>
				<activeLength unit="deg">3.3482</activeLength>
			</detector>
		</diffractedBeamPath>
		<scan appendNumber="0" mode="Continuous" scanAxis="Gonio" status="Completed">
			<header>
				<startTimeStamp>2023-01-21T10:25:23+01:00</startTimeStamp>
				<endTimeStamp>2023-01-21T13:25:49+01:00</endTimeStamp>
				<author>
					<name>User</name>
				</author>
				<source>
					<applicationSoftware version="5.5a">Data Collector</applicationSoftware>
					<instrumentControlSoftware version="8.2  20201204">EMPYREAN</instrumentControlSoftware>
					<instrumentID>0000000011159748</instrumentID>
				</source>
			</header>
			<dataPoints>
				<positions axis="2Theta" unit="deg">
					<startPosition>9.99846514</startPosition>
					<endPosition>99.99342261</endPosition>
				</positions>
				<positions axis="Omega" unit="deg">
					<startPosition>4.99923257</startPosition>
					<endPosition>49.99671130</endPosition>
				</positions>
				<positions axis="Z" unit="mm">
					<commonPosition>8.846</commonPosition>
				</positions>
				<commonCountingTime unit="seconds">386.070</commonCountingTime>
				<intensities unit="counts">6924 7127 6951 7091 6933 6847 6962 6835 6916 6890 6854 6902 6946 6749 6851 6715 6805 6932 6790 6739 6733 6887 6811 6627 6942 6756 6722 6817 6689 6725 6718 6901 6826 6641 6784 6617 6791 6686 6650 6648 6731 6650 6740 6741 6561 6684 6678 6763 6822 6805 6697 6665 6671 6822 6786 6740 6801 6749 6809 6934 6756 6752 6756 6885 7004 6768 6924 7157 7064 7266 7109 7425 7456 7793 8050 8648 9312 10183 11712 13165 16451 21458 27637 35155 43884 50835 51599 47271 39442 31623 25523 19528 15062 12106 9767 8746 7937 7485 7118 7124 7016 6851 6801 6575 6618 6747 6465 6469 6618 6552 6413 6385 6433 6399 6533 6450 6373 6494 6294 6533 6386 6395 6365 6458 6293 6262 6205 6285 6205 6361 6273 6234 6230 6310 6272 6274 6204 6225 6170 6289 6152 6385 6230 6243 6152 6325 6257 6302 6085 6153 6133 6196 6171 6120 6168 6204 6120 6034 6147 6043 6071 6080 6132 6105 6040 6020 6237 6023 5967 6173 6026 5915 6080 6094 6023 5952 6112 5907 6011 5907 5862 5959 5940 5902 5979 5962 6006 6039 5909 5872 5958 5965 5947 5903 5858 5835 5932 5973 5887 5901 5919 5858 6045 5937 6040 5795 5803 5797 5922 5789 5830 5835 5766 5798 5854 5838 5692 5843 5884 5678 5727 5624 5786 5737 5660 5821 5866 5737 5608 5768 5719 5743 5959 5744 5768 5690 5714 5745 5704 5556 5850 5636 5628 5704 5731 5738 5725 5651 5646 5750 5603 5695 5620 5642 5553 5723 5598 5550 5548 5566 5536 5623 5641 5656 5651 5593 5648 5643 5510 5615 5643 5706 5459 5553 5517 5349 5564 5491 5556 5550 5590 5503 5574 5457 5460 5397 5577 5522 5588 5413 5537 5511 5435 5469 5364 5547 5478 5384 5488 5484 5353 5383 5439 5403 5433 5538 5411 5346 5408 5343 5409 5329 5264 5229 5248 5453 5323 5318 5453 5543 5219 5280 5315 5259 5345 5370 5276 5271 5272 5309 5286 5436 5302 5299 5247 5266 5307 5211 5284 5142 5432 5255 5291 5200 5190 5266 5179 5231 5450 5293 5227 5274 5201 5207 5046 5165 5256 5117 5313 5308 5115 5189 5159 5312 5312 5196 5174 5117 5154 5144 5233 5308 5144 5163 5077 5097 5049 5253 5272 5163 5206 5094 5273 5185 5103 5036 5019 5284 5210 5253 5157 5153 5170 5129 4996 4946 5025 5081 5217 5085 4941 4997 5051 5053 5180 5126 5003 5045 5108 5015 5055 5015 5000 5076 5036 4971 5041 5236 5128 4860 5045 4992 4921 4973 4985 4986 5083 4965 4913 5019 4996 5018 4999 5133 4930 4860 4978 4878 4859 5046 5060 5107 4996 4968 4951 4913 4900 4884 4933 4987 4999 4920 4932 4996 4858 4984 4790 4929 5009 4952 5001 5055 5048 4995 4955 4986 5127 5075 4968 5029 4901 5048 5039 5114 5038 5015 5048 5099 4995 4984 5037 5126 5094 4994 5099 5046 5114 5038 5113 5094 5096 5105 5083 5110 5109 5041 5125 5062 5019 4998 4952 4847 4835 4805 4859 4720 4857 4889 4608 4796 4969 4696 4708 4746 4831 4829 4871 4902 4794 4736 4799 4826 4748 4818 4772 4758 4770 4747 4758 4850 4831 4830 4752 4838 4822 4752 4768 4765 4779 4605 4651 4803 4804 4822 4856 4624 4913 4594 4788 4861 4809 4812 4959 4926 4922 4940 5064 4875 4818 4811 4830 4755 4699 4751 4574 4675 4623 4674 4540 4634 4655 4676 4777 4635 4610 4570 4591 4566 4577 4476 4682 4597 4643 4636 4497 4657 4625 4593 4729 4735 4751 4813 4863 4921 4851 4713 4619 4583 4809 4501 4595 4594 4503 4545 4487 4583 4535 4593 4498 4441 4576 4568 4585 4501 4520 4492 4376 4414 4466 4439 4370 4467 4457 4453 4491 4490 4338 4448 4553 4489 4444 4449 4367 4371 4429 4406 4596 4524 4480 4408 4381 4340 4439 4493 4493 4410 4507 4417 4461 4478 4498 4535 4530 4513 4565 4550 4526 4527 4488 4601 4418 4572 4451 4481 4489 4431 4325 4438 4323 4408 4327 4325 4423 4365 4316 4459 4314 4308 4317 4369 4362 4342 4292 4276 4483 4295 4566 4478 4497 4590 4760 4632 4649 4641 4687 4790 4701 4737 4765 4735 4647 4774 4767 4748 4706 4555 4761 4600 4697 4742 4763 4803 4822 4795 4780 4769 4825 4939 5035 5176 5129 5388 5507 5531 5840 6010 6353 6608 7212 7915 9088 10906 14073 18492 25920 37595 55120 79490 103051 118887 121230 113354 101752 89787 73183 54671 38638 27280 19486 14424 10841 8735 7444 6575 6217 5855 5664 5441 5268 5123 4907 4981 4761 4710 4757 4716 4520 4723 4592 4624 4479 4570 4541 4609 4837 4704 4815 4908 4833 4860 4707 4619 4616 4562 4576 4460 4455 4353 4237 4316 4402 4232 4272 4308 4335 4207 4324 4264 4249 4331 4310 4237 4282 4286 4210 4211 4230 4178 4278 4165 4227 4350 4215 4278 4218 4193 4226 4294 4169 4284 4180 4168 4179 4134 4088 4151 4089 4151 4164 4281 4089 4083 4103 4016 4132 4097 4075 4120 4151 4035 4097 3993 3991 3966 4003 4024 4140 4135 4142 4143 4054 4066 3972 4168 4068 4124 4032 4171 3971 4103 4149 4060 4049 4080 3914 4068 3934 4084 3995 3897 3946 4005 3907 4093 3956 3929 3981 3907 3928 3916 3885 3897 3979 3913 4032 3985 4013 4067 3998 4127 3999 4136 3953 4008 4042 4033 4134 3962 4052 4108 4316 4311 4258 4320 4362 4266 4245 4127 4234 4273 4197 4035 4055 3995 4093 4085 4046 4143 4085 4115 3979 4052 4017 4053 4017 4062 4088 4033 3993 4032 4211 4151 4312 4469 4597 4932 5508 6126 7348 9376 12206 16042 19455 19762 18496 16619 16084 15204 12200 9568 7760 6611 5609 4856 4331 4438 4229 4104 4131 4007 4000 3997 3852 3890 3977 4015 3983 3980 3935 3967 3892 4020 3894 4058 4013 3883 3931 3967 3893 3960 4066 3844 3898 3927 3809 3813 3836 3774 3792 3861 3786 3791 3881 3844 3657 3780 3849 3854 3684 3803 3921 3689 3711 3774 3714 3765 3745 3775 3804 3732 3770 3795 3765 3781 3735 3791 3847 3843 3909 3784 3775 3830 3917 3897 3839 3896 3877 3878 3913 3732 3882 3871 3916 3922 3892 3920 3896 3957 3990 3936 3923 3950 4005 3984 4012 4028 3941 4011 4062 3895 3996 4036 3933 3984 4041 4103 4059 4153 4201 4191 4226 4213 4509 4584 4514 4492 4631 4714 4716 4746 4830 4992 5217 5445 5778 6555 7904 10201 14527 20560 27348 36049 43527 46244 43577 38854 34828 31971 27751 22245 17405 14145 12709 13158 15938 22212 30955 39414 44233 48310 48553 46035 40726 35443 30924 24639 18971 14493 10839 8198 6452 5560 4924 4782 4674 4523 4329 4239 4266 4103 3996 3993 4023 4066 3842 3944 3865 3837 3668 3786 3812 3924 3880 3864 3846 3838 3841 3808 3713 3817 3905 3886 3888 3924 4002 3964 3965 3872 3827 3841 3672 3771 3663 3614 3724 3698 3612 3576 3688 3698 3648 3672 3731 3713 3621 3657 3683 3690 3719 3784 3697 3614 3611 3546 3757 3781 3683 3556 3742 3548 3679 3626 3593 3666 3524 3551 3602 3637 3695 3578 3540 3655 3525 3622 3595 3597 3580 3532 3498 3409 3508 3484 3534 3463 3585 3587 3555 3598 3589 3556 3573 3529 3503 3618 3562 3593 3579 3652 3595 3622 3737 3723 3764 3785 4009 4043 4147 4006 4001 3930 3900 3857 3756 3880 3631 3589 3666 3602 3576 3476 3596 3609 3495 3626 3581 3394 3494 3519 3527 3509 3593 3609 3583 3597 3415 3540 3414 3502 3487 3624 3504 3490 3578 3599 3485 3493 3419 3504 3382 3472 3515 3386 3411 3363 3395 3526 3408 3340 3492 3439 3565 3631 3692 3626 3674 3669 3716 3650 3614 3675 3810 3635 3644 3682 3722 3726 3744 3634 3689 3695 3695 3806 3662 3673 3646 3647 3740 3773 3600 3804 3625 3657 3695 3755 3598 3655 3687 3617 3654 3717 3723 3631 3708 3779 3824 3964 3841 3827 3893 4012 4032 4116 4152 4347 4483 4481 4649 4968 4956 5323 5589 5938 6453 7124 7904 9137 11169 14380 19790 29626 44174 61092 75190 82779 80224 71350 64274 58157 53721 46562 38447 28776 20699 14924 10837 8496 7226 6358 5749 5490 4919 4703 4461 4362 4213 4072 3968 3853 3780 3845 3703 3737 3822 3803 3635 3623 3585 3652 3618 3732 3790 3661 3853 3783 3862 3899 3953 3918 4004 3920 3900 3822 3874 3779 3765 3745 3669 3683 3707 3557 3610 3596 3598 3634 3604 3594 3602 3673 3610 3514 3586 3509 3489 3480 3464 3474 3516 3594 3492 3474 3607 3517 3614 3491 3495 3506 3622 3513 3480 3550 3556 3646 3648 3488 3531 3557 3619 3687 3735 3741 3738 3819 3978 4026 4150 4090 4178 4374 4534 4693 4809 5078 5597 6465 8426 11958 17207 24328 30688 33940 32697 28699 25682 24375 23906 22615 19728 16601 14739 14467 15523 17020 19027 19501 18745 17039 15324 13735 12636 11603 10225 8515 7077 5781 4808 4366 4084 4015 3862 3670 3689 3604 3491 3547 3525 3412 3454 3423 3476 3420 3343 3308 3372 3365 3397 3321 3412 3475 3397 3372 3412 3417 3355 3490 3395 3392 3383 3313 3248 3189 3309 3388 3322 3314 3347 3382 3335 3415 3307 3196 3363 3236 3266 3273 3393 3358 3346 3335 3366 3381 3239 3226 3220 3236 3263 3321 3294 3228 3254 3321 3280 3230 3319 3268 3398 3251 3301 3305 3196 3241 3230 3111 3140 3138 3324 3242 3220 3133 3101 3184 3162 3060 3166 3243 3186 3214 3005 3207 3198 3093 3206 3179 3340 3046 3144 3305 3145 3166 3210 3173 3178 3221 3121 3077 3267 3116 3185 3194 3250 3156 3219 3214 3225 3197 3129 3174 3160 3145 3096 3232 3171 3060 3197 3259 3178 3119 3141 3035 3054 3082 3125 3172 3113 3093 3109 3104 3133 3068 3165 3016 3126 3188 3055 3085 3109 3068 3166 3037 3048 3026 3188 3207 3069 3119 3112 3134 3111 3010 2963 3109 3184 3071 3063 3133 3075 3117 3060 3085 3149 3116 3119 3111 3132 3134 3146 3110 3136 3044 3183 3092 3078 3154 3097 3102 3087 3141 3070 3187 3182 3172 3198 3135 3155 3262 3301 3167 3272 3116 3265 3283 3297 3193 3280 3283 3150 3170 3217 3107 3277 3150 3337 3273 3240 3274 3226 3434 3364 3351 3436 3489 3496 3601 3546 3627 3757 3732 3807 4005 4324 4693 5507 7368 10779 15788 20924 22427 19788 15586 13304 12528 13434 13969 12621 10189 7894 6331 5183 4592 4322 3941 3856 3817 3722 3700 3868 3813 3821 3944 3981 4120 4178 4235 4380 4429 4617 4943 5562 6614 8535 12044 17703 24995 32369 36366 34283 28999 24526 22721 21781 22035 20698 18116 14147 10915 8543 6581 5586 5061 4631 4468 4286 4213 4108 4160 4241 4372 4326 4390 4644 4726 5014 5309 5912 6831 8305 10913 14613 18862 23626 27383 30078 30101 27742 26122 25455 27008 29731 30136 27288 22320 17353 14808 13262 12306 11526 9787 7879 6547 5633 4682 4219 3881 3756 3642 3572 3507 3387 3409 3416 3330 3455 3273 3326 3286 3218 3238 3179 3265 3261 3211 3200 3197 3179 3124 3109 3194 3155 3239 3144 3161 3162 3219 3227 3284 3191 3321 3219 3313 3308 3426 3459 3460 3475 3603 3558 3799 3832 4198 4862 5843 7691 10346 12947 14643 13878 11643 9734 8809 8499 9279 9072 8326 7050 5840 4714 4016 3642 3625 3372 3264 3317 3267 3230 3292 3309 3560 3637 3765 3710 3666 3433 3477 3394 3308 3351 3321 3312 3225 3197 3081 3035 3046 3094 3024 2984 2951 2965 2927 2986 3004 3051 2956 2931 2979 2915 2903 2936 3006 3001 2926 2990 2900 2929 2928 2895 3018 2976 2851 2978 2922 2874 2903 2909 2901 2974 2906 2880 2967 2942 2874 2862 2880 3034 2942 2856 2910 2924 2753 2965 2865 2906 3017 2880 2807 2828 2909 2760 2927 2948 2867 2932 2961 2939 2923 3036 3071 3070 3027 3072 3018 3001 3077 3011 3059 3015 2966 3024 2982 2951 2912 2931 2946 2933 2870 2923 2963 2984 2876 2835 2863 2851 2919 3032 2865 2919 3007 3030 3079 3013 2995 3156 3103 3081 3177 3263 3344 3476 3794 4370 5596 7212 8867 9866 9987 8794 7419 6313 5976 6311 6671 6559 6069 5258 4367 3740 3448 3171 3240 3186 3078 3000 3025 3075 3015 2945 2966 2989 2797 2884 3007 3023 2984 2922 2912 2884 2887 3012 2866 2922 2990 2965 3070 3066 3132 3008 3092 3172 3124 3208 3474 3514 3690 4221 4856 5969 7375 8775 9597 10044 9720 8833 8102 7279 7026 6757 6721 6628 6047 5263 4626 4036 3582 3395 3335 3149 3142 3228 3353 3480 3709 3844 3715 3564 3357 3318 3227 3323 3471 3342 3307 3110 3054 2999 2951 2830 2717 2879 2756 2822 2747 2767 2846 2744 2670 2790 2663 2757 2864 2769 2773 2721 2727 2751 2798 2795 2740 2701 2670 2667 2746 2740 2813 2688 2727 2803 2677 2698 2761 2685 2784 2711 2762 2737 2849 2742 2690 2754 2748 2695 2825 2785 2778 2736 2779 2738 2698 2768 2756 2737 2750 2759 2808 2773 2752 2816 2774 2804 2777 2786 2786 2780 2821 2718 2716 2806 2674 2717 2737 2731 2777 2642 2862 2674 2721 2720 2779 2785 2803 2758 2792 2846 2745 2747 2829 2781 2783 2781 2750 2831 2760 2805 2835 2685 2711 2734 2691 2680 2762 2701 2764 2703 2784 2676 2719 2737 2708 2767 2729 2738 2740 2766 2672 2753 2735 2740 2737 2830 2813 2716 2691 2757 2753 2884 2927 2859 2963 3048 3040 3053 3330 3591 3940 4561 4892 5255 5215 4866 4485 4294 4069 4064 4035 4207 4098 3928 3693 3469 3241 3259 3227 3108 3112 3294 3339 3601 3776 4503 5634 6679 7583 7463 7182 6388 5817 5184 5238 5443 5567 5582 5227 4741 4346 3952 3728 3696 3659 3832 4524 5455 6643 8292 9691 9664 8660 7415 6249 5591 5713 6178 6533 6358 6087 5147 4288 3755 3525 3332 3163 3054 3032 2990 2873 2879 3040 2927 2890 2827 2861 2842 2959 2837 2807 2868 3027 2895 2923 3031 2971 3020 3141 3271 3192 3224 3317 3479 3691 3825 4304 4873 5658 6682 8167 9855 11067 11516 10767 9454 8221 7764 7713 8539 9817 11907 13649 14845 14836 13427 11395 9922 8537 8589 9976 11747 14058 15720 15970 14873 12800 9999 8264 7267 7163 7536 7913 7834 7044 6022 4905 4059 3693 3497 3150 3081 2973 3018 2871 2823 2816 2903 2916 2984 2736 2775 2785 2788 2734 2800 2742 2728 2777 2789 2763 2673 2780 2696 2732 2729 2778 2724 2743 2683 2680 2616 2714 2667 2637 2534 2600 2686 2646 2720 2647 2633 2613 2738 2681 2652 2712 2704 2669 2696 2670 2606 2695 2692 2688 2617 2596 2732 2733 2723 2675 2594 2625 2680 2666 2695 2764 2669 2659 2723 2621 2634 2691 2629 2635 2677 2674 2680 2623 2604 2706 2627 2649 2623 2588 2706 2694 2700 2666 2629 2683 2634 2741 2721 2621 2704 2617 2703 2736 2691 2730 2699 2726 2733 2714 2732 2805 2779 2683 2614 2636 2743 2784 2606 2674 2754 2792 2641 2582 2597 2629 2677 2664 2563 2587 2752 2636 2679 2636 2677 2714 2754 2555 2675 2660 2657 2691 2792 2734 2661 2654 2842 2830 2915 3093 3232 3431 3582 3527 3229 3136 3084 3002 3049 3066 3095 3033 3055 2926 2801 2708 2834 2683 2745 2617 2616 2587 2652 2618 2634 2747 2639 2586 2680 2683 2742 2641 2700 2580 2490 2629 2668 2703 2608 2575 2521 2631 2615 2610 2655 2625 2682 2692 2630 2627 2702 2704 2801 2787 2823 2901 3009 3218 3250 3407 3576 3782 4113 4009 3655 3364 3286 3144 3170 3165 3398 3346 3215 3063 3037 2862 2878 2754 2751 2914 2793 2980 2950 2947 3086 3296 3650 4041 4462 5100 5628 5717 5679 5244 4747 4296 4010 3963 4256 4290 4218 4099 3828 3525 3202 3098 2918 2814 2825 2770 2752 2718 2699 2696 2690 2703 2690 2619 2684 2614 2660 2560 2552 2731 2598 2552 2675 2616 2571 2749 2546 2612 2737 2563 2628 2576 2688 2583 2695 2685 2654 2654 2641 2634 2677 2546 2604 2566 2732 2676 2682 2717 2778 2851 2779 2730 2789 2781 2836 2861 2858 2846 2938 3024 3009 3014 3291 3476 3876 4706 5783 8243 10612 11894 11790 9807 7537 5900 5093 5076 5764 6781 7424 7227 6484 5236 4349 3810 3335 3121 3049 2818 2841 2760 2734 2755 2770 2741 2721 2780 2649 2715 2683 2709 2709 2764 2866 2787 2758 2766 2831 2831 2782 2795 2934 3040 3147 3416 3939 4604 5889 7246 7492 7125 5865 4848 4239 3894 4026 4293 4852 5142 5117 4690 4071 3517 3194 3106 2939 2954 2898 2726 2792 2802 2779 2775 2753 2699 2747 2728 2645 2694 2760 2737 2777 2665 2726 2745 2774 2816 2695 2674 2723 2782 2698 2813 2800 2699 2834 2832 2962 2854 2841 2903 2890 3065 2942 3156 3207 3255 3518 3814 4389 5012 5995 6858 7941 8422 8891 8472 7414 6126 5363 5113 5202 5429 5767 5988 5897 5419 4619 4014 3579 3348 3223 3256 3009 3075 2891 2918 2968 2985 3045 3023 3145 3104 3145 3133 3197 3364 3364 3355 3522 3624 3588 3747 3876 3877 4348 4794 5237 5914 7113 8974 11518 14627 18097 19924 19922 17778 14637 12100 10686 9651 9901 10949 12083 12241 11595 9935 8272 6749 5625 4907 4347 4111 3706 3646 3574 3395 3355 3306 3234 3311 3275 3252 3269 3224 3351 3342 3425 3490 3641 3952 4324 5127 6255 8164 10032 12173 12667 12813 12931 12775 12743 11800 10931 10381 9931 9286 8880 8420 8309 8162 7756 7123 6266 5620 4935 4390 3959 3832 3990 4195 4483 5033 6354 8061 10269 12194 13385 12813 11146 8816 7281 6321 6137 6338 7218 8031 8262 7807 6723 5725 4706 4116 3823 3488 3226 3171 3095 2999 3061 3026 2948 3040 2850 2973 2836 2879 2883 2877 2799 2842 2904 2774 2827 2862 2852 2745 2771 2788 2993 3043 3185 3427 3407 3510 3430 3296 3234 3105 3193 3207 3303 3239 3358 3322 3206 3247 3345 3293 3314 3350 3287 3136 3217 3131 3202 3159 3238 3141 3233 3333 3329 3343 3440 3388 3409 3448 3628 3573 3779 3989 4233 4781 5466 6731 8556 11317 14738 17840 19302 18314 16225 13384 11283 9798 9627 10434 11633 12940 12901 11996 10503 8813 7388 6228 5503 5002 4810 4484 4249 3997 3802 3692 3540 3345 3348 3301 3327 3404 3206 3335 3379 3507 3592 3743 3972 4259 4797 5680 6577 7788 9242 10281 11194 11402 10368 8851 7404 6631 6359 6295 6559 6959 7226 7275 6795 5888 5097 4411 4109 3687 3505 3287 3190 3013 2925 3055 2963 2829 2808 2908 2840 2787 2759 2802 2888 2798 2785 2717 2770 2765 2670 2776 2735 2708 2689 2804 2709 2778 2844 2870 2815 2929 2846 2928 2960 3035 2894 2928 2849 3063 3058 3134 3280 3449 3785 4036 4595 5540 6688 8265 9170 8867 7978 6501 5242 4594 4277 4546 4810 5505 6072 6126 5678 5112 4431 4079 3979 3753 3821 3689 3632 3307 3045 2927 3004 3063 3079 3126 3193 3139 3108 2992 2983 2941 2763 2799 2753 2821 2843 2871 2768 2714 2683 2790 2775 2761 2697 2697 2658 2720 2705 2704 2799 2655 2676 2777 2672 2673 2852 2806 2823 2828 2942 2872 2916 2835 2939 2994 2860 3071 3107 3044 3237 3282 3503 3764 4189 5035 6036 7335 8747 9744 10273 10849 10504 9829 8835 7330 6137 5989 5917 6220 6640 6839 6906 6657 6274 5249 4661 3964 3497 3298 3229 3058 3069 3048 3078 3206 3263 3434 3638 4025 4315 4821 5418 5531 5625 5697 5777 5637 5366 5081 4621 4311 4253 4147 4186 4361 4275 4062 4106 3836 3604 3206 3109 2928 2898 2857 2839 2776 2698 2689 2690 2679 2648 2707 2674 2684 2761 2841 2802 3049 3058 3314 3592 3781 4087 4435 4407 4223 3871 3666 3489 3207 3240 3358 3391 3613 3676 3710 3593 3343 3159 3009 2876 2858 2700 2740 2756 2719 2768 2733 2834 2680 2599 2682 2614 2766 2546 2636 2673 2538 2707 2691 2639 2646 2572 2663 2693 2644 2587 2589 2631 2619 2550 2586 2541 2611 2616 2552 2566 2701 2763 2587 2704 2659 2753 2727 2780 2888 2990 2908 2895 3126 2999 2979 2993 2983 2956 2931 2881 2780 2803 2750 2802 2712 2769 2769 2639 2756 2787 2746 2701 2584 2580 2644 2600 2710 2718 2632 2606 2708 2576 2564 2642 2580 2605 2566 2574 2596 2596 2510 2694 2517 2610 2511 2617 2557 2590 2615 2501 2690 2647 2584 2660 2653 2692 2648 2692 2640 2697 2640 2717 2739 2773 2706 2749 2748 2817 2818 3009 3000 2916 2965 3058 3074 3197 3357 3397 3517 3959 4274 4928 5638 7018 8511 10214 11529 11684 10730 9293 7839 6568 5872 5627 5756 6319 6799 7485 7608 7531 6660 5858 5007 4382 3858 3775 3535 3573 3431 3512 3582 3690 3638 3569 3450 3191 2984 2929 2945 2929 2995 2958 3129 3088 3159 3207 3150 2980 3052 2866 2970 2908 2871 2957 2927 3125 3176 3125 3232 3337 3542 3823 4110 4696 5784 7268 8775 10105 11113 11892 11644 11326 10182 9388 8669 8184 7667 7652 7907 8521 9203 9543 9438 8813 8012 7072 6192 5594 4863 4394 4159 4085 4013 4006 4125 4021 3728 3424 3328 3233 3129 3082 3090 2980 2849 2832 2830 2755 2870 2953 2840 2974 2990 3052 3161 3036 3078 3045 3166 3101 3228 3367 3430 3683 3925 4272 4876 5602 6461 7291 7929 8592 9266 9494 9894 10116 9859 9636 8862 8008 7451 6949 7070 7353 7873 8363 8889 9464 9698 9395 8594 7179 6067 5225 4702 4380 4343 4400 4638 4720 4920 4810 4643 4150 3850 3590 3387 3238 3224 3145 3246 2985 2993 3108 3016 3112 3053 3056 3081 3211 3255 3333 3602 3803 4007 4500 5233 6213 7424 8559 8651 8229 7145 6002 5332 4838 4525 4715 4788 5430 6075 6576 6772 6453 5824 5028 4495 4156 4026 3973 3975 3921 4033 3877 3689 3510 3329 3328 3211 3169 3176 3296 3214 3295 3184 3152 3218 3024 3002 2946 3034 3070 3099 3137 3321 3388 3453 3587 3986 4296 4766 5285 5943 6592 7438 8011 8353 8199 7711 7267 6236 5789 5557 5534 5849 6377 7180 8193 9212 10664 11262 11126 10282 8816 7116 5908 5134 4873 4798 4897 5344 5742 6339 6653 6494 6192 5784 5290 5305 5420 5972 6782 7787 8850 9323 9717 8963 7993 6919 5785 5249 5000 4888 4962 5321 5775 6133 6388 6186 5638 5030 4497 4083 3592 3290 3308 3128 3123 3160 3171 3067 3111 3108 3111 3209 3162 3195 3353 3358 3566 3953 4410 5029 5573 6393 7223 8036 8627 9363 9150 9462 9219 8605 7998 7687 7601 7702 8217 9235 10774 12917 14044 13935 12945 11300 9425 7741 6529 5678 5555 5501 5753 6238 6790 6998 6839 6299 5091 4607 4034 3700 3390 3306 3138 3118 3006 2860 2971 2978 2829 2851 2740 2857 2863 2795 2893 2814 2844 2820 2892 2798 2867 2855 2858 2859 2977 2890 2967 2992 3091 3117 3158 3160 3269 3361 3476 3579 4066 4377 4985 5811 6821 8301 9329 10354 10391 9881 9391 8937 8832 9256 9510 9950 9767 9818 9617 8980 8622 8055 7510 7147 7019 7401 7313 7807 7415 7339 6858 6521 6038 5488 5250 5079 4909 4969 5256 5331 5679 5726 5832 5700 5431 5201 4772 4408 3908 3766 3694 3676 3646 3776 3770 3738 3755 3769 3452 3238 3063 2925 2804 2655 2836 2679 2634 2656 2597 2573 2650 2662 2532 2514 2554 2532 2645 2587 2581 2447 2583 2500 2505 2598 2471 2544 2541 2488 2489 2565 2491 2522 2458 2561 2518 2486 2514 2470 2521 2449 2506 2479 2561 2503 2472 2520 2546 2510 2419 2534 2512 2503 2546 2530 2461 2488 2495 2438 2526 2496 2437 2344 2472 2418 2465 2425 2501 2540 2475 2555 2436 2584 2535 2614 2630 2589 2647 2504 2469 2394 2428 2478 2445 2423 2520 2524 2439 2577 2483 2586 2507 2412 2443 2490 2438 2403 2387 2487 2366 2463 2524 2467 2509 2524 2428 2285 2502 2413 2379 2307 2528 2344 2388 2545 2438 2460 2418 2441 2379 2383 2478 2456 2405 2384 2407 2441 2343 2372 2327 2431 2378 2434 2449 2436 2451 2463 2527 2388 2440 2438 2520 2428 2441 2423 2511 2468 2429 2298 2321 2351 2457 2475 2475 2465 2588 2480 2612 2625 2632 2747 2704 2817 2967 2881 2949 2956 3277 3222 3431 3646 3894 4070 4117 3829 3592 3331 3180 3107 2931 2938 2930 2961 3100 3290 3259 3281 3301 3196 3027 2994 2774 2653 2618 2771 2647 2633 2645 2583 2669 2749 2806 2965 2931 3065 3280 3566 3845 4208 4574 4942 5197 5219 5060 4966 4747 4481 4162 3910 3623 3597 3572 3647 3774 3818 3861 3846 3729 3683 3487 3353 3193 2902 2801 2657 2621 2540 2556 2467 2580 2555 2495 2448 2518 2392 2410 2344 2383 2441 2410 2355 2430 2409 2431 2401 2392 2405 2407 2371 2426 2380 2469 2446 2473 2414 2494 2577 2544 2571 2592 2596 2509 2630 2680 2523 2546 2651 2750 2661 2596 2716 2700 2661 2718 2728 2688 2609 2676 2646 2556 2552 2562 2502 2496 2443 2467 2447 2475 2519 2466 2608 2430 2591 2417 2385 2383 2393 2392 2429 2411 2353 2428 2443 2342 2337 2357 2383 2289 2313 2301 2359 2286 2381 2419 2360 2354 2404 2493 2379 2333 2379 2393 2413 2408 2392 2389 2374 2315 2402 2434 2399 2367 2383 2341 2306 2332 2425 2374 2322 2338 2427 2308 2381 2347 2411 2397 2344 2289 2319 2404 2371 2313 2339 2271 2376 2383 2313 2319 2394 2381 2402 2411 2368 2309 2339 2313 2383 2413 2371 2375 2412 2287 2359 2359 2365 2350 2376 2573 2544 2440 2437 2556 2460 2475 2405 2327 2402 2370 2429 2421 2538 2489 2476 2565 2591 2481 2591 2551 2612 2386 2511 2422 2385 2456 2418 2471 2468 2485 2449 2465 2435 2495 2487 2438 2439 2418 2300 2348 2319 2288 2303 2425 2301 2313 2307 2357 2332 2412 2324 2276 2342 2317 2339 2277 2358 2422 2335 2367 2280 2398 2167 2284 2433 2289 2261 2263 2382 2379 2307 2288 2376 2372 2421 2447 2390 2381 2317 2400 2438 2367 2397 2357 2326 2422 2381 2335 2364 2292 2329 2339 2331 2377 2425 2379 2274 2390 2451 2382 2438 2340 2372 2379 2459 2431 2411 2477 2443 2525 2675 2711 2872 3049 3301 3511 3628 3695 3474 3118 2990 2740 2686 2697 2595 2650 2692 2879 2776 2988 3043 3117 3127 3182 2931 2920 2873 2905 2858 2899 2867 2727 2791 2796 2664 2733 2702 2833 2753 2770 2746 2675 2820 2632 2786 2679 2711 2682 2618 2658 2747 2705 2844 2868 3032 3268 3564 4135 4589 5093 5233 5168 4553 3950 3472 3073 2909 2894 2871 2786 2873 3078 3275 3503 3895 3936 3624 3613 3233 2980 2865 2700 2677 2618 2537 2497 2591 2466 2571 2472 2647 2632 2681 2582 2856 2881 2943 3302 3634 3769 3947 3860 3487 3360 3054 2936 2838 2743 2802 2795 2942 3039 3118 3373 3379 3622 3857 3858 3744 3742 3905 3839 3795 3717 3791 3725 3542 3326 3312 3197 3162 3079 3128 3236 3300 3223 3310 3393 3403 3476 3614 3775 4027 4271 4743 5424 5979 6585 7100 7489 7279 6499 5530 4922 4346 4066 3875 3776 3924 4254 4645 4918 5559 5856 6295 6284 6123 5506 4940 4524 4100 3853 3557 3392 3424 3358 3472 3501 3719 3732 3827 3891 3817 3710 3530 3629 3600 3780 3921 4358 4708 4982 5195 4962 4742 4541 4033 3673 3385 3286 3291 3297 3428 3640 3717 3793 4047 4067 3949 4001 3609 3380 3254 3139 3061 2976 2914 2882 2863 2911 3008 2989 2937 2918 3048 3041 3101 3196 3354 3596 3649 3838 4026 4170 4178 4369 4269 4401 4256 4066 3899 3786 3685 3563 3390 3611 3782 3948 4356 4951 5483 5995 6076 5819 5290 4495 4040 3601 3364 3152 3073 3062 3033 3075 3267 3531 3760 3800 3836 3621 3415 3190 2907 2864 2858 2806 2743 2854 2852 3038 3184 3415 3650 3758 4112 4250 3996 3660 3422 3206 3100 2994 2933 2955 2944 2952 3029 3300 3524 3621 3765 3775 3875 3783 3728 3732 3683 3601 3618 3566 3473 3377 3161 3101 2988 2975 2890 2916 2953 2983 2987 2934 2967 2999 2934 2982 2934 2700 2824 2684 2614 2615 2531 2533 2533 2517 2421 2440 2498 2532 2542 2518 2483 2531 2535 2575 2496 2575 2523 2510 2548 2533 2661 2693 2706 2763 2846 3052 3333 3616 3749 3934 4098 4134 4253 3922 3692 3519 3189 3035 2873 2829 2875 2878 3115 3078 3082 3288 3234 3299 3357 3194 3010 2966 2890 2817 2729 2554 2634 2674 2726 2729 2781 2855 3010 3187 3417 3840 3916 4102 4152 4208 4054 3836 3769 3506 3394 3250 3314 3287 3297 3213 3270 3355 3384 3503 3553 3535 3553 3311 3418 3382 3352 3504 3529 3618 3927 3896 3892 4016 4028 3946 3806 3895 3738 3598 3551 3414 3264 3055 3143 3188 3041 3264 3336 3267 3358 3363 3309 3336 3104 3090 2997 2986 2941 2794 2789 2886 3004 2953 3115 3346 3750 4015 4454 4831 5209 5371 5156 5232 5086 5282 5277 5290 5382 5165 4602 4220 3867 3851 3689 3787 3976 4027 4074 3989 3666 3793 3829 3844 3871 3732 3450 3283 2928 2817 2682 2580 2563 2541 2548 2550 2475 2415 2370 2418 2410 2380 2452 2420 2331 2420 2312 2301 2401 2365 2466 2428 2357 2410 2516 2356 2331 2465 2267 2283 2372 2294 2312 2302 2363 2303 2328 2452 2385 2348 2376 2278 2338 2444 2322 2352 2298 2338 2390 2407 2340 2346 2366 2362 2352 2305 2335 2364 2324 2339 2383 2358 2349 2375 2372 2333 2328 2321 2371 2417 2327 2287 2311 2427 2310 2358 2296 2389 2402 2322 2408 2405 2398 2424 2458 2352 2436 2404 2461 2567 2598 2548 2616 2562 2481 2476 2447 2474 2444 2468 2441 2353 2398 2480 2432 2386 2416 2607 2550 2437 2466 2505 2599 2577 2428 2468 2545 2522 2510 2636 2644 2544 2644 2783 2773 2791 2847 2885 2911 2919 2858 2896 2758 2804 2828 2862 3007 3047 3162 3200 3418 3715 3955 4227 4487 4680 4764 4828 4821 4578 4252 3978 3712 3374 3259 3240 3164 3186 3088 3158 3332 3360 3490 3541 3559 3505 3363 3356 3190 3068 2885 2896 2714 2622 2663 2627 2649 2569 2560 2619 2579 2599 2554 2525 2542 2644 2666 2503 2676 2658 2794 2866 2940 2974 3082 3373 3495 3748 4098 4258 4272 4520 4410 4426 4332 4176 3894 3713 3487 3281 3170 3059 3194 3151 3082 3283 3374 3313 3436 3443 3436 3311 3340 3311 3204 2977 2828 2791 2706 2609 2653 2651 2632 2650 2767 2797 2916 2904 3141 3018 3096 3085 2999 2896 2761 2678 2579 2620 2494 2480 2603 2547 2669 2629 2538 2772 2773 2793 2763 2762 2602 2571 2549 2613 2659 2494 2600 2745 2765 2686 2816 2906 3062 2830 2920 2697 2596 2593 2532 2509 2603 2570 2514 2551 2528 2672 2664 2653 2667 2796 2781 2763 2822 2763 2733 2926 2956 3053 3303 3274 3271 3408 3570 3420 3505 3445 3498 3527 3494 3342 3342 3177 3039 2967 3074 3026 3039 3157 3285 3240 3246 3398 3363 3401 3348 3428 3436 3634 3676 3671 3584 3652 3538 3633 3785 3854 3902 4150 4000 4043 3924 3872 3811 3775 3905 3927 3905 3993 4106 4155 4210 4140 4118 4050 4125 3924 3886 3650 3506 3401 3221 3270 3164 3154 3175 3167 3190 3266 3089 3131 3172 3190 3083 3163 3187 3130 3202 3262 3236 3540 3818 3975 4106 4158 4185 3997 3653 3573 3236 3201 2960 2911 2883 2934 2811 2970 2996 3148 3249 3353 3521 3546 3650 3384 3374 3287 3164 3132 3015 2900 2874 2678 2683 2854 2678 2662 2702 2758 2630 2691 2737 2742 2954 2863 2753 2793 3042 2894 2997 3044 3332 3367 3398 3444 3801 3776 4014 4326 4511 4642 4820 4813 5080 5213 5533 5768 6140 6402 6482 6489 6263 5940 5636 5298 5210 5087 5153 5037 4945 4920 5123 5244 5422 5886 5882 5774 5636 5596 5313 5131 5003 4951 4882 4880 4836 4712 4543 4026 4173 3813 3882 3854 3656 3620 3499 3394 3340 3313 3329 3278 3511 3560 3717 3663 3788 3684 3711 3671 3601 3585 3510 3548 3335 3281 3253 3333 3304 3362 3255 3336 3513 3391 3532 3544 3583 3698 3754 3504 3529 3528 3397 3353 3152 2963 2966 2841 2903 2812 2888 2829 2826 2845 2940 2887 2799 2802 2863 2710 2730 2707 2614 2585 2568 2551 2422 2465 2470 2495 2659 2573 2460 2553 2468 2490 2612 2477 2502 2529 2458 2495 2415 2455 2656 2524 2435 2532 2541 2651 2552 2532 2530 2634 2650 2804 2747 2734 2847 2911 3146 3210 3350 3633 3801 3903 4013 4309 4282 4299 4339 4199 4121 3965 3638 3387 3180 3171 3033 3037 3025 3102 3034 3159 3244 3269 3300 3315 3460 3437 3313 3324 3180 3236 3078 3104 3242 3515 3672 3809 3751 3714 3481 3237 2980 2922 2792 2702 2633 2596 2695 2647 2699 2720 2775 2817 2880 3005 3078 3208 3082 2878 2821 2621 2661 2553 2463 2469 2435 2465 2485 2507 2520 2374 2424 2362 2439 2410 2393 2347 2455 2494 2488 2480 2452 2465 2414 2417 2531 2383 2378 2390 2453 2506 2419 2427 2531 2537 2481 2588 2533 2664 2704 2706 2575 2655 2746 2568 2732 2883 2705 2574 2604 2680 2628 2564 2640 2719 2751 2727 2868 2708 2823 2834 2936 3035 3286 3317 3464 3405 3453 3331 3193 3066 2801 2798 2678 2669 2632 2590 2490 2592 2566 2671 2623 2744 2751 2807 2834 2853 2835 2765 2622 2557 2525 2584 2376 2410 2425 2429 2336 2449 2384 2413 2429 2395 2464 2378 2373 2320 2429 2412 2406 2398 2409 2395 2474 2490 2423 2537 2508 2529 2462 2480 2506 2501 2531 2476 2448 2448 2375 2460 2383 2321 2303 2353 2338 2459 2413 2445 2448 2500 2427 2449 2366 2364 2495 2453 2402 2455 2478 2403 2446 2528 2545 2566 2443 2384 2385 2347 2432 2358 2394 2400 2405 2408 2456 2304 2422 2387 2413 2387 2490 2321 2383 2401 2486 2453 2487 2501 2473 2482 2504 2519 2648 2670 2766 2830 2737 2823 2851 2960 2899 2905 3059 2906 3003 3112 3089 2927 2926 3040 2945 2909 3013 2949 3049 3271 3366 3530 3599 3800 3928 4035 4040 3995 4099 4009 4069 3957 3799 3652 3530 3620 3513 3359 3310 3416 3395 3549 3455 3524 3597 3547 3418 3476 3373 3227 3222 3114 3011 3035 2967 2814 2759 2870 2686 2810 2643 2668 2707 2604 2665 2489 2574 2505 2495 2460 2526 2522 2541 2396 2419 2532 2474 2496 2456 2461 2402 2461 2480 2462 2517 2613 2622 2682 2659 2896 2939 2904 3096 3020 3107 2858 2757 2811 2696 2700 2682 2599 2571 2527 2616 2489 2595 2518 2648 2692 2611 2726 2811 2907 2857 2769 2690 2680 2681 2679 2809 2793 2903 2925 3012 3040 3301 3265 3258 3234 3256 3152 3029 2925 2803 2795 2818 2684 2709 2708 2581 2766 2780 2890 2919 2935 3134 3174 3289 3250 3151 3017 2875 2786 2804 2739 2684 2612 2604 2652 2540 2687 2548 2710 2717 2692 2768 2841 2887 3070 3077 3058 3141 3283 3347 3366 3371 3306 3145 3107 2991 2860 2879 2743 2713 2724 2696 2725 2699 2745 2854 2944 3111 3098 3249 3466 3642 3535 3954 3875 3942 3921 3560 3409 3353 3060 3082 2996 2856 2839 2882 2925 2910 2934 2873 3039 2990 2980 3018 3059 3094 2970 2929 2961 2964 2845 2931 2825 2802 2687 2765 2738 2863 2848 2997 2898 3069 3053 3191 3262 3393 3629 3612 3661 3792 3875 3882 3880 3670 3560 3431 3047 2919 2993 2867 2863 2782 2861 2798 2756 2924 2877 2980 3006 2931 3098 3071 3032 3083 3108 3052 2966 2864 2700 2646 2599 2603 2513 2592 2582 2534 2656 2624 2647 2743 2807 3002 3027 3030 3187 3199 3246 3201 3236 3109 3023 2898 2676 2770 2662 2509 2626 2544 2617 2615 2585 2549 2547 2694 2810 2880 2957 2858 3020 2895 2802 2688 2632 2645 2480 2591 2487 2650 2340 2408 2410 2474 2476 2386 2453 2535 2631 2534 2593 2732 2679 2806 2832 2974 3103 3240 3343 3540 3596 3846 3759 3675 3349 3077 3036 2882 2770 2638 2662 2665 2753 2631 2708 2707 2827 2825 2769 2883 2932 3142 3133 3174 3203 3209 3164 3049 3062 2947 3113 3131 3188 3343 3273 3325 3277 3203 3053 2997 3035 3071 3033 3137 3028 3034 3049 2990 2991 2900 3007 2978 3035 3024 3052 3256 3161 3133 3070 3071 3131 3040 3052 3017 3036 2994 3009 3062 2901 3038 2891 3028 2938 2972 2861 2885 2948 3000 3096 3352 3471 3377 3373 3232 3208 2966 2901 2769 2803 2740 2726 2727 2743 2732 2689 2732 2818 2863 2800 2992 2898 2996 3027 3211 3253 3298 3328 3328 3589 3562 3743 3894 3928 3886 3894 3757 3847 3814 3723 3797 3623 3579 3442 3221 3136 3026 3021 2956 3029 2936 3079 3016 3184 3118 3240 3348 3458 3371 3362 3419 3536 3472 3561 3670 3790 3908 3925 3911 3802 3659 3505 3289 3016 3067 3002 2880 2831 3007 2879 3010 2921 3034 3052 3197 3149 3273 3244 3350 3235 3451 3253 3243 3181 3001 3031 2975 2930 3021 2866 2894 2844 2782 2701 2761 2690 2741 2737 2672 2668 2632 2622 2523 2624 2503 2549 2670 2603 2608 2594 2739 2673 2705 2775 2736 2841 2830 2839 2819 2866 2774 2760 2781 2771 2846 2819 2853 2780 2817 2758 2746 2939 2822 2944 2954 2891 3000 3122 3066 3195 3239 3279 3328 3462 3789 3734 3801 3722 3622 3527 3505 3194 3064 2987 2881 2927 2691 2795 2818 2635 2798 2693 2696 2767 2842 2899 2951 3097 2926 3066 3077 3004 2817 2831 2747 2667 2612 2600 2458 2517 2402 2409 2419 2394 2454 2392 2478 2459 2452 2408 2283 2357 2397 2405 2458 2359 2379 2328 2297 2383 2342 2341 2400 2400 2285 2367 2273 2342 2284 2304 2381 2328 2417 2326 2346 2342 2339 2336 2308 2373 2362 2329 2389 2416 2398 2361 2388 2418 2410 2488 2527 2437 2574 2623 2768 2769 2902 3022 3248 3282 3123 3162 3104 2989 2880 2921 2863 2827 2865 2818 2775 2858 2805 2799 2882 2844 2742 2823 2919 2973 2796 2939 2949 2843 2856 2796 2717 2701 2712 2726 2661 2609 2590 2725 2674 2615 2647 2636 2732 2657 2752 2714 2784 2767 2878 2811 2979 3080 3204 3353 3350 3521 3507 3489 3504 3296 3211 3345 3118 2981 3011 2925 2876 2821 2763 2700 2864 2662 2815 2578 2712 2671 2832 2882 2878 2948 2909 2865 2811 2893 2763 2601 2642 2582 2598 2568 2575 2561 2598 2473 2488 2424 2346 2401 2393 2321 2293 2335 2318 2287 2266 2376 2390 2406 2279 2259 2353 2337 2307 2413 2325 2330 2367 2415 2359 2364 2290 2376 2278 2316 2344 2343 2345 2430 2347 2354 2288 2357 2270 2376 2330 2377 2342 2292 2294 2239 2300 2361 2235 2378 2347 2336 2345 2339 2336 2335 2330 2216 2428 2352 2369 2351 2324 2286 2461 2340 2262 2380 2432 2478 2475 2393 2410 2376 2373 2345 2402 2494 2605 2541 2536 2503 2609 2405 2511 2490 2464 2408 2388 2513 2401 2461 2490 2428 2473 2419 2434 2431 2426 2485 2478 2530 2528 2597 2670 2644 2627 2690 2693 2751 2850 2928 2815 2938 2962 3036 3007 3103 3256 3327 3366 3568 3602 3651 3634 3485 3307 3256 3102 3061 3017 2909 2812 2861 2964 2871 2960 3028 3046 3206 3234 3318 3507 3577 3776 3736 3477 3501 3542 3332 3197 3101 3050 2822 2786 2664 2642 2656 2647 2645 2613 2730 2673 2778 2828 2773 3046 3049 3198 3158 3179 3174 3325 3203 3244 3142 3067 3225 3111 3106 3037 3135 3106 3058 3176 3110 3145 3198 3160 3097 3001 3069 2928 2818 2865 2828 2825 2815 2788 2811 2821 2638 2747 2769 2752 2778 2722 2711 2704 2757 2757 2715 2655 2617 2737 2649 2512 2534 2592 2498 2427 2391 2481 2347 2396 2375 2407 2467 2381 2375 2466 2485 2553 2453 2414 2414 2414 2416 2458 2352 2520 2449 2477 2565 2530 2530 2597 2590 2674 2616 2733 2748 2943 3039 3102 3247 3411 3559 3815 3886 3879 3847 3744 3891 3833 3883 3628 3562 3512 3529 3459 3329 3329 3395 3304 3431 3480 3484 3714 3732 4067 4249 4287 4449 4440 4476 4483 4573 4611 4688 4657 4445 4404 4337 4079 3895 3957 3665 3476 3413 3311 3348 3426 3381 3407 3432 3546 3579 3688 3795 3767 3806 3861 3995 3984 3912 4128 3973 4004 4099 4001 3917 3985 3759 3874 3732 3716 3586 3439 3541 3273 3378 3228 3135 3006 2984 2888 2983 2917 2876 3033 2881 2972 2995 3050 3005 3039 3102 3089 3239 3275 3215 3364 3472 3549 3637</intensities>
			</dataPoints>
			<nonAmbientPoints type="Temperature" unit="K">
[...]
			</nonAmbientPoints>
		</scan>
	</xrdMeasurement>
</xrdMeasurements>