File: powder_X-ray_diffraction/variable-temperature_experiments/NaTaO2F2/raw_data/140°C.xrdml
<?xml version="1.0" encoding="UTF-8"?>
<xrdMeasurements xmlns="http://www.xrdml.com/XRDMeasurement/1.7" xmlns:xsi="http://www.w3.org/2001/XMLSchema-instance" xsi:schemaLocation="http://www.xrdml.com/XRDMeasurement/1.7 http://www.xrdml.com/XRDMeasurement/1.7/XRDMeasurement.xsd" status="Completed">
	<comment>
		<entry>Configuration=XRK900, Owner=User-1, Creation date=12/01/2015 16:52:44</entry>
		<entry>Goniometer=Theta/Theta; Minimum step size 2Theta:0.0001; Minimum step size Omega:0.0001</entry>
		<entry>Sample stage=AP XRK-900 with z-axis; Minimum step size Z:0.001</entry>
		<entry>Diffractometer system=EMPYREAN</entry>
		<entry>Measurement program=C:\PANalytical\Data Collector\Programs\Gwen\NaTaO2F2\NaTaO2F2-Lent.xrdmp, Identifier={FF50B583-C5FF-42DA-A01D-A1FB659EF29A}</entry>
		<entry>Batch program=C:\PANalytical\Data Collector\Programs\Gwen\NaTaO2F2\Thermodiff-Ouail.xrdmp, Identifier={5D65A6B1-42FC-480C-9FBB-D7D88D55EA08}</entry>
	</comment>
	<sample type="To be analyzed">
		<id></id>
		<name></name>
		<preparedBy></preparedBy>
	</sample>
	<xrdMeasurement measurementType="Scan" status="Completed" sampleMode="Reflection">
		<comment>
			<entry>PHD Lower Level = 4.02 (keV), PHD Upper Level = 12.07 (keV)</entry>
		</comment>
		<usedWavelength intended="K-Alpha 1">
			<kAlpha1 unit="Angstrom">1.5405980</kAlpha1>
			<kAlpha2 unit="Angstrom">1.5444260</kAlpha2>
			<kBeta unit="Angstrom">1.3922500</kBeta>
			<ratioKAlpha2KAlpha1>0.5000</ratioKAlpha2KAlpha1>
		</usedWavelength>
		<incidentBeamPath>
			<radius unit="mm">240.00</radius>
			<xRayTube id="1010048" name="Empyrean Cu LFF HR (9430 033 7310x) DK434948">
				<tension unit="kV">45.0</tension>
				<current unit="mA">30.0</current>
				<anodeMaterial>Cu</anodeMaterial>
				<focus type="Line">
					<length unit="mm">12.0</length>
					<width unit="mm">0.4</width>
					<takeOffAngle unit="deg">6.0</takeOffAngle>
				</focus>
			</xRayTube>
			<sollerSlit id="21010001" name="Soller slits 0.02 rad.">
				<opening unit="rad">0.0200</opening>
			</sollerSlit>
			<mask id="22030010" name="Fixed mask 20 mm">
				<width unit="mm">20.00</width>
			</mask>
			<antiScatterSlit id="22010003" name="Fixed slit 1Â°" xsi:type="fixedAntiScatterSlitType">
				<height unit="mm">1.52</height>
			</antiScatterSlit>
			<divergenceSlit id="22010012" name="Programmable divergence slit" xsi:type="fixedDivergenceSlitType">
				<distanceToSample unit="mm">140.00</distanceToSample>
				<angle unit="deg">0.5</angle>
			</divergenceSlit>
		</incidentBeamPath>
		<diffractedBeamPath>
			<radius unit="mm">240.00</radius>
			<antiScatterSlit id="22090010" name="AS slit 8.0 mm (PIXcel)" xsi:type="fixedAntiScatterSlitType">
				<height unit="mm">8.00</height>
			</antiScatterSlit>
			<sollerSlit id="21010001" name="Soller slits 0.02 rad.">
				<opening unit="rad">0.0200</opening>
			</sollerSlit>
			<filter id="20030001" name="Large beta-filter Nickel">
				<material>Ni</material>
				<thickness unit="mm">0.020</thickness>
			</filter>
			<detector id="7010019" name="PIXcel1D-Medipix3 detector" xsi:type="rtmsDetectorType">
				<phd unit="%">
					<lowerLevel>25.0</lowerLevel>
					<upperLevel>75.0</upperLevel>
				</phd>
				<mode>Scanning</mode>
				<activeLength unit="deg">3.3482</activeLength>
			</detector>
		</diffractedBeamPath>
		<scan appendNumber="0" mode="Continuous" scanAxis="Gonio" status="Completed">
			<header>
				<startTimeStamp>2023-01-21T13:51:15+01:00</startTimeStamp>
				<endTimeStamp>2023-01-21T16:51:44+01:00</endTimeStamp>
				<author>
					<name>User</name>
				</author>
				<source>
					<applicationSoftware version="5.5a">Data Collector</applicationSoftware>
					<instrumentControlSoftware version="8.2  20201204">EMPYREAN</instrumentControlSoftware>
					<instrumentID>0000000011159748</instrumentID>
				</source>
			</header>
			<dataPoints>
				<positions axis="2Theta" unit="deg">
					<startPosition>9.99846514</startPosition>
					<endPosition>99.99342261</endPosition>
				</positions>
				<positions axis="Omega" unit="deg">
					<startPosition>4.99923257</startPosition>
					<endPosition>49.99671130</endPosition>
				</positions>
				<positions axis="Z" unit="mm">
					<commonPosition>8.846</commonPosition>
				</positions>
				<commonCountingTime unit="seconds">386.070</commonCountingTime>
				<intensities unit="counts">6814 6876 6939 6753 7052 6801 6753 6747 6794 6816 6785 6844 6865 6655 6820 6780 6678 6621 6759 6744 6737 6628 6716 6808 6667 6660 6830 6724 6668 6714 6615 6676 6522 6704 6605 6611 6549 6715 6585 6606 6386 6443 6708 6863 6468 6490 6516 6503 6611 6460 6476 6766 6665 6448 6613 6766 6698 6759 6663 6878 6835 6692 6731 6829 6781 6719 6807 6943 7120 7149 7238 7359 7469 7693 7958 8530 9606 10510 11503 13264 16657 22064 28179 36353 45848 51122 51521 46893 38363 31269 24750 18999 14464 11568 9379 8319 7618 7216 7133 6929 6868 6656 6744 6629 6547 6679 6509 6353 6433 6449 6170 6376 6244 6356 6399 6549 6413 6390 6271 6266 6277 6332 6319 6327 6264 6246 6185 6244 6241 6305 6271 6289 6183 6160 6077 6103 6193 6217 6151 6232 6102 6152 6199 6112 6148 6101 6002 6046 6101 6049 6024 6088 6097 6116 6092 6082 6030 5936 6033 6043 6000 6058 6000 6072 6121 5981 5926 6025 6005 5920 5895 5894 5926 5900 5823 5873 5863 6059 5889 6026 6038 5916 5932 5799 5885 5829 5839 5924 5886 5851 5797 5895 5879 5778 5936 5747 6012 5811 5879 5781 5791 5756 5788 5754 5850 5720 5651 5820 5760 5717 5768 5699 5670 5711 5778 5753 5788 5852 5605 5671 5727 5746 5802 5688 5545 5638 5694 5758 5684 5632 5721 5671 5641 5629 5718 5618 5625 5538 5611 5628 5725 5436 5618 5530 5673 5522 5516 5553 5669 5574 5482 5528 5743 5522 5597 5524 5711 5671 5553 5594 5565 5556 5671 5636 5614 5524 5519 5565 5533 5500 5450 5639 5577 5491 5421 5447 5443 5454 5360 5399 5568 5404 5405 5321 5467 5308 5552 5473 5324 5472 5438 5514 5329 5251 5406 5396 5564 5410 5440 5396 5385 5277 5379 5372 5439 5383 5359 5319 5394 5350 5327 5252 5353 5248 5321 5399 5329 5209 5360 5253 5166 5282 5167 5236 5226 5257 5281 5274 5234 5384 5246 5350 5175 5192 5219 5082 5301 5075 5211 5322 5224 5210 5300 5249 5195 5290 5253 5068 5266 5336 5172 5156 5042 5134 5127 5117 5072 5149 5154 5250 5108 5370 5144 5175 5227 5125 5139 5092 5295 5249 4938 5147 5079 5140 5235 5066 5027 5136 5058 5103 5190 5137 5013 5158 4952 5091 4978 5092 5000 4986 5110 5007 5079 5068 5017 5061 5058 5085 4987 4925 5115 5039 5047 5003 5087 4948 5162 5117 5034 4970 4968 4878 5124 4889 5036 5121 4998 4995 4987 5012 5130 5020 4892 4927 4979 4888 4979 4897 4989 4880 4866 4935 4898 4944 4952 4964 4960 4919 4972 4981 5050 4931 4889 4895 4962 4896 4865 4987 4831 5039 4826 4893 4953 4923 4985 4862 4944 4912 4832 5031 4866 4928 4940 4926 4893 5002 5069 4983 4842 4968 4907 4793 5006 4995 4876 4970 5034 4949 5146 5006 5085 5112 5000 5030 4946 5069 5162 5071 5040 5196 4997 4976 5073 4994 4949 4931 5020 4996 5003 4955 4989 4980 4811 4871 4846 4657 4849 4878 4723 4630 4722 4682 4620 4861 4644 4776 4729 4819 4716 4796 4786 4815 4647 4784 4705 4655 4757 4704 4731 4632 4683 4691 4804 4690 4738 4684 4657 4722 4783 4712 4732 4757 4600 4718 4661 4698 4809 4662 4698 4839 4816 4783 5069 4868 4913 4930 4828 4846 4908 4804 4697 4820 4607 4638 4721 4515 4720 4650 4548 4485 4480 4623 4615 4572 4595 4640 4499 4495 4604 4609 4493 4583 4540 4733 4560 4604 4525 4624 4668 4747 4824 4893 4754 4839 4814 4765 4628 4514 4622 4523 4509 4452 4474 4556 4501 4459 4387 4463 4488 4420 4423 4394 4453 4462 4403 4414 4443 4512 4477 4416 4508 4422 4417 4402 4453 4484 4480 4453 4353 4417 4391 4430 4423 4521 4324 4398 4357 4421 4335 4375 4280 4358 4260 4332 4419 4277 4399 4423 4290 4396 4365 4542 4520 4454 4515 4457 4495 4382 4536 4562 4480 4505 4345 4467 4340 4464 4362 4231 4363 4255 4224 4227 4183 4437 4469 4391 4234 4239 4201 4343 4285 4304 4176 4327 4387 4451 4484 4419 4337 4559 4686 4642 4556 4632 4647 4666 4729 4611 4605 4753 4596 4702 4674 4668 4721 4551 4802 4596 4713 4703 4627 4653 4640 4687 4766 4886 4965 4939 5267 5185 5288 5329 5637 5780 5995 6074 6360 6956 7611 8610 10076 12626 16800 22709 33052 48637 70715 95606 115636 121373 115368 105717 94391 79298 60364 43582 30716 22254 16186 12169 9145 7693 6918 6346 5960 5767 5382 5353 4993 4989 4881 4748 4832 4584 4599 4519 4644 4551 4621 4526 4596 4488 4751 4742 4711 4658 4681 4731 4783 4551 4609 4519 4555 4487 4463 4353 4398 4379 4312 4364 4444 4220 4356 4324 4282 4235 4203 4206 4274 4214 4228 4316 4269 4195 4223 4324 4283 4162 4202 4070 4033 4168 4135 4187 4162 4203 4178 4133 4057 4210 4033 4146 4198 4058 4211 4162 4090 4195 4132 4111 4072 4169 4037 4114 4329 4124 4065 4060 4087 4080 3970 3931 4067 4067 4070 4045 4001 4103 4027 3959 4079 3965 3976 4109 4002 4025 3996 4055 4019 3990 4093 3997 4029 3975 4020 4043 3900 4138 4001 3908 3970 3874 4059 3949 3916 4027 4063 3924 4039 3965 3977 3987 4014 3885 4024 3991 3950 3830 3979 4092 4050 4010 4065 3994 3936 4023 4034 3829 4085 4191 4164 4230 4301 4358 4270 4211 4246 4096 4186 4228 4009 4141 3999 4001 4082 4176 4138 4063 4142 4066 4025 3935 4120 4091 4000 3900 4012 4037 4060 4106 4127 4077 4309 4547 4517 4964 5657 6527 8258 10342 13886 17819 20218 19356 17604 16139 16175 14146 11113 8409 7123 6234 5178 4675 4332 4243 4193 4010 4070 3995 3992 4005 4067 3902 3885 3852 3845 3878 3852 3873 3833 3945 3948 3794 3969 3847 3897 3863 3869 3920 4047 3885 3792 3762 3910 3900 3794 3751 3789 3822 3743 3833 3827 3797 3747 3811 3838 3839 3661 3830 3744 3824 3699 3800 3828 3762 3716 3753 3743 3706 3794 3749 3761 3723 3700 3812 3772 3787 3788 3741 3923 3891 3840 3791 3778 3811 3833 3810 3935 3899 3833 3988 3801 3868 3977 3972 3957 3943 4093 3947 3883 3951 4015 4036 4031 3968 3958 3940 4081 4072 4022 3872 4034 3952 4134 4026 4057 4154 4188 4164 4095 4256 4466 4524 4428 4465 4617 4521 4648 4655 4819 5086 5225 5426 5929 6788 8275 10855 15617 22375 29654 37872 43704 46525 42947 38472 34307 31341 26591 21324 16724 14223 13725 14898 19379 27684 36714 42964 47732 49723 47369 43105 37859 32715 27638 21485 16097 12022 8673 6914 5789 5178 4782 4591 4453 4448 4257 4290 4121 4130 4019 3957 3846 3891 4022 3771 3826 3937 3816 3837 3797 3758 3809 3876 3768 3719 3807 3799 3812 3788 3848 3623 3680 3883 4109 3954 3934 3897 3803 3795 3688 3689 3608 3784 3764 3778 3670 3599 3680 3761 3618 3680 3624 3648 3592 3764 3647 3706 3688 3771 3645 3671 3563 3721 3657 3610 3680 3598 3565 3533 3619 3777 3666 3638 3648 3678 3654 3591 3620 3429 3670 3559 3605 3478 3631 3507 3560 3536 3629 3596 3449 3475 3640 3552 3498 3552 3586 3525 3534 3499 3486 3496 3572 3651 3533 3599 3622 3546 3563 3545 3579 3683 3745 3821 3757 3905 4149 4107 4023 4060 3960 3931 3898 3707 3729 3705 3570 3548 3544 3566 3577 3464 3550 3505 3607 3532 3551 3492 3563 3577 3589 3524 3472 3472 3515 3509 3567 3618 3493 3378 3545 3433 3470 3490 3517 3467 3522 3395 3532 3466 3376 3487 3447 3442 3661 3494 3554 3490 3659 3641 3719 3619 3725 3687 3618 3530 3606 3737 3536 3645 3582 3559 3729 3774 3824 3668 3713 3652 3690 3624 3699 3679 3749 3591 3744 3680 3750 3718 3730 3611 3635 3594 3671 3640 3625 3660 3840 3798 3708 3715 3827 3670 3773 3775 3760 3878 3991 3866 3888 4109 4074 4226 4240 4443 4577 4575 4879 5069 5309 5506 5885 6501 6820 7731 8792 10666 13529 18456 27228 40764 57276 72603 81558 81016 74202 66468 60056 54403 48588 39795 30763 22550 15742 11410 8839 7250 6571 5824 5266 4932 4699 4536 4361 4346 4128 4088 3974 3804 3858 3809 3760 3715 3727 3732 3728 3581 3666 3681 3627 3651 3787 3732 3821 3947 3905 4124 4064 3903 3945 3954 3737 3727 3846 3803 3806 3685 3732 3665 3532 3772 3757 3503 3652 3618 3732 3613 3677 3426 3568 3543 3463 3505 3556 3489 3490 3551 3522 3549 3612 3526 3504 3465 3488 3371 3559 3532 3665 3546 3565 3534 3538 3542 3608 3651 3678 3610 3768 3629 3751 3820 3805 3797 3993 4019 3954 4267 4250 4433 4649 4664 4822 5351 6194 7455 10473 15086 21504 28683 33266 33695 30668 26372 24808 24298 23334 21160 18062 15762 15282 15917 17207 19160 19613 18775 17289 15318 14141 13011 11893 10373 8890 6951 5851 4905 4245 4121 3794 3728 3594 3667 3537 3522 3500 3494 3454 3413 3454 3329 3362 3414 3395 3420 3457 3343 3394 3437 3427 3316 3472 3468 3357 3349 3328 3374 3378 3274 3313 3277 3242 3320 3420 3330 3394 3427 3361 3285 3342 3269 3373 3247 3376 3226 3261 3315 3370 3287 3263 3318 3282 3292 3413 3357 3255 3376 3344 3276 3280 3343 3290 3251 3300 3261 3256 3230 3323 3206 3226 3224 3187 3193 3217 3114 3151 3356 3193 3217 3186 3243 3219 3287 3142 3308 3251 3278 3253 3131 3228 3175 3197 3193 3104 3229 3171 3117 3132 3092 3191 3088 3255 3191 3197 3067 3128 3178 3252 3226 3167 3278 3219 3110 3192 3148 3142 3224 3239 3136 3112 3097 3265 3165 3155 3150 3159 3204 3057 3159 3127 3083 3034 3027 3119 3036 3117 3019 3234 3087 3176 3049 3014 3145 3037 3137 3148 3171 3193 3081 3182 3101 3067 3147 3037 3105 3114 3143 3066 3114 3153 3034 3196 3085 3170 3156 3133 3161 3086 3132 3088 2998 3135 3148 3158 3073 3112 3183 3233 3096 3070 3166 3049 3119 3135 3116 3097 3167 3219 3085 3174 3121 3152 3046 3202 3222 3073 3304 3009 3235 3214 3315 3295 3202 3386 3098 3157 3186 3174 3229 3197 3203 3258 3328 3278 3235 3254 3326 3263 3348 3356 3428 3426 3559 3508 3670 3708 3765 3850 3875 4005 4379 5039 6329 8859 13151 18473 22359 21194 17501 14185 12620 12722 13594 13404 11337 9132 7019 5734 4835 4228 3972 3891 3767 3748 3809 3722 3841 3657 3752 3888 3953 3938 4044 4148 4202 4405 4480 4847 5121 5902 7016 9868 14251 20282 28145 34441 35969 31660 27362 23525 22088 21630 21992 19685 16275 12612 9803 7619 6085 5215 4795 4545 4544 4289 4257 4328 4224 4245 4381 4588 4648 4819 5158 5371 6275 7281 9123 12280 16248 20701 24927 28819 30356 29287 26867 24404 24251 25692 28514 29707 27276 22248 16771 13558 12532 11919 11486 9918 8355 6815 5814 4781 4383 4074 3843 3622 3484 3593 3406 3387 3396 3366 3267 3292 3211 3216 3252 3312 3244 3133 3123 3334 3191 3216 3221 3120 3253 3129 3214 3159 3062 3196 3218 3226 3213 3285 3266 3288 3380 3332 3367 3453 3457 3507 3467 3477 3464 3747 4015 4510 5252 6816 8927 11783 14434 14101 12727 10867 9199 8664 8944 9318 8758 7756 6575 5190 4532 3922 3626 3499 3438 3285 3336 3138 3249 3257 3383 3645 3773 3949 3729 3550 3423 3278 3333 3388 3444 3233 3199 3032 3063 3110 3052 3073 2884 2967 2847 2917 2971 3022 3009 2988 3034 3028 2945 3038 3066 2975 2990 2974 2978 2853 2947 3007 2936 3048 2895 3042 2955 2930 2881 2948 2873 2974 2937 2987 2951 2907 2961 2853 2970 3053 2960 2932 2899 2859 2964 2917 2941 2961 2820 2862 2894 2823 2872 2887 2902 2888 2903 2871 2898 2921 2902 3025 3079 2947 3013 2968 2922 2930 2979 3028 3124 3011 3002 3006 2953 2923 2961 2915 2966 2864 2950 2842 2980 2923 2900 2967 2866 2913 2920 2957 2953 2972 2863 2913 2975 3011 2975 2902 3047 3026 3127 3073 3081 3183 3071 3262 3432 3544 3757 4729 5857 7412 8765 9896 9828 8504 7171 6281 6237 6490 6707 6480 5976 5142 4240 3737 3328 3222 3205 3194 3181 3117 3070 2964 3117 2891 2972 2931 2931 2953 3074 2986 2915 2994 3003 2876 2936 2999 2998 2983 3018 3003 3183 3094 3192 3329 3096 3255 3347 3401 3629 3838 4577 5454 6702 8115 9261 9952 9929 9575 8604 7638 7086 6871 6843 6801 6328 5796 4941 4110 3697 3369 3249 3196 3159 3164 3203 3359 3637 3717 3626 3523 3409 3325 3252 3356 3303 3403 3306 3098 3145 3066 2945 2856 2874 2788 2802 2768 2753 2808 2840 2820 2889 2762 2910 2795 2668 2773 2716 2672 2701 2739 2709 2653 2687 2751 2719 2793 2748 2727 2706 2763 2676 2785 2667 2743 2724 2710 2645 2775 2766 2774 2839 2798 2671 2725 2781 2719 2799 2772 2703 2788 2663 2801 2726 2801 2730 2769 2724 2699 2859 2805 2725 2747 2856 2780 2805 2838 2640 2741 2731 2787 2693 2785 2789 2651 2628 2656 2793 2713 2708 2826 2712 2749 2811 2711 2760 2818 2801 2718 2813 2807 2744 2775 2746 2701 2743 2717 2784 2738 2763 2667 2739 2698 2766 2772 2738 2764 2642 2765 2684 2670 2727 2724 2714 2714 2715 2690 2797 2768 2805 2700 2771 2784 2877 2800 2824 2786 2766 2841 2838 2826 2871 2790 2908 2949 2901 2993 3189 3361 3624 4100 4491 4869 5135 4972 4930 4524 4105 4014 4089 4057 4143 4142 3863 3635 3401 3294 3136 3162 3063 3231 3362 3596 3871 4224 5019 6244 7134 7452 7126 6527 6031 5413 5253 5378 5470 5730 5332 4822 4437 3995 3779 3604 3469 3547 3863 4195 4804 6043 7497 9078 9644 9449 8160 6782 5786 5666 5912 6290 6663 6097 5496 4676 3988 3567 3393 3238 3096 3058 3088 2878 2941 2897 2986 2889 2891 2918 2932 2882 2868 2817 2916 2986 2874 2963 3025 3025 3077 3178 3157 3223 3381 3442 3550 3814 4135 4797 5422 6645 7870 9500 10758 11367 10955 9876 8412 7733 7548 8288 9384 10769 12504 14199 14615 14279 12298 10581 8907 8325 9357 11279 13564 15396 16253 15411 13460 10542 8524 7381 7057 7410 7681 7926 7254 6242 5265 4449 3754 3431 3180 3114 3068 3052 2890 2905 2819 2818 2739 2812 2869 2822 2755 2698 2771 2795 2819 2740 2808 2741 2801 2793 2748 2671 2781 2593 2705 2661 2649 2653 2647 2760 2557 2649 2689 2761 2612 2632 2764 2659 2733 2704 2727 2627 2666 2671 2729 2640 2601 2728 2648 2593 2565 2640 2698 2684 2644 2653 2727 2706 2647 2700 2729 2684 2678 2680 2754 2784 2670 2601 2747 2648 2782 2650 2645 2639 2628 2723 2601 2667 2674 2552 2586 2706 2678 2694 2641 2682 2680 2612 2703 2664 2639 2703 2668 2676 2624 2759 2737 2711 2633 2676 2699 2711 2646 2604 2596 2738 2743 2715 2778 2802 2745 2691 2717 2728 2697 2616 2659 2678 2635 2636 2646 2638 2686 2689 2583 2642 2639 2644 2587 2619 2540 2726 2663 2744 2640 2747 2641 2707 2681 2834 2815 2831 2909 3234 3315 3492 3457 3286 3149 3231 2992 3037 3060 3038 3137 3085 2951 2840 2875 2787 2729 2667 2734 2652 2823 2646 2657 2651 2611 2633 2567 2556 2669 2742 2696 2642 2571 2705 2769 2709 2689 2671 2652 2710 2709 2660 2667 2614 2670 2668 2743 2648 2654 2633 2663 2563 2769 2717 2850 3013 2976 3133 3456 3659 3794 3870 3825 3835 3516 3341 3269 3239 3317 3357 3313 3275 3236 3124 2989 2892 2967 2814 2873 2856 2996 2998 3044 3177 3317 3533 4137 4470 4989 5560 5692 5459 5190 4676 4215 4067 4054 4124 4363 4368 4118 3835 3631 3342 3180 2956 2817 2793 2743 2809 2719 2706 2788 2695 2693 2802 2709 2713 2638 2585 2605 2686 2623 2667 2601 2598 2491 2607 2675 2697 2633 2565 2610 2594 2610 2620 2618 2606 2614 2637 2659 2551 2646 2530 2590 2587 2561 2805 2630 2699 2674 2709 2828 2741 2798 2775 2839 2913 2878 2875 2979 2800 2956 2957 3070 3137 3225 3490 3852 4786 6192 8621 10730 12308 11644 9642 7472 5868 5117 5337 5766 6753 7375 7436 6342 5217 4347 3538 3146 3174 2966 3033 2817 2929 2848 2684 2802 2736 2724 2653 2658 2747 2760 2724 2691 2776 2842 2800 2851 2833 2866 2864 2898 2843 2819 2980 3084 3239 3491 4016 4968 6114 7387 7558 6631 5674 4737 4281 3969 4080 4392 4996 5246 4871 4469 3746 3422 3250 3016 2961 2823 2791 2793 2829 2810 2749 2801 2693 2724 2568 2722 2824 2770 2669 2666 2710 2689 2649 2735 2784 2750 2689 2769 2695 2783 2822 2784 2795 2912 2913 2843 2953 2873 2913 3009 3108 3097 3163 3295 3483 3818 4443 4964 5913 6858 7643 8385 8650 8414 7332 6159 5271 5148 5119 5419 5635 5856 5937 5338 4714 4087 3556 3416 3181 3111 3108 3021 2970 3092 2964 2932 3027 3083 3043 3164 3205 3248 3258 3332 3294 3467 3484 3492 3540 3641 3779 3904 4228 4570 5031 5839 6837 8466 10874 14145 17795 20306 20226 18360 15372 12703 11005 9965 10275 10887 12087 12486 11686 10379 8634 7218 5908 5093 4466 3999 3864 3598 3502 3334 3365 3392 3172 3361 3173 3246 3209 3240 3271 3437 3442 3452 3531 3673 4019 4427 5259 6702 8458 10638 12611 13070 13034 13130 13159 12640 11913 10577 10385 9909 9432 8895 8719 8224 8034 7783 7000 6185 5371 4759 4343 3910 3943 4036 4203 4798 5665 6761 8530 11142 13049 13220 12552 10527 8297 6934 6356 6195 6635 7607 8238 8273 7672 6513 5385 4578 3864 3580 3497 3255 3223 3195 3012 2987 2890 2923 2901 2889 2892 2825 2840 2745 2844 2841 2843 2893 2913 2798 2794 2897 2857 2847 2821 2866 3009 3072 3201 3309 3527 3524 3449 3251 3200 3168 3303 3098 3281 3324 3297 3252 3331 3380 3423 3372 3425 3352 3195 3186 3161 3123 3275 3222 3293 3300 3310 3390 3503 3410 3404 3348 3367 3556 3739 3767 4031 4368 4941 5884 7231 9078 12491 16117 18496 19014 18239 15776 12759 10823 9789 9873 10806 11709 12849 12778 11674 9969 8356 6999 6207 5389 4916 4640 4377 4127 3842 3653 3443 3572 3345 3458 3369 3356 3351 3400 3506 3649 3739 3915 4129 4611 5024 5930 7039 8195 9761 10808 11266 11201 10098 8271 7364 6605 6207 6403 6837 7104 7318 7031 6609 5907 5025 4446 3818 3574 3446 3276 3149 3069 2964 2989 2934 2937 2903 2802 2880 2772 2850 2745 2838 2715 2771 2806 2764 2756 2823 2800 2754 2834 2824 2797 2874 2910 2752 2791 2882 3020 2964 2884 2935 2930 2978 2967 2964 2995 3104 3210 3263 3605 3786 4328 5134 6163 8017 9031 9307 8483 7158 5800 4752 4447 4445 4645 5240 5900 6179 6039 5464 4689 4210 3959 3824 3798 3645 3588 3461 3280 3150 3057 2974 3063 3110 3162 3155 3155 3047 2962 2918 2786 2804 2888 2769 2748 2766 2751 2740 2801 2819 2686 2825 2785 2741 2728 2737 2740 2703 2775 2766 2692 2720 2641 2767 2690 2838 2822 2768 2828 2768 2732 2808 2875 2800 2958 2950 3026 2981 3052 3122 3185 3346 3531 3789 4133 4997 6030 7483 8823 9834 10585 10788 10699 9724 8749 7449 6223 5833 6093 6326 6567 6923 6739 6810 6138 5385 4504 3892 3573 3361 3259 3174 3157 3212 3151 3342 3544 3613 4165 4461 4857 5187 5617 5739 5795 5745 5557 5238 5095 4592 4498 4315 4297 4458 4335 4274 4148 4170 3884 3505 3356 3107 3030 2971 2740 2773 2757 2705 2707 2776 2669 2903 2784 2742 2809 2640 2717 2836 2856 2918 3038 3270 3429 3615 3901 4186 4443 4248 3997 3839 3439 3269 3213 3310 3469 3545 3611 3689 3587 3530 3233 2977 2960 2932 2806 2827 2847 2832 2761 2651 2688 2746 2627 2699 2640 2655 2714 2652 2570 2633 2576 2617 2611 2595 2613 2707 2595 2591 2716 2590 2786 2735 2619 2621 2609 2665 2598 2638 2606 2582 2619 2620 2663 2728 2738 2886 2835 2868 2828 3016 3014 3021 2961 3029 3020 2967 2916 2919 2822 2818 2768 2815 2810 2751 2783 2740 2763 2695 2705 2724 2758 2682 2640 2717 2718 2694 2602 2728 2585 2563 2637 2595 2585 2609 2623 2645 2619 2733 2588 2621 2587 2665 2524 2681 2556 2641 2637 2731 2678 2608 2738 2802 2594 2684 2728 2669 2616 2677 2793 2836 2778 2755 2803 2785 2819 2938 2828 2999 2957 2985 3023 3102 3106 3191 3310 3487 3761 4080 4613 5420 6632 8018 9771 11054 11748 11139 9839 8323 6815 5933 5694 5651 6104 6461 7305 7806 7619 6774 6201 5303 4652 3957 3681 3504 3600 3505 3481 3525 3614 3656 3506 3391 3297 3064 3087 3054 2992 2956 3045 3059 3087 3107 3155 3091 2916 2954 2930 3020 2936 2986 2949 2953 2978 3014 3022 3101 3140 3201 3311 3529 3745 4095 4688 5625 6957 8353 10049 11478 12363 12773 12330 11186 10057 8163 7465 7041 7389 8077 8912 9520 10003 9377 8782 8011 6721 5788 4979 4545 4375 4203 4222 4201 4037 3878 3637 3426 3253 3260 3053 2990 2919 2942 3022 2930 2906 2917 2888 2790 3058 2898 2943 3038 2965 3022 2963 3047 3084 3260 3229 3339 3576 3748 4027 4503 5160 5984 6790 7514 8213 8744 9388 9620 9807 9942 9750 9000 8349 7859 7225 7142 7215 7379 7915 8568 8985 9351 9646 9106 8269 6984 5926 5087 4768 4379 4311 4411 4731 4876 4924 4842 4602 4049 3903 3613 3386 3247 3227 3123 3136 2982 3085 2943 3050 3008 3063 3062 3143 3098 3209 3255 3415 3547 3728 4287 4872 5723 6683 8167 8697 8750 8138 6962 5893 5183 4887 4840 4791 5081 5849 6288 6823 6833 6367 5512 5013 4486 4218 4100 3965 4083 3917 3858 3735 3559 3445 3357 3256 3163 3239 3201 3327 3256 3316 3063 3152 3150 3131 2974 3123 3091 3223 3264 3274 3427 3600 3885 4220 4806 5182 5709 6688 7408 8025 8332 8328 8015 7185 6506 5749 5451 5564 5824 6098 6898 7858 8824 10152 10876 10970 10557 9391 8273 6566 5581 4968 4756 4819 5105 5635 6127 6398 6631 6448 6221 5651 5586 5683 6192 6931 7847 8954 9340 9702 9130 8137 6852 5908 5268 4842 4862 5110 5308 5767 6012 6257 6139 5561 4965 4348 3894 3652 3406 3280 3248 3193 3126 3055 3105 3107 2992 3184 3100 3110 3194 3175 3314 3432 3561 3954 4414 4924 5753 6432 7144 7986 8364 9000 8895 8740 8278 8011 7626 7640 7568 7660 8093 8589 9457 10629 12300 13304 13669 12563 10716 9009 7423 6308 5925 5440 5291 5749 6107 6785 7013 6917 6277 5366 4699 4120 3745 3348 3222 3242 3125 2986 2933 2931 2896 2903 2820 2904 2801 2819 2828 2806 2885 2904 2829 2737 2925 2848 2935 2883 3011 3020 2953 2912 2991 3019 3230 3189 3341 3298 3521 3686 3856 4259 4728 5730 6732 8125 9463 10477 10784 10514 10049 9735 9666 9898 9871 9829 9395 8953 8762 8585 8420 8096 7814 7682 7535 7516 7881 7724 7508 7214 6664 6058 5514 5223 5042 4937 4827 5174 5221 5469 5650 5605 5864 5662 5351 4953 4511 4189 3891 3714 3724 3718 3806 3741 3759 3691 3643 3464 3266 3210 2958 2770 2813 2738 2664 2652 2698 2638 2607 2571 2546 2629 2577 2580 2526 2502 2481 2587 2530 2601 2481 2593 2534 2593 2516 2529 2516 2650 2522 2449 2526 2559 2643 2508 2584 2547 2498 2537 2485 2583 2505 2493 2515 2532 2576 2565 2581 2456 2431 2509 2507 2567 2511 2620 2495 2488 2519 2452 2446 2502 2388 2510 2467 2521 2462 2357 2475 2440 2493 2416 2503 2416 2567 2574 2623 2533 2534 2638 2530 2459 2519 2472 2486 2436 2373 2525 2523 2528 2551 2531 2519 2455 2542 2400 2407 2486 2417 2431 2419 2444 2505 2405 2431 2484 2518 2430 2494 2495 2497 2499 2437 2512 2413 2493 2506 2497 2509 2408 2487 2472 2545 2335 2421 2386 2424 2520 2481 2464 2479 2463 2456 2364 2457 2445 2488 2429 2433 2428 2500 2409 2457 2438 2418 2461 2496 2544 2524 2461 2471 2465 2506 2468 2517 2488 2483 2608 2577 2626 2624 2777 2765 2747 2854 2948 3003 3106 3294 3327 3639 3965 3916 4177 4075 3915 3579 3413 3194 3073 3023 3011 2998 3123 3108 3277 3381 3368 3222 2998 2882 2854 2755 2742 2691 2586 2641 2659 2574 2784 2758 2807 2853 2947 3074 3350 3506 3860 4081 4390 4652 4648 4598 4735 4672 4646 4640 4639 4253 4141 3792 3834 3728 3651 3689 3778 3782 3644 3496 3419 3430 3270 3237 3025 2940 2687 2692 2559 2581 2535 2399 2501 2404 2476 2452 2373 2415 2401 2424 2386 2388 2351 2383 2433 2433 2408 2510 2400 2417 2433 2488 2462 2407 2390 2443 2505 2562 2441 2564 2600 2654 2532 2651 2694 2688 2652 2625 2748 2527 2658 2588 2706 2745 2673 2738 2643 2833 2766 2775 2669 2709 2590 2604 2446 2565 2469 2581 2467 2510 2443 2433 2483 2444 2500 2517 2383 2433 2410 2390 2441 2370 2383 2372 2340 2293 2426 2349 2354 2289 2388 2390 2348 2350 2405 2386 2290 2409 2377 2342 2341 2361 2470 2384 2377 2382 2407 2426 2311 2383 2367 2471 2486 2396 2404 2385 2456 2399 2363 2445 2419 2314 2402 2420 2454 2349 2383 2390 2404 2362 2418 2443 2385 2352 2351 2337 2331 2310 2305 2444 2275 2405 2274 2329 2373 2339 2331 2425 2349 2380 2476 2318 2377 2430 2440 2390 2379 2407 2521 2461 2483 2522 2412 2542 2482 2436 2466 2322 2386 2413 2468 2422 2446 2447 2538 2498 2583 2579 2571 2643 2463 2446 2331 2507 2452 2374 2407 2420 2361 2445 2343 2423 2417 2455 2403 2465 2411 2376 2389 2373 2348 2305 2382 2403 2348 2318 2361 2346 2425 2404 2271 2264 2385 2322 2299 2271 2412 2339 2316 2253 2426 2398 2295 2424 2339 2344 2394 2415 2379 2475 2359 2350 2424 2362 2404 2435 2440 2258 2306 2367 2495 2411 2385 2394 2316 2342 2337 2412 2324 2348 2383 2398 2364 2373 2306 2366 2421 2349 2413 2416 2328 2449 2464 2457 2437 2408 2402 2524 2436 2477 2534 2556 2690 2758 2958 3188 3503 3625 3703 3689 3323 3109 2871 2788 2720 2673 2683 2679 2752 2759 3023 2959 3153 3033 3142 3152 3106 3072 3073 2959 2926 2885 2781 2852 2702 2726 2817 2677 2737 2712 2741 2785 2790 2756 2756 2677 2652 2712 2773 2726 2804 2900 3033 3258 3575 4043 4624 5024 5264 4992 4637 4083 3579 3207 2976 2695 2909 2886 2950 3035 3330 3594 3773 3752 3783 3582 3194 2930 2748 2696 2649 2556 2577 2487 2543 2570 2541 2474 2603 2563 2637 2616 2647 2665 2675 2746 2829 3034 3331 3614 3822 3907 3840 3566 3281 3061 2946 2887 2821 2765 2853 2895 3109 3309 3591 3910 3976 4152 4162 4143 4038 4029 3773 3811 3664 3586 3334 3218 3093 3135 3156 3126 3201 3231 3305 3433 3425 3379 3357 3486 3506 3609 3860 4120 4579 5179 5602 6290 6911 7041 7107 6620 5986 5174 4687 4322 4161 4074 4022 4405 4804 5176 5591 5944 6438 6264 5960 5539 4998 4493 4090 3701 3596 3570 3481 3545 3706 3746 3809 3918 3817 3832 3635 3535 3346 3241 3314 3307 3659 3789 4209 4676 4937 5105 5156 4861 4478 4143 3834 3689 3422 3428 3382 3501 3550 3702 3936 3976 4011 4103 4014 3531 3455 3230 3185 3004 3062 3035 3023 3070 2984 2973 3100 3249 3129 3319 3407 3594 3662 3839 4091 4068 4314 4286 4281 4302 4243 4014 4025 3791 3621 3497 3389 3518 3590 3665 3893 4132 4324 4966 5540 6019 6156 5610 4931 4270 3952 3444 3371 3067 2961 2976 3020 3103 3390 3557 3683 3910 3806 3625 3433 3119 2999 2984 2735 2687 2790 2734 2852 2925 3081 3269 3519 3651 3973 4182 4159 4001 3729 3418 3278 3051 2944 2982 2885 3125 3198 3281 3536 3715 3921 3986 4053 3998 3954 3838 3734 3672 3645 3368 3293 3111 3101 3044 2869 2826 2852 2933 2968 2984 2904 3063 2970 2956 2977 2946 2806 2741 2655 2578 2655 2480 2495 2608 2519 2477 2572 2563 2481 2526 2476 2463 2618 2512 2641 2538 2476 2599 2539 2599 2649 2689 2680 2770 2823 2999 3105 3296 3596 3855 4071 4141 4183 4155 3931 3630 3232 3167 2961 2955 2955 2886 2841 3060 2951 3206 3439 3371 3246 3352 3318 3062 2999 2779 2678 2734 2604 2670 2701 2569 2767 2833 2945 2993 3292 3427 3699 3839 4049 4043 4356 4096 3997 3861 3611 3510 3375 3201 3213 3282 3204 3188 3332 3428 3496 3451 3384 3461 3488 3386 3364 3558 3646 3756 3750 3968 4018 4013 4136 3925 4013 3819 3787 3725 3647 3543 3427 3323 3332 3124 3219 3258 3207 3253 3338 3293 3205 3223 3173 3182 3065 2935 3100 2932 2946 2960 2984 2964 3178 3337 3638 3914 4414 4869 5149 5375 5207 5159 5277 5240 5389 5448 5225 5065 4541 4152 3904 3715 3796 4059 3944 3843 3862 3952 3943 3903 3912 3917 3802 3625 3398 3272 2926 2855 2724 2710 2515 2595 2463 2510 2453 2497 2381 2422 2473 2330 2411 2416 2438 2406 2499 2488 2353 2307 2369 2423 2383 2418 2485 2350 2263 2353 2471 2368 2409 2345 2406 2393 2408 2235 2371 2329 2404 2412 2294 2325 2323 2367 2337 2428 2329 2373 2393 2409 2364 2430 2309 2352 2317 2215 2431 2376 2421 2439 2292 2338 2387 2315 2365 2335 2319 2302 2304 2352 2274 2355 2293 2387 2414 2288 2268 2380 2353 2389 2362 2396 2313 2382 2274 2387 2415 2421 2490 2424 2489 2463 2555 2476 2507 2512 2515 2529 2546 2439 2402 2462 2428 2445 2454 2554 2521 2498 2554 2531 2408 2478 2504 2519 2613 2508 2505 2527 2651 2617 2599 2540 2782 2663 2684 2781 2775 2763 2835 2929 2897 2957 2961 2918 2902 2889 2844 2935 2942 3164 3302 3395 3632 3880 4129 4377 4449 4752 4821 4778 4642 4374 4081 3679 3490 3384 3140 3134 3150 3125 3173 3246 3424 3543 3518 3616 3598 3505 3252 3238 3087 3044 2800 2754 2714 2605 2563 2596 2563 2562 2445 2559 2626 2558 2567 2709 2533 2684 2741 2624 2705 2819 2924 3009 3170 3450 3607 3833 3977 4244 4388 4435 4414 4465 4342 4262 3859 3751 3460 3337 3168 3076 3138 3191 3159 3273 3302 3569 3376 3430 3322 3442 3369 3175 3083 3082 2804 2747 2733 2625 2544 2536 2601 2503 2505 2622 2643 2685 2809 2865 2978 3043 3110 3033 3157 2979 2750 2757 2662 2588 2601 2575 2524 2617 2546 2567 2632 2781 2784 2837 2679 2751 2646 2742 2758 2688 2663 2585 2592 2616 2652 2742 2810 2754 2880 3003 2978 2844 2802 2680 2647 2580 2687 2609 2604 2548 2473 2563 2644 2677 2695 2658 2760 2878 2839 2749 2793 2887 3027 3119 3297 3378 3468 3535 3406 3426 3574 3544 3483 3388 3471 3407 3320 3198 3151 3012 3031 3013 3069 3221 3266 3270 3295 3296 3255 3442 3550 3500 3761 3705 3784 3803 3865 3905 4077 3906 4042 4057 4099 3993 3874 3744 3741 3773 3899 3984 4004 4022 4025 4183 4292 4276 4113 4217 4139 3946 3878 3589 3488 3350 3276 3159 3200 3240 3170 3153 3183 3156 3195 3241 3196 3191 3156 2956 3065 3083 3036 3051 3061 3234 3453 3704 3820 4112 4155 4214 3980 3840 3561 3346 3191 3089 3048 2912 3047 2959 3008 3105 3162 3303 3401 3440 3499 3656 3657 3464 3319 3299 3118 3023 2919 2818 2744 2770 2825 2849 2840 2853 2703 2768 2779 2849 2694 2783 2801 2934 2918 3051 2913 2974 3176 3246 3447 3336 3543 3692 3879 4124 4304 4547 4613 4616 4759 4755 4886 5212 5214 5304 5534 5911 6009 6178 6282 6110 5960 5739 5532 5543 5412 5245 5384 5252 5456 5566 5488 5323 5305 4957 5169 5196 5060 5248 5151 5161 5091 5070 5029 4776 4567 4286 4076 3847 3890 3720 3567 3504 3343 3265 3438 3401 3465 3601 3739 3812 3950 4049 3927 3825 3606 3560 3414 3270 3276 3302 3226 3259 3229 3213 3360 3287 3367 3522 3506 3522 3841 3657 3813 3548 3580 3586 3426 3374 3161 3094 2965 2926 2844 2819 2862 2852 2891 2756 2857 2939 2754 2965 2786 2848 2812 2792 2798 2555 2641 2499 2511 2558 2464 2457 2599 2416 2556 2484 2506 2480 2518 2489 2485 2355 2471 2557 2526 2535 2560 2514 2529 2519 2583 2596 2549 2620 2607 2613 2640 2719 2780 2728 2810 2895 3067 3184 3240 3476 3558 3775 3906 3971 4109 4252 4156 4069 3977 3788 3750 3498 3389 3332 3143 3095 3001 3140 3077 3245 3176 3233 3340 3395 3287 3254 3440 3225 3111 3261 3043 3001 3100 3055 3208 3280 3494 3659 3886 3722 3618 3367 3112 3007 2821 2809 2730 2719 2725 2730 2756 2739 2789 2752 2875 3051 3017 3207 3175 3045 2852 2818 2736 2695 2645 2581 2483 2522 2502 2594 2449 2400 2476 2408 2474 2425 2389 2538 2419 2433 2480 2366 2512 2482 2490 2451 2460 2435 2448 2423 2322 2394 2566 2556 2568 2431 2529 2616 2613 2750 2755 2694 2682 2594 2705 2692 2764 2807 2576 2771 2767 2723 2762 2750 2825 2748 2742 2848 2799 2815 2976 3155 3138 3215 3376 3464 3437 3332 3288 3103 2829 2716 2730 2658 2622 2605 2618 2641 2502 2552 2620 2714 2692 2837 2819 2837 2760 2833 2735 2628 2612 2516 2562 2440 2396 2461 2287 2414 2480 2405 2468 2380 2364 2313 2382 2477 2419 2384 2376 2395 2387 2347 2395 2377 2319 2362 2367 2458 2532 2492 2475 2493 2659 2507 2522 2537 2431 2511 2476 2500 2480 2486 2439 2465 2482 2420 2417 2386 2426 2414 2488 2430 2493 2464 2453 2469 2363 2416 2451 2470 2472 2400 2445 2465 2526 2423 2450 2418 2344 2367 2442 2406 2382 2388 2440 2453 2438 2391 2381 2425 2487 2396 2415 2497 2408 2519 2433 2442 2497 2530 2541 2508 2625 2685 2719 2791 2855 2947 2915 2951 2908 2887 2975 3118 3112 3162 3117 3110 3001 2889 2954 2920 3079 3098 3240 3375 3505 3679 3823 3922 3996 4095 4198 4123 4136 4101 4069 3910 3738 3651 3476 3355 3286 3404 3370 3513 3443 3452 3431 3546 3476 3433 3448 3332 3308 3219 3244 3155 3079 3008 2939 2792 2847 2791 2707 2736 2734 2770 2619 2665 2692 2584 2533 2522 2479 2402 2398 2379 2563 2411 2461 2393 2491 2504 2555 2500 2578 2484 2629 2701 2786 2791 2847 2927 2953 3144 3107 3029 2951 2905 2814 2736 2632 2617 2694 2577 2572 2631 2604 2569 2642 2556 2669 2715 2820 2712 2724 2850 2792 2811 2745 2775 2606 2729 2675 2777 2846 2902 3100 3146 3230 3402 3421 3269 3129 3012 2876 2911 2819 2761 2685 2615 2812 2700 2756 2802 2751 2915 2772 2930 3007 3022 3192 3194 3171 3177 3085 2985 2972 2747 2777 2688 2727 2667 2648 2636 2679 2656 2729 2779 2674 2804 2966 3043 3107 3353 3397 3378 3410 3473 3439 3195 3095 2975 2850 2820 2904 2805 2788 2779 2721 2727 2700 2849 2922 2960 2971 3140 3175 3298 3393 3586 3566 3718 3857 3878 3684 3569 3354 3173 3057 3021 2900 2967 2974 2930 2944 2877 2862 2968 2922 3040 2938 2979 3114 3094 3116 3010 2859 2878 2859 2802 2749 2810 2792 2776 2794 2842 2838 2947 2992 3124 3283 3330 3614 3557 3774 3697 3947 3828 3800 3673 3804 3476 3278 3140 3013 2808 2824 2806 2741 2768 2756 2777 2884 2804 3009 3032 3100 3108 3161 3136 3057 3025 2986 2903 2795 2740 2631 2596 2554 2510 2621 2529 2517 2608 2624 2638 2683 2678 2794 2955 2980 3001 3124 3202 3336 3243 3257 3154 2989 2844 2825 2702 2711 2650 2654 2644 2639 2638 2549 2653 2707 2674 2909 2880 2868 2952 2856 2895 2869 2674 2785 2722 2475 2616 2538 2566 2469 2505 2648 2634 2471 2464 2514 2673 2618 2597 2750 2729 2800 2882 2932 2935 2929 2987 3178 3245 3344 3330 3442 3609 3636 3423 3389 3150 3010 2889 2856 2721 2709 2864 2751 2779 2743 2838 2832 2832 2904 2992 2987 3114 3202 3269 3320 3206 3228 3211 3121 3239 3255 3207 3310 3292 3226 3245 3208 3132 2997 3117 3237 3073 3103 2923 3006 3056 3024 3106 2922 3064 2938 2994 3115 3098 3205 3270 3167 3025 3024 2974 2992 2910 2882 2898 3027 2979 2950 2946 2998 2930 3044 3104 3121 3375 3330 3222 3388 3442 3289 3153 2985 2903 2832 2797 2814 2648 2746 2730 2663 2643 2809 2715 2679 2883 2879 2892 2953 2969 3089 3234 3164 3144 3171 3231 3317 3384 3472 3464 3481 3518 3576 3631 3585 3654 3728 3663 3708 3705 3682 3680 3401 3397 3263 3094 3133 3104 3068 3002 2949 3162 3018 3072 3156 3259 3262 3222 3313 3353 3409 3529 3530 3746 3854 3858 3878 3957 3848 3718 3476 3424 3196 3105 3044 2986 2999 3065 2982 3052 3017 2939 3022 3115 3206 3168 3129 3169 3228 3237 3287 3227 3206 3111 3019 3022 3058 2918 2935 2863 2723 2765 2898 2796 2682 2728 2721 2733 2674 2532 2642 2593 2555 2537 2628 2622 2656 2615 2770 2771 2865 2791 2816 2770 2838 2861 2843 2849 2874 2819 2835 2701 2769 2787 2851 2705 2774 2848 2819 2852 2812 2981 2957 3062 3002 3150 3076 3235 3299 3366 3602 3639 3782 3870 3784 3688 3587 3442 3277 3179 2962 2953 2819 2896 2780 2770 2774 2701 2712 2842 2763 2826 2829 2919 2972 3007 3090 2983 2988 2883 2794 2709 2672 2685 2677 2571 2588 2487 2488 2508 2454 2435 2441 2391 2435 2395 2465 2423 2433 2341 2382 2369 2390 2429 2403 2351 2348 2321 2281 2317 2377 2355 2318 2333 2364 2332 2330 2380 2303 2342 2256 2315 2393 2425 2378 2290 2366 2369 2383 2352 2385 2508 2352 2473 2484 2446 2486 2530 2531 2733 2770 2729 2985 2978 3025 3237 3222 3037 3048 2937 2916 2823 2818 2738 2804 2807 2946 2830 2915 2865 2769 2837 2866 2902 3007 2801 2944 2894 2992 2889 2868 2803 2865 2786 2741 2668 2641 2676 2546 2693 2712 2607 2594 2750 2699 2569 2578 2550 2674 2663 2778 2705 2764 2787 2985 3104 3257 3474 3560 3689 3681 3685 3453 3332 3218 3152 3094 2941 2872 2827 2774 2814 2690 2677 2597 2747 2791 2664 2777 2595 2819 2812 3015 2941 2881 2852 2785 2833 2849 2702 2639 2657 2570 2546 2512 2500 2438 2459 2393 2379 2399 2478 2393 2359 2380 2423 2337 2417 2453 2378 2400 2297 2401 2307 2342 2407 2331 2403 2417 2388 2305 2264 2288 2280 2382 2268 2347 2277 2418 2302 2395 2339 2253 2383 2372 2462 2428 2338 2292 2386 2403 2294 2351 2409 2325 2273 2367 2323 2340 2350 2309 2289 2353 2359 2349 2357 2418 2387 2431 2361 2388 2426 2397 2419 2393 2408 2387 2353 2433 2425 2518 2513 2527 2458 2587 2548 2525 2551 2537 2486 2491 2550 2525 2408 2423 2371 2354 2407 2388 2340 2479 2452 2452 2413 2395 2503 2409 2455 2579 2611 2569 2634 2590 2668 2730 2734 2784 2845 2800 2803 2930 3045 3138 3184 3333 3266 3330 3583 3552 3648 3723 3670 3334 3203 3044 3073 2916 2756 2816 2816 2850 2972 2972 2998 3193 3185 3434 3347 3534 3636 3601 3743 3698 3556 3355 3329 3150 3185 2957 2794 2846 2641 2773 2720 2736 2668 2614 2716 2719 2824 2711 2856 2862 3032 2997 2990 3092 2967 2997 3132 3098 3082 3167 3206 3148 3164 3285 3190 3217 3218 3323 3155 3153 3116 3242 3195 3130 2979 2958 2835 2883 2778 2815 2871 2722 2739 2774 2746 2740 2755 2836 2825 2820 2791 2827 2840 2843 2729 2741 2731 2666 2746 2652 2608 2646 2596 2539 2451 2523 2467 2469 2426 2419 2480 2435 2435 2384 2491 2458 2439 2371 2423 2438 2443 2463 2437 2384 2403 2498 2471 2456 2496 2508 2546 2578 2692 2675 2621 2755 2791 2861 2946 3029 3197 3432 3482 3489 3718 3967 3976 4078 3986 4022 3988 3698 3675 3575 3530 3433 3280 3335 3206 3216 3144 3214 3402 3418 3447 3763 3836 3990 4085 4331 4478 4499 4424 4568 4400 4407 4597 4527 4498 4364 4387 4108 3900 3895 3702 3611 3467 3415 3506 3353 3407 3540 3615 3573 3575 3808 3671 3771 3817 3976 3928 3918 3974 4210 4109 4114 4075 4064 4093 3973 3918 3755 3678 3471 3430 3332 3252 3234 3133 3046 2910 2870 3032 2956 2846 2958 2936 2932 2955 3037 3050 3011 3051 2963 3186 3094 3092 3222 3201 3201 3354 3528 3492 3427 3413</intensities>
			</dataPoints>
			<nonAmbientPoints type="Temperature" unit="K">
[...]
			</nonAmbientPoints>
		</scan>
	</xrdMeasurement>
</xrdMeasurements>