File: powder_X-ray_diffraction/variable-temperature_experiments/NaTaO2F2/raw_data/160°C.xrdml
<?xml version="1.0" encoding="UTF-8"?>
<xrdMeasurements xmlns="http://www.xrdml.com/XRDMeasurement/1.7" xmlns:xsi="http://www.w3.org/2001/XMLSchema-instance" xsi:schemaLocation="http://www.xrdml.com/XRDMeasurement/1.7 http://www.xrdml.com/XRDMeasurement/1.7/XRDMeasurement.xsd" status="Completed">
	<comment>
		<entry>Configuration=XRK900, Owner=User-1, Creation date=12/01/2015 16:52:44</entry>
		<entry>Goniometer=Theta/Theta; Minimum step size 2Theta:0.0001; Minimum step size Omega:0.0001</entry>
		<entry>Sample stage=AP XRK-900 with z-axis; Minimum step size Z:0.001</entry>
		<entry>Diffractometer system=EMPYREAN</entry>
		<entry>Measurement program=C:\PANalytical\Data Collector\Programs\Gwen\NaTaO2F2\NaTaO2F2-Lent.xrdmp, Identifier={FF50B583-C5FF-42DA-A01D-A1FB659EF29A}</entry>
		<entry>Batch program=C:\PANalytical\Data Collector\Programs\Gwen\NaTaO2F2\Thermodiff-Ouail.xrdmp, Identifier={5D65A6B1-42FC-480C-9FBB-D7D88D55EA08}</entry>
	</comment>
	<sample type="To be analyzed">
		<id></id>
		<name></name>
		<preparedBy></preparedBy>
	</sample>
	<xrdMeasurement measurementType="Scan" status="Completed" sampleMode="Reflection">
		<comment>
			<entry>PHD Lower Level = 4.02 (keV), PHD Upper Level = 12.07 (keV)</entry>
		</comment>
		<usedWavelength intended="K-Alpha 1">
			<kAlpha1 unit="Angstrom">1.5405980</kAlpha1>
			<kAlpha2 unit="Angstrom">1.5444260</kAlpha2>
			<kBeta unit="Angstrom">1.3922500</kBeta>
			<ratioKAlpha2KAlpha1>0.5000</ratioKAlpha2KAlpha1>
		</usedWavelength>
		<incidentBeamPath>
			<radius unit="mm">240.00</radius>
			<xRayTube id="1010048" name="Empyrean Cu LFF HR (9430 033 7310x) DK434948">
				<tension unit="kV">45.0</tension>
				<current unit="mA">30.0</current>
				<anodeMaterial>Cu</anodeMaterial>
				<focus type="Line">
					<length unit="mm">12.0</length>
					<width unit="mm">0.4</width>
					<takeOffAngle unit="deg">6.0</takeOffAngle>
				</focus>
			</xRayTube>
			<sollerSlit id="21010001" name="Soller slits 0.02 rad.">
				<opening unit="rad">0.0200</opening>
			</sollerSlit>
			<mask id="22030010" name="Fixed mask 20 mm">
				<width unit="mm">20.00</width>
			</mask>
			<antiScatterSlit id="22010003" name="Fixed slit 1Â°" xsi:type="fixedAntiScatterSlitType">
				<height unit="mm">1.52</height>
			</antiScatterSlit>
			<divergenceSlit id="22010012" name="Programmable divergence slit" xsi:type="fixedDivergenceSlitType">
				<distanceToSample unit="mm">140.00</distanceToSample>
				<angle unit="deg">0.5</angle>
			</divergenceSlit>
		</incidentBeamPath>
		<diffractedBeamPath>
			<radius unit="mm">240.00</radius>
			<antiScatterSlit id="22090010" name="AS slit 8.0 mm (PIXcel)" xsi:type="fixedAntiScatterSlitType">
				<height unit="mm">8.00</height>
			</antiScatterSlit>
			<sollerSlit id="21010001" name="Soller slits 0.02 rad.">
				<opening unit="rad">0.0200</opening>
			</sollerSlit>
			<filter id="20030001" name="Large beta-filter Nickel">
				<material>Ni</material>
				<thickness unit="mm">0.020</thickness>
			</filter>
			<detector id="7010019" name="PIXcel1D-Medipix3 detector" xsi:type="rtmsDetectorType">
				<phd unit="%">
					<lowerLevel>25.0</lowerLevel>
					<upperLevel>75.0</upperLevel>
				</phd>
				<mode>Scanning</mode>
				<activeLength unit="deg">3.3482</activeLength>
			</detector>
		</diffractedBeamPath>
		<scan appendNumber="0" mode="Continuous" scanAxis="Gonio" status="Completed">
			<header>
				<startTimeStamp>2023-01-21T17:16:37+01:00</startTimeStamp>
				<endTimeStamp>2023-01-21T20:17:03+01:00</endTimeStamp>
				<author>
					<name>User</name>
				</author>
				<source>
					<applicationSoftware version="5.5a">Data Collector</applicationSoftware>
					<instrumentControlSoftware version="8.2  20201204">EMPYREAN</instrumentControlSoftware>
					<instrumentID>0000000011159748</instrumentID>
				</source>
			</header>
			<dataPoints>
				<positions axis="2Theta" unit="deg">
					<startPosition>9.99846514</startPosition>
					<endPosition>99.99342261</endPosition>
				</positions>
				<positions axis="Omega" unit="deg">
					<startPosition>4.99923257</startPosition>
					<endPosition>49.99671130</endPosition>
				</positions>
				<positions axis="Z" unit="mm">
					<commonPosition>8.846</commonPosition>
				</positions>
				<commonCountingTime unit="seconds">386.070</commonCountingTime>
				<intensities unit="counts">6792 6742 6863 6889 6972 6856 6733 6890 6582 6639 6832 6704 6565 6643 6668 6726 6731 6485 6525 6624 6672 6628 6508 6388 6561 6610 6704 6539 6626 6453 6581 6507 6581 6667 6563 6381 6520 6471 6465 6473 6580 6574 6387 6482 6483 6564 6314 6599 6517 6318 6580 6559 6582 6467 6381 6583 6637 6735 6467 6731 6665 6748 6601 6732 6731 6788 6774 6845 6949 7040 7011 7229 7350 7576 8014 8565 9246 10222 11532 13645 17391 22562 28611 36928 46262 50456 51289 45378 37146 30382 23644 18084 14242 11181 9317 8180 7623 7203 7049 6880 6699 6817 6522 6561 6543 6500 6444 6428 6310 6275 6430 6322 6349 6225 6224 6379 6287 6167 6325 6142 6297 6095 6134 6123 6183 6164 6188 6203 6241 6147 6172 6076 6175 6089 6095 6109 6033 5940 6117 6066 6035 6119 5901 6088 6045 6085 5988 5899 6032 6009 5932 6039 5943 6161 6035 6027 6078 6072 6024 6025 5885 6014 5947 5875 5867 5918 5954 5867 5930 6016 5878 5856 5879 5826 5731 5728 5927 5925 5937 5723 5839 5730 5799 5799 5710 5786 5831 5753 5982 5839 5921 5935 5888 5767 5749 5601 5819 5708 5891 5819 5571 5770 5667 5759 5764 5599 5653 5705 5678 5781 5745 5598 5709 5691 5629 5609 5747 5611 5638 5586 5606 5617 5646 5723 5610 5754 5622 5537 5448 5638 5590 5491 5582 5541 5676 5575 5621 5634 5487 5488 5504 5613 5527 5584 5604 5619 5585 5567 5445 5687 5425 5510 5489 5594 5534 5716 5555 5593 5608 5636 5460 5425 5415 5457 5454 5547 5509 5643 5489 5472 5466 5393 5323 5561 5444 5444 5532 5491 5348 5430 5410 5282 5324 5481 5333 5454 5267 5509 5454 5383 5406 5381 5258 5219 5370 5356 5253 5233 5349 5350 5441 5287 5343 5273 5264 5312 5282 5350 5191 5261 5252 5297 5150 5244 5043 5259 5219 5425 5032 5162 5314 5293 5237 5388 5138 5301 5229 5212 5320 5384 5196 5124 5271 5229 5217 5092 5177 5234 5194 5147 5186 5118 5128 5147 5127 5189 5156 5127 5137 5242 5172 5099 5128 5269 5064 5170 5155 4999 5252 5164 5033 5121 5172 4968 5184 5024 5172 5099 5113 5008 4987 4995 5115 5047 5028 5101 5016 5175 4967 4974 5084 4930 5026 5116 4933 5145 5024 5099 4954 5030 4953 4855 5110 4939 5080 4986 4987 4913 4973 4833 4995 5024 4962 4929 4827 4935 4865 5079 5026 4951 4968 4942 4925 4873 4903 4954 4924 4776 4966 4955 4964 4808 4915 4884 4978 5033 5062 4811 4787 4825 4799 5033 4764 4861 4988 4816 4948 4834 4921 4816 4935 4874 4784 4976 4885 4920 4850 4914 4856 4794 4928 4803 4838 4766 4824 4860 4835 4774 4775 4912 4939 4960 4965 4974 4982 4959 4939 4990 4937 4855 4951 4911 5063 5025 4899 4944 5056 4874 4925 4903 4915 4978 4908 4921 4926 4921 4990 4990 4994 4998 4874 5050 5011 4927 4942 4968 4861 4857 4832 4912 4857 4771 4834 4853 4751 4811 4610 4716 4850 4638 4636 4715 4734 4594 4657 4724 4628 4576 4508 4762 4582 4698 4840 4806 4750 4732 4729 4580 4679 4794 4738 4610 4636 4595 4595 4651 4684 4725 4613 4553 4613 4759 4748 4655 4697 4783 4678 4713 4781 4804 4861 4682 4904 4957 5082 4794 4695 4921 4753 4586 4815 4708 4613 4594 4584 4586 4545 4605 4526 4558 4529 4576 4518 4641 4545 4452 4419 4503 4583 4634 4598 4613 4553 4569 4640 4605 4584 4539 4578 4658 4812 4684 4846 4792 4705 4602 4597 4529 4533 4553 4402 4421 4346 4428 4344 4349 4472 4388 4518 4447 4609 4388 4381 4399 4468 4420 4316 4280 4330 4422 4432 4337 4421 4527 4415 4342 4229 4335 4417 4222 4464 4316 4427 4337 4448 4396 4350 4335 4349 4363 4304 4458 4433 4501 4266 4334 4274 4479 4313 4331 4438 4343 4432 4509 4393 4403 4413 4508 4500 4406 4400 4397 4430 4361 4516 4340 4240 4342 4357 4269 4327 4418 4210 4338 4331 4348 4317 4167 4288 4213 4299 4313 4247 4247 4465 4486 4534 4469 4678 4628 4611 4592 4542 4603 4640 4646 4638 4702 4747 4760 4751 4770 4685 4757 4589 4627 4631 4766 4593 4641 4595 4799 4767 4827 4752 4889 4853 5091 5226 5130 5309 5490 5710 5744 6016 6271 6688 7513 8127 9770 11859 15102 20659 29528 43509 63631 87546 110098 121953 118413 111246 100588 86334 67408 49907 35743 25196 17997 13426 10076 8217 7114 6458 6093 5795 5518 5350 5318 4983 4886 4828 4796 4754 4661 4572 4579 4559 4524 4530 4458 4515 4440 4610 4769 4777 4703 4799 4886 4815 4673 4652 4528 4423 4481 4504 4310 4451 4408 4326 4341 4235 4287 4090 4231 4249 4197 4201 4314 4179 4259 4215 4069 4238 4244 4218 4091 4052 4165 4022 4183 4089 4241 4066 4070 4076 4147 4188 4112 4217 4099 4156 4024 3933 4073 4094 4228 3972 4046 4100 4058 4106 4239 4167 4031 4100 4102 4037 4080 4005 4022 3983 4034 4112 4058 4099 4021 4049 4005 4006 3951 3977 3961 4107 4100 4106 4122 3992 4003 3958 3919 4005 4066 4134 3937 4033 4001 3946 3957 3964 3925 4063 4051 3991 3905 3984 3820 3932 3926 4025 3903 3862 3911 3828 3972 4028 3953 4028 3933 3930 3931 3761 4100 3953 3982 4089 3978 4094 4170 4242 4261 4296 4258 4403 4455 4394 4204 4083 4007 4184 4085 4087 3897 3956 3950 3975 4088 4215 4139 4047 4019 3952 4024 3963 3964 4037 4021 4093 4131 4060 3998 3930 4233 4349 4542 4652 5191 5825 6878 8752 11548 15529 18744 19927 18381 16734 15993 15659 12880 9664 7805 6828 5907 5010 4473 4295 4117 4029 3941 4080 3967 3905 3897 3949 3831 3917 3981 3835 3883 3941 3899 3954 3861 3845 3836 3826 3832 3949 3852 3972 3858 3939 3860 3915 3854 3782 3773 3745 3746 3785 3836 3819 3765 3659 3770 3738 3787 3664 3705 3695 3631 3622 3660 3656 3702 3722 3824 3694 3675 3711 3765 3859 3813 3803 3638 3703 3747 3881 3739 3794 3756 3789 3815 3901 3792 3785 3894 3837 3746 3839 3874 3774 3729 3881 3805 3826 3917 4007 3955 3817 3912 3887 4015 3946 4055 3987 4061 3999 3966 3949 3845 3954 4020 4098 3952 4030 3994 4084 4125 4067 4301 4354 4395 4349 4389 4581 4602 4717 4630 4827 4810 4784 4970 5290 5497 6020 6835 8738 11852 16830 23361 31510 39053 44514 45139 41027 36657 33100 30398 25730 19939 16069 14456 15188 17401 24351 33623 40993 46754 49065 47628 43956 39534 34493 29101 22944 17393 13109 9874 7535 6292 5403 4899 4682 4483 4497 4313 4357 4088 3972 4010 3929 3977 3830 3888 3703 3820 3741 3858 3665 3750 3834 3851 3744 3710 3707 3728 3664 3699 3813 3737 3804 3896 3893 3985 3930 3929 3902 3817 3732 3836 3610 3700 3709 3666 3752 3647 3605 3612 3562 3713 3814 3488 3585 3687 3626 3471 3703 3595 3639 3578 3678 3621 3650 3723 3669 3710 3583 3646 3569 3746 3662 3673 3557 3652 3468 3584 3626 3458 3494 3678 3573 3603 3462 3584 3517 3538 3546 3454 3470 3531 3492 3653 3663 3522 3516 3518 3490 3476 3555 3467 3485 3510 3599 3480 3468 3448 3501 3614 3543 3527 3515 3676 3640 3690 3867 3926 3981 4000 4143 4117 4042 3987 3871 3854 3768 3734 3867 3842 3737 3523 3561 3646 3672 3587 3512 3490 3467 3580 3590 3526 3549 3412 3468 3566 3406 3458 3400 3536 3500 3393 3374 3536 3544 3462 3416 3550 3503 3399 3485 3545 3384 3386 3423 3462 3552 3470 3607 3667 3624 3669 3715 3607 3656 3600 3667 3600 3561 3646 3673 3668 3604 3665 3669 3665 3774 3605 3595 3664 3733 3680 3565 3734 3659 3606 3677 3650 3741 3725 3756 3758 3694 3638 3581 3705 3703 3610 3719 3645 3692 3643 3727 3678 3773 3876 3827 3841 3861 4012 4049 3980 4353 4252 4407 4544 4719 4964 5006 5240 5409 5821 6293 6749 7706 8464 9940 12769 17434 25241 37973 54484 71081 81544 82409 75957 68201 61355 55766 49602 42201 32808 23721 16769 12233 9428 7664 6661 5863 5516 4973 4649 4528 4339 4303 4173 3912 3839 3836 3816 3819 3849 3735 3718 3655 3593 3639 3640 3548 3615 3620 3608 3765 3809 3758 3974 4052 3861 3990 3838 3828 3806 3757 3727 3856 3765 3680 3659 3624 3594 3655 3683 3637 3594 3690 3543 3603 3545 3711 3604 3566 3534 3530 3558 3547 3558 3470 3647 3660 3548 3516 3520 3510 3563 3522 3461 3655 3606 3538 3479 3591 3502 3637 3486 3488 3653 3713 3569 3641 3689 3811 3747 3862 3803 3966 3970 4238 4247 4318 4526 4570 4821 5218 5771 6964 9394 13030 19252 26390 32273 34435 32245 28205 25709 24544 23874 22088 19526 16970 16152 16692 17938 19382 19838 19430 17446 15580 14153 13118 11960 10466 8570 7110 5944 5018 4315 3967 3842 3752 3624 3635 3492 3573 3427 3521 3541 3418 3556 3452 3317 3389 3341 3408 3404 3417 3320 3383 3343 3435 3412 3405 3374 3338 3451 3408 3305 3376 3402 3348 3337 3267 3252 3263 3356 3259 3238 3286 3259 3290 3240 3187 3260 3436 3384 3337 3346 3259 3298 3274 3209 3170 3224 3254 3353 3260 3349 3315 3258 3291 3236 3295 3223 3243 3352 3319 3189 3207 3227 3225 3207 3152 3260 3227 3333 3237 3207 3209 3199 3283 3213 3157 3156 3142 3216 3120 3123 3157 3190 3133 3117 3151 3303 3294 3222 3169 3203 3188 3053 3247 3308 3243 3215 3198 3141 3158 3178 3099 3178 3123 3181 3198 3179 3130 3024 3144 3162 3167 3165 3009 3150 3087 3134 3082 3162 3113 3134 3093 3034 3154 3024 3120 3128 3128 3134 3029 3158 3116 3068 3082 3047 3224 3219 3184 3033 3064 3090 3096 3063 3153 3202 3120 3042 3138 3106 3127 3137 3111 3117 3074 3178 3114 3176 3211 3134 3142 3081 3126 3028 3146 3173 2978 3066 3137 3139 3151 3044 3048 3137 3128 3093 3032 3172 3171 3154 3215 3213 3088 3157 3113 3138 3151 3153 3128 3321 3199 3268 3195 3201 3255 3227 3232 3251 3248 3255 3167 3166 3114 3259 3191 3292 3187 3309 3232 3306 3241 3404 3397 3563 3364 3464 3575 3742 3625 3791 3783 3981 3869 4259 4797 5618 7621 11052 16298 21091 21867 19345 15895 13162 12901 13704 13793 12257 10128 7888 6339 5099 4437 4080 3859 3765 3741 3648 3692 3683 3720 3678 3850 3730 3790 3997 4016 4089 4174 4260 4461 4807 5026 5571 6465 8119 11735 16556 24039 31257 35420 34485 29827 25712 22974 22251 21934 20661 18320 14890 11586 8712 6892 5638 5054 4684 4478 4437 4496 4290 4367 4389 4382 4580 4601 4884 5150 5705 6518 7912 10297 13806 18068 22560 26768 29472 30096 28184 25462 23484 23251 24878 27378 28483 26154 21045 16497 13447 12055 11403 11304 10132 8602 7082 6094 5097 4451 3939 3731 3669 3447 3547 3498 3325 3342 3346 3325 3298 3114 3257 3150 3203 3290 3374 3162 3212 3169 3274 3123 3251 3128 3228 3203 3188 3252 3052 3112 3235 3189 3210 3206 3252 3358 3257 3362 3401 3460 3446 3482 3619 3732 3839 4231 5011 6177 8100 10619 13616 14837 13474 11682 9866 8798 8804 9293 9143 8109 6838 5699 4747 3996 3779 3574 3451 3304 3275 3210 3214 3200 3386 3531 3583 3726 3799 3596 3463 3434 3349 3254 3338 3299 3338 3209 3141 3027 3021 3031 3039 2994 2942 2985 2855 2901 2844 2920 3001 2983 2968 2939 2782 2968 3013 2967 3006 2880 3039 3015 2978 2922 2998 2919 3053 3034 2973 2887 2800 2998 2931 2856 2962 2975 2972 2951 3031 2929 2883 2925 2937 2947 2941 2990 2878 2909 2991 2968 2927 2910 2700 2862 2931 2861 2907 2923 2939 2924 2931 2960 3024 2919 2977 3075 2971 3008 3023 2865 2958 2912 3034 3012 3129 2928 2961 3022 2996 3004 2906 2936 2940 3023 3011 2942 2932 3000 2912 2958 2964 2919 2953 2901 2880 2876 3003 2990 2982 2998 3016 3029 3151 3110 3059 3105 3189 3252 3403 3464 3864 4747 5976 7635 9041 9761 9656 8558 7066 6207 6145 6459 6780 6527 5937 4941 4237 3697 3428 3306 3164 3192 3068 3086 2988 2975 2923 2815 2972 3179 2998 3013 3043 2921 2932 2982 2949 3077 3006 3051 2999 3023 3084 3001 3118 3120 3094 3143 3263 3410 3550 3723 4160 4786 6016 7315 8695 9696 10088 10052 9065 8117 7530 7127 6916 6720 6522 6083 5313 4692 4134 3696 3326 3218 3149 3111 3200 3283 3518 3627 3630 3697 3520 3416 3471 3313 3441 3473 3351 3165 3153 2880 2935 2921 2873 2882 2842 2760 2784 2849 2771 2800 2858 2916 2764 2712 2795 2833 2724 2795 2794 2788 2701 2648 2729 2782 2726 2815 2663 2773 2797 2738 2848 2791 2743 2750 2741 2772 2723 2748 2761 2731 2786 2715 2786 2796 2747 2778 2731 2665 2687 2689 2845 2692 2824 2746 2685 2705 2713 2827 2823 2753 2711 2783 2734 2807 2796 2688 2763 2729 2620 2790 2839 2733 2705 2723 2655 2771 2816 2813 2810 2789 2717 2804 2758 2844 2752 2808 2763 2746 2629 2737 2754 2752 2748 2698 2737 2781 2737 2649 2736 2725 2694 2802 2721 2713 2716 2777 2703 2713 2740 2817 2787 2837 2681 2709 2808 2665 2709 2662 2746 2713 2750 2728 2787 2775 2751 2795 2767 2808 2739 2797 2840 2936 2908 2798 2850 2988 3139 3145 3291 3769 4160 4594 5027 5201 5222 4895 4506 4173 4141 4096 4172 4018 4033 3984 3658 3435 3241 3152 3214 3211 3307 3504 3681 4087 4715 5818 6741 7603 7355 6750 6105 5540 5169 5303 5436 5676 5356 4976 4718 4243 3782 3624 3393 3417 3551 3698 3897 4388 5170 6574 8186 9627 9961 9101 7555 6446 5793 5686 6109 6659 6611 6016 5280 4455 3897 3451 3268 3177 3125 2985 3021 2870 2927 2917 2942 2966 2848 2882 2870 2922 2989 2929 2936 2960 2950 2984 3115 3069 3146 3227 3370 3443 3559 3792 4022 4386 5206 6386 7519 9335 10791 11324 11311 10286 8599 7721 7423 7875 8798 10217 11704 13295 14261 14333 13276 11404 9737 8735 9145 10399 12836 15025 16133 15741 14065 11369 9192 7709 7259 7300 7630 7780 7316 6546 5420 4477 3952 3589 3204 3066 3020 3024 2978 2852 2798 2856 2857 2837 2785 2687 2767 2828 2752 2846 2800 2788 2684 2742 2707 2606 2799 2674 2791 2816 2804 2650 2598 2668 2727 2700 2662 2709 2703 2610 2679 2829 2639 2713 2635 2660 2685 2681 2713 2750 2678 2698 2697 2803 2752 2519 2742 2704 2651 2677 2752 2659 2615 2601 2665 2628 2739 2653 2711 2549 2599 2653 2690 2660 2747 2676 2669 2686 2685 2673 2683 2696 2576 2766 2730 2637 2638 2685 2648 2681 2616 2594 2729 2667 2600 2654 2766 2624 2730 2719 2826 2669 2761 2685 2655 2778 2699 2763 2623 2800 2743 2681 2732 2688 2800 2740 2669 2744 2759 2757 2711 2714 2702 2596 2639 2662 2632 2689 2631 2661 2660 2573 2687 2548 2635 2648 2591 2629 2593 2629 2656 2667 2616 2632 2711 2666 2775 2802 2945 3055 3197 3368 3480 3328 3240 3129 3073 3094 3144 3127 3166 3054 3031 2888 2889 2847 2747 2667 2654 2740 2651 2712 2641 2680 2651 2668 2742 2688 2619 2576 2619 2642 2704 2592 2683 2418 2531 2611 2618 2585 2570 2644 2675 2655 2616 2670 2661 2624 2687 2673 2579 2754 2722 2748 2769 2935 2843 3075 3283 3445 3659 4019 4107 3917 3631 3533 3325 3227 3297 3282 3391 3370 3275 3298 3055 2947 2885 2962 2876 2815 2840 2990 3043 3170 3317 3585 4195 4594 5139 5636 5846 5502 5231 4588 4147 4076 4001 4130 4145 4358 4167 3743 3520 3279 3079 2963 2806 2701 2722 2702 2702 2676 2832 2747 2825 2736 2615 2686 2707 2640 2635 2663 2534 2646 2595 2665 2733 2628 2564 2573 2749 2719 2607 2611 2710 2596 2769 2587 2550 2689 2637 2518 2743 2648 2705 2631 2620 2541 2688 2719 2651 2728 2723 2650 2760 2768 2866 2822 2842 2888 2886 2847 2985 2866 2901 3094 3245 3427 3736 4091 4996 6549 8911 11393 12382 11351 9296 7076 5837 5196 5247 6090 7171 7545 7195 6286 5112 4181 3681 3170 3075 2908 2929 2868 2805 2737 2796 2780 2713 2763 2759 2743 2760 2669 2775 2796 2664 2857 2809 2789 2804 2875 2890 2801 2898 2844 2905 2931 3151 3276 3566 4278 5275 6543 7416 7432 6627 5527 4444 4078 4009 4193 4793 5133 5209 5014 4327 3683 3420 3099 3105 3106 2831 2906 2790 2887 2826 2749 2701 2738 2759 2706 2664 2739 2725 2651 2752 2661 2690 2805 2802 2730 2903 2766 2772 2755 2807 2880 2878 2843 2860 2872 2866 2865 2986 2994 3014 3172 3385 3526 3733 4262 4997 5844 6620 7457 8439 8749 8320 7528 6064 5396 5292 5157 5502 5716 5922 5796 5434 4626 4041 3662 3371 3232 3195 3108 2975 2954 2959 3091 3028 3000 3154 3140 3242 3216 3247 3305 3262 3211 3334 3366 3622 3557 3755 3863 3828 4137 4536 5033 5683 6707 8115 10447 13451 16818 19541 20453 18883 16173 13079 10892 10084 10107 10763 11821 12284 12050 10753 8691 7352 6073 5157 4688 4168 3862 3669 3575 3496 3366 3406 3307 3214 3255 3197 3234 3237 3338 3339 3322 3388 3328 3505 3698 4063 4657 5512 6900 8821 11165 12430 13121 13228 13406 12872 12297 11452 10833 10221 9733 9268 8879 8545 8503 8202 7546 6815 6188 5313 4673 3999 3890 3990 4151 4412 5164 5970 7471 9721 11849 13465 13453 11879 9759 7800 6639 6214 6536 7132 7909 8380 8054 7426 6109 5098 4312 3718 3621 3359 3237 3097 3023 3016 3118 2952 2878 2862 2900 2872 2849 2770 2870 2801 2801 2907 2879 2781 2886 2810 2742 2835 2824 2886 2937 2870 3088 3245 3437 3515 3529 3500 3422 3336 3201 3103 3159 3209 3173 3252 3397 3374 3404 3322 3389 3481 3438 3323 3380 3313 3226 3220 3280 3327 3279 3436 3416 3332 3447 3416 3428 3518 3558 3782 3921 4171 4591 5203 6369 7802 10040 13384 16972 18989 19154 17331 14698 12035 10670 9479 9667 10891 11998 12795 12054 10782 9300 7937 6602 5769 5326 4891 4650 4244 4025 3739 3735 3432 3537 3520 3419 3466 3408 3295 3529 3657 3846 4036 4382 4892 5461 6500 7758 9077 10314 11098 11328 10635 9147 7705 6869 6354 6277 6658 6907 7250 7215 7020 6105 5374 4697 4132 3753 3563 3310 3202 3073 3126 2958 2898 2905 2870 2926 2861 2871 2818 2800 2884 2857 2831 2795 2791 2818 2751 2835 2768 2744 2789 2848 2778 2854 2830 2893 2888 2886 2894 2936 2931 2918 2944 2990 2910 2985 2983 3150 3256 3441 3688 3989 4745 5808 7191 8692 9309 8783 7520 6135 5161 4474 4378 4546 5066 5544 6137 6128 5608 4946 4426 4088 3881 3849 3778 3627 3467 3281 3062 3054 2960 3039 3149 2997 3146 3136 3186 3095 2975 2856 2924 2773 2859 2767 2806 2746 2845 2794 2711 2862 2814 2806 2779 2719 2754 2746 2775 2759 2719 2747 2686 2830 2752 2798 2739 2870 2713 2814 2743 2754 2814 2803 2930 2867 2970 2976 3058 2954 3047 3078 3036 3212 3378 3489 3862 4225 4973 6096 7602 8726 9884 10425 10776 10751 9696 8506 7272 6247 5940 6033 6321 6860 6771 6751 6683 6134 5436 4621 3978 3518 3428 3198 3217 3238 3158 3276 3548 3765 3951 4466 4682 5249 5543 5905 5833 5799 5891 5667 5104 4652 4523 4402 4273 4248 4393 4195 4223 4081 4059 3626 3392 3300 3052 2921 2853 2784 2865 2784 2715 2760 2800 2694 2728 2757 2735 2744 2717 2664 2833 2903 2855 3036 3027 3262 3505 3985 4111 4361 4340 4096 3939 3694 3448 3269 3249 3364 3554 3517 3570 3580 3518 3361 3081 2969 2947 2886 2811 2775 2697 2777 2747 2678 2690 2656 2637 2667 2765 2642 2620 2633 2800 2643 2671 2633 2551 2623 2726 2601 2617 2630 2679 2657 2626 2526 2640 2630 2733 2643 2682 2639 2752 2750 2701 2753 2747 2858 2812 3064 3000 2872 3068 3051 2969 2937 3060 2863 2905 2887 2842 2815 2863 2839 2827 2769 2749 2766 2748 2840 2760 2748 2696 2631 2626 2697 2648 2718 2742 2668 2707 2651 2598 2634 2675 2633 2610 2653 2739 2656 2690 2635 2681 2606 2664 2644 2651 2618 2739 2744 2630 2753 2758 2677 2761 2757 2739 2658 2669 2700 2821 2604 2778 2743 2786 2855 2836 2798 2907 2997 2950 2994 3101 3124 3174 3301 3427 3671 4020 4390 4992 5917 7451 9146 10734 11749 11324 10103 8772 7033 6307 5617 5593 5836 6447 7137 7548 7749 7008 6421 5572 4768 4078 3836 3657 3617 3557 3473 3576 3642 3649 3650 3470 3318 3180 3083 2969 2977 3072 3117 3020 3106 3070 2993 2981 3050 2943 2869 2901 2909 3021 2962 2992 3022 2964 3060 3043 3066 3091 3142 3196 3364 3457 3797 4176 4703 5693 7018 8786 10620 12216 13404 13687 12960 11312 9608 7955 7279 7276 7688 8438 9193 9638 9809 9521 8328 7297 6238 5320 4835 4619 4286 4254 4173 4011 3770 3442 3284 3235 3113 3091 3063 3018 2907 2925 2923 2912 2845 2849 2945 2980 2970 2968 3004 3084 3181 3039 3182 3195 3252 3303 3506 3597 3812 4139 4718 5459 6223 7022 7704 8448 8791 9297 9593 9544 9513 8966 8386 7813 7486 7121 7006 7221 7561 7842 8401 8916 9244 9363 8813 7645 6702 5780 4958 4589 4386 4236 4505 4580 4711 4924 4742 4420 4149 3803 3536 3306 3285 3150 3078 3105 3114 2982 3034 3003 2993 3135 2970 3070 3006 3147 3197 3390 3486 3692 3962 4445 5165 6082 7209 8496 9070 8892 7801 6725 5737 5152 4854 4622 4886 5309 5953 6778 7191 6692 6063 5527 4935 4663 4202 4117 4125 3912 3810 3732 3687 3532 3420 3343 3270 3433 3207 3247 3352 3106 3160 3118 3170 3040 3212 3041 3154 3248 3372 3527 3614 3800 4072 4480 5078 5753 6447 7338 7949 8375 8575 8100 7384 6532 5748 5524 5419 5622 5994 6648 7370 8385 9484 10559 11005 10939 10294 8792 7060 6108 5213 4730 4855 4906 5239 5877 6477 6505 6702 6417 5907 5941 5905 6220 7020 8032 8908 9232 9474 8873 7826 6637 5761 5141 4942 4886 5134 5416 5797 6022 6194 5987 5587 4839 4399 4093 3590 3362 3252 3226 3101 3141 3120 3026 2956 3106 3078 3133 3066 3168 3105 3272 3318 3414 3623 3948 4415 4919 5648 6262 7144 7943 8347 8710 8507 8098 7575 7324 6962 7003 7273 7492 7963 8636 9240 9774 10530 11686 12751 12820 12220 10334 8704 7435 6582 6052 5442 5434 5507 6126 6597 7064 6875 6313 5461 4697 4276 3758 3426 3323 3163 3145 3085 3009 2975 2801 2956 2939 2963 2876 2804 2896 2899 2932 2829 2822 2899 2941 2926 2943 2970 3041 3061 3004 2992 2962 3194 3276 3329 3338 3394 3643 3915 4292 4746 5661 6682 7822 9409 10827 11336 11399 10953 10883 10685 10253 10012 9408 8981 8454 8168 8472 8478 8491 8325 7982 8209 8176 7853 7693 7287 7033 6223 5835 5321 5069 4897 5015 5176 5208 5576 5585 5726 5716 5646 5647 5097 4583 4322 3987 3604 3751 3656 3837 3749 3655 3871 3767 3620 3457 3192 3018 2842 2768 2661 2798 2644 2629 2556 2586 2651 2676 2575 2630 2642 2627 2488 2570 2571 2527 2571 2581 2481 2604 2590 2645 2524 2611 2613 2614 2560 2600 2585 2570 2642 2605 2547 2618 2458 2537 2544 2570 2434 2585 2528 2432 2554 2571 2531 2506 2480 2535 2517 2487 2476 2546 2481 2517 2465 2496 2450 2535 2499 2495 2504 2408 2403 2579 2449 2585 2505 2439 2483 2532 2473 2556 2558 2471 2658 2606 2550 2568 2588 2439 2587 2584 2503 2598 2400 2470 2514 2615 2487 2435 2487 2557 2492 2578 2540 2528 2483 2490 2521 2605 2523 2425 2458 2402 2475 2451 2428 2430 2454 2520 2488 2461 2461 2479 2449 2335 2498 2471 2391 2410 2433 2464 2505 2522 2374 2545 2389 2513 2507 2441 2500 2490 2470 2387 2531 2479 2427 2361 2484 2469 2460 2464 2521 2586 2532 2547 2521 2536 2487 2473 2649 2562 2548 2620 2586 2623 2741 2757 2795 2825 2938 3031 3061 3085 3332 3440 3720 4026 4053 4181 3982 3631 3539 3220 3142 3159 3052 3009 3024 2984 3209 3292 3388 3324 3194 2936 2952 2922 2782 2769 2609 2667 2712 2665 2730 2791 2907 2917 3018 3183 3246 3575 3875 4198 4382 4392 4294 4375 4197 4187 4246 4349 4503 4434 4375 4225 4085 3951 3864 3698 3622 3496 3410 3387 3334 3373 3316 3227 3215 3001 2818 2692 2659 2578 2584 2582 2460 2533 2448 2447 2400 2523 2372 2422 2376 2513 2467 2439 2479 2401 2496 2505 2479 2396 2373 2502 2464 2429 2583 2511 2439 2432 2464 2680 2727 2713 2749 2693 2711 2695 2679 2665 2708 2640 2695 2678 2682 2658 2713 2733 2860 2750 2790 2651 2734 2563 2590 2573 2554 2630 2532 2524 2535 2501 2495 2602 2534 2475 2544 2353 2299 2418 2479 2415 2456 2335 2433 2394 2419 2374 2411 2352 2350 2363 2373 2464 2293 2333 2290 2343 2377 2308 2465 2482 2427 2406 2467 2438 2373 2329 2399 2364 2375 2353 2386 2422 2412 2439 2376 2424 2381 2406 2388 2438 2433 2453 2424 2396 2415 2411 2419 2425 2431 2417 2347 2497 2386 2353 2393 2358 2301 2363 2475 2359 2352 2327 2330 2420 2389 2399 2267 2250 2321 2363 2270 2350 2352 2439 2400 2422 2435 2459 2439 2500 2491 2538 2604 2623 2579 2317 2511 2429 2390 2379 2518 2433 2410 2499 2518 2435 2555 2521 2587 2500 2541 2577 2456 2445 2465 2434 2511 2396 2488 2424 2296 2384 2375 2441 2411 2426 2524 2383 2370 2318 2405 2395 2355 2285 2438 2380 2287 2316 2411 2381 2332 2295 2321 2351 2333 2316 2417 2374 2373 2418 2421 2377 2295 2402 2432 2341 2352 2341 2405 2312 2345 2335 2426 2390 2330 2387 2407 2365 2433 2403 2515 2425 2454 2431 2424 2314 2400 2382 2347 2379 2380 2444 2295 2336 2377 2400 2386 2408 2343 2383 2495 2324 2487 2434 2391 2471 2411 2366 2512 2470 2471 2455 2509 2592 2613 2824 2881 3018 3279 3505 3723 3620 3543 3299 3042 2767 2768 2665 2715 2780 2713 2871 2945 3072 3065 3291 3243 3375 3220 3096 3096 3059 2872 2798 2751 2788 2917 2757 2699 2721 2649 2696 2764 2753 2773 2796 2826 2808 2788 2865 2851 2985 3094 3511 4027 4594 4921 5264 5157 4660 4260 3633 3221 2921 2896 2898 2888 2874 3085 3244 3559 3755 3875 3744 3476 3265 2879 2834 2738 2576 2525 2523 2574 2498 2557 2554 2531 2548 2522 2464 2578 2528 2526 2571 2633 2671 2649 2753 2960 2969 3239 3594 3747 3916 3879 3586 3378 3146 2988 3012 2763 3010 3104 3072 3413 3441 3878 4136 4307 4344 4263 3959 3896 3887 3687 3362 3258 3210 3097 3113 3071 3131 3249 3257 3298 3311 3377 3332 3372 3447 3394 3425 3654 3746 4181 4421 4820 5304 5798 6144 6715 6856 6813 6329 5824 5070 4768 4470 4378 4423 4526 4821 5041 5542 5850 6105 6044 6020 5406 5014 4347 4020 3882 3743 3621 3736 3707 3707 3813 3971 3795 3721 3559 3400 3210 3146 3148 3001 3241 3356 3424 3639 4056 4450 4874 5049 5155 5048 4593 4328 3960 3608 3578 3522 3475 3425 3514 3661 3652 3772 3958 3826 3852 3634 3595 3375 3220 3132 3159 3027 3069 3167 3135 3197 3157 3372 3408 3808 3803 3963 4052 4217 4212 4319 4370 4355 4237 3968 3937 3751 3621 3501 3459 3522 3627 3711 3893 3999 4161 4473 4987 5648 5982 5974 5500 4669 4135 3580 3296 3132 2944 2927 2903 2951 3165 3346 3648 3733 3999 3889 3639 3303 3078 2905 2949 2710 2865 2780 2841 2749 2856 3025 3089 3167 3453 3774 4005 4255 4002 3904 3628 3384 3028 3105 3100 3139 3134 3262 3475 3661 3762 4037 4134 4232 4212 3988 3905 3882 3746 3544 3244 3167 3155 2976 2942 2905 2901 3072 2942 3056 3061 2938 2907 2966 2887 2804 2794 2765 2719 2582 2646 2666 2574 2572 2546 2532 2561 2608 2497 2543 2474 2530 2539 2580 2542 2560 2503 2574 2618 2553 2609 2753 2736 2789 2902 3003 3114 3362 3549 3863 4052 4240 4275 4134 3866 3637 3406 3141 3026 2868 2935 2886 3014 3017 3068 3224 3282 3410 3352 3271 3143 2961 2978 2832 2770 2691 2658 2676 2651 2540 2670 2790 2998 3044 3309 3433 3623 3840 3992 4194 4254 4229 4059 4021 3698 3549 3352 3109 3092 3120 3034 3150 3256 3336 3398 3655 3536 3470 3517 3496 3572 3742 3769 3813 3877 4095 4048 4033 4025 3988 3736 3533 3578 3455 3557 3479 3390 3395 3355 3334 3315 3329 3285 3253 3330 3247 3313 3243 3061 3042 3126 2980 3089 3038 2951 2991 3084 3114 3339 3591 3996 4336 4949 5237 5397 5441 5304 5240 5432 5353 5307 5146 4878 4326 3997 3817 3810 3799 3792 3929 4133 3952 4026 3847 3931 3836 3919 3741 3615 3398 3185 2949 2826 2779 2654 2571 2477 2607 2457 2347 2406 2448 2452 2404 2473 2390 2402 2512 2477 2362 2405 2374 2439 2351 2406 2386 2485 2384 2405 2408 2401 2368 2326 2369 2275 2428 2424 2345 2337 2391 2360 2369 2349 2395 2383 2420 2441 2426 2347 2357 2415 2299 2374 2339 2338 2246 2342 2322 2379 2381 2392 2418 2295 2277 2442 2493 2392 2309 2379 2443 2386 2417 2405 2345 2448 2384 2307 2510 2375 2382 2438 2301 2454 2432 2438 2444 2399 2385 2468 2328 2440 2443 2538 2499 2518 2486 2554 2458 2449 2488 2489 2589 2485 2528 2475 2458 2445 2533 2559 2484 2440 2495 2484 2396 2428 2473 2354 2437 2435 2499 2422 2518 2531 2584 2566 2531 2645 2735 2739 2717 2764 2843 2873 2924 2982 2898 2967 3055 2868 2988 2919 2942 3020 3125 3188 3241 3493 3753 4084 4275 4569 4635 4816 4786 4679 4593 4442 3952 3725 3491 3349 3179 3181 3210 3212 3356 3284 3437 3419 3639 3571 3622 3469 3208 3166 3084 2910 2808 2792 2690 2623 2670 2623 2584 2519 2597 2633 2641 2583 2576 2532 2562 2718 2677 2857 2894 2982 3106 3303 3483 3706 3933 4102 4305 4327 4510 4332 4245 4166 3903 3614 3437 3259 3068 3080 3027 3076 3202 3296 3331 3446 3430 3480 3330 3387 3181 3202 3046 2846 2793 2706 2644 2577 2501 2531 2592 2508 2515 2464 2546 2690 2621 2735 2740 2856 3050 3162 3083 3122 3133 3000 2809 2814 2779 2739 2653 2611 2553 2651 2598 2565 2771 2626 2692 2702 2688 2873 2679 2784 2723 2555 2533 2506 2641 2582 2559 2577 2640 2761 2867 2875 2923 2923 2933 2844 2828 2638 2567 2605 2627 2577 2627 2511 2521 2758 2670 2755 2739 2752 2851 2789 2920 2968 3004 3143 3280 3495 3414 3441 3397 3423 3538 3449 3577 3586 3462 3382 3350 3237 3098 3113 3062 3160 3198 3253 3268 3429 3250 3385 3471 3474 3612 3695 3810 3954 4055 4190 4220 4277 4153 4224 4148 4053 3910 3719 3751 3767 3855 3908 3939 4043 4016 4131 4222 4304 4159 4188 4234 4074 3887 3586 3423 3354 3215 3175 3283 3329 3279 3139 3149 3172 3158 3151 3092 3091 3040 3043 3018 2947 2976 3059 2971 3124 3196 3384 3554 3846 4015 4205 4173 4061 3927 3642 3399 3214 3151 3123 3060 3023 2961 3008 3010 3215 3208 3418 3544 3540 3650 3541 3641 3304 3225 3138 2957 2861 2820 2730 2751 2818 2771 2762 2815 2817 2717 2873 2807 2746 2872 2913 2803 2982 2920 3066 3114 3128 3346 3333 3548 3722 3857 4063 4366 4500 4633 4642 4653 4638 4519 4606 4689 4694 4767 4993 5207 5175 5535 5900 6217 6329 6404 6392 6056 5986 6038 5806 5869 5652 5357 5190 5049 4832 4743 4752 4579 4781 5056 5153 5357 5289 5194 5073 5077 4886 4389 4221 4096 3879 3687 3680 3494 3414 3379 3423 3435 3542 3725 3872 4085 4021 4089 3930 3813 3478 3427 3336 3050 3201 3142 3313 3372 3298 3399 3471 3412 3463 3546 3690 3601 3768 3791 3649 3660 3503 3396 3481 3258 3134 3122 2966 2917 2898 2927 2838 2851 2884 2880 2818 2820 2846 2867 2912 2890 2834 2771 2735 2683 2546 2478 2570 2462 2535 2510 2480 2511 2475 2503 2544 2538 2543 2460 2462 2530 2385 2449 2535 2492 2531 2466 2612 2563 2495 2518 2677 2626 2609 2634 2690 2765 2840 2863 2891 2994 3170 3340 3395 3644 3674 3940 4001 4051 4137 4064 3971 3769 3741 3592 3558 3436 3329 3297 3311 3301 3257 3227 3280 3263 3218 3370 3250 3178 3318 3263 3258 3090 3108 2942 2912 2835 3010 2932 2994 2965 3137 3386 3547 3783 3851 3680 3435 3288 3023 2859 2787 2705 2715 2719 2652 2794 2664 2692 2718 2846 2822 3006 2932 3071 2994 2898 2793 2688 2604 2697 2618 2627 2478 2626 2532 2511 2504 2508 2523 2465 2410 2421 2446 2443 2454 2402 2466 2458 2405 2436 2475 2488 2435 2468 2527 2526 2501 2539 2620 2625 2635 2671 2773 2708 2703 2700 2679 2641 2779 2709 2774 2593 2685 2658 2656 2770 2737 2741 2816 2741 2865 2705 2882 2923 3047 3079 3345 3391 3522 3413 3324 3265 2971 2901 2820 2674 2638 2569 2524 2672 2631 2645 2570 2616 2727 2708 2895 2785 2803 2912 2728 2636 2568 2611 2511 2506 2592 2397 2430 2506 2433 2470 2376 2315 2438 2378 2413 2366 2432 2442 2377 2470 2440 2505 2439 2348 2376 2389 2371 2325 2382 2436 2514 2421 2569 2425 2458 2585 2559 2506 2648 2613 2583 2533 2488 2438 2429 2402 2426 2420 2426 2296 2483 2434 2419 2459 2479 2407 2434 2483 2518 2505 2435 2477 2478 2469 2434 2559 2468 2550 2585 2457 2428 2444 2402 2462 2403 2428 2375 2315 2421 2490 2411 2453 2487 2441 2393 2427 2468 2491 2573 2471 2566 2589 2597 2563 2692 2693 2776 2785 2886 2889 2927 2986 2960 2963 3008 2998 3115 3109 3154 3189 3048 2972 2946 3004 3073 3163 3225 3401 3588 3744 3821 4052 4224 4221 4178 4263 4161 4154 4122 3890 3853 3625 3469 3415 3369 3435 3267 3318 3397 3450 3439 3442 3499 3447 3341 3179 3231 3266 3087 3088 3018 3026 2847 2841 2784 2685 2750 2658 2695 2687 2717 2579 2597 2678 2531 2458 2490 2549 2466 2580 2456 2399 2524 2490 2555 2539 2558 2531 2612 2624 2611 2629 2739 2919 2956 3145 3078 3084 3047 2862 2821 2835 2743 2653 2630 2650 2566 2552 2582 2560 2484 2695 2657 2757 2721 2645 2697 2778 2786 2732 2658 2630 2755 2694 2630 2702 2788 2848 2874 3071 3232 3369 3329 3312 3313 3070 3077 3047 2955 2897 2756 2678 2694 2593 2723 2651 2687 2675 2773 2743 2853 2986 2954 3004 3084 3111 3133 3080 3099 3000 2852 2891 2836 2719 2799 2706 2706 2739 2690 2769 2828 2878 2846 3041 3138 3266 3409 3376 3493 3417 3508 3335 3084 2998 2869 2776 2900 2774 2756 2704 2672 2768 2751 2761 2831 2810 2945 2991 3174 3098 3284 3181 3419 3417 3507 3539 3709 3708 3524 3412 3289 3097 3127 2997 2886 2889 2951 2785 2790 2817 2944 2966 2894 2895 2947 3019 3033 3036 3043 3026 2947 2815 2831 2777 2900 2868 2808 2814 2820 2888 2944 3079 3245 3216 3422 3511 3821 3904 3818 3866 4063 4007 3678 3579 3376 3179 2978 2984 2843 2742 2805 2694 2778 2832 2785 2865 3100 3014 3122 3168 3233 3151 3191 3112 3044 2946 2880 2738 2635 2605 2594 2572 2593 2558 2488 2548 2504 2536 2510 2609 2583 2579 2677 2773 2917 3004 3050 3237 3367 3280 3229 3197 3100 2924 2845 2796 2732 2669 2567 2563 2558 2609 2484 2737 2678 2749 2787 2842 2847 3017 2991 2897 2896 2801 2816 2725 2603 2601 2562 2558 2550 2573 2531 2533 2507 2575 2492 2614 2688 2678 2724 2720 2750 2874 2911 2963 2892 2906 2824 2884 2933 3064 3025 3123 3356 3464 3595 3490 3353 3230 3022 2988 2883 2905 2846 2760 2792 2864 2923 2775 2847 2838 3014 2950 3083 3199 3193 3318 3362 3404 3360 3388 3379 3492 3324 3439 3339 3367 3240 3176 3173 3226 3122 3034 2957 3088 2997 3062 2995 3090 3012 2996 3122 3049 3149 3153 3067 3008 3039 2982 3010 2936 2894 2962 2895 2949 2994 3040 3081 3040 3183 3177 3389 3464 3505 3532 3471 3415 3311 3100 2957 2824 2746 2803 2780 2668 2696 2689 2702 2777 2874 2747 2818 2778 2871 3013 3039 3154 3167 3095 3141 3073 3057 3113 3196 3254 3309 3270 3303 3232 3306 3327 3256 3331 3445 3495 3666 3613 3691 3692 3783 3744 3519 3467 3363 3256 3221 3170 3121 3004 3120 2943 3021 3010 2995 3097 3102 3239 3253 3250 3296 3542 3479 3572 3722 3687 3949 4126 4011 3875 3732 3416 3386 3284 3185 3142 3007 3051 3103 3079 3056 3012 3069 2878 3039 3052 3042 3144 3261 3190 3284 3257 3255 3159 2957 2988 2952 3008 2969 2911 2866 2919 2836 2814 2736 2680 2743 2580 2712 2588 2505 2709 2579 2630 2601 2618 2663 2650 2754 2831 2775 2766 2962 2930 2910 2873 2807 2884 2845 2841 2884 2837 2886 2901 2828 2778 2966 2978 2816 3022 2916 3027 3001 3028 3023 3171 3345 3443 3523 3432 3799 3869 3906 3696 3615 3496 3317 3076 3009 2931 2820 2929 2860 2821 2751 2867 2746 2742 2790 2755 2972 2920 3043 3008 3141 3041 3023 3017 2938 2847 2675 2642 2649 2548 2570 2482 2501 2469 2438 2447 2398 2358 2464 2520 2462 2380 2469 2462 2404 2417 2450 2397 2386 2460 2360 2404 2386 2361 2443 2365 2353 2424 2367 2370 2363 2334 2312 2345 2355 2391 2334 2449 2364 2501 2449 2371 2400 2462 2425 2454 2433 2597 2511 2481 2600 2577 2609 2725 2819 2970 2952 3119 3205 3141 3201 3006 2875 2979 2808 2809 2822 2736 2801 2849 2841 2895 2804 2897 2893 2821 2966 2897 2876 2884 2966 2893 2926 2998 2841 2763 2623 2718 2640 2545 2752 2598 2613 2606 2623 2676 2714 2629 2590 2652 2633 2662 2625 2722 2700 2723 2793 2844 2955 3071 3282 3363 3578 3634 3670 3743 3593 3351 3238 3268 3040 3019 2896 2832 2753 2785 2674 2624 2616 2660 2721 2679 2751 2837 2814 2917 2941 3036 3032 3001 2979 2884 2679 2749 2734 2681 2675 2590 2557 2375 2441 2372 2427 2402 2421 2466 2451 2346 2393 2327 2475 2409 2339 2269 2350 2408 2211 2343 2401 2403 2446 2398 2367 2336 2416 2387 2325 2332 2316 2389 2324 2361 2335 2400 2452 2346 2346 2398 2418 2394 2353 2408 2335 2361 2398 2455 2375 2420 2370 2379 2448 2347 2315 2254 2391 2290 2381 2309 2401 2340 2385 2390 2334 2400 2379 2400 2470 2424 2421 2427 2368 2408 2526 2523 2425 2508 2511 2589 2569 2547 2441 2532 2369 2542 2568 2537 2421 2488 2412 2504 2460 2435 2445 2429 2447 2439 2367 2560 2417 2536 2422 2467 2513 2506 2586 2598 2579 2754 2735 2703 2688 2764 2885 2941 2949 2959 3149 3239 3314 3432 3529 3569 3737 3786 3663 3642 3387 3274 3113 3072 2955 2929 2900 2916 2788 3000 3071 3156 3210 3450 3421 3542 3587 3751 3645 3558 3560 3451 3379 3193 3056 3061 2948 2799 2785 2653 2644 2672 2702 2717 2738 2665 2666 2769 2893 2961 2927 2940 2784 2864 2846 2841 2808 2885 2824 2901 2942 3033 2953 3160 3113 3190 3157 3275 3322 3373 3292 3361 3263 3317 3168 3072 2940 2882 2940 2848 2747 2670 2693 2693 2748 2713 2739 2756 2802 2710 2817 2747 2875 2819 2818 2919 2790 2837 2836 2743 2750 2735 2643 2564 2661 2580 2614 2567 2395 2358 2470 2405 2442 2450 2420 2444 2438 2467 2390 2463 2444 2507 2468 2477 2324 2438 2481 2503 2541 2493 2507 2484 2519 2533 2628 2678 2701 2757 2826 2796 2964 3098 3168 3321 3487 3635 3805 3971 4068 4059 4088 4119 3977 3721 3624 3818 3521 3379 3279 3261 3201 3116 3174 3154 3250 3259 3369 3396 3651 3736 3868 4022 4276 4361 4541 4438 4247 4422 4333 4351 4247 4292 4283 4240 4078 4141 4012 4010 3832 3715 3540 3549 3633 3524 3560 3670 3667 3790 3847 3845 3936 3984 3963 4024 3997 4189 4189 4175 4287 4223 4031 4016 3876 3821 3619 3564 3478 3306 3172 3128 3008 3068 2849 2958 3075 2904 2914 2942 3004 3028 2991 3028 3026 3007 3108 2991 3055 3013 2935 3081 2998 3091 3144 3319 3349 3533 3479 3223 3162 3025 3060</intensities>
			</dataPoints>
			<nonAmbientPoints type="Temperature" unit="K">
[...]
			</nonAmbientPoints>
		</scan>
	</xrdMeasurement>
</xrdMeasurements>