File: powder_X-ray_diffraction/variable-temperature_experiments/NaTaO2F2/raw_data/180°C.xrdml
<?xml version="1.0" encoding="UTF-8"?>
<xrdMeasurements xmlns="http://www.xrdml.com/XRDMeasurement/1.7" xmlns:xsi="http://www.w3.org/2001/XMLSchema-instance" xsi:schemaLocation="http://www.xrdml.com/XRDMeasurement/1.7 http://www.xrdml.com/XRDMeasurement/1.7/XRDMeasurement.xsd" status="Completed">
	<comment>
		<entry>Configuration=XRK900, Owner=User-1, Creation date=12/01/2015 16:52:44</entry>
		<entry>Goniometer=Theta/Theta; Minimum step size 2Theta:0.0001; Minimum step size Omega:0.0001</entry>
		<entry>Sample stage=AP XRK-900 with z-axis; Minimum step size Z:0.001</entry>
		<entry>Diffractometer system=EMPYREAN</entry>
		<entry>Measurement program=C:\PANalytical\Data Collector\Programs\Gwen\NaTaO2F2\NaTaO2F2-Lent.xrdmp, Identifier={FF50B583-C5FF-42DA-A01D-A1FB659EF29A}</entry>
		<entry>Batch program=C:\PANalytical\Data Collector\Programs\Gwen\NaTaO2F2\Thermodiff-Ouail.xrdmp, Identifier={5D65A6B1-42FC-480C-9FBB-D7D88D55EA08}</entry>
	</comment>
	<sample type="To be analyzed">
		<id></id>
		<name></name>
		<preparedBy></preparedBy>
	</sample>
	<xrdMeasurement measurementType="Scan" status="Completed" sampleMode="Reflection">
		<comment>
			<entry>PHD Lower Level = 4.02 (keV), PHD Upper Level = 12.07 (keV)</entry>
		</comment>
		<usedWavelength intended="K-Alpha 1">
			<kAlpha1 unit="Angstrom">1.5405980</kAlpha1>
			<kAlpha2 unit="Angstrom">1.5444260</kAlpha2>
			<kBeta unit="Angstrom">1.3922500</kBeta>
			<ratioKAlpha2KAlpha1>0.5000</ratioKAlpha2KAlpha1>
		</usedWavelength>
		<incidentBeamPath>
			<radius unit="mm">240.00</radius>
			<xRayTube id="1010048" name="Empyrean Cu LFF HR (9430 033 7310x) DK434948">
				<tension unit="kV">45.0</tension>
				<current unit="mA">30.0</current>
				<anodeMaterial>Cu</anodeMaterial>
				<focus type="Line">
					<length unit="mm">12.0</length>
					<width unit="mm">0.4</width>
					<takeOffAngle unit="deg">6.0</takeOffAngle>
				</focus>
			</xRayTube>
			<sollerSlit id="21010001" name="Soller slits 0.02 rad.">
				<opening unit="rad">0.0200</opening>
			</sollerSlit>
			<mask id="22030010" name="Fixed mask 20 mm">
				<width unit="mm">20.00</width>
			</mask>
			<antiScatterSlit id="22010003" name="Fixed slit 1Â°" xsi:type="fixedAntiScatterSlitType">
				<height unit="mm">1.52</height>
			</antiScatterSlit>
			<divergenceSlit id="22010012" name="Programmable divergence slit" xsi:type="fixedDivergenceSlitType">
				<distanceToSample unit="mm">140.00</distanceToSample>
				<angle unit="deg">0.5</angle>
			</divergenceSlit>
		</incidentBeamPath>
		<diffractedBeamPath>
			<radius unit="mm">240.00</radius>
			<antiScatterSlit id="22090010" name="AS slit 8.0 mm (PIXcel)" xsi:type="fixedAntiScatterSlitType">
				<height unit="mm">8.00</height>
			</antiScatterSlit>
			<sollerSlit id="21010001" name="Soller slits 0.02 rad.">
				<opening unit="rad">0.0200</opening>
			</sollerSlit>
			<filter id="20030001" name="Large beta-filter Nickel">
				<material>Ni</material>
				<thickness unit="mm">0.020</thickness>
			</filter>
			<detector id="7010019" name="PIXcel1D-Medipix3 detector" xsi:type="rtmsDetectorType">
				<phd unit="%">
					<lowerLevel>25.0</lowerLevel>
					<upperLevel>75.0</upperLevel>
				</phd>
				<mode>Scanning</mode>
				<activeLength unit="deg">3.3482</activeLength>
			</detector>
		</diffractedBeamPath>
		<scan appendNumber="0" mode="Continuous" scanAxis="Gonio" status="Completed">
			<header>
				<startTimeStamp>2023-01-21T20:41:41+01:00</startTimeStamp>
				<endTimeStamp>2023-01-21T23:42:08+01:00</endTimeStamp>
				<author>
					<name>User</name>
				</author>
				<source>
					<applicationSoftware version="5.5a">Data Collector</applicationSoftware>
					<instrumentControlSoftware version="8.2  20201204">EMPYREAN</instrumentControlSoftware>
					<instrumentID>0000000011159748</instrumentID>
				</source>
			</header>
			<dataPoints>
				<positions axis="2Theta" unit="deg">
					<startPosition>9.99846514</startPosition>
					<endPosition>99.99342261</endPosition>
				</positions>
				<positions axis="Omega" unit="deg">
					<startPosition>4.99923257</startPosition>
					<endPosition>49.99671130</endPosition>
				</positions>
				<positions axis="Z" unit="mm">
					<commonPosition>8.846</commonPosition>
				</positions>
				<commonCountingTime unit="seconds">386.070</commonCountingTime>
				<intensities unit="counts">6895 6865 6688 6802 6880 6633 6866 6620 6606 6574 6544 6674 6629 6615 6563 6476 6581 6493 6555 6707 6628 6567 6615 6441 6569 6532 6517 6375 6477 6493 6399 6514 6588 6459 6385 6435 6531 6480 6511 6396 6384 6448 6434 6492 6380 6460 6392 6451 6141 6478 6472 6492 6510 6237 6450 6439 6586 6586 6555 6515 6552 6584 6625 6774 6761 6729 6629 6816 6934 6945 7078 7059 7357 7584 7945 8642 9587 10526 11703 14074 17850 22990 29432 38549 46337 50964 51041 44905 36987 29574 22764 17369 13433 10814 8880 8064 7390 7207 6948 6803 6600 6569 6454 6425 6282 6309 6466 6246 6408 6232 6234 6110 6344 6280 6226 6136 6138 6115 6153 6126 6236 6183 6115 6080 5982 6213 5977 6131 6091 6126 5881 6065 5946 6074 5950 5963 6142 6124 6066 5950 5961 5988 5864 5836 5904 5914 6022 6014 5975 6047 5937 5883 5913 5918 5875 5934 5912 5847 5839 5866 5963 5760 5986 5784 5851 5853 5922 5922 5851 5737 5894 5763 5849 5807 5756 5824 5800 5666 5874 5898 5682 5753 5720 5772 5653 5902 5941 5724 5751 5745 5670 5679 5632 5606 5632 5827 5653 5807 5612 5639 5656 5711 5598 5642 5691 5671 5699 5566 5777 5631 5798 5719 5544 5529 5668 5527 5652 5601 5656 5567 5552 5491 5594 5636 5623 5581 5594 5689 5467 5504 5642 5574 5637 5653 5793 5494 5612 5562 5534 5514 5467 5494 5504 5446 5431 5520 5558 5410 5392 5475 5488 5419 5487 5330 5467 5481 5437 5445 5539 5308 5473 5389 5321 5468 5366 5465 5497 5369 5267 5444 5407 5364 5317 5487 5260 5391 5335 5407 5335 5352 5306 5402 5312 5167 5277 5249 5319 5192 5188 5408 5238 5251 5315 5200 5209 5146 5157 5123 5228 5296 5276 5275 5291 5086 5192 5259 5351 5267 5240 5201 5239 5239 5252 5284 5216 5206 5300 5242 5187 5213 5256 5220 5230 5173 5190 5234 5120 5233 5071 5190 5115 5235 5197 5194 5091 5192 5195 5128 5138 5054 5072 5185 5108 5079 5089 5259 5089 5070 5049 5037 4836 5010 5161 4981 5011 5127 5226 5050 5091 5062 5128 5002 4910 5063 5075 5024 5018 5130 5027 5047 4953 4931 5101 5133 5028 5022 5085 4989 4969 4978 4977 5011 5083 4855 5118 4892 4915 4876 4953 4896 4825 4912 5017 4933 4915 4978 4845 4925 4900 4959 5039 4896 4907 4703 5000 5027 5022 4991 4903 4977 5066 5002 4883 4861 4970 4793 4883 4894 4946 4919 4922 4838 4874 4814 4970 4946 4945 4994 4784 4966 4865 4930 4832 4891 4874 4731 4853 4761 4830 4902 4812 4780 4885 4814 4878 4751 4841 4776 4854 4770 4800 4880 4878 4858 4854 4894 4694 4767 4897 4762 4782 4844 4740 4799 4906 4787 4884 4704 4844 4930 4958 4926 4898 4838 5015 4762 4971 4778 4858 4914 4936 4926 4832 5064 4797 5009 4921 5015 4956 4843 4913 4851 4776 4964 4879 4901 4879 4965 4868 4864 4837 4708 4777 4743 4774 4654 4735 4681 4657 4735 4799 4681 4620 4691 4653 4556 4567 4660 4686 4826 4560 4723 4746 4740 4555 4508 4570 4742 4610 4592 4691 4641 4664 4620 4690 4730 4719 4589 4632 4779 4626 4479 4582 4562 4758 4806 4618 4566 4752 4647 4718 4736 4730 4899 4850 4697 4814 4684 4677 4606 4613 4592 4525 4448 4659 4581 4423 4438 4567 4576 4649 4502 4378 4619 4553 4555 4534 4394 4522 4678 4443 4626 4584 4477 4603 4598 4542 4492 4660 4686 4743 4835 4769 4635 4510 4685 4616 4484 4496 4466 4438 4271 4550 4344 4573 4467 4515 4287 4323 4429 4485 4442 4405 4358 4489 4437 4501 4463 4384 4310 4411 4306 4536 4324 4367 4483 4445 4336 4262 4306 4424 4451 4372 4369 4268 4278 4264 4296 4270 4253 4353 4151 4288 4399 4287 4337 4370 4365 4263 4504 4352 4269 4317 4398 4331 4357 4388 4579 4441 4503 4440 4348 4367 4284 4316 4269 4300 4207 4163 4245 4356 4267 4295 4305 4248 4280 4176 4285 4274 4261 4149 4186 4261 4365 4357 4402 4445 4547 4611 4582 4714 4610 4598 4701 4645 4598 4698 4574 4666 4728 4737 4503 4672 4657 4504 4570 4620 4610 4610 4835 4668 4717 4795 4759 4783 4883 4993 5032 5220 5241 5393 5566 5728 5931 6097 6497 7073 7950 8927 10897 13769 18345 26528 40417 58867 80963 105131 123122 122381 114347 105478 92824 73167 54460 39139 28152 19642 14339 10629 8435 7384 6701 6215 5875 5563 5353 5073 4898 4793 4749 4600 4585 4630 4645 4602 4550 4523 4357 4380 4528 4408 4554 4678 4828 4773 4603 4772 4720 4708 4510 4608 4575 4435 4389 4438 4274 4219 4346 4298 4191 4152 4237 4311 4255 4234 4321 4223 4268 4202 4356 4153 4237 4154 4158 4148 4135 4127 4052 4161 4184 4043 4103 4148 4092 4115 4051 4056 4054 3929 4077 4032 4049 4029 3975 4217 4109 4058 3959 4014 3960 4165 4053 4099 4022 3996 4019 4186 4028 4061 4046 3957 4010 4092 4018 4072 4048 4072 3892 4018 3937 3979 3869 4076 4038 3788 3941 3919 3901 3936 3965 4011 3882 3926 3798 3935 3921 3907 3943 4036 3957 3828 3985 3986 3925 3976 3950 3902 3952 3944 3854 3948 3924 3962 3932 3980 4032 4045 4006 3908 4021 3914 3799 4004 3881 3864 4110 4015 4000 4137 4190 4267 4330 4362 4233 4286 4113 4170 4079 4100 4058 3879 4060 3878 3992 3966 4027 3938 4059 3990 4032 3955 3965 4035 3960 4080 3995 4047 4039 4068 4109 4134 4154 4390 4498 4980 5375 6101 7418 9626 12864 17200 19534 19417 17898 16568 16024 14394 11326 8834 7257 6241 5295 4633 4210 4275 4148 4144 3925 4032 3975 3909 3845 3877 3802 3887 3872 3771 3920 3845 3744 3856 3920 3976 3878 3931 3874 3879 4045 3877 3820 3849 3998 3663 3744 3813 3874 3698 3759 3721 3843 3731 3793 3731 3760 3707 3644 3702 3727 3826 3691 3784 3651 3714 3672 3849 3683 3683 3809 3733 3724 3737 3769 3652 3761 3693 3674 3872 3752 3691 3785 3743 3807 3663 3736 3964 3784 3741 3770 3709 3909 3764 3866 3895 3846 3932 3962 4057 4032 3908 3897 3831 3995 4083 3919 3957 3990 4001 3839 3926 3906 4124 3954 3961 3839 3948 4003 4045 4189 4122 4271 4320 4462 4363 4413 4490 4596 4587 4597 4609 4693 4971 5027 5369 5750 6453 7289 9414 13020 18334 25744 33488 40993 46324 46077 41053 36845 32837 30838 25217 19967 16275 15578 17000 22111 30489 38302 44305 48809 48709 45620 40979 36219 31095 25218 19142 14437 10803 8167 6506 5565 5008 4723 4560 4429 4387 4293 4125 4066 4066 3923 4001 3903 3871 3943 3923 3844 3870 3770 3689 3921 3760 3698 3873 3795 3745 3716 3691 3752 3697 3775 3898 3797 3972 3935 3970 3883 3803 3823 3710 3730 3659 3697 3793 3633 3617 3698 3699 3622 3639 3658 3591 3704 3771 3671 3579 3618 3631 3493 3494 3621 3637 3628 3582 3650 3691 3624 3618 3491 3607 3538 3604 3617 3564 3631 3568 3564 3598 3454 3509 3582 3543 3432 3466 3536 3602 3452 3552 3471 3558 3542 3518 3445 3636 3468 3506 3492 3521 3587 3550 3459 3476 3511 3512 3528 3584 3536 3583 3605 3652 3481 3392 3607 3687 3658 3855 3884 3878 3995 3964 3987 3930 3874 3886 3677 3689 3758 3591 3613 3615 3673 3458 3506 3579 3348 3565 3481 3584 3527 3678 3591 3575 3489 3502 3410 3487 3471 3562 3601 3536 3440 3521 3486 3411 3334 3479 3441 3563 3394 3599 3499 3518 3456 3479 3545 3579 3409 3394 3558 3566 3478 3591 3578 3667 3568 3655 3735 3568 3657 3670 3536 3741 3679 3736 3679 3697 3578 3658 3646 3619 3714 3781 3634 3661 3628 3634 3680 3624 3704 3630 3655 3635 3615 3618 3646 3715 3788 3725 3715 3682 3604 3676 3679 3841 3853 3836 3794 3817 3934 4025 4242 4238 4433 4429 4619 4775 4917 5039 5358 5557 6181 6645 7314 8328 9492 12128 16104 23442 35292 51595 68747 80611 83943 79058 70936 63541 57152 51362 44322 35130 25846 18098 12741 9516 7662 6663 5951 5456 5112 4832 4590 4398 4201 4125 4181 3962 3879 3867 3725 3768 3753 3799 3691 3701 3724 3606 3739 3669 3702 3752 3694 3700 3894 3920 3969 4018 3986 3913 3884 3762 3878 3750 3719 3698 3593 3625 3646 3589 3720 3685 3513 3604 3633 3756 3574 3544 3521 3549 3592 3513 3637 3549 3471 3627 3555 3554 3447 3421 3555 3548 3390 3570 3517 3503 3511 3590 3505 3536 3560 3575 3550 3516 3652 3677 3612 3674 3597 3667 3633 3687 3828 3893 3939 3974 4027 4091 4163 4440 4601 4791 5065 5502 6657 8351 11814 16876 23665 30185 33685 33349 29197 26203 25055 24331 22760 20542 18057 16950 17536 18465 19637 20153 19313 17683 15640 14170 13257 11736 10354 8516 7088 5782 4870 4390 4065 3806 3760 3739 3527 3585 3631 3567 3436 3451 3340 3440 3385 3378 3428 3403 3461 3493 3353 3285 3248 3320 3298 3424 3398 3362 3450 3529 3432 3463 3451 3349 3313 3355 3283 3264 3319 3316 3266 3314 3294 3239 3427 3245 3348 3343 3399 3294 3201 3249 3210 3318 3219 3341 3274 3351 3316 3201 3311 3260 3294 3350 3303 3357 3322 3251 3284 3265 3269 3320 3199 3148 3245 3261 3210 3136 3235 3178 3227 3269 3064 3195 3256 3153 3201 3276 3233 3232 3238 3169 3183 3159 3088 3181 3075 3105 3208 3218 3157 3145 3208 3147 3178 3090 3193 3220 3257 3096 3174 3130 3251 3279 3185 3114 3164 3174 3088 3083 3097 3146 3039 3180 3219 3086 3217 3075 3152 3193 3114 3152 3033 3203 3160 3124 3087 3100 3093 3145 3175 3042 3063 3145 3192 2994 3084 3106 3080 3137 3100 3094 3117 3180 3222 3078 3166 3190 3141 3061 3066 3139 3198 3082 3103 3159 3224 3197 3075 3214 3149 3160 3172 3208 3154 3158 3156 3058 3082 3143 2927 3038 3198 3135 3155 3073 3088 3187 3100 3070 3106 3105 3095 3186 3115 3071 3065 3105 3217 3211 3224 3146 3323 3244 3242 3192 3114 3252 3210 3213 3193 3308 3144 3122 3205 3251 3183 3154 3279 3271 3389 3249 3335 3467 3472 3479 3529 3594 3607 3835 3941 3962 4088 4621 5275 6664 9605 14469 19142 22040 20542 17184 14473 13130 13066 13653 12909 10850 8815 6812 5544 4788 4210 3996 3827 3737 3697 3652 3577 3741 3706 3744 3699 3693 3827 3842 4051 4191 4086 4204 4442 4549 4823 5233 5829 7305 9402 13505 19987 27426 33576 35369 32162 28077 24422 22453 22123 21588 19864 16703 13516 10230 8030 6272 5308 4915 4556 4493 4485 4515 4360 4455 4564 4775 4895 5090 5443 6031 7005 8862 11451 15758 19945 24695 28517 30075 29241 26569 24471 22591 22601 23939 25474 26986 25072 20603 16038 12933 11794 11361 11365 10404 8948 7198 6143 5284 4375 4054 3838 3581 3619 3548 3432 3317 3298 3392 3428 3266 3266 3360 3259 3295 3192 3121 3226 3153 3235 3120 3127 3204 3156 3126 3185 3159 3140 3171 3153 3182 3249 3295 3281 3226 3297 3392 3437 3487 3448 3466 3502 3648 3781 4100 4652 5621 7229 9684 12344 14649 14049 12341 10529 9277 8984 9106 9312 8678 7535 6015 5048 4298 3846 3682 3536 3440 3306 3274 3249 3312 3400 3419 3467 3726 3767 3804 3534 3410 3312 3364 3282 3350 3242 3244 3028 3051 3025 3005 3047 3051 3000 2971 2988 3069 2985 2944 2988 2873 2917 3106 2987 2969 3033 2828 2920 3017 2950 2940 2996 2867 2967 2971 2939 2924 2935 3012 2917 2957 2953 2969 2932 2814 2805 2935 2894 2926 3038 2994 2993 2903 2997 2894 2926 2901 2926 2867 2999 2837 2848 2838 2872 2829 2912 2999 2879 2972 2894 2880 2945 2966 2992 3043 3068 2959 2935 3143 3070 2868 3078 2974 2973 3049 2993 2930 3144 2910 2954 2909 2946 2948 2968 3036 2910 2955 3004 2958 2887 2994 2878 2895 2862 2958 2924 2916 2971 2984 2949 3063 3008 3006 2994 3057 3119 3090 3243 3227 3359 3460 3989 4656 5941 7462 9183 10037 9445 8231 6613 6024 5997 6305 6589 6348 5667 4782 4020 3616 3528 3185 3219 3112 3154 3098 2920 2988 3072 3054 2964 2972 3040 2879 2903 2961 2935 2958 2930 3111 3140 3065 3001 3128 3126 3165 3240 3190 3151 3429 3403 3501 3907 4534 5513 6714 7913 9221 9750 10073 9532 8563 7751 7266 6825 6781 6724 6251 5739 5114 4394 3748 3491 3339 3144 3030 3240 3092 3379 3492 3637 3654 3625 3559 3393 3299 3420 3399 3325 3241 3136 3047 2922 3006 2988 2907 2798 2849 2766 2858 2765 2845 2835 2763 2749 2798 2791 2803 2658 2728 2816 2785 2762 2799 2864 2833 2784 2777 2795 2788 2813 2810 2891 2804 2699 2777 2784 2797 2646 2774 2765 2755 2714 2814 2625 2747 2744 2728 2772 2816 2761 2746 2668 2753 2728 2721 2684 2792 2804 2822 2715 2675 2825 2791 2714 2728 2779 2811 2795 2798 2808 2735 2760 2753 2738 2845 2741 2802 2754 2754 2795 2662 2736 2868 2789 2835 2725 2831 2786 2858 2689 2755 2800 2726 2794 2712 2692 2757 2672 2705 2791 2721 2675 2743 2747 2785 2825 2690 2701 2726 2718 2649 2756 2756 2677 2779 2680 2822 2690 2671 2759 2764 2757 2772 2753 2780 2874 2669 2806 2800 2801 2842 2786 2910 2827 2889 2878 2845 2906 3008 3081 3377 3930 4299 4687 4924 5044 5017 4757 4323 4117 4031 4040 4026 4106 3969 3805 3572 3404 3215 3155 3304 3282 3423 3499 3837 4461 5443 6597 7542 7679 7150 6323 5686 5348 5249 5455 5655 5457 5171 4760 4216 3937 3523 3519 3370 3396 3400 3599 3625 4096 4715 5908 7513 9001 9988 9633 8428 7182 6106 5704 5835 6380 6673 6387 5727 4660 4070 3609 3500 3238 3036 3061 3015 3052 2902 3023 3016 2830 2904 2926 2910 2977 3039 2978 2981 3050 3092 3062 3158 3176 3167 3342 3310 3518 3657 4078 4362 5269 6216 7421 8985 10333 11262 11297 10337 8792 7765 7488 7776 8465 9613 10700 12170 13242 13794 13267 12027 10409 9228 8958 9877 12101 14553 16156 16091 14478 12073 9615 8101 7302 7299 7752 7898 7555 6600 5616 4579 3907 3475 3281 3106 3072 3017 2941 2989 2981 2871 2821 2789 2741 2833 2886 2806 2789 2749 2785 2832 2740 2636 2780 2654 2704 2804 2743 2721 2726 2692 2786 2687 2634 2682 2713 2639 2705 2717 2743 2726 2752 2637 2669 2666 2764 2663 2737 2682 2746 2786 2759 2651 2693 2606 2707 2625 2772 2808 2711 2644 2673 2641 2597 2707 2700 2731 2714 2630 2599 2723 2512 2704 2844 2744 2657 2689 2634 2599 2626 2639 2729 2705 2591 2652 2700 2753 2671 2649 2642 2604 2651 2599 2640 2720 2648 2732 2640 2679 2631 2771 2763 2659 2742 2676 2682 2744 2583 2658 2813 2681 2679 2710 2689 2633 2712 2814 2666 2616 2597 2705 2701 2751 2625 2699 2655 2607 2633 2672 2638 2641 2621 2711 2668 2730 2665 2741 2654 2689 2772 2700 2673 2683 2716 2640 2752 2779 2964 3063 3151 3368 3397 3454 3306 3275 3111 3069 2965 3129 3089 3182 3021 2993 3065 2826 2777 2790 2731 2734 2702 2601 2643 2648 2598 2663 2697 2577 2709 2636 2657 2717 2643 2703 2685 2702 2630 2599 2612 2626 2678 2636 2617 2609 2628 2745 2661 2733 2775 2625 2720 2704 2723 2706 2794 2780 2818 2784 3038 3163 3676 3905 4023 4079 3963 3792 3384 3442 3216 3304 3389 3543 3380 3453 3195 3145 2968 2839 2959 2933 2930 2872 3088 3173 3266 3747 4197 4653 5088 5527 5693 5495 5131 4455 4137 3982 4022 4189 4209 4212 4015 3725 3385 3159 3063 2970 2804 2792 2857 2681 2790 2731 2742 2740 2695 2704 2732 2678 2753 2712 2628 2662 2611 2734 2656 2611 2610 2641 2595 2696 2629 2597 2599 2594 2634 2659 2687 2623 2684 2668 2614 2689 2700 2666 2668 2597 2677 2698 2664 2741 2714 2691 2801 2714 2707 2778 2788 2760 2800 2884 2775 2852 2763 2869 2906 2967 3062 3209 3390 3603 4034 5156 6898 9280 11588 12340 11142 8962 6952 5733 5197 5361 6098 7199 7590 7013 6093 4968 4218 3582 3249 3077 3039 2967 2817 2882 2768 2737 2658 2691 2792 2748 2756 2751 2715 2698 2800 2769 2850 2747 2816 2907 2804 2920 2956 2750 2924 2869 2893 2991 3150 3363 3861 4523 5591 6945 7496 7284 6227 5022 4576 4042 4088 4314 4775 5323 5034 4813 4166 3508 3293 3129 2817 2957 2942 2730 2676 2765 2776 2676 2752 2795 2795 2725 2808 2720 2773 2770 2798 2768 2676 2742 2694 2774 2756 2818 2832 2812 2953 2913 2865 2929 2870 2904 2954 3065 3033 3219 3454 3526 3732 4380 5025 5921 6968 7800 8452 8675 8488 7290 6001 5288 5037 5121 5411 5716 5920 5718 5230 4609 3968 3632 3509 3304 3233 3129 3013 3002 3028 3064 3120 3052 3097 3251 3239 3213 3092 3242 3255 3376 3408 3499 3470 3569 3618 3793 3912 4059 4393 5017 5482 6421 7864 10061 13370 16418 19411 20534 19322 16503 13427 11344 10212 9908 10672 11773 12194 12251 10823 9268 7511 6277 5299 4657 4203 3920 3590 3526 3431 3506 3285 3284 3234 3278 3176 3314 3270 3233 3272 3288 3340 3283 3464 3471 3707 4106 4692 5618 7187 9253 11516 12707 12959 12973 13518 13199 12434 11286 10509 9987 9628 9234 8786 8389 8340 8097 7573 6679 5770 5128 4766 4199 4077 4134 4328 4831 5439 6655 8290 10561 12736 13322 12888 10859 8955 7484 6320 6353 6532 7524 8096 8397 7852 6819 5655 4677 4069 3780 3529 3244 3340 3218 3053 3230 3009 3016 3084 2865 2778 2972 2894 2865 2825 2802 2748 2760 2799 2859 2807 2792 2831 2824 2804 2843 2913 2948 3080 3166 3247 3611 3580 3583 3452 3332 3245 3096 3040 3076 3214 3224 3391 3484 3398 3504 3345 3375 3378 3287 3381 3296 3315 3210 3367 3442 3352 3470 3415 3526 3503 3552 3530 3523 3597 3671 3909 4118 4743 5616 6651 8427 11144 14576 17751 19462 18617 16762 14135 11722 10028 9676 10337 11511 12401 12677 11837 10562 8982 7384 6380 5652 5173 4874 4420 4130 3876 3724 3628 3542 3471 3517 3422 3507 3527 3558 3739 3849 4102 4562 5122 5960 7007 8453 9865 10958 11356 11257 10146 8626 7188 6469 6529 6346 6663 7262 7341 7082 6661 5709 5005 4275 3838 3672 3336 3424 3192 3183 3089 2953 2934 2871 2996 2865 2947 2857 2812 2849 2933 2803 2829 2858 2789 2835 2812 2885 2867 2818 2850 2754 2781 2876 2933 2913 2826 2958 2858 2981 2943 3047 3001 2930 3017 3109 3145 3176 3384 3505 3859 4519 5478 6728 8157 9243 9154 7982 6847 5691 4905 4396 4552 4797 5497 5881 6082 5841 5332 4746 4120 3930 3949 3816 3736 3653 3321 3064 3109 3070 3048 3076 3130 3242 3125 3149 3030 2980 2961 2855 2966 2864 2833 2788 2749 2791 2704 2854 2738 2819 2745 2801 2842 2824 2681 2725 2740 2759 2820 2800 2730 2774 2750 2837 2769 2826 2791 2891 2740 2794 2892 2927 2899 2865 3079 3003 2946 3048 2998 3023 3149 3141 3186 3359 3456 3916 4319 5003 6180 7541 8466 9914 10431 10703 10659 9812 8404 7031 6107 5850 6012 6252 6581 6677 6836 6659 6138 5306 4643 3850 3606 3467 3328 3223 3304 3322 3556 3607 3973 4650 4869 5284 5511 5806 6018 5880 5956 5669 5336 4793 4643 4403 4378 4295 4344 4223 4303 4143 4096 3730 3442 3207 3107 2890 2812 2833 2776 2751 2754 2770 2713 2747 2753 2709 2744 2747 2785 2833 2759 2803 2828 2822 2900 2968 3168 3404 3726 3875 4227 4314 4154 4209 3857 3553 3456 3254 3351 3453 3396 3533 3560 3542 3484 3182 3123 3025 2883 2808 2824 2777 2714 2683 2695 2819 2802 2746 2576 2652 2603 2655 2610 2609 2714 2614 2532 2503 2669 2611 2670 2733 2701 2654 2664 2710 2716 2562 2639 2718 2556 2661 2647 2644 2767 2744 2786 2871 2861 2926 2943 2988 3055 3011 3015 2974 3013 2937 2918 2964 2864 2843 2956 2764 2799 2905 2879 2892 2817 2713 2763 2767 2656 2677 2694 2626 2754 2666 2722 2660 2680 2671 2668 2653 2625 2714 2697 2627 2568 2716 2527 2575 2673 2663 2690 2684 2627 2662 2647 2778 2729 2746 2663 2679 2750 2646 2854 2687 2797 2762 2792 2773 2672 2812 2781 3061 2887 2997 2870 2982 3122 3064 3211 3195 3264 3434 3546 4002 4433 4865 5755 7141 8728 10485 11629 11542 10343 9025 7535 6417 5684 5535 5728 6081 7014 7429 7452 7209 6440 5626 4792 4359 3848 3647 3543 3528 3504 3612 3616 3653 3496 3376 3413 3115 3073 3011 2952 2952 3128 3010 2994 3133 3111 2972 3069 2969 2892 2883 2924 2918 2974 2973 2975 2981 2893 2924 2962 3144 3092 3113 3104 3197 3350 3498 3734 4215 4956 5825 7341 8995 11297 12780 13876 13512 12646 11068 9624 8259 7768 7927 8127 8571 9213 9408 9279 8911 7882 6904 6053 5370 4724 4622 4388 4093 3859 3688 3430 3393 3262 3064 3031 3054 3009 2919 2942 2935 2882 2992 2932 2950 2988 2942 2979 3070 3144 3080 3106 3234 3172 3252 3318 3581 3585 3960 4509 5120 5881 6542 7200 8043 8718 9237 9422 9553 9768 9574 8873 8119 7436 7128 6816 7080 7308 7661 8121 8609 9119 9543 9147 8559 7568 6526 5616 5034 4554 4274 4353 4583 4620 4928 5094 4739 4360 4115 3773 3525 3431 3240 3212 3113 3024 3086 3034 3104 2965 3095 3058 3072 3041 3015 3177 3224 3343 3313 3630 3907 4199 4794 5476 6511 7604 8794 9056 8385 7538 6223 5620 5073 4612 4799 5169 5742 6451 6915 7026 6744 5868 5442 4885 4487 4353 3880 3882 3765 3681 3611 3548 3379 3322 3409 3411 3337 3292 3348 3301 3208 3074 3122 3202 3042 3090 3395 3359 3400 3753 3905 4106 4488 5014 5635 6262 7214 8019 8615 8634 8255 7554 6709 5922 5485 5374 5413 5808 6500 7240 7871 8870 9994 10539 10675 10420 9205 7750 6292 5337 4859 4700 4790 5092 5626 6227 6460 6787 6697 6280 6054 6027 6655 7196 8122 8999 9553 9520 8798 7632 6627 5880 5153 4919 4945 5072 5510 5837 6176 6200 5977 5450 4851 4207 3769 3636 3312 3111 3201 3157 3084 3065 3058 3121 2967 2986 2988 3120 3040 3033 3080 3087 3307 3392 3584 3955 4433 5033 5670 6408 7150 8014 8582 8690 8177 7739 7156 6685 6276 6251 6647 7231 7878 8529 9016 9437 9667 10359 11305 12107 12344 11758 10639 8763 7473 6460 5906 5566 5486 5749 6142 6560 6965 6804 6364 5845 4910 4264 3780 3580 3256 3132 3126 3024 3051 2986 2988 2890 2880 2818 2882 2905 2862 2909 2951 2860 3030 2894 2973 2942 2970 2935 3018 3091 3047 3103 3199 3348 3290 3430 3537 3691 3816 4269 4849 5478 6621 8009 9420 11269 12042 12059 11806 11447 10984 10493 9716 8981 8224 7803 7890 8192 8423 8633 8722 8611 8650 8466 7918 7444 7082 6588 6012 5451 5039 4881 4856 5108 5110 5228 5528 5607 5772 5908 5561 5269 4843 4367 4057 3864 3734 3631 3697 3753 3701 3555 3560 3655 3502 3245 3021 2885 2825 2816 2735 2687 2782 2781 2703 2604 2608 2684 2604 2678 2541 2674 2629 2583 2456 2518 2541 2625 2496 2612 2610 2573 2636 2602 2546 2530 2629 2566 2499 2580 2599 2652 2545 2594 2524 2595 2525 2396 2524 2566 2561 2535 2445 2581 2587 2590 2517 2579 2627 2534 2417 2417 2605 2441 2461 2555 2454 2545 2516 2456 2441 2472 2473 2562 2518 2446 2361 2461 2497 2502 2631 2559 2583 2535 2551 2618 2641 2606 2515 2603 2562 2466 2599 2504 2510 2445 2510 2536 2472 2405 2562 2501 2447 2602 2508 2515 2486 2519 2491 2437 2477 2401 2450 2521 2558 2474 2434 2544 2583 2589 2515 2571 2457 2435 2410 2438 2427 2437 2464 2458 2551 2498 2438 2473 2529 2437 2425 2527 2479 2444 2514 2542 2429 2520 2499 2579 2463 2515 2429 2403 2650 2503 2562 2486 2497 2571 2460 2566 2567 2584 2479 2439 2609 2679 2627 2694 2790 2815 2802 2832 2917 3082 3058 3218 3312 3461 3838 4070 4008 4068 3730 3573 3357 3169 3006 3072 2933 3065 3163 3175 3189 3359 3190 3123 3179 3016 2831 2782 2705 2762 2649 2752 2665 2797 2717 2875 2928 3133 3357 3460 3754 3958 4267 4238 4238 4181 3891 3867 3867 3740 4155 4113 4324 4652 4424 4419 4379 4054 3754 3590 3458 3191 3261 3247 3114 3314 3149 3303 3212 3203 2911 2852 2770 2610 2568 2589 2620 2543 2450 2484 2451 2425 2510 2474 2512 2454 2459 2405 2366 2439 2496 2451 2385 2519 2382 2415 2438 2476 2439 2544 2526 2533 2651 2482 2643 2605 2679 2649 2746 2692 2701 2717 2626 2694 2664 2604 2659 2737 2727 2719 2797 2722 2699 2761 2721 2616 2589 2556 2633 2636 2461 2519 2556 2470 2648 2422 2465 2550 2423 2447 2385 2302 2457 2373 2427 2417 2460 2434 2433 2341 2307 2444 2389 2430 2328 2360 2445 2499 2458 2453 2369 2418 2424 2527 2369 2419 2327 2450 2385 2484 2408 2368 2407 2401 2424 2384 2400 2399 2283 2482 2396 2434 2401 2380 2408 2429 2337 2388 2396 2463 2346 2441 2421 2388 2374 2325 2395 2333 2410 2420 2380 2330 2367 2442 2345 2382 2420 2367 2401 2436 2391 2390 2358 2407 2409 2400 2389 2454 2387 2354 2424 2317 2480 2504 2561 2518 2487 2562 2521 2524 2394 2460 2399 2448 2391 2460 2408 2419 2423 2459 2456 2477 2563 2533 2603 2545 2681 2504 2471 2470 2435 2404 2420 2370 2484 2395 2515 2433 2453 2498 2417 2460 2502 2420 2413 2456 2333 2360 2410 2346 2371 2460 2389 2298 2408 2367 2375 2317 2370 2322 2289 2381 2330 2313 2323 2428 2408 2297 2410 2415 2382 2402 2437 2287 2395 2351 2459 2393 2356 2362 2353 2360 2391 2478 2384 2332 2399 2423 2365 2464 2462 2396 2349 2442 2402 2379 2395 2438 2368 2458 2455 2513 2475 2367 2340 2404 2294 2475 2398 2412 2402 2430 2463 2417 2480 2516 2476 2501 2598 2571 2667 2878 2999 3216 3336 3573 3627 3622 3559 3260 3072 2954 2773 2724 2747 2741 2746 2996 3148 3366 3385 3550 3574 3462 3172 3135 3039 2845 2834 2833 2756 2781 2809 2721 2625 2709 2763 2789 2848 2911 2829 2809 2916 3126 3323 3609 3984 4562 5042 5298 5199 4792 4165 3682 3426 3045 2915 2886 2802 2854 3158 3300 3591 3746 3762 3844 3469 3426 2958 2794 2795 2577 2603 2570 2552 2630 2546 2583 2487 2480 2550 2396 2464 2566 2513 2555 2506 2515 2543 2636 2683 2732 2827 2909 3093 3214 3653 3900 3918 3794 3644 3310 3085 3139 3052 3165 3097 3256 3471 3735 4005 4159 4251 4219 4193 4151 3842 3651 3460 3345 3186 3205 3137 3162 3198 3221 3361 3225 3289 3256 3288 3292 3395 3363 3395 3616 3736 3795 3875 4107 4412 4802 5097 5700 6242 6795 6852 6740 6267 5759 5233 5065 4750 4754 4577 4729 5069 5389 5516 5652 5763 5601 5460 5021 4663 4379 4089 3864 3915 3765 3853 3975 3955 3827 3683 3488 3438 3224 3241 2993 2971 3018 3066 3195 3281 3371 3717 3951 4341 4623 4932 5120 5115 4763 4484 3988 3909 3690 3596 3474 3422 3470 3414 3620 3695 3775 3971 3851 3841 3591 3526 3458 3234 3171 3189 3220 3245 3451 3510 3641 3735 3961 4105 4241 4322 4315 4304 4216 4192 4040 3915 3753 3671 3511 3462 3428 3409 3529 3719 3720 3815 3971 4184 4591 4960 5624 5949 5767 5199 4341 3917 3561 3379 3069 2991 2918 2997 3041 3187 3390 3583 3932 3978 3714 3550 3295 3207 2966 2841 2825 2769 2723 2831 2832 2821 2922 2975 3099 3288 3739 3856 4105 4243 4070 3873 3630 3388 3334 3279 3270 3433 3417 3622 3597 3845 4031 4207 4144 4352 4257 3967 3782 3653 3383 3122 3112 3025 3014 2990 3140 2898 2956 3029 3030 3032 2965 2935 2930 2903 2769 2731 2625 2594 2691 2557 2505 2521 2492 2560 2528 2427 2460 2449 2449 2522 2467 2559 2591 2639 2506 2512 2562 2609 2571 2675 2779 2850 2919 3092 3256 3481 3745 3911 4225 4244 4189 3977 3829 3410 3214 3115 2984 2866 2922 2934 3019 3042 3097 3290 3348 3422 3445 3297 3105 3017 2880 2813 2755 2660 2649 2665 2592 2662 2788 2840 2823 2879 3143 3503 3598 3748 4137 4373 4317 4342 4120 4074 3801 3619 3344 3211 3162 3013 3092 3127 3200 3460 3440 3543 3499 3625 3590 3690 3731 3770 3827 3793 4040 3939 4123 4080 3895 3664 3642 3455 3421 3421 3479 3399 3499 3531 3454 3339 3481 3425 3227 3264 3394 3244 3103 3030 3107 3012 3038 2973 3161 3088 3099 3147 3395 3442 3665 4008 4496 4949 5193 5392 5413 5260 5219 5370 5368 5456 5286 4658 4395 4015 3702 3704 3759 3876 3897 3999 4134 4084 4043 3879 3808 4012 3735 3612 3354 3131 2963 2810 2737 2708 2554 2637 2443 2414 2433 2461 2456 2517 2465 2377 2355 2440 2467 2365 2414 2386 2333 2464 2423 2396 2376 2371 2375 2469 2397 2436 2353 2367 2384 2406 2368 2458 2448 2413 2476 2387 2362 2369 2358 2376 2379 2322 2479 2329 2437 2263 2369 2451 2425 2391 2394 2315 2379 2354 2427 2309 2355 2431 2301 2412 2375 2386 2359 2394 2327 2422 2285 2451 2416 2347 2415 2419 2413 2404 2475 2472 2332 2365 2392 2441 2435 2464 2378 2466 2419 2452 2417 2494 2426 2585 2523 2455 2503 2499 2411 2561 2525 2458 2512 2598 2563 2525 2459 2463 2542 2501 2526 2459 2506 2474 2480 2450 2408 2530 2420 2573 2439 2587 2489 2622 2587 2497 2595 2676 2708 2748 2766 2850 2751 2919 2856 2795 2911 2984 3040 3086 2934 3051 2977 3154 3127 3383 3507 3672 3924 4201 4516 4611 4845 4944 4871 4519 4349 3977 3744 3524 3237 3251 3175 3078 3202 3200 3390 3395 3454 3500 3632 3541 3408 3372 3234 3184 2991 2875 2647 2569 2637 2554 2616 2558 2619 2631 2692 2679 2619 2693 2676 2695 2813 2896 2974 3101 3248 3491 3599 3791 4116 4178 4228 4411 4418 4388 4265 4151 3824 3711 3406 3253 3117 3166 3001 3104 3180 3268 3356 3517 3439 3455 3346 3343 3201 3205 2994 2990 2830 2720 2609 2568 2540 2641 2550 2539 2541 2569 2486 2570 2567 2596 2600 2766 2761 2799 2993 3092 3147 3247 3145 3189 3004 2870 2779 2685 2728 2578 2565 2580 2515 2605 2568 2653 2680 2857 2803 2860 2786 2830 2597 2654 2610 2502 2568 2502 2544 2589 2723 2568 2643 2842 2847 2879 2988 2906 2899 2860 2661 2706 2743 2613 2594 2571 2579 2557 2560 2697 2767 2777 2750 2902 2998 3071 3254 3232 3286 3383 3304 3292 3378 3450 3505 3383 3433 3480 3472 3511 3360 3074 3132 3120 3147 3146 3244 3167 3182 3325 3346 3380 3567 3699 3699 3840 3974 4069 4332 4426 4467 4346 4036 3888 3903 3693 3723 3747 3792 3854 3894 4069 4073 4036 4069 4199 4293 4137 4096 4059 3818 3660 3325 3314 3300 3177 3140 3332 3089 3177 3128 3212 3162 3141 3061 3088 3028 2878 2871 2928 2851 2952 2984 2988 3072 3133 3382 3563 3730 3944 4182 4050 4209 3922 3638 3558 3266 3248 3146 2994 2975 2962 3124 3069 3102 3236 3437 3559 3624 3703 3475 3626 3446 3131 3045 2996 2950 2880 2748 2762 2760 2730 2810 2702 2803 2838 2817 2939 2833 2915 2853 3026 3033 3006 3136 3130 3253 3342 3565 3631 3823 4029 4206 4522 4695 4683 4695 4870 4534 4650 4557 4264 4256 4333 4313 4689 4662 5098 5359 5592 6144 6501 6808 6731 6756 6644 6476 6319 5919 5419 5045 4651 4405 4388 4266 4448 4526 4678 5135 5289 5535 5653 5557 5337 5000 4753 4421 4265 4004 3794 3597 3503 3510 3473 3456 3633 3804 3851 4095 4164 4095 3990 3754 3549 3572 3382 3304 3274 3089 3281 3298 3421 3313 3527 3518 3596 3537 3679 3673 3643 3719 3612 3562 3393 3410 3487 3344 3205 3123 3106 2985 2950 2930 2898 2911 2866 2930 2908 2871 2887 2929 2863 2784 2876 2950 2747 2611 2710 2612 2546 2643 2531 2613 2507 2520 2511 2450 2574 2425 2508 2462 2535 2540 2576 2568 2517 2492 2550 2579 2618 2548 2557 2528 2589 2701 2621 2739 2729 2742 2779 2850 2983 3059 3071 3386 3482 3663 3664 3686 3787 3923 3867 3861 3771 3592 3568 3413 3381 3376 3342 3460 3424 3352 3412 3413 3431 3338 3329 3209 3325 3250 3257 3075 3052 3025 2932 2941 2904 2901 2811 2855 3016 2792 2900 3045 3024 3164 3400 3690 3877 3715 3555 3371 3208 3109 2940 2785 2770 2605 2752 2655 2672 2691 2710 2787 2882 2874 2953 3092 3082 2907 2897 2739 2696 2572 2620 2541 2555 2523 2443 2493 2466 2570 2479 2403 2430 2640 2522 2441 2435 2417 2384 2462 2452 2395 2537 2451 2534 2406 2508 2545 2483 2682 2596 2666 2611 2669 2685 2616 2622 2687 2707 2638 2728 2657 2716 2744 2634 2709 2679 2745 2737 2741 2719 2823 2915 2907 2990 3116 3339 3472 3441 3365 3294 3259 3196 2898 2919 2733 2633 2587 2623 2614 2564 2501 2652 2692 2693 2801 2860 2761 2798 2833 2811 2659 2665 2602 2521 2564 2438 2494 2371 2390 2461 2307 2498 2381 2446 2413 2416 2372 2388 2423 2450 2432 2479 2497 2404 2359 2411 2444 2418 2474 2454 2476 2400 2458 2485 2451 2459 2468 2523 2548 2646 2575 2572 2530 2532 2527 2434 2537 2472 2432 2466 2534 2330 2428 2349 2453 2390 2500 2473 2483 2488 2403 2463 2452 2544 2517 2367 2466 2446 2514 2526 2548 2546 2465 2453 2390 2435 2479 2421 2353 2434 2420 2433 2442 2413 2432 2394 2540 2471 2506 2551 2506 2484 2505 2575 2614 2678 2547 2752 2792 2772 2854 2917 2891 2906 3016 2956 3016 3065 3181 3110 3143 3101 3104 3000 3027 3084 3119 3321 3241 3439 3618 3738 3921 4037 4156 4150 4274 4245 4308 4264 3984 3877 3745 3607 3474 3489 3345 3371 3346 3290 3407 3317 3390 3492 3514 3278 3322 3246 3280 3193 3196 3049 3041 2857 2825 2789 2733 2726 2610 2663 2711 2693 2648 2624 2457 2475 2622 2444 2469 2543 2472 2415 2516 2531 2513 2499 2566 2596 2513 2526 2649 2793 2829 2838 2913 3028 2992 3031 3106 2990 2882 2850 2778 2696 2685 2620 2630 2559 2649 2523 2590 2640 2605 2668 2731 2767 2843 2728 2751 2739 2734 2642 2693 2633 2693 2726 2753 2721 2850 3013 3103 3161 3264 3296 3336 3264 3176 3069 2913 2829 2788 2804 2713 2731 2664 2700 2593 2713 2787 2720 2797 2777 2858 2920 2954 2972 2945 2934 3042 2928 2923 3020 3022 2960 2882 2892 2882 2811 2776 2821 2862 2829 2935 3011 3079 3139 3240 3363 3410 3321 3179 3186 3188 3095 2860 2960 2803 2745 2824 2781 2754 2717 2833 2878 2821 2950 3022 2985 2955 3173 3120 3081 3109 3132 3204 3393 3420 3531 3641 3677 3557 3486 3266 3046 2966 2981 2905 2890 2791 2787 2877 2925 2843 2892 2855 2943 2905 2973 3032 3019 3116 3111 2949 2840 2888 2831 2790 2825 2780 2799 2759 2966 3107 3138 3388 3557 3634 3753 3932 4024 4131 3911 3858 3753 3543 3325 3135 3083 2930 2840 2741 2795 2777 2735 2835 2901 2918 3046 3060 3192 3119 3307 3121 3230 3038 3019 2830 2830 2836 2636 2759 2668 2459 2569 2540 2599 2668 2563 2605 2557 2572 2676 2605 2689 2716 2673 2954 3052 3112 3142 3239 3382 3240 3296 3193 3030 2884 2841 2781 2703 2728 2568 2564 2624 2668 2657 2721 2737 2831 2900 2874 2813 2901 2969 2955 2839 2722 2840 2646 2604 2600 2629 2599 2638 2645 2625 2609 2649 2625 2718 2814 2718 2761 2803 2746 2858 2866 2897 2797 2775 2801 2821 2749 2806 2704 2906 3073 3167 3339 3459 3620 3523 3323 3216 3078 2998 2984 2986 2904 2824 2824 2807 2892 2858 2963 2956 3024 2963 3280 3368 3273 3383 3559 3544 3548 3584 3464 3428 3512 3447 3213 3198 3288 3187 3171 3035 3031 3101 3079 2901 3015 3069 3041 3050 3102 3095 2965 3045 2884 2914 2999 2996 2948 2979 3041 2849 2848 2925 2979 3086 3149 3284 3441 3405 3475 3501 3447 3300 3209 3113 2893 2946 2790 2831 2762 2694 2697 2725 2702 2735 2664 2858 2882 2905 3047 3118 3119 3126 3035 2981 2938 3097 2912 3127 3169 3185 3097 3169 3141 3115 3168 3166 3123 3150 3209 3306 3351 3467 3492 3606 3616 3640 3636 3726 3783 3622 3602 3492 3314 3256 3171 2967 3041 2968 2901 2841 2964 3003 2975 3118 3200 3267 3300 3366 3413 3542 3621 3846 3871 4124 4145 3885 3816 3725 3568 3414 3325 3249 3332 3125 3050 2985 3051 2936 2910 2905 2930 2908 2798 3077 3084 3129 3329 3229 3325 3234 3160 3013 2990 2994 2926 2960 2920 2777 2674 2845 2650 2624 2636 2628 2653 2586 2658 2620 2554 2638 2708 2693 2749 2679 2826 2798 2837 2995 2956 2915 3004 2843 2949 2934 2729 2935 2926 2897 2924 2917 2857 2882 2915 2944 3004 3055 3065 3101 3162 3178 3268 3453 3511 3806 3891 3934 3879 3691 3600 3481 3236 3212 3065 2913 2925 2879 2828 2833 2733 2732 2740 2717 2908 2822 2880 3034 3118 3006 3083 3105 3061 3036 2842 2787 2685 2754 2629 2641 2487 2425 2487 2505 2554 2419 2506 2463 2368 2443 2535 2396 2334 2429 2395 2435 2415 2354 2372 2389 2355 2513 2421 2377 2318 2398 2393 2337 2424 2443 2322 2351 2426 2392 2420 2380 2385 2400 2373 2401 2418 2319 2436 2409 2483 2494 2501 2488 2492 2611 2596 2749 2766 2838 2835 3043 3136 3236 3192 3071 2979 2798 2801 2892 2889 2725 2809 2800 2716 2856 2883 2913 2871 2973 2862 2854 2994 2947 2887 2938 2985 2901 2877 2760 2733 2616 2712 2596 2607 2643 2701 2667 2615 2661 2611 2629 2662 2674 2679 2647 2543 2621 2736 2660 2650 2744 2756 2873 3026 3195 3185 3339 3474 3509 3665 3458 3561 3324 3310 3242 3105 3045 2821 2814 2788 2590 2791 2621 2767 2679 2676 2738 2795 2738 2790 2945 2964 3004 3023 2975 2986 2911 2904 2726 2654 2634 2602 2554 2516 2551 2455 2352 2476 2451 2457 2408 2385 2397 2505 2420 2396 2410 2461 2437 2264 2359 2363 2412 2458 2365 2473 2440 2455 2423 2439 2411 2389 2335 2392 2390 2332 2315 2329 2363 2331 2305 2411 2352 2373 2316 2320 2282 2390 2384 2347 2294 2426 2479 2361 2327 2334 2417 2365 2435 2304 2436 2378 2413 2406 2318 2350 2387 2333 2339 2471 2413 2353 2443 2469 2403 2402 2486 2326 2485 2477 2512 2523 2525 2574 2520 2492 2456 2535 2511 2436 2484 2413 2415 2455 2443 2506 2376 2373 2310 2441 2508 2394 2422 2500 2502 2505 2489 2600 2592 2580 2573 2584 2549 2607 2616 2689 2726 2752 2931 3051 2995 3107 3338 3369 3624 3692 3782 3708 3587 3572 3556 3318 3067 2950 2991 3058 2862 2869 2941 2947 3067 3195 3282 3404 3380 3576 3673 3574 3505 3526 3572 3392 3230 3180 3144 2964 2906 2898 2753 2668 2626 2653 2669 2760 2743 2723 2745 2750 2824 2858 2863 2808 2819 2821 2810 2763 2753 2721 2768 2790 2701 2792 2801 2918 3037 3086 3075 3219 3251 3239 3351 3338 3383 3431 3372 3432 3306 3218 3137 3027 2896 2826 2735 2753 2700 2774 2675 2680 2763 2816 2709 2836 2855 2916 2964 2977 2936 2931 2931 2957 2857 2877 2714 2653 2745 2700 2572 2592 2509 2617 2481 2494 2466 2410 2530 2486 2430 2534 2452 2471 2557 2381 2368 2370 2559 2350 2535 2567 2566 2563 2471 2530 2580 2505 2454 2565 2572 2698 2749 2854 2839 2931 3013 3147 3202 3342 3423 3681 3811 3793 4068 4186 4100 4100 4006 3767 3853 3711 3502 3322 3197 3167 3078 3058 2991 3008 3042 3193 3307 3473 3449 3557 3773 3871 4071 4111 4270 4411 4406 4323 4467 4036 4097 4142 4203 4226 4120 4238 4203 4131 4236 4000 4047 3946 3970 3708 3711 3719 3651 3886 3725 3940 3965 3999 4150 4053 3994 4077 4016 3980 4058 3999 3975 4015 3891 3890 3830 3627 3525 3399 3338 3181 3175 3096 3154 2965 3064 3009 3024 3124 3063 3036 3041 3033 2969 3009 2905 2922 2967 2863 2942 2941 2853 2865 3047 3035 3106 3230 3341 3356 3492 3175 3221 3079 2857 2900 2770</intensities>
			</dataPoints>
			<nonAmbientPoints type="Temperature" unit="K">
[...]
			</nonAmbientPoints>
		</scan>
	</xrdMeasurement>
</xrdMeasurements>