File: powder_X-ray_diffraction/variable-temperature_experiments/NaTaO2F2/raw_data/200°C.xrdml
<?xml version="1.0" encoding="UTF-8"?>
<xrdMeasurements xmlns="http://www.xrdml.com/XRDMeasurement/1.7" xmlns:xsi="http://www.w3.org/2001/XMLSchema-instance" xsi:schemaLocation="http://www.xrdml.com/XRDMeasurement/1.7 http://www.xrdml.com/XRDMeasurement/1.7/XRDMeasurement.xsd" status="Completed">
	<comment>
		<entry>Configuration=XRK900, Owner=User-1, Creation date=12/01/2015 16:52:44</entry>
		<entry>Goniometer=Theta/Theta; Minimum step size 2Theta:0.0001; Minimum step size Omega:0.0001</entry>
		<entry>Sample stage=AP XRK-900 with z-axis; Minimum step size Z:0.001</entry>
		<entry>Diffractometer system=EMPYREAN</entry>
		<entry>Measurement program=C:\PANalytical\Data Collector\Programs\Gwen\NaTaO2F2\NaTaO2F2-Lent.xrdmp, Identifier={FF50B583-C5FF-42DA-A01D-A1FB659EF29A}</entry>
		<entry>Batch program=C:\PANalytical\Data Collector\Programs\Gwen\NaTaO2F2\Thermodiff-Ouail.xrdmp, Identifier={5D65A6B1-42FC-480C-9FBB-D7D88D55EA08}</entry>
	</comment>
	<sample type="To be analyzed">
		<id></id>
		<name></name>
		<preparedBy></preparedBy>
	</sample>
	<xrdMeasurement measurementType="Scan" status="Completed" sampleMode="Reflection">
		<comment>
			<entry>PHD Lower Level = 4.02 (keV), PHD Upper Level = 12.07 (keV)</entry>
		</comment>
		<usedWavelength intended="K-Alpha 1">
			<kAlpha1 unit="Angstrom">1.5405980</kAlpha1>
			<kAlpha2 unit="Angstrom">1.5444260</kAlpha2>
			<kBeta unit="Angstrom">1.3922500</kBeta>
			<ratioKAlpha2KAlpha1>0.5000</ratioKAlpha2KAlpha1>
		</usedWavelength>
		<incidentBeamPath>
			<radius unit="mm">240.00</radius>
			<xRayTube id="1010048" name="Empyrean Cu LFF HR (9430 033 7310x) DK434948">
				<tension unit="kV">45.0</tension>
				<current unit="mA">30.0</current>
				<anodeMaterial>Cu</anodeMaterial>
				<focus type="Line">
					<length unit="mm">12.0</length>
					<width unit="mm">0.4</width>
					<takeOffAngle unit="deg">6.0</takeOffAngle>
				</focus>
			</xRayTube>
			<sollerSlit id="21010001" name="Soller slits 0.02 rad.">
				<opening unit="rad">0.0200</opening>
			</sollerSlit>
			<mask id="22030010" name="Fixed mask 20 mm">
				<width unit="mm">20.00</width>
			</mask>
			<antiScatterSlit id="22010003" name="Fixed slit 1Â°" xsi:type="fixedAntiScatterSlitType">
				<height unit="mm">1.52</height>
			</antiScatterSlit>
			<divergenceSlit id="22010012" name="Programmable divergence slit" xsi:type="fixedDivergenceSlitType">
				<distanceToSample unit="mm">140.00</distanceToSample>
				<angle unit="deg">0.5</angle>
			</divergenceSlit>
		</incidentBeamPath>
		<diffractedBeamPath>
			<radius unit="mm">240.00</radius>
			<antiScatterSlit id="22090010" name="AS slit 8.0 mm (PIXcel)" xsi:type="fixedAntiScatterSlitType">
				<height unit="mm">8.00</height>
			</antiScatterSlit>
			<sollerSlit id="21010001" name="Soller slits 0.02 rad.">
				<opening unit="rad">0.0200</opening>
			</sollerSlit>
			<filter id="20030001" name="Large beta-filter Nickel">
				<material>Ni</material>
				<thickness unit="mm">0.020</thickness>
			</filter>
			<detector id="7010019" name="PIXcel1D-Medipix3 detector" xsi:type="rtmsDetectorType">
				<phd unit="%">
					<lowerLevel>25.0</lowerLevel>
					<upperLevel>75.0</upperLevel>
				</phd>
				<mode>Scanning</mode>
				<activeLength unit="deg">3.3482</activeLength>
			</detector>
		</diffractedBeamPath>
		<scan appendNumber="0" mode="Continuous" scanAxis="Gonio" status="Completed">
			<header>
				<startTimeStamp>2023-01-22T00:06:43+01:00</startTimeStamp>
				<endTimeStamp>2023-01-22T03:07:16+01:00</endTimeStamp>
				<author>
					<name>User</name>
				</author>
				<source>
					<applicationSoftware version="5.5a">Data Collector</applicationSoftware>
					<instrumentControlSoftware version="8.2  20201204">EMPYREAN</instrumentControlSoftware>
					<instrumentID>0000000011159748</instrumentID>
				</source>
			</header>
			<dataPoints>
				<positions axis="2Theta" unit="deg">
					<startPosition>9.99846514</startPosition>
					<endPosition>99.99342261</endPosition>
				</positions>
				<positions axis="Omega" unit="deg">
					<startPosition>4.99923257</startPosition>
					<endPosition>49.99671130</endPosition>
				</positions>
				<positions axis="Z" unit="mm">
					<commonPosition>8.846</commonPosition>
				</positions>
				<commonCountingTime unit="seconds">386.070</commonCountingTime>
				<intensities unit="counts">6732 6807 6674 6712 6554 6531 6576 6612 6586 6649 6599 6680 6765 6536 6574 6477 6388 6412 6510 6468 6630 6482 6369 6271 6385 6305 6394 6529 6483 6203 6472 6477 6464 6333 6405 6447 6309 6319 6481 6311 6275 6341 6438 6434 6356 6452 6242 6392 6376 6432 6409 6366 6477 6348 6473 6359 6312 6243 6493 6460 6494 6519 6655 6685 6533 6700 6708 6565 6810 6913 7062 7069 7266 7682 7888 8601 9422 10546 11736 14134 18376 23271 29967 39438 47923 51713 50633 44207 36870 29611 22158 16608 12786 10269 8445 7746 7283 6926 6829 6669 6662 6558 6339 6433 6369 6266 6328 6224 6253 6297 6206 6241 6175 6132 6203 5959 5993 6036 6124 5998 6014 6113 5974 6249 5990 6001 5978 5994 6154 5923 5971 6041 5953 5866 5861 5976 5936 5830 5807 5927 5998 5929 5907 6049 5889 5852 5876 5879 5809 5896 5963 5803 5827 5757 5782 5772 5817 5745 5849 5754 5795 5918 5673 5910 5849 5948 5898 5835 5717 5725 5712 5674 5775 5692 5742 5670 5804 5736 5698 5814 5666 5491 5688 5727 5700 5790 5760 5607 5677 5779 5643 5580 5570 5786 5719 5508 5592 5731 5580 5752 5826 5703 5601 5634 5668 5567 5717 5631 5552 5537 5566 5610 5595 5546 5570 5579 5498 5609 5412 5553 5522 5422 5444 5459 5557 5466 5425 5532 5543 5547 5580 5437 5459 5463 5432 5381 5518 5535 5388 5406 5375 5516 5472 5483 5474 5539 5481 5404 5510 5402 5460 5458 5303 5482 5329 5324 5098 5281 5409 5429 5284 5242 5369 5322 5357 5284 5491 5422 5318 5349 5367 5326 5440 5358 5306 5277 5399 5377 5397 5216 5278 5265 5361 5377 5166 5219 5149 5210 5199 5199 5285 5266 5209 5173 5232 5240 5392 5223 5185 5153 5253 5214 5238 5099 5246 5209 5198 5203 5284 5184 5125 5242 5157 5148 5117 5202 5114 5186 5127 5059 5142 5050 5107 5205 5024 5237 5194 5154 5101 4956 5185 5022 5177 5206 5201 5060 5206 5069 5274 4969 4956 5078 5075 5010 5000 5192 5039 5131 5051 5084 5059 5023 4999 5049 5031 5055 5050 5048 5111 5018 4907 4952 5069 4940 4990 4968 4965 4931 5041 5052 4869 5077 4886 4827 4996 5082 4871 4937 4896 4884 5102 4997 4986 4978 5014 4921 4925 4915 4806 4979 5086 4885 4904 4913 4997 4931 4943 4908 4832 5028 4784 4843 4928 4948 4884 4960 5049 4822 4847 4869 4836 4862 5027 4734 4920 4861 4833 4851 4879 4878 4859 4803 4862 4860 4895 4719 4810 4852 4812 4813 4765 4745 4824 4908 4761 4895 4768 4802 4809 4830 4722 4798 4808 4808 4776 4720 4789 4762 4766 4884 4767 4793 4726 4687 4634 4676 4825 4711 4880 4800 4719 4888 4842 4823 4926 4980 4948 4819 4887 4901 4887 5048 4956 4929 4762 4897 4873 4944 4752 4894 4843 4993 4896 4851 4922 4781 4944 5027 4841 4874 4863 4812 4805 4934 4834 4865 4859 4862 4856 4690 4782 4691 4709 4781 4677 4718 4621 4605 4680 4671 4624 4524 4680 4621 4557 4688 4577 4561 4664 4709 4673 4599 4619 4498 4569 4595 4595 4651 4572 4573 4607 4666 4577 4566 4522 4527 4459 4513 4587 4578 4617 4749 4567 4599 4659 4531 4589 4708 4658 4855 4693 4664 4751 4677 4784 4657 4695 4728 4598 4650 4542 4611 4612 4520 4501 4569 4498 4604 4509 4457 4555 4474 4547 4462 4469 4401 4405 4516 4468 4468 4581 4252 4482 4443 4463 4453 4456 4639 4706 4868 4822 4780 4694 4739 4609 4570 4600 4553 4470 4403 4416 4368 4457 4385 4345 4364 4396 4387 4364 4346 4449 4373 4322 4353 4292 4375 4429 4305 4387 4338 4430 4349 4218 4346 4300 4336 4330 4376 4321 4270 4394 4445 4345 4250 4188 4344 4336 4280 4331 4215 4339 4194 4245 4298 4199 4358 4304 4270 4280 4344 4375 4450 4455 4416 4211 4423 4506 4366 4437 4429 4418 4347 4327 4379 4194 4282 4237 4216 4237 4149 4243 4105 4206 4078 4334 4229 4239 4198 4107 4271 4279 4243 4313 4203 4425 4538 4415 4465 4669 4597 4636 4699 4552 4536 4525 4607 4717 4682 4784 4498 4650 4680 4701 4601 4593 4423 4696 4671 4629 4776 4769 4667 4807 4759 4823 4830 5044 5176 5242 5366 5597 5649 5904 5941 6272 6843 7625 8598 10151 12768 16626 23014 34266 51780 75115 100230 121584 126502 120378 110065 97754 82769 62036 44352 31647 22679 15972 11713 9284 7751 6921 6306 5981 5685 5430 5135 4952 4871 4799 4704 4624 4711 4552 4550 4592 4503 4574 4467 4458 4341 4497 4693 4742 4759 4715 4645 4870 4552 4602 4540 4591 4400 4442 4290 4319 4247 4329 4219 4182 4081 4221 4185 4262 4289 4088 4327 4212 4061 4140 4070 4135 4089 4172 4173 4139 4188 4109 4141 4128 4140 4109 4084 4100 4084 4031 4059 4060 4027 4053 4031 3971 4050 3948 4078 4125 4197 3974 4013 3943 4062 4070 4150 4001 4149 4034 3969 3947 3855 4020 4017 3886 3992 3967 3970 4025 3937 3962 3944 3914 3991 4004 3877 3877 3917 3897 3896 3906 3950 3880 3940 3843 3960 3947 4030 3899 3946 3897 4000 3891 3925 3956 3933 3898 3825 3933 3990 3867 3914 3991 3954 3879 3851 3854 3977 4001 3904 3915 3960 3894 3895 3930 4019 3957 3909 3850 3819 4023 4092 4071 4244 4116 4200 4252 4212 4205 4057 4121 3984 3979 3961 4072 4151 4097 4023 4006 3997 4000 3911 3975 3929 3977 3749 3962 3976 3943 4058 3970 3957 4134 4128 4238 4219 4473 4603 5190 5691 6496 8529 11150 14834 18330 19922 18841 17148 16410 15662 12933 10078 8083 6892 5832 5008 4481 4346 4197 4161 4078 4032 3912 3893 3877 3915 3809 3885 3807 3900 3856 3929 3755 3821 3806 3906 3788 3859 3840 3923 3854 3845 3870 3861 3793 3937 3855 3812 3819 3728 3721 3730 3848 3777 3762 3665 3807 3694 3625 3673 3743 3757 3798 3706 3781 3653 3736 3676 3811 3672 3654 3684 3755 3723 3748 3612 3794 3680 3583 3684 3715 3767 3816 3825 3751 3767 3767 3874 3783 3860 3850 3904 3795 3797 3854 3884 3903 3969 3786 3924 3890 3910 3817 4020 3927 3951 3807 3950 3964 3933 3947 3944 3879 3953 3970 4079 4123 4028 4021 4076 4077 4082 4266 4179 4138 4244 4450 4376 4465 4531 4612 4590 4576 4790 5001 5016 5336 5754 6481 7561 9887 14129 20338 27375 35844 42195 46451 44555 39886 35627 32724 29243 24031 19304 16347 17138 20925 28251 36270 41597 47921 49640 46556 42861 38267 33760 27929 21484 16174 12285 9239 7139 5818 5234 4908 4748 4543 4334 4284 4141 4054 3990 4028 3874 4030 3829 3866 3895 3790 3763 3812 3832 3865 3814 3792 3696 3701 3786 3707 3734 3866 3696 3776 3937 3852 3890 4008 3886 3882 3856 3649 3613 3643 3670 3717 3656 3648 3736 3711 3684 3658 3581 3515 3613 3675 3604 3659 3595 3589 3561 3542 3694 3703 3586 3561 3593 3602 3630 3683 3797 3538 3520 3578 3596 3650 3552 3617 3658 3615 3561 3609 3573 3556 3535 3511 3567 3523 3560 3541 3548 3462 3559 3575 3489 3458 3610 3535 3475 3494 3536 3502 3531 3493 3492 3578 3514 3438 3558 3569 3499 3549 3591 3480 3553 3486 3609 3593 3729 3756 3792 4025 4003 3946 3971 3849 3802 3663 3953 3807 3794 3593 3587 3608 3590 3445 3562 3395 3476 3523 3425 3556 3593 3578 3620 3503 3410 3509 3545 3502 3562 3526 3531 3543 3522 3575 3454 3478 3486 3506 3489 3392 3481 3455 3495 3597 3568 3456 3496 3510 3597 3487 3610 3573 3742 3704 3615 3729 3731 3705 3648 3588 3595 3704 3666 3602 3652 3660 3729 3623 3468 3638 3723 3716 3562 3717 3642 3780 3700 3724 3699 3675 3690 3729 3604 3641 3696 3753 3617 3614 3637 3691 3591 3673 3735 3749 3635 3904 3679 3850 3880 3998 3959 4173 4217 4293 4436 4559 4688 4888 5054 5260 5784 6004 6479 7200 8014 9430 11477 15500 21962 33051 49139 66588 80536 84685 79147 71660 64580 59561 53580 45656 36193 26956 19330 13820 10258 8164 6849 6152 5624 5203 4743 4601 4377 4171 4214 4041 3940 3974 3798 3736 3746 3847 3664 3805 3705 3589 3648 3579 3689 3675 3676 3756 3778 3813 3864 3901 3911 3917 3893 3890 3817 3762 3826 3754 3679 3673 3661 3623 3685 3673 3675 3628 3655 3569 3557 3590 3500 3575 3587 3629 3569 3532 3501 3436 3445 3535 3439 3574 3487 3523 3588 3520 3522 3455 3614 3672 3445 3475 3494 3583 3757 3466 3599 3591 3515 3605 3629 3627 3704 3661 3845 3742 4015 3906 3973 4024 4152 4202 4454 4576 4769 4962 5317 6130 7504 10451 15068 21489 28429 32915 34149 30183 27282 25824 24645 23546 21818 19350 18281 18306 18874 19456 20222 19421 17613 15583 14408 13123 11968 10452 8634 7110 5729 4866 4332 4069 3847 3773 3873 3606 3618 3584 3437 3451 3529 3461 3350 3642 3449 3411 3432 3383 3462 3391 3248 3335 3381 3353 3457 3408 3336 3436 3347 3498 3446 3396 3389 3230 3333 3234 3325 3370 3418 3293 3174 3303 3429 3273 3367 3305 3413 3320 3289 3325 3225 3251 3400 3373 3257 3217 3290 3400 3462 3307 3380 3345 3286 3320 3275 3206 3242 3231 3259 3370 3247 3213 3108 3118 3136 3156 3110 3162 3273 3215 3156 3164 3220 3216 3134 3190 3278 3270 3211 3175 3150 3181 3046 3178 3176 3237 3192 3100 3280 3161 3133 3211 3246 3296 3175 3258 3282 3247 3157 3110 3102 3090 3029 3152 3105 3137 3104 3179 3097 3108 3198 3008 3077 3011 3207 3178 3116 3167 3158 3097 3185 3063 3249 3136 3146 3127 3093 3190 3116 3120 2987 3202 3133 3081 3042 3167 3079 3004 3064 3146 3141 3116 3115 3100 3146 3226 3179 3101 3044 3130 3109 3152 3126 3149 3155 3106 3089 3146 3004 3105 3026 3072 3143 3142 3220 3061 3179 3144 3094 3076 3099 3199 3110 3178 3134 3118 3100 3125 3128 3223 3124 3200 3126 3091 3064 3214 3234 3147 3223 3053 3170 3130 3120 3265 3249 3143 3252 3321 3215 3229 3257 3173 3315 3232 3358 3171 3187 3413 3264 3325 3352 3326 3374 3483 3495 3655 3669 3737 3746 3865 4021 4368 4797 6078 8315 12149 17173 21175 21811 18728 15242 13591 13205 13389 13447 11927 9932 7676 6063 5105 4373 4048 3898 3691 3687 3743 3680 3597 3671 3594 3665 3639 3755 3725 3900 3887 4010 4121 4275 4310 4503 4520 4975 5270 6289 8151 11438 16336 23282 31517 36260 34840 30355 26040 22602 21762 21647 21248 18401 14945 11707 8808 6902 5788 5019 4730 4616 4562 4551 4414 4594 4565 4875 4953 5247 5679 6256 7704 9911 13330 18005 22525 27321 29934 29962 28348 25381 23337 21736 21769 22865 24169 25261 24233 20315 15829 12806 11565 11139 11358 10636 9206 7716 6314 5319 4757 4170 3859 3685 3493 3496 3489 3477 3395 3296 3308 3267 3221 3272 3205 3247 3309 3214 3282 3187 3207 3224 3201 3157 3271 3192 3253 3121 3154 3199 3180 3163 3327 3261 3294 3309 3286 3285 3488 3492 3552 3573 3563 3818 3833 4330 5045 6381 8645 11531 13879 14493 13112 11120 9522 8950 8898 9446 9114 7997 6662 5574 4646 3940 3740 3390 3343 3292 3274 3154 3172 3321 3417 3552 3558 3768 3737 3579 3341 3302 3352 3433 3303 3250 3242 3192 2986 2906 3022 2979 3067 2902 2893 3029 2962 2896 2797 2812 3036 3047 2911 2983 3010 2873 2939 2957 3001 2879 2974 2909 2845 2895 2888 3044 2947 3011 2902 2917 3002 2944 3019 3004 2987 2902 2861 3024 2944 2909 2918 2937 2865 2932 2871 3025 2943 2948 2959 2995 2893 2883 2920 2922 2952 2911 2900 2946 2852 2962 2978 3023 3056 3075 3089 2932 3055 3052 2941 2895 2981 2948 3023 3013 3016 2971 2906 3091 2890 2897 2931 2916 2937 2808 2950 2882 2977 2968 2896 2975 2928 2936 2844 2881 2911 3032 2944 2962 2900 3081 3000 2947 3017 3080 3054 3049 3078 3090 3243 3241 3247 3429 3539 4011 4783 5934 7613 9211 9759 9158 7867 6592 6019 6144 6369 6669 6291 5500 4604 4057 3640 3249 3397 3180 3130 3104 2987 3140 2989 2893 2977 3053 3004 2962 3010 2951 2980 3035 2904 3005 2943 2992 3162 3031 3109 3288 3157 3107 3331 3438 3549 3676 4053 4928 6141 7586 8965 9730 10117 9830 9046 8004 7412 6989 6825 6772 6498 5959 5322 4630 3941 3635 3284 3174 3148 3085 3031 3311 3423 3652 3708 3613 3455 3412 3220 3347 3403 3335 3311 3292 3121 3064 3038 3073 2986 3067 2844 2831 2816 2794 2848 2748 2749 2737 2819 2878 2805 2657 2873 2756 2751 2782 2749 2794 2824 2676 2741 2666 2690 2661 2816 2795 2679 2798 2681 2761 2735 2818 2711 2684 2706 2786 2764 2721 2777 2828 2686 2738 2795 2710 2679 2763 2812 2763 2704 2731 2823 2782 2649 2781 2775 2736 2733 2799 2734 2733 2735 2779 2811 2768 2750 2810 2867 2768 2802 2797 2777 2747 2697 2766 2729 2698 2819 2800 2776 2723 2827 2805 2802 2708 2759 2733 2758 2757 2815 2858 2727 2817 2832 2831 2658 2689 2724 2715 2751 2712 2791 2658 2887 2625 2820 2724 2676 2818 2771 2807 2737 2681 2748 2814 2766 2697 2715 2804 2759 2907 2761 2716 2787 2851 2818 2718 2826 2895 2778 2853 2857 2856 2871 3002 3126 3427 3928 4319 4609 4901 4962 4830 4726 4147 4074 3973 4040 4099 4058 3944 3781 3497 3368 3187 3154 3211 3406 3563 3842 4405 5111 6164 7535 7793 7444 6580 5836 5357 5374 5448 5556 5530 5369 4840 4408 4074 3827 3530 3395 3263 3235 3463 3412 3532 3792 4307 5380 6622 8317 9496 10043 9164 7894 6445 5816 5926 6143 6686 6548 6048 5273 4587 3902 3563 3462 3121 3070 3012 3011 2996 2980 2985 3000 2950 2945 2925 2930 2871 2952 2958 2938 3022 3099 3150 3220 3247 3225 3425 3681 3817 4263 5101 6049 7145 8603 10125 11407 11518 10673 9066 8032 7496 7611 8371 9304 10188 11501 12796 13575 13505 12433 11023 9603 8981 9807 11681 14389 15815 16596 15384 12698 10073 8334 7384 7400 7776 7941 7711 6818 5635 4856 4064 3748 3440 3277 3016 2941 2951 2963 2906 2975 2920 2919 2861 2879 2836 2790 2824 2845 2746 2784 2811 2868 2805 2693 2757 2672 2768 2831 2733 2719 2698 2693 2785 2678 2697 2681 2742 2648 2719 2690 2669 2664 2683 2760 2596 2691 2699 2698 2729 2666 2782 2783 2672 2727 2640 2738 2627 2759 2626 2621 2615 2714 2641 2727 2639 2649 2616 2679 2670 2695 2715 2762 2708 2663 2700 2642 2692 2768 2619 2748 2694 2698 2615 2620 2696 2732 2565 2709 2707 2661 2747 2681 2656 2717 2688 2707 2656 2775 2702 2802 2712 2702 2735 2709 2694 2722 2662 2691 2757 2705 2680 2678 2715 2713 2731 2736 2672 2792 2720 2609 2689 2658 2756 2655 2662 2723 2642 2658 2647 2669 2669 2667 2660 2685 2661 2653 2756 2657 2766 2700 2664 2672 2772 2738 2748 2813 2810 2823 2881 3218 3302 3420 3346 3319 3151 3027 3023 3104 2972 2990 3093 3062 2940 2857 2760 2759 2800 2710 2655 2616 2728 2691 2736 2609 2642 2711 2624 2652 2671 2678 2701 2709 2674 2684 2723 2661 2541 2635 2730 2613 2616 2633 2621 2626 2648 2612 2658 2693 2728 2780 2717 2726 2692 2734 2797 2846 3005 3149 3401 3692 3910 4163 4157 3871 3548 3371 3175 3250 3406 3439 3413 3481 3252 3230 3032 3047 2907 2945 2862 2920 3000 3185 3415 3770 4201 4712 5292 5486 5657 5545 5044 4395 4170 4070 4158 4191 4290 4191 4042 3739 3485 3207 3055 2862 2836 2822 2731 2796 2666 2717 2697 2786 2709 2745 2783 2747 2683 2729 2656 2662 2643 2693 2677 2667 2609 2684 2807 2649 2561 2632 2513 2577 2655 2650 2726 2691 2637 2698 2707 2624 2575 2581 2647 2727 2653 2707 2590 2652 2706 2823 2690 2734 2754 2743 2705 2849 2859 2819 2789 2867 2865 2876 3009 3010 2930 3092 3256 3506 3789 4264 5403 7301 9697 11758 12127 10719 8501 6668 5454 5131 5366 6298 7284 7339 6982 5917 4828 4083 3548 3260 3085 2965 2953 2855 2830 2831 2782 2741 2689 2652 2711 2728 2704 2754 2672 2652 2853 2637 2805 2767 2831 2773 2848 2791 2850 2891 2823 2921 2966 2948 3318 3583 4084 5015 6045 7111 7588 6974 5812 4908 4204 4074 4052 4456 4832 5228 5049 4513 3962 3473 3303 3143 3028 2958 2917 2849 2736 2740 2918 2836 2771 2800 2795 2808 2797 2706 2730 2814 2749 2765 2788 2881 2798 2874 2809 2867 2903 2890 2950 2912 2882 2933 2925 2993 3075 3203 3349 3454 3834 4389 5140 5894 6886 7869 8438 8571 8348 7053 5914 5401 5054 5203 5569 5752 5840 5820 5272 4536 3972 3521 3356 3289 3039 3070 2972 3055 3090 3086 3078 3109 3050 3115 3287 3159 3212 3158 3355 3424 3450 3508 3490 3485 3512 3721 3867 3959 4447 4819 5310 6328 7754 9850 12732 15979 19178 20457 19455 16726 14049 11451 10361 9910 10706 11473 12399 12126 11166 9634 7838 6430 5341 4654 4325 3948 3843 3442 3367 3322 3313 3202 3214 3154 3305 3215 3138 3241 3177 3165 3321 3264 3324 3495 3514 3801 4386 4948 6027 7911 9936 11757 12704 12749 13025 13567 13022 11950 11170 10490 9822 9482 8889 8619 8373 8559 8010 7213 6499 5529 4909 4458 4029 4040 4091 4551 4976 5821 7332 9031 11333 12973 13147 12040 9865 8214 6763 6105 6256 6930 7810 8257 8336 7514 6325 5165 4343 3981 3641 3435 3324 3126 3183 3131 3025 3025 2947 2938 2837 2980 2862 2872 2882 2829 2930 2833 2777 2819 2832 2845 2756 2894 2843 2896 2748 2926 2947 3025 3251 3372 3525 3592 3663 3397 3327 3166 3058 3186 3195 3214 3330 3425 3424 3306 3375 3419 3455 3480 3451 3343 3376 3157 3273 3385 3333 3390 3469 3463 3555 3551 3460 3633 3547 3702 3807 4159 4435 4968 5905 7122 9121 12298 15710 18300 19207 18207 15691 13157 11057 10036 9808 10526 11639 12369 12189 11580 9979 8422 7089 6088 5386 4911 4661 4145 4073 3792 3760 3608 3507 3473 3513 3568 3591 3771 3948 4027 4369 4889 5514 6288 7842 9114 10454 11465 11473 10869 9426 7816 6925 6435 6494 6596 7036 7318 7546 6983 6123 5481 4691 4026 3678 3561 3275 3227 3192 3060 2948 2980 3035 2989 2980 2808 2878 2905 2759 2832 2881 2895 2863 2867 2880 2766 2846 2821 2930 2856 2793 2834 2843 2891 2855 2987 2955 2985 2908 2868 2888 2953 2948 3008 3051 3073 3111 3248 3464 3814 4050 5093 6080 7898 8906 8945 8207 7224 6179 5009 4605 4349 4726 5269 5882 6195 5971 5273 4868 4364 4118 3828 3767 3836 3619 3325 3256 3155 3116 2935 3033 3192 3240 3195 3191 3055 3045 2936 2836 2875 2800 2826 2827 2862 2826 2833 2757 2735 2848 2833 2752 2733 2786 2786 2765 2780 2771 2781 2828 2654 2757 2772 2804 2752 2779 2682 2866 2774 2803 2784 2852 2869 2859 2833 2889 2999 3002 2961 2988 2998 3070 3218 3187 3267 3222 3643 3931 4482 5171 6267 7517 8812 10091 10627 10591 10393 9385 8160 7142 6174 6011 6011 6460 6768 6853 6959 6551 5932 5374 4462 3952 3638 3415 3285 3339 3319 3451 3742 4118 4456 4943 5177 5655 5822 5860 5905 5852 5764 5081 4835 4525 4427 4447 4391 4314 4398 4430 4341 4093 3776 3436 3271 3050 3073 2832 2876 2785 2773 2768 2745 2753 2770 2637 2760 2779 2713 2769 2680 2774 2851 2758 2793 2927 2929 3164 3080 3350 3581 3725 3979 4238 4315 4236 3860 3647 3497 3291 3171 3298 3385 3431 3660 3546 3361 3200 3196 2929 2886 2775 2746 2926 2753 2704 2628 2737 2723 2763 2655 2623 2736 2721 2524 2764 2722 2662 2716 2555 2614 2625 2640 2666 2615 2696 2666 2526 2680 2739 2658 2649 2826 2669 2750 2777 2731 2812 2995 2972 3068 3106 3227 3099 2985 3090 3116 3051 2970 2972 2963 2981 2889 2834 2853 2916 2846 2749 2810 2803 2754 2828 2666 2724 2730 2642 2656 2663 2619 2656 2719 2691 2726 2676 2638 2655 2578 2733 2627 2596 2751 2626 2703 2724 2707 2705 2684 2610 2710 2582 2670 2720 2756 2717 2714 2798 2773 2709 2647 2707 2726 2779 2815 3013 2932 2917 2914 2998 2914 3031 2992 3002 3114 3181 3354 3398 3573 3815 4191 4693 5474 6596 8362 9904 11207 11206 10493 9163 7586 6484 5870 5566 5638 6217 6889 7278 7615 7347 6543 5814 5072 4388 3869 3762 3628 3508 3583 3656 3608 3653 3469 3368 3263 3121 3127 3116 2976 2932 3174 3010 3049 3153 3032 2945 2852 2921 2853 2866 2912 2845 2770 2951 2918 3023 2940 2974 3015 3046 3064 3112 3143 3135 3198 3380 3531 3709 3995 4557 5223 6434 8152 10031 11630 12698 13174 12841 12214 11096 10254 9064 8339 8184 8383 8460 8552 8937 8837 8305 7682 6890 6225 5497 4943 4391 4057 3769 3615 3426 3330 3281 3184 3050 3091 3110 3018 2891 2994 2928 2984 2954 2979 3130 2974 3064 3144 3096 3181 3060 3201 3206 3325 3504 3576 3864 4236 4740 5270 6073 6897 7759 8561 8803 9118 9404 9458 9425 8940 8338 7579 7003 6842 6921 6991 7355 7752 8112 8703 9107 9020 8859 8148 6960 6131 5403 4745 4508 4460 4443 4576 4851 5006 4986 4766 4382 3886 3780 3445 3313 3126 3240 3077 3173 2974 3066 3105 3037 2975 3014 3034 3117 3251 3134 3198 3245 3295 3406 3685 3986 4481 5010 5899 7045 8207 8878 8914 8070 6859 5982 5273 4903 4938 5099 5405 6089 6697 7189 6922 6353 5859 5231 4748 4366 4127 3892 3683 3485 3627 3594 3503 3683 3526 3425 3368 3292 3246 3190 3153 3138 3272 3218 3283 3152 3365 3558 3663 3717 4029 4489 5075 5639 6441 7281 8071 8598 8651 8289 7654 6686 6008 5485 5303 5513 5788 6279 6943 7731 8473 9463 10243 10579 10534 9589 8290 6920 5697 5014 4746 4842 5092 5392 5939 6538 6846 6946 6749 6559 6576 6998 7702 8439 9123 9734 9480 8503 7350 6212 5518 4957 4958 4913 5336 5722 6044 6163 6114 5699 5173 4667 4173 3676 3485 3253 3217 3135 3034 3030 3045 3039 3047 3005 3109 3161 2929 3049 3029 3095 3230 3199 3355 3432 3862 4105 4529 5122 5666 6570 7198 7979 8453 8492 8125 7589 6897 6217 5878 5870 5958 6525 7282 7947 8675 9115 9329 9674 9971 10755 11405 11917 11574 10239 8703 7568 6558 6069 5762 5744 5892 6176 6669 7034 6886 6619 5766 5048 4448 3873 3632 3447 3301 3212 3080 3038 3027 2961 2998 2819 2949 2891 2909 3033 3025 2997 2929 2927 3023 2980 2943 2967 3053 2963 3076 3090 3043 3157 3338 3388 3454 3765 4024 4290 4786 5574 6686 8002 9602 11352 12361 12606 12429 11937 11134 10271 9327 8491 7731 7386 7768 8017 8746 8957 9229 9054 8722 8403 8228 7415 6829 6134 5651 5195 4916 4776 4903 5058 5163 5397 5648 5737 5800 5638 5405 5022 4543 4037 3664 3599 3639 3581 3632 3808 3627 3849 3582 3600 3514 3314 3053 2914 2841 2684 2760 2738 2687 2625 2649 2606 2559 2555 2621 2594 2636 2632 2580 2591 2563 2489 2511 2601 2616 2553 2517 2561 2581 2585 2538 2542 2567 2556 2632 2692 2556 2547 2543 2521 2660 2534 2561 2608 2531 2561 2493 2616 2542 2448 2415 2522 2593 2495 2523 2571 2540 2473 2485 2500 2519 2559 2552 2417 2506 2441 2500 2546 2604 2553 2528 2451 2558 2576 2420 2560 2528 2457 2526 2557 2545 2559 2505 2558 2578 2596 2563 2570 2522 2593 2530 2499 2532 2548 2492 2430 2533 2542 2545 2441 2499 2478 2503 2488 2444 2472 2455 2443 2506 2474 2391 2493 2509 2426 2490 2420 2457 2487 2559 2438 2443 2495 2507 2493 2507 2503 2485 2456 2456 2504 2594 2504 2451 2475 2395 2562 2440 2465 2610 2410 2427 2475 2491 2497 2464 2530 2513 2526 2510 2548 2566 2489 2570 2611 2451 2632 2507 2539 2675 2618 2692 2729 2612 2724 2804 2863 3045 3159 3187 3256 3523 3708 3913 4030 4035 4034 3681 3381 3226 3113 2926 3017 2999 3062 3115 3361 3359 3354 3247 3146 2954 2923 2809 2861 2693 2745 2738 2750 2843 2884 2907 3000 3125 3377 3572 3894 4157 4063 4245 4205 4064 3845 3685 3507 3564 3737 3941 4028 4345 4573 4624 4724 4389 4133 3726 3423 3207 3154 3084 3184 3133 3277 3243 3197 3219 3180 3022 2869 2740 2623 2579 2567 2578 2541 2507 2525 2556 2520 2456 2480 2524 2442 2438 2442 2514 2385 2493 2420 2568 2397 2505 2462 2435 2467 2458 2468 2575 2614 2629 2749 2645 2696 2699 2722 2719 2779 2678 2726 2637 2735 2789 2682 2690 2745 2784 2914 2684 2703 2591 2673 2722 2640 2483 2595 2472 2588 2572 2468 2455 2519 2461 2461 2580 2564 2508 2409 2388 2414 2374 2349 2341 2410 2562 2417 2386 2439 2358 2406 2404 2458 2414 2424 2404 2438 2415 2422 2349 2341 2453 2372 2411 2436 2428 2376 2474 2341 2397 2431 2412 2429 2520 2417 2445 2365 2385 2355 2455 2394 2379 2431 2360 2436 2390 2453 2363 2416 2464 2424 2378 2413 2349 2354 2484 2363 2339 2330 2382 2333 2374 2411 2339 2460 2293 2372 2407 2357 2365 2403 2494 2504 2383 2453 2325 2427 2424 2394 2456 2454 2526 2555 2608 2544 2536 2497 2473 2500 2410 2419 2438 2384 2424 2420 2551 2491 2460 2539 2552 2514 2456 2525 2562 2596 2644 2509 2541 2421 2486 2430 2358 2406 2336 2526 2430 2425 2545 2427 2524 2462 2390 2484 2398 2375 2369 2371 2339 2455 2358 2459 2433 2333 2356 2387 2286 2410 2413 2359 2386 2492 2365 2434 2395 2457 2379 2401 2340 2457 2376 2390 2317 2311 2422 2424 2403 2448 2262 2307 2448 2388 2399 2411 2340 2401 2382 2421 2432 2414 2324 2368 2431 2395 2470 2432 2518 2444 2424 2423 2443 2441 2538 2391 2460 2327 2363 2500 2435 2360 2570 2411 2544 2430 2519 2451 2492 2523 2471 2562 2570 2667 2770 3000 3007 3202 3434 3569 3784 3592 3265 3101 2943 2888 2823 2762 2840 2893 3001 3201 3294 3401 3669 3591 3398 3296 3177 3050 2840 2836 2881 2732 2728 2735 2853 2819 2810 2948 2806 2941 2938 3252 3363 3497 4111 4705 5240 5130 5229 4709 4080 3642 3227 3048 2971 3004 2934 2864 3104 3467 3613 3773 3788 3777 3575 3309 3104 2849 2743 2709 2646 2674 2626 2583 2505 2477 2459 2528 2604 2548 2463 2539 2483 2551 2523 2617 2470 2593 2641 2620 2596 2697 2620 2717 2879 3084 3152 3553 3873 4028 3809 3622 3474 3309 3298 3322 3534 3570 3638 3941 3977 4071 4229 4173 4269 4106 3886 3437 3401 3277 3143 3193 3164 3247 3204 3288 3347 3168 3291 3385 3513 3427 3449 3494 3648 3722 3807 3753 3682 3827 4118 4317 4740 5271 6045 6445 7017 7092 6904 6360 5754 5404 5078 4731 4781 4980 5132 5075 5445 5405 5383 5439 5464 5187 4832 4485 4161 4082 3998 4017 3920 4028 3857 3635 3557 3362 3205 3103 3010 2968 2937 2982 3050 3100 3165 3405 3424 3550 3846 4125 4619 4803 5064 5157 4914 4549 4298 4071 3770 3509 3362 3377 3370 3318 3445 3629 3825 4077 4078 3912 3844 3765 3588 3584 3349 3406 3662 3817 4052 4063 4137 4387 4373 4337 4273 4369 4236 4062 3955 3855 3687 3694 3565 3481 3509 3555 3490 3645 3731 3763 3804 3929 4234 4481 5060 5552 5822 5457 4889 4336 3714 3316 3118 2970 2882 2923 3044 3105 3193 3317 3652 3880 3875 3866 3482 3214 3134 3038 2909 2791 2785 2696 2840 2731 2840 2903 2938 3139 3250 3336 3744 4016 4133 4180 4033 3963 3768 3566 3469 3561 3591 3692 3729 3851 3927 4142 4162 4251 4220 4089 3956 3658 3425 3379 3183 3118 3149 3116 3069 3024 3090 3140 3031 3138 2965 2892 2899 2647 2853 2610 2588 2640 2524 2503 2618 2490 2583 2539 2449 2469 2496 2527 2563 2501 2574 2571 2555 2588 2628 2587 2585 2682 2640 2735 2612 2764 2997 3232 3336 3548 3818 4094 4260 4335 4149 3964 3671 3307 3248 3109 2962 2869 2994 3022 2973 3106 3352 3323 3461 3337 3315 3222 3034 2997 2798 2703 2726 2671 2570 2675 2696 2706 2823 2819 2852 3118 3136 3266 3675 3930 4241 4323 4422 4414 4116 4095 3787 3504 3302 3122 3108 3023 3070 3111 3249 3500 3613 3558 3703 3870 3865 3860 3724 3877 3787 3859 3852 4120 4003 3939 3738 3690 3505 3327 3284 3300 3397 3451 3558 3597 3619 3496 3482 3465 3404 3412 3216 3132 3091 3109 3033 2970 3059 3061 3200 3274 3264 3404 3588 3865 4231 4616 4934 5262 5531 5482 5447 5455 5562 5595 5208 4937 4592 4162 3947 3809 3658 3751 3879 3943 4064 4011 3993 3875 3906 3953 3734 3755 3459 3269 3057 2857 2779 2591 2617 2616 2541 2507 2461 2523 2484 2379 2415 2394 2430 2503 2524 2484 2437 2452 2346 2461 2479 2464 2341 2439 2480 2416 2353 2436 2307 2450 2411 2387 2343 2472 2396 2469 2454 2339 2449 2430 2407 2388 2383 2382 2459 2432 2412 2326 2506 2393 2485 2328 2474 2324 2432 2366 2399 2319 2431 2376 2471 2301 2389 2451 2389 2372 2370 2424 2348 2284 2385 2423 2350 2480 2358 2432 2398 2469 2350 2407 2435 2503 2413 2437 2456 2487 2482 2493 2488 2553 2576 2467 2527 2491 2500 2412 2370 2392 2427 2506 2501 2427 2532 2550 2493 2523 2453 2543 2512 2564 2494 2516 2481 2399 2590 2477 2484 2435 2587 2623 2466 2492 2536 2536 2433 2555 2649 2648 2501 2775 2720 2828 2799 2868 2917 2931 2911 2959 2955 3089 3149 3015 3058 3082 3227 3414 3434 3720 4016 4193 4384 4643 4777 4821 4904 4628 4349 4177 3935 3714 3480 3303 3240 3174 3236 3330 3364 3469 3422 3518 3597 3535 3428 3361 3214 3136 3131 2959 2907 2663 2657 2609 2655 2586 2720 2638 2708 2667 2624 2721 2733 2863 2870 3019 3171 3267 3474 3655 3931 4042 4271 4376 4538 4367 4431 4206 4107 3784 3557 3465 3197 3078 3084 3094 3150 3256 3392 3343 3462 3529 3353 3408 3343 3203 3103 3014 2806 2789 2699 2659 2667 2553 2487 2519 2474 2504 2486 2533 2397 2499 2601 2677 2537 2599 2736 2670 2729 2831 2998 3090 3095 3180 3128 2983 2891 2811 2737 2694 2628 2631 2659 2555 2655 2717 2625 2689 2758 2926 2799 2790 2811 2712 2682 2668 2670 2564 2602 2489 2628 2676 2646 2702 2581 2724 2795 2896 2863 2890 2858 2834 2812 2648 2650 2610 2658 2618 2586 2607 2604 2733 2713 2873 2874 2944 3103 3175 3385 3321 3438 3294 3549 3334 3430 3570 3557 3387 3548 3523 3457 3229 3168 3062 3080 3037 3109 3241 3230 3298 3398 3349 3555 3684 3991 4043 4284 4412 4586 4522 4381 4419 4164 3981 3853 3796 3720 3911 3985 3916 3910 4076 4086 4110 4204 4210 4239 4122 3974 3742 3658 3551 3408 3388 3268 3209 3140 3185 3333 3148 3223 3160 3091 2984 3036 2967 3006 2791 2820 2852 2747 2856 2886 2971 3027 3062 3257 3322 3751 3984 4047 4292 4247 3860 3642 3459 3392 3262 3093 3155 3022 3068 3107 3157 3242 3337 3334 3568 3644 3673 3570 3613 3377 3241 3137 3021 2936 2802 2881 2704 2776 2738 2897 2852 2800 2888 2798 2870 2976 2971 2977 2987 2993 3189 3115 3230 3349 3483 3571 3701 4029 4198 4424 4589 4825 4754 4739 4529 4521 4291 4132 3970 4036 3891 4120 4283 4428 4610 5028 5378 5734 6108 6621 7013 7181 7361 7091 6525 5973 5274 5038 4580 4331 4200 4160 4279 4383 4561 4938 5177 5485 5646 5605 5523 5414 5106 4777 4472 4069 3973 3727 3681 3773 3625 3826 3827 3842 4024 3974 4007 3982 3819 3574 3436 3285 3197 3199 3138 3093 3292 3412 3356 3347 3499 3639 3468 3731 3696 3707 3614 3637 3548 3573 3531 3378 3339 3243 3237 3109 2945 2953 2936 2932 2903 2922 2919 3008 3022 2832 2845 2958 2909 2980 2819 2775 2694 2587 2654 2544 2630 2549 2546 2467 2621 2524 2576 2513 2544 2707 2502 2523 2567 2539 2491 2585 2638 2613 2663 2594 2556 2615 2502 2697 2647 2679 2690 2768 2824 2961 2897 3128 3111 3324 3411 3405 3671 3707 3790 3714 3874 3669 3771 3639 3355 3395 3288 3260 3298 3327 3344 3380 3438 3497 3498 3540 3491 3485 3507 3371 3338 3225 3038 3004 2979 2961 2825 2826 2793 2792 2952 2873 2768 2851 2856 2881 2907 3099 3142 3347 3576 3763 3683 3693 3558 3381 3077 2899 2794 2749 2710 2685 2703 2682 2678 2702 2704 2725 2934 2971 2985 3145 3041 3038 2985 2741 2739 2604 2609 2512 2448 2422 2477 2456 2528 2520 2497 2484 2541 2554 2531 2446 2479 2390 2447 2446 2476 2464 2491 2428 2468 2601 2578 2539 2620 2731 2717 2730 2600 2699 2701 2776 2737 2663 2699 2689 2791 2700 2722 2766 2751 2734 2842 2802 2762 2850 2877 3113 3172 3304 3513 3438 3407 3497 3324 3097 2903 2857 2809 2767 2651 2652 2565 2681 2584 2682 2671 2750 2839 2868 2894 2901 2916 2810 2721 2672 2676 2608 2482 2463 2416 2516 2384 2455 2329 2389 2449 2412 2396 2387 2385 2493 2463 2421 2443 2412 2469 2384 2432 2294 2377 2380 2434 2396 2476 2390 2507 2406 2445 2443 2435 2434 2492 2603 2531 2603 2546 2503 2613 2513 2603 2546 2558 2436 2448 2404 2442 2456 2434 2425 2560 2538 2415 2467 2429 2504 2521 2468 2561 2462 2510 2561 2474 2512 2493 2469 2411 2632 2471 2480 2414 2435 2511 2438 2453 2442 2387 2422 2465 2436 2395 2487 2417 2473 2520 2410 2519 2556 2615 2671 2607 2640 2724 2846 2943 2860 2911 2947 2950 2884 2978 3043 3058 3248 3190 3195 3099 3116 3070 3011 3124 3195 3386 3397 3571 3764 3813 3876 4058 4205 4351 4370 4478 4230 4188 4017 3836 3742 3459 3413 3458 3325 3276 3399 3371 3336 3231 3364 3365 3370 3390 3407 3390 3210 3097 3026 2936 2894 2829 2810 2767 2746 2708 2732 2693 2655 2652 2609 2586 2468 2575 2525 2453 2497 2476 2495 2578 2571 2591 2621 2535 2537 2561 2716 2726 2843 2904 2983 3035 3077 3047 2975 2985 2878 2762 2699 2785 2659 2606 2628 2608 2545 2519 2661 2716 2691 2721 2653 2698 2829 2851 2838 2710 2867 2693 2667 2702 2737 2638 2733 2726 2790 2872 3034 3125 3235 3187 3371 3298 3340 3150 2981 2898 2931 2815 2720 2801 2627 2688 2636 2621 2617 2722 2794 2704 2832 2878 3056 2983 3038 2808 2781 2927 2852 2846 2826 2827 3053 3026 2955 2934 2989 2928 3057 2890 2965 3156 3130 3153 3332 3311 3313 3257 3165 3035 2979 3058 2902 2939 2831 2856 2829 2779 2749 2785 2774 2939 2930 2984 2896 2927 3029 2981 2995 3089 3078 3037 3053 3138 3062 3223 3473 3559 3582 3675 3543 3296 3332 3070 2975 2903 2879 2821 2824 2877 2804 2915 2829 2794 2741 2955 2979 2872 3050 3102 3111 2979 2957 2908 2787 2814 2931 2908 2928 2904 3021 3209 3256 3312 3609 3628 3618 3829 3880 3882 3707 3742 3505 3366 3245 3081 2985 2989 2930 2875 2860 2972 2865 2824 2912 3100 3058 3030 3138 3191 3172 3125 3118 3017 2851 2911 2769 2879 2699 2581 2589 2517 2614 2607 2622 2580 2585 2449 2560 2515 2618 2599 2616 2675 2595 2790 2821 3008 3038 3102 3303 3348 3526 3279 3157 3100 3092 2870 2729 2818 2659 2688 2652 2654 2706 2677 2783 2853 2904 2901 2783 2914 2871 2908 2934 2826 2760 2734 2715 2569 2592 2630 2577 2598 2711 2616 2686 2779 2842 2829 2774 2902 2770 2716 2867 2810 2652 2699 2725 2669 2652 2621 2578 2657 2741 2716 2779 2985 3118 3201 3391 3544 3661 3714 3586 3304 3111 2981 2899 3025 2831 2894 2988 2865 2895 2946 3038 3169 3122 3180 3337 3331 3411 3627 3624 3742 3694 3677 3652 3375 3415 3310 3195 3140 3188 3046 2997 3095 3047 3120 3079 3087 3036 2931 3042 2968 3008 2945 3029 3013 3100 2981 2975 2912 2980 2995 3084 3117 3245 3244 3456 3449 3567 3495 3282 3271 2945 2949 2995 2830 2863 2846 2700 2696 2787 2599 2830 2812 2870 2819 2884 2844 2963 3003 3125 2952 2988 3114 3003 3083 3065 3146 3241 3178 3071 3050 2947 3025 2913 2990 2828 2879 2891 3028 3083 3197 3200 3365 3438 3508 3538 3649 3771 3880 3754 3768 3677 3619 3367 3193 3193 3102 2980 2886 2978 2945 2898 2961 3039 2987 3153 3193 3241 3406 3446 3421 3692 3776 3863 4064 4222 4148 4094 4022 3772 3578 3495 3386 3157 3204 3233 3152 3016 2922 2852 2877 2965 2890 2984 3055 3033 3211 3258 3394 3275 3405 3306 3296 3062 3024 3024 2883 2835 2891 2827 2768 2632 2842 2694 2633 2629 2628 2609 2593 2674 2611 2663 2560 2786 2780 2810 2970 2978 3007 2988 2888 3001 2975 2914 2938 2898 2963 2810 2872 2897 2880 2882 3019 2952 2955 3079 3113 3147 3206 3378 3355 3664 3801 3777 3867 3718 3734 3713 3428 3380 3148 3016 2931 2976 2912 2956 2847 2690 2833 2812 2760 2738 2828 2985 2982 2989 3101 3087 3016 3095 2963 2960 2694 2672 2732 2582 2606 2516 2405 2545 2529 2462 2394 2467 2426 2461 2557 2366 2516 2413 2413 2437 2531 2410 2395 2456 2383 2378 2415 2382 2363 2350 2356 2364 2424 2321 2424 2393 2352 2431 2395 2368 2405 2490 2450 2486 2474 2413 2477 2437 2428 2414 2446 2617 2559 2593 2626 2656 2790 2900 2991 3139 3073 3196 3072 3047 2996 3008 2864 2876 2904 2840 2878 2828 2815 2917 2678 2859 2918 2849 2895 3042 3004 2937 2960 2998 2895 2995 2883 2859 2790 2643 2731 2666 2618 2611 2582 2692 2603 2582 2620 2709 2667 2729 2798 2678 2632 2602 2633 2537 2609 2692 2698 2766 2967 3049 3211 3188 3305 3389 3489 3424 3529 3571 3582 3491 3326 3107 3104 2873 2888 2803 2668 2691 2712 2591 2641 2668 2669 2788 2770 2767 2905 2796 2881 2829 2936 3058 2977 2944 2772 2748 2622 2592 2538 2453 2432 2514 2405 2392 2479 2423 2412 2483 2512 2377 2428 2516 2402 2374 2366 2354 2360 2363 2354 2439 2340 2407 2346 2413 2402 2391 2316 2341 2343 2407 2269 2297 2416 2354 2328 2405 2407 2358 2375 2397 2382 2367 2384 2361 2455 2450 2423 2415 2374 2466 2405 2446 2363 2496 2429 2371 2381 2441 2376 2381 2353 2415 2403 2417 2394 2416 2308 2351 2395 2478 2465 2525 2432 2531 2576 2506 2541 2547 2630 2670 2539 2610 2509 2436 2472 2490 2395 2442 2500 2440 2455 2385 2489 2536 2464 2419 2502 2418 2516 2361 2512 2505 2555 2551 2468 2626 2572 2531 2571 2652 2541 2729 2847 2814 2998 3181 3229 3307 3447 3528 3588 3618 3752 3657 3434 3333 3205 3292 3132 3124 3049 2928 3092 2887 2982 3207 3315 3309 3479 3535 3618 3599 3523 3567 3500 3471 3350 3209 3194 3032 3004 2977 2828 2780 2727 2707 2790 2650 2626 2780 2782 2860 2751 2836 2776 2826 2796 2755 2765 2671 2592 2644 2587 2629 2603 2630 2579 2674 2708 2751 2841 2801 3026 3047 3121 3180 3227 3421 3269 3571 3512 3582 3464 3412 3250 3211 3108 2881 2849 2752 2649 2701 2668 2687 2642 2558 2731 2760 2747 2846 2845 2933 2923 2997 2971 2886 2947 2895 2844 2824 2785 2644 2767 2595 2558 2596 2499 2513 2574 2484 2458 2519 2494 2485 2540 2416 2472 2523 2468 2458 2443 2415 2495 2504 2464 2482 2536 2501 2471 2562 2580 2552 2620 2642 2804 2722 2824 2884 2828 3062 3255 3273 3275 3482 3586 3772 3771 3870 3923 4166 4032 4097 3797 3850 3642 3413 3354 3202 3083 3053 3019 3094 3109 3123 3229 3143 3299 3311 3452 3491 3640 3703 3879 4058 4296 4171 4352 4224 4082 4093 3985 3852 4041 3937 4051 4170 4157 4313 4280 4333 4280 4274 4094 4107 3944 3877 4100 4044 4045 3982 4066 4030 4103 3957 4106 3940 3983 3818 3796 3825 3940 3800 3770 3655 3591 3526 3533 3302 3314 3288 3185 3150 3094 3081 3000 3072 2973 3113 3033 3067 3020 2999 3038 3003 2959 2915 2965 2798 2909 2841 2796 2851 2962 2877 2969 3037 3249 3376 3361 3419 3172 3071 2954 2737 2830 2864 2692 2661</intensities>
			</dataPoints>
			<nonAmbientPoints type="Temperature" unit="K">
[...]
			</nonAmbientPoints>
		</scan>
	</xrdMeasurement>
</xrdMeasurements>