File: powder_X-ray_diffraction/variable-temperature_experiments/NaTaO2F2/raw_data/230°C.xrdml
<?xml version="1.0" encoding="UTF-8"?>
<xrdMeasurements xmlns="http://www.xrdml.com/XRDMeasurement/1.7" xmlns:xsi="http://www.w3.org/2001/XMLSchema-instance" xsi:schemaLocation="http://www.xrdml.com/XRDMeasurement/1.7 http://www.xrdml.com/XRDMeasurement/1.7/XRDMeasurement.xsd" status="Completed">
	<comment>
		<entry>Configuration=XRK900, Owner=User-1, Creation date=12/01/2015 16:52:44</entry>
		<entry>Goniometer=Theta/Theta; Minimum step size 2Theta:0.0001; Minimum step size Omega:0.0001</entry>
		<entry>Sample stage=AP XRK-900 with z-axis; Minimum step size Z:0.001</entry>
		<entry>Diffractometer system=EMPYREAN</entry>
		<entry>Measurement program=C:\PANalytical\Data Collector\Programs\Gwen\NaTaO2F2\NaTaO2F2-Lent.xrdmp, Identifier={FF50B583-C5FF-42DA-A01D-A1FB659EF29A}</entry>
		<entry>Batch program=C:\PANalytical\Data Collector\Programs\Gwen\NaTaO2F2\Thermodiff-Ouail.xrdmp, Identifier={5D65A6B1-42FC-480C-9FBB-D7D88D55EA08}</entry>
	</comment>
	<sample type="To be analyzed">
		<id></id>
		<name></name>
		<preparedBy></preparedBy>
	</sample>
	<xrdMeasurement measurementType="Scan" status="Completed" sampleMode="Reflection">
		<comment>
			<entry>PHD Lower Level = 4.02 (keV), PHD Upper Level = 12.07 (keV)</entry>
		</comment>
		<usedWavelength intended="K-Alpha 1">
			<kAlpha1 unit="Angstrom">1.5405980</kAlpha1>
			<kAlpha2 unit="Angstrom">1.5444260</kAlpha2>
			<kBeta unit="Angstrom">1.3922500</kBeta>
			<ratioKAlpha2KAlpha1>0.5000</ratioKAlpha2KAlpha1>
		</usedWavelength>
		<incidentBeamPath>
			<radius unit="mm">240.00</radius>
			<xRayTube id="1010048" name="Empyrean Cu LFF HR (9430 033 7310x) DK434948">
				<tension unit="kV">45.0</tension>
				<current unit="mA">30.0</current>
				<anodeMaterial>Cu</anodeMaterial>
				<focus type="Line">
					<length unit="mm">12.0</length>
					<width unit="mm">0.4</width>
					<takeOffAngle unit="deg">6.0</takeOffAngle>
				</focus>
			</xRayTube>
			<sollerSlit id="21010001" name="Soller slits 0.02 rad.">
				<opening unit="rad">0.0200</opening>
			</sollerSlit>
			<mask id="22030010" name="Fixed mask 20 mm">
				<width unit="mm">20.00</width>
			</mask>
			<antiScatterSlit id="22010003" name="Fixed slit 1Â°" xsi:type="fixedAntiScatterSlitType">
				<height unit="mm">1.52</height>
			</antiScatterSlit>
			<divergenceSlit id="22010012" name="Programmable divergence slit" xsi:type="fixedDivergenceSlitType">
				<distanceToSample unit="mm">140.00</distanceToSample>
				<angle unit="deg">0.5</angle>
			</divergenceSlit>
		</incidentBeamPath>
		<diffractedBeamPath>
			<radius unit="mm">240.00</radius>
			<antiScatterSlit id="22090010" name="AS slit 8.0 mm (PIXcel)" xsi:type="fixedAntiScatterSlitType">
				<height unit="mm">8.00</height>
			</antiScatterSlit>
			<sollerSlit id="21010001" name="Soller slits 0.02 rad.">
				<opening unit="rad">0.0200</opening>
			</sollerSlit>
			<filter id="20030001" name="Large beta-filter Nickel">
				<material>Ni</material>
				<thickness unit="mm">0.020</thickness>
			</filter>
			<detector id="7010019" name="PIXcel1D-Medipix3 detector" xsi:type="rtmsDetectorType">
				<phd unit="%">
					<lowerLevel>25.0</lowerLevel>
					<upperLevel>75.0</upperLevel>
				</phd>
				<mode>Scanning</mode>
				<activeLength unit="deg">3.3482</activeLength>
			</detector>
		</diffractedBeamPath>
		<scan appendNumber="0" mode="Continuous" scanAxis="Gonio" status="Completed">
			<header>
				<startTimeStamp>2023-01-22T06:54:27+01:00</startTimeStamp>
				<endTimeStamp>2023-01-22T09:54:55+01:00</endTimeStamp>
				<author>
					<name>User</name>
				</author>
				<source>
					<applicationSoftware version="5.5a">Data Collector</applicationSoftware>
					<instrumentControlSoftware version="8.2  20201204">EMPYREAN</instrumentControlSoftware>
					<instrumentID>0000000011159748</instrumentID>
				</source>
			</header>
			<dataPoints>
				<positions axis="2Theta" unit="deg">
					<startPosition>9.99846514</startPosition>
					<endPosition>99.99342261</endPosition>
				</positions>
				<positions axis="Omega" unit="deg">
					<startPosition>4.99923257</startPosition>
					<endPosition>49.99671130</endPosition>
				</positions>
				<positions axis="Z" unit="mm">
					<commonPosition>8.846</commonPosition>
				</positions>
				<commonCountingTime unit="seconds">386.070</commonCountingTime>
				<intensities unit="counts">6611 6462 6605 6564 6462 6549 6376 6501 6420 6422 6374 6373 6347 6415 6329 6489 6299 6315 6428 6435 6382 6484 6244 6222 6331 6476 6219 6424 6276 6291 6136 6383 6273 6469 6391 6186 6106 6221 6343 6187 6194 6118 6333 6337 6212 6309 6186 6236 6340 6355 6257 6368 6216 6191 6194 6182 6240 6257 6312 6481 6365 6491 6376 6407 6516 6563 6489 6667 6843 6714 6858 7073 7268 7599 7947 8599 9422 10476 11857 14617 19236 24607 31536 41259 48935 52555 49505 42015 34638 28261 21289 15926 12098 9711 8338 7687 7112 6989 6869 6539 6456 6326 6214 6145 6143 6074 6223 6004 6152 6119 6021 6011 6090 6011 6166 5966 6097 5990 6094 6034 5959 5838 6007 5898 5924 5942 5967 6005 6041 5864 5991 5759 5867 5965 5904 5780 5897 5861 5857 6007 5834 5801 5835 5866 5795 5857 5785 5701 5810 5678 5859 5726 5700 5651 5587 5708 5861 5737 5679 5687 5818 5689 5679 5828 5561 5729 5670 5611 5708 5736 5863 5569 5670 5605 5583 5605 5804 5582 5566 5572 5708 5613 5701 5416 5540 5601 5648 5569 5529 5630 5444 5443 5544 5553 5455 5566 5546 5581 5497 5508 5589 5505 5355 5497 5405 5501 5590 5562 5546 5497 5568 5516 5465 5482 5626 5454 5440 5579 5454 5351 5447 5443 5406 5476 5490 5392 5458 5477 5403 5540 5412 5472 5394 5310 5240 5328 5528 5417 5454 5449 5431 5243 5363 5401 5527 5446 5563 5329 5346 5400 5307 5342 5260 5319 5276 5358 5200 5249 5333 5293 5268 5276 5268 5229 5359 5346 5373 5305 5296 5304 5382 5281 5305 5112 5284 5263 5161 5340 5279 5185 5334 5443 5188 5226 5125 5195 5207 5199 5107 5215 5105 5138 5160 5119 5124 5274 5100 5051 5156 5084 5157 5212 5080 5044 5124 5113 5105 5077 5017 5138 5038 5062 4998 4981 5004 5107 5203 5073 5118 5158 5310 5099 5180 4970 5017 5079 4974 5141 5061 5032 4998 5042 4967 4990 5063 5005 5091 5002 4992 5113 4787 5051 5032 4970 4855 5044 4981 4980 5028 4877 4960 5053 4994 4885 4962 4885 4934 4809 5089 5128 5090 4924 4837 4762 4896 4900 4842 4964 4887 4700 4963 4828 4845 4912 4900 4759 4777 5031 4874 4804 4771 4842 4895 4909 4795 4866 4938 4771 4818 4980 4902 4887 4843 4872 4907 4848 4888 4934 4827 4972 4726 4752 4810 4771 4842 4822 4883 4772 4835 4888 4709 4796 4860 4775 4726 4806 4879 4804 4747 4783 4681 4801 4723 4692 4637 4684 4776 4650 4667 4774 4749 4735 4767 4684 4759 4749 4726 4743 4626 4815 4803 4726 4810 4631 4706 4697 4705 4606 4701 4692 4749 4639 4624 4698 4722 4711 4682 4690 4680 4642 4781 4772 4725 4794 4755 4759 4790 4850 4710 4947 5007 4824 4745 4845 4697 4897 4941 4728 4955 4964 4859 4779 4762 4763 4784 4789 4743 4704 4878 4776 4621 4857 4636 4754 4735 4838 4773 4741 4713 4709 4626 4697 4734 4772 4573 4615 4457 4595 4649 4611 4553 4571 4442 4512 4512 4608 4607 4543 4728 4663 4582 4691 4586 4456 4624 4445 4674 4581 4568 4493 4473 4444 4430 4446 4587 4691 4463 4516 4555 4534 4506 4662 4507 4466 4658 4672 4555 4646 4478 4730 4760 4755 4823 4738 4571 4654 4513 4634 4577 4514 4545 4457 4536 4420 4442 4450 4504 4360 4471 4411 4511 4448 4311 4358 4401 4270 4431 4510 4420 4494 4480 4520 4404 4522 4618 4510 4657 4653 4693 4677 4777 4692 4531 4525 4506 4470 4429 4325 4333 4364 4308 4238 4274 4323 4350 4287 4284 4487 4365 4299 4354 4239 4364 4192 4383 4335 4286 4352 4344 4386 4267 4299 4259 4346 4212 4343 4327 4340 4365 4306 4316 4265 4254 4178 4267 4371 4239 4118 4188 4256 4234 4374 4192 4266 4166 4146 4221 4257 4209 4299 4407 4180 4280 4309 4311 4394 4293 4326 4389 4252 4164 4268 4318 4289 4222 4200 4270 4095 4261 4212 4195 4131 4223 4187 4210 4147 4114 4055 4311 4149 4181 4214 4219 4240 4334 4357 4521 4465 4434 4433 4450 4614 4722 4718 4645 4550 4596 4592 4632 4532 4636 4588 4626 4640 4541 4568 4618 4616 4727 4654 4718 4639 4704 4712 4801 4912 5050 5388 5247 5419 5541 5765 5943 6252 6717 7344 8649 10408 12702 17259 23623 34815 52009 75856 100147 119840 126455 120079 108818 97342 81311 61594 44678 31291 22250 16283 12010 9385 7659 6937 6227 5964 5678 5431 5048 5060 4894 4784 4663 4574 4731 4579 4436 4424 4542 4509 4605 4467 4441 4452 4647 4558 4646 4606 4704 4663 4674 4506 4554 4464 4505 4382 4313 4315 4157 4205 4159 4276 4204 4187 4066 4219 4158 4039 4179 4129 4089 4217 4164 4144 4180 4083 4119 4073 4084 4071 4097 4097 4159 3933 4195 4091 3954 4029 4034 3924 4045 4008 4005 3965 4084 4053 4029 4016 4004 3913 4068 3992 4089 4040 3991 4127 3840 3965 4002 3902 3965 4100 3966 4022 4010 3886 3889 3845 3836 3938 3896 3958 3976 3918 3881 3839 3914 3945 3954 3883 3843 3850 3868 3867 3893 3986 3924 3851 3803 3895 3863 3871 3880 4041 3943 3877 3966 3926 3946 3875 3937 3861 3776 3889 3818 3826 3894 3930 3924 3956 3937 3886 3929 3894 3933 3912 4093 3815 3878 3902 3928 4065 4247 4113 4204 4256 4082 4166 4109 4052 3927 3852 4021 3999 3920 3979 4004 3952 4038 3930 3911 3942 3979 3992 3825 3862 3887 4023 3970 3940 4028 3966 4053 4197 4163 4423 4431 5058 5533 6336 7594 10043 13673 17533 19812 19271 17694 16571 16403 14143 11165 8631 7311 6118 5269 4538 4397 4010 4055 4110 4032 3947 3800 3916 3798 3902 3913 3870 3750 3798 3838 3846 3870 3769 3876 3798 3824 3830 3986 3889 3805 3842 3892 3878 3869 3708 3782 3795 3766 3684 3664 3620 3732 3740 3811 3729 3703 3568 3655 3761 3649 3604 3693 3789 3744 3645 3619 3696 3643 3610 3667 3719 3672 3745 3711 3628 3800 3699 3682 3641 3805 3704 3707 3644 3716 3726 3773 3845 3825 3809 3774 3889 3794 3735 3840 3877 3869 3836 3836 3978 3880 4020 3814 3892 3943 3907 3823 3727 3951 4007 3827 4055 3918 3908 3955 3980 3940 4035 4118 4069 3905 4077 4131 4245 4204 4386 4500 4494 4556 4484 4525 4611 4611 4865 4964 5185 5508 5998 6842 8440 11212 16142 23430 31232 38916 43954 45353 42863 38415 34368 32016 27837 22885 19432 19095 22488 29273 36316 42491 48078 49839 47544 43891 39235 34072 27935 21543 17057 12912 9546 7171 5888 5142 4863 4654 4475 4374 4213 4100 4105 3933 4004 3928 3855 4008 3830 3792 3866 3779 3835 3744 3847 3760 3628 3734 3656 3759 3610 3703 3839 3742 3672 3968 3813 3934 3942 3954 3782 3895 3807 3777 3643 3614 3687 3734 3664 3618 3633 3634 3574 3576 3531 3738 3629 3530 3612 3651 3545 3633 3525 3591 3608 3483 3639 3610 3621 3641 3680 3623 3600 3601 3597 3694 3553 3592 3586 3519 3626 3551 3444 3483 3529 3599 3521 3530 3402 3504 3567 3547 3473 3496 3489 3510 3512 3425 3483 3496 3406 3483 3441 3533 3588 3492 3458 3414 3409 3541 3453 3604 3516 3456 3549 3449 3545 3530 3561 3632 3603 3634 3880 3833 3810 3798 3868 3859 3904 3988 3863 3815 3698 3714 3607 3493 3571 3556 3477 3567 3553 3509 3576 3544 3570 3550 3559 3452 3356 3450 3617 3424 3496 3553 3525 3535 3432 3541 3469 3401 3390 3357 3459 3549 3441 3388 3459 3422 3477 3496 3467 3434 3481 3608 3693 3550 3720 3608 3667 3741 3760 3663 3759 3650 3592 3608 3657 3585 3745 3720 3741 3662 3681 3620 3719 3675 3608 3645 3663 3691 3610 3607 3604 3673 3689 3730 3764 3703 3689 3733 3463 3628 3681 3727 3614 3751 3743 3639 3870 3924 3901 3948 3943 4025 4187 4221 4313 4542 4620 4733 4983 5163 5398 5738 6265 6695 7294 8265 9865 12436 16485 24085 36374 53198 71706 84489 85860 78365 70446 65340 59601 53276 43534 33794 25352 18288 12924 9732 7742 6709 5787 5464 4919 4647 4656 4363 4214 4150 4122 3898 3814 3782 3898 3697 3771 3671 3786 3684 3622 3633 3669 3608 3714 3678 3691 3748 3851 3970 3946 3915 3844 3836 3800 3744 3776 3698 3869 3768 3562 3588 3549 3607 3571 3592 3584 3519 3511 3666 3524 3584 3609 3581 3635 3459 3480 3493 3600 3766 3540 3586 3569 3502 3498 3519 3451 3595 3381 3501 3492 3475 3479 3537 3509 3487 3419 3607 3559 3624 3600 3602 3646 3618 3774 3810 3862 3853 3817 3967 4121 4234 4256 4470 4633 4624 5030 5356 6240 7697 10400 15278 21813 28100 31854 33126 30642 27099 25226 24567 23498 22212 20217 19445 19648 20272 20549 20284 18632 16405 15069 13606 12358 11213 9532 7713 6456 5294 4477 4184 4006 3866 3712 3637 3679 3608 3597 3475 3543 3410 3473 3333 3406 3518 3415 3507 3289 3277 3381 3346 3519 3278 3388 3380 3363 3396 3427 3539 3314 3363 3456 3337 3407 3325 3436 3242 3345 3303 3270 3350 3290 3286 3346 3316 3358 3408 3250 3265 3389 3372 3329 3314 3340 3295 3357 3368 3374 3310 3286 3342 3303 3311 3239 3352 3229 3186 3187 3268 3179 3205 3226 3244 3267 3177 3172 3170 3183 3166 3086 3206 3175 3234 3117 3272 3262 3079 3115 3167 3149 3180 3177 3142 3136 3120 3150 3249 3180 3240 3190 3139 3285 3216 3154 3169 3107 3197 3219 3145 3176 3208 3151 3098 3178 3086 3267 3179 3192 3124 2990 3099 3125 3114 3175 3206 3221 3205 3056 3182 3147 3152 3102 3151 3179 3169 3135 3173 3111 3109 3125 3185 2986 3111 3104 3073 3174 3107 3160 3112 3170 3104 3136 3147 3088 3032 3147 3155 3199 3145 3197 3078 3044 3119 3093 3149 3043 3025 3147 3147 3149 3114 3091 3120 3121 3049 3037 3135 3097 3092 3219 3145 3047 3158 3014 3209 3158 3201 3060 3112 3148 3177 3134 3239 3279 3290 3164 3201 3268 3230 3253 3298 3175 3122 3240 3227 3110 3226 3174 3300 3349 3309 3221 3296 3154 3206 3320 3262 3290 3366 3219 3346 3365 3536 3578 3489 3765 3886 3705 3969 4229 4496 5196 6759 9989 14167 18895 21521 19988 16496 13835 13308 13328 13683 12573 10967 8491 6731 5738 4787 4254 3943 3879 3713 3708 3637 3660 3683 3662 3526 3585 3612 3648 3676 3754 3773 3871 3803 3998 4154 4317 4422 4669 4838 5325 6204 7530 10290 14928 21594 29130 34559 36052 32194 27451 23810 22145 21972 21887 19562 16256 12788 9592 7465 6090 5417 5124 4859 4545 4609 4722 4697 4818 5034 5351 5953 6511 8075 10490 14202 18987 23612 27992 29942 29165 27409 25284 22705 21249 20840 20515 21079 22049 22128 21106 17697 13702 11911 11146 10987 11137 10642 8640 7179 6211 5246 4532 3989 3847 3655 3628 3596 3406 3336 3405 3331 3359 3211 3282 3297 3280 3161 3185 3193 3221 3222 3231 3270 3146 3085 3178 3186 3312 3244 3227 3278 3275 3285 3270 3387 3305 3362 3411 3341 3498 3542 3547 3603 3859 4208 4560 5706 7302 9798 12655 14171 14033 12288 10516 9423 8940 9306 9344 8462 7381 5976 5217 4417 3900 3643 3512 3294 3341 3252 3329 3306 3272 3395 3480 3730 3690 3550 3506 3472 3390 3427 3410 3302 3261 3168 3234 3067 3066 3027 3047 3098 2919 3080 2900 2866 2953 3083 3039 3003 2925 2983 2996 3082 2994 3014 3025 3095 2871 2971 3020 2956 3099 3020 2937 2937 2948 3015 3064 2991 2841 3051 2936 3055 2861 2929 2987 2928 2971 2981 2853 3057 2951 2869 2850 2861 2905 2968 3026 2952 2889 2948 2951 2884 2921 2909 2872 2920 3025 2986 2941 2927 3016 2886 2972 2920 2941 3044 3018 2992 3030 3065 2941 3109 2969 2969 3004 3019 2985 3046 2929 2989 3010 2909 3030 2832 2859 2935 3029 2967 2976 2858 2888 2938 2931 2873 3016 2871 2910 2981 2879 2978 3011 3024 3095 2993 3116 3069 3116 3273 3149 3248 3432 3679 4075 5051 6310 8056 9490 9751 8882 7381 6296 5884 6134 6564 6482 5978 5349 4451 3905 3540 3350 3197 3167 3179 3126 3165 3064 3044 3000 3051 3078 2951 3054 2964 2991 3013 3136 3044 3039 3135 3171 3174 3091 3250 3242 3262 3372 3648 3946 4412 5332 6607 8050 9466 10241 10138 9262 8440 7762 7150 6787 7098 6728 6279 5602 4920 4329 3799 3395 3302 3262 3211 3023 3143 3299 3448 3583 3670 3516 3417 3312 3301 3359 3299 3374 3298 3140 3227 3016 2899 2930 2908 2871 2827 2894 2783 2868 2950 2804 2775 2757 2759 2857 2790 2799 2840 2811 2814 2764 2676 2856 2830 2772 2827 2866 2756 2818 2747 2733 2735 2804 2856 2772 2751 2798 2797 2816 2813 2716 2755 2742 2786 2805 2747 2842 2718 2758 2685 2786 2692 2736 2790 2750 2754 2758 2715 2708 2746 2872 2815 2886 2767 2769 2808 2677 2800 2805 2877 2712 2721 2755 2793 2776 2751 2782 2765 2716 2769 2843 2683 2869 2631 2802 2724 2752 2721 2735 2915 2751 2804 2818 2752 2760 2791 2786 2735 2791 2628 2742 2722 2691 2698 2834 2772 2716 2788 2710 2727 2713 2801 2862 2842 2710 2659 2693 2829 2800 2853 2782 2761 2684 2852 2831 2798 2823 2790 2766 2747 2822 2855 2815 2841 2775 2800 2894 2965 3013 3225 3390 3789 4167 4570 4778 4992 5003 4662 4347 4116 4019 4029 4059 4061 3864 3641 3571 3292 3293 3239 3313 3465 3659 4173 4782 5904 7044 7878 7889 7051 6254 5553 5302 5237 5519 5730 5592 5153 4462 4105 3817 3489 3364 3278 3170 3322 3285 3127 3362 3502 3787 4180 4946 6170 7866 9409 10344 9574 8268 6875 5958 5727 6164 6706 6797 6289 5633 4811 3974 3521 3316 3205 3093 3019 2992 3031 3064 2961 3064 2923 2958 3001 3096 2996 2933 3063 3216 3148 3236 3266 3379 3486 3597 3804 4201 4840 5660 6975 8440 10163 11309 11351 10581 9163 8073 7678 7590 8115 8616 9420 10686 11699 13337 13280 13049 12109 10511 9698 9674 11307 13702 15641 16500 15963 13736 10793 8913 7772 7536 7680 8013 7824 7000 5898 4808 4162 3699 3523 3170 3176 3037 2988 2842 2903 2949 2930 2922 2781 2794 2877 2846 2824 2743 2708 2809 2804 2778 2750 2798 2803 2719 2843 2645 2764 2762 2645 2721 2836 2714 2709 2667 2690 2620 2745 2733 2680 2657 2689 2614 2719 2677 2714 2830 2712 2726 2718 2692 2713 2670 2689 2764 2838 2740 2763 2682 2674 2669 2757 2609 2592 2687 2708 2683 2733 2669 2769 2732 2726 2677 2794 2727 2666 2690 2710 2663 2754 2766 2669 2662 2613 2653 2680 2678 2626 2703 2705 2626 2705 2628 2615 2662 2630 2646 2728 2719 2686 2652 2602 2760 2756 2750 2702 2708 2666 2689 2706 2714 2760 2741 2746 2740 2783 2833 2759 2765 2738 2623 2760 2663 2526 2724 2640 2591 2659 2594 2715 2693 2721 2708 2765 2737 2626 2593 2737 2686 2593 2644 2628 2657 2747 2681 2624 2750 2893 3031 3178 3333 3362 3315 3128 3087 2956 2961 3040 3018 3018 3042 2942 3040 2842 2817 2806 2780 2615 2686 2664 2632 2708 2659 2709 2646 2597 2748 2614 2689 2605 2685 2687 2714 2594 2710 2788 2640 2641 2726 2690 2646 2673 2640 2637 2765 2760 2665 2723 2770 2712 2742 2695 2584 2742 2803 2954 3018 3110 3335 3603 3961 4128 4174 3915 3496 3238 3161 3299 3336 3451 3501 3524 3374 3214 3168 3046 2963 3005 3046 3183 3258 3585 3836 4399 4711 5184 5498 5361 5241 4779 4484 4224 4057 4053 4265 4242 4059 3877 3581 3482 3168 2920 2886 2806 2833 2857 2714 2831 2648 2710 2748 2755 2706 2695 2672 2746 2647 2589 2669 2732 2616 2681 2641 2714 2614 2553 2633 2714 2698 2622 2672 2738 2712 2742 2677 2611 2656 2612 2698 2565 2714 2642 2662 2660 2681 2666 2667 2676 2639 2694 2682 2777 2779 2811 2645 2757 2830 2878 2936 2885 2803 2905 2949 2957 3030 3042 3218 3326 3637 4090 5147 6697 8890 11055 11780 10543 8745 7013 5853 5188 5270 6047 7073 7472 6926 5849 4932 4182 3613 3196 3090 3001 2965 2868 2804 2815 2807 2728 2769 2809 2651 2651 2681 2820 2752 2722 2868 2933 2747 2818 2780 2818 2859 2916 2937 2891 2953 2877 2997 2926 3117 3184 3395 3717 4456 5334 6457 7147 7292 6361 5303 4595 4103 3966 4180 4661 4900 4883 4717 4249 3615 3391 3124 2867 2931 2922 2882 2859 2873 2754 2819 2764 2805 2837 2790 2777 2747 2779 2866 2778 2877 2905 2788 2932 2820 2882 2884 2875 2837 2930 3006 3062 3025 3059 3171 3373 3584 3926 4438 5157 6173 7088 7980 8613 8916 8271 6873 5915 5257 5101 5365 5600 5815 5976 5669 5228 4343 3959 3532 3325 3191 2996 3048 3036 3022 3141 3100 3045 3014 3114 3145 3129 3196 3156 3256 3289 3317 3373 3315 3366 3528 3618 3733 3793 4011 4315 4778 5401 6176 7429 9524 12358 15609 18616 20555 19764 17611 14904 11803 10351 10027 10447 11396 12291 12206 11372 9659 8078 6623 5360 4927 4318 4005 3659 3488 3499 3342 3282 3249 3264 3171 3225 3130 3154 3206 3151 3109 3221 3327 3299 3507 3468 3559 3769 4306 4782 6039 7913 9908 12184 12933 12951 12962 13257 13158 12293 11176 10847 10143 9730 9169 8689 8620 8228 8055 7243 6478 5764 5030 4497 4185 4093 4337 4527 5084 6039 7606 9642 11990 13317 13032 11398 9599 7892 6615 6030 6409 7129 7809 8236 8263 7034 6104 5064 4350 3889 3563 3402 3323 3162 3119 3058 3118 2971 2960 3003 2990 3025 2895 2991 2947 2948 2859 2764 2811 2760 2802 2832 2842 2866 2937 2904 2975 2842 2935 3100 3189 3259 3370 3500 3630 3519 3432 3267 3215 3183 3119 3225 3181 3287 3372 3446 3587 3478 3511 3393 3446 3489 3351 3416 3469 3273 3303 3455 3508 3507 3684 3592 3591 3702 3655 3658 3877 4061 4476 4954 5817 7167 9346 12182 15654 18215 18893 18143 15765 13305 11087 9977 9937 10556 11220 12045 12191 11103 9958 8257 6953 6029 5427 4941 4518 4236 4020 3884 3577 3679 3481 3507 3626 3702 3809 4102 4299 4765 5492 6422 7409 8792 10022 10953 11363 10926 9547 7848 6991 6382 6428 6689 6934 7190 7322 7176 6317 5528 4933 4152 3762 3486 3390 3350 3273 3202 3135 3126 2991 3058 2896 3033 2929 2918 2851 2884 2882 2892 2817 2774 2738 2946 2879 2822 2847 2807 2772 2843 2872 2841 2915 2916 2950 2875 2997 2935 2924 3067 2944 3031 3035 3077 3172 3267 3489 3762 4460 5133 6511 7910 8811 9050 8069 6957 5783 5124 4531 4649 4845 5404 5929 6032 5674 5306 4819 4303 4067 3905 3695 3816 3791 3339 3150 3094 3085 3116 3060 3171 3125 3215 3093 3018 3088 2860 2874 2862 2895 2844 2781 2755 2821 2822 2884 2870 2851 2763 2795 2801 2856 2793 2846 2793 2803 2764 2835 2746 2661 2826 2811 2856 2781 2808 2829 2746 2867 2838 2778 2779 2872 2910 2935 2839 2823 2965 2904 3011 3021 3037 3025 3108 3131 3217 3412 3470 3829 4249 4718 5913 7065 8349 9654 10339 10609 10525 9695 8701 7450 6340 6007 6103 6394 6760 7050 7026 6654 6211 5420 4810 4309 3765 3555 3528 3391 3660 3837 4235 4712 4911 5442 5713 5870 5925 6015 5893 5801 5316 5106 4672 4579 4416 4445 4432 4480 4385 4383 4053 3802 3536 3324 3106 3061 2923 2867 2775 2874 2684 2833 2770 2747 2759 2783 2843 2779 2807 2776 2787 2634 2735 2755 2902 2749 2881 2890 2953 3022 3269 3524 3789 3938 4261 4328 4225 3782 3684 3471 3269 3249 3249 3249 3461 3543 3561 3456 3311 3107 2948 2867 2861 2827 2780 2715 2854 2724 2778 2760 2744 2717 2583 2637 2590 2710 2692 2664 2761 2698 2732 2691 2697 2596 2768 2674 2696 2685 2610 2707 2741 2763 2635 2769 2850 2774 2802 2915 3019 3045 3075 3112 3108 3079 3044 3129 3008 3033 2936 2908 2897 2885 2818 2989 2858 2781 2824 2830 2693 2781 2751 2743 2659 2703 2764 2733 2721 2756 2765 2733 2744 2582 2772 2696 2621 2685 2656 2607 2712 2707 2770 2699 2670 2743 2704 2734 2773 2706 2578 2772 2647 2731 2731 2687 2716 2759 2831 2821 2780 2793 2785 2799 2919 2962 2942 2936 3062 3011 3073 3080 3116 3210 3318 3458 3658 3950 4370 5010 5876 7017 8748 10335 11385 11279 10134 8727 7399 6314 5730 5542 5894 6187 6950 7401 7426 7148 6308 5564 4837 4259 3923 3697 3511 3534 3616 3497 3537 3672 3491 3272 3229 3103 3026 3052 3040 3025 3036 3039 3060 3068 2994 2916 2962 2921 2765 2865 2915 2890 2909 3023 2814 3019 2930 3028 2995 3026 3101 3047 3073 3002 3275 3281 3273 3510 3689 3995 4394 5120 5974 6971 8155 9055 10078 11006 11796 12820 13026 12675 11349 10137 8965 7876 7688 7270 7480 7719 7959 8088 7857 7397 6612 5768 5021 4357 4024 3589 3537 3320 3268 3312 3162 3100 3048 3125 3119 3009 3039 3057 3022 2993 3004 3101 3110 3079 3207 3119 3189 3291 3350 3305 3624 3949 4168 4695 5409 6145 7140 7743 8271 8781 9135 9363 9261 9561 8976 8406 7691 6993 6607 6712 6833 7012 7331 7651 8372 8581 9099 8986 8551 7441 6580 5687 5158 4560 4433 4323 4453 4664 4807 5084 4882 4707 4387 4059 3641 3433 3407 3258 3231 3018 3036 3041 3054 3078 2975 3062 3102 2999 3093 3214 3094 3104 3243 3372 3406 3621 3781 4134 4505 5264 6050 7393 8148 8992 8867 7966 6898 5968 5388 5014 4866 5184 5725 6408 7084 7071 6983 6341 5674 5058 4496 4165 3769 3723 3688 3792 3650 3696 3725 3456 3500 3425 3308 3343 3356 3233 3198 3211 3248 3345 3369 3565 3662 3905 4158 4700 5129 6004 6990 7555 8391 8765 8582 8018 7107 6399 5589 5260 5302 5553 5832 6316 7066 7658 8460 9224 9959 10255 10343 9625 8369 6947 5839 5177 4854 4885 5050 5306 5957 6587 6899 7227 7120 7077 7367 7786 8630 9259 9423 9466 8720 7801 6826 5763 5055 5065 5084 5230 5708 5846 6192 6127 5813 5374 4731 4296 4089 3693 3404 3230 3152 3194 3084 2892 3075 3095 3066 2978 3123 3028 3114 3089 3021 2918 3051 3117 3148 3280 3387 3752 4217 4550 5350 5924 6540 7498 7975 8165 8216 7833 7227 6522 5849 5454 5194 5247 5767 6389 7044 7529 8297 8578 8588 8770 8952 9444 10471 11360 11381 10735 9218 7906 6775 6071 5778 5618 5754 5864 6228 6747 7063 6901 6094 5283 4597 4155 3714 3501 3379 3224 3081 3052 3104 2969 3112 2967 3024 2762 2943 2932 2965 2850 3078 3021 3088 3161 3068 3030 3109 3277 3091 3154 3264 3338 3415 3563 3757 3977 4471 4977 5708 6847 8498 10314 11977 13441 13812 13345 12535 11063 9592 8447 7664 7221 7106 7612 8632 9449 9792 10106 9799 8963 8392 7492 6868 6140 5731 5252 5065 4799 5019 5056 5426 5501 5625 5619 5632 5540 5257 4830 4406 4021 3888 3692 3809 3745 3692 3847 3669 3751 3723 3598 3357 3200 3082 2938 2754 2753 2858 2678 2757 2671 2607 2693 2657 2642 2629 2541 2618 2614 2562 2542 2585 2496 2620 2615 2576 2579 2627 2628 2549 2629 2528 2634 2639 2650 2532 2603 2563 2587 2557 2619 2565 2566 2576 2613 2638 2588 2603 2557 2594 2583 2556 2542 2591 2513 2623 2577 2533 2468 2503 2509 2493 2555 2565 2515 2518 2525 2462 2516 2490 2567 2480 2487 2476 2571 2572 2510 2566 2603 2554 2597 2532 2566 2528 2565 2574 2599 2589 2653 2575 2612 2599 2542 2551 2520 2591 2536 2524 2472 2447 2513 2526 2454 2542 2511 2482 2552 2444 2595 2549 2549 2418 2594 2474 2451 2616 2414 2453 2512 2489 2626 2597 2505 2480 2469 2457 2490 2447 2521 2557 2432 2481 2566 2405 2563 2444 2526 2476 2537 2531 2525 2391 2451 2554 2452 2453 2668 2527 2425 2523 2597 2566 2533 2602 2557 2633 2574 2589 2623 2655 2662 2769 2803 2780 2747 2862 2869 2870 2961 3130 3250 3469 3482 3788 4100 4166 3974 3696 3637 3280 3205 3001 2908 2946 2988 3160 3239 3253 3357 3290 3296 3030 2991 2927 2774 2879 2808 2891 2777 2952 2873 3072 3239 3374 3606 3904 4325 4289 4255 4152 3794 3579 3396 3313 3231 3409 3542 3644 3955 4186 4403 4737 4632 4569 4179 3986 3646 3268 3060 3025 3018 3039 3033 3092 3168 3148 3126 3116 3027 2911 2785 2653 2653 2582 2568 2500 2490 2516 2508 2409 2510 2519 2528 2470 2472 2501 2565 2494 2445 2507 2494 2520 2545 2515 2434 2569 2578 2595 2708 2729 2629 2686 2669 2664 2744 2737 2805 2791 2676 2653 2804 2624 2719 2764 2818 2794 2787 2773 2716 2780 2630 2692 2667 2501 2457 2541 2590 2597 2450 2536 2519 2606 2444 2497 2406 2406 2435 2434 2453 2472 2335 2437 2415 2415 2425 2436 2428 2408 2466 2395 2401 2460 2437 2437 2410 2405 2391 2443 2491 2412 2360 2409 2313 2457 2409 2448 2386 2427 2415 2451 2395 2370 2477 2438 2529 2513 2432 2520 2439 2432 2468 2345 2453 2474 2478 2403 2440 2384 2280 2367 2437 2418 2409 2303 2448 2300 2301 2391 2349 2362 2400 2353 2454 2449 2398 2460 2404 2385 2405 2419 2362 2388 2456 2446 2412 2510 2473 2422 2483 2566 2542 2428 2587 2556 2463 2427 2396 2496 2427 2309 2430 2433 2427 2432 2563 2439 2596 2506 2413 2389 2437 2570 2466 2544 2498 2707 2584 2410 2434 2399 2484 2407 2440 2483 2459 2478 2529 2429 2372 2416 2434 2463 2359 2444 2300 2516 2417 2377 2431 2425 2475 2315 2446 2343 2413 2317 2405 2339 2380 2484 2456 2384 2426 2426 2374 2417 2388 2421 2422 2398 2490 2461 2430 2412 2399 2428 2356 2442 2406 2423 2456 2334 2524 2439 2524 2477 2430 2415 2429 2391 2439 2441 2381 2478 2389 2539 2496 2425 2432 2345 2409 2448 2494 2440 2440 2450 2561 2433 2422 2540 2469 2513 2388 2400 2464 2498 2556 2482 2513 2536 2590 2654 2804 2849 3090 3392 3526 3641 3769 3745 3420 3349 3084 2914 2906 2908 2894 3151 3253 3415 3434 3442 3512 3534 3264 3374 2951 2935 2790 2794 2905 2853 2870 2947 2979 3006 3320 3477 3847 4347 4805 5298 5299 4984 4450 3975 3541 3202 2962 3050 2868 3007 3099 3179 3494 3659 3894 3860 3667 3428 3169 2983 2796 2780 2627 2536 2591 2522 2632 2523 2483 2496 2580 2688 2521 2568 2582 2505 2519 2595 2520 2536 2537 2565 2530 2582 2549 2621 2602 2669 2664 2639 2832 2839 2996 3268 3584 3777 3951 4007 4107 4046 3856 3940 4022 3883 3836 3858 3852 3839 4059 3924 3837 3811 3642 3540 3479 3497 3301 3415 3406 3389 3296 3337 3372 3378 3373 3502 3556 3598 3561 3568 3432 3331 3313 3336 3320 3467 3736 4033 4513 5061 5648 6326 7006 7316 7565 7070 6378 5947 5604 5159 4892 4833 4905 4948 4832 4740 5035 5270 5306 5409 4985 4791 4703 4471 4392 4167 4002 3825 3495 3568 3206 3214 3115 3004 2913 3014 2982 3043 3023 3063 3153 3146 3152 3280 3475 3590 3890 4170 4738 5166 5488 5408 5135 4752 4125 3841 3611 3363 3253 3307 3446 3378 3539 3901 3964 4078 4381 4423 4265 4178 4057 4195 4199 4356 4551 4563 4423 4518 4357 4314 4208 4185 3891 3763 3541 3532 3517 3408 3452 3503 3681 3674 3716 3693 3743 3689 3875 3834 4093 4293 4844 5238 5303 5039 4644 4062 3493 3177 3077 2930 2982 2969 3052 3091 3324 3396 3694 3968 3846 3585 3384 3343 3027 2918 2913 2864 2744 2831 2831 2807 2757 2838 3017 2978 3153 3302 3421 3722 4110 4284 4523 4370 4098 4177 3875 3916 3900 3761 3913 3900 3847 3874 3866 3919 3858 3876 3742 3659 3465 3424 3271 3282 3131 3137 3130 3094 3099 2976 2824 2820 2861 2656 2702 2722 2568 2595 2595 2577 2549 2573 2463 2480 2629 2526 2538 2434 2560 2586 2578 2550 2627 2560 2602 2673 2761 2651 2603 2619 2838 2848 3039 3103 3364 3600 3806 4007 4146 4305 4038 3950 3616 3273 3109 3050 2954 2902 2919 2999 3094 3189 3314 3320 3411 3331 3346 3161 3012 2954 2814 2700 2672 2627 2661 2716 2726 2652 2709 2772 2889 3064 3101 3360 3592 3781 4164 4341 4389 4343 4287 4007 3771 3498 3350 3129 3057 2953 2945 3134 3258 3274 3615 3652 3834 3927 3852 3991 3846 3935 3779 3883 3987 3923 3874 3681 3604 3401 3298 3133 3238 3271 3257 3387 3572 3621 3668 3566 3601 3499 3493 3280 3164 3111 3042 3042 2928 3045 3183 3071 3283 3404 3541 3819 4063 4494 4842 5102 5319 5605 5587 5603 5509 5406 5423 5277 4841 4449 4087 3853 3822 3788 3879 3941 4145 4028 3982 4035 4077 3878 3863 3864 3608 3468 3210 3043 2800 2791 2661 2648 2650 2586 2506 2545 2536 2480 2418 2522 2549 2457 2479 2494 2574 2443 2435 2459 2485 2516 2444 2387 2428 2565 2448 2433 2433 2413 2471 2437 2436 2437 2485 2411 2411 2468 2509 2305 2400 2518 2401 2335 2392 2404 2371 2439 2467 2370 2450 2390 2339 2434 2399 2391 2468 2353 2500 2383 2406 2398 2368 2336 2445 2331 2465 2362 2379 2414 2418 2539 2460 2336 2467 2450 2357 2436 2528 2487 2448 2430 2467 2325 2467 2461 2491 2588 2425 2494 2369 2523 2554 2594 2597 2555 2402 2515 2492 2662 2565 2570 2447 2501 2576 2487 2493 2573 2482 2482 2590 2483 2456 2590 2546 2512 2452 2528 2432 2429 2318 2520 2469 2500 2557 2540 2677 2615 2533 2591 2572 2640 2592 2643 2781 2784 2873 2896 2928 2987 2921 2965 3042 3090 3157 3141 3127 3129 3393 3518 3694 3913 4355 4514 4627 4828 4865 4826 4509 4322 4113 3869 3670 3526 3261 3275 3204 3192 3336 3311 3630 3641 3534 3628 3539 3430 3426 3123 3049 3084 2842 2815 2787 2774 2742 2746 2706 2619 2600 2818 2791 2825 2855 2935 3165 3267 3400 3566 3801 3873 4071 4373 4354 4381 4506 4455 4089 3956 3777 3509 3324 3252 3133 3187 3231 3247 3291 3345 3431 3507 3390 3454 3454 3299 3263 3034 2828 2841 2742 2642 2577 2607 2598 2641 2536 2551 2514 2536 2589 2550 2583 2530 2614 2580 2508 2547 2603 2607 2615 2669 2759 2858 2862 2931 3159 3205 3189 3254 3047 2926 2926 2716 2709 2600 2639 2630 2644 2603 2702 2748 2779 2981 2830 2827 2832 2747 2797 2673 2610 2602 2657 2549 2611 2625 2560 2586 2672 2648 2774 2716 2763 2787 2843 2967 2866 2789 2830 2609 2638 2680 2610 2660 2662 2658 2749 2841 2842 2957 3086 3227 3357 3417 3653 3411 3444 3471 3464 3540 3546 3557 3439 3437 3341 3179 3138 3202 3196 3260 3410 3332 3456 3597 3740 3948 4042 4327 4399 4364 4594 4483 4409 4395 4139 4137 4283 4063 4136 3984 4242 4071 4156 4198 4118 4077 4069 4069 3861 3733 3713 3654 3425 3377 3380 3326 3266 3383 3280 3219 3272 3144 3134 2995 2966 3036 2915 2916 2805 2814 2718 2860 2684 2779 2814 2817 2879 3118 3086 3266 3607 3824 3966 3955 4143 3989 3975 3698 3430 3325 3229 3067 3104 3085 3040 3225 3199 3303 3429 3681 3632 3735 3648 3479 3440 3199 3072 3030 2899 2844 2876 2944 2896 2817 2888 2897 2887 2862 2868 2988 2990 2956 2919 3059 3106 3137 3312 3464 3518 3588 3796 4110 4350 4664 4714 4688 4884 4737 4506 4307 4114 4010 3868 3752 3667 3642 3740 3887 4071 4291 4669 5054 5450 5872 6031 6221 6666 6785 6835 6748 6779 6259 5709 5247 4864 4547 4202 4179 4178 4463 4580 4926 5281 5436 5417 5501 5451 5307 5230 4848 4718 4409 4266 4140 4168 3900 3964 4046 4031 4044 4047 3706 3916 3607 3540 3371 3327 3209 3326 3266 3444 3431 3484 3542 3678 3574 3588 3594 3654 3590 3491 3534 3466 3414 3461 3372 3423 3337 3305 3042 3013 2953 2968 2913 2974 2869 2902 2955 2867 2945 2919 2967 2798 2809 2917 2807 2781 2745 2671 2585 2697 2517 2591 2661 2521 2555 2624 2486 2548 2532 2515 2429 2607 2555 2546 2516 2505 2584 2523 2541 2596 2603 2670 2651 2600 2626 2702 2791 2866 3041 2975 3075 3301 3263 3389 3654 3794 3697 3707 3820 3596 3415 3433 3290 3239 3039 3046 3013 3071 3058 3290 3215 3359 3541 3509 3587 3547 3672 3563 3433 3391 3282 3173 3056 2926 2867 2799 2798 2769 2796 2796 2708 2712 2746 2869 2777 2866 2846 2883 3046 2956 3138 3271 3434 3684 3788 3823 3598 3444 3116 2971 2898 2810 2704 2720 2594 2656 2603 2647 2757 2839 2797 2860 2979 3104 3025 2980 2945 2770 2642 2642 2640 2627 2516 2464 2645 2497 2533 2570 2485 2509 2468 2558 2513 2505 2438 2517 2508 2473 2559 2560 2626 2690 2559 2710 2733 2755 2684 2784 2813 2768 2787 2800 2761 2693 2654 2759 2755 2682 2715 2753 2711 2804 2781 2845 2938 3072 3060 3090 3365 3455 3522 3500 3358 3301 3203 3038 2855 2735 2770 2617 2734 2592 2653 2633 2605 2762 2687 2781 2902 2929 2918 2855 2911 2700 2659 2556 2551 2500 2456 2496 2490 2527 2306 2390 2431 2436 2431 2471 2428 2446 2518 2395 2389 2436 2397 2359 2415 2366 2413 2327 2408 2522 2386 2440 2355 2342 2450 2365 2459 2447 2398 2443 2597 2558 2590 2601 2463 2529 2618 2592 2580 2616 2527 2652 2516 2532 2588 2510 2535 2551 2497 2495 2403 2460 2428 2508 2400 2575 2463 2473 2421 2588 2510 2548 2496 2610 2570 2542 2514 2508 2451 2467 2466 2462 2535 2448 2430 2518 2476 2538 2500 2519 2438 2473 2487 2502 2524 2500 2537 2588 2719 2688 2718 2741 2850 2798 2880 2836 2944 2865 2942 3011 3094 3082 3160 3291 3244 3197 3183 3100 3147 3271 3506 3593 3630 3686 3634 3908 3987 4179 4383 4368 4408 4371 4187 3968 3799 3502 3441 3309 3252 3379 3389 3426 3313 3389 3242 3331 3245 3335 3396 3293 3359 3260 3163 3012 2894 2961 2887 2742 2704 2755 2737 2618 2735 2633 2582 2559 2666 2531 2560 2569 2598 2424 2515 2563 2585 2676 2544 2690 2590 2667 2694 2881 2975 2904 3078 3058 3065 3011 2957 2912 2846 2797 2738 2609 2615 2611 2665 2617 2715 2602 2616 2630 2689 2756 2832 2807 2796 2820 2738 2806 2743 2790 2696 2754 2648 2671 2699 2792 2835 2930 3068 3125 3209 3236 3360 3306 3208 3187 3009 2996 2787 2723 2725 2828 2719 2668 2652 2750 2654 2686 2738 2712 2857 2875 3007 2964 2945 2907 2746 2811 2781 2727 2760 2855 2910 2955 3014 3060 3134 3184 3331 3269 3294 3422 3455 3403 3304 3275 3147 3093 2888 2822 2748 2767 2795 2878 2714 2804 2806 2855 2811 2882 2932 2949 3078 3080 2962 2859 2897 2886 2866 2878 2880 2814 3031 2962 3093 3089 3208 3269 3460 3648 3538 3506 3365 3231 3038 3081 2949 2904 2825 2852 2756 2872 2864 2791 2731 2857 2763 2879 2994 3131 3084 3128 3130 2999 3043 2983 2766 2999 2994 3144 3260 3332 3457 3579 3646 3722 3839 3850 3732 3716 3649 3340 3320 3251 3003 2974 3041 2977 3071 2941 3088 3021 3002 3099 3109 3014 3159 3147 3183 3035 3083 2983 2951 2795 2861 2722 2721 2624 2588 2660 2666 2597 2720 2649 2638 2621 2569 2595 2514 2555 2573 2496 2597 2581 2568 2607 2748 2735 2815 2953 3131 3134 3285 3402 3251 3201 3141 3023 3042 2864 2761 2762 2792 2752 2697 2674 2770 2755 2760 2751 2843 2870 2892 2837 2834 2934 2976 2972 2800 2729 2777 2710 2667 2767 2776 2905 2821 2904 2917 2884 2856 2913 2828 2831 2747 2720 2738 2587 2586 2590 2651 2511 2610 2572 2649 2685 2669 2702 2792 2846 3012 2926 3102 3232 3338 3438 3692 3643 3553 3545 3372 3191 3096 3125 3021 2931 2964 2938 3008 2898 3153 3192 3234 3364 3387 3618 3871 3850 3978 3816 3716 3610 3397 3433 3280 3271 3215 3157 3128 3141 3047 3051 2917 2896 2906 2970 2906 3063 2996 3132 3198 3103 3076 3245 3210 3304 3333 3513 3521 3443 3407 3207 3143 2952 2897 2882 2793 2801 2637 2876 2828 2863 2854 2911 2843 2909 2847 3013 2981 2948 2971 3001 2950 2966 2981 2970 2882 3002 2931 3168 3137 3159 3242 3056 3080 2969 3006 2989 2851 2797 2829 2897 2749 2887 2808 2912 3048 3140 3213 3338 3462 3584 3684 3679 3846 3741 3775 3696 3572 3508 3388 3225 3199 3000 2951 2825 2866 2873 2827 2904 3009 2972 3112 3162 3301 3369 3465 3593 3694 3846 4066 4116 4270 4365 4196 3968 3774 3554 3454 3362 3124 3084 2864 2898 2874 2928 2970 2789 2917 2884 2990 2889 3122 3123 3265 3357 3271 3314 3227 3087 2880 2939 2892 2830 2801 2632 2692 2765 2644 2752 2751 2610 2661 2715 2654 2759 2714 2775 2802 2941 2949 3005 2933 2952 3006 2984 2938 2845 2936 3059 2906 2887 2981 2910 2882 3003 2953 3003 3029 3055 3113 3258 3166 3307 3559 3781 3773 3860 3881 3755 3589 3492 3379 3262 2986 3051 2982 2864 2876 2872 2836 2756 2870 2833 2799 2792 2950 2975 3043 3120 3055 3123 3026 3022 2881 2784 2659 2724 2648 2535 2599 2534 2584 2455 2425 2424 2511 2481 2509 2519 2470 2400 2458 2494 2471 2448 2465 2413 2425 2408 2425 2377 2362 2401 2465 2337 2406 2371 2424 2332 2390 2441 2414 2421 2418 2384 2410 2422 2480 2457 2466 2492 2497 2457 2573 2594 2551 2631 2745 2718 2847 2950 3046 3299 3182 3083 3098 3020 2910 2754 2813 2716 2850 2815 2749 2805 2776 2877 2846 2902 2842 2893 3007 2890 3027 2972 3018 2971 2984 2924 2953 2816 2755 2811 2656 2635 2710 2585 2579 2659 2492 2662 2637 2640 2633 2702 2704 2601 2561 2680 2634 2662 2758 2793 2771 2723 2915 3066 3055 3078 3239 3132 3179 3219 3203 3400 3351 3413 3383 3358 3153 3146 3001 2919 2806 2849 2738 2759 2793 2734 2733 2796 2722 2798 2883 2865 2886 2820 2926 2838 2908 2851 2982 2887 2759 2784 2736 2634 2612 2457 2531 2559 2460 2372 2384 2469 2536 2512 2497 2430 2435 2405 2354 2421 2470 2441 2320 2422 2479 2379 2482 2554 2372 2473 2502 2512 2413 2456 2247 2355 2298 2414 2448 2394 2452 2407 2442 2447 2393 2241 2420 2481 2342 2402 2419 2405 2336 2418 2398 2398 2367 2369 2437 2375 2430 2346 2443 2334 2280 2344 2311 2434 2382 2418 2454 2541 2402 2406 2462 2440 2534 2523 2553 2589 2476 2606 2569 2624 2535 2613 2446 2502 2480 2447 2443 2452 2371 2416 2452 2421 2528 2429 2424 2444 2429 2497 2602 2471 2441 2468 2584 2548 2560 2532 2488 2595 2559 2649 2709 2717 2777 2832 2909 2926 3155 3369 3515 3617 3665 3697 3571 3621 3445 3371 3329 3191 3057 3157 3112 3091 3185 3191 3224 3344 3331 3339 3486 3482 3516 3474 3506 3403 3356 3283 3310 3269 3166 3105 3040 2901 2927 2789 2789 2794 2793 2768 2854 2928 2835 2880 2805 2887 2865 2803 2691 2710 2637 2647 2644 2597 2589 2516 2532 2606 2591 2526 2495 2544 2607 2601 2669 2675 2800 2872 2916 3134 3157 3097 3413 3324 3484 3563 3479 3454 3498 3337 3338 3077 3102 2931 2734 2761 2686 2744 2676 2704 2633 2664 2741 2784 2849 2791 2912 2941 2897 2991 2999 3032 3051 2960 2846 2880 2782 2690 2729 2622 2587 2543 2476 2565 2418 2430 2436 2472 2532 2540 2462 2573 2475 2531 2431 2420 2448 2517 2568 2485 2515 2506 2609 2544 2737 2600 2674 2660 2758 2819 2920 2991 3078 3175 3222 3388 3231 3479 3529 3417 3705 3596 3659 3737 3708 3835 3844 3790 3802 3748 3556 3550 3498 3243 3263 3147 3174 3305 3257 3312 3278 3262 3301 3273 3409 3473 3498 3586 3558 3732 3890 3899 4033 4155 4276 4127 4011 3998 3901 3956 3845 3824 4025 4180 4296 4377 4479 4577 4592 4541 4350 4400 4382 4169 4139 4075 4032 3946 3964 3905 3834 3837 3788 3703 3565 3726 3570 3437 3539 3469 3505 3565 3502 3392 3385 3508 3453 3424 3247 3247 3124 3126 3027 3072 2935 2993 2934 2944 2914 2820 2737 2799 2778 2884 2764 2742 2717 2857 2687 2877 2869 2936 3134 3235 3373 3333 3406 3191 3118 3072 3022 2854 2778 2867 2803 2739 2853 2801 2757</intensities>
			</dataPoints>
			<nonAmbientPoints type="Temperature" unit="K">
[...]
			</nonAmbientPoints>
		</scan>
	</xrdMeasurement>
</xrdMeasurements>