File: powder_X-ray_diffraction/variable-temperature_experiments/NaTaO2F2/raw_data/240°C.xrdml
<?xml version="1.0" encoding="UTF-8"?>
<xrdMeasurements xmlns="http://www.xrdml.com/XRDMeasurement/1.7" xmlns:xsi="http://www.w3.org/2001/XMLSchema-instance" xsi:schemaLocation="http://www.xrdml.com/XRDMeasurement/1.7 http://www.xrdml.com/XRDMeasurement/1.7/XRDMeasurement.xsd" status="Completed">
	<comment>
		<entry>Configuration=XRK900, Owner=User-1, Creation date=12/01/2015 16:52:44</entry>
		<entry>Goniometer=Theta/Theta; Minimum step size 2Theta:0.0001; Minimum step size Omega:0.0001</entry>
		<entry>Sample stage=AP XRK-900 with z-axis; Minimum step size Z:0.001</entry>
		<entry>Diffractometer system=EMPYREAN</entry>
		<entry>Measurement program=C:\PANalytical\Data Collector\Programs\Gwen\NaTaO2F2\NaTaO2F2-Lent.xrdmp, Identifier={FF50B583-C5FF-42DA-A01D-A1FB659EF29A}</entry>
		<entry>Batch program=C:\PANalytical\Data Collector\Programs\Gwen\NaTaO2F2\Thermodiff-Ouail.xrdmp, Identifier={5D65A6B1-42FC-480C-9FBB-D7D88D55EA08}</entry>
	</comment>
	<sample type="To be analyzed">
		<id></id>
		<name></name>
		<preparedBy></preparedBy>
	</sample>
	<xrdMeasurement measurementType="Scan" status="Completed" sampleMode="Reflection">
		<comment>
			<entry>PHD Lower Level = 4.02 (keV), PHD Upper Level = 12.07 (keV)</entry>
		</comment>
		<usedWavelength intended="K-Alpha 1">
			<kAlpha1 unit="Angstrom">1.5405980</kAlpha1>
			<kAlpha2 unit="Angstrom">1.5444260</kAlpha2>
			<kBeta unit="Angstrom">1.3922500</kBeta>
			<ratioKAlpha2KAlpha1>0.5000</ratioKAlpha2KAlpha1>
		</usedWavelength>
		<incidentBeamPath>
			<radius unit="mm">240.00</radius>
			<xRayTube id="1010048" name="Empyrean Cu LFF HR (9430 033 7310x) DK434948">
				<tension unit="kV">45.0</tension>
				<current unit="mA">30.0</current>
				<anodeMaterial>Cu</anodeMaterial>
				<focus type="Line">
					<length unit="mm">12.0</length>
					<width unit="mm">0.4</width>
					<takeOffAngle unit="deg">6.0</takeOffAngle>
				</focus>
			</xRayTube>
			<sollerSlit id="21010001" name="Soller slits 0.02 rad.">
				<opening unit="rad">0.0200</opening>
			</sollerSlit>
			<mask id="22030010" name="Fixed mask 20 mm">
				<width unit="mm">20.00</width>
			</mask>
			<antiScatterSlit id="22010003" name="Fixed slit 1Â°" xsi:type="fixedAntiScatterSlitType">
				<height unit="mm">1.52</height>
			</antiScatterSlit>
			<divergenceSlit id="22010012" name="Programmable divergence slit" xsi:type="fixedDivergenceSlitType">
				<distanceToSample unit="mm">140.00</distanceToSample>
				<angle unit="deg">0.5</angle>
			</divergenceSlit>
		</incidentBeamPath>
		<diffractedBeamPath>
			<radius unit="mm">240.00</radius>
			<antiScatterSlit id="22090010" name="AS slit 8.0 mm (PIXcel)" xsi:type="fixedAntiScatterSlitType">
				<height unit="mm">8.00</height>
			</antiScatterSlit>
			<sollerSlit id="21010001" name="Soller slits 0.02 rad.">
				<opening unit="rad">0.0200</opening>
			</sollerSlit>
			<filter id="20030001" name="Large beta-filter Nickel">
				<material>Ni</material>
				<thickness unit="mm">0.020</thickness>
			</filter>
			<detector id="7010019" name="PIXcel1D-Medipix3 detector" xsi:type="rtmsDetectorType">
				<phd unit="%">
					<lowerLevel>25.0</lowerLevel>
					<upperLevel>75.0</upperLevel>
				</phd>
				<mode>Scanning</mode>
				<activeLength unit="deg">3.3482</activeLength>
			</detector>
		</diffractedBeamPath>
		<scan appendNumber="0" mode="Continuous" scanAxis="Gonio" status="Completed">
			<header>
				<startTimeStamp>2023-01-22T10:17:06+01:00</startTimeStamp>
				<endTimeStamp>2023-01-22T13:17:35+01:00</endTimeStamp>
				<author>
					<name>User</name>
				</author>
				<source>
					<applicationSoftware version="5.5a">Data Collector</applicationSoftware>
					<instrumentControlSoftware version="8.2  20201204">EMPYREAN</instrumentControlSoftware>
					<instrumentID>0000000011159748</instrumentID>
				</source>
			</header>
			<dataPoints>
				<positions axis="2Theta" unit="deg">
					<startPosition>9.99846514</startPosition>
					<endPosition>99.99342261</endPosition>
				</positions>
				<positions axis="Omega" unit="deg">
					<startPosition>4.99923257</startPosition>
					<endPosition>49.99671130</endPosition>
				</positions>
				<positions axis="Z" unit="mm">
					<commonPosition>8.846</commonPosition>
				</positions>
				<commonCountingTime unit="seconds">386.070</commonCountingTime>
				<intensities unit="counts">6511 6552 6490 6550 6551 6355 6425 6537 6474 6232 6479 6291 6413 6299 6448 6350 6373 6381 6379 6195 6312 6437 6422 6292 6297 6243 6252 6268 6248 6164 6315 6284 6336 6258 6356 6473 6215 6306 6230 6323 6172 6187 6216 6331 6222 6215 6315 6367 6210 6106 6252 6204 6112 6094 6229 6341 6231 6381 6350 6362 6366 6428 6502 6531 6291 6497 6395 6454 6708 6831 6854 6940 7186 7444 7926 8500 9326 10706 12391 15166 19678 24691 31266 40707 48168 49999 47514 40494 33715 27211 20500 15906 12280 9648 8640 7696 7068 6796 6659 6491 6384 6169 6143 6023 6138 6019 6063 6060 6147 6122 6056 5826 6028 5949 5996 5983 5939 5944 5825 5850 5897 5903 5998 5998 5784 5746 5753 5824 5804 5820 5764 5674 5814 5854 5858 5745 5800 5782 5715 5712 5751 5923 5927 5728 5736 5782 5733 5734 5741 5672 5705 5571 5707 5641 5738 5696 5767 5777 5690 5557 5721 5654 5793 5621 5509 5681 5694 5551 5688 5591 5724 5730 5554 5724 5541 5500 5777 5527 5488 5702 5545 5512 5481 5578 5576 5559 5480 5448 5593 5309 5450 5534 5477 5616 5559 5561 5486 5580 5577 5563 5473 5449 5437 5434 5538 5449 5440 5547 5424 5447 5447 5439 5448 5367 5345 5437 5463 5481 5392 5459 5306 5389 5346 5333 5496 5311 5338 5402 5375 5389 5200 5486 5464 5354 5340 5272 5378 5353 5272 5264 5253 5296 5395 5226 5355 5318 5186 5361 5258 5232 5255 5374 5204 5314 5367 5156 5342 5379 5378 5238 5204 5252 5181 5324 5328 5410 5368 5343 5222 5163 5018 5163 5194 5083 5244 5180 5296 5201 5184 5088 5212 5309 5114 5071 5187 5232 5198 5132 5158 5137 5137 5174 5058 5161 5236 5237 5130 4956 5164 5197 5115 5149 5121 4911 5016 5081 5043 5235 5197 5107 5187 4957 5040 5005 4960 4977 5001 5198 5014 5096 5070 5070 4994 5009 5006 5017 4938 4979 4965 5119 5017 5053 5009 5200 5022 4972 4909 5019 4950 4933 4856 5150 4941 4981 4903 4898 4963 4870 4905 4865 4883 4902 4849 5012 4929 4846 4898 4954 4936 4901 4939 4868 4921 4894 4880 4859 5046 4966 4910 4811 4786 4849 4963 4930 4785 4833 4921 4810 4834 4898 4720 4901 4801 4875 4861 4900 4789 4924 4949 4716 4797 4772 4727 4777 4876 4938 4801 4723 4780 4824 4792 4926 4765 4743 4858 4660 4799 4847 4804 4663 4736 4735 4592 4728 4867 4698 4757 4686 4711 4720 4792 4607 4701 4749 4796 4712 4690 4642 4879 4708 4702 4717 4683 4814 4596 4738 4685 4741 4721 4700 4766 4737 4684 4723 4642 4728 4776 4580 4614 4645 4592 4690 4691 4742 4718 4705 4694 4708 4711 4719 4703 4766 4850 4772 4657 4664 4770 4819 4770 4857 4867 4750 4805 4717 4823 4766 5009 4737 4897 4766 4796 4861 4640 4798 4881 4824 4763 4835 4767 4680 4812 4825 4707 4732 4694 4632 4633 4725 4647 4811 4655 4632 4500 4611 4569 4637 4631 4615 4490 4623 4553 4424 4496 4537 4660 4519 4438 4515 4567 4449 4650 4485 4573 4532 4547 4413 4475 4397 4490 4562 4471 4554 4432 4537 4598 4629 4581 4536 4492 4526 4534 4451 4448 4568 4581 4579 4428 4533 4549 4630 4557 4596 4786 4657 4666 4487 4627 4566 4506 4383 4385 4405 4561 4559 4381 4313 4523 4417 4377 4463 4366 4356 4342 4258 4428 4449 4434 4460 4519 4436 4374 4391 4445 4433 4447 4460 4631 4679 4730 4644 4777 4628 4604 4378 4530 4487 4514 4455 4507 4325 4320 4475 4407 4332 4325 4429 4321 4345 4338 4344 4351 4333 4270 4292 4297 4286 4257 4283 4168 4273 4345 4281 4243 4303 4159 4312 4219 4180 4200 4141 4168 4305 4222 4251 4341 4333 4191 4248 4275 4215 4357 4335 4303 4272 4213 4229 4213 4216 4238 4199 4217 4394 4188 4143 4287 4238 4319 4272 4315 4398 4229 4286 4158 4269 4385 4231 4251 4155 4120 4089 4125 4157 4188 4252 4214 4154 4140 4164 4186 4160 4311 4201 4301 4214 4432 4517 4482 4579 4522 4509 4553 4579 4617 4605 4494 4674 4524 4608 4584 4669 4565 4715 4520 4570 4763 4537 4579 4673 4653 4723 4679 4694 4873 4871 4790 5011 5098 5282 5381 5564 5838 5875 6138 6456 6900 7792 9048 10974 14084 18753 26398 39497 59634 83912 106487 123801 124039 115410 105047 91938 73159 54932 39604 27820 19594 14507 10844 8588 7334 6541 6002 5992 5530 5193 5157 4963 4799 4755 4643 4621 4598 4480 4598 4528 4416 4394 4314 4431 4457 4339 4378 4551 4420 4486 4606 4621 4482 4459 4512 4477 4364 4399 4253 4201 4188 4155 4270 4102 4192 4263 4208 4177 4216 4132 4093 4189 4135 4176 4057 4029 4027 4026 4129 4150 4173 4228 4119 4049 4019 4067 3891 3999 4085 4057 4067 3916 3998 4050 4083 4081 4069 3956 4007 3992 4016 3977 4054 4076 4046 4081 3927 3993 3855 3903 4014 3970 3934 3991 4067 3945 3991 3936 3980 3969 3892 3950 3908 3861 3953 4110 3945 4010 3910 3862 3818 4036 3841 3860 3938 4034 3869 3938 3892 3981 3854 3956 3936 3835 3912 3912 3786 3851 3774 3872 3839 3831 3746 3744 3839 3894 3827 3793 3898 3830 3925 3946 3830 3801 3859 3839 3939 4009 3945 3885 3896 4042 4031 4123 4011 4256 4301 4131 4212 4183 3996 4026 4006 4001 3929 3869 3900 3901 3983 3977 3993 4009 4050 3852 3807 3823 3873 3982 3932 3881 3976 3951 4007 3961 4118 4007 4233 4225 4618 4842 5425 6471 7800 10378 14302 17570 19368 18425 17478 16524 16011 13516 10531 8266 7176 5991 5114 4521 4243 4087 4016 4038 3913 3908 3878 3844 3773 3727 3868 3633 3816 3815 3759 3633 3686 3747 3834 3879 3928 3871 3723 3929 3851 3811 3795 3872 3610 3707 3686 3858 3719 3666 3720 3744 3583 3751 3743 3692 3675 3758 3765 3616 3593 3651 3671 3706 3759 3697 3766 3698 3585 3632 3587 3750 3673 3641 3661 3687 3656 3668 3668 3761 3732 3776 3703 3710 3807 3702 3740 3780 3803 3804 3870 3814 3788 3776 3851 3891 3815 3928 3974 3846 3947 3794 3891 3910 4029 3817 3861 3915 3800 4080 3998 3880 3932 3990 3933 3908 3966 3940 4084 3947 3962 4187 4091 4176 4314 4232 4341 4305 4378 4440 4469 4559 4625 4893 4872 5248 5638 6077 7099 8846 12132 16601 23758 31911 39493 44076 45129 42376 38924 35152 33532 28595 22791 19960 21071 25250 32096 37946 43746 48237 48271 44191 40867 36878 31199 24707 18662 14723 11115 8223 6469 5470 5064 4757 4396 4350 4253 4178 4148 3982 3912 3851 3890 3796 3826 3775 3922 3764 3680 3814 3713 3785 3619 3647 3759 3725 3646 3771 3741 3773 3642 3804 3766 3895 3863 4076 3975 3947 3822 3799 3775 3658 3661 3557 3640 3639 3640 3697 3736 3640 3728 3627 3556 3664 3609 3670 3701 3568 3550 3600 3549 3552 3642 3572 3639 3733 3600 3539 3658 3677 3572 3601 3700 3712 3598 3522 3502 3511 3545 3457 3593 3517 3595 3395 3508 3618 3540 3462 3475 3548 3506 3614 3462 3366 3516 3456 3571 3525 3440 3471 3564 3487 3483 3429 3552 3439 3613 3575 3538 3496 3515 3430 3476 3545 3469 3612 3552 3614 3645 3686 3660 3761 3843 3822 3891 3811 3736 3825 3622 3682 3730 3645 3502 3505 3629 3540 3443 3597 3449 3502 3653 3601 3538 3419 3511 3494 3570 3449 3416 3443 3470 3427 3532 3518 3551 3493 3516 3472 3383 3340 3257 3392 3403 3395 3432 3367 3506 3571 3499 3555 3474 3651 3590 3635 3660 3695 3625 3591 3747 3637 3592 3761 3700 3696 3727 3610 3650 3683 3622 3526 3492 3577 3580 3680 3568 3584 3628 3676 3545 3643 3687 3714 3680 3759 3629 3642 3594 3760 3639 3744 3816 3734 3688 3782 3755 3773 3712 3945 3911 3917 3971 4131 4212 4389 4549 4692 4771 4976 5339 5325 5947 6303 6799 7666 8800 10694 13767 19316 28300 42336 61018 77207 85355 82857 74351 68166 63840 57928 50009 40430 30807 22594 16271 11666 8952 7296 6473 5671 5281 5008 4571 4528 4345 4113 4012 3929 3830 3873 3827 3823 3701 3756 3676 3629 3596 3688 3487 3627 3747 3602 3630 3750 3829 3966 3755 4005 3903 3824 3852 3799 3719 3698 3641 3803 3659 3650 3636 3535 3606 3632 3635 3628 3501 3537 3574 3587 3606 3652 3604 3557 3629 3600 3573 3661 3599 3656 3585 3448 3560 3607 3562 3557 3551 3599 3469 3576 3540 3591 3478 3537 3599 3602 3592 3605 3598 3645 3599 3720 3763 3666 3797 3852 3826 4025 4022 4017 4274 4365 4375 4600 4878 5055 5739 6598 8520 11969 16937 23965 29789 32820 32036 29246 26309 25495 24218 23243 22078 20258 20089 20336 21027 21163 19605 17611 15633 14648 13206 12026 10603 8708 6951 5804 4903 4211 4165 3900 3764 3723 3639 3540 3509 3462 3494 3419 3504 3490 3468 3320 3344 3413 3272 3319 3370 3415 3430 3263 3515 3376 3314 3361 3383 3381 3345 3482 3421 3398 3490 3316 3343 3391 3329 3438 3281 3184 3221 3331 3291 3287 3271 3205 3316 3273 3202 3268 3235 3320 3229 3223 3279 3354 3317 3218 3369 3376 3326 3299 3221 3304 3298 3275 3299 3185 3245 3288 3291 3319 3227 3239 3324 3310 3219 3275 3303 3134 3189 3204 3248 3247 3167 3117 3222 3215 3198 3207 3126 3200 3286 3194 3152 3180 3167 3144 3196 3325 3202 3104 3226 3267 3090 3201 3144 3216 3171 3131 3220 3226 3275 3188 3157 3118 3133 3200 3194 3092 3176 3110 3178 3190 3160 3176 3112 3121 3154 3083 3201 3157 3136 3057 3083 3118 3172 3120 3126 3038 3077 3051 3171 3035 3092 3136 3025 3062 3071 3242 3275 3289 3137 3090 3076 3027 3166 3091 3110 3128 3159 3146 3152 3148 3189 3176 3122 3162 3091 3143 3174 3083 2982 3152 3073 3182 3129 3046 3095 3104 3176 3095 3199 3139 3145 3227 3088 3033 3060 3199 3042 3101 3133 3169 3239 3135 3212 3269 3114 3236 3131 3199 3267 3265 3131 3191 3196 3094 3237 3283 3285 3161 3202 3324 3168 3364 3434 3259 3286 3398 3483 3557 3493 3572 3668 3703 3762 3809 4100 4517 5014 6443 8864 13186 18128 21327 21061 17412 14391 13178 13426 13923 13060 11125 9142 7248 5862 4920 4375 3900 3872 3669 3611 3467 3536 3622 3460 3458 3554 3547 3535 3679 3741 3786 3754 3866 3844 4047 4149 4243 4456 4647 4952 5521 6488 8317 11143 16429 23429 29875 34496 34196 30247 26257 23008 21521 21345 20743 18337 15161 11855 8813 6805 5751 5240 4793 4707 4699 4801 4612 4759 5114 5223 5642 6561 7638 9830 13095 17671 21981 26599 29024 29269 27728 24772 22384 20985 20449 20034 20093 20860 20899 21179 19379 15494 12211 10646 10544 10750 10741 9322 7984 6594 5622 4806 4222 3869 3607 3513 3634 3487 3437 3313 3280 3244 3250 3177 3193 3199 3064 3237 3265 3187 3142 3264 3219 3221 3187 3179 3251 3196 3237 3170 3294 3267 3261 3256 3270 3339 3354 3342 3389 3410 3512 3532 3681 3791 3951 4474 5376 6710 9100 11868 13919 14152 12739 10867 9179 8863 8805 9132 8697 7453 6259 5293 4490 4100 3650 3371 3402 3300 3243 3252 3268 3303 3297 3506 3664 3603 3486 3527 3421 3301 3314 3326 3345 3234 3208 3235 3138 3073 2986 3027 3052 3010 2869 2966 2961 2956 2993 2949 2964 2999 2964 2860 2954 2963 2915 2956 2932 2859 2962 2933 2930 2986 2956 2938 3001 3016 2938 2926 2951 2832 2914 2907 2972 2991 3015 2879 3018 2974 3001 2977 2872 2865 2959 2839 2941 3020 2852 2957 2892 2889 2989 2860 2842 2852 3038 2912 2990 2930 3030 3037 2999 3019 2857 2920 2900 2958 2966 2937 2946 2926 2848 3012 3007 2957 2949 2967 2962 2984 2950 2915 2950 2968 2867 2886 2884 2927 2921 2937 2919 2968 2938 2880 2837 2910 2923 2932 2882 3046 2969 2896 2996 2934 3002 3054 3023 2980 3070 3100 3139 3138 3210 3275 3497 3752 4321 5014 6413 8102 9133 9661 8835 7162 6153 5669 5987 6213 6560 5972 5200 4361 3809 3525 3332 3232 3163 3134 3048 2981 3234 2926 2986 2993 2957 2968 3035 2984 2991 3089 3040 3188 3102 3096 2986 3099 3142 3221 3193 3362 3572 3807 4178 5132 6347 7605 8972 9625 9858 9614 8464 7787 7242 6924 6807 6536 6434 5761 5073 4468 3734 3470 3272 3102 3069 3029 3079 3229 3419 3541 3451 3619 3457 3480 3275 3297 3361 3470 3200 3192 3080 3041 2921 3004 2922 2982 2958 2905 2782 2859 2847 2928 2716 2760 2861 2665 2859 2718 2711 2778 2809 2779 2734 2780 2848 2780 2724 2866 2792 2801 2820 2712 2772 2823 2817 2771 2780 2856 2739 2893 2793 2767 2767 2749 2842 2780 2662 2690 2651 2842 2735 2649 2797 2871 2786 2672 2778 2772 2772 2758 2688 2806 2767 2856 2864 2763 2695 2797 2803 2770 2735 2861 2833 2808 2710 2818 2815 2779 2803 2774 2822 2713 2711 2789 2757 2714 2749 2804 2694 2795 2746 2912 2731 2700 2740 2718 2790 2711 2638 2660 2759 2623 2701 2825 2711 2752 2701 2708 2710 2733 2744 2728 2660 2802 2757 2723 2731 2754 2628 2791 2659 2797 2678 2737 2691 2713 2805 2695 2729 2794 2809 2753 2817 2758 2691 2804 2771 2873 2950 3011 3109 3241 3701 4047 4419 4702 4684 4871 4764 4409 4064 3895 3986 4009 4011 3978 3623 3543 3427 3381 3334 3383 3360 3659 3982 4782 5733 6958 7792 7847 7211 6170 5666 5289 5126 5583 5621 5538 5022 4515 4070 3676 3597 3399 3292 3177 3194 3265 3228 3290 3298 3527 3831 4306 5216 6534 8431 9891 10068 9207 7885 6540 5926 5904 6205 6628 6640 6097 5241 4499 3980 3629 3385 3236 3083 3096 3079 3069 2978 2995 3074 2926 2960 2926 2915 3084 3058 3092 3154 3237 3198 3376 3402 3582 3811 4156 4866 5618 6895 8188 9939 11207 11189 10496 9270 7990 7240 7538 8041 8628 9421 9980 11285 12651 13396 13242 12393 11102 9752 10077 10951 13375 15329 16774 16117 13749 11098 8808 7614 7494 7635 7940 7703 7057 5900 5001 4132 3698 3405 3210 3200 3074 2968 2939 2943 2890 2943 2898 2804 2782 2883 2867 2824 2713 2821 2695 2740 2740 2763 2833 2807 2790 2751 2807 2768 2746 2766 2700 2759 2809 2585 2669 2745 2713 2751 2695 2661 2654 2688 2713 2727 2634 2632 2630 2763 2698 2670 2731 2684 2575 2714 2664 2685 2799 2627 2680 2690 2656 2638 2632 2770 2588 2697 2680 2814 2706 2662 2683 2611 2711 2747 2742 2710 2676 2592 2665 2687 2719 2715 2596 2585 2668 2777 2733 2710 2544 2561 2728 2654 2747 2628 2596 2703 2739 2773 2624 2630 2705 2648 2671 2661 2689 2686 2763 2618 2732 2696 2732 2724 2760 2762 2808 2770 2742 2747 2702 2641 2724 2712 2732 2665 2653 2664 2722 2613 2700 2598 2731 2712 2674 2580 2760 2582 2643 2688 2655 2537 2749 2671 2599 2666 2668 2731 2702 2950 3055 3125 3169 3366 3303 3220 3132 3005 2972 3036 2978 3061 3074 2976 3033 2910 2783 2708 2637 2629 2748 2721 2671 2604 2706 2650 2737 2658 2680 2738 2700 2736 2672 2611 2794 2651 2685 2664 2645 2734 2609 2651 2667 2619 2664 2706 2659 2660 2649 2617 2637 2776 2629 2748 2768 2699 2772 2857 2830 3008 3251 3544 3803 4179 4176 4014 3663 3370 3362 3289 3287 3348 3545 3537 3354 3247 3098 2963 3049 3094 3081 3054 3373 3577 3954 4305 4946 5428 5467 5492 5213 4687 4317 4162 4006 4178 4180 4105 4168 3834 3564 3279 3100 2862 2972 2876 2861 2757 2729 2746 2688 2692 2788 2704 2690 2696 2698 2797 2748 2703 2636 2684 2736 2713 2587 2551 2622 2660 2693 2642 2699 2621 2623 2653 2680 2714 2657 2664 2611 2732 2699 2702 2641 2733 2671 2702 2737 2677 2675 2589 2570 2709 2747 2753 2658 2675 2802 2741 2842 2824 2768 2783 2775 2873 2778 2942 2956 3029 3100 3266 3505 3903 4584 5782 7864 9881 11516 10861 9229 7289 5734 5059 5076 5671 6622 7161 6996 6106 5100 4309 3741 3297 3018 2985 2974 2939 2886 2724 2769 2737 2793 2750 2733 2637 2772 2748 2793 2674 2758 2915 2757 2737 2829 2878 2807 2782 2745 2737 2908 2896 2877 2856 2954 3132 3132 3447 3903 4470 5541 6463 7135 7209 6297 5055 4424 4088 3902 4219 4608 4998 4967 4841 4041 3648 3299 3156 2926 2899 2923 2845 2918 2768 2817 2861 2874 2776 2805 2783 2758 2896 2795 2800 2856 2792 2783 2930 2946 2917 2771 2919 2961 2955 3080 3059 3039 3091 3160 3358 3521 3942 4534 5408 6272 7322 8144 8599 8651 8120 7023 5788 5405 5319 5481 5649 5946 5911 5836 5148 4430 3888 3448 3279 3124 3119 2958 3009 3057 3113 2971 3092 3164 3128 3099 3076 3182 3299 3178 3257 3469 3359 3341 3554 3560 3574 3735 3874 3892 4306 4777 5372 6081 7539 9291 12078 15299 18252 20135 19750 17614 15009 12472 10615 10098 10436 11345 12234 12295 11329 9810 8226 6831 5695 4876 4413 4034 3828 3693 3321 3372 3325 3219 3239 3146 3180 3218 3193 3298 3291 3296 3381 3345 3358 3387 3382 3416 3810 4095 4724 5576 7262 9082 11383 12478 12741 13042 13195 13444 12736 11618 10858 10523 9893 9059 8768 8524 8571 8250 7699 6822 6116 5409 4485 4234 4048 4234 4472 4946 5651 6868 8912 11248 12972 13058 12073 10001 8092 6745 6152 6365 6749 7634 8226 8273 7275 6200 5269 4603 3972 3651 3407 3229 3253 3080 3056 2989 2887 3054 2993 2876 2946 2942 2970 2882 2879 2793 2957 2844 2866 2755 2980 2883 2829 2846 2859 2909 2899 2824 3065 3095 3068 3344 3432 3522 3659 3478 3425 3251 3148 3140 3166 3095 3236 3324 3304 3338 3384 3427 3532 3547 3380 3465 3490 3411 3453 3440 3400 3431 3557 3627 3607 3494 3754 3701 3764 3681 3871 4332 4779 5635 6759 8988 11514 14568 17509 18779 18385 16462 13762 11551 10354 9984 10355 10977 11899 11993 11550 10520 8863 7592 6440 5645 5091 4762 4448 4130 3806 3696 3653 3555 3587 3650 3692 3841 4094 4375 4890 5732 6691 7646 9065 10296 11213 11278 10250 8944 7595 6889 6381 6284 6680 7115 7371 7427 6743 6058 5197 4552 4062 3716 3530 3407 3296 3166 3140 3063 2908 3029 2984 2967 2975 2917 2865 2893 2886 2939 2808 2854 2878 2858 2862 2764 2868 2841 2801 2775 2773 2840 2824 2919 2953 2896 2996 2845 2916 2980 3004 3030 3113 3110 3029 3260 3395 3487 3973 4747 5641 6963 8257 8807 8426 7695 6471 5387 4782 4703 4718 5124 5547 6002 5882 5541 5085 4447 4189 3999 3923 3788 3688 3583 3317 3201 3085 2974 2929 3047 3060 3062 3107 3135 2978 3067 2872 2894 2907 2845 2921 2922 2738 2788 2837 2785 2863 2779 2754 2856 2812 2740 2832 2758 2704 2804 2830 2811 2689 2855 2774 2836 2668 2767 2694 2803 2738 2832 2694 2884 2823 2940 2895 2847 2873 2913 2919 2975 2932 2908 3121 3012 3116 3080 3154 3257 3438 3686 3957 4685 5311 6541 7711 8854 9978 10463 10424 10277 8991 7806 7060 6167 5935 6084 6472 6793 6830 6778 6372 5738 5222 4525 3992 3685 3667 3511 3703 3882 4277 4683 5115 5452 5801 6224 6410 6498 6419 5798 5325 4980 4700 4627 4397 4440 4602 4626 4415 4416 4177 3759 3624 3356 3075 3018 2916 2927 2847 2697 2798 2729 2776 2844 2756 2783 2738 2867 2767 2752 2819 2842 2788 2709 2696 2839 2817 2931 2941 2995 3202 3278 3618 3794 4100 4332 4296 4099 3790 3545 3360 3334 3118 3248 3330 3410 3623 3516 3390 3205 3000 2960 2990 2855 2903 2810 2768 2695 2714 2700 2786 2707 2788 2689 2718 2768 2680 2752 2721 2748 2791 2590 2705 2747 2737 2727 2688 2660 2687 2675 2727 2778 2718 2650 2771 2851 2890 2857 2989 3072 3019 3015 3148 3107 3100 3060 2951 3117 2971 2917 2951 2948 2929 2885 2959 2880 2873 2721 2768 2810 2735 2746 2759 2747 2624 2746 2568 2695 2711 2913 2680 2679 2789 2735 2772 2713 2673 2736 2763 2813 2706 2727 2688 2693 2733 2811 2734 2741 2688 2615 2792 2773 2833 2803 2776 2698 2877 2781 2758 2873 2776 2905 2850 2878 2898 2985 2920 2972 3023 3067 3117 3163 3287 3509 3687 4195 4557 5179 6145 7698 9152 10843 11394 10843 9671 8243 7006 6019 5771 5641 5826 6543 7334 7340 7409 6775 6135 5129 4577 4121 3756 3654 3603 3643 3598 3569 3672 3491 3400 3250 3233 3045 2939 3009 3093 3014 2990 3094 3057 2988 2984 2851 2893 2832 2861 2827 2898 2878 2882 2895 3022 2960 2949 3003 2966 3012 3052 3013 3115 3130 3268 3194 3377 3454 3645 4081 4555 5269 6050 6999 7512 8359 9055 10328 11412 12362 13062 12895 12141 10708 9548 8091 7563 7273 7161 7587 7862 8150 8079 7589 6980 6192 5169 4512 3898 3632 3433 3253 3289 3145 3023 3166 3115 3087 3026 3111 3041 3087 3070 3066 3062 3117 3088 3162 3265 3115 3166 3271 3444 3429 3733 4113 4310 4795 5578 6316 7012 7750 8378 8971 9426 9417 10056 9687 9151 8369 7629 7242 6816 6640 6784 7008 7588 7834 8203 8987 9199 9045 8474 7518 6637 5698 5083 4437 4366 4305 4376 4630 4961 5024 5137 4570 4208 3962 3600 3395 3285 3087 3177 3061 3074 3087 3050 3029 2999 3058 2996 3002 3031 3042 3110 3070 3080 3350 3406 3481 3740 3832 4335 5060 5757 7076 8242 9038 9150 8196 7155 6230 5547 5250 5036 5187 5589 6326 6762 7035 7096 6520 5894 5233 4610 4191 3971 3745 3653 3864 3825 3673 3672 3576 3433 3395 3352 3310 3319 3271 3211 3281 3275 3348 3413 3650 3714 4044 4378 4857 5516 6442 7104 7798 8328 8731 8371 7589 6758 6044 5443 5322 5226 5567 5993 6593 7094 7716 8490 9201 9990 10140 10087 9107 7892 6374 5578 5023 4921 5014 5183 5614 6026 6687 7155 6999 7210 7251 7586 8349 9111 9519 9518 9025 7977 6877 5999 5305 5021 4904 5158 5577 5813 6037 6181 5978 5703 5047 4496 3939 3818 3431 3287 3162 3116 3128 3133 3015 3042 2990 3099 2971 3031 3072 3043 3042 2964 2920 3186 3190 3159 3430 3550 3814 4183 4765 5211 6105 6690 7398 7964 8507 8447 7932 7199 6418 5796 5380 5186 5338 5665 6100 6714 7281 7876 8171 8382 8425 8645 8832 9620 10820 11160 10870 10069 8478 7238 6482 6019 5764 5716 5881 6096 6601 6955 7024 6393 5762 5039 4457 4018 3674 3458 3412 3182 3200 3031 2954 3028 3074 2983 2929 3009 2980 2890 2908 2990 3000 3074 2978 3060 3139 3107 3160 3288 3315 3328 3386 3489 3622 3831 4158 4428 4986 5829 7010 8491 10563 12378 13811 13992 13543 12436 11070 9408 8196 7485 7074 7093 7979 8681 9498 10039 10157 9751 8996 8352 7469 6814 6011 5494 5227 4905 4828 5009 5110 5288 5430 5624 5651 5662 5461 5091 4761 4348 3955 3699 3753 3694 3664 3826 3738 3660 3715 3659 3475 3328 3203 3046 2893 2926 2764 2771 2739 2683 2714 2578 2689 2687 2745 2661 2669 2558 2601 2690 2599 2544 2651 2575 2572 2604 2626 2612 2552 2593 2581 2561 2620 2596 2570 2615 2461 2553 2664 2560 2483 2512 2612 2501 2575 2533 2526 2521 2571 2570 2496 2491 2470 2569 2465 2468 2499 2538 2492 2554 2566 2550 2462 2575 2482 2486 2580 2507 2579 2495 2582 2562 2484 2531 2485 2491 2447 2451 2608 2533 2498 2626 2503 2514 2462 2545 2598 2580 2574 2565 2497 2519 2496 2475 2534 2627 2587 2595 2529 2457 2541 2520 2379 2430 2466 2560 2536 2380 2442 2525 2519 2564 2536 2631 2506 2541 2514 2472 2435 2444 2551 2501 2476 2519 2575 2455 2587 2517 2478 2492 2471 2532 2461 2448 2501 2521 2430 2413 2531 2529 2427 2568 2510 2469 2581 2542 2446 2515 2532 2538 2535 2483 2552 2522 2530 2565 2665 2654 2655 2792 2730 2754 2684 2784 2838 2872 2892 2943 2993 3145 3290 3434 3716 3841 4089 3948 3849 3714 3361 3236 3221 3078 2946 3014 3057 3158 3149 3284 3325 3354 3171 3072 2920 2876 2751 2915 2687 2758 2858 3020 3138 3177 3473 3586 3837 4107 4219 4171 4235 3966 3670 3385 3295 3126 3252 3333 3568 3662 3896 4367 4426 4549 4565 4489 4042 3797 3483 3290 3084 2909 2857 2954 3066 2985 3130 3112 3184 3115 3047 3021 2828 2688 2586 2546 2560 2490 2492 2616 2489 2478 2522 2422 2443 2505 2581 2460 2378 2446 2471 2440 2478 2526 2468 2571 2546 2552 2629 2665 2660 2775 2681 2608 2706 2756 2736 2736 2741 2824 2663 2795 2752 2717 2730 2781 2759 2814 2714 2698 2656 2677 2703 2569 2655 2586 2601 2535 2542 2446 2544 2553 2538 2553 2552 2477 2442 2500 2378 2364 2338 2427 2468 2433 2455 2423 2389 2471 2433 2483 2366 2321 2419 2400 2459 2434 2400 2475 2426 2402 2360 2456 2482 2419 2280 2388 2361 2341 2381 2477 2515 2374 2438 2374 2447 2411 2330 2495 2436 2432 2416 2443 2435 2549 2416 2388 2502 2478 2438 2351 2404 2401 2481 2396 2384 2403 2419 2426 2476 2422 2461 2406 2452 2402 2340 2329 2366 2333 2316 2413 2462 2423 2372 2473 2391 2365 2392 2243 2431 2489 2514 2559 2468 2542 2435 2499 2573 2474 2426 2437 2383 2365 2418 2421 2436 2475 2397 2392 2373 2409 2504 2513 2436 2363 2607 2473 2520 2521 2594 2500 2427 2432 2497 2444 2490 2416 2458 2495 2520 2464 2475 2470 2485 2478 2353 2459 2440 2433 2330 2384 2449 2305 2377 2513 2397 2402 2368 2340 2392 2390 2379 2481 2399 2346 2398 2399 2426 2344 2412 2300 2401 2386 2371 2420 2453 2357 2390 2423 2322 2473 2397 2388 2430 2384 2372 2468 2459 2420 2430 2495 2354 2419 2522 2495 2430 2328 2533 2429 2457 2507 2393 2391 2503 2501 2514 2484 2402 2478 2437 2416 2438 2442 2522 2530 2480 2530 2469 2488 2544 2468 2495 2599 2643 2502 2709 2772 3010 3039 3223 3639 3722 3734 3563 3441 3258 3120 3051 3058 2982 3192 3275 3364 3307 3390 3606 3500 3373 3229 3158 3001 2914 2850 2881 2943 3019 3087 3166 3260 3537 3744 4384 4801 5132 5222 4977 4556 3980 3454 3285 3203 2979 2892 2906 3186 3162 3378 3703 3662 3883 3734 3409 3186 2934 2760 2701 2617 2608 2473 2525 2623 2601 2521 2377 2532 2646 2577 2514 2475 2551 2676 2586 2563 2533 2504 2489 2547 2533 2547 2751 2708 2590 2643 2642 2733 2728 2930 3052 3222 3415 3741 4043 4210 4311 4275 4078 4083 4085 4046 3792 3865 3729 3796 3714 3643 3688 3707 3630 3674 3628 3487 3438 3330 3448 3399 3288 3301 3436 3434 3451 3507 3539 3458 3378 3285 3239 3154 3195 3249 3285 3412 3591 3956 4505 4921 5757 6341 6982 7411 7417 7095 6549 5969 5548 5222 5116 4816 4766 4470 4574 4573 4919 5018 5193 5422 5249 4949 4736 4575 4426 4129 3884 3751 3563 3387 3086 2951 2989 2984 3008 2940 2915 2969 2966 2984 3108 3074 3167 3137 3259 3449 3815 4047 4489 4816 4985 5245 5123 4842 4452 3852 3555 3528 3405 3225 3288 3391 3548 3689 3957 4216 4317 4554 4448 4440 4441 4399 4562 4449 4507 4539 4497 4307 4460 4155 4128 3983 3749 3580 3537 3419 3404 3509 3727 3694 3707 3608 3658 3696 3663 3796 3653 3789 3951 4398 4848 5175 5215 4957 4522 3939 3567 3215 3107 3102 2902 2994 2964 3115 3253 3385 3751 3808 3645 3576 3435 3139 2971 2942 2891 2884 2849 2862 2889 2866 2870 2901 2948 2936 2992 3162 3392 3773 3976 4238 4423 4629 4474 4373 4274 4110 3924 3889 3867 3767 3837 3876 3810 3658 3729 3674 3647 3708 3527 3392 3367 3326 3178 3153 3120 3106 3043 2872 2814 2854 2781 2685 2711 2663 2697 2621 2581 2617 2567 2484 2515 2611 2616 2533 2592 2602 2543 2504 2605 2550 2629 2583 2620 2710 2613 2625 2732 2754 2790 3047 3060 3279 3552 3942 4074 4208 4353 4102 3780 3571 3450 3239 3061 2900 2907 2956 2900 2918 3156 3199 3299 3374 3384 3333 3211 3065 2853 2834 2820 2823 2703 2623 2729 2594 2739 2708 2652 2732 2966 3049 3246 3478 3731 4022 4224 4307 4309 4188 4206 3852 3595 3404 3198 3082 2997 3097 3060 3294 3278 3446 3731 3807 3826 3843 3958 3947 3893 3990 3800 3947 3980 3791 3829 3725 3401 3346 3151 3301 3278 3236 3375 3425 3632 3724 3772 3697 3527 3433 3399 3235 3136 3107 2886 2947 2938 2972 3064 3190 3341 3569 3894 4158 4540 5062 5267 5522 5563 5577 5612 5389 5486 5348 5124 4881 4323 3993 3735 3730 3735 3933 3938 3959 4044 3995 4000 3937 3843 3871 3850 3627 3371 3164 2956 2716 2720 2660 2615 2574 2570 2502 2546 2505 2521 2472 2468 2475 2468 2519 2504 2470 2473 2460 2483 2475 2511 2401 2442 2450 2436 2410 2377 2321 2393 2354 2397 2474 2544 2434 2318 2432 2382 2361 2412 2465 2466 2407 2340 2357 2416 2382 2392 2413 2473 2447 2312 2394 2376 2430 2327 2283 2432 2442 2465 2369 2375 2356 2430 2419 2349 2388 2376 2494 2445 2399 2443 2356 2402 2485 2485 2426 2364 2328 2484 2458 2479 2346 2369 2461 2412 2412 2452 2429 2416 2517 2496 2435 2591 2523 2530 2529 2517 2450 2447 2488 2380 2436 2474 2415 2519 2534 2568 2477 2543 2572 2535 2551 2430 2528 2430 2448 2504 2477 2432 2456 2391 2453 2561 2490 2491 2544 2570 2654 2554 2629 2679 2683 2670 2649 2791 2785 2927 2968 2874 2959 2916 3060 3082 3111 3129 3128 3260 3369 3467 3701 3953 4133 4277 4623 4891 4861 4813 4673 4608 4279 3962 3768 3472 3474 3243 3342 3265 3316 3372 3490 3651 3574 3646 3628 3579 3430 3373 3277 3060 2909 2897 2967 2823 2745 2755 2736 2733 2710 2789 2733 2816 2895 2978 3159 3325 3360 3621 3870 4128 4278 4297 4436 4304 4374 4331 4231 3824 3715 3497 3353 3186 3219 3202 3263 3363 3295 3368 3443 3509 3475 3445 3462 3217 3148 2978 2880 2744 2707 2687 2644 2657 2620 2518 2632 2589 2531 2460 2514 2463 2552 2514 2487 2498 2616 2488 2601 2664 2631 2578 2638 2746 2832 2971 3039 3154 3165 3165 3218 3057 2925 2877 2740 2703 2643 2639 2615 2607 2649 2641 2659 2777 2820 2797 2863 2789 2772 2685 2658 2619 2655 2629 2584 2569 2538 2609 2573 2448 2633 2702 2710 2732 2878 2822 2871 2942 2777 2783 2706 2610 2728 2719 2766 2600 2773 2844 2743 2925 2994 3137 3308 3352 3519 3471 3467 3520 3562 3657 3620 3406 3419 3411 3370 3391 3305 3313 3174 3277 3292 3396 3427 3579 3785 3832 4128 4275 4316 4480 4553 4502 4453 4175 4248 4242 4202 4107 4189 4117 4017 4148 4140 4113 4063 4141 3907 4005 3854 3695 3754 3474 3494 3416 3308 3256 3259 3241 3291 3239 3165 3164 3087 3102 2935 2749 2796 2888 2799 2845 2801 2822 2772 2836 2751 2732 2833 2988 3107 3209 3390 3686 3854 4019 4075 4160 3988 3854 3640 3357 3211 3163 3064 3071 3127 3178 3266 3237 3275 3523 3486 3633 3588 3517 3392 3433 3208 3122 2994 2920 2976 2865 2913 2835 2877 2913 2855 2885 2969 3012 2970 2946 2947 3013 3111 3162 3201 3177 3397 3552 3837 3885 4344 4533 4789 4960 4847 4622 4643 4288 4120 3902 3709 3637 3645 3630 3716 3883 4072 4148 4531 4916 5193 5464 5944 6160 6527 6345 6496 6316 6483 6394 6087 5715 5415 4974 4469 4480 4317 4433 4565 4782 5176 5463 5432 5401 5387 5427 5130 5116 4944 4853 4788 4415 4360 4170 4008 4093 4004 3904 3800 3845 3759 3703 3536 3400 3357 3269 3263 3390 3346 3397 3525 3603 3612 3653 3639 3741 3647 3601 3586 3495 3441 3492 3554 3438 3378 3358 3215 3157 3058 3134 3031 2977 3033 2819 2861 2874 2891 2819 2886 2920 2804 2972 2834 2865 2755 2740 2746 2708 2665 2549 2475 2553 2439 2456 2559 2483 2555 2594 2509 2524 2568 2533 2600 2560 2570 2561 2597 2666 2638 2622 2598 2571 2570 2711 2747 2873 2826 2959 3134 3172 3340 3365 3413 3649 3714 3652 3696 3709 3620 3561 3401 3332 3101 2955 2934 2935 2944 3093 3111 3202 3320 3395 3558 3508 3525 3598 3541 3495 3328 3253 3218 3177 2969 2848 2800 2746 2713 2748 2828 2726 2772 2769 2824 2767 2896 2817 2820 2994 2982 3011 3068 3221 3304 3515 3823 3737 3604 3432 3140 2982 2786 2785 2714 2711 2669 2722 2707 2641 2679 2813 2777 2878 3022 3084 3004 3029 2962 2846 2681 2646 2619 2653 2492 2527 2531 2539 2624 2481 2511 2535 2491 2456 2524 2527 2508 2542 2447 2514 2595 2705 2637 2660 2619 2739 2820 2802 2710 2744 2819 2736 2740 2712 2765 2726 2774 2654 2794 2740 2739 2800 2791 2786 2798 2926 2968 3049 3229 3351 3433 3481 3486 3355 3263 3129 2906 2875 2794 2774 2736 2670 2659 2651 2656 2661 2771 2797 2756 2818 2920 2885 2849 2713 2668 2646 2634 2590 2555 2525 2434 2547 2437 2467 2526 2501 2407 2393 2494 2413 2496 2391 2372 2449 2452 2545 2374 2374 2467 2442 2447 2399 2347 2363 2424 2368 2480 2432 2477 2380 2472 2346 2519 2478 2553 2643 2547 2498 2522 2610 2604 2492 2563 2653 2659 2477 2556 2510 2537 2483 2430 2428 2391 2460 2585 2566 2541 2520 2554 2513 2485 2462 2450 2585 2620 2540 2600 2510 2469 2550 2523 2491 2558 2497 2409 2457 2474 2516 2492 2411 2461 2462 2422 2379 2457 2489 2465 2458 2666 2544 2621 2698 2681 2711 2661 2742 2854 2820 2963 2888 2960 3009 3071 2955 3132 3226 3181 3112 3197 3106 3188 3186 3206 3292 3563 3540 3606 3880 3933 4082 4252 4492 4390 4330 4314 4245 4029 3701 3736 3573 3346 3417 3373 3341 3394 3337 3209 3300 3207 3176 3249 3388 3234 3322 3370 3171 3011 2965 2863 2802 2817 2815 2747 2667 2617 2635 2652 2625 2645 2621 2590 2618 2480 2449 2542 2463 2482 2622 2561 2615 2663 2671 2655 2693 2861 3044 3022 3145 3090 3089 3037 2892 2892 2813 2828 2633 2592 2558 2643 2558 2568 2652 2628 2629 2729 2728 2769 2721 2733 2773 2786 2781 2674 2752 2667 2708 2696 2707 2673 2736 2775 2840 2992 2900 3144 3261 3377 3235 3389 3242 3069 3027 3000 2851 2792 2817 2791 2786 2745 2605 2626 2774 2685 2731 2939 2905 2910 2894 2926 2913 2782 2843 2771 2831 2831 2779 2881 2852 2805 3020 3007 3152 3367 3337 3567 3566 3555 3457 3369 3318 3309 3022 3083 2866 2779 2726 2665 2790 2710 2844 2781 2882 2881 2873 2904 3000 3022 3070 3050 3056 2910 2889 2839 2852 2780 2810 2783 2813 2922 2945 2994 3149 3400 3413 3558 3612 3529 3382 3277 3159 3075 2976 2953 2868 2777 2833 2833 2764 2786 2840 2716 2766 2936 2913 2933 3113 3125 3088 2986 2905 2916 2922 3076 3098 3124 3228 3392 3502 3626 3770 3770 3691 3862 3636 3647 3453 3233 3260 3214 2975 3018 3011 2983 2994 3030 3098 3206 3171 3173 3205 3244 3185 3207 3197 3129 3094 3039 2818 2848 2691 2722 2794 2701 2736 2644 2643 2677 2619 2770 2598 2580 2707 2639 2513 2563 2599 2518 2533 2632 2663 2616 2663 2752 2820 2846 3019 3080 3121 3228 3319 3230 3123 3151 3003 3077 2816 2797 2705 2669 2765 2692 2725 2704 2724 2812 2735 2749 2885 2849 2863 2891 2957 2995 2891 2802 2816 2750 2688 2803 2868 2772 2786 2810 2997 2898 2885 2815 2694 2719 2753 2679 2511 2590 2553 2624 2691 2588 2601 2599 2570 2606 2760 2710 2798 2811 2847 2984 2905 3026 3055 3247 3460 3716 3709 3615 3470 3276 3328 3099 3100 3065 2951 2948 2917 2959 3057 3123 3174 3216 3296 3515 3593 3817 3753 3854 3687 3707 3651 3520 3382 3447 3120 3124 3225 3068 3122 3069 2975 2952 2996 2905 3062 3091 3116 3178 3103 3212 3230 3227 3338 3467 3513 3466 3409 3341 3314 3050 3033 2841 2808 2723 2811 2741 2783 2808 2808 2812 2954 2833 2821 2997 2892 3101 3070 2908 3032 3028 2995 2845 2885 2934 2837 3002 3023 3153 3116 3098 3218 3048 3163 2958 2974 2871 2855 2876 2814 2748 2699 2830 2928 2793 2904 3060 3172 3291 3320 3570 3631 3701 3647 3739 3641 3689 3649 3517 3351 3307 3139 3004 2951 2803 2830 2900 2889 2879 2898 3017 3086 3184 3319 3332 3388 3572 3759 3900 3806 4040 4192 4433 4264 4166 4018 3738 3546 3348 3204 3199 3097 2939 2878 2861 2887 2898 2865 2786 2960 2973 3083 3257 3279 3378 3523 3330 3342 3258 3082 3106 2778 2957 2829 2696 2725 2748 2727 2698 2691 2740 2765 2759 2707 2679 2877 2814 2944 3023 2865 2909 2979 2938 2979 2948 2952 2900 2891 2857 2882 2942 2813 2935 2985 2983 2884 3043 2911 3026 3168 3232 3306 3310 3577 3743 3800 3697 3868 3686 3649 3561 3259 3115 3099 3016 2947 2893 2924 2857 2920 2873 2896 2955 2855 2863 2948 2868 2994 3089 3142 3019 2945 2925 2709 2862 2813 2712 2593 2570 2632 2572 2500 2661 2489 2492 2483 2471 2563 2542 2462 2352 2360 2391 2445 2425 2384 2354 2416 2438 2441 2317 2401 2373 2427 2451 2378 2463 2389 2399 2369 2370 2432 2424 2500 2396 2467 2369 2514 2453 2537 2403 2462 2495 2560 2621 2687 2775 2849 2880 2877 3097 3211 3176 3165 3083 2964 2906 2876 2775 2866 2763 2773 2752 2889 2777 2779 2804 2898 2888 2933 2904 2998 3003 2967 3038 2971 2934 2891 2757 2713 2742 2675 2573 2639 2688 2677 2544 2759 2630 2620 2606 2669 2576 2655 2652 2717 2613 2624 2712 2669 2641 2671 2826 2880 2933 2968 3039 3167 3179 3264 3143 3221 3170 3184 3312 3233 3356 3388 3226 3294 3138 2996 2849 2758 2826 2818 2777 2789 2715 2847 2745 2747 2822 2819 2845 2772 2825 2847 2921 2873 2851 2845 2840 2694 2742 2609 2673 2548 2652 2518 2567 2398 2471 2495 2475 2423 2401 2464 2441 2391 2517 2497 2401 2427 2483 2369 2458 2448 2402 2493 2505 2439 2344 2377 2464 2515 2386 2406 2482 2383 2437 2477 2476 2344 2349 2441 2312 2362 2334 2416 2391 2465 2394 2340 2443 2379 2384 2354 2408 2439 2387 2319 2415 2485 2481 2411 2329 2468 2346 2402 2423 2383 2431 2450 2443 2463 2515 2459 2467 2654 2556 2481 2477 2620 2526 2555 2534 2504 2552 2482 2430 2426 2516 2455 2440 2486 2487 2448 2475 2400 2619 2473 2525 2515 2587 2452 2516 2507 2549 2593 2567 2467 2572 2546 2512 2604 2598 2792 2678 2776 2929 2977 3154 3195 3351 3544 3715 3587 3629 3632 3506 3367 3223 3181 3136 3170 3075 3165 3285 3307 3358 3310 3373 3482 3539 3517 3342 3482 3328 3422 3473 3299 3209 3253 3092 3156 2947 2903 2912 2863 2789 2753 2908 2956 2890 2935 2812 2900 2868 2884 2836 2743 2732 2749 2635 2614 2569 2596 2561 2611 2453 2506 2542 2459 2595 2598 2541 2625 2618 2672 2660 2704 2825 2971 2946 3014 3246 3327 3313 3330 3432 3454 3374 3415 3237 3230 3192 3011 2907 2844 2732 2704 2606 2655 2574 2650 2680 2689 2833 2746 2898 2878 2891 2821 2884 2990 2992 2911 2959 2871 2839 2815 2765 2655 2689 2546 2616 2495 2515 2502 2443 2471 2470 2504 2408 2606 2495 2554 2492 2516 2533 2519 2552 2589 2578 2531 2614 2552 2696 2684 2774 2755 2822 2891 2871 2962 2997 2981 3161 3102 3104 3409 3443 3405 3491 3483 3597 3709 3647 3660 3680 3822 3847 3780 3649 3610 3584 3422 3408 3208 3253 3294 3257 3244 3230 3216 3195 3189 3284 3266 3351 3472 3486 3457 3621 3645 3902 3888 4186 4256 4138 4199 4148 4052 4003 3891 4114 3986 3996 4072 4262 4309 4598 4550 4446 4594 4504 4344 4252 4375 4162 4095 4030 3888 3869 3991 3848 3699 3669 3604 3626 3543 3364 3327 3352 3440 3430 3449 3547 3379 3448 3379 3399 3314 3263 3205 3177 3056 3064 2857 3012 2935 2901 2816 2926 2699 2699 2722 2806 2602 2715 2840 2757 2700 2874 2821 2955 2880 3116 3203 3333 3371 3381 3344 3107 2976 2885 2856 2867 2969 2811 2803 2879 2925 2803 2822</intensities>
			</dataPoints>
			<nonAmbientPoints type="Temperature" unit="K">
[...]
			</nonAmbientPoints>
		</scan>
	</xrdMeasurement>
</xrdMeasurements>