File: powder_X-ray_diffraction/variable-temperature_experiments/NaTaO2F2/raw_data/25°C.xrdml
<?xml version="1.0" encoding="UTF-8"?>
<xrdMeasurements xmlns="http://www.xrdml.com/XRDMeasurement/1.7" xmlns:xsi="http://www.w3.org/2001/XMLSchema-instance" xsi:schemaLocation="http://www.xrdml.com/XRDMeasurement/1.7 http://www.xrdml.com/XRDMeasurement/1.7/XRDMeasurement.xsd" status="Completed">
	<comment>
		<entry>Configuration=XRK900, Owner=User-1, Creation date=12/01/2015 16:52:44</entry>
		<entry>Goniometer=Theta/Theta; Minimum step size 2Theta:0.0001; Minimum step size Omega:0.0001</entry>
		<entry>Sample stage=AP XRK-900 with z-axis; Minimum step size Z:0.001</entry>
		<entry>Diffractometer system=EMPYREAN</entry>
		<entry>Measurement program=C:\PANalytical\Data Collector\Programs\Gwen\NaTaO2F2\NaTaO2F2-Lent.xrdmp, Identifier={FF50B583-C5FF-42DA-A01D-A1FB659EF29A}</entry>
		<entry>Batch program=C:\PANalytical\Data Collector\Programs\Gwen\NaTaO2F2\Thermodiff-Ouail.xrdmp, Identifier={5D65A6B1-42FC-480C-9FBB-D7D88D55EA08}</entry>
	</comment>
	<sample type="To be analyzed">
		<id></id>
		<name></name>
		<preparedBy></preparedBy>
	</sample>
	<xrdMeasurement measurementType="Scan" status="Completed" sampleMode="Reflection">
		<comment>
			<entry>PHD Lower Level = 4.02 (keV), PHD Upper Level = 12.07 (keV)</entry>
		</comment>
		<usedWavelength intended="K-Alpha 1">
			<kAlpha1 unit="Angstrom">1.5405980</kAlpha1>
			<kAlpha2 unit="Angstrom">1.5444260</kAlpha2>
			<kBeta unit="Angstrom">1.3922500</kBeta>
			<ratioKAlpha2KAlpha1>0.5000</ratioKAlpha2KAlpha1>
		</usedWavelength>
		<incidentBeamPath>
			<radius unit="mm">240.00</radius>
			<xRayTube id="1010048" name="Empyrean Cu LFF HR (9430 033 7310x) DK434948">
				<tension unit="kV">45.0</tension>
				<current unit="mA">30.0</current>
				<anodeMaterial>Cu</anodeMaterial>
				<focus type="Line">
					<length unit="mm">12.0</length>
					<width unit="mm">0.4</width>
					<takeOffAngle unit="deg">6.0</takeOffAngle>
				</focus>
			</xRayTube>
			<sollerSlit id="21010001" name="Soller slits 0.02 rad.">
				<opening unit="rad">0.0200</opening>
			</sollerSlit>
			<mask id="22030010" name="Fixed mask 20 mm">
				<width unit="mm">20.00</width>
			</mask>
			<antiScatterSlit id="22010003" name="Fixed slit 1Â°" xsi:type="fixedAntiScatterSlitType">
				<height unit="mm">1.52</height>
			</antiScatterSlit>
			<divergenceSlit id="22010012" name="Programmable divergence slit" xsi:type="fixedDivergenceSlitType">
				<distanceToSample unit="mm">140.00</distanceToSample>
				<angle unit="deg">0.5</angle>
			</divergenceSlit>
		</incidentBeamPath>
		<diffractedBeamPath>
			<radius unit="mm">240.00</radius>
			<antiScatterSlit id="22090010" name="AS slit 8.0 mm (PIXcel)" xsi:type="fixedAntiScatterSlitType">
				<height unit="mm">8.00</height>
			</antiScatterSlit>
			<sollerSlit id="21010001" name="Soller slits 0.02 rad.">
				<opening unit="rad">0.0200</opening>
			</sollerSlit>
			<filter id="20030001" name="Large beta-filter Nickel">
				<material>Ni</material>
				<thickness unit="mm">0.020</thickness>
			</filter>
			<detector id="7010019" name="PIXcel1D-Medipix3 detector" xsi:type="rtmsDetectorType">
				<phd unit="%">
					<lowerLevel>25.0</lowerLevel>
					<upperLevel>75.0</upperLevel>
				</phd>
				<mode>Scanning</mode>
				<activeLength unit="deg">3.3482</activeLength>
			</detector>
		</diffractedBeamPath>
		<scan appendNumber="0" mode="Continuous" scanAxis="Gonio" status="Completed">
			<header>
				<startTimeStamp>2023-01-20T17:16:18+01:00</startTimeStamp>
				<endTimeStamp>2023-01-20T20:16:44+01:00</endTimeStamp>
				<author>
					<name>User</name>
				</author>
				<source>
					<applicationSoftware version="5.5a">Data Collector</applicationSoftware>
					<instrumentControlSoftware version="8.2  20201204">EMPYREAN</instrumentControlSoftware>
					<instrumentID>0000000011159748</instrumentID>
				</source>
			</header>
			<dataPoints>
				<positions axis="2Theta" unit="deg">
					<startPosition>9.99846514</startPosition>
					<endPosition>99.99342261</endPosition>
				</positions>
				<positions axis="Omega" unit="deg">
					<startPosition>4.99923257</startPosition>
					<endPosition>49.99671130</endPosition>
				</positions>
				<positions axis="Z" unit="mm">
					<commonPosition>8.846</commonPosition>
				</positions>
				<commonCountingTime unit="seconds">386.070</commonCountingTime>
				<intensities unit="counts">7605 7619 7730 7554 7644 7647 7383 7419 7545 7280 7319 7245 7268 7342 7255 7292 7439 7336 7336 7307 7438 7266 7371 7371 7178 7552 7371 7446 7250 7287 7291 7424 7218 7151 7214 7102 7301 7208 7349 7201 7274 7206 7144 7342 7272 7213 7206 7223 7236 7208 7295 7267 7331 7268 7209 7137 7429 7296 7347 7358 7261 7401 7223 7384 7410 7452 7567 7536 7571 7680 7717 8019 7906 8186 8516 8921 9638 10393 11527 13217 16360 21053 26845 33349 42323 49399 52633 49443 42466 34547 27193 21143 16887 12624 10348 9037 8280 7911 7727 7654 7420 7370 7295 7265 7089 7021 7049 7012 7058 7023 6958 6986 6936 6849 6888 7043 6851 6757 6659 6838 6893 6937 6826 7014 6811 6844 6920 6835 6857 6768 6730 6835 6861 6746 6554 6524 6571 6778 6897 6827 6774 6635 6756 6595 6718 6623 6657 6630 6596 6635 6497 6688 6676 6864 6615 6570 6528 6538 6537 6382 6431 6640 6474 6465 6441 6479 6654 6442 6477 6507 6452 6449 6426 6427 6258 6464 6428 6433 6326 6587 6375 6513 6485 6376 6490 6444 6286 6381 6428 6517 6424 6440 6332 6352 6316 6392 6240 6315 6357 6307 6275 6356 6258 6500 6209 6162 6434 6257 6241 6333 6218 6243 6235 6305 6240 6224 6333 6336 6148 6197 6181 6246 6137 6135 6162 6190 6241 6189 6071 6063 6362 6013 6147 6017 6185 6165 6132 6167 6104 6079 6137 6071 6045 6027 6253 6103 6032 6107 6047 6189 6000 5997 5961 5988 5971 6001 6087 5988 6046 6246 5941 6092 6057 6048 6068 6182 6026 5823 6097 6099 6077 6122 6034 5904 6001 5919 5817 6006 5871 5815 6075 5969 5861 5788 5907 5836 5867 5854 5811 5842 5866 5920 5832 5918 5900 5806 5909 5816 5913 5805 5838 5662 5806 5752 5848 5824 5724 5857 5690 5858 5740 5796 5897 5714 5843 5679 5631 5626 5711 5600 5633 5708 5785 5708 5644 5728 5659 5762 5763 5670 5458 5662 5663 5757 5644 5578 5722 5549 5649 5540 5668 5592 5735 5601 5662 5774 5547 5696 5639 5690 5610 5528 5636 5668 5489 5505 5486 5561 5540 5589 5449 5549 5614 5577 5672 5596 5594 5431 5555 5556 5576 5413 5500 5661 5514 5452 5443 5531 5539 5552 5517 5390 5556 5499 5499 5461 5641 5437 5475 5510 5536 5352 5340 5571 5430 5540 5395 5468 5379 5541 5433 5447 5485 5427 5401 5314 5481 5402 5475 5401 5282 5275 5373 5365 5371 5295 5474 5275 5444 5436 5322 5479 5296 5157 5262 5461 5364 5305 5470 5309 5269 5249 5344 5303 5242 5451 5252 5398 5377 5442 5236 5289 5260 5234 5250 5216 5280 5224 5312 5287 5328 5262 5289 5322 5361 5238 5258 5168 5207 5257 5319 5175 5352 5284 5385 5316 5350 5291 5244 5258 5219 5418 5349 5252 5371 5281 5303 5418 5307 5414 5352 5365 5242 5397 5299 5354 5340 5368 5425 5600 5353 5440 5300 5453 5343 5418 5452 5324 5263 5228 5099 5236 5138 5234 5088 5089 5237 5159 5094 5119 5084 5083 5152 5039 5102 5153 5106 5080 5082 5131 5062 5077 5137 5075 5030 5081 5120 4984 5128 4995 5037 5061 4953 5125 5038 5132 4999 5034 4904 4943 5016 5051 5036 5002 4945 4867 5117 5147 5039 5046 5015 5046 5103 5083 5200 5259 5193 5144 5231 5200 5170 5035 5074 4969 5103 5024 4956 4821 4936 4900 4822 4937 4951 4911 4914 4961 4836 5060 4996 4811 4906 4869 4855 4865 5028 4910 4937 4988 4939 4817 4827 4888 4965 5119 5093 5112 5106 5107 5069 4948 5015 4856 4937 4957 4817 4701 4777 4754 4796 4956 4802 4754 4688 4727 4777 4718 4860 4673 4714 4594 4839 4770 4679 4826 4787 4693 4741 4715 4818 4716 4685 4631 4609 4762 4734 4647 4480 4812 4628 4600 4659 4612 4590 4582 4731 4652 4770 4709 4683 4631 4631 4727 4785 4765 4691 4686 4809 4818 4681 4836 4751 4712 4682 4785 4808 4683 4744 4598 4690 4616 4567 4645 4614 4609 4567 4630 4532 4389 4555 4504 4514 4715 4467 4528 4519 4654 4627 4557 4671 4686 4823 4836 4841 4787 4862 4994 4987 5035 5030 4887 4736 4893 5013 4942 4961 4974 4949 4995 4913 5040 4903 4805 4973 4949 4869 5062 4922 4974 4977 5011 5212 5358 5462 5356 5524 5813 5814 6071 6299 6540 6954 7320 8228 9565 11571 14515 19067 26425 37112 53896 75758 97967 112485 114569 108212 98674 85988 69311 52454 37513 26390 19174 14177 10849 8695 7575 6785 6242 6153 5892 5563 5355 5166 5195 5100 4912 4927 5060 4993 4742 4885 4702 4665 4779 4647 4777 4781 4830 4859 4760 5025 4985 4956 4829 4926 4897 4747 4690 4570 4636 4689 4634 4514 4667 4448 4427 4568 4455 4444 4514 4436 4513 4488 4644 4454 4468 4396 4501 4398 4418 4358 4359 4427 4423 4307 4414 4205 4461 4482 4423 4314 4346 4381 4374 4357 4318 4258 4381 4281 4331 4307 4278 4378 4277 4314 4409 4268 4380 4365 4294 4196 4260 4248 4274 4369 4323 4346 4263 4246 4321 4250 4202 4397 4166 4191 4182 4190 4200 4226 4246 4156 4318 4279 4338 4284 4275 4231 4141 4200 4184 4175 4168 4186 4274 4176 4219 4197 4151 4168 4152 4143 4127 4085 4157 4202 4237 4015 4314 4102 4140 4200 4261 4212 4219 4137 4178 4301 4338 4231 4235 4162 4317 4317 4343 4369 4381 4494 4407 4553 4591 4477 4375 4382 4355 4258 4191 4265 4193 4254 4195 4168 4312 4215 4226 4182 4275 4301 4418 4150 4265 4250 4303 4322 4299 4454 4689 4792 5083 5633 6411 7902 9918 12884 16861 20060 20211 19254 17066 16191 14738 11996 9243 7443 6331 5729 4912 4535 4383 4374 4289 4251 4106 4165 4098 4126 4143 4101 4211 4043 4141 4191 4175 4040 4203 4081 4160 4112 4251 4263 4083 4072 4045 3969 3853 3975 4071 3886 3959 3910 3964 3954 4019 3959 3976 4019 3895 3967 3884 3973 3971 3961 4031 3867 4008 3971 3955 3828 3876 4047 3881 3882 3739 3836 4022 3890 3970 3893 4013 4040 3987 4012 4027 4081 4040 3939 4011 3980 3899 4013 3948 3968 4074 3987 4018 3983 3962 4134 4115 4002 4161 4129 4121 4276 4167 4082 4126 4112 4158 4048 3995 4135 4113 4231 4209 4197 4176 4222 4233 4125 4169 4318 4403 4269 4476 4567 4659 4701 4819 4821 4810 4961 4956 5183 5424 5360 5947 6775 8205 10527 14530 20255 27606 35993 43909 46485 43263 38606 34287 31490 27782 22310 16743 12721 10491 10178 10341 11722 15135 21313 28992 37433 43326 45766 45459 41771 38196 34499 28155 22969 17356 13455 10331 7657 6167 5271 5038 4808 4670 4567 4413 4407 4096 4094 4035 4073 3952 4023 4107 3934 3962 4047 3946 3907 3906 3850 3954 3876 3950 4146 3971 3814 3851 3771 3956 3917 4017 4061 3977 4105 3980 4001 4002 3854 3973 3846 3770 3773 3881 3779 3822 3786 3852 3730 3889 3630 3800 3776 3769 3738 3754 3773 3806 3684 3629 3753 3665 3777 3761 3581 3823 3753 3644 3672 3801 3788 3675 3752 3781 3731 3609 3701 3713 3689 3739 3809 3635 3585 3564 3706 3617 3656 3652 3659 3621 3669 3811 3667 3696 3579 3670 3785 3665 3635 3672 3699 3698 3620 3691 3837 3811 3883 3850 3996 4089 4089 4168 4056 4115 4031 3968 3907 3916 3831 3757 3833 3733 3671 3727 3670 3629 3546 3707 3662 3621 3577 3574 3615 3674 3711 3597 3767 3685 3664 3762 3575 3654 3550 3626 3614 3513 3485 3616 3516 3640 3543 3628 3649 3582 3701 3606 3572 3641 3610 3627 3477 3504 3538 3545 3617 3626 3612 3600 3641 3719 3646 3672 3759 3755 3678 3759 3792 3739 3797 3702 3731 3694 3743 3850 3737 3738 3649 3695 3768 3653 3654 3738 3763 3802 3598 3612 3694 3788 3707 3712 3747 3776 3769 3733 3727 3878 3776 3703 3812 3840 3845 3881 3853 3882 3751 3872 3827 4042 3940 4142 4223 4280 4439 4521 4595 4716 4940 5091 5281 5578 5656 6544 6979 7813 8712 10364 13212 17151 23866 34875 50021 66176 77566 79502 73138 65325 61140 56993 51173 43076 33316 25579 18628 13530 10489 8309 7315 6304 5803 5378 4924 4623 4506 4297 4343 3947 3958 4022 3797 3870 3919 3814 3670 3738 3860 3847 3797 3794 3869 3709 3718 3851 3720 3741 3787 3874 4046 4136 4250 4038 4111 3964 4046 3953 3849 3975 3788 3628 3715 3681 3780 3676 3655 3670 3691 3583 3628 3658 3651 3636 3653 3742 3663 3606 3586 3430 3482 3591 3598 3637 3587 3592 3671 3668 3733 3645 3572 3677 3517 3665 3631 3571 3653 3671 3562 3774 3807 3882 3808 3769 3977 3790 4032 4014 4090 4332 4474 4538 4487 4955 5227 5793 6981 9051 12774 18438 25696 32449 36624 34568 28887 25349 23901 23647 22455 19250 15226 12999 11606 11101 12268 14511 16718 17872 18391 17141 15672 13757 12589 11832 10611 9313 7633 6221 5155 4336 4136 3838 3745 3677 3497 3617 3697 3632 3579 3528 3494 3424 3492 3551 3423 3436 3432 3420 3433 3371 3373 3477 3375 3413 3455 3446 3414 3345 3411 3375 3368 3327 3494 3391 3342 3473 3420 3290 3349 3417 3377 3243 3323 3263 3252 3156 3334 3253 3228 3320 3370 3233 3181 3307 3411 3288 3271 3219 3342 3374 3388 3424 3277 3348 3318 3361 3365 3331 3260 3214 3356 3334 3228 3272 3274 3317 3250 3235 3327 3227 3262 3308 3278 3285 3210 3186 3219 3154 3151 3109 3225 3105 3252 3232 3177 3110 3259 3181 3134 3232 3147 3200 3184 3243 3184 3207 3166 3176 3152 3198 3139 3167 3232 3242 3130 3239 3181 3184 3215 3159 3212 3230 3288 3103 3087 3101 3088 3151 3111 3188 3300 3252 3180 3188 3191 3165 3081 3093 3095 3000 3132 3270 3127 3138 3109 3182 3226 3179 3135 3074 3150 3133 3175 3226 3199 3235 3228 3201 3118 3183 3100 3229 3179 3123 3105 3178 3097 3071 3145 3215 3219 3121 3161 3161 3135 3171 3124 3169 3095 3159 3152 3088 3096 3109 3169 3105 3133 3085 3167 3229 3230 3265 3234 3269 3116 3311 3315 3279 3220 3347 3228 3217 3246 3195 3212 3127 3286 3295 3265 3262 3187 3202 3237 3160 3155 3187 3258 3168 3331 3200 3151 3285 3413 3372 3416 3434 3451 3438 3549 3754 3570 3761 3793 3897 3925 4052 4588 5414 7181 10171 15291 20736 22905 20760 16437 12996 11985 12766 14105 12903 10875 8205 6400 5211 4628 4317 4209 4067 3911 4062 4022 4218 4252 4305 4386 4634 4909 5059 5754 6545 8584 11881 17527 24414 31280 34878 32855 28701 25288 21926 21168 21045 19978 17415 14243 11094 8268 6378 5354 4822 4528 4319 4142 4055 3966 4029 3990 3909 4025 4098 4227 4219 4237 4474 4604 4661 4986 5272 5938 6644 7938 9992 13253 17260 21961 26507 30142 32512 32838 33200 33535 31960 28446 25233 22273 19793 17447 15663 13115 10118 7799 6449 5459 4677 4230 3961 3724 3751 3656 3537 3445 3378 3443 3451 3374 3236 3311 3277 3249 3238 3216 3139 3176 3189 3137 3085 3161 3157 3105 3149 3137 3268 3172 3278 3170 3212 3137 3195 3200 3262 3183 3172 3312 3354 3388 3286 3302 3408 3365 3470 3552 3481 3696 3726 4079 4585 5691 7144 9598 12432 13876 13783 11817 9938 8737 8498 8980 8987 8586 7223 5952 4957 4123 3930 3578 3516 3302 3210 3261 3209 3314 3465 3748 3847 3929 3887 3882 3610 3481 3599 3481 3434 3432 3243 3074 3225 3025 3056 3020 3005 3178 3087 2994 2928 2901 2963 2966 3011 2842 2994 2874 3174 2986 2959 2911 2979 2950 3026 2953 2902 2939 2999 2886 2981 2961 2905 2812 2924 2966 2842 2963 2961 2907 2889 2979 2989 2977 3000 2920 2953 3096 2979 2975 2957 2998 2984 2928 2852 2941 2865 2897 2910 2865 2974 2851 2921 2846 2986 2910 2969 2975 3078 3071 3057 3019 3001 2977 3070 3033 2961 3028 3099 3154 3078 3058 3058 2972 2929 2894 2917 2986 2909 2999 2977 3095 3104 3052 2917 3063 3138 3106 3106 3188 3190 3202 3358 3308 3744 4263 5218 6662 8250 9785 9963 9092 7490 6587 6066 6178 6591 6649 6276 5481 4577 3793 3550 3346 3165 3226 3040 2932 2994 3010 3033 2984 3019 2938 3030 2974 3083 2924 2899 2941 2976 2886 2990 2944 2884 2988 2887 2910 2922 2938 2851 2909 2993 3053 2920 3083 3120 3081 3166 3068 3167 3153 3358 3373 3518 3838 4368 5213 6027 7418 8652 9614 10143 10034 9096 8075 7327 7109 6759 6750 6568 5957 5326 4546 3927 3620 3337 3260 3154 3288 3264 3435 3608 3845 3906 3685 3564 3450 3270 3345 3241 3448 3324 3218 3072 3014 2904 2819 2902 2775 2856 2753 2817 2770 2836 2805 2749 2769 2763 2657 2690 2690 2749 2808 2738 2659 2748 2799 2810 2740 2826 2751 2661 2637 2774 2779 2778 2697 2672 2698 2716 2762 2692 2679 2711 2768 2822 2765 2717 2758 2744 2795 2800 2714 2898 2707 2744 2709 2688 2757 2778 2705 2676 2671 2706 2661 2751 2731 2776 2710 2698 2754 2738 2686 2725 2761 2722 2727 2653 2707 2640 2714 2759 2808 2747 2765 2730 2723 2817 2723 2676 2707 2643 2657 2683 2730 2680 2729 2772 2810 2766 2737 2742 2689 2715 2637 2698 2735 2626 2580 2634 2640 2761 2710 2747 2702 2647 2744 2701 2740 2765 2689 2732 2694 2741 2676 2788 2750 2674 2701 2859 2793 2782 2949 2706 2762 2796 2812 2844 2901 3039 3194 3478 4039 4318 4980 5254 5272 5098 4786 4460 4130 4080 4201 4113 4076 4052 3740 3491 3354 3260 3021 3099 3086 3126 3154 3244 3274 3528 3766 4063 4778 5659 6515 7340 7092 6609 5969 5476 5215 5254 5437 5647 5551 5418 5176 5288 5997 7004 8477 9450 9719 8760 7194 6288 5720 5732 6185 6489 6270 5774 5082 4172 3777 3555 3269 3177 3053 2925 2975 2887 2825 2914 2880 2851 2850 2912 2870 2795 2739 2774 2749 2898 2836 2781 2857 2875 2874 2861 2871 2992 2885 3126 3027 3140 3134 3247 3261 3468 3506 3564 3860 4263 4678 5772 6639 7824 9017 10360 10785 10681 9547 8720 8040 8088 9348 11415 13924 15767 15853 14274 11881 9714 8030 7754 8839 10555 12330 13616 14741 14769 14171 12311 10059 8362 7337 7198 7508 8096 8002 7321 6275 5290 4341 3935 3492 3103 3106 2973 2948 2915 2841 2728 2934 2868 2739 2827 2790 2823 2835 2756 2761 2718 2814 2668 2685 2795 2730 2691 2673 2609 2540 2550 2662 2628 2669 2590 2672 2758 2679 2669 2548 2625 2612 2704 2659 2723 2644 2687 2754 2561 2709 2497 2623 2682 2584 2578 2652 2737 2606 2691 2684 2669 2622 2655 2581 2663 2654 2630 2624 2718 2702 2764 2627 2665 2637 2678 2623 2617 2662 2630 2556 2574 2572 2617 2710 2591 2603 2606 2618 2677 2603 2585 2700 2641 2593 2646 2723 2679 2740 2724 2680 2616 2751 2731 2593 2601 2667 2591 2665 2735 2733 2577 2594 2643 2660 2627 2775 2560 2735 2737 2706 2606 2695 2623 2655 2603 2739 2623 2549 2700 2674 2681 2577 2616 2540 2593 2684 2603 2645 2608 2658 2668 2782 2667 2747 2768 2844 3015 3221 3303 3416 3475 3504 3348 3075 3083 2968 3078 3099 3142 3068 3066 2856 2893 2704 2664 2621 2661 2673 2605 2792 2616 2629 2568 2573 2662 2645 2627 2631 2661 2678 2640 2495 2622 2638 2645 2637 2682 2603 2596 2582 2587 2581 2674 2622 2613 2539 2723 2720 2780 2870 2969 3030 3133 3077 2964 3090 3214 3381 3559 3859 3711 3722 3401 3158 3190 3041 3175 3150 3129 3046 2974 2960 2853 2827 2871 2757 2693 2806 2889 2808 2821 2810 2888 3042 3077 3294 3519 3773 4208 4785 5460 5797 5752 5530 5117 4616 4267 4137 4054 4206 4345 4374 4064 3925 3566 3222 3050 2924 2973 2768 2790 2698 2774 2663 2686 2606 2531 2675 2647 2586 2638 2552 2651 2615 2548 2665 2547 2636 2554 2594 2477 2536 2636 2514 2636 2693 2525 2642 2564 2660 2601 2573 2587 2590 2625 2613 2593 2617 2647 2726 2672 2702 2828 2898 2810 2890 2874 2853 2791 2986 3059 3037 3221 3366 3694 4569 5796 7766 10289 12267 12255 10339 8037 6101 5116 5127 5536 6495 7455 7553 6831 5439 4359 3606 3184 3008 3032 2954 2868 2774 2759 2706 2676 2749 2743 2735 2667 2723 2720 2710 2704 2685 2712 2761 2808 2791 2810 2926 3055 3182 3667 4440 5395 6712 7495 7403 6352 5258 4465 3908 3910 4202 4928 5103 5209 4810 4103 3622 3275 3040 2991 2846 2810 2747 2737 2733 2679 2719 2629 2552 2639 2703 2626 2656 2645 2732 2647 2697 2649 2690 2583 2514 2773 2624 2663 2680 2681 2702 2604 2664 2641 2671 2637 2747 2625 2680 2687 2754 2890 2779 2819 2870 2808 2825 2939 2953 2870 3069 3189 3369 3522 3880 4325 5086 5824 6838 7837 8876 9135 8563 7446 5912 5426 5006 5086 5482 5689 6031 5771 5292 4574 3781 3579 3184 3122 3172 2911 2886 2871 2891 3024 2982 3011 3104 3155 3205 3230 3366 3213 3389 3388 3466 3499 3613 3753 3809 4156 4382 4584 5061 5785 6808 8180 10392 13415 16474 18568 18958 17108 14579 12340 10623 9650 10143 10632 11541 12030 11397 10064 8609 7123 6052 5264 4632 4219 3964 3851 3636 3484 3496 3373 3324 3286 3337 3343 3338 3364 3430 3599 3775 4091 4732 5814 7290 9393 11340 12158 12092 12057 12135 12055 10959 10174 9579 9380 8921 8616 8239 7938 7751 7327 6629 6014 5369 4867 4231 3881 3746 3757 3846 3950 4372 4961 5935 7256 9280 11531 12893 12740 11171 9340 7729 6551 6196 6271 6957 7730 8196 7750 6987 5962 4979 4277 3906 3568 3392 3154 3126 3058 2967 2891 2924 2822 2835 2802 2826 2871 2808 2877 2699 2736 2754 2788 2771 2902 2846 2889 3020 3185 3507 3475 3385 3309 3123 3007 2919 3006 3104 3112 3293 3285 3276 3303 3317 3250 3257 3153 3099 3267 3212 3205 3087 3082 3106 3109 3089 3160 3143 3134 3247 3276 3277 3196 3242 3222 3424 3362 3575 3722 3878 4063 4408 5019 5756 7058 8863 11757 15014 17494 18770 18127 15741 13088 10856 9948 10077 10556 11724 12805 13138 12499 10883 9084 7581 6268 5690 5117 4757 4639 4525 4317 3963 3744 3487 3350 3302 3163 3087 3155 3154 3183 3305 3315 3229 3309 3366 3282 3354 3474 3714 3909 4282 4670 5263 5972 7092 8283 9472 10288 10427 9843 8617 7307 6409 6060 6090 6156 6596 6730 6664 6539 5926 5105 4381 3857 3550 3341 3200 3107 2943 2889 2867 2828 2805 2913 2850 2805 2854 2704 2680 2780 2716 2728 2759 2788 2680 2746 2627 2649 2641 2685 2790 2718 2698 2706 2769 2800 2728 2888 2940 2893 2966 2970 2961 3096 3152 3210 3126 3410 3346 3588 3715 3914 4523 5228 6575 7789 9116 9210 8052 6760 5493 4739 4219 4234 4572 5122 5708 5995 5751 5209 4602 4252 3948 3938 3866 3757 3511 3312 3187 3044 2957 2930 2971 3097 3217 3121 3087 2931 2877 2688 2736 2663 2675 2659 2749 2701 2615 2615 2683 2712 2657 2697 2717 2699 2678 2714 2704 2696 2778 2693 2812 2859 2765 2873 2859 2980 2899 2944 2967 3014 3043 3058 3316 3487 3776 4196 5200 6335 7736 8913 9885 10684 10975 10557 9555 8092 6477 5784 5602 5861 6229 6617 6844 7014 6528 5874 5047 4132 3732 3266 3153 2970 2910 2911 2896 2973 2865 2879 2923 2943 3027 3231 3352 3563 4005 4310 4648 5063 5148 5209 5221 5423 5288 5096 4556 4256 4047 3912 4117 3901 3887 3902 4045 3785 3605 3315 3140 2949 2829 2736 2744 2726 2707 2708 2693 2802 2859 2934 3030 3209 3527 3795 4094 4490 4462 4188 3966 3668 3391 3201 3070 3218 3350 3412 3506 3514 3597 3269 3112 2881 2890 2900 2801 2776 2793 2785 2713 2659 2582 2588 2643 2544 2591 2667 2594 2644 2614 2581 2647 2635 2599 2535 2595 2489 2524 2593 2666 2479 2549 2454 2480 2547 2549 2545 2573 2580 2558 2481 2503 2557 2553 2544 2645 2489 2565 2544 2558 2562 2645 2581 2686 2707 2587 2659 2819 2731 2782 2868 2857 2792 2878 2782 2904 2794 2730 2711 2627 2683 2751 2668 2526 2694 2710 2719 2729 2714 2615 2557 2592 2587 2570 2579 2522 2548 2603 2499 2580 2576 2545 2586 2608 2454 2527 2623 2581 2548 2604 2443 2606 2624 2511 2558 2591 2483 2574 2646 2575 2550 2537 2560 2631 2561 2581 2633 2619 2588 2562 2704 2559 2643 2672 2740 2779 2686 2840 2782 2833 2855 2730 2953 2943 3000 3105 3198 3298 3562 3758 3931 4514 5187 6410 7768 9250 10475 11108 10654 9726 8253 6884 6200 5804 5624 5968 6429 6963 7344 7397 6948 6189 5226 4646 4194 3909 3648 3555 3406 3464 3579 3523 3518 3652 3537 3535 3373 3115 3110 2997 3100 3213 3090 3178 3350 3277 3315 3370 3209 3203 3265 3335 3536 3866 4443 5074 6216 7751 9094 10268 10970 10578 9737 8512 6818 5889 5447 5453 5899 6753 7739 8662 9430 9586 9117 8203 6940 5766 4977 4956 4944 5147 5551 5851 6059 5741 5467 5017 4455 4090 3848 3746 3665 3834 3854 3787 3608 3453 3339 3059 3091 2992 2926 2868 2867 2783 2834 2895 2861 2824 2884 2960 2887 2817 2988 2996 3013 3026 3132 3279 3259 3432 3625 4079 4164 4765 5414 6347 7381 7980 8769 9287 9708 9791 9877 9625 9291 8657 7910 7386 7152 7499 7852 8429 9108 9605 9542 9111 8308 7145 6031 5219 4845 4440 4513 4423 4590 4702 4648 4485 4199 3965 3670 3453 3289 3295 3129 3165 3084 3083 3065 3118 3053 3194 3238 3387 3391 3654 3968 4295 4926 5731 6672 7708 8121 8006 7063 6193 5406 4843 4636 4520 4667 4982 5457 6143 6442 6499 5980 5111 4513 4038 3665 3524 3394 3459 3503 3594 3829 3910 3935 3719 3449 3485 3160 2894 2969 2950 2802 2983 3040 3061 3204 3128 3062 3019 2926 2960 2939 2935 2970 2980 2973 3204 3257 3296 3489 3551 3766 4030 4259 4647 5224 5876 6637 7257 7854 8347 8264 7512 6971 6336 5902 5796 5887 6593 7502 8511 10090 11251 11682 11521 10316 8688 6990 5799 5327 4784 4851 5037 5633 5973 6527 6606 6161 5678 5165 4715 4343 4448 4534 4900 5693 6362 7413 8305 9121 9379 9156 8243 7032 5842 5124 4873 4815 4922 5303 5699 5996 6220 6085 5782 5055 4572 4044 3842 3541 3525 3316 3288 3218 3251 3352 3421 3510 3605 3917 4255 4861 5777 6712 7731 8683 9517 9914 10225 10431 10004 9630 9531 9684 10699 12288 13465 13781 12977 11547 10123 9054 8238 7518 7062 6644 6539 7019 7156 7290 6806 6113 5222 4637 3920 3598 3410 3315 3122 2980 3007 2939 2917 2770 2869 2764 2791 2721 2677 2731 2619 2702 2661 2607 2594 2721 2745 2734 2746 2657 2709 2719 2769 2775 2839 2836 2736 2906 2958 2856 2897 2964 3183 3283 3390 3528 3781 4220 4732 5360 6443 7576 8852 9781 9684 9095 8080 7217 6643 6362 6604 7157 8133 9472 10503 11164 11488 10469 9792 8225 7045 6110 5639 5648 5701 6080 6620 6942 7125 7130 6863 6664 6114 5954 5473 5296 5264 5148 5282 5479 5539 5848 5905 5789 5662 5176 4716 4278 4066 3851 3834 3700 3803 3817 3692 3775 3641 3649 3465 3207 2968 2704 2642 2599 2624 2544 2590 2478 2519 2462 2470 2550 2572 2567 2477 2521 2442 2491 2456 2452 2479 2441 2449 2502 2491 2396 2520 2448 2482 2399 2484 2454 2413 2479 2535 2557 2425 2517 2493 2469 2452 2502 2420 2453 2431 2424 2460 2466 2447 2382 2436 2382 2404 2452 2383 2375 2399 2544 2479 2490 2467 2485 2412 2584 2598 2614 2539 2507 2651 2488 2384 2398 2540 2501 2475 2439 2418 2498 2497 2456 2435 2487 2441 2378 2430 2387 2386 2384 2427 2302 2396 2404 2442 2368 2381 2335 2403 2426 2400 2395 2477 2436 2355 2261 2374 2432 2446 2391 2382 2372 2381 2319 2307 2383 2459 2398 2339 2422 2427 2336 2377 2340 2375 2392 2364 2383 2398 2332 2286 2339 2375 2358 2357 2311 2464 2453 2346 2402 2404 2403 2348 2315 2358 2372 2426 2289 2393 2404 2435 2359 2393 2405 2390 2428 2471 2528 2491 2412 2480 2531 2558 2616 2681 2840 2972 3160 3245 3484 3779 3913 4200 4138 4088 3666 3457 3263 3081 3061 3023 2960 3031 3031 3232 3298 3219 3342 3063 3069 2877 2893 2703 2661 2535 2660 2613 2582 2599 2655 2744 2753 2721 2974 3055 3290 3491 3698 4200 4483 4790 4912 4952 5065 4874 4702 4502 4309 4268 3868 3652 3748 3730 3702 3832 3809 3787 3773 3683 3601 3322 3247 3023 2759 2678 2689 2589 2446 2528 2504 2477 2389 2487 2448 2434 2399 2361 2384 2405 2390 2373 2255 2304 2264 2381 2320 2294 2469 2406 2357 2327 2406 2288 2358 2406 2440 2422 2449 2436 2339 2409 2503 2422 2460 2488 2588 2581 2591 2530 2591 2602 2486 2591 2550 2498 2550 2660 2607 2657 2632 2666 2720 2593 2644 2582 2631 2540 2446 2493 2483 2437 2439 2512 2416 2382 2424 2518 2376 2424 2431 2387 2325 2351 2320 2350 2343 2357 2323 2320 2266 2264 2265 2314 2307 2280 2304 2287 2304 2300 2379 2314 2312 2401 2281 2304 2339 2367 2352 2328 2228 2364 2296 2263 2289 2271 2406 2309 2344 2295 2349 2352 2332 2299 2275 2234 2379 2293 2349 2316 2192 2327 2288 2215 2219 2227 2250 2277 2296 2276 2337 2278 2252 2285 2285 2282 2343 2313 2331 2350 2313 2276 2309 2343 2397 2389 2288 2388 2399 2579 2512 2553 2502 2392 2478 2420 2433 2468 2351 2423 2479 2546 2512 2645 2556 2488 2567 2526 2381 2344 2374 2454 2311 2405 2336 2353 2438 2361 2329 2343 2336 2290 2313 2269 2275 2300 2212 2401 2349 2193 2263 2247 2279 2250 2281 2320 2307 2416 2333 2334 2208 2236 2308 2267 2278 2260 2208 2322 2300 2268 2266 2280 2260 2311 2253 2347 2265 2293 2336 2253 2341 2227 2317 2354 2280 2312 2269 2337 2228 2254 2329 2394 2273 2307 2288 2341 2298 2333 2386 2366 2306 2353 2400 2340 2318 2437 2385 2524 2332 2525 2542 2611 2789 2937 3308 3385 3546 3449 3251 2978 2915 2733 2629 2600 2585 2506 2660 2656 2795 2816 2884 2907 2932 2722 2677 2656 2460 2422 2461 2471 2493 2522 2516 2465 2558 2616 2695 2689 2729 2743 2687 2577 2666 2529 2575 2620 2612 2685 2674 2704 2627 2833 2712 2659 2650 2628 2570 2528 2522 2531 2565 2531 2516 2524 2487 2624 2527 2642 2589 2688 2828 3224 3352 3817 4528 5173 5411 5191 4793 3937 3471 3203 3022 2865 2870 2788 2832 3146 3323 3641 3801 3931 3901 3615 3402 3083 2868 2861 2899 3077 3541 3759 3928 3826 3568 3241 3009 2880 2757 2601 2636 2691 2669 2751 2851 2994 3200 3268 3140 3051 2895 2731 2909 2652 2762 2628 2804 2855 2895 3023 3077 3247 3358 3498 3654 3632 3636 3701 3749 3823 3787 3683 3453 3441 3386 3638 3836 4111 4714 5084 5893 6314 6831 7144 7037 6394 5865 5076 4595 4168 3937 3944 4014 4141 4487 4699 4805 4934 5164 4781 4636 4385 4207 3996 3840 4019 4159 4429 4555 4595 4537 4492 4071 3874 3602 3581 3640 3785 4031 4409 5009 5566 5916 6012 5824 5346 4935 4324 3840 3477 3467 3247 3325 3336 3366 3531 3735 3999 4078 3946 3900 3714 3455 3380 3167 3010 2889 2792 2693 2704 2773 2661 2691 2683 2719 2783 2946 2878 2836 2884 2727 2779 2761 2660 2676 2611 2681 2793 2849 2830 3085 3144 3141 3283 3652 3621 3816 4060 4155 4098 4164 4399 4396 4259 4323 4542 4686 5047 5506 5853 5929 5457 5087 4598 4037 3975 3732 3660 3598 3583 3443 3537 3662 3789 3927 3875 3944 3708 3347 3144 2909 2999 3106 3043 3109 3375 3770 4114 4039 4030 3864 3317 3248 3030 2885 2815 2700 2694 2842 2887 2911 3033 3162 3253 3414 3332 3188 3124 2950 2885 2845 2808 2795 2845 2840 3048 3087 3097 3276 3360 3389 3378 3401 3519 3446 3310 3265 3171 3090 2905 2816 2846 2824 2838 2936 2767 2926 2958 2810 2830 2830 2844 2736 2682 2600 2650 2473 2481 2613 2455 2484 2475 2491 2408 2410 2422 2462 2551 2459 2439 2448 2464 2487 2478 2459 2525 2627 2721 2730 3048 3039 3294 3352 3621 3906 3993 4105 4054 3879 3670 3376 3127 2981 2949 2892 2916 2857 3001 3015 3105 3279 3331 3333 3244 3171 3067 2951 2731 2710 2697 2609 2627 2675 2753 2903 3061 3082 3436 3644 3934 4008 4046 4210 3945 3754 3564 3199 3111 2995 2945 2815 2991 2994 3163 3486 3442 3713 3676 3584 3514 3384 3329 3124 3054 2987 3088 3113 3119 3308 3579 3816 4232 4285 4428 4337 4125 3953 3768 3339 3219 3155 3071 3020 3026 3084 3059 3138 3159 3271 3287 3333 3249 3162 3050 2922 2831 2742 2622 2743 2710 2660 2681 2750 2725 2818 2755 2952 3112 3434 3810 4348 4660 4886 5122 5016 4872 4711 4777 4860 5177 5298 5437 5252 4921 4320 4089 3918 3935 3890 4040 3843 3788 3752 3558 3618 3653 3785 3719 3811 3617 3357 3190 2809 2679 2623 2497 2440 2439 2391 2338 2450 2304 2290 2340 2292 2279 2349 2353 2291 2290 2286 2213 2304 2302 2301 2197 2207 2323 2378 2304 2311 2316 2256 2288 2212 2237 2317 2342 2301 2315 2281 2224 2296 2314 2262 2255 2219 2335 2313 2358 2277 2351 2259 2244 2267 2335 2334 2309 2243 2261 2261 2230 2243 2282 2312 2147 2314 2370 2293 2292 2279 2270 2263 2286 2253 2383 2408 2426 2320 2415 2402 2452 2475 2379 2300 2408 2422 2415 2428 2364 2460 2509 2449 2406 2482 2467 2452 2401 2373 2375 2370 2434 2398 2410 2435 2463 2396 2481 2441 2459 2550 2602 2642 2700 2600 2565 2655 2682 2748 2701 2805 2870 2808 2792 2736 2719 2596 2670 2638 2680 2706 2860 2855 2993 3195 3320 3564 3694 3965 4086 4505 4693 4775 4691 4491 4403 3965 3780 3549 3259 3173 3044 3119 2994 3113 3196 3273 3380 3470 3647 3512 3471 3422 3271 3096 2983 2817 2741 2658 2505 2545 2560 2497 2573 2508 2502 2483 2573 2496 2477 2523 2413 2364 2340 2508 2549 2493 2541 2566 2611 2666 2744 2631 2669 2819 2967 3077 3142 3239 3679 3699 4026 4309 4263 4423 4507 4546 4426 4037 3934 3649 3527 3187 3048 3096 3094 3060 3261 3307 3439 3528 3575 3527 3619 3745 3621 3505 3499 3513 3374 3246 3233 3041 2875 2794 2783 2586 2626 2510 2492 2557 2608 2559 2715 2638 2668 2690 2569 2673 2696 2591 2595 2563 2582 2688 2754 2788 2986 3038 2981 2985 2743 2770 2728 2667 2610 2448 2558 2419 2464 2562 2536 2607 2645 2685 2629 2737 2719 2677 2565 2542 2516 2565 2455 2528 2481 2626 2608 2723 2743 2944 2908 3142 3249 3433 3473 3604 3504 3540 3599 3520 3520 3455 3445 3132 3185 2909 2876 2818 2916 2930 2978 3111 3156 3095 3218 3312 3317 3401 3453 3510 3518 3424 3285 3341 3151 3008 3033 2972 2826 2899 2916 3023 3013 3121 3246 3458 3680 3700 3964 3967 4139 4026 3965 3837 3679 3734 3617 3804 3674 3862 3853 3940 4098 4095 4042 4065 4054 3958 3935 3784 3647 3480 3276 3360 3215 3267 3238 3370 3297 3352 3508 3516 3589 3772 3929 4111 4322 4442 4545 4462 4019 3946 3644 3472 3200 3086 3126 2980 2874 2925 3040 3115 3047 3101 3247 3291 3404 3293 3324 3273 3087 3171 3070 2995 2989 2968 2946 2923 2811 2768 2735 2717 2687 2655 2633 2638 2696 2657 2756 2744 2655 2826 2889 2873 2950 3025 3124 3308 3330 3494 3653 4168 4432 5124 5664 6242 6312 6298 6038 5986 5496 5393 5105 5052 4823 4994 5136 4994 5024 4929 4984 5064 5077 5047 5241 5237 5095 4756 4877 4784 4837 4901 5254 5235 5460 5271 5392 5260 5251 4890 4966 4575 4406 4048 3824 3731 3571 3477 3330 3428 3595 3569 3425 3600 3584 3616 3489 3429 3484 3460 3410 3241 3295 3232 3165 3077 3050 3120 3068 3293 3351 3484 3604 3628 3660 3623 3553 3432 3408 3420 3505 3378 3379 3420 3378 3398 3361 3386 3338 3243 3297 3196 3173 3143 3066 2994 2875 2805 2834 2924 2974 2918 2870 2825 2862 2791 2671 2703 2681 2563 2511 2546 2467 2406 2504 2465 2485 2435 2422 2459 2338 2428 2422 2361 2285 2398 2398 2414 2399 2511 2460 2458 2547 2450 2412 2516 2648 2682 2702 2867 2817 2862 3090 3067 3104 3272 3288 3224 3193 3306 3333 3266 3263 3287 3400 3468 3577 3650 3803 4012 3826 4098 3935 3903 3765 3488 3506 3396 3181 3133 3169 3242 3298 3413 3565 3961 4183 4315 4400 4275 3932 3639 3475 3245 3041 2905 2849 2791 2675 2676 2570 2715 2764 2755 2813 2920 3234 3076 3107 2935 2804 2646 2620 2586 2568 2623 2504 2519 2528 2485 2440 2425 2465 2486 2390 2479 2459 2394 2366 2312 2374 2441 2491 2398 2346 2317 2395 2368 2317 2288 2477 2413 2411 2449 2409 2355 2433 2344 2365 2435 2410 2289 2403 2459 2409 2352 2516 2472 2559 2488 2527 2508 2519 2571 2600 2549 2562 2607 2610 2603 2515 2483 2672 2612 2572 2676 2689 2662 2647 2739 2754 2823 2783 2872 3065 3212 3289 3474 3429 3244 3145 3049 2868 2758 2673 2604 2533 2534 2524 2454 2519 2560 2621 2597 2656 2719 2795 2755 2811 2785 2656 2574 2460 2410 2403 2324 2365 2269 2428 2301 2260 2319 2386 2411 2355 2343 2315 2413 2469 2449 2434 2451 2492 2452 2437 2394 2457 2375 2319 2352 2277 2269 2399 2359 2307 2379 2341 2335 2376 2335 2362 2467 2426 2410 2312 2403 2340 2372 2301 2471 2351 2284 2439 2455 2410 2340 2423 2317 2317 2333 2342 2259 2292 2305 2305 2320 2357 2402 2395 2364 2397 2423 2402 2389 2373 2348 2433 2376 2404 2296 2374 2311 2314 2429 2423 2384 2392 2559 2504 2534 2554 2597 2633 2690 2890 2792 2921 2920 2770 2960 2938 2975 2968 3059 2777 2773 2789 2744 2664 2731 2844 2974 3001 3140 3321 3615 3754 3891 3921 3851 3819 3830 3863 3702 3731 3627 3612 3378 3171 3199 3251 3194 3305 3250 3420 3553 3549 3549 3559 3538 3533 3512 3521 3397 3483 3272 3175 3123 3051 2874 2843 2787 2814 2660 2681 2637 2602 2596 2634 2582 2604 2654 2620 2648 2540 2520 2497 2476 2491 2411 2457 2382 2446 2396 2345 2439 2454 2406 2379 2288 2420 2529 2447 2468 2559 2476 2636 2667 2752 2677 2863 2935 3030 3077 2942 2994 2940 2755 2692 2605 2624 2567 2551 2549 2618 2543 2511 2606 2578 2631 2749 2711 2742 2930 2870 2786 2778 2705 2767 2781 2933 3011 3069 3187 3238 3240 3333 3324 3195 3255 3162 3199 3090 3061 3176 3100 3088 2876 2856 2832 2876 2840 2883 2971 2908 2885 2847 2854 2890 2700 2873 2758 2822 2778 2738 2811 2687 2671 2669 2632 2590 2553 2609 2572 2511 2522 2570 2560 2684 2592 2603 2669 2821 2819 2951 3090 3254 3350 3315 3284 3321 3174 3220 3177 3114 3095 3059 3114 3202 3166 3435 3613 3655 3773 3733 3700 3503 3314 3353 3284 3227 3239 3087 3117 3095 3048 3108 3205 3146 3024 2989 3230 3269 3438 3237 3243 3281 3207 3128 3012 3011 2832 2975 2886 2823 2697 2763 2689 2764 2682 2732 2707 2681 2692 2687 2705 2764 2757 2905 3014 3019 3085 3365 3572 3761 3790 3930 3848 3801 3616 3480 3269 3006 2904 2728 2702 2612 2622 2548 2565 2543 2712 2691 2818 2978 2933 3001 3129 3016 3061 3119 3072 2956 2969 2951 2812 2869 3001 3167 3226 3348 3307 3280 3300 3192 3084 3005 2869 2681 2578 2677 2627 2649 2551 2544 2466 2559 2545 2578 2668 2724 2755 2758 2818 2806 2813 2758 2802 2596 2511 2531 2500 2635 2476 2577 2551 2503 2514 2555 2585 2490 2574 2739 2845 2989 3131 3364 3522 3527 3493 3198 3018 2724 2743 2769 2715 2677 2758 2760 2700 2720 2781 2939 2964 2979 3060 3162 3250 3211 3239 3145 3053 2823 2853 2665 2672 2605 2437 2540 2590 2640 2644 2716 2728 2753 2733 2857 2954 2928 3007 3185 3114 3178 3163 3069 3024 3017 3050 2951 2936 2854 2910 2940 2875 2999 2912 2955 2963 3153 3031 3064 3229 3182 3207 3191 3175 3154 3142 3276 3079 3068 3073 3006 2947 2914 2819 2940 2751 2846 2842 2819 2829 2755 2823 2760 2736 2686 2784 2748 2732 2721 2842 2766 2880 2926 2890 2999 3108 3178 3250 3197 3285 3221 3175 2987 2927 2860 2806 2881 2908 3029 3201 3123 3480 3562 3550 3675 3873 4050 4182 4235 4307 4276 4199 4035 4042 3774 3557 3422 3313 3182 3210 3048 3025 3048 3074 3208 3198 3295 3231 3397 3550 3438 3735 3709 3675 3905 3902 4046 4142 3962 3931 3702 3562 3394 3190 3043 2956 2857 2868 2777 2646 2600 2674 2719 2716 2788 2706 2872 3012 3094 3200 3154 3234 3203 3079 3210 3076 2974 3062 2903 2950 2857 2899 2796 2812 2749 2792 2638 2761 2612 2586 2513 2620 2592 2584 2543 2575 2599 2505 2584 2623 2639 2571 2596 2643 2549 2575 2605 2593 2577 2651 2738 2696 2593 2755 2661 2681 2760 2836 2731 2742 2612 2727 2685 2574 2676 2572 2678 2685 2677 2676 2876 2772 2890 2907 2819 2855 2955 3091 3077 3052 3017 3068 3214 3428 3480 3566 3713 3645 3688 3565 3476 3171 3119 2991 2980 2890 2719 2722 2756 2732 2662 2668 2654 2751 2687 2701 2790 2833 2827 3066 3010 2967 2869 2786 2769 2686 2621 2623 2539 2514 2462 2482 2400 2380 2376 2295 2373 2319 2416 2309 2312 2301 2314 2345 2286 2389 2325 2275 2303 2264 2366 2250 2276 2217 2322 2268 2317 2201 2171 2304 2304 2310 2156 2200 2258 2163 2326 2247 2328 2291 2369 2303 2264 2271 2368 2318 2375 2313 2406 2344 2357 2315 2375 2409 2342 2468 2472 2569 2540 2653 2595 2683 2762 3096 3069 3077 3294 3284 3300 3162 3081 2964 2852 2854 2908 2889 2816 2685 2810 2802 2794 2724 2680 2683 2847 2671 2847 2858 2890 2990 2997 2967 2850 2881 2848 2820 2914 2810 2777 2935 2895 2982 2996 3013 3181 3216 3201 3370 3185 3122 2983 2975 2857 2819 2808 2833 2773 2916 2873 2987 3159 3153 3046 3125 3029 3014 2937 3043 2940 3084 3038 2965 2809 2729 2701 2685 2536 2477 2546 2514 2552 2531 2513 2678 2597 2622 2596 2579 2642 2530 2480 2515 2463 2461 2442 2414 2415 2359 2413 2316 2291 2324 2282 2293 2278 2344 2294 2311 2326 2293 2285 2257 2322 2189 2309 2356 2208 2225 2230 2273 2284 2340 2174 2229 2246 2284 2353 2254 2272 2240 2216 2251 2341 2165 2318 2107 2221 2228 2301 2277 2328 2317 2286 2288 2260 2280 2276 2293 2381 2280 2271 2266 2168 2314 2240 2232 2296 2356 2281 2320 2341 2380 2331 2420 2346 2427 2375 2327 2381 2311 2383 2340 2440 2423 2480 2461 2419 2444 2461 2542 2464 2577 2451 2463 2382 2416 2328 2464 2316 2465 2523 2448 2430 2508 2575 2691 2537 2770 2720 2885 2847 2860 2818 2986 3062 2888 2950 2826 2871 2925 2859 2860 2799 2886 2913 3043 3087 3162 3283 3416 3645 3573 3561 3514 3371 3204 3020 3047 2908 2904 2871 2801 2791 2839 2857 2878 2924 3028 2912 3256 3187 3419 3455 3568 3786 3731 3660 3707 3607 3433 3443 3352 3328 3097 3130 3112 3113 2911 2965 2900 2733 2789 2759 2840 2819 2914 2931 3003 3150 3124 3158 3177 3260 3234 3330 3414 3302 3397 3134 2984 3020 2836 2780 2714 2634 2591 2504 2565 2526 2518 2491 2534 2469 2500 2545 2592 2580 2628 2591 2576 2717 2715 2700 2604 2554 2515 2477 2338 2465 2355 2407 2353 2433 2421 2365 2496 2326 2416 2332 2484 2385 2341 2370 2412 2391 2377 2381 2414 2460 2486 2552 2593 2655 2620 2673 2678 2867 3034 3153 3104 3203 3431 3494 3447 3454 3402 3430 3507 3377 3466 3341 3370 3594 3508 3457 3578 3591 3782 4049 4172 4243 4337 4482 4550 4606 4754 4666 4756 4537 4346 4468 4167 3990 3806 3690 3615 3565 3440 3253 3365 3206 3267 3301 3320 3297 3358 3359 3537 3517 3279 3467 3443 3441 3431 3377 3304 3229 3195 3184 3114 3215 3157 3154 3286 3153 3251 3312 3239 3324 3419 3398 3445 3446 3461 3616 3515 3579 3622 3618 3580 3602 3540 3537 3523 3432</intensities>
			</dataPoints>
			<nonAmbientPoints type="Temperature" unit="K">
[...]
			</nonAmbientPoints>
		</scan>
	</xrdMeasurement>
</xrdMeasurements>