File: powder_X-ray_diffraction/variable-temperature_experiments/NaTaO2F2/raw_data/260°C.xrdml
<?xml version="1.0" encoding="UTF-8"?>
<xrdMeasurements xmlns="http://www.xrdml.com/XRDMeasurement/1.7" xmlns:xsi="http://www.w3.org/2001/XMLSchema-instance" xsi:schemaLocation="http://www.xrdml.com/XRDMeasurement/1.7 http://www.xrdml.com/XRDMeasurement/1.7/XRDMeasurement.xsd" status="Completed">
	<comment>
		<entry>Configuration=XRK900, Owner=User-1, Creation date=12/01/2015 16:52:44</entry>
		<entry>Goniometer=Theta/Theta; Minimum step size 2Theta:0.0001; Minimum step size Omega:0.0001</entry>
		<entry>Sample stage=AP XRK-900 with z-axis; Minimum step size Z:0.001</entry>
		<entry>Diffractometer system=EMPYREAN</entry>
		<entry>Measurement program=C:\PANalytical\Data Collector\Programs\Gwen\NaTaO2F2\NaTaO2F2-Lent.xrdmp, Identifier={FF50B583-C5FF-42DA-A01D-A1FB659EF29A}</entry>
		<entry>Batch program=C:\PANalytical\Data Collector\Programs\Gwen\NaTaO2F2\Thermodiff-Ouail.xrdmp, Identifier={5D65A6B1-42FC-480C-9FBB-D7D88D55EA08}</entry>
	</comment>
	<sample type="To be analyzed">
		<id></id>
		<name></name>
		<preparedBy></preparedBy>
	</sample>
	<xrdMeasurement measurementType="Scan" status="Completed" sampleMode="Reflection">
		<comment>
			<entry>PHD Lower Level = 4.02 (keV), PHD Upper Level = 12.07 (keV)</entry>
		</comment>
		<usedWavelength intended="K-Alpha 1">
			<kAlpha1 unit="Angstrom">1.5405980</kAlpha1>
			<kAlpha2 unit="Angstrom">1.5444260</kAlpha2>
			<kBeta unit="Angstrom">1.3922500</kBeta>
			<ratioKAlpha2KAlpha1>0.5000</ratioKAlpha2KAlpha1>
		</usedWavelength>
		<incidentBeamPath>
			<radius unit="mm">240.00</radius>
			<xRayTube id="1010048" name="Empyrean Cu LFF HR (9430 033 7310x) DK434948">
				<tension unit="kV">45.0</tension>
				<current unit="mA">30.0</current>
				<anodeMaterial>Cu</anodeMaterial>
				<focus type="Line">
					<length unit="mm">12.0</length>
					<width unit="mm">0.4</width>
					<takeOffAngle unit="deg">6.0</takeOffAngle>
				</focus>
			</xRayTube>
			<sollerSlit id="21010001" name="Soller slits 0.02 rad.">
				<opening unit="rad">0.0200</opening>
			</sollerSlit>
			<mask id="22030010" name="Fixed mask 20 mm">
				<width unit="mm">20.00</width>
			</mask>
			<antiScatterSlit id="22010003" name="Fixed slit 1Â°" xsi:type="fixedAntiScatterSlitType">
				<height unit="mm">1.52</height>
			</antiScatterSlit>
			<divergenceSlit id="22010012" name="Programmable divergence slit" xsi:type="fixedDivergenceSlitType">
				<distanceToSample unit="mm">140.00</distanceToSample>
				<angle unit="deg">0.5</angle>
			</divergenceSlit>
		</incidentBeamPath>
		<diffractedBeamPath>
			<radius unit="mm">240.00</radius>
			<antiScatterSlit id="22090010" name="AS slit 8.0 mm (PIXcel)" xsi:type="fixedAntiScatterSlitType">
				<height unit="mm">8.00</height>
			</antiScatterSlit>
			<sollerSlit id="21010001" name="Soller slits 0.02 rad.">
				<opening unit="rad">0.0200</opening>
			</sollerSlit>
			<filter id="20030001" name="Large beta-filter Nickel">
				<material>Ni</material>
				<thickness unit="mm">0.020</thickness>
			</filter>
			<detector id="7010019" name="PIXcel1D-Medipix3 detector" xsi:type="rtmsDetectorType">
				<phd unit="%">
					<lowerLevel>25.0</lowerLevel>
					<upperLevel>75.0</upperLevel>
				</phd>
				<mode>Scanning</mode>
				<activeLength unit="deg">3.3482</activeLength>
			</detector>
		</diffractedBeamPath>
		<scan appendNumber="0" mode="Continuous" scanAxis="Gonio" status="Completed">
			<header>
				<startTimeStamp>2023-01-22T17:02:26+01:00</startTimeStamp>
				<endTimeStamp>2023-01-22T20:02:55+01:00</endTimeStamp>
				<author>
					<name>User</name>
				</author>
				<source>
					<applicationSoftware version="5.5a">Data Collector</applicationSoftware>
					<instrumentControlSoftware version="8.2  20201204">EMPYREAN</instrumentControlSoftware>
					<instrumentID>0000000011159748</instrumentID>
				</source>
			</header>
			<dataPoints>
				<positions axis="2Theta" unit="deg">
					<startPosition>9.99846514</startPosition>
					<endPosition>99.99342261</endPosition>
				</positions>
				<positions axis="Omega" unit="deg">
					<startPosition>4.99923257</startPosition>
					<endPosition>49.99671130</endPosition>
				</positions>
				<positions axis="Z" unit="mm">
					<commonPosition>8.846</commonPosition>
				</positions>
				<commonCountingTime unit="seconds">386.070</commonCountingTime>
				<intensities unit="counts">6466 6282 6455 6388 6418 6292 6309 6414 6382 6308 6129 6351 6253 6212 6255 6234 6139 6318 6229 6179 6142 6271 6220 6263 6248 6246 6199 6141 6281 6243 6282 6307 6209 6075 6173 6002 6230 6192 6292 6073 6246 6013 6002 6139 6190 5961 5923 5934 6170 6237 6068 6102 6143 6172 6230 6320 6118 6393 6315 6300 6354 6296 6305 6449 6366 6533 6434 6432 6679 6816 6707 6966 7112 7409 7878 8372 9480 10553 12680 15442 20173 25238 32026 41106 48515 49797 47495 42871 34257 26866 21422 15389 11839 9668 8240 7450 6870 6836 6640 6570 6415 6321 5998 6141 5894 6143 6069 6017 5948 6057 5964 5978 5888 5910 5950 5840 5943 5837 6113 5793 5872 5873 5789 5887 5752 5827 5695 5816 5941 5876 5864 5751 5749 5693 5791 5769 5702 5959 5852 5755 5702 5764 5722 5631 5757 5569 5740 5794 5736 5571 5646 5674 5756 5677 5816 5767 5652 5649 5771 5613 5451 5595 5638 5593 5688 5639 5478 5605 5675 5582 5744 5537 5616 5511 5506 5547 5485 5523 5461 5556 5609 5595 5521 5479 5584 5384 5383 5441 5557 5462 5589 5495 5352 5450 5376 5536 5519 5426 5510 5427 5537 5496 5374 5383 5382 5506 5359 5238 5412 5457 5404 5494 5258 5393 5327 5285 5487 5561 5243 5267 5355 5422 5365 5337 5253 5457 5417 5400 5293 5492 5167 5303 5258 5286 5489 5260 5372 5357 5384 5328 5233 5422 5291 5340 5330 5285 5321 5254 5252 5313 5221 5424 5284 5079 5227 5223 5171 5275 5078 5226 5240 5233 5195 5250 5127 5137 5158 5123 5187 5203 5216 5356 5291 5099 5219 5181 5173 5102 5156 5218 5107 5079 4988 5203 5174 5208 5088 5114 5181 5077 5068 5202 5069 5099 5026 5124 4971 4936 5174 5129 5017 5182 5052 4900 5035 5120 5173 5066 5076 5065 4963 4921 5021 5031 5072 4947 5051 4968 5046 4998 5018 4936 4910 4890 4880 4855 4985 4936 4857 5003 4923 5042 4804 4928 4796 5127 4868 4894 4971 4918 4897 4835 4955 5049 4851 4970 4823 4880 4860 4736 4830 4942 4899 4872 4945 4870 4914 4865 4862 4958 4896 4878 4770 4882 4802 4872 4855 4851 4916 4948 4957 4795 4893 4760 4859 4854 4667 4680 4871 4820 4907 4928 4814 4835 4817 4786 4818 4810 4780 4827 4794 4742 4788 4784 4824 4798 4721 4809 4776 4922 4709 4731 4694 4717 4763 4761 4705 4643 4765 4699 4576 4657 4693 4669 4645 4669 4593 4703 4763 4752 4635 4668 4743 4588 4733 4721 4778 4719 4689 4622 4661 4727 4788 4593 4571 4683 4673 4599 4567 4641 4747 4637 4701 4610 4678 4634 4601 4436 4570 4608 4629 4532 4636 4735 4690 4534 4612 4580 4632 4698 4677 4688 4620 4751 4778 4742 4673 4893 4801 4715 4776 4841 4599 4745 4728 4659 4804 4659 4777 4834 4608 4684 4793 4742 4779 4674 4763 4759 4616 4625 4751 4561 4643 4661 4684 4692 4631 4552 4568 4661 4612 4471 4590 4460 4604 4665 4490 4488 4689 4542 4477 4568 4538 4556 4507 4669 4509 4487 4337 4564 4572 4453 4515 4406 4467 4498 4443 4451 4465 4467 4529 4440 4393 4406 4422 4401 4531 4493 4585 4473 4424 4569 4522 4474 4450 4629 4493 4505 4552 4536 4587 4496 4608 4518 4470 4548 4340 4390 4360 4550 4360 4458 4455 4259 4442 4354 4454 4481 4309 4360 4281 4334 4358 4382 4340 4220 4328 4510 4502 4300 4316 4410 4460 4434 4356 4390 4558 4566 4718 4669 4586 4619 4610 4514 4453 4351 4349 4314 4313 4293 4144 4236 4301 4353 4246 4380 4278 4288 4420 4280 4388 4250 4261 4198 4143 4197 4150 4203 4207 4240 4192 4316 4216 4392 4291 4164 4195 4145 4270 4220 4289 4199 4203 4198 4283 4209 4336 4189 4087 4196 4196 4157 4136 4168 4171 4293 4249 4148 4230 4196 4166 4039 4214 4208 4342 4331 4297 4378 4221 4186 4206 4201 4165 4224 4160 4247 4154 4188 4148 4120 4196 4205 3985 3929 4148 4097 4056 4090 4045 4111 4111 4242 4330 4371 4354 4374 4433 4370 4574 4698 4546 4462 4583 4681 4520 4586 4606 4673 4454 4510 4579 4682 4548 4500 4510 4553 4487 4541 4432 4601 4714 4713 4851 4894 4938 5114 5172 5229 5325 5616 5888 5826 6268 6755 7446 8270 10119 12864 16401 23132 33832 52206 73938 95870 116510 122714 115409 106350 97284 79469 60324 44248 31791 22231 16008 12119 9142 7701 6752 6273 5813 5618 5226 4990 5035 4835 4802 4617 4601 4589 4495 4407 4452 4422 4314 4394 4381 4365 4428 4393 4405 4498 4551 4521 4473 4587 4478 4452 4434 4276 4187 4310 4231 4136 4178 4059 4103 4178 4053 4103 4187 4050 3975 4046 4075 4119 4154 4083 4027 4109 3995 4046 3985 3908 4001 3957 3962 3959 4079 4158 4028 4051 4063 3982 3972 3945 3867 3947 3825 3855 3913 3992 3908 3981 4032 4117 3845 3850 4072 3962 3865 4046 3899 3871 3918 3928 3899 3944 3870 3829 3935 3852 3936 3899 3927 3851 3898 3986 3961 3827 3741 3844 3836 3785 3982 3923 3816 4047 3882 3933 3795 3793 3782 3792 3829 3823 3798 3830 3770 3872 3823 3887 3820 3806 3791 3840 3772 3863 3823 3724 3708 3782 3766 3844 3892 3902 3811 3785 3803 3876 3845 3894 3887 3987 3903 3960 3971 4102 4137 4120 4243 4130 4151 3984 3902 3872 3815 3820 3777 3977 3880 4032 4183 3916 3859 3853 3884 3884 3779 3903 3877 4005 3881 3937 3973 3882 4014 3920 4052 4124 4303 4354 4638 5224 5735 6779 8543 11425 15370 18008 19412 18513 17034 15854 14610 11853 9536 7595 6386 5251 4648 4269 4094 4197 3936 3903 3864 3851 3827 3975 3818 3850 3813 3788 3699 3711 3676 3844 3616 3627 3762 3930 3912 3765 3804 3873 3858 3865 3829 3889 3844 3780 3664 3789 3695 3746 3754 3725 3691 3664 3615 3538 3745 3743 3544 3649 3560 3584 3539 3588 3549 3504 3568 3648 3667 3722 3666 3679 3641 3625 3673 3655 3676 3743 3667 3829 3695 3684 3763 3827 3689 3809 3759 3748 3731 3811 3686 3827 3791 3796 3706 3802 3831 3839 4020 3947 3879 3919 3893 3855 3926 3844 3885 3931 3885 3999 3987 3920 3945 3906 3893 3915 3882 3959 3951 4009 3947 4032 4146 4187 4313 4301 4245 4405 4570 4470 4525 4542 4618 4911 5047 5326 5553 6120 7565 9312 12862 18534 25949 33911 41007 44854 44783 42674 37641 33489 30526 26563 22948 20759 23436 29786 36727 41343 45976 47298 44875 40767 37142 31977 25745 20094 15700 11958 8761 6707 5652 5064 4729 4727 4396 4267 4246 4132 3956 3993 3995 3815 3838 3866 3800 3825 3781 3733 3814 3869 3745 3787 3621 3642 3655 3764 3687 3675 3748 3797 3681 3800 3984 3837 3967 3880 3773 3809 3737 3652 3706 3689 3557 3602 3669 3685 3555 3633 3636 3625 3612 3584 3590 3637 3690 3535 3638 3501 3624 3528 3604 3653 3596 3630 3684 3621 3502 3554 3600 3571 3691 3756 3603 3596 3502 3610 3517 3521 3496 3527 3466 3488 3487 3479 3483 3648 3477 3481 3409 3516 3395 3517 3520 3477 3615 3543 3491 3488 3474 3425 3537 3447 3424 3532 3463 3494 3438 3502 3400 3439 3608 3559 3470 3522 3570 3422 3450 3593 3565 3470 3552 3775 3804 3972 3784 3662 3647 3712 3582 3637 3652 3654 3679 3650 3564 3487 3506 3564 3468 3646 3609 3411 3376 3421 3526 3519 3526 3505 3567 3517 3464 3440 3531 3389 3199 3457 3439 3465 3436 3380 3376 3509 3489 3375 3478 3473 3643 3444 3454 3500 3591 3686 3688 3649 3632 3630 3582 3679 3593 3533 3714 3685 3659 3622 3652 3587 3691 3619 3629 3575 3556 3706 3691 3658 3658 3657 3682 3653 3604 3642 3548 3547 3720 3602 3666 3677 3725 3756 3762 3775 3754 3670 3740 3678 3671 3837 3721 3825 3973 4004 4317 4211 4337 4475 4671 4796 4840 5112 5489 5825 6278 6655 7524 8516 10152 13073 18053 26893 39746 56947 74280 84376 82798 75509 68678 63915 58999 50911 41471 31786 23705 17266 12462 9223 7338 6451 5886 5404 4969 4750 4561 4298 4068 4103 4004 3942 3949 3786 3746 3770 3774 3725 3615 3635 3589 3638 3572 3605 3692 3597 3826 3823 3930 4036 3880 3749 3835 3902 3838 3770 3760 3650 3636 3696 3690 3613 3651 3681 3645 3655 3535 3605 3561 3529 3677 3601 3564 3533 3555 3590 3483 3533 3590 3525 3429 3514 3526 3416 3489 3539 3609 3410 3521 3482 3461 3588 3585 3530 3649 3557 3484 3634 3619 3543 3694 3627 3612 3776 3600 3697 3815 3827 3899 3929 3961 4143 4238 4279 4540 4661 4901 5364 6286 7854 10380 15271 21583 28078 31663 33198 30124 26329 25283 24926 24073 22837 21582 20622 21158 21595 21517 20204 17867 16078 14533 13243 12198 10598 8784 7022 5920 4889 4399 4021 3866 3779 3682 3688 3516 3451 3552 3453 3437 3481 3393 3376 3450 3365 3493 3413 3418 3230 3285 3395 3311 3348 3386 3353 3317 3418 3249 3325 3331 3382 3501 3404 3427 3373 3312 3375 3412 3295 3218 3214 3264 3367 3230 3204 3285 3262 3217 3174 3289 3331 3371 3347 3329 3310 3301 3361 3353 3318 3403 3180 3341 3284 3180 3203 3256 3195 3282 3225 3281 3242 3270 3304 3213 3233 3149 3166 3197 3110 3176 3189 3284 3170 3161 3151 3119 3175 3235 3269 3111 3193 3158 3111 3248 3171 3141 3269 3223 3254 3139 3075 3095 3188 3102 3226 3186 3117 3171 3070 3247 3153 3162 3242 3223 3214 3178 3197 3184 3159 3149 3196 3060 3193 3193 3285 3226 3170 3187 3107 3199 3115 3127 3068 3137 3162 3181 3094 3094 3074 3066 3187 3106 3134 3112 3032 3019 3198 3187 3181 3168 3164 3154 3150 3210 3210 3170 3156 3130 3221 3231 3246 3121 3159 3074 3085 3219 3072 3006 3070 3086 3165 3131 3175 3125 3150 3107 3035 3030 3179 3131 3064 3075 3161 3116 3124 3130 3168 3171 3071 3177 3101 3134 3134 3146 3222 3160 3244 3145 3087 3248 3208 3212 3252 3251 3233 3248 3106 3131 3094 3205 3209 3300 3311 3349 3262 3390 3252 3337 3287 3365 3444 3637 3636 3683 3614 3754 3805 3900 4176 4734 5623 7570 11010 15619 20081 20879 18646 15153 12792 12614 13191 13233 11864 9986 7971 6216 5269 4468 4235 3935 3714 3689 3589 3560 3447 3562 3555 3439 3571 3600 3539 3515 3651 3791 3806 3945 4003 4082 4117 4257 4491 4405 4766 5168 5778 7252 9467 13584 19673 27000 33047 35164 32976 29370 24478 22431 21680 21792 20127 17235 13768 10574 7982 6447 5687 5253 4840 4922 4969 4825 5001 5264 5466 6122 7043 8795 11381 15236 20007 24685 28526 30346 29935 27459 24493 21790 20374 20170 19143 19017 18598 19101 19578 19021 16247 13373 11218 10488 10582 10882 10103 8576 6967 5837 4859 4223 3938 3796 3663 3573 3560 3446 3341 3295 3329 3298 3162 3330 3284 3238 3142 3182 3316 3219 3232 3268 3144 3276 3236 3219 3100 3255 3248 3288 3229 3331 3383 3258 3334 3341 3364 3431 3524 3468 3696 3731 3818 4334 4920 6400 8401 11257 13677 14516 13425 11442 9662 9113 9033 9403 9094 7928 6758 5581 4780 4041 3830 3591 3505 3364 3273 3171 3134 3228 3260 3465 3551 3572 3547 3411 3369 3302 3352 3272 3277 3228 3304 3172 3093 3033 3046 3058 2991 3000 2938 2964 2967 3072 3021 3024 3038 2962 2924 2971 3035 2929 2928 2947 3036 2911 2980 2946 2964 2957 3061 2951 2994 3041 2994 3055 3071 3005 2857 2959 3021 2871 2920 2964 2954 2875 3017 2870 3054 2950 2940 3043 2994 2947 2927 2872 2906 3040 2902 2945 2818 2985 2936 2975 2946 2886 2924 2902 3021 2876 2983 3087 3062 2885 2846 2926 3066 2933 2996 2977 2968 2898 2990 2928 3039 2934 2952 2827 2940 2956 2882 2880 2923 2832 2961 2983 2922 2971 2977 2988 2988 2925 2999 2971 2922 2903 2952 2908 2871 2978 2857 3049 3029 3135 3028 3050 3179 3210 3115 3177 3182 3341 3515 3790 4197 5177 6496 8338 9263 9681 8523 7072 6275 5833 6129 6227 6309 6008 5200 4309 3890 3421 3261 3183 3078 3056 3038 3098 3053 3000 3121 3082 3015 3036 2975 3070 3066 3182 3184 3115 3300 3180 3256 3153 3108 3250 3435 3714 4059 4644 5667 7161 8282 9470 10097 9872 8813 8019 7323 6945 6819 6698 6504 6003 5276 4576 3962 3525 3292 3264 3171 3177 3157 3217 3364 3436 3647 3559 3696 3378 3329 3246 3397 3395 3291 3408 3237 3194 2962 2979 2945 2841 2941 2920 2781 2831 2832 2846 2864 2864 2854 2851 2753 2779 2672 2722 2809 2781 2715 2784 2824 2624 2769 2762 2707 2767 2842 2740 2775 2719 2839 2807 2809 2735 2696 2704 2773 2754 2759 2754 2726 2794 2753 2760 2755 2819 2742 2754 2803 2751 2822 2808 2816 2812 2756 2716 2711 2766 2761 2664 2720 2725 2861 2831 2719 2817 2776 2682 2813 2735 2778 2821 2729 2815 2717 2704 2834 2789 2739 2769 2733 2768 2795 2788 2798 2770 2771 2784 2776 2802 2758 2671 2682 2836 2816 2797 2774 2756 2715 2721 2820 2769 2808 2788 2768 2631 2725 2699 2787 2756 2750 2812 2787 2707 2703 2717 2737 2794 2735 2770 2793 2835 2730 2631 2730 2775 2685 2833 2747 2787 2851 2713 2804 2830 2848 2968 3029 3139 3331 3740 4063 4357 4794 4705 4719 4425 4128 3983 3893 4036 3957 3918 3900 3647 3565 3453 3279 3297 3404 3579 3836 4453 5271 6593 7549 8036 7436 6766 5859 5223 4963 5334 5756 5565 5190 4764 4242 3839 3561 3264 3336 3266 3205 3296 3159 3170 3168 3269 3440 3696 3972 4774 5890 7413 9278 10344 10129 8854 7287 6091 5826 5980 6556 6889 6547 5995 4949 4343 3762 3548 3250 3128 3170 3042 3009 3110 2936 2951 3002 3092 2958 3180 3001 3075 3214 3122 3155 3222 3415 3588 3876 4284 4752 5652 6750 8464 9849 11258 11287 10696 9316 7959 7388 7375 8109 8502 9144 9639 10563 11986 12984 13340 12681 11429 10466 10159 10838 12883 15157 16775 16361 14417 11841 9185 8015 7602 7602 7852 7721 7041 6224 5072 4304 3845 3421 3353 3260 3024 3045 3050 2853 2902 2849 2858 2827 2872 2710 2775 2778 2915 2732 2779 2729 2871 2791 2790 2783 2784 2802 2754 2700 2764 2687 2747 2771 2684 2757 2690 2665 2701 2781 2710 2807 2696 2564 2736 2729 2712 2698 2687 2709 2811 2756 2738 2812 2753 2660 2691 2629 2642 2787 2717 2585 2724 2761 2633 2702 2788 2761 2636 2654 2741 2689 2639 2716 2696 2757 2703 2621 2742 2768 2634 2722 2699 2761 2743 2639 2718 2633 2665 2709 2661 2699 2665 2691 2651 2581 2725 2727 2749 2686 2668 2689 2539 2650 2640 2695 2574 2672 2775 2685 2717 2650 2743 2742 2669 2730 2752 2777 2621 2811 2742 2691 2608 2779 2791 2731 2658 2677 2679 2640 2693 2655 2712 2626 2666 2694 2677 2675 2745 2721 2602 2672 2666 2822 2711 2667 2720 2739 2856 2849 2966 3112 3321 3219 3385 3277 3139 2985 3041 3057 3002 2984 3139 3022 2981 2859 2869 2705 2694 2674 2700 2690 2734 2780 2698 2703 2631 2712 2636 2619 2603 2622 2642 2598 2701 2676 2735 2681 2700 2703 2721 2676 2743 2689 2723 2623 2698 2670 2734 2734 2765 2778 2793 2610 2692 2779 2752 2807 2757 3028 3156 3456 3776 3916 4163 4089 3950 3587 3409 3230 3238 3330 3438 3496 3453 3450 3229 3196 3090 3077 3130 3123 3420 3654 4040 4617 5021 5437 5591 5451 4987 4502 4187 4126 4113 4060 4241 4075 3932 3729 3457 3303 3120 2976 2850 2889 2737 2673 2788 2642 2686 2669 2736 2655 2723 2788 2732 2831 2737 2700 2655 2740 2715 2685 2704 2667 2616 2662 2618 2788 2741 2662 2641 2692 2634 2716 2707 2648 2726 2644 2608 2603 2575 2657 2581 2656 2627 2773 2687 2676 2629 2649 2721 2758 2713 2706 2776 2769 2788 2815 2881 2914 2907 2859 3003 2907 3006 3032 3166 3109 3357 3675 4138 4941 6218 8322 10313 11633 11332 9457 7260 5615 4956 5130 5762 6703 7316 7269 6253 5115 4213 3630 3198 3045 3076 2834 2870 2857 2875 2817 2766 2779 2748 2828 2784 2742 2774 2739 2777 2854 2813 2791 2798 2730 2832 2831 2866 2829 2905 2831 2840 2860 2975 2915 3080 3134 3201 3678 4041 4828 6021 6724 7179 6881 5740 4843 4386 3931 3986 4318 4793 5051 4787 4445 3999 3483 3241 3226 3041 2902 2895 2794 2893 2958 2793 2811 2792 2758 2929 2772 2755 2902 2832 2906 2810 2933 2913 2898 2870 2948 2862 2940 3058 2994 3149 3123 3243 3393 3639 3948 4613 5245 6330 7203 8142 8604 8654 8015 6680 5705 5186 5202 5378 5676 5829 5810 5677 5031 4344 3814 3474 3344 3108 3061 3107 3067 3131 3114 3007 2969 3172 3127 3092 3111 3155 3229 3252 3159 3493 3298 3399 3520 3533 3558 3664 3752 4138 4195 4625 5172 6013 7169 9201 11783 15272 18398 20363 20044 17988 14686 12110 10697 10067 10378 11408 11969 12182 11517 9909 8220 6702 5597 4876 4290 4080 3788 3543 3464 3411 3274 3315 3125 3249 3209 3149 3267 3133 3175 3254 3302 3357 3376 3400 3399 3537 3640 3757 4201 4857 6196 7836 10216 11892 12882 12717 13119 13630 12943 12223 11325 10925 10324 9614 8945 8625 8665 8403 7928 7249 6558 5955 5210 4556 4183 4194 4343 4691 5340 6323 7917 10075 12063 13397 12948 11298 9363 7449 6548 6165 6550 7329 7841 8248 7896 6940 5932 4962 4410 3711 3417 3347 3369 3261 3107 3056 3089 3021 3004 2957 2927 2910 2758 2923 2861 2879 2829 2898 2932 2955 2913 3086 2776 2754 2801 2962 3027 2951 3007 3015 3081 3187 3148 3368 3549 3473 3529 3317 3355 3217 3054 3196 3359 3306 3327 3410 3473 3457 3646 3702 3578 3601 3583 3392 3490 3427 3399 3501 3495 3606 3633 3618 3656 3692 3544 3772 3986 4093 4612 5109 5928 7274 9413 12349 15767 18236 19133 17844 15554 12823 10953 9683 9675 10247 10997 11765 11835 11066 9661 8285 7024 6108 5274 4968 4401 4148 3956 3836 3697 3693 3705 3681 3819 3935 4304 4610 5343 6315 7294 8712 10118 11125 11602 11263 9650 8354 7172 6626 6487 6616 6909 7134 7495 7238 6503 5614 4972 4292 3861 3728 3417 3306 3094 3133 3054 2999 3017 3002 3086 3003 2945 2855 2936 2915 2815 2919 2903 2908 2948 2863 2964 2786 2827 2887 2883 2836 2905 2950 2906 2931 2898 3056 2855 3025 3016 2954 2954 3017 3078 3233 3149 3305 3569 3752 4489 5486 6788 8026 8933 8849 7962 6761 5775 4810 4711 4652 5095 5562 5929 6141 5731 5312 4588 4160 4022 3909 3851 3698 3532 3311 3282 3105 3046 3127 3075 3073 3187 3208 3232 3150 2957 2906 2836 2837 2836 2837 2802 2797 2894 2852 2837 2841 2895 2743 2833 2686 2801 2711 2819 2868 2789 2788 2803 2795 2847 2910 2780 2777 2698 2777 2681 2808 2788 2807 2730 2775 2907 2870 2843 2911 2960 2946 2934 3001 3020 3046 2966 2981 3073 3035 3158 3272 3348 3394 3631 4114 4574 5405 6608 7900 9209 10159 10659 10415 9748 8642 7774 6570 6130 5955 6304 6471 6797 6938 6864 6265 5587 4890 4517 3993 3715 3626 3796 4044 4282 4729 5116 5535 5964 6180 6155 6070 6107 5810 5454 4854 4699 4548 4437 4528 4298 4533 4387 4302 4089 3790 3512 3291 3115 2968 2866 2921 2774 2750 2775 2793 2828 2736 2760 2805 2752 2902 2781 2850 2829 2732 2738 2845 2818 2829 2828 2778 2859 2909 2950 3168 3180 3491 3782 4012 4057 4166 4059 3832 3584 3413 3286 3211 3203 3334 3341 3381 3451 3412 3308 3197 2914 2883 2863 2845 2777 2808 2712 2861 2731 2753 2694 2770 2758 2868 2806 2743 2788 2809 2836 2795 2686 2719 2729 2777 2724 2726 2655 2672 2727 2737 2761 2806 2841 2815 2992 2925 3116 3024 2996 3011 3153 3179 3045 2990 2965 2956 3075 2880 2916 2848 2958 2870 2915 2814 2884 2875 2834 2759 2812 2774 2714 2768 2681 2642 2687 2681 2736 2804 2630 2658 2656 2712 2744 2671 2668 2756 2828 2756 2813 2764 2775 2687 2574 2817 2719 2700 2752 2642 2717 2698 2734 2825 2860 2884 2803 2849 2837 2853 2944 2990 2962 2916 2933 2967 3090 3065 3194 3246 3270 3449 3520 3787 4069 4447 5050 6153 7633 9334 10814 11480 11292 10146 8368 7155 6156 5744 5679 5885 6531 7077 7621 7579 7034 6178 5452 4692 4257 3923 3768 3529 3593 3490 3662 3549 3538 3374 3275 3226 3089 3073 2956 3031 3003 3073 3098 2986 3105 2940 3030 2931 2893 2980 2944 2988 3016 2929 2807 2854 2851 2901 2863 2966 2991 3070 3076 3113 3184 3162 3202 3297 3408 3555 3745 4357 4890 5608 6158 6677 6995 6998 7636 8786 9936 11371 12548 13273 13074 12302 11027 9582 8015 7286 6789 6878 7285 7834 7931 7987 7733 6822 6032 5158 4648 4084 3740 3550 3170 3177 3195 3152 3158 3040 3053 3154 3101 2971 3213 3055 3069 3072 3191 3227 3044 3132 3244 3343 3491 3690 3837 4145 4651 5312 6205 6860 7579 8129 8894 9199 9266 9658 9863 9473 8686 8021 7448 6858 6720 6732 6854 7059 7448 7762 8332 8591 8844 8538 8191 7109 6284 5707 4778 4524 4381 4273 4459 4670 4908 4947 4914 4713 4235 4011 3680 3505 3306 3205 3225 3094 3098 2969 2929 2986 2987 2930 2996 3039 3081 3015 3170 3177 3188 3303 3312 3487 3619 3873 4129 4644 5414 6325 7687 8592 9207 8791 7719 6655 5782 5458 5038 5090 5560 6119 6749 7266 7342 6957 6207 5401 4875 4424 4058 3854 3898 3810 3814 3941 3799 3681 3646 3461 3435 3316 3383 3254 3260 3356 3443 3627 3696 3758 4116 4506 5027 5626 6369 7190 7941 8518 8688 8358 7640 6602 5917 5552 5411 5324 5592 5949 6490 6997 7574 8183 8892 9355 9620 9610 9489 7998 6766 5654 5063 4915 4817 5085 5580 5886 6723 6886 7447 7430 7544 7957 8782 9312 9574 9487 8676 7536 6345 5382 5286 5013 4996 5209 5464 5982 6165 6193 5825 5279 4775 4231 3848 3639 3481 3182 3209 3146 3159 3042 3102 3148 2971 3073 2974 3031 2963 3091 3047 2974 3039 3037 3136 3255 3286 3409 3498 3872 4325 4920 5374 6104 6802 7609 8028 8330 8226 7660 7064 6280 5571 5156 5106 5150 5469 5852 6334 6918 6961 7340 7679 7677 7727 8123 8744 9570 10718 11293 11314 10299 8675 7330 6418 6028 5748 5716 5800 6071 6664 7048 7044 6618 5948 5240 4551 3986 3675 3495 3320 3168 3146 3052 3044 3050 3002 3016 2948 3064 3044 3032 3144 3085 3184 3042 3139 3116 3262 3258 3216 3309 3346 3460 3514 3713 3829 4162 4762 5294 6085 7485 9173 11033 12876 14312 14515 13511 12152 10388 8954 7785 7299 7072 7541 8002 8964 9891 10319 10274 9691 8899 7889 6964 6296 5644 5110 5008 4872 4900 5140 5309 5395 5484 5403 5563 5316 5102 4724 4442 4047 3749 3763 3663 3551 3746 3699 3658 3583 3631 3547 3419 3241 3077 2801 2815 2791 2811 2776 2689 2709 2670 2611 2730 2609 2644 2692 2618 2610 2607 2649 2662 2678 2581 2610 2551 2611 2565 2631 2680 2643 2665 2616 2556 2601 2559 2681 2583 2522 2665 2593 2541 2728 2631 2674 2641 2565 2643 2553 2525 2585 2456 2529 2551 2604 2590 2586 2624 2573 2579 2647 2582 2576 2609 2570 2429 2479 2465 2565 2489 2538 2554 2541 2447 2500 2474 2551 2533 2548 2476 2601 2626 2573 2497 2522 2484 2481 2538 2509 2616 2539 2575 2604 2524 2557 2538 2542 2574 2521 2576 2445 2579 2621 2526 2496 2521 2457 2511 2580 2501 2566 2613 2543 2494 2372 2433 2475 2465 2521 2615 2592 2490 2595 2442 2565 2537 2600 2557 2599 2540 2549 2548 2437 2468 2445 2448 2527 2518 2473 2587 2422 2427 2649 2597 2532 2479 2559 2511 2554 2512 2561 2449 2576 2594 2599 2588 2641 2521 2564 2728 2664 2699 2841 2748 2812 2843 2886 2998 3010 3108 3193 3320 3468 3813 3994 4083 4077 3845 3648 3330 3127 3066 3090 2951 3097 3089 3135 3305 3313 3320 3247 3002 2976 2943 2915 2875 2856 2909 2844 3005 3186 3287 3652 3709 4020 4212 4263 4024 3971 3712 3301 3332 3087 3074 3158 3357 3431 3531 3899 3856 4142 4247 4258 4082 4143 4020 3669 3527 3276 3073 3023 2894 2776 3003 2994 3112 3042 3161 3181 3123 2998 2876 2756 2705 2740 2573 2501 2508 2450 2492 2461 2502 2380 2523 2487 2460 2505 2567 2454 2500 2500 2550 2577 2532 2492 2509 2659 2678 2670 2706 2673 2784 2800 2731 2831 2850 2627 2653 2661 2807 2763 2767 2638 2707 2713 2801 2654 2654 2659 2724 2616 2709 2468 2650 2602 2538 2609 2578 2513 2503 2454 2504 2501 2445 2530 2471 2589 2425 2357 2447 2529 2340 2488 2462 2379 2354 2413 2320 2405 2329 2459 2470 2438 2424 2420 2432 2432 2454 2403 2410 2543 2440 2414 2307 2442 2392 2504 2368 2473 2422 2491 2505 2459 2462 2405 2488 2412 2478 2470 2510 2385 2427 2399 2363 2475 2468 2360 2367 2407 2400 2379 2390 2357 2442 2432 2349 2399 2376 2445 2463 2425 2397 2397 2442 2458 2455 2412 2394 2363 2464 2373 2422 2329 2459 2416 2400 2374 2475 2428 2526 2601 2489 2475 2489 2511 2467 2454 2485 2437 2459 2395 2522 2359 2386 2486 2495 2412 2421 2464 2476 2379 2361 2404 2537 2587 2585 2554 2530 2476 2592 2512 2547 2552 2463 2455 2396 2492 2556 2484 2447 2532 2463 2478 2479 2470 2403 2499 2459 2354 2464 2372 2483 2347 2406 2406 2387 2324 2318 2425 2462 2457 2485 2396 2425 2361 2409 2412 2472 2386 2465 2314 2453 2418 2499 2384 2411 2448 2351 2399 2410 2426 2308 2375 2394 2446 2460 2416 2507 2513 2354 2473 2514 2458 2472 2433 2479 2442 2402 2405 2486 2450 2418 2447 2518 2394 2447 2471 2477 2461 2410 2420 2410 2487 2427 2540 2563 2483 2571 2497 2551 2563 2637 2618 2719 2648 2866 2853 3079 3249 3469 3713 3657 3836 3654 3400 3220 3253 3269 3253 3166 3247 3318 3193 3216 3287 3332 3361 3400 3212 3180 3080 3088 3195 3232 3560 3729 4017 4512 4964 5132 5105 4863 4483 3818 3598 3204 2961 2895 2933 2999 3055 3262 3476 3767 3797 3727 3482 3434 3078 2977 2786 2720 2716 2669 2531 2531 2514 2505 2660 2512 2531 2547 2491 2556 2483 2535 2490 2486 2586 2461 2643 2622 2501 2456 2535 2561 2580 2688 2600 2599 2669 2725 2784 2760 2925 2986 3148 3370 3619 4004 4448 4529 4555 4450 4200 4114 3869 3867 3929 3653 3454 3386 3370 3506 3614 3758 3694 3809 3638 3566 3502 3496 3443 3489 3578 3529 3522 3587 3444 3304 3352 3239 3090 3013 3088 3085 3187 3248 3440 3773 4084 4373 4956 5424 6052 6625 7155 7366 7343 7063 6569 6151 5520 5187 4758 4536 4533 4346 4527 4588 5037 5247 5346 5377 5475 5305 4946 4585 4164 3859 3633 3369 3325 3138 3085 3011 2949 2997 3024 2997 3073 2968 2945 3042 3019 2988 3061 3305 3200 3525 3841 4087 4515 4798 5207 5323 5189 4790 4342 4054 3701 3534 3396 3448 3421 3568 3813 3942 4298 4464 4807 5037 5016 4978 4977 4905 4833 4770 4545 4553 4340 4231 3963 3981 3732 3707 3596 3532 3698 3612 3759 3689 3693 3661 3761 3626 3511 3554 3366 3402 3650 3943 4375 4715 5119 5201 4792 4259 3811 3388 3319 3070 3062 3098 3132 3135 3141 3339 3495 3651 3838 3764 3685 3440 3128 3000 2925 2955 2854 2793 2871 2803 2867 2779 2859 2839 2937 3040 3246 3420 3565 4021 4370 4509 4859 4884 4595 4578 4358 3995 3969 3844 3775 3652 3501 3410 3553 3574 3712 3733 3819 3720 3444 3460 3366 3208 3185 3029 3048 2991 2702 2681 2796 2664 2625 2619 2663 2634 2693 2582 2693 2664 2545 2507 2628 2578 2560 2607 2626 2538 2537 2572 2583 2573 2593 2634 2656 2683 2771 2858 2955 3004 3158 3360 3640 3942 4101 4045 4139 3997 3637 3519 3222 3079 3014 2847 2835 2931 2961 3008 3135 3265 3423 3338 3445 3255 3168 3075 2852 2756 2744 2634 2688 2606 2702 2739 2639 2722 2832 2834 2955 3149 3303 3547 3858 4003 4337 4460 4395 4237 4085 3837 3441 3354 3130 3125 3031 3199 3089 3210 3367 3577 3630 3697 3973 3989 4011 4060 4080 3989 3962 3937 3782 3647 3655 3403 3263 3241 3145 3072 3147 3176 3340 3520 3764 3709 3778 3743 3693 3606 3340 3211 3212 3083 3077 2910 3012 3199 3312 3425 3730 3865 4471 4854 5189 5561 5582 5849 5683 5551 5707 5442 5251 5064 4593 4142 3793 3575 3604 3859 4031 4026 4129 4133 4082 4072 3992 3935 4003 3667 3463 3298 3118 2944 2872 2745 2666 2572 2667 2538 2553 2529 2553 2499 2483 2555 2457 2540 2552 2477 2506 2523 2491 2467 2436 2389 2420 2460 2419 2393 2477 2468 2316 2434 2460 2397 2447 2416 2445 2523 2463 2419 2379 2417 2456 2435 2428 2379 2475 2436 2452 2447 2352 2441 2446 2514 2463 2348 2394 2510 2406 2341 2408 2386 2385 2505 2488 2401 2429 2441 2442 2413 2453 2426 2434 2359 2401 2467 2413 2443 2424 2413 2413 2482 2406 2470 2359 2463 2436 2412 2489 2486 2407 2562 2534 2572 2587 2515 2511 2488 2506 2449 2594 2492 2470 2558 2454 2506 2495 2493 2532 2520 2511 2523 2481 2633 2502 2470 2585 2574 2553 2475 2458 2475 2490 2529 2552 2497 2457 2484 2528 2608 2519 2547 2661 2647 2702 2676 2677 2757 2786 2852 2804 2895 2872 3025 2992 3046 3034 3175 3184 3288 3256 3343 3459 3705 3909 4198 4402 4542 4843 4882 4807 4686 4599 4226 4115 3973 3679 3471 3488 3302 3284 3396 3446 3416 3571 3721 3721 3639 3561 3370 3319 3227 3176 3055 2950 2822 2716 2890 2774 2844 2721 2841 2795 2854 2898 3086 3195 3259 3557 3727 3951 4091 4242 4325 4556 4491 4387 4474 4050 3921 3648 3476 3287 3289 3213 3229 3154 3355 3282 3321 3466 3518 3440 3504 3354 3307 3119 3094 2883 2800 2715 2660 2607 2516 2624 2482 2576 2495 2538 2520 2585 2459 2569 2594 2499 2501 2485 2588 2649 2462 2673 2542 2640 2583 2645 2707 2744 2904 3032 3055 3156 3195 3202 3210 3045 2961 2805 2700 2736 2708 2609 2608 2573 2793 2658 2750 2859 2884 2842 2788 2826 2852 2823 2758 2669 2633 2636 2575 2568 2665 2576 2631 2538 2675 2541 2710 2790 2914 2877 2864 2879 2963 2892 2767 2813 2731 2704 2738 2824 2718 2748 2811 3003 3195 3310 3387 3579 3509 3582 3608 3416 3573 3689 3525 3275 3276 3372 3330 3221 3271 3265 3238 3422 3606 3911 3923 4042 4330 4378 4483 4307 4395 4314 4293 4169 4109 4152 4250 4154 4177 4244 4307 4065 4138 4029 4211 3979 3940 3929 3601 3416 3412 3443 3398 3378 3390 3342 3374 3281 3241 3253 3176 3098 3007 2966 2915 2876 2863 2823 2798 2758 2720 2733 2802 2658 2736 2865 2982 3099 3001 3150 3390 3416 3729 3804 4047 3999 3871 3740 3668 3401 3260 3202 3163 3242 3019 3268 3333 3399 3324 3439 3470 3513 3541 3563 3344 3267 3230 3062 2939 2934 3008 2817 2893 2926 2797 2941 2886 3021 2970 3052 2882 2909 3018 3067 3143 3222 3366 3424 3692 3916 4202 4380 4557 4862 4999 5016 4706 4451 4189 3887 3814 3679 3532 3555 3616 3538 3600 3833 3948 4292 4692 4765 5214 5424 5659 5909 5761 5811 5721 5591 5592 5730 5700 5841 5833 5454 5374 5037 4660 4658 4665 5114 5242 5432 5397 5310 5283 5097 4983 4842 4988 5010 4908 4985 4844 4446 4376 4071 3946 3836 3789 3765 3606 3602 3447 3487 3385 3505 3387 3417 3449 3600 3671 3671 3678 3591 3710 3562 3449 3450 3501 3430 3447 3400 3429 3419 3431 3227 3153 3094 3024 3018 2991 2957 3012 3000 2824 2915 2819 2894 2972 2932 2846 2872 2951 2859 2734 2692 2643 2648 2649 2625 2544 2579 2520 2645 2563 2562 2572 2561 2578 2583 2614 2560 2570 2647 2548 2613 2539 2579 2651 2554 2678 2712 2744 2826 2991 2893 3046 3216 3403 3377 3440 3624 3776 3723 3675 3767 3746 3575 3351 3228 3135 3080 2988 2948 2934 2914 3090 3077 3229 3229 3258 3440 3414 3416 3440 3334 3517 3376 3266 3175 3119 3112 2988 2853 2852 2811 2738 2746 2714 2587 2813 2749 2809 2731 2911 2916 2870 2885 2973 2972 3091 3033 3097 3374 3515 3719 3682 3733 3647 3381 3099 2999 2814 2897 2729 2726 2657 2758 2743 2646 2788 2812 2892 2904 3020 3062 3149 3047 2983 2783 2820 2675 2614 2561 2634 2637 2476 2523 2504 2536 2512 2551 2522 2529 2485 2564 2563 2528 2552 2639 2597 2728 2754 2803 2641 2823 2703 2718 2788 2748 2741 2726 2753 2802 2761 2717 2754 2748 2745 2750 2849 2825 2896 2915 2981 3214 3329 3387 3446 3540 3333 3325 3057 2936 2853 2778 2751 2794 2589 2604 2637 2720 2712 2841 2781 2669 2895 2786 2839 2912 2782 2824 2647 2629 2518 2510 2540 2600 2427 2437 2523 2467 2505 2539 2466 2430 2460 2463 2538 2448 2409 2474 2357 2482 2367 2498 2424 2336 2525 2396 2511 2514 2358 2418 2398 2344 2408 2404 2409 2420 2363 2455 2485 2468 2552 2514 2575 2562 2658 2624 2595 2630 2657 2638 2602 2572 2514 2591 2530 2435 2507 2524 2458 2502 2467 2465 2548 2557 2435 2506 2439 2492 2516 2539 2505 2565 2455 2482 2463 2473 2564 2457 2509 2551 2540 2440 2467 2427 2555 2437 2526 2458 2418 2605 2469 2540 2491 2595 2769 2680 2726 2677 2722 2883 2964 2983 2957 2969 2997 2942 3060 3088 3088 3229 3303 3285 3379 3332 3230 3291 3287 3466 3513 3727 3824 3862 3914 4189 4379 4346 4313 4369 4447 4015 3945 3712 3584 3593 3365 3304 3301 3363 3341 3333 3228 3178 3278 3308 3258 3378 3255 3304 3325 3165 2958 3002 2797 2804 2748 2844 2739 2712 2653 2585 2596 2495 2460 2594 2523 2497 2520 2575 2527 2673 2663 2637 2640 2632 2739 2890 2931 3011 3042 3136 3097 3103 2959 2921 2896 2817 2775 2565 2633 2578 2612 2627 2619 2572 2707 2652 2720 2650 2696 2712 2797 2977 2758 2854 2727 2732 2773 2575 2719 2668 2764 2704 2830 2711 2940 2930 3061 3213 3258 3313 3315 3218 3126 3090 2982 2880 2796 2793 2741 2705 2661 2697 2683 2710 2722 2723 2732 2890 2962 2926 2935 2973 2915 2849 2865 2726 2811 2755 2804 2763 2856 2963 3031 3197 3216 3285 3341 3526 3552 3560 3521 3391 3140 3009 2961 2929 2882 2825 2759 2747 2750 2760 2797 2773 2836 2863 2899 3044 2999 2990 2980 3007 2903 3027 2846 2821 2826 2812 2768 2782 2767 2872 2848 2920 3033 3023 3253 3489 3506 3764 3532 3363 3281 3107 3114 2975 2810 2901 2779 2864 2792 2886 2773 2754 2792 2832 2885 2935 3056 3157 3153 3120 3165 3062 3122 3197 3228 3270 3408 3679 3637 3699 3710 3889 3747 3712 3639 3431 3208 3234 3001 2891 2860 2979 2964 2901 2970 3062 3176 3131 3195 3324 3402 3291 3404 3293 3301 3233 3065 2997 2932 2855 2699 2742 2687 2658 2622 2644 2679 2595 2663 2687 2666 2683 2652 2622 2583 2585 2661 2642 2668 2581 2617 2504 2699 2679 2714 2743 2813 2997 2989 3184 3329 3323 3315 3199 3239 3059 3067 2846 2839 2778 2770 2703 2697 2747 2785 2784 2744 2754 2750 2816 2839 2848 2928 2987 2972 2840 2838 2903 2950 2884 2982 2957 2964 2820 2800 2938 2882 2776 2650 2751 2606 2640 2654 2657 2552 2569 2610 2528 2625 2686 2692 2664 2717 2777 2662 2812 2781 2867 2867 2897 2909 2940 3010 3050 3401 3423 3539 3650 3717 3536 3598 3341 3117 3145 3146 3077 3175 3161 3107 3256 3363 3426 3589 3594 3637 3676 3676 3751 3723 3702 3747 3543 3407 3468 3188 3139 3121 3091 3052 2993 3011 3023 3093 3160 3253 3272 3317 3472 3530 3563 3484 3583 3518 3278 3255 3147 2966 2890 2746 2796 2712 2618 2751 2746 2707 2787 2753 2884 2999 2941 2898 3023 3143 3239 3075 2990 3012 2881 2973 2909 2916 3033 2956 3002 3037 3112 3134 3109 3091 3013 2960 2950 2783 2769 2894 2835 2801 2887 2834 2887 2927 2868 2857 2999 3141 3206 3429 3396 3458 3565 3635 3584 3545 3623 3532 3507 3502 3393 3289 3239 3141 2972 2971 2930 2855 2863 2819 2919 3035 3132 3215 3319 3404 3376 3509 3626 3835 3982 4140 4105 4287 4241 4060 3971 3783 3559 3360 3267 3119 2984 2977 2952 2758 2925 2844 2940 2976 3055 3094 3172 3259 3324 3345 3420 3286 3277 3028 2998 2892 2910 2873 2805 2624 2792 2764 2658 2688 2766 2768 2740 2821 2877 2831 2968 2873 3018 3018 2923 2936 2994 3005 3013 2936 2873 2903 2935 2871 2938 2983 2923 2986 2922 2975 3042 2982 3120 3369 3257 3363 3507 3664 3767 3784 3717 3772 3564 3388 3405 3263 2985 3058 2985 2921 2862 2924 2906 2831 2739 2835 2865 2810 3007 2997 2993 2929 3050 3143 3046 2921 2821 2790 2683 2605 2625 2526 2604 2417 2520 2568 2527 2591 2531 2416 2505 2385 2499 2433 2422 2427 2388 2433 2483 2428 2393 2486 2545 2469 2437 2374 2434 2424 2428 2424 2449 2315 2483 2466 2407 2510 2514 2512 2539 2496 2593 2515 2535 2543 2531 2574 2673 2687 2713 2882 2883 2997 3126 3103 3144 3066 3089 2933 2783 2847 2767 2749 2715 2764 2733 2718 2679 2785 2881 2874 2877 2874 3099 3067 3055 2896 2999 3004 2936 2875 2737 2913 2665 2620 2638 2712 2681 2672 2597 2556 2606 2683 2583 2599 2674 2733 2695 2653 2573 2581 2672 2643 2634 2670 2734 2875 2970 2958 3005 3114 3134 3060 2990 3149 3041 3128 3092 3112 3141 3174 3256 3295 3246 3125 3089 2992 2866 2882 2873 2802 2797 2752 2789 2921 2757 2805 2841 2892 2724 2779 2753 2741 2846 2818 2833 2887 2916 2663 2731 2618 2598 2626 2483 2504 2490 2614 2509 2506 2509 2467 2424 2473 2404 2473 2441 2475 2332 2416 2445 2387 2475 2466 2457 2478 2493 2430 2475 2441 2449 2344 2409 2394 2447 2498 2416 2487 2379 2376 2434 2496 2410 2418 2428 2407 2413 2403 2306 2396 2393 2379 2539 2424 2352 2413 2379 2393 2503 2365 2362 2499 2416 2323 2445 2345 2398 2458 2468 2499 2474 2467 2570 2453 2521 2568 2705 2552 2562 2540 2514 2590 2622 2449 2552 2435 2411 2351 2509 2373 2454 2540 2433 2518 2470 2565 2492 2542 2525 2495 2541 2501 2540 2483 2455 2529 2591 2548 2566 2686 2735 2741 2684 2732 2891 3054 3087 3291 3348 3490 3599 3591 3630 3478 3385 3319 3207 3234 3132 3222 3178 3328 3317 3339 3356 3345 3519 3445 3527 3459 3239 3331 3300 3232 3258 3297 3200 3070 3002 2891 2906 2885 2963 2914 2899 3008 2779 3055 2992 2827 2938 2847 2853 2794 2849 2715 2748 2604 2673 2611 2570 2564 2573 2458 2497 2452 2676 2570 2493 2479 2551 2614 2586 2482 2646 2594 2744 2866 2770 2914 2874 2959 3216 3209 3262 3398 3405 3518 3497 3366 3331 3216 3197 3166 2965 2975 2779 2879 2849 2635 2661 2609 2755 2732 2657 2753 2774 2936 2959 2985 2924 3014 2903 2969 2959 3014 2865 2790 2746 2725 2688 2717 2694 2586 2598 2496 2489 2551 2511 2512 2550 2609 2540 2443 2486 2560 2494 2612 2614 2594 2546 2739 2645 2595 2737 2665 2901 2911 2983 2880 3001 2916 3052 3128 3137 3076 3193 3286 3365 3270 3318 3232 3290 3379 3398 3565 3680 3742 3651 3715 3762 3723 3661 3504 3392 3361 3395 3222 3233 3275 3255 3088 3115 3153 3190 3233 3305 3323 3436 3441 3497 3684 3668 3843 3904 4025 4187 4138 4266 4236 4142 4110 4125 4035 4180 4194 4159 4309 4366 4569 4581 4650 4580 4649 4521 4434 4332 4210 4071 3990 3936 3822 3811 3822 3784 3704 3385 3422 3435 3347 3313 3374 3344 3522 3475 3575 3507 3481 3427 3510 3395 3309 3276 3051 3149 3086 2968 2894 2726 2868 2766 2851 2774 2679 2649 2718 2674 2724 2663 2779 2702 2794 2759 2875 2959 2982 3068 3384 3320 3357 3330 3218 3064 3059 3064 2956 2876 2996 3038 2931 2907 2970 2944 2960 2952 2945</intensities>
			</dataPoints>
			<nonAmbientPoints type="Temperature" unit="K">
[...]
			</nonAmbientPoints>
		</scan>
	</xrdMeasurement>
</xrdMeasurements>