File: powder_X-ray_diffraction/variable-temperature_experiments/NaTaO2F2/raw_data/270°C.xrdml
<?xml version="1.0" encoding="UTF-8"?>
<xrdMeasurements xmlns="http://www.xrdml.com/XRDMeasurement/1.7" xmlns:xsi="http://www.w3.org/2001/XMLSchema-instance" xsi:schemaLocation="http://www.xrdml.com/XRDMeasurement/1.7 http://www.xrdml.com/XRDMeasurement/1.7/XRDMeasurement.xsd" status="Completed">
	<comment>
		<entry>Configuration=XRK900, Owner=User-1, Creation date=12/01/2015 16:52:44</entry>
		<entry>Goniometer=Theta/Theta; Minimum step size 2Theta:0.0001; Minimum step size Omega:0.0001</entry>
		<entry>Sample stage=AP XRK-900 with z-axis; Minimum step size Z:0.001</entry>
		<entry>Diffractometer system=EMPYREAN</entry>
		<entry>Measurement program=C:\PANalytical\Data Collector\Programs\Gwen\NaTaO2F2\NaTaO2F2-Lent.xrdmp, Identifier={FF50B583-C5FF-42DA-A01D-A1FB659EF29A}</entry>
		<entry>Batch program=C:\PANalytical\Data Collector\Programs\Gwen\NaTaO2F2\Thermodiff-Ouail.xrdmp, Identifier={5D65A6B1-42FC-480C-9FBB-D7D88D55EA08}</entry>
	</comment>
	<sample type="To be analyzed">
		<id></id>
		<name></name>
		<preparedBy></preparedBy>
	</sample>
	<xrdMeasurement measurementType="Scan" status="Completed" sampleMode="Reflection">
		<comment>
			<entry>PHD Lower Level = 4.02 (keV), PHD Upper Level = 12.07 (keV)</entry>
		</comment>
		<usedWavelength intended="K-Alpha 1">
			<kAlpha1 unit="Angstrom">1.5405980</kAlpha1>
			<kAlpha2 unit="Angstrom">1.5444260</kAlpha2>
			<kBeta unit="Angstrom">1.3922500</kBeta>
			<ratioKAlpha2KAlpha1>0.5000</ratioKAlpha2KAlpha1>
		</usedWavelength>
		<incidentBeamPath>
			<radius unit="mm">240.00</radius>
			<xRayTube id="1010048" name="Empyrean Cu LFF HR (9430 033 7310x) DK434948">
				<tension unit="kV">45.0</tension>
				<current unit="mA">30.0</current>
				<anodeMaterial>Cu</anodeMaterial>
				<focus type="Line">
					<length unit="mm">12.0</length>
					<width unit="mm">0.4</width>
					<takeOffAngle unit="deg">6.0</takeOffAngle>
				</focus>
			</xRayTube>
			<sollerSlit id="21010001" name="Soller slits 0.02 rad.">
				<opening unit="rad">0.0200</opening>
			</sollerSlit>
			<mask id="22030010" name="Fixed mask 20 mm">
				<width unit="mm">20.00</width>
			</mask>
			<antiScatterSlit id="22010003" name="Fixed slit 1Â°" xsi:type="fixedAntiScatterSlitType">
				<height unit="mm">1.52</height>
			</antiScatterSlit>
			<divergenceSlit id="22010012" name="Programmable divergence slit" xsi:type="fixedDivergenceSlitType">
				<distanceToSample unit="mm">140.00</distanceToSample>
				<angle unit="deg">0.5</angle>
			</divergenceSlit>
		</incidentBeamPath>
		<diffractedBeamPath>
			<radius unit="mm">240.00</radius>
			<antiScatterSlit id="22090010" name="AS slit 8.0 mm (PIXcel)" xsi:type="fixedAntiScatterSlitType">
				<height unit="mm">8.00</height>
			</antiScatterSlit>
			<sollerSlit id="21010001" name="Soller slits 0.02 rad.">
				<opening unit="rad">0.0200</opening>
			</sollerSlit>
			<filter id="20030001" name="Large beta-filter Nickel">
				<material>Ni</material>
				<thickness unit="mm">0.020</thickness>
			</filter>
			<detector id="7010019" name="PIXcel1D-Medipix3 detector" xsi:type="rtmsDetectorType">
				<phd unit="%">
					<lowerLevel>25.0</lowerLevel>
					<upperLevel>75.0</upperLevel>
				</phd>
				<mode>Scanning</mode>
				<activeLength unit="deg">3.3482</activeLength>
			</detector>
		</diffractedBeamPath>
		<scan appendNumber="0" mode="Continuous" scanAxis="Gonio" status="Completed">
			<header>
				<startTimeStamp>2023-01-22T20:25:04+01:00</startTimeStamp>
				<endTimeStamp>2023-01-22T23:25:30+01:00</endTimeStamp>
				<author>
					<name>User</name>
				</author>
				<source>
					<applicationSoftware version="5.5a">Data Collector</applicationSoftware>
					<instrumentControlSoftware version="8.2  20201204">EMPYREAN</instrumentControlSoftware>
					<instrumentID>0000000011159748</instrumentID>
				</source>
			</header>
			<dataPoints>
				<positions axis="2Theta" unit="deg">
					<startPosition>9.99846514</startPosition>
					<endPosition>99.99342261</endPosition>
				</positions>
				<positions axis="Omega" unit="deg">
					<startPosition>4.99923257</startPosition>
					<endPosition>49.99671130</endPosition>
				</positions>
				<positions axis="Z" unit="mm">
					<commonPosition>8.846</commonPosition>
				</positions>
				<commonCountingTime unit="seconds">386.070</commonCountingTime>
				<intensities unit="counts">6370 6289 6441 6385 6455 6412 6347 6325 6237 6267 6407 6257 6279 6225 6105 6129 6225 6300 6227 6277 6232 6241 6237 6206 6140 6210 5945 6174 6244 6151 6090 6018 6275 6192 6128 6186 6171 6079 6118 6026 6116 6086 6088 6061 6085 6051 5998 6095 6083 6131 6008 6048 6068 6068 6197 6246 6262 6303 6358 6142 6160 6330 6489 6326 6377 6339 6447 6379 6625 6642 6946 6841 7085 7355 8015 8642 9477 10900 12623 15786 20412 25467 32667 41388 47605 49847 47678 40828 32911 25546 19692 14373 10918 8868 7763 7108 6784 6716 6380 6223 6369 6340 6160 6079 5935 5981 5889 6020 5868 5989 5780 5905 5857 5910 5895 5863 5924 5756 5719 5762 5892 5754 5741 5833 5833 5638 5853 5715 5788 5864 5778 5659 5634 5739 5807 5752 5720 5729 5605 5649 5713 5622 5640 5723 5674 5750 5584 5709 5668 5463 5566 5673 5400 5656 5591 5643 5779 5483 5626 5675 5640 5480 5555 5503 5512 5496 5551 5665 5622 5671 5510 5598 5637 5581 5502 5470 5528 5503 5535 5704 5620 5508 5440 5552 5327 5445 5355 5466 5528 5474 5515 5580 5386 5402 5336 5418 5324 5482 5412 5428 5294 5331 5379 5550 5398 5455 5437 5228 5395 5474 5361 5405 5331 5453 5227 5414 5244 5317 5230 5232 5432 5239 5151 5285 5285 5263 5230 5227 5201 5296 5221 5234 5156 5260 5389 5060 5249 5176 5276 5282 5296 5225 5241 5215 5338 5362 5367 5117 5200 5176 5271 5198 5198 5269 5222 5202 5230 5203 5128 5148 5154 5188 5241 5160 5064 5120 5165 5097 5417 5029 5071 5247 5173 5057 5047 5212 5192 5189 5223 5081 5020 4967 5103 5101 5199 4889 5078 5224 5141 5079 5192 5009 5094 5067 5055 5046 5022 5012 5063 5104 4930 4977 5168 5017 4948 4971 4947 5017 5108 5028 5061 4985 5037 4952 5088 4855 4854 5022 4934 4969 4973 4967 4993 4987 4842 5079 5033 4914 4910 5029 4971 5003 4965 4940 4973 4923 4787 5106 4909 4922 4918 4906 4847 4857 4879 4962 4907 5020 5049 4866 4931 4873 4913 4929 4805 4865 4867 4777 4803 4815 4705 4717 4766 4825 4847 4813 4849 4816 4883 4904 4808 4802 4727 4832 4889 4873 4767 4732 4703 4781 4821 4768 4807 4824 4830 4726 4780 4821 4812 4672 4761 4725 4756 4666 4684 4747 4731 4907 4680 4882 4671 4757 4719 4774 4710 4729 4760 4658 4664 4728 4663 4603 4822 4704 4660 4705 4639 4717 4696 4777 4695 4723 4631 4760 4635 4702 4719 4722 4713 4694 4704 4655 4654 4713 4629 4603 4714 4675 4676 4713 4681 4680 4750 4516 4746 4644 4735 4679 4597 4692 4732 4617 4489 4484 4561 4660 4636 4480 4604 4704 4571 4733 4672 4623 4728 4705 4617 4711 4816 4886 4750 4717 4688 4826 4704 4847 4726 4736 4717 4712 4754 4782 4712 4777 4778 4638 4796 4829 4706 4705 4563 4569 4706 4697 4563 4693 4638 4609 4532 4642 4519 4428 4608 4533 4540 4488 4499 4546 4639 4498 4514 4535 4442 4517 4463 4446 4474 4417 4482 4486 4513 4512 4445 4533 4495 4557 4547 4475 4522 4430 4334 4325 4496 4403 4376 4534 4535 4404 4478 4494 4409 4398 4500 4416 4528 4566 4530 4429 4598 4547 4553 4639 4418 4597 4478 4441 4410 4471 4409 4431 4361 4364 4378 4342 4395 4319 4401 4460 4428 4364 4305 4452 4381 4287 4354 4280 4520 4466 4352 4395 4304 4210 4352 4295 4359 4507 4439 4588 4767 4464 4688 4504 4490 4416 4369 4293 4349 4380 4355 4367 4406 4193 4363 4165 4221 4279 4306 4220 4279 4424 4352 4294 4251 4143 4271 4328 4228 4199 4079 4229 4235 4100 4150 4267 4183 4196 4236 4185 4098 4289 4147 4171 4188 4102 4294 4208 4269 4237 4212 4025 4184 4270 4283 4088 4183 4260 4205 4243 4137 4234 4201 4162 4231 4295 4182 4092 4082 4312 4202 4303 4272 4230 4105 4181 4236 4098 4069 4071 4067 4078 4137 4064 4138 4136 4151 4257 4156 4200 4181 4167 4197 4231 4361 4366 4450 4500 4516 4495 4536 4486 4449 4499 4619 4514 4549 4716 4497 4642 4578 4548 4563 4374 4524 4635 4554 4497 4587 4616 4580 4518 4754 4758 4752 4807 4929 5087 5051 5291 5373 5466 5735 6052 6365 7085 7685 9033 10933 14196 18862 26671 39634 59138 81770 104948 120577 119926 112705 103764 91116 71902 54081 39414 27801 19233 13954 10578 8442 7366 6632 6002 5759 5450 5257 4996 4865 4687 4758 4603 4494 4470 4533 4483 4446 4367 4289 4339 4297 4352 4362 4426 4396 4427 4522 4330 4504 4492 4438 4529 4288 4515 4373 4142 4212 4152 4062 4112 4097 4092 4086 4135 4169 4053 4077 4094 3979 4160 4172 3943 4011 4111 4056 4035 3977 3935 4107 3982 4194 4166 4039 4037 4000 4080 4034 4012 4018 3954 3987 4060 3890 3978 3955 3927 3934 3886 3972 3974 3926 4103 3972 3942 3814 3939 3807 3925 3939 3843 3864 3952 3904 3901 3915 3941 3869 3882 4001 3982 3928 3809 3990 3944 3855 3946 3826 3857 3794 3783 3850 3883 3843 3721 3892 3887 3864 3757 3818 3786 3865 3945 3801 3808 3790 3869 3887 3827 3763 3884 3819 3832 3712 3768 3689 3834 3842 3847 3931 3882 3813 3854 3818 3933 3751 3904 3833 3735 3848 3960 4025 4088 4161 4112 4132 4101 4170 4023 3873 3910 3925 3823 3828 3824 4009 4039 3976 4001 3911 3994 3946 3853 3926 3751 3797 3887 3909 3910 3913 3965 3942 4088 4024 4075 4323 4356 4693 5304 6034 6885 8839 11836 15586 18423 18985 18015 16490 15165 13411 11017 8937 7227 6060 4986 4497 4327 4099 4011 3968 4041 3898 3847 3851 3772 3740 3882 3725 3811 3794 3761 3655 3755 3682 3716 3953 3773 3800 3811 3803 3850 3825 3719 3843 3777 3793 3739 3729 3654 3774 3759 3701 3728 3640 3737 3658 3657 3636 3687 3639 3750 3593 3645 3674 3704 3695 3538 3587 3638 3584 3583 3638 3528 3591 3611 3542 3641 3639 3774 3649 3763 3692 3657 3613 3657 3699 3650 3659 3703 3727 3724 3777 3731 3771 3777 3869 3808 3931 3859 3835 3870 3949 3852 3783 3898 3791 3872 3789 3868 3917 3958 3844 4009 3962 3879 3807 3902 3892 3863 3864 3916 4016 4085 4091 4206 4235 4287 4324 4195 4425 4439 4524 4568 4605 4786 5003 5231 5632 6294 7532 9675 13250 19428 26803 35836 41524 44390 43513 40163 36234 32319 29387 25837 22406 21646 26265 33121 38379 42979 47448 47598 43570 39540 35722 30261 23960 18162 14371 10772 7919 6306 5405 4885 4708 4501 4354 4205 4152 4047 4126 3919 3828 3861 3773 3930 3869 3850 3861 3873 3726 3810 3668 3641 3627 3691 3748 3745 3624 3694 3738 3709 3750 3657 3931 3863 4029 3880 3743 3805 3767 3619 3733 3655 3581 3594 3547 3696 3619 3631 3658 3497 3598 3517 3645 3607 3572 3570 3545 3605 3680 3492 3676 3528 3584 3611 3618 3537 3702 3662 3663 3561 3654 3608 3722 3637 3531 3522 3518 3579 3658 3508 3475 3454 3528 3532 3492 3576 3517 3511 3525 3571 3489 3447 3359 3562 3512 3521 3529 3443 3440 3565 3452 3473 3454 3457 3527 3509 3390 3357 3424 3569 3382 3495 3447 3437 3584 3506 3579 3485 3578 3594 3684 3552 3727 3711 3710 3706 3679 3821 3597 3617 3622 3609 3599 3601 3508 3511 3510 3611 3463 3526 3570 3498 3554 3554 3440 3525 3447 3497 3389 3438 3387 3409 3469 3430 3479 3490 3370 3400 3435 3517 3406 3501 3361 3454 3514 3363 3552 3376 3511 3506 3662 3573 3594 3607 3629 3589 3715 3457 3613 3573 3575 3751 3624 3561 3659 3629 3612 3622 3539 3689 3612 3618 3654 3559 3608 3816 3648 3787 3551 3716 3739 3665 3646 3750 3650 3586 3633 3580 3568 3596 3695 3648 3682 3795 3771 3876 3865 3878 3927 4070 4234 4257 4419 4425 4668 4955 5172 5286 5596 5984 6404 7036 7875 9252 11317 14733 21342 31472 46593 65998 81270 85687 80429 72785 66497 62484 57070 47952 37525 28331 20720 15281 10992 8466 6900 6220 5516 5230 4830 4758 4468 4270 4086 4075 3901 3906 3837 3789 3751 3628 3757 3708 3774 3641 3714 3726 3792 3672 3759 3751 3758 3943 3834 3907 3860 3882 3794 3862 3904 3793 3652 3721 3612 3668 3643 3642 3397 3646 3618 3571 3553 3631 3554 3601 3622 3575 3605 3565 3531 3584 3609 3560 3484 3512 3683 3415 3420 3548 3535 3631 3455 3609 3513 3470 3530 3647 3506 3570 3584 3607 3543 3515 3595 3606 3619 3751 3693 3586 3745 3658 3857 3899 3854 4006 4056 4057 4298 4391 4635 4966 5182 5525 6542 8580 12133 17323 24176 29654 32694 32579 29174 25795 25072 24279 23771 22835 21589 21232 21639 21689 21035 18992 16615 15012 13535 12520 11433 9591 7837 6340 5141 4553 4129 4088 3804 3812 3763 3649 3486 3531 3465 3436 3414 3410 3370 3448 3269 3428 3422 3313 3424 3384 3427 3369 3318 3198 3385 3326 3415 3443 3473 3395 3385 3307 3471 3399 3302 3438 3250 3320 3289 3387 3202 3367 3405 3344 3327 3375 3232 3245 3330 3301 3155 3342 3390 3338 3334 3440 3244 3326 3432 3345 3261 3329 3277 3198 3246 3232 3219 3309 3295 3228 3389 3274 3183 3237 3220 3247 3143 3178 3240 3103 3157 3198 3247 3185 3254 3262 3179 3269 3132 3145 3155 3139 3241 3009 3028 3109 3191 3137 3299 3198 3184 3213 3161 3312 3229 3152 3081 3134 3167 3183 3124 3099 3159 3221 3145 3129 3079 3154 3208 3103 3120 3118 3099 3120 3090 3144 3086 3139 3049 3064 2995 3038 3056 3172 3181 2959 3097 3065 3148 3099 3130 3118 3092 3216 3099 3103 3037 3134 3184 3179 3226 3216 3163 3130 3074 3231 3168 3097 3097 3122 3174 3105 3028 3126 3143 3129 3042 3095 3136 3150 3082 3217 3132 3192 3053 3164 3155 3172 2983 3152 3097 3088 3231 3100 3054 3066 3140 3054 3052 3162 3107 3028 3080 3115 3198 3151 3306 3160 3144 3126 3312 3247 3295 3186 3194 3284 3147 3259 3143 3265 3326 3346 3302 3301 3203 3222 3228 3297 3430 3409 3307 3575 3548 3779 3814 3789 3834 3904 4275 4692 5399 7150 10064 15168 19372 20911 18954 15393 12950 12435 13103 13318 12372 10214 8058 6257 5229 4667 4174 3925 3678 3698 3667 3484 3474 3480 3444 3431 3468 3562 3612 3590 3667 3744 3645 3836 4026 4025 4013 4182 4197 4506 4664 4829 5406 6120 7659 10463 14951 21208 28552 34316 35305 32345 27897 23834 22140 21923 21561 19597 16534 13009 9788 7433 6283 5450 5240 5091 5010 4828 5057 5106 5426 5905 6726 8135 10647 14234 18972 24178 28223 30881 30556 28362 25325 22579 21185 20406 19785 18761 17902 17884 18532 18822 17609 14804 12279 10590 10078 10457 10461 9661 7953 6520 5360 4525 4009 3844 3639 3595 3498 3533 3376 3410 3303 3227 3344 3300 3345 3268 3237 3173 3272 3180 3127 3203 3182 3256 3187 3198 3224 3230 3263 3283 3254 3282 3379 3340 3485 3293 3444 3376 3540 3564 3543 3571 3890 4279 4816 6081 8024 10899 13455 14668 13486 11654 9993 9176 9161 9292 9197 8343 7112 5683 4927 4173 3672 3638 3501 3392 3289 3221 3172 3136 3227 3299 3527 3541 3494 3460 3399 3294 3195 3343 3286 3202 3233 3209 3118 3166 3051 2869 3063 3072 3005 2925 3068 2930 3071 2947 2957 2997 2970 2875 2996 3007 2934 2940 2916 2934 2926 2963 2953 3029 3070 2873 2877 2925 3031 2898 2917 2960 2861 2969 2903 2992 2948 2983 2959 3011 3007 2906 2885 2918 2971 2883 3008 2954 2964 2943 2843 2779 2922 2971 2955 2863 3027 2909 2952 2938 2944 2971 2875 2843 2968 2995 2916 2859 2861 3062 3081 2895 2940 2970 2907 2965 2977 2938 3025 2986 2922 2917 2985 2823 2955 2891 2871 3012 2991 2957 2968 2903 2875 2941 2966 2916 2903 2935 2833 2863 2846 2974 2993 2977 2914 3077 2973 2929 3028 3018 3052 3060 3050 3093 3290 3238 3412 3482 3765 4289 5312 6657 8208 9227 9219 8611 7060 6058 5837 6094 6400 6302 5824 5142 4299 3827 3540 3226 3195 3090 3056 3013 3049 3089 3167 3046 3056 3045 2969 3140 3038 3064 3047 3151 3123 3189 3098 3253 3261 3303 3449 3618 4013 4513 5501 6713 8219 9210 10076 9874 9052 8290 7353 6882 6720 6916 6589 6240 5390 4718 3989 3569 3377 3210 3175 3135 3041 3170 3338 3339 3443 3591 3414 3452 3299 3270 3161 3384 3441 3371 3170 3079 3097 2995 3048 2907 2948 2880 2854 2888 2819 2781 2812 2822 2813 2820 2741 2726 2681 2843 2796 2737 2743 2803 2812 2726 2719 2818 2755 2842 2779 2790 2746 2716 2849 2837 2801 2789 2782 2765 2713 2808 2805 2749 2719 2718 2787 2800 2766 2764 2760 2792 2708 2806 2759 2854 2729 2809 2725 2754 2762 2795 2749 2670 2822 2853 2748 2895 2954 2622 2781 2805 2802 2679 2816 2770 2808 2708 2772 2850 2758 2796 2896 2734 2848 2742 2678 2847 2759 2794 2714 2766 2837 2834 2767 2746 2877 2812 2783 2772 2791 2743 2867 2745 2707 2844 2768 2720 2754 2727 2717 2718 2727 2724 2703 2730 2676 2709 2731 2853 2866 2748 2717 2694 2691 2820 2786 2887 2815 2763 2750 2826 2873 2744 2940 2784 2835 2884 2830 2864 2992 3053 3313 3520 3775 4391 4623 4651 4659 4514 4224 4046 3927 3843 3934 3957 3870 3683 3587 3485 3345 3402 3351 3425 3961 4345 5186 6347 7575 8003 7431 6600 5928 5418 5185 5360 5624 5663 5308 4982 4330 3944 3616 3424 3391 3250 3249 3143 3109 3260 3228 3199 3274 3487 3707 4164 5006 6265 7993 9582 10377 9843 8255 7027 6168 5894 6241 6768 6910 6544 5727 4828 4194 3643 3316 3295 3155 3102 3013 3013 2970 3192 3037 3031 3108 2950 3111 3053 3136 3220 3247 3320 3356 3626 3946 4217 4630 5575 6768 8194 9735 11317 11407 10660 9303 8147 7346 7393 7948 8483 8968 9353 10164 11473 12676 13415 13123 11864 10611 9884 10874 13046 14903 16716 16523 14566 11929 9620 8263 7705 7841 7908 7914 7086 5961 5123 4410 3810 3504 3310 3109 2999 3018 2890 2895 2859 2930 2982 2819 2830 2703 2735 2824 2744 2957 2863 2755 2795 2824 2790 2791 2750 2751 2742 2720 2718 2657 2800 2779 2727 2804 2794 2744 2704 2680 2695 2823 2583 2715 2690 2680 2675 2734 2726 2644 2676 2656 2680 2677 2639 2654 2737 2740 2748 2674 2619 2606 2735 2675 2642 2658 2741 2691 2764 2660 2737 2673 2644 2710 2740 2716 2715 2810 2771 2732 2759 2598 2654 2688 2683 2720 2771 2718 2647 2595 2740 2691 2679 2729 2696 2642 2611 2662 2718 2628 2667 2722 2676 2722 2813 2706 2701 2816 2560 2559 2609 2816 2649 2713 2699 2650 2797 2766 2796 2762 2786 2823 2728 2702 2657 2679 2725 2728 2749 2721 2704 2730 2683 2670 2683 2660 2668 2735 2679 2584 2652 2804 2702 2754 2750 2670 2749 2717 2789 2895 2883 2891 3137 3186 3289 3173 3214 3061 2980 2896 2967 3061 2988 2987 2933 2994 2904 2803 2663 2700 2695 2621 2697 2660 2701 2570 2762 2601 2566 2738 2761 2627 2609 2718 2693 2732 2700 2669 2772 2686 2650 2650 2696 2703 2643 2665 2622 2706 2690 2690 2768 2741 2817 2730 2704 2677 2759 2828 2937 2872 3061 3386 3549 3957 4134 4191 3938 3757 3424 3363 3299 3344 3549 3535 3468 3512 3301 3139 3124 2987 3123 3227 3421 3642 4180 4550 5107 5539 5426 5292 4901 4473 4145 3961 4019 4216 4088 4069 3817 3667 3392 3269 3063 2973 2917 2818 2805 2904 2677 2707 2756 2759 2723 2714 2726 2732 2841 2706 2782 2672 2697 2796 2713 2580 2782 2797 2651 2681 2688 2658 2626 2625 2604 2549 2698 2733 2593 2724 2725 2711 2696 2728 2688 2730 2719 2767 2710 2605 2687 2730 2813 2791 2724 2734 2742 2807 2763 2751 2804 2820 2940 2875 2985 2947 2954 2962 3014 2979 3069 3114 3248 3462 3870 4574 5571 7206 9378 11064 11607 10224 7706 6309 5180 4964 5519 6279 6976 7182 6614 5500 4492 3786 3423 3038 3024 2885 2869 2771 2781 2753 2713 2733 2822 2741 2814 2739 2767 2801 2836 2813 2798 2791 2749 2896 2768 2873 2938 2776 2826 2929 2879 2973 2879 3003 3000 3040 3149 3310 3688 4144 4987 6010 6801 7213 6583 5442 4647 4033 3967 4108 4416 4850 5165 4945 4310 3852 3469 3239 3144 2971 3017 2891 2940 2809 2921 2907 2823 2843 2855 2795 2822 2802 2783 2719 2872 2846 2878 2863 2859 2887 2950 2957 2965 3037 3105 3206 3170 3422 3635 4070 4664 5481 6585 7377 8345 8726 8507 7768 6573 5655 5288 5305 5515 5586 5898 5977 5593 4968 4270 3759 3416 3290 3211 3167 3129 3078 2993 2996 3040 3115 3146 3258 3097 3203 3236 3217 3245 3422 3397 3384 3360 3392 3538 3628 3735 3835 4019 4350 4746 5265 5946 7408 9037 11601 14950 18420 20421 20025 18246 15061 12904 11105 10140 10542 11425 12356 12342 11565 9973 8410 6983 5736 4945 4557 4044 3883 3777 3485 3346 3334 3322 3249 3180 3177 3217 3217 3168 3164 3296 3223 3303 3297 3429 3480 3441 3673 3794 4069 4665 5763 7396 9246 11208 12397 12790 13002 13214 13006 12465 11793 11095 10473 10028 9503 8782 8716 8476 8299 7556 6823 6159 5418 4836 4314 4118 4316 4433 5118 5950 7358 9434 11554 13154 13345 11699 9582 7738 6556 6318 6258 7042 7867 8237 7959 7306 6166 4995 4402 3844 3669 3293 3251 3223 3200 3080 3019 2986 2927 2922 3026 2960 2831 2874 2845 2920 2843 2869 2804 2952 2929 2972 2929 2859 2914 2925 2840 2893 3033 3033 2961 3052 3213 3281 3402 3502 3449 3531 3348 3269 3168 3280 3202 3302 3299 3399 3499 3496 3493 3572 3495 3555 3701 3469 3392 3425 3341 3402 3455 3400 3522 3642 3664 3671 3739 3796 3959 4199 4351 5010 5655 6969 8652 11599 14840 17527 18916 18366 16553 13471 11141 10028 9580 9962 10758 11478 11857 11313 10235 8682 7151 6376 5523 4853 4483 4266 3992 3924 3739 3795 3748 3813 3939 3948 4457 5004 5542 6592 7790 9108 10501 11344 11592 10661 8871 7876 6964 6465 6637 6819 7187 7459 7498 6956 6076 5335 4773 4246 3845 3525 3384 3300 3280 3098 2991 3052 3005 3050 2996 2935 2859 2979 2871 2871 2905 2810 2815 3036 2762 2872 2855 2825 2818 2883 2933 2958 2885 2904 2862 3009 3021 2917 3003 2964 3004 2957 2976 2970 3137 3219 3309 3376 3642 4037 4896 5840 7354 8550 8831 8783 7492 6240 5342 4914 4626 4761 5302 5804 5935 5980 5547 4865 4486 4034 3900 3920 3813 3729 3451 3384 3238 3082 3201 3085 3003 3226 3165 3170 3088 3040 3069 2946 2877 2871 2862 2876 2802 2877 2827 2821 2972 2780 2838 2816 2896 2853 2814 2820 2772 2693 2844 2822 2894 2822 2844 2819 2847 2880 2851 2753 2856 2717 2803 2847 2867 2872 2743 2818 2921 2892 2856 2998 2968 2942 3034 3026 2967 3007 3075 3173 3150 3179 3261 3405 3511 3756 4383 5112 6138 7186 8447 9809 10332 10261 10009 9363 8169 7144 6248 6075 6051 6368 6784 6854 6835 6472 5850 5251 4588 4324 3851 3820 3967 4090 4397 4804 5132 5507 5862 5972 6196 6277 6058 5774 5438 4972 4700 4608 4507 4512 4535 4325 4332 4334 4257 3837 3507 3327 3083 3009 2862 2781 2886 2755 2760 2808 2705 2810 2772 2692 2851 2712 2833 2800 2828 2775 2867 2865 2768 2870 2940 2818 2823 2854 2941 3018 3191 3370 3475 3765 3933 4211 4216 4199 3803 3586 3368 3295 3234 3247 3267 3402 3329 3396 3266 3206 3134 2992 2874 2800 2914 2817 2832 2868 2783 2725 2702 2630 2675 2771 2617 2680 2689 2751 2725 2668 2772 2747 2671 2805 2715 2756 2797 2711 2771 2797 2822 2787 2770 2861 2982 2943 3042 3041 3123 3033 3168 3131 2960 3021 2999 2953 2968 2896 2875 2914 2804 2906 2990 2812 2902 2785 2785 2711 2696 2663 2795 2685 2772 2651 2716 2642 2721 2777 2774 2773 2708 2598 2693 2725 2743 2778 2655 2746 2773 2736 2803 2739 2804 2775 2664 2731 2690 2699 2730 2801 2813 2720 2804 2824 2843 2809 2906 2852 2959 2957 2944 3047 3069 3010 3022 3014 3105 3288 3318 3437 3526 3803 4213 4941 5620 6682 8541 10169 11445 11945 11318 9522 7972 6773 5981 5834 5716 6163 6897 7594 7770 7538 6962 5920 5085 4531 4102 3840 3530 3675 3515 3636 3659 3613 3408 3278 3181 3142 3062 2954 3055 3075 3049 3009 3061 3151 2929 2948 2969 2915 2746 2839 2984 2965 2845 2913 2841 2925 2935 2849 2866 2894 2972 3013 3076 3018 3092 3142 3182 3358 3567 3651 4124 4461 4957 5735 6021 6528 6574 6721 7086 7827 9277 10489 11929 12895 13403 12775 11743 10124 8732 7475 6804 6645 6988 7394 7694 7672 7678 7027 6319 5608 4830 4309 3821 3625 3421 3435 3326 3147 3150 3033 3168 3102 3140 3081 3223 2993 3059 3195 3214 3281 3091 3333 3351 3350 3517 3634 3914 4456 4799 5463 6394 7117 7795 8328 8809 9527 9677 9889 9795 9279 8448 7734 7018 6906 6737 6694 6920 7248 7519 7620 8043 8433 8592 8625 8033 7076 6254 5453 4930 4546 4213 4306 4344 4690 4914 5071 4941 4688 4371 3898 3666 3418 3311 3216 3142 3063 3111 2960 3080 3040 3077 3006 3008 3119 3096 3057 3114 3153 3225 3269 3250 3525 3638 3848 4141 4610 5135 6221 7307 8301 9140 8833 8054 7181 6191 5494 5180 5047 5565 5877 6619 7117 7277 7068 6294 5545 4835 4311 4041 3958 3820 3810 3868 3890 3711 3737 3676 3473 3340 3328 3366 3249 3352 3436 3490 3596 3752 3923 4295 4621 5587 6148 6942 7592 8282 8731 8474 8139 7025 6265 5615 5246 5259 5444 5635 6231 6762 7207 7643 8238 8779 9428 9603 9699 8947 7564 6436 5744 5116 4799 4900 5104 5717 6097 6767 7166 7594 7776 8152 8479 9255 9641 9616 9070 7906 6629 5912 5342 5103 4964 5128 5546 5801 6043 6309 5964 5395 4777 4317 3927 3551 3521 3339 3166 3054 3055 3119 2999 3056 2972 3112 3037 3031 3012 3081 3100 3025 3012 3064 3132 3090 3134 3320 3394 3517 3920 4398 5018 5400 6140 7064 7721 8115 8449 8170 7503 6824 6060 5462 5158 5122 5124 5227 5812 6152 6452 6780 6932 7154 7049 7309 7720 8084 9101 9947 10983 11178 10846 9608 8044 6862 6196 5882 5703 5823 5892 6205 6826 6934 6947 6461 5543 4855 4247 3890 3460 3393 3268 3197 3129 3118 3133 2976 3090 2990 2936 3053 2964 3016 3110 3104 3127 3151 3161 3221 3286 3343 3283 3364 3476 3629 3776 3926 4302 4785 5266 6206 7641 9560 11586 13344 14362 14377 13335 11655 10129 8661 7638 7111 7118 7508 8386 9293 10084 10589 10222 9345 8590 7540 6813 6205 5459 5041 5085 5002 5157 5361 5453 5471 5602 5563 5581 5337 5043 4708 4291 3958 3797 3729 3755 3677 3624 3734 3725 3675 3617 3499 3205 3096 3063 2917 2806 2723 2733 2857 2704 2681 2641 2745 2656 2718 2634 2648 2600 2725 2581 2707 2533 2616 2683 2726 2631 2659 2595 2667 2626 2660 2622 2563 2609 2558 2598 2638 2610 2616 2624 2584 2563 2515 2555 2522 2559 2643 2511 2575 2646 2564 2517 2575 2579 2561 2567 2547 2609 2547 2584 2639 2561 2553 2592 2608 2651 2625 2568 2603 2610 2461 2588 2491 2470 2505 2550 2586 2486 2460 2587 2602 2620 2590 2506 2572 2475 2545 2427 2577 2615 2550 2607 2582 2547 2582 2461 2544 2584 2569 2583 2523 2539 2561 2505 2594 2537 2470 2494 2535 2589 2557 2464 2527 2605 2500 2410 2570 2438 2472 2526 2538 2490 2477 2584 2485 2500 2464 2572 2526 2521 2512 2518 2570 2485 2528 2593 2619 2520 2422 2508 2572 2508 2507 2470 2481 2539 2477 2508 2535 2548 2596 2628 2519 2559 2577 2607 2683 2706 2610 2615 2740 2686 2811 2827 2957 2858 2947 2940 2952 3065 3234 3391 3551 3910 4109 4083 3889 3734 3535 3254 3146 2959 3120 2989 3058 3189 3298 3291 3263 3326 3130 3058 2964 2944 2904 2837 2863 2872 3007 3191 3317 3491 3746 3955 4066 4222 4151 3831 3775 3399 3291 3271 3096 3143 3216 3362 3585 3670 3691 3889 4043 4057 4167 4012 3922 3870 3630 3423 3325 3053 2957 2995 2910 2983 3044 3033 3239 3191 3124 2997 3026 2970 2677 2715 2590 2682 2539 2497 2464 2511 2504 2536 2561 2509 2530 2530 2500 2503 2508 2507 2584 2521 2601 2541 2511 2569 2670 2656 2609 2854 2736 2682 2784 2849 2777 2754 2840 2737 2618 2796 2686 2735 2736 2731 2656 2760 2691 2756 2699 2792 2622 2661 2586 2512 2517 2565 2548 2507 2582 2449 2509 2431 2454 2495 2455 2419 2371 2404 2416 2419 2343 2478 2435 2548 2517 2430 2474 2390 2470 2460 2418 2407 2445 2587 2327 2386 2460 2463 2393 2394 2435 2445 2513 2381 2429 2406 2353 2457 2466 2414 2348 2392 2438 2389 2439 2509 2390 2430 2361 2455 2426 2566 2517 2448 2438 2490 2436 2464 2481 2405 2380 2462 2495 2440 2344 2421 2504 2410 2432 2372 2409 2395 2484 2282 2394 2542 2418 2437 2475 2367 2390 2386 2479 2455 2329 2399 2460 2462 2515 2589 2611 2630 2580 2574 2426 2474 2454 2419 2497 2441 2453 2393 2572 2420 2458 2424 2511 2429 2517 2454 2462 2438 2504 2472 2539 2596 2585 2568 2531 2547 2390 2527 2438 2498 2532 2431 2458 2461 2432 2450 2535 2558 2466 2455 2436 2362 2459 2439 2376 2415 2397 2368 2380 2427 2429 2389 2362 2361 2483 2404 2411 2388 2494 2486 2444 2395 2327 2437 2476 2423 2402 2380 2288 2391 2406 2437 2511 2373 2440 2384 2499 2436 2484 2496 2513 2491 2534 2403 2477 2452 2381 2409 2430 2457 2445 2475 2402 2541 2479 2521 2549 2390 2509 2461 2456 2348 2405 2494 2508 2455 2552 2434 2474 2440 2414 2511 2396 2505 2486 2561 2553 2591 2624 2732 2685 2673 2788 2889 3142 3398 3552 3757 3862 3863 3578 3473 3366 3297 3323 3273 3303 3276 3199 3118 3261 3191 3344 3420 3282 3332 3276 3293 3369 3547 3728 4170 4543 5091 5264 5080 4801 4400 3917 3582 3281 3019 2874 3029 3026 3107 3403 3547 3817 3808 3705 3526 3254 3178 2927 2673 2732 2667 2490 2689 2652 2520 2503 2609 2505 2534 2633 2493 2499 2553 2521 2465 2523 2504 2581 2573 2540 2489 2576 2632 2518 2619 2662 2754 2628 2703 2767 2714 2743 2819 2862 3076 3226 3364 3738 4126 4477 4588 4646 4592 4398 4204 3970 4056 3671 3531 3374 3430 3366 3382 3429 3638 3687 3803 3761 3629 3521 3407 3540 3591 3591 3469 3458 3512 3388 3316 3236 3124 3096 2995 3075 3078 3296 3166 3473 3715 4055 4469 4742 5376 5944 6532 7090 7403 7618 7357 6919 6408 5679 5208 4839 4504 4280 4338 4366 4724 5062 5246 5417 5677 5447 5300 4773 4434 4195 3795 3589 3314 3287 3177 3057 3067 2964 3029 3007 3160 2960 2905 3014 2928 3012 3011 3147 3158 3202 3425 3554 3911 4497 4674 4901 5220 5110 5090 4558 4238 3962 3699 3379 3361 3581 3674 3787 4046 4350 4747 4880 5248 5432 5306 5179 4984 4955 4774 4582 4420 4175 4064 4007 3687 3530 3375 3569 3651 3587 3774 3610 3787 3692 3608 3651 3575 3424 3400 3287 3388 3651 3866 4236 4828 5086 5110 4772 4166 3697 3425 3174 3117 3055 2974 2904 3123 3096 3280 3529 3712 3833 3741 3647 3273 2989 3004 2930 2934 3018 2925 2810 2848 2961 2850 2840 2845 3028 3147 3153 3408 3774 4061 4441 4606 4806 4906 4799 4534 4333 4003 3919 3746 3481 3403 3399 3391 3371 3423 3569 3728 3760 3743 3667 3419 3320 3251 3100 3177 3023 2965 2761 2790 2712 2741 2647 2692 2715 2604 2727 2619 2541 2543 2507 2562 2617 2602 2590 2536 2539 2626 2530 2549 2526 2649 2694 2712 2582 2660 2811 2899 2962 3158 3371 3588 3865 4124 4301 4383 4089 3777 3585 3310 3053 3021 2933 3015 2954 2955 2965 3234 3217 3291 3394 3408 3302 3177 3115 3034 2862 2636 2711 2643 2629 2764 2737 2649 2759 2670 2780 2928 2958 3237 3449 3604 3967 4199 4208 4379 4336 4058 3906 3582 3309 3164 3063 3124 3069 3193 3336 3295 3491 3652 3788 3818 3851 3973 4107 4083 3947 3946 3896 3738 3843 3615 3515 3334 3169 3100 3156 3168 3173 3224 3405 3527 3664 3637 3717 3594 3617 3446 3224 3071 3022 3049 3129 3115 3005 3156 3291 3523 3924 4540 4780 5240 5703 5797 5688 5686 5644 5580 5480 5383 4875 4399 4009 3879 3778 3673 3917 3861 4095 4144 4152 4154 4076 4154 3913 3905 3702 3449 3177 3076 2905 2853 2618 2583 2672 2634 2609 2601 2644 2464 2524 2475 2506 2495 2468 2451 2434 2510 2436 2565 2425 2423 2464 2433 2465 2496 2488 2471 2469 2465 2418 2426 2447 2469 2404 2412 2366 2437 2392 2387 2528 2505 2388 2328 2445 2372 2440 2480 2517 2402 2456 2376 2347 2414 2383 2557 2471 2423 2474 2433 2430 2447 2410 2387 2389 2383 2394 2370 2456 2519 2429 2493 2416 2416 2394 2463 2430 2403 2399 2410 2348 2406 2404 2336 2474 2402 2410 2459 2583 2590 2470 2482 2474 2449 2531 2517 2476 2499 2506 2554 2511 2537 2521 2481 2448 2568 2533 2572 2524 2460 2574 2482 2480 2586 2530 2587 2506 2457 2553 2537 2490 2490 2485 2579 2555 2451 2493 2525 2548 2455 2536 2550 2605 2624 2722 2616 2779 2767 2814 2749 2800 2900 2970 3082 3089 2960 3067 3217 3202 3237 3397 3463 3585 3705 3870 4240 4411 4779 4728 4814 4871 4686 4489 4237 4014 3682 3590 3498 3401 3273 3274 3410 3412 3700 3680 3713 3672 3532 3462 3377 3263 3188 3095 2953 2831 2710 2811 2774 2840 2774 2730 2678 2899 2915 3065 3287 3432 3491 3736 3922 4162 4399 4326 4567 4444 4394 4244 4141 3841 3634 3392 3278 3222 3248 3299 3286 3423 3380 3325 3375 3542 3496 3363 3457 3297 3156 2982 2855 2754 2709 2693 2595 2620 2595 2652 2527 2531 2551 2497 2518 2537 2469 2524 2438 2517 2503 2452 2489 2474 2564 2563 2610 2583 2651 2583 2722 2853 2825 2970 3069 3266 3140 3148 3152 3079 2889 2911 2862 2821 2690 2648 2546 2619 2597 2650 2781 2777 2707 2804 2891 2820 2801 2801 2719 2735 2673 2522 2626 2585 2497 2491 2491 2536 2723 2521 2649 2833 2805 2866 2902 2924 2901 2801 2809 2695 2665 2711 2668 2680 2818 2863 2895 3062 3206 3296 3466 3446 3478 3534 3546 3475 3517 3501 3456 3541 3410 3434 3348 3350 3342 3379 3480 3681 3665 4102 4166 4182 4317 4399 4231 4304 4088 4026 4228 4206 4210 4274 4256 4298 4305 4277 4162 4205 4227 3988 4034 3833 3706 3618 3519 3365 3299 3249 3321 3376 3415 3337 3461 3272 3160 3152 3130 3000 3096 2874 2797 2881 2798 2726 2830 2649 2789 2700 2753 2812 2772 2901 2905 2932 3066 3275 3394 3597 3782 4018 4039 3994 3863 3670 3565 3370 3225 3079 3092 3227 3205 3165 3281 3367 3403 3441 3532 3460 3546 3420 3440 3190 3096 3140 3198 2895 3031 2898 2902 2846 2970 2923 2936 2840 3009 3004 2996 3024 3183 2999 3234 3358 3506 3647 3727 4214 4408 4746 4890 4983 4870 4774 4377 4158 4048 3709 3726 3650 3466 3567 3474 3540 3649 3943 4201 4417 4709 5127 5399 5639 5896 5615 5704 5402 5374 5280 5334 5377 5560 5804 5777 5681 5265 5179 5000 4984 4885 5267 5412 5466 5529 5322 5015 4923 4907 4983 5026 4986 4947 4924 4848 4513 4297 3940 3958 3831 3770 3686 3673 3596 3496 3448 3411 3596 3555 3546 3706 3700 3593 3728 3553 3582 3595 3537 3456 3366 3507 3393 3304 3423 3319 3462 3270 3205 3105 3027 3013 3062 2961 2930 2965 2880 2957 2838 2784 2873 2940 2876 2884 2886 2892 2816 2724 2687 2643 2604 2573 2632 2463 2642 2561 2467 2569 2487 2521 2499 2568 2562 2616 2661 2611 2623 2595 2597 2639 2699 2644 2572 2718 2873 2809 2959 3047 3100 3191 3252 3512 3565 3699 3619 3647 3671 3687 3562 3489 3221 3053 3039 3072 3030 2999 2953 2917 2998 3090 3139 3267 3255 3376 3395 3352 3394 3276 3404 3238 3233 3053 3130 3003 3088 2841 2890 2840 2792 2655 2855 2647 2798 2737 2738 2843 2802 2887 2819 3008 2891 2870 2842 3045 3094 3232 3274 3444 3517 3825 3739 3686 3299 3037 2955 2804 2683 2777 2616 2821 2741 2782 2770 2712 2716 2901 2957 2987 3039 3088 2976 2935 2776 2583 2611 2625 2639 2482 2525 2488 2457 2563 2490 2524 2498 2542 2659 2543 2507 2491 2559 2647 2759 2667 2700 2815 2675 2716 2744 2759 2881 2734 2734 2805 2718 2677 2720 2718 2714 2742 2786 2752 2811 2704 2927 3023 3085 3265 3375 3354 3545 3423 3425 3265 3140 2965 2993 2780 2768 2660 2706 2695 2679 2669 2617 2736 2731 2819 2897 2802 2750 2904 2828 2694 2728 2532 2523 2593 2455 2549 2513 2596 2443 2538 2467 2428 2417 2457 2434 2503 2482 2406 2471 2410 2326 2432 2376 2376 2523 2449 2484 2396 2335 2490 2411 2349 2444 2404 2452 2513 2418 2411 2515 2462 2426 2526 2549 2446 2576 2557 2489 2625 2555 2587 2493 2581 2669 2606 2625 2595 2524 2561 2511 2454 2464 2497 2506 2534 2493 2500 2560 2612 2471 2469 2551 2596 2517 2480 2585 2539 2574 2546 2559 2534 2560 2461 2536 2375 2466 2534 2480 2461 2445 2508 2515 2462 2506 2572 2651 2633 2628 2677 2627 2711 2799 2883 2842 2887 2926 2932 3004 3050 3002 3106 3128 3295 3367 3299 3233 3324 3261 3189 3350 3555 3448 3662 3808 3968 4062 4083 4209 4339 4511 4411 4273 4125 3977 3829 3772 3570 3472 3309 3464 3350 3313 3265 3219 3223 3316 3193 3315 3215 3305 3322 3290 3223 2986 2927 2891 2851 2802 2785 2752 2754 2617 2591 2521 2580 2494 2616 2602 2618 2609 2465 2538 2508 2625 2684 2578 2699 2747 2773 2950 3073 3038 3079 3076 3128 2932 2931 2819 2909 2782 2690 2666 2633 2669 2747 2621 2623 2634 2720 2753 2669 2772 2838 2711 2881 2727 2777 2714 2716 2714 2650 2649 2711 2749 2737 2822 2788 2901 2960 3109 3177 3244 3301 3259 3292 3231 3017 2875 2853 2796 2743 2732 2612 2746 2718 2679 2729 2783 2834 2894 2896 2921 2891 2867 3003 2907 2871 2886 2846 2823 2832 2837 2727 2868 2835 3046 3177 3221 3363 3291 3480 3429 3369 3497 3421 3210 3105 2878 2850 2900 2700 2769 2780 2699 2765 2843 2804 2823 2861 2938 2952 2982 3038 3070 2927 2860 2800 2889 2814 2840 2716 2828 2790 2811 2902 2897 2854 2938 3093 3274 3460 3499 3584 3635 3449 3314 3186 3049 2926 2963 2794 2878 2757 2819 2816 2917 2801 2733 2908 2825 2892 2876 3174 3136 3243 3161 3212 3185 3195 3296 3383 3374 3535 3785 3777 3742 3841 3684 3608 3700 3226 3178 2989 2984 2922 2790 2870 2887 2997 2970 2948 3120 3224 3309 3290 3289 3418 3377 3251 3273 3170 3006 2942 2944 2769 2686 2802 2651 2658 2605 2633 2539 2652 2665 2634 2707 2595 2685 2619 2612 2693 2636 2678 2575 2681 2638 2616 2649 2711 2676 2865 2921 2947 2944 3106 3306 3182 3265 3312 3205 3192 3036 2989 2874 2804 2726 2852 2755 2793 2736 2748 2681 2718 2711 2854 2825 2892 2965 2947 2956 3070 3047 2880 2923 2947 3014 2948 2989 2950 2932 2828 2845 2712 2708 2629 2578 2627 2626 2522 2579 2608 2498 2728 2689 2579 2643 2707 2676 2681 2794 2739 2781 2784 2796 2731 2811 2816 2786 3011 3141 3270 3377 3513 3656 3724 3585 3566 3358 3387 3284 3266 3149 3138 3118 3299 3344 3384 3353 3522 3584 3728 3759 3681 3726 3710 3717 3753 3518 3303 3298 3145 3143 3072 2955 2941 3047 3084 3207 3304 3316 3356 3386 3583 3545 3580 3488 3542 3327 3120 3017 2948 2871 2764 2745 2777 2678 2687 2717 2710 2714 2787 2875 2850 2938 3014 3066 3090 3108 3151 3004 3023 2906 2915 2950 2958 3021 3071 2936 3061 3171 3104 3069 3059 2902 2953 2878 2756 2830 2800 2711 2696 2719 2761 2790 2840 2884 2853 2882 2911 3091 3010 3270 3349 3412 3494 3383 3608 3600 3436 3615 3415 3539 3484 3313 3312 3197 3089 2995 2958 2852 2870 2929 2925 3022 3206 3141 3208 3312 3383 3512 3603 3707 3855 3909 4147 4118 4131 4186 4071 3779 3514 3452 3295 3066 3079 3006 2969 2883 2905 2955 2871 3064 2978 3133 3219 3352 3246 3271 3357 3358 3280 3158 3101 2967 2915 2786 2837 2840 2761 2776 2778 2730 2720 2696 2760 2798 2920 2920 2929 3021 3024 2960 2995 2933 2988 3000 2956 2926 2929 2886 2922 3026 2864 2938 2912 2961 3001 3035 3089 3101 3201 3292 3436 3414 3633 3633 3893 3824 3649 3599 3476 3343 3233 3242 2990 3115 2937 2852 2828 2811 2880 2791 2914 2912 2909 2900 2905 2941 3029 2958 2968 2989 2903 2898 2879 2741 2716 2522 2622 2524 2534 2542 2501 2505 2530 2589 2553 2571 2494 2458 2532 2434 2488 2445 2402 2367 2385 2432 2434 2407 2423 2392 2476 2380 2448 2405 2401 2403 2436 2413 2492 2501 2437 2387 2531 2432 2393 2415 2552 2439 2479 2587 2575 2632 2816 2796 2881 3051 3067 3101 3189 3269 3198 2956 2815 2814 2705 2772 2784 2812 2757 2792 2818 2730 2778 2913 2879 2927 3003 3022 2965 3008 2994 2893 2905 2888 2875 2774 2769 2615 2700 2575 2688 2637 2633 2666 2671 2762 2565 2563 2557 2593 2683 2688 2590 2611 2595 2677 2654 2640 2719 2716 2856 2841 3087 2950 2993 3075 3034 3102 2990 3082 2997 2965 3023 3107 3149 3124 3221 3183 3160 3229 3165 3112 2889 2973 2872 2886 2864 2767 2797 2884 2842 2760 2771 2892 2688 2860 2753 2777 2897 2801 2773 2855 2852 2798 2694 2691 2586 2563 2538 2548 2418 2489 2429 2508 2403 2487 2428 2395 2413 2497 2524 2477 2497 2387 2457 2618 2458 2417 2452 2486 2427 2415 2437 2514 2350 2467 2437 2443 2363 2422 2503 2396 2391 2338 2435 2437 2378 2293 2425 2380 2370 2419 2432 2443 2401 2443 2421 2471 2455 2398 2414 2421 2414 2421 2494 2483 2418 2462 2435 2443 2567 2496 2412 2481 2587 2499 2561 2626 2533 2612 2598 2587 2577 2531 2518 2418 2426 2508 2566 2460 2384 2469 2398 2459 2500 2459 2495 2458 2544 2472 2447 2531 2455 2582 2592 2573 2629 2457 2528 2514 2575 2576 2533 2579 2673 2745 2786 2839 2967 3156 3237 3351 3370 3589 3502 3556 3490 3351 3334 3199 3305 3262 3253 3277 3178 3306 3360 3430 3455 3443 3429 3365 3444 3338 3243 3265 3263 3181 3117 3205 3082 3151 3039 3158 2871 2952 2884 2900 2872 2800 2906 2819 2916 2894 2899 2865 2832 2695 2666 2669 2654 2516 2647 2551 2684 2571 2583 2547 2582 2597 2563 2550 2640 2524 2570 2516 2562 2644 2649 2678 2766 2771 2826 2929 2985 3043 3144 3219 3324 3389 3344 3487 3388 3421 3288 3170 3200 3146 3147 2973 2811 2895 2885 2785 2766 2697 2716 2694 2786 2737 2720 2840 2895 2900 2901 2926 2904 2929 2902 3017 2823 2837 2827 2688 2617 2670 2702 2648 2604 2623 2518 2434 2552 2511 2542 2511 2503 2533 2658 2531 2522 2551 2523 2675 2630 2699 2666 2662 2787 2833 2917 2943 2978 2984 3033 3041 3040 3062 3081 3239 3208 3159 3216 3192 3191 3284 3302 3429 3444 3504 3665 3755 3781 3809 3643 3806 3573 3623 3713 3525 3381 3251 3235 3317 3203 3109 3218 3180 3151 3218 3153 3339 3410 3340 3443 3625 3664 3699 3887 4010 4214 4138 4180 4269 4102 4112 4084 4019 4158 4149 3964 4239 4233 4447 4570 4639 4659 4606 4589 4399 4488 4186 4127 3976 3946 3874 3745 3678 3631 3563 3541 3472 3334 3211 3324 3284 3396 3341 3465 3525 3482 3475 3460 3493 3267 3327 3286 3276 3141 3114 3120 2922 2880 2846 2773 2644 2794 2745 2707 2631 2655 2700 2691 2691 2883 2682 2824 2896 2972 3047 3142 3233 3275 3396 3492 3450 3127 3177 3174 3022 3052 3002 2960 2827 3045 2978 2970 2879 2951 2788 2816 2871</intensities>
			</dataPoints>
			<nonAmbientPoints type="Temperature" unit="K">
[...]
			</nonAmbientPoints>
		</scan>
	</xrdMeasurement>
</xrdMeasurements>