File: powder_X-ray_diffraction/variable-temperature_experiments/NaTaO2F2/raw_data/280°C.xrdml
<?xml version="1.0" encoding="UTF-8"?>
<xrdMeasurements xmlns="http://www.xrdml.com/XRDMeasurement/1.7" xmlns:xsi="http://www.w3.org/2001/XMLSchema-instance" xsi:schemaLocation="http://www.xrdml.com/XRDMeasurement/1.7 http://www.xrdml.com/XRDMeasurement/1.7/XRDMeasurement.xsd" status="Completed">
	<comment>
		<entry>Configuration=XRK900, Owner=User-1, Creation date=12/01/2015 16:52:44</entry>
		<entry>Goniometer=Theta/Theta; Minimum step size 2Theta:0.0001; Minimum step size Omega:0.0001</entry>
		<entry>Sample stage=AP XRK-900 with z-axis; Minimum step size Z:0.001</entry>
		<entry>Diffractometer system=EMPYREAN</entry>
		<entry>Measurement program=C:\PANalytical\Data Collector\Programs\Gwen\NaTaO2F2\NaTaO2F2-Lent.xrdmp, Identifier={FF50B583-C5FF-42DA-A01D-A1FB659EF29A}</entry>
		<entry>Batch program=C:\PANalytical\Data Collector\Programs\Gwen\NaTaO2F2\Thermodiff-Ouail.xrdmp, Identifier={5D65A6B1-42FC-480C-9FBB-D7D88D55EA08}</entry>
	</comment>
	<sample type="To be analyzed">
		<id></id>
		<name></name>
		<preparedBy></preparedBy>
	</sample>
	<xrdMeasurement measurementType="Scan" status="Completed" sampleMode="Reflection">
		<comment>
			<entry>PHD Lower Level = 4.02 (keV), PHD Upper Level = 12.07 (keV)</entry>
		</comment>
		<usedWavelength intended="K-Alpha 1">
			<kAlpha1 unit="Angstrom">1.5405980</kAlpha1>
			<kAlpha2 unit="Angstrom">1.5444260</kAlpha2>
			<kBeta unit="Angstrom">1.3922500</kBeta>
			<ratioKAlpha2KAlpha1>0.5000</ratioKAlpha2KAlpha1>
		</usedWavelength>
		<incidentBeamPath>
			<radius unit="mm">240.00</radius>
			<xRayTube id="1010048" name="Empyrean Cu LFF HR (9430 033 7310x) DK434948">
				<tension unit="kV">45.0</tension>
				<current unit="mA">30.0</current>
				<anodeMaterial>Cu</anodeMaterial>
				<focus type="Line">
					<length unit="mm">12.0</length>
					<width unit="mm">0.4</width>
					<takeOffAngle unit="deg">6.0</takeOffAngle>
				</focus>
			</xRayTube>
			<sollerSlit id="21010001" name="Soller slits 0.02 rad.">
				<opening unit="rad">0.0200</opening>
			</sollerSlit>
			<mask id="22030010" name="Fixed mask 20 mm">
				<width unit="mm">20.00</width>
			</mask>
			<antiScatterSlit id="22010003" name="Fixed slit 1Â°" xsi:type="fixedAntiScatterSlitType">
				<height unit="mm">1.52</height>
			</antiScatterSlit>
			<divergenceSlit id="22010012" name="Programmable divergence slit" xsi:type="fixedDivergenceSlitType">
				<distanceToSample unit="mm">140.00</distanceToSample>
				<angle unit="deg">0.5</angle>
			</divergenceSlit>
		</incidentBeamPath>
		<diffractedBeamPath>
			<radius unit="mm">240.00</radius>
			<antiScatterSlit id="22090010" name="AS slit 8.0 mm (PIXcel)" xsi:type="fixedAntiScatterSlitType">
				<height unit="mm">8.00</height>
			</antiScatterSlit>
			<sollerSlit id="21010001" name="Soller slits 0.02 rad.">
				<opening unit="rad">0.0200</opening>
			</sollerSlit>
			<filter id="20030001" name="Large beta-filter Nickel">
				<material>Ni</material>
				<thickness unit="mm">0.020</thickness>
			</filter>
			<detector id="7010019" name="PIXcel1D-Medipix3 detector" xsi:type="rtmsDetectorType">
				<phd unit="%">
					<lowerLevel>25.0</lowerLevel>
					<upperLevel>75.0</upperLevel>
				</phd>
				<mode>Scanning</mode>
				<activeLength unit="deg">3.3482</activeLength>
			</detector>
		</diffractedBeamPath>
		<scan appendNumber="0" mode="Continuous" scanAxis="Gonio" status="Completed">
			<header>
				<startTimeStamp>2023-01-22T23:47:37+01:00</startTimeStamp>
				<endTimeStamp>2023-01-23T02:48:04+01:00</endTimeStamp>
				<author>
					<name>User</name>
				</author>
				<source>
					<applicationSoftware version="5.5a">Data Collector</applicationSoftware>
					<instrumentControlSoftware version="8.2  20201204">EMPYREAN</instrumentControlSoftware>
					<instrumentID>0000000011159748</instrumentID>
				</source>
			</header>
			<dataPoints>
				<positions axis="2Theta" unit="deg">
					<startPosition>9.99846514</startPosition>
					<endPosition>99.99342261</endPosition>
				</positions>
				<positions axis="Omega" unit="deg">
					<startPosition>4.99923257</startPosition>
					<endPosition>49.99671130</endPosition>
				</positions>
				<positions axis="Z" unit="mm">
					<commonPosition>8.846</commonPosition>
				</positions>
				<commonCountingTime unit="seconds">386.070</commonCountingTime>
				<intensities unit="counts">6223 6236 6241 6270 6231 6356 6151 6375 6232 6136 6185 6281 6330 6233 6327 6173 6062 6111 6265 6235 6120 6197 6219 6277 6426 6312 6108 6214 6182 6177 6197 6257 6143 6194 6041 5994 6089 6077 6021 6029 6191 6131 6099 6010 6112 6099 5940 6037 6097 6055 6118 6046 6048 6081 5922 5957 5999 6014 6308 6333 6293 6171 6262 6262 6252 6436 6223 6452 6539 6413 6778 6860 7188 7543 7948 8671 9530 10836 12601 16081 20752 25950 33148 40987 46983 48688 46210 40605 33300 25553 19484 14397 10666 8837 7581 7044 6739 6663 6490 6308 6221 6237 6052 6000 6015 5797 6025 5867 5967 5952 5844 5870 5796 5831 5846 5837 5896 5801 5953 5817 5719 5801 5815 5840 5671 5727 5734 5847 5778 5735 5772 5767 5733 5788 5740 5718 5855 5710 5680 5566 5817 5676 5578 5636 5571 5561 5603 5622 5717 5572 5549 5508 5574 5577 5586 5621 5729 5595 5570 5668 5514 5529 5677 5608 5553 5602 5639 5620 5499 5474 5541 5483 5444 5506 5379 5445 5440 5477 5507 5478 5378 5424 5414 5390 5392 5323 5401 5362 5443 5323 5426 5588 5367 5532 5407 5446 5325 5415 5227 5347 5375 5435 5430 5296 5439 5334 5218 5320 5231 5305 5354 5388 5311 5437 5336 5303 5350 5241 5234 5172 5247 5183 5303 5216 5253 5421 5247 5280 5356 5342 5248 5303 5264 5345 5141 5309 5331 5294 5269 5083 5334 5276 5098 5062 5206 5270 5286 5208 5194 5172 5266 5268 5121 5230 5171 5295 5046 5178 4996 5218 5129 5174 5187 5112 5092 5235 5196 5197 5110 5222 5000 5200 5148 5142 5067 5149 5064 5212 5209 5101 5108 5025 5002 5166 4916 4942 4917 5083 5042 5132 5010 4908 5063 5087 5048 5023 5125 5235 5025 4944 4958 5099 5006 5049 5048 5078 4958 5072 4942 5000 4900 4973 5026 5053 4844 5098 5057 4872 5007 4916 4953 4953 4915 4996 4796 4951 4919 4830 5035 5022 4733 4931 4928 4817 4806 4936 4828 4863 4862 4931 4761 4844 4741 4857 4817 4894 4810 4817 4865 4951 4837 4908 4795 4914 4755 4946 4743 4897 4824 4825 4824 4775 4897 4881 4740 4837 4701 4822 4646 4973 4777 4730 4902 4738 4798 4737 4859 4614 4817 4750 4875 4853 4703 4898 4762 4730 4730 4733 4671 4781 4790 4751 4643 4748 4701 4761 4711 4747 4804 4663 4825 4751 4565 4758 4784 4710 4653 4759 4646 4600 4759 4676 4763 4903 4622 4609 4609 4617 4730 4657 4624 4601 4622 4695 4638 4643 4754 4796 4591 4600 4603 4553 4626 4637 4643 4552 4617 4579 4617 4750 4634 4574 4607 4697 4541 4547 4567 4539 4514 4689 4550 4595 4603 4651 4688 4632 4571 4634 4668 4686 4628 4638 4597 4792 4756 4655 4644 4846 4651 4744 4630 4621 4832 4802 4723 4649 4804 4710 4771 4671 4652 4680 4734 4761 4797 4658 4737 4689 4692 4605 4657 4613 4581 4566 4752 4586 4592 4653 4711 4774 4592 4533 4450 4476 4490 4493 4571 4469 4517 4528 4407 4544 4404 4463 4416 4529 4413 4420 4522 4551 4507 4444 4363 4463 4489 4473 4454 4441 4421 4613 4439 4306 4450 4499 4409 4480 4546 4554 4487 4485 4445 4497 4365 4433 4672 4573 4548 4498 4507 4482 4613 4602 4531 4605 4527 4497 4497 4400 4452 4385 4465 4467 4412 4399 4422 4367 4357 4445 4321 4406 4279 4349 4319 4349 4358 4471 4275 4457 4357 4356 4462 4377 4439 4446 4385 4394 4538 4565 4545 4454 4541 4589 4463 4458 4266 4306 4342 4331 4339 4287 4140 4197 4240 4280 4170 4268 4219 4233 4319 4221 4116 4091 4380 4179 4208 4194 4290 4121 4188 4233 4207 4152 4142 4165 4100 4156 4152 4249 4393 4253 4205 4222 4179 4137 4200 4127 4266 4188 4140 4200 4218 4160 4283 4028 4105 4023 4085 4113 4109 4075 4085 4165 4187 4230 4301 4220 4243 4181 4293 4335 4236 4198 4099 4161 4280 4161 4065 4079 4089 4041 4136 4151 4250 4100 4110 4034 3980 4080 4152 4214 4135 4361 4305 4466 4405 4525 4520 4416 4430 4514 4573 4483 4619 4540 4680 4505 4467 4531 4457 4491 4562 4623 4660 4528 4451 4521 4719 4594 4559 4503 4592 4812 4928 4900 4978 5097 5133 5153 5513 5627 5955 6290 6420 7083 8066 9515 11849 15230 20620 30075 44921 66441 90456 111344 122962 118780 109824 100411 85319 65926 48013 34637 24481 17381 12594 9805 7927 6899 6415 5931 5641 5488 5253 4920 4742 4725 4724 4467 4466 4510 4536 4463 4408 4237 4292 4306 4322 4231 4430 4273 4320 4441 4383 4530 4444 4368 4492 4333 4406 4237 4264 4297 4110 4115 4243 4168 4169 4139 3987 4072 3960 4230 4144 4095 4122 4013 4026 4024 4113 3956 4094 4064 4028 3862 4062 4075 3954 4086 3976 4100 3963 4018 3847 3944 3893 3860 3917 3911 3904 4072 4003 3955 4057 3990 4059 3884 3915 4021 3874 3843 3992 3897 3905 3979 3856 4002 3774 3820 3886 3963 3866 3965 3909 3878 3959 3924 3863 3667 3874 3794 3686 3888 3819 3787 3861 3919 3826 3900 3907 3903 3927 3955 3951 3875 3792 3877 3840 3868 3854 3836 3731 3860 3792 3791 3824 3788 3893 3773 3917 3861 3893 3720 3798 3783 3928 3812 3873 3823 3728 3769 3960 3977 3878 3880 4013 4050 4120 4087 4083 4231 4082 3958 3995 3965 3882 3885 3959 3916 3910 3926 3962 3919 3944 4059 3896 3909 4004 3849 3740 3833 3884 3805 3832 3980 3895 3801 3909 4017 3941 4180 4254 4456 4684 5286 6039 7385 9463 12741 15952 18236 18219 17254 16210 14922 12918 10721 8594 7032 5766 4850 4338 4158 4007 4023 4026 4034 3873 3928 3866 3807 3888 3779 3813 3772 3732 3717 3797 3810 3815 3729 3777 3819 3755 3855 3721 3775 3977 3813 3663 3884 3813 3824 3755 3834 3726 3763 3760 3602 3805 3625 3688 3634 3605 3658 3547 3647 3746 3611 3596 3632 3676 3693 3605 3589 3683 3610 3555 3479 3626 3625 3718 3690 3682 3520 3639 3654 3651 3723 3726 3697 3688 3709 3639 3696 3747 3829 3762 3653 3670 3809 3863 3975 3924 3858 3839 3889 3838 3899 3830 3762 3903 3871 3841 3845 3802 3833 3919 3965 3838 3907 4019 3881 3992 3886 3985 3992 4148 4082 4118 4243 4221 4198 4330 4336 4491 4479 4547 4594 4679 4895 5062 5425 5849 6400 7845 10123 14189 20461 28164 36875 42506 44406 42408 39247 35885 32393 28619 25055 22785 23665 29212 35779 39923 44586 47981 47131 42227 37054 32755 28521 22238 16830 12765 9581 7408 6081 5229 4843 4633 4439 4170 4026 4105 4021 3945 3947 3912 3814 3852 3822 3816 3765 3745 3826 3808 3736 3817 3765 3628 3809 3672 3761 3712 3694 3575 3766 3616 3745 3857 3922 3840 3911 3840 3653 3692 3725 3704 3673 3557 3693 3569 3510 3577 3584 3500 3572 3699 3402 3546 3529 3625 3469 3488 3453 3562 3487 3588 3502 3674 3671 3461 3615 3678 3552 3648 3654 3659 3574 3510 3440 3463 3514 3615 3515 3526 3564 3615 3533 3471 3479 3507 3438 3505 3398 3506 3408 3568 3476 3468 3532 3630 3497 3390 3434 3592 3471 3429 3325 3337 3430 3421 3387 3499 3413 3353 3486 3314 3506 3408 3541 3507 3508 3492 3618 3634 3464 3661 3599 3493 3695 3632 3704 3729 3662 3701 3625 3563 3653 3553 3513 3676 3626 3443 3631 3614 3589 3581 3418 3514 3522 3352 3382 3470 3390 3605 3509 3494 3421 3363 3393 3387 3406 3444 3384 3346 3421 3437 3379 3391 3442 3384 3451 3511 3434 3530 3564 3541 3568 3613 3652 3693 3647 3677 3660 3668 3551 3692 3702 3615 3772 3564 3551 3615 3651 3679 3707 3689 3666 3554 3572 3628 3668 3662 3710 3667 3559 3667 3584 3684 3699 3621 3642 3526 3714 3736 3755 3727 3675 3706 3675 3832 3805 3925 3710 3980 4080 4316 4269 4389 4625 4660 4811 5098 5458 5760 6074 6652 7193 8072 9977 12462 17304 25693 38191 54974 74533 84605 83416 76015 69651 64204 59822 52599 42644 32974 24565 17805 12773 9623 7760 6573 5846 5497 5022 4709 4585 4286 4246 4123 4127 3947 3871 3863 3829 3799 3819 3878 3644 3681 3644 3718 3638 3621 3678 3749 3750 3917 3893 3912 3880 3838 3771 3682 3809 3764 3623 3634 3620 3653 3669 3565 3623 3552 3434 3526 3560 3629 3662 3626 3627 3546 3624 3524 3557 3649 3525 3572 3501 3612 3453 3633 3519 3534 3591 3500 3490 3495 3637 3498 3542 3532 3469 3530 3591 3563 3480 3582 3585 3594 3585 3603 3626 3573 3627 3683 3714 3842 3850 3974 4030 4126 4197 4280 4565 4676 4744 5275 5928 7230 9623 13690 19706 26309 31085 33101 31168 27547 25877 25420 24408 23737 22761 22106 21990 22269 21582 20206 18101 15829 14273 13136 12113 10444 8524 6857 5648 4767 4202 3982 3957 3679 3822 3660 3493 3606 3501 3498 3532 3441 3479 3457 3353 3306 3373 3351 3413 3393 3428 3327 3396 3249 3335 3194 3287 3417 3371 3391 3452 3279 3450 3353 3358 3335 3337 3320 3178 3371 3277 3164 3249 3166 3293 3273 3298 3274 3312 3303 3281 3218 3256 3282 3314 3245 3295 3376 3437 3292 3336 3410 3316 3287 3309 3282 3236 3272 3251 3288 3258 3214 3237 3237 3365 3248 3296 3188 3171 3300 3158 3212 3224 3233 3269 3214 3288 3217 3136 3160 3207 3148 3202 3198 3268 3196 3242 3306 3127 3058 3270 3129 3124 3222 3164 3184 3119 3250 3164 3101 3251 3254 3197 3240 3152 3115 3123 3181 3209 3148 3134 3140 3166 3045 3230 3195 3224 3145 3085 3118 3152 3107 3212 3077 3071 3130 3068 3181 3060 3183 3119 3118 3132 3139 3096 3188 3024 3133 3164 3081 3075 3102 3239 3114 3065 3176 3052 3233 3110 3086 3076 2983 3187 3072 3098 3164 3194 3179 3172 3172 3187 3010 3214 3131 3212 3182 3208 3109 3160 3168 3180 3156 3093 3221 3123 3253 3026 3167 3116 3109 3103 3115 3179 3249 3084 3325 3133 3238 3183 3117 3237 3197 3148 3198 3311 3236 3278 3280 3153 3216 3220 3257 3324 3172 3261 3300 3281 3398 3429 3560 3542 3552 3600 3631 3691 3817 3882 4003 4134 4346 5326 6750 9508 13944 19277 20871 19226 16059 13372 12323 13199 13376 12658 10510 8459 6645 5398 4709 4383 4046 3827 3714 3626 3535 3491 3472 3393 3471 3428 3610 3544 3488 3429 3641 3746 3679 3879 3952 3991 4142 4245 4428 4414 4522 4863 5532 6529 8141 11498 16655 23542 30610 35021 34791 31310 26269 23048 22210 21706 21028 18704 15283 11990 9084 7113 6027 5509 5109 4988 4994 5056 4869 5428 5825 6284 7760 9743 13203 17464 21858 26814 29856 30564 29146 25521 22702 20846 19972 19462 18410 17020 16393 17020 18042 17699 15923 13591 11158 10202 10160 10237 10039 8750 7195 5985 4860 4257 3989 3731 3648 3460 3446 3445 3344 3349 3279 3281 3158 3227 3257 3250 3249 3270 3163 3124 3310 3138 3327 3163 3178 3250 3256 3297 3208 3247 3241 3427 3405 3293 3362 3373 3504 3604 3658 3557 3668 3758 4246 4730 5785 7719 10564 13048 14254 13501 11687 10239 9122 9194 9636 9205 8317 7152 5992 4961 4233 3848 3551 3446 3411 3332 3254 3341 3304 3319 3344 3509 3560 3496 3527 3385 3219 3249 3222 3357 3319 3315 3104 3127 3069 3148 3054 3006 2960 2943 3026 2940 3052 2942 3045 2997 2916 2944 2993 2927 2876 3054 2961 2943 2876 2970 3111 2953 2952 2984 2950 2953 3000 2892 2892 3011 2940 2927 2871 2956 3031 2913 2907 3060 3033 2952 3032 3013 2972 2914 2952 2994 3018 2912 2908 2969 2946 2906 2912 2955 2931 3016 2897 2961 2894 2982 2969 2932 2994 2955 2967 2967 2965 2952 2878 2945 3088 2919 2863 2949 2911 2954 3016 2924 2858 2940 2965 2986 2938 2987 2958 2932 2907 3022 2954 2908 2975 3004 3000 2962 3031 2907 2935 2930 2997 2890 2830 2864 2978 2886 3087 2997 2984 3061 2985 2991 3083 3066 3057 3041 3161 3211 3475 3446 3743 4095 5239 6653 8288 9016 9219 8436 6907 6092 5853 6016 6315 6279 5886 5059 4247 3782 3555 3362 3252 3190 3135 3088 3079 2925 3084 3029 3006 3040 2929 3108 3020 3120 3142 3120 3145 3230 3248 3198 3351 3356 3521 3982 4470 5346 6662 8051 9400 10069 10154 9137 8267 7589 7134 6719 6760 6762 6235 5692 4792 4097 3527 3391 3270 3121 3209 3209 3103 3280 3344 3626 3572 3543 3454 3450 3295 3145 3335 3369 3411 3262 3088 3029 2986 2917 2980 2847 2876 2845 2888 2898 2900 2775 2865 2750 2844 2784 2770 2790 2805 2748 2832 2849 2736 2757 2770 2761 2692 2762 2744 2752 2770 2707 2814 2832 2763 2962 2740 2778 2748 2713 2797 2707 2779 2776 2820 2754 2666 2697 2674 2818 2795 2729 2827 2712 2710 2746 2786 2774 2747 2755 2712 2816 2641 2830 2788 2725 2773 2788 2811 2823 2740 2740 2759 2718 2760 2720 2655 2756 2732 2764 2711 2733 2757 2642 2710 2785 2719 2809 2880 2771 2900 2752 2727 2691 2717 2731 2819 2747 2787 2819 2886 2837 2832 2785 2771 2725 2703 2824 2860 2718 2609 2753 2793 2689 2811 2768 2749 2751 2665 2675 2709 2797 2738 2804 2698 2715 2672 2822 2810 2749 2824 2792 2739 2926 2855 2861 2889 2937 2986 2904 3204 3259 3538 3766 4046 4402 4597 4603 4609 4316 4137 4026 3935 3924 3861 3844 3776 3595 3489 3418 3389 3389 3447 3838 4385 5182 6197 7465 8051 7513 6856 6074 5486 5288 5510 5623 5757 5258 4959 4283 3790 3616 3412 3285 3184 3117 3252 3137 3166 3282 3243 3169 3385 3522 3900 4366 5271 6698 8538 10066 10616 9735 8013 6680 5896 5973 6257 6763 6839 6236 5484 4636 4123 3614 3383 3153 3249 3214 3134 3193 3005 3133 3109 3041 3122 3043 3104 3295 3102 3287 3304 3462 3570 3733 4154 4778 5724 6658 8166 9818 11007 11568 10657 9312 8200 7569 7492 7898 8516 8857 9307 10079 11066 12624 13315 13067 12204 10818 10442 11118 12789 15241 16588 16676 14499 12028 9865 8270 7716 7860 8030 7926 7184 6443 5196 4395 3961 3486 3294 3236 3122 3036 3049 2905 2951 2898 2859 2840 2794 2880 2843 2760 2832 2741 2751 2757 2817 2794 2665 2780 2776 2715 2631 2747 2866 2783 2717 2782 2720 2698 2724 2814 2766 2714 2679 2812 2781 2686 2747 2759 2696 2749 2692 2661 2694 2682 2717 2759 2751 2712 2706 2794 2770 2734 2723 2707 2691 2657 2718 2757 2734 2551 2684 2702 2737 2741 2706 2814 2661 2645 2625 2670 2724 2651 2615 2706 2696 2668 2890 2681 2646 2724 2603 2729 2561 2652 2757 2724 2607 2605 2637 2696 2681 2655 2551 2632 2614 2665 2627 2644 2650 2724 2626 2719 2704 2670 2754 2755 2706 2762 2744 2799 2682 2831 2727 2724 2791 2744 2546 2662 2635 2691 2643 2677 2658 2691 2659 2661 2712 2612 2595 2707 2681 2666 2696 2770 2711 2764 2635 2632 2757 2753 2739 2825 2885 3007 3153 3308 3283 3271 3199 3134 2965 3032 3016 3054 3077 3001 3005 2975 2829 2734 2686 2723 2701 2743 2689 2708 2654 2722 2640 2680 2799 2623 2662 2666 2738 2711 2701 2746 2705 2782 2711 2644 2637 2743 2619 2729 2548 2654 2671 2739 2708 2598 2664 2675 2690 2741 2708 2718 2764 2777 2878 2971 3008 3269 3471 3786 4056 4129 4225 3797 3575 3382 3315 3409 3523 3540 3553 3427 3357 3175 3175 3135 3231 3190 3416 3791 4186 4642 5278 5612 5323 5249 4811 4327 4191 4095 4053 4180 4144 4162 3952 3708 3456 3149 2939 2907 2826 2826 2820 2838 2730 2627 2621 2758 2786 2756 2730 2689 2770 2852 2641 2749 2688 2733 2692 2621 2757 2694 2727 2631 2613 2670 2774 2712 2607 2620 2730 2747 2677 2577 2713 2702 2606 2694 2672 2684 2651 2721 2512 2649 2779 2846 2675 2708 2758 2789 2813 2724 2810 2759 2792 2752 2841 2830 2806 2897 2938 2944 2906 2992 3022 3153 3289 3353 3651 4157 5184 6652 8656 10691 11249 10338 8653 6569 5422 4906 5332 6013 6828 7006 6903 5766 4773 3858 3375 3209 3113 3004 2963 2965 2803 2828 2837 2664 2848 2836 2785 2838 2794 2737 2807 2817 2765 2727 2724 2801 2872 2884 2846 2768 2818 2850 2902 2826 2801 2904 2870 2787 3077 3143 3357 3806 4309 5214 5950 6876 7058 6374 5355 4517 4146 4116 4126 4320 4854 5085 4878 4367 3778 3432 3234 3130 2984 2886 2845 2901 2905 2800 2889 2938 2849 2761 2877 2973 2840 2918 2902 2966 2863 2907 2858 2989 2893 2968 3064 3080 3027 3249 3178 3402 3701 4161 4698 5679 6526 7493 8193 8594 8547 7677 6339 5634 5282 5283 5353 5521 5878 5849 5519 4709 4191 3674 3528 3224 3244 3123 2977 3037 3041 3090 3004 3129 3134 3033 3035 3052 3092 3158 3148 3376 3440 3384 3325 3393 3625 3608 3659 3685 4003 4264 4565 5310 5993 7085 9129 11688 15019 17868 19935 19939 17801 14803 12189 10654 10040 10352 11202 12036 12160 11339 9801 8455 6856 5756 5030 4415 3991 3686 3628 3353 3257 3343 3276 3217 3202 3243 3245 3237 3232 3200 3209 3248 3293 3291 3264 3325 3355 3554 3683 3934 4456 5434 6795 8495 10700 12160 12702 12719 13182 13363 12981 12149 11306 10635 9996 9314 8777 8446 8383 8394 7819 7223 6513 5647 4938 4433 4166 4271 4511 4817 5769 7075 8783 11124 13035 13137 12204 10268 8081 6800 6349 6477 6930 7839 8252 8147 7399 6203 5270 4514 4045 3615 3422 3284 3299 3092 3085 3062 3095 2967 3053 3034 3044 2929 2908 2974 2885 2966 2900 2948 2907 2876 2880 2828 2822 2921 2910 2946 2906 2867 2905 2921 3121 3067 3155 3364 3340 3517 3553 3464 3370 3208 3075 3193 3173 3284 3298 3488 3430 3586 3551 3658 3550 3501 3501 3501 3477 3523 3403 3430 3566 3562 3635 3698 3634 3567 3720 3930 3915 4288 4711 5379 6525 8231 10787 13773 16854 18436 18350 16921 14422 11991 10380 9503 9830 10318 11192 11887 11579 10406 9148 7701 6566 5571 5124 4570 4259 4163 3900 3685 3779 3874 3857 4042 4328 4501 5124 5886 6987 8271 9771 10889 11618 11567 10273 8590 7502 6710 6548 6595 6944 7347 7438 7271 6712 5862 5099 4421 4134 3715 3458 3301 3301 3210 3211 3194 2996 3043 3077 2995 2883 2968 2894 2955 2900 2873 2944 2873 2823 2911 2843 2790 2784 2866 2844 2833 2826 2925 2754 2930 2941 2968 2967 3001 2871 2963 3002 2906 3091 3099 3326 3326 3438 3797 4397 5057 6465 7909 8840 8711 8169 6912 5768 4934 4701 4651 5107 5513 5976 6144 5755 5204 4656 4168 3913 3904 3872 3721 3658 3314 3336 3173 3150 3160 3039 3149 3196 3116 3107 3038 3117 2878 2969 2875 2817 2778 2833 2825 2933 2795 2879 2826 2879 2803 2907 2783 2729 2796 2775 2806 2826 2848 2934 2802 2797 2764 2820 2785 2784 2857 2826 2817 2914 2834 2689 2781 2783 2859 2811 2947 2969 2980 2949 2918 2941 3037 3070 3004 2992 3026 2998 3147 3074 3142 3211 3462 3639 4083 4745 5585 6982 8156 9192 10259 10400 10231 9518 8741 7493 6700 6258 6053 6382 6609 6777 6827 6653 6167 5578 5148 4383 3992 3891 3925 4133 4390 4710 5133 5467 5767 6303 6133 6087 6236 5796 5238 5046 4668 4624 4499 4687 4508 4452 4360 4316 4103 3807 3579 3207 3105 3057 2875 2864 2873 2851 2703 2826 2846 2748 2769 2828 2792 2812 2880 2787 2730 2786 2776 2793 2769 2764 2871 2768 2883 2901 2993 2996 3072 3249 3470 3622 3794 3901 4145 4070 4014 3864 3466 3401 3205 3261 3244 3421 3378 3439 3484 3430 3180 3085 2907 2875 2896 2841 2741 2913 2781 2781 2860 2795 2720 2743 2750 2790 2787 2726 2790 2785 2776 2756 2832 2684 2760 2712 2718 2692 2773 2781 2901 2843 2766 2946 2965 3014 3083 3097 3220 3127 2992 3264 3128 3045 2985 3042 2910 2866 2940 2914 2816 2927 2927 2922 2808 2816 2699 2762 2692 2835 2741 2742 2653 2677 2746 2662 2728 2715 2719 2855 2694 2662 2716 2842 2752 2757 2720 2699 2691 2688 2676 2805 2718 2670 2781 2646 2767 2677 2774 2725 2751 2810 2757 2832 2766 2864 2864 2921 2844 2904 3001 3111 3132 3099 3052 3064 3137 3276 3282 3515 3765 4058 4474 5101 6099 7486 9249 10636 11558 11354 10061 8618 7148 6280 5797 5553 5799 6481 7122 7651 7555 6996 6467 5381 4762 4225 3974 3853 3645 3613 3692 3599 3669 3459 3421 3276 3159 3110 2969 2988 3033 3073 3052 3144 3062 3100 2963 2917 2927 2893 2899 2836 2908 2931 2881 2824 2833 2891 3007 2899 2940 2859 2907 3026 3021 3079 3056 3228 3285 3345 3475 3751 4235 4590 5230 5763 6143 6236 6115 6299 6732 7546 8668 9724 10957 12346 12794 13136 12156 10824 9105 7737 6933 6689 6802 6995 7294 7508 7624 7301 6669 6075 5202 4506 3975 3716 3445 3356 3236 3186 2999 3216 3141 3101 3069 3119 3145 3145 3163 3220 3143 3229 3276 3359 3365 3282 3560 3834 3951 4511 5185 5805 6597 7290 7979 8746 9082 9378 9611 9818 9799 9165 8002 7446 7085 6757 6642 6694 7048 7273 7319 7826 8311 8487 8478 8182 7930 7014 6241 5392 4883 4482 4324 4261 4606 4718 4858 5147 5033 4606 4392 3982 3707 3258 3205 3163 3121 3101 3128 3102 3066 3063 3068 3101 3002 3033 3123 3055 3052 3092 3080 3215 3285 3429 3544 3789 4012 4434 5136 5918 6915 8293 8979 9127 8340 7339 6371 5795 5272 5326 5429 6042 6629 7116 7297 7160 6466 5703 4917 4542 4145 3930 3855 3862 4017 3952 3852 3893 3631 3469 3385 3405 3295 3270 3315 3476 3492 3641 3904 4088 4581 5077 5750 6468 7310 7916 8490 8699 8411 7385 6747 5937 5576 5409 5258 5502 5994 6349 6924 7546 7955 8352 8878 9305 9662 9348 8220 7259 6087 5364 5000 4811 4960 5324 6018 6507 6933 7406 7852 8061 8427 9248 9584 9835 9148 8148 6967 6088 5402 5159 4845 4938 5352 5831 5957 6152 6149 5677 5005 4550 4101 3747 3457 3391 3217 3158 3085 3056 3045 3029 2989 2993 2975 2982 3080 3008 2987 2979 3076 3067 2971 3138 3101 3198 3279 3291 3626 4069 4490 4959 5766 6345 7115 7800 8354 8452 8172 7216 6607 5768 5372 5147 4913 5286 5493 5737 6267 6352 6464 6604 6580 6798 6927 7309 7681 8466 9413 10447 11152 10993 10195 8571 7235 6368 5856 5707 5627 5880 6228 6678 6826 6983 6777 6093 5254 4444 4013 3725 3587 3304 3221 3213 3113 3086 3115 3060 3084 3087 3053 3159 3145 3097 3043 3140 3226 3091 3118 3204 3421 3339 3542 3485 3606 3752 4024 4456 4850 5529 6453 8048 9738 12023 13882 14769 14484 12988 11261 9546 8271 7482 7026 7290 7895 8658 9523 10489 10501 10288 9442 8578 7451 6685 5873 5448 4964 4916 5090 5184 5284 5353 5634 5651 5588 5459 5326 4924 4385 4005 3815 3756 3723 3589 3685 3611 3803 3743 3598 3583 3563 3243 3002 2976 2882 2928 2728 2752 2768 2715 2668 2740 2804 2773 2671 2704 2689 2669 2595 2707 2760 2614 2543 2707 2566 2602 2628 2629 2697 2718 2671 2616 2698 2747 2660 2695 2575 2641 2595 2666 2599 2546 2561 2624 2605 2556 2588 2602 2611 2649 2667 2627 2577 2494 2608 2654 2640 2612 2628 2624 2540 2571 2571 2545 2669 2585 2487 2564 2602 2578 2537 2614 2596 2588 2586 2447 2588 2633 2632 2589 2537 2626 2542 2559 2474 2581 2590 2541 2560 2500 2573 2427 2637 2544 2553 2440 2617 2672 2535 2579 2472 2508 2574 2556 2404 2534 2432 2567 2525 2506 2541 2590 2569 2477 2520 2540 2472 2535 2566 2602 2514 2587 2505 2485 2468 2615 2561 2479 2610 2483 2483 2596 2588 2429 2440 2482 2465 2570 2450 2539 2526 2552 2607 2544 2551 2471 2567 2564 2526 2684 2572 2633 2512 2572 2636 2628 2649 2733 2712 2676 2740 2692 2856 2858 2857 2941 2787 2954 3157 3144 3309 3447 3714 3879 3975 4065 3829 3657 3394 3230 3031 3086 2999 2964 3123 3246 3201 3388 3367 3216 3112 3128 3012 2936 2949 2975 2932 3006 3148 3325 3530 3774 3957 4110 4196 4256 3924 3815 3513 3296 3131 3112 3037 3004 3148 3368 3493 3667 3725 3772 4000 3905 3883 3975 3964 3760 3684 3517 3296 3106 2939 2795 2828 2873 2925 2944 3117 3106 3071 2948 2931 2874 2798 2675 2627 2608 2549 2569 2580 2558 2528 2410 2467 2488 2495 2573 2469 2535 2487 2563 2549 2455 2541 2497 2671 2528 2617 2758 2725 2690 2713 2772 2843 2705 2771 2809 2729 2714 2781 2662 2705 2695 2741 2686 2825 2697 2808 2599 2619 2611 2623 2663 2520 2517 2564 2561 2562 2567 2292 2487 2530 2475 2474 2505 2475 2530 2567 2496 2406 2422 2410 2437 2422 2507 2463 2393 2454 2369 2330 2477 2431 2379 2401 2436 2441 2451 2410 2423 2429 2437 2412 2320 2424 2429 2435 2381 2428 2439 2414 2457 2395 2433 2463 2451 2488 2432 2401 2477 2366 2497 2488 2547 2443 2458 2546 2343 2450 2398 2420 2450 2395 2401 2443 2411 2320 2545 2435 2456 2357 2459 2488 2399 2497 2540 2401 2418 2430 2462 2413 2468 2391 2411 2501 2440 2401 2441 2523 2480 2446 2488 2471 2438 2437 2431 2414 2487 2491 2427 2459 2345 2519 2518 2483 2392 2498 2475 2487 2434 2551 2487 2542 2412 2454 2455 2490 2469 2497 2564 2455 2575 2490 2556 2473 2509 2469 2497 2386 2433 2530 2418 2504 2403 2458 2524 2461 2451 2370 2421 2389 2386 2427 2514 2353 2416 2481 2411 2605 2413 2430 2300 2425 2357 2516 2398 2482 2512 2349 2493 2573 2397 2403 2413 2394 2368 2434 2378 2383 2437 2475 2448 2399 2464 2376 2447 2388 2481 2538 2559 2392 2472 2518 2484 2486 2533 2389 2471 2429 2471 2471 2497 2555 2437 2497 2482 2431 2440 2478 2431 2522 2497 2478 2478 2496 2472 2479 2387 2505 2460 2510 2444 2579 2569 2655 2628 2685 2681 2745 2942 3100 3234 3341 3589 3809 3949 3957 3733 3563 3510 3451 3324 3310 3201 3138 3092 3085 3235 3319 3383 3341 3475 3488 3414 3550 3848 4065 4640 5031 5161 4894 4721 4197 3736 3573 3221 3035 3003 2929 3077 3120 3383 3534 3641 3802 3699 3585 3342 2996 2907 2674 2694 2769 2608 2525 2614 2578 2624 2608 2541 2554 2517 2481 2590 2616 2544 2584 2517 2655 2608 2531 2526 2480 2488 2550 2569 2592 2640 2587 2675 2640 2727 2756 2727 2761 2872 2954 3027 3168 3408 3776 3966 4404 4682 4733 4812 4397 4225 4084 3845 3646 3504 3278 3279 3275 3414 3448 3666 3799 3784 3724 3595 3679 3690 3602 3503 3555 3633 3534 3475 3285 3134 3038 3043 2958 3040 3085 3131 3290 3282 3604 3861 3977 4403 4676 5164 5644 6452 7031 7497 7674 7667 7034 6570 5754 5112 4731 4438 4398 4383 4436 4752 4914 5355 5446 5786 5593 5482 5060 4411 4101 3698 3408 3244 3174 3112 3135 3084 2934 3034 3108 2941 2963 2939 3014 2970 2903 3046 3088 3142 3212 3386 3498 3837 4145 4370 4922 5137 5182 5164 4898 4543 4085 3867 3746 3613 3615 3614 3954 4063 4390 4778 5008 5473 5639 5542 5366 5137 5003 4701 4549 4296 4106 3960 3786 3690 3659 3714 3707 3604 3701 3791 3665 3673 3702 3585 3403 3329 3257 3337 3310 3465 3569 3920 4256 4785 5055 5019 4783 4189 3623 3349 3058 2919 2951 2911 2945 3118 3172 3252 3500 3763 3841 3730 3589 3278 3132 2995 2950 2893 2895 2786 2866 2855 2915 2852 2982 2954 3026 3172 3191 3460 3803 4019 4324 4614 5056 5105 4765 4669 4414 4093 4010 3577 3497 3399 3293 3339 3376 3452 3554 3799 3720 3714 3662 3537 3434 3284 3170 2956 2856 2807 2704 2812 2672 2624 2670 2608 2588 2608 2560 2517 2510 2610 2609 2523 2649 2545 2503 2444 2524 2555 2608 2450 2565 2504 2630 2654 2755 2738 2930 3002 3079 3349 3655 3797 3962 4191 4069 4062 3830 3592 3307 3038 2967 3034 2890 2990 2885 3017 3113 3141 3362 3292 3392 3326 3174 3066 2931 2798 2794 2804 2717 2729 2793 2676 2670 2662 2737 2832 3030 2947 3150 3450 3723 3827 4043 4236 4335 4162 4129 3926 3714 3496 3324 3148 3132 3035 3092 3159 3358 3443 3529 3779 3868 3959 3959 4125 4069 4026 3966 4054 3829 3707 3558 3437 3377 3226 3258 3185 3134 3279 3267 3304 3516 3728 3594 3778 3688 3585 3439 3328 3123 3073 3155 2935 3086 3250 3148 3392 3798 4053 4587 5081 5350 5461 5807 5922 5644 5647 5502 5509 5226 4953 4490 3965 3814 3812 3668 3750 3976 4044 4052 4151 4137 4082 3905 4027 3950 3637 3431 3266 3018 2838 2746 2735 2718 2729 2608 2634 2498 2476 2532 2524 2559 2533 2378 2453 2469 2553 2465 2455 2491 2484 2464 2500 2409 2410 2482 2413 2467 2409 2397 2480 2511 2492 2496 2416 2492 2319 2357 2351 2420 2480 2392 2409 2451 2522 2381 2374 2392 2378 2484 2445 2414 2488 2461 2323 2374 2461 2392 2398 2455 2429 2449 2469 2435 2350 2496 2458 2380 2479 2542 2484 2299 2411 2380 2551 2353 2440 2418 2407 2495 2404 2450 2390 2474 2487 2484 2520 2442 2613 2475 2537 2446 2536 2612 2536 2516 2509 2532 2440 2550 2489 2525 2547 2518 2593 2507 2549 2584 2560 2604 2346 2553 2456 2565 2556 2488 2566 2469 2485 2579 2542 2505 2537 2518 2622 2502 2540 2492 2564 2606 2559 2539 2476 2554 2585 2751 2709 2673 2882 2777 2853 2884 2913 3014 2971 2979 3067 3170 3217 3312 3260 3444 3614 3571 3787 4029 4329 4548 4841 4703 4816 4684 4512 4294 4250 3923 3616 3570 3493 3325 3432 3393 3406 3492 3646 3567 3693 3593 3676 3400 3427 3140 3106 3101 2911 2840 2794 2806 2822 2778 2965 2798 2903 2907 3067 3264 3522 3514 3714 3941 4125 4351 4489 4433 4459 4453 4193 4067 3790 3519 3414 3202 3153 3276 3174 3286 3396 3363 3346 3475 3436 3481 3518 3374 3405 3180 3024 2986 2798 2807 2731 2615 2600 2576 2573 2597 2436 2518 2623 2547 2528 2533 2458 2544 2574 2470 2517 2473 2543 2448 2400 2589 2584 2594 2602 2618 2759 2802 2888 2969 2971 3158 3229 3192 3253 3063 3030 2887 2889 2730 2728 2676 2692 2654 2566 2603 2661 2757 2800 2822 2974 2976 2781 2784 2741 2763 2600 2559 2575 2565 2528 2506 2632 2681 2511 2657 2628 2669 2764 2832 2915 2797 2907 2830 2896 2832 2795 2753 2675 2755 2735 2882 3003 3016 3202 3330 3324 3460 3523 3590 3401 3534 3391 3499 3499 3452 3347 3479 3343 3449 3356 3512 3640 3849 4136 4089 4302 4344 4267 4394 4282 4151 4146 4260 4170 4265 4320 4314 4376 4309 4419 4380 4230 4236 4126 4052 3809 3660 3571 3527 3332 3324 3411 3306 3337 3294 3405 3283 3312 3277 3125 3005 3144 3034 2830 2887 2771 2813 2723 2796 2791 2709 2768 2784 2774 2706 2936 2838 2946 3104 3194 3414 3491 3717 3807 4076 4098 3986 3771 3740 3517 3314 3309 3253 3166 3173 3227 3167 3211 3370 3467 3478 3571 3414 3420 3307 3267 3169 3123 2911 3003 3048 2913 2930 3042 2893 2902 2945 2960 3033 3124 2948 3050 3108 3156 3321 3275 3525 3687 3826 4148 4405 4663 4939 4842 4872 4832 4362 4238 3970 3775 3682 3528 3477 3391 3564 3480 3747 3961 4153 4410 4717 4945 5210 5449 5603 5730 5529 5306 5199 5069 5022 5010 5210 5381 5574 5727 5798 5576 5494 5217 5246 5394 5474 5715 5451 5333 5286 5014 4850 4834 4814 4885 4900 5007 4884 4716 4360 4137 4050 3860 3658 3791 3718 3652 3584 3577 3539 3346 3542 3641 3643 3806 3619 3498 3479 3601 3366 3511 3502 3395 3479 3383 3393 3412 3289 3260 3280 3241 3099 3098 3019 2913 2937 2877 2915 2991 2842 2912 2946 2841 2868 2897 2878 2851 2870 2763 2665 2675 2618 2658 2602 2638 2513 2488 2485 2613 2626 2490 2574 2627 2541 2576 2588 2638 2577 2630 2585 2605 2654 2657 2689 2734 2769 2820 2912 2822 3032 3174 3289 3467 3478 3536 3707 3781 3738 3698 3605 3533 3439 3357 3092 3159 3050 3035 3026 2903 2934 3106 2974 3002 3191 3202 3278 3335 3302 3260 3250 3224 3200 3220 3141 3175 2992 3073 3049 3020 2956 2831 2784 2772 2839 2719 2687 2775 2634 2736 2817 2827 2917 2861 2913 2962 2981 2957 3095 3063 3253 3478 3558 3858 3811 3581 3381 3115 2976 2891 2752 2768 2765 2748 2630 2695 2721 2793 2767 2815 2942 2937 2997 3015 3094 2928 2831 2795 2675 2646 2635 2647 2571 2637 2625 2662 2654 2472 2478 2467 2488 2617 2600 2533 2629 2635 2563 2729 2699 2826 2783 2738 2655 2771 2788 2725 2853 2693 2794 2622 2676 2690 2858 2743 2736 2784 2883 2920 2963 3209 3309 3315 3482 3444 3494 3517 3306 3131 3069 2993 2795 2764 2774 2724 2689 2547 2667 2675 2714 2660 2816 2899 2840 2914 2823 2841 2788 2704 2653 2577 2534 2556 2413 2509 2518 2433 2545 2422 2406 2454 2399 2438 2519 2420 2434 2434 2502 2495 2454 2392 2412 2424 2445 2431 2421 2410 2481 2505 2489 2410 2449 2439 2434 2461 2509 2386 2457 2440 2462 2503 2608 2527 2589 2544 2578 2570 2563 2675 2606 2677 2579 2734 2676 2554 2598 2618 2623 2542 2573 2391 2626 2420 2451 2492 2505 2569 2575 2443 2492 2570 2604 2462 2599 2666 2521 2451 2547 2552 2567 2552 2569 2445 2529 2491 2514 2539 2402 2491 2511 2482 2574 2598 2574 2498 2649 2564 2644 2696 2764 2895 2972 2989 3032 3093 2992 3020 3143 3054 3169 3298 3286 3394 3233 3274 3320 3273 3441 3566 3653 3781 3798 3896 3980 4166 4334 4372 4297 4349 4239 3949 3808 3664 3567 3394 3441 3524 3279 3330 3331 3164 3299 3218 3200 3246 3267 3351 3391 3276 3300 3007 3026 2927 2795 2805 2821 2730 2800 2689 2653 2602 2659 2621 2634 2525 2568 2507 2648 2545 2611 2557 2652 2717 2688 2823 2954 2971 3097 3255 3044 3186 3015 2925 2852 2803 2850 2720 2649 2677 2647 2576 2591 2655 2726 2655 2641 2793 2846 2717 2797 2786 2714 2779 2733 2712 2762 2648 2624 2678 2694 2704 2699 2721 2824 2853 2991 3072 3232 3322 3319 3305 3206 3173 3134 2896 2743 2793 2882 2691 2720 2663 2634 2738 2668 2680 2756 2815 2914 2919 2957 2981 2991 2948 2849 2883 2764 2879 2813 2811 2834 2872 2957 3148 3226 3361 3345 3468 3454 3427 3512 3335 3235 3200 3010 2969 2881 2834 2789 2820 2729 2777 2820 2844 2887 2944 2880 3038 2993 3039 2958 3012 3041 2917 2900 2837 2829 2821 2744 2817 2799 2881 2809 2855 2874 2963 3089 3111 3273 3555 3662 3758 3406 3389 3256 3150 3004 2916 2891 2892 2787 2722 2848 2842 2725 2850 2793 2913 3011 2924 3077 3184 3285 3160 3213 3191 3276 3278 3462 3628 3728 3744 3824 3851 3813 3686 3616 3425 3279 3128 2926 2826 2811 2868 2797 2892 2777 2992 3078 3028 3227 3311 3330 3388 3464 3348 3329 3246 3153 3041 3000 2887 2637 2802 2772 2641 2584 2592 2659 2750 2684 2657 2607 2614 2556 2614 2588 2616 2586 2570 2638 2679 2643 2595 2688 2638 2671 2729 2780 2783 2876 3080 3002 3209 3274 3336 3280 3250 3225 3075 3066 2947 2858 2882 2790 2773 2765 2845 2659 2781 2772 2698 2744 2976 2873 2932 2871 3043 3073 3033 3103 3019 3026 2952 2980 2967 2882 2894 2866 2749 2827 2734 2606 2607 2616 2549 2652 2607 2651 2503 2579 2636 2655 2696 2576 2582 2713 2636 2712 2773 2677 2881 2779 2807 2752 2858 2950 2974 3036 3224 3300 3583 3556 3609 3806 3623 3367 3292 3262 3344 3264 3260 3251 3325 3485 3474 3529 3493 3629 3616 3630 3708 3680 3567 3593 3637 3447 3257 3190 3177 3006 3101 3051 3125 3132 3242 3218 3281 3491 3451 3653 3740 3637 3563 3339 3170 3125 3020 2886 2877 2748 2753 2676 2600 2645 2716 2784 2774 2812 2882 2919 2973 2956 3135 3035 3019 3005 3025 2931 2913 2968 2942 2912 3016 3055 3057 3026 3210 3160 3155 3036 2989 2888 2802 2751 2818 2809 2744 2736 2681 2791 2788 2870 2856 2950 2873 2871 3015 3124 3180 3221 3295 3330 3403 3514 3375 3526 3447 3567 3472 3470 3366 3322 3242 3196 2995 2952 2931 2871 2929 2840 2943 3148 3110 3180 3368 3437 3449 3607 3714 3801 3901 4004 4059 4102 4133 4199 3970 3746 3583 3413 3208 3130 3071 3000 2889 2883 2939 3019 2926 3076 3138 3291 3101 3272 3340 3261 3266 3282 3122 3161 2878 2896 2846 2776 2788 2809 2705 2693 2720 2670 2862 2756 2827 2866 2938 2948 3007 3098 3018 3068 3010 2977 2947 3027 2910 2797 3055 2820 3014 2963 3119 3096 2978 3008 3049 3090 3142 3192 3291 3471 3535 3630 3746 3795 3786 3790 3577 3538 3324 3162 3150 3020 2980 2964 2966 2841 2834 2854 2824 2853 2830 2842 2850 2982 3038 3056 3023 2999 2913 2922 2879 2724 2652 2696 2633 2544 2578 2553 2570 2570 2572 2504 2521 2500 2510 2445 2439 2505 2459 2559 2530 2491 2464 2360 2407 2434 2479 2379 2485 2440 2484 2386 2415 2415 2396 2532 2418 2506 2478 2389 2427 2468 2505 2489 2478 2525 2571 2692 2636 2596 2676 2798 3022 3045 3130 3070 3136 3186 2965 2953 2905 2846 2881 2820 2742 2781 2735 2791 2860 2859 2839 2909 2842 2986 2896 2975 2980 2959 3053 2865 2874 2974 2804 2772 2846 2778 2598 2653 2791 2613 2584 2632 2637 2574 2609 2660 2667 2780 2764 2642 2605 2668 2630 2778 2693 2736 2727 2777 2857 2916 3095 3138 3034 3118 3006 2889 2966 2905 2969 2952 2893 3017 3054 3146 3191 3159 3249 3230 3150 3137 3025 2987 2988 2761 2861 2826 2891 2839 2890 2835 2811 2794 2747 2780 2624 2695 2738 2771 2759 2725 2722 2892 2845 2759 2681 2679 2558 2603 2561 2529 2383 2458 2474 2449 2497 2468 2504 2361 2421 2345 2428 2463 2414 2477 2419 2505 2530 2515 2459 2386 2504 2554 2499 2402 2406 2407 2377 2410 2430 2431 2446 2337 2445 2404 2430 2349 2430 2454 2464 2463 2464 2437 2462 2484 2409 2391 2501 2451 2560 2411 2540 2430 2445 2417 2487 2433 2451 2419 2509 2479 2399 2530 2488 2530 2570 2567 2577 2531 2605 2590 2516 2479 2468 2594 2550 2471 2468 2391 2476 2481 2563 2509 2444 2515 2438 2452 2523 2529 2441 2517 2527 2574 2525 2511 2558 2556 2525 2555 2593 2556 2597 2611 2768 2770 2705 2903 3051 3047 3147 3472 3517 3406 3505 3534 3480 3346 3193 3175 3186 3204 3260 3277 3334 3391 3449 3418 3616 3567 3470 3415 3320 3298 3267 3221 3369 3250 3148 3264 3188 3124 3156 2978 2990 2938 2869 2925 2845 2920 2972 2955 3017 2930 3076 2919 2834 2756 2653 2644 2650 2598 2603 2554 2632 2586 2495 2636 2533 2507 2557 2553 2554 2517 2489 2579 2602 2417 2598 2656 2619 2645 2717 2827 2884 2971 3004 3069 3200 3225 3384 3455 3381 3402 3371 3297 3156 3264 3259 3103 2967 3043 2972 2841 2829 2774 2809 2691 2696 2739 2899 2865 2732 2865 2894 3008 2916 2959 2920 2853 2967 2830 2870 2785 2877 2770 2712 2560 2585 2709 2558 2545 2579 2639 2550 2643 2511 2509 2619 2478 2559 2616 2594 2623 2648 2692 2708 2768 2860 2891 2876 2934 2924 3061 3006 3019 2951 3060 3019 3073 3059 3071 3146 3218 3233 3288 3239 3453 3231 3361 3588 3683 3682 3708 3795 3812 3731 3785 3651 3566 3473 3434 3295 3217 3259 3245 3154 3190 3101 3125 3235 3200 3124 3309 3361 3421 3513 3632 3743 3829 3911 4073 4175 4239 4245 4260 4336 4279 4255 4081 4067 4171 4057 4188 4380 4459 4484 4643 4567 4614 4543 4393 4372 4262 4089 4041 3862 3754 3657 3682 3519 3510 3442 3475 3356 3408 3263 3244 3295 3425 3384 3401 3558 3379 3497 3352 3535 3367 3241 3231 3122 3045 2936 2848 2789 2817 2775 2624 2697 2699 2791 2821 2610 2776 2627 2694 2688 2849 2949 2866 2896 3198 3226 3385 3429 3442 3364 3377 3366 3265 3089 3093 3039 3023 3056 3037 2937 2853 2839 2822 2847 2845 2796 2872 2753</intensities>
			</dataPoints>
			<nonAmbientPoints type="Temperature" unit="K">
[...]
			</nonAmbientPoints>
		</scan>
	</xrdMeasurement>
</xrdMeasurements>