File: powder_X-ray_diffraction/variable-temperature_experiments/NaTaO2F2/raw_data/290°C.xrdml
<?xml version="1.0" encoding="UTF-8"?>
<xrdMeasurements xmlns="http://www.xrdml.com/XRDMeasurement/1.7" xmlns:xsi="http://www.w3.org/2001/XMLSchema-instance" xsi:schemaLocation="http://www.xrdml.com/XRDMeasurement/1.7 http://www.xrdml.com/XRDMeasurement/1.7/XRDMeasurement.xsd" status="Completed">
	<comment>
		<entry>Configuration=XRK900, Owner=User-1, Creation date=12/01/2015 16:52:44</entry>
		<entry>Goniometer=Theta/Theta; Minimum step size 2Theta:0.0001; Minimum step size Omega:0.0001</entry>
		<entry>Sample stage=AP XRK-900 with z-axis; Minimum step size Z:0.001</entry>
		<entry>Diffractometer system=EMPYREAN</entry>
		<entry>Measurement program=C:\PANalytical\Data Collector\Programs\Gwen\NaTaO2F2\NaTaO2F2-Lent.xrdmp, Identifier={FF50B583-C5FF-42DA-A01D-A1FB659EF29A}</entry>
		<entry>Batch program=C:\PANalytical\Data Collector\Programs\Gwen\NaTaO2F2\Thermodiff-Ouail.xrdmp, Identifier={5D65A6B1-42FC-480C-9FBB-D7D88D55EA08}</entry>
	</comment>
	<sample type="To be analyzed">
		<id></id>
		<name></name>
		<preparedBy></preparedBy>
	</sample>
	<xrdMeasurement measurementType="Scan" status="Completed" sampleMode="Reflection">
		<comment>
			<entry>PHD Lower Level = 4.02 (keV), PHD Upper Level = 12.07 (keV)</entry>
		</comment>
		<usedWavelength intended="K-Alpha 1">
			<kAlpha1 unit="Angstrom">1.5405980</kAlpha1>
			<kAlpha2 unit="Angstrom">1.5444260</kAlpha2>
			<kBeta unit="Angstrom">1.3922500</kBeta>
			<ratioKAlpha2KAlpha1>0.5000</ratioKAlpha2KAlpha1>
		</usedWavelength>
		<incidentBeamPath>
			<radius unit="mm">240.00</radius>
			<xRayTube id="1010048" name="Empyrean Cu LFF HR (9430 033 7310x) DK434948">
				<tension unit="kV">45.0</tension>
				<current unit="mA">30.0</current>
				<anodeMaterial>Cu</anodeMaterial>
				<focus type="Line">
					<length unit="mm">12.0</length>
					<width unit="mm">0.4</width>
					<takeOffAngle unit="deg">6.0</takeOffAngle>
				</focus>
			</xRayTube>
			<sollerSlit id="21010001" name="Soller slits 0.02 rad.">
				<opening unit="rad">0.0200</opening>
			</sollerSlit>
			<mask id="22030010" name="Fixed mask 20 mm">
				<width unit="mm">20.00</width>
			</mask>
			<antiScatterSlit id="22010003" name="Fixed slit 1Â°" xsi:type="fixedAntiScatterSlitType">
				<height unit="mm">1.52</height>
			</antiScatterSlit>
			<divergenceSlit id="22010012" name="Programmable divergence slit" xsi:type="fixedDivergenceSlitType">
				<distanceToSample unit="mm">140.00</distanceToSample>
				<angle unit="deg">0.5</angle>
			</divergenceSlit>
		</incidentBeamPath>
		<diffractedBeamPath>
			<radius unit="mm">240.00</radius>
			<antiScatterSlit id="22090010" name="AS slit 8.0 mm (PIXcel)" xsi:type="fixedAntiScatterSlitType">
				<height unit="mm">8.00</height>
			</antiScatterSlit>
			<sollerSlit id="21010001" name="Soller slits 0.02 rad.">
				<opening unit="rad">0.0200</opening>
			</sollerSlit>
			<filter id="20030001" name="Large beta-filter Nickel">
				<material>Ni</material>
				<thickness unit="mm">0.020</thickness>
			</filter>
			<detector id="7010019" name="PIXcel1D-Medipix3 detector" xsi:type="rtmsDetectorType">
				<phd unit="%">
					<lowerLevel>25.0</lowerLevel>
					<upperLevel>75.0</upperLevel>
				</phd>
				<mode>Scanning</mode>
				<activeLength unit="deg">3.3482</activeLength>
			</detector>
		</diffractedBeamPath>
		<scan appendNumber="0" mode="Continuous" scanAxis="Gonio" status="Completed">
			<header>
				<startTimeStamp>2023-01-23T03:10:13+01:00</startTimeStamp>
				<endTimeStamp>2023-01-23T06:10:39+01:00</endTimeStamp>
				<author>
					<name>User</name>
				</author>
				<source>
					<applicationSoftware version="5.5a">Data Collector</applicationSoftware>
					<instrumentControlSoftware version="8.2  20201204">EMPYREAN</instrumentControlSoftware>
					<instrumentID>0000000011159748</instrumentID>
				</source>
			</header>
			<dataPoints>
				<positions axis="2Theta" unit="deg">
					<startPosition>9.99846514</startPosition>
					<endPosition>99.99342261</endPosition>
				</positions>
				<positions axis="Omega" unit="deg">
					<startPosition>4.99923257</startPosition>
					<endPosition>49.99671130</endPosition>
				</positions>
				<positions axis="Z" unit="mm">
					<commonPosition>8.846</commonPosition>
				</positions>
				<commonCountingTime unit="seconds">386.070</commonCountingTime>
				<intensities unit="counts">6460 6293 6540 6425 6237 6274 6248 6277 6233 6179 6382 6251 6073 6231 6180 6324 6231 6269 6236 6267 6026 6108 6235 6223 6224 6008 6217 6046 6190 6090 6155 6284 5986 6082 6173 6060 6170 6114 5943 6060 6078 6027 6001 5976 5954 5959 6001 5816 6130 6235 5983 5978 6078 6001 6097 6234 6067 6115 6187 6128 6242 6369 6182 6284 6262 6257 6418 6523 6515 6483 6692 6753 7068 7512 7932 8618 9564 10923 12716 16219 21048 26724 33718 41188 46327 48490 46163 39741 32597 25876 19330 14505 10938 8940 7558 7109 6930 6477 6407 6373 6347 6168 6029 6082 6054 6077 5975 5890 5783 5900 5856 5739 5822 5794 5860 5923 5785 5752 5611 5857 5907 5735 5760 5668 5713 5766 5707 5685 5771 5596 5586 5679 5718 5635 5615 5595 5713 5622 5584 5625 5668 5589 5535 5564 5613 5552 5538 5461 5469 5476 5513 5453 5507 5552 5619 5597 5393 5604 5525 5484 5642 5668 5626 5532 5415 5496 5658 5559 5659 5531 5542 5426 5513 5382 5440 5319 5401 5453 5415 5438 5420 5386 5362 5373 5382 5590 5435 5481 5516 5483 5404 5495 5362 5338 5429 5415 5456 5385 5315 5314 5427 5215 5297 5331 5346 5370 5261 5354 5340 5424 5377 5448 5296 5436 5342 5253 5341 5415 5316 5246 5119 5398 5166 5261 5149 5269 5329 5293 5422 5189 5171 5111 5317 5200 5300 5090 5159 5218 5153 5273 5178 5207 5209 5282 5376 5285 5186 5160 5159 5060 5019 5173 5015 5133 5166 5113 5141 5166 5190 5175 5065 5188 5148 5162 4971 5127 5234 5130 5121 5089 4993 5221 5003 4954 5008 5249 5100 5183 5170 5193 5035 5121 5139 4943 4992 5115 5012 5039 5006 5117 5055 5044 5213 4967 5011 4956 4996 5040 5046 4980 5024 4887 4905 4932 4854 4792 4929 5021 4851 4845 4961 4987 4978 4907 4963 4977 4890 4970 4945 4982 4931 4908 4856 5006 4968 4848 4786 4850 4877 4859 4904 4909 5005 5003 4789 4825 4868 4841 4888 4899 4769 4816 4953 4749 4733 4882 4793 4737 4772 4771 4708 4878 4879 4768 4753 4898 4875 4788 4778 4824 4663 4775 4737 4877 4923 4745 4787 4831 4682 4742 4719 4894 4787 4934 4776 4781 4768 4567 4746 4882 4874 4615 4742 4756 4868 4844 4857 4701 4852 4709 4748 4913 4745 4853 4665 4688 4765 4675 4740 4704 4696 4563 4721 4514 4686 4557 4667 4575 4639 4851 4786 4680 4733 4646 4864 4635 4614 4706 4538 4750 4584 4644 4547 4734 4637 4589 4695 4737 4641 4624 4599 4620 4611 4612 4627 4690 4534 4582 4636 4630 4662 4569 4557 4587 4659 4798 4525 4603 4547 4686 4589 4661 4537 4593 4722 4408 4764 4640 4617 4510 4608 4581 4673 4656 4681 4682 4649 4698 4757 4776 4822 4647 4642 4784 4726 4822 4667 4663 4676 4805 4764 4703 4698 4744 4678 4832 4617 4528 4653 4699 4690 4636 4579 4599 4605 4444 4398 4555 4600 4454 4588 4496 4485 4562 4502 4462 4513 4520 4548 4452 4425 4367 4382 4531 4527 4559 4508 4537 4436 4472 4504 4361 4535 4526 4424 4453 4380 4420 4338 4425 4650 4463 4378 4248 4391 4518 4352 4457 4399 4428 4335 4442 4445 4423 4348 4329 4407 4562 4451 4366 4467 4436 4501 4608 4482 4411 4390 4360 4423 4469 4400 4392 4520 4399 4356 4385 4289 4444 4343 4316 4292 4282 4326 4290 4274 4277 4304 4337 4323 4389 4333 4329 4291 4371 4394 4422 4569 4589 4647 4660 4537 4449 4370 4373 4427 4192 4253 4193 4311 4343 4217 4249 4336 4242 4138 4175 4154 4365 4261 4220 4202 4313 4340 4191 4332 4203 4224 4225 4146 4155 4193 4143 4215 4171 4232 4289 4145 4152 4226 4173 4205 4165 4260 4081 4121 4236 4114 4114 4119 4082 4149 4329 4122 4168 4120 4205 4127 4138 4148 4188 4161 4154 4116 4162 4224 4210 4133 4180 4269 4201 4320 4229 4217 4019 4251 4126 4120 4221 4090 4066 4115 4036 4116 4209 4065 4018 4133 4125 4221 4340 4268 4319 4290 4437 4421 4399 4343 4485 4489 4491 4508 4570 4469 4643 4515 4533 4627 4576 4445 4521 4541 4570 4635 4533 4492 4399 4612 4688 4595 4660 4704 4686 4769 5030 4901 5050 5194 5216 5512 5726 5833 6129 6523 7189 8377 10253 12878 16933 23400 33957 51787 74112 98597 117273 123091 117309 108820 97997 80052 61942 45771 32801 23353 16609 12356 10000 8134 6983 6248 5944 5503 5277 5011 4841 4748 4597 4557 4459 4482 4533 4561 4435 4410 4250 4360 4305 4261 4439 4432 4347 4334 4502 4430 4485 4497 4519 4490 4403 4240 4264 4148 4193 4223 4067 4065 4090 4062 4127 4112 4156 4056 4087 3994 3873 4007 3977 4009 4084 3987 4072 4057 3959 4047 3908 3983 4035 3824 3823 3967 3931 4081 4023 4011 3944 3984 3921 3948 4098 3924 4003 3986 3925 3978 3948 3986 3908 4009 3888 3941 3945 3945 3939 3816 3939 3861 3836 3971 3886 3983 4025 3964 3872 3781 3769 3834 3972 3895 3769 3791 3940 3703 3788 3899 3815 3969 3783 3838 3873 3860 3892 3841 3842 3903 3791 3907 3947 3836 3823 3972 3793 3782 3817 3854 3859 3756 3679 3782 3763 3820 3812 3881 3873 3827 3802 3766 3797 3802 3789 3858 3871 3802 3783 3917 3885 4025 3941 4035 4224 4075 4065 4094 4002 3954 3919 3873 3981 3932 3800 3899 3883 3824 3937 4015 4022 3890 3813 3871 3923 3966 3883 3804 3911 3879 4039 3915 3927 4037 4077 4039 4151 4301 4536 4789 5425 6256 7605 9789 13195 16327 18509 18539 17066 15728 14479 12443 10202 8235 6891 5563 4873 4215 4200 4031 3965 3940 3854 3993 3732 3857 3781 3644 3625 3835 3715 3686 3719 3787 3789 3732 3797 3745 3663 3809 3844 3902 3805 3724 3766 3801 3757 3763 3759 3740 3639 3729 3811 3724 3689 3566 3633 3684 3617 3665 3531 3576 3590 3601 3609 3592 3665 3680 3589 3578 3616 3664 3698 3626 3683 3490 3647 3699 3672 3597 3702 3666 3673 3635 3770 3838 3787 3608 3664 3821 3781 3749 3884 3759 3721 3842 3701 3896 3866 3943 3952 3892 3908 3881 3971 3850 3792 3938 3781 3778 3908 3807 3798 3778 3919 3882 4057 3896 4060 3914 3939 3900 4050 4065 4106 4118 4270 4122 4231 4395 4327 4362 4291 4516 4459 4766 4888 5103 5368 5727 6576 7827 10465 14611 21330 29412 37523 43119 44740 42851 39542 35931 32071 29243 25611 23986 26199 31874 37720 41928 46750 48813 45298 40660 36734 31767 26586 20380 15562 11892 8923 7039 5908 5096 4842 4566 4370 4384 4161 4160 3977 4014 3893 3993 3841 3731 3727 3808 3878 3823 3722 3777 3728 3690 3710 3671 3724 3692 3794 3740 3679 3731 3779 3826 3773 3978 3897 3793 3750 3804 3690 3724 3726 3695 3633 3661 3643 3742 3620 3555 3530 3566 3596 3712 3499 3547 3538 3644 3509 3627 3556 3521 3643 3619 3650 3641 3673 3624 3509 3614 3565 3645 3661 3602 3587 3676 3715 3556 3622 3501 3561 3465 3577 3482 3608 3441 3438 3419 3656 3564 3599 3551 3505 3472 3344 3317 3498 3497 3566 3496 3382 3516 3439 3555 3489 3486 3459 3417 3463 3429 3573 3551 3421 3564 3548 3386 3502 3393 3586 3402 3573 3521 3492 3615 3626 3696 3685 3700 3649 3664 3629 3665 3604 3659 3599 3670 3670 3577 3624 3450 3623 3496 3637 3574 3597 3472 3426 3525 3504 3435 3480 3463 3520 3481 3394 3502 3530 3359 3385 3352 3514 3437 3415 3503 3382 3466 3416 3519 3561 3573 3637 3535 3682 3476 3608 3545 3675 3633 3524 3530 3694 3568 3716 3636 3644 3627 3644 3517 3667 3688 3647 3556 3563 3553 3616 3561 3574 3657 3689 3654 3534 3623 3575 3751 3610 3521 3593 3702 3633 3632 3691 3674 3738 3667 3747 3804 3778 3763 3959 3788 3941 3938 4062 4119 4318 4386 4610 4793 4905 5141 5383 5889 6250 7009 7618 8861 10691 14334 19670 30062 45221 63300 78546 84711 79886 73290 67916 63124 57209 48122 38363 29726 21687 15894 11359 8679 7384 6270 5718 5246 4869 4638 4383 4245 4119 4043 3968 3789 3803 3763 3825 3709 3720 3681 3680 3803 3649 3676 3614 3686 3670 3799 3827 3706 3829 3821 3891 3730 3855 3809 3757 3709 3686 3767 3708 3679 3614 3605 3588 3694 3567 3611 3580 3543 3539 3663 3771 3605 3600 3522 3661 3571 3522 3569 3659 3648 3484 3489 3557 3597 3575 3535 3483 3639 3481 3416 3567 3545 3614 3558 3664 3721 3509 3524 3541 3609 3660 3554 3704 3629 3646 3793 3872 3861 3821 3976 4106 4096 4274 4418 4461 4715 5051 5446 6228 7708 10596 15374 22031 28090 32062 32731 29761 26534 25646 25127 24753 24079 23014 22247 22605 22426 21643 19260 16921 15111 13680 12496 11258 9469 7766 6335 5313 4556 4189 4062 3821 3772 3768 3728 3520 3528 3509 3502 3449 3609 3437 3410 3384 3512 3454 3441 3339 3372 3330 3419 3350 3388 3401 3372 3437 3343 3365 3396 3487 3338 3384 3385 3388 3360 3381 3219 3304 3264 3393 3227 3371 3361 3403 3364 3290 3278 3284 3231 3295 3237 3381 3285 3261 3336 3398 3351 3417 3404 3336 3315 3298 3262 3367 3316 3221 3364 3323 3244 3256 3311 3201 3284 3263 3235 3199 3265 3207 3155 3183 3232 3235 3299 3206 3050 3252 3207 3236 3227 3181 3246 3206 3225 3198 3172 3215 3200 3247 3218 3258 3216 3261 3126 3210 3108 3111 3269 3239 3172 3204 3219 3197 3205 3215 3168 3131 3155 3140 3028 3074 3201 3173 3045 3186 3161 3037 3143 3162 3083 3133 3201 3214 3179 3110 3102 3021 3147 3068 3232 3103 3203 3097 3073 3144 3143 3195 3106 3117 3109 3184 3177 3190 3067 3143 3103 3120 3086 3186 3178 3133 3056 3177 3188 3158 3071 3198 3136 3212 3143 3106 3211 3190 3120 3190 3103 3108 3152 3218 3168 3116 3108 3121 3115 3170 3205 3049 3114 3054 3056 3164 3158 3084 3151 3229 3224 3116 3149 3219 3194 3269 3350 3186 3227 3228 3222 3227 3343 3117 3197 3255 3159 3354 3227 3329 3284 3332 3352 3372 3405 3431 3530 3688 3573 3710 3878 3958 3912 4332 5070 6431 8855 12893 18043 20703 19633 16544 13571 12270 12825 13401 12593 10894 8533 6773 5681 4858 4287 3978 3848 3647 3611 3515 3481 3458 3390 3558 3437 3567 3618 3507 3530 3620 3618 3708 3760 3960 3979 4099 4174 4352 4302 4507 4690 5154 5662 6690 8851 12405 18049 25244 31921 35796 34039 30123 25581 23026 21879 21887 20736 18332 14625 11411 8821 6961 6031 5417 5198 5028 5067 5205 5319 5639 6199 7231 9191 12349 16358 20860 25454 28840 30266 29489 25937 22889 21023 20103 19179 18456 16737 15449 15496 16539 17648 17239 15297 12454 10620 10092 10124 10278 9614 8198 6642 5348 4746 4181 3786 3707 3560 3392 3360 3509 3326 3336 3322 3337 3384 3227 3207 3265 3244 3187 3270 3154 3300 3149 3345 3237 3293 3274 3349 3179 3096 3287 3373 3328 3314 3311 3347 3412 3475 3531 3574 3554 3884 4027 4532 5652 7368 9782 12647 14262 13818 12001 10321 9305 9134 9251 9194 8351 7394 6132 5034 4327 3971 3565 3499 3376 3373 3217 3183 3274 3135 3231 3470 3473 3482 3492 3475 3224 3285 3195 3321 3295 3138 3190 2992 3060 3030 3037 2987 3042 2974 2927 2934 2913 2931 2913 2944 2946 2904 3072 2952 2896 3019 2918 2970 3050 3057 2918 3029 2920 2858 3051 2951 2917 3025 3040 3043 2961 3043 2936 2907 2919 2896 2972 3066 3023 2933 3018 2868 2958 3083 3006 2983 3072 3002 2964 2911 2904 2942 2882 2998 2890 3008 2918 3024 2946 3081 3047 2970 2926 2863 2906 3043 2964 2944 2800 2948 2942 2821 2937 3001 2877 2936 3022 2841 2915 3009 2944 2980 2925 2963 2951 2998 3016 2883 2983 2894 2909 3023 2973 3013 2962 2992 2903 2974 2977 2867 2867 2882 2956 2946 3029 2858 2930 3091 2998 3001 3035 3077 3140 3216 3099 3097 3167 3523 3597 3821 4386 5374 6780 8243 9232 9071 8335 7111 6042 5789 6234 6203 6216 5686 5006 4285 3793 3460 3323 3255 3128 3146 3043 3231 3114 3035 3112 3097 3030 3003 3009 3138 3080 3112 3171 3086 3188 3227 3330 3425 3542 3838 4281 5095 6267 7702 9029 10002 10062 9458 8397 7602 6918 6817 6685 6705 6313 5631 4852 4259 3768 3520 3339 3215 3090 3137 3059 3166 3294 3548 3497 3569 3442 3310 3207 3207 3388 3220 3280 3237 3230 3075 3002 2966 2940 2937 2958 2947 2892 2804 2826 2822 2841 2754 2778 2891 2735 2816 2883 2815 2735 2849 2852 2808 2724 2841 2832 2743 2755 2725 2854 2786 2713 2755 2774 2797 2830 2780 2690 2831 2762 2784 2741 2795 2739 2756 2824 2835 2838 2777 2709 2803 2689 2755 2721 2720 2811 2715 2799 2813 2896 2657 2744 2755 2795 2828 2755 2739 2761 2762 2756 2796 2699 2783 2816 2853 2892 2803 2801 2776 2790 2781 2736 2810 2764 2734 2696 2834 2834 2719 2781 2770 2897 2684 2737 2804 2766 2643 2763 2785 2812 2792 2884 2716 2837 2829 2729 2774 2723 2713 2695 2767 2759 2730 2744 2917 2803 2809 2751 2734 2805 2791 2744 2779 2766 2763 2807 2709 2784 2878 2803 2879 2732 2770 2786 2856 2849 2844 2919 3016 3044 3106 3405 3675 3993 4282 4460 4584 4749 4289 4173 4044 4017 3950 3797 3825 3721 3683 3586 3549 3417 3461 3532 3727 4347 5127 6173 7110 8002 7828 7069 6228 5457 5356 5285 5618 5715 5347 5005 4392 3984 3634 3383 3398 3163 3222 3133 3261 3222 3091 3152 3190 3183 3491 3618 3979 4606 5619 7039 8939 10084 10411 9203 7781 6378 5930 5982 6631 6856 6814 6245 5190 4407 3864 3591 3341 3234 3129 3099 3109 2985 3086 3214 3114 3099 3114 3132 3152 3134 3154 3324 3438 3565 3867 4186 4658 5581 6635 8281 9889 11106 11440 10898 9428 8204 7506 7211 7771 8496 8978 9138 9540 10845 12166 13222 13175 12567 11093 10539 10866 12483 14921 16217 16495 14943 12250 9898 8523 7940 7866 8081 7764 7074 6283 5198 4424 3874 3424 3358 3176 3031 3044 3023 3064 2864 2913 2902 2911 2775 2673 2807 2787 2790 2782 2776 2834 2829 2733 2824 2732 2760 2741 2857 2792 2757 2818 2755 2737 2743 2742 2740 2805 2833 2795 2780 2709 2776 2740 2627 2745 2789 2743 2763 2731 2738 2769 2724 2673 2729 2768 2658 2767 2767 2707 2707 2826 2722 2649 2668 2803 2643 2740 2716 2707 2689 2717 2803 2794 2673 2808 2780 2621 2626 2645 2687 2642 2694 2688 2776 2609 2741 2643 2692 2703 2706 2749 2757 2665 2685 2715 2745 2712 2627 2604 2747 2750 2678 2702 2698 2737 2687 2662 2661 2582 2655 2734 2691 2711 2805 2722 2731 2657 2686 2732 2708 2805 2755 2715 2739 2766 2733 2687 2766 2697 2668 2746 2687 2686 2650 2684 2678 2667 2771 2689 2649 2611 2728 2664 2786 2689 2729 2786 2663 2739 2864 2895 3152 3185 3299 3333 3192 3106 3010 2953 3007 2888 3019 3089 3020 2945 2878 2831 2740 2746 2714 2699 2680 2621 2709 2717 2656 2728 2741 2673 2792 2682 2691 2757 2604 2679 2737 2654 2698 2596 2782 2709 2690 2618 2663 2708 2776 2667 2665 2679 2646 2616 2609 2703 2749 2787 2809 2722 2813 2887 2930 3299 3350 3687 3952 4156 4087 3870 3634 3450 3347 3416 3486 3629 3527 3506 3390 3370 3147 3087 3211 3237 3485 3788 4283 4832 5088 5358 5444 5059 4699 4274 3950 4000 4190 4174 4177 4098 3860 3624 3382 3210 3112 2893 2831 2767 2914 2681 2800 2730 2690 2690 2638 2740 2694 2719 2764 2689 2730 2734 2661 2737 2662 2720 2572 2625 2755 2707 2699 2603 2728 2637 2640 2577 2631 2720 2658 2727 2644 2791 2624 2694 2646 2712 2781 2782 2708 2716 2781 2754 2661 2732 2699 2657 2749 2769 2706 2785 2817 2812 2747 2823 2855 2796 2867 2928 2864 2931 3047 3069 3171 3291 3553 4051 4672 6011 7857 9800 11212 10780 9408 7266 5697 5104 4959 5675 6372 6955 6857 6366 5248 4217 3640 3344 3179 2962 2985 2909 2915 2764 2856 2764 2836 2730 2783 2757 2729 2764 2725 2770 2810 2789 2720 2769 2770 2795 2824 2815 2842 2791 2936 2930 2808 2830 2975 2997 3008 3164 3323 3288 3715 4436 5146 6080 7020 7004 6250 5204 4508 4246 3961 4165 4596 4761 4891 4818 4230 3720 3373 3144 2946 3023 2901 2965 2930 2832 2873 2871 2924 2839 2947 2865 2945 2857 2904 2778 2935 2868 2892 3009 2931 3008 3043 3037 3031 3167 3290 3442 3669 4217 4669 5494 6662 7383 8309 8640 8565 7413 6347 5478 5233 5144 5434 5703 5920 5884 5524 4727 4169 3680 3408 3286 3186 3056 3059 2995 3075 2997 3137 3145 3081 3112 3034 3203 3147 3227 3152 3234 3306 3423 3501 3427 3577 3600 3733 3777 4023 4200 4669 5030 5937 7066 8854 11609 14810 17907 20323 20170 17930 14920 12522 10973 9994 10536 11169 12131 12259 11682 9929 8248 6968 5761 4883 4454 4020 3927 3590 3424 3339 3401 3258 3128 3268 3263 3209 3253 3117 3096 3141 3291 3175 3220 3346 3299 3503 3468 3576 3857 4182 4942 6263 7807 9850 11518 12151 12428 12817 13377 13069 12393 11645 11136 10369 9517 9011 8582 8355 8389 8228 7554 6761 5929 5224 4565 4311 4451 4468 4839 5462 6625 8341 10664 12501 13356 12550 10656 8687 6966 6355 6275 6674 7414 8175 8196 7613 6532 5406 4802 4113 3767 3518 3257 3195 3284 3087 3067 2998 2981 3083 2910 2965 2897 3009 2897 2900 2818 2858 2897 2931 2943 2871 2884 2848 2909 2906 3060 2896 2981 2927 3041 3052 3126 3176 3219 3309 3509 3644 3609 3379 3266 3289 3243 3218 3316 3298 3322 3589 3537 3628 3616 3495 3512 3539 3666 3451 3557 3530 3524 3550 3665 3673 3553 3671 3726 3703 3939 3912 4130 4687 5248 6163 7591 9810 12886 15752 17959 18884 17675 15207 12700 10733 9598 9470 10212 11038 11632 11711 10936 9599 8099 6971 5796 5251 4729 4364 4177 4110 3906 3849 3908 3957 4136 4334 4802 5274 6288 7427 8657 10142 11027 11582 11061 9774 8177 7161 6582 6485 6687 7072 7451 7483 7389 6411 5701 4853 4410 3887 3715 3508 3411 3326 3218 3132 3153 3133 3076 2911 2953 3014 2926 2961 2862 2964 2945 2767 2952 2973 2951 2957 2766 2829 2854 2917 2867 2972 2973 2927 3046 2902 3016 3005 3051 3042 3033 3005 3004 3068 3193 3224 3355 3670 4032 4677 5653 7165 8282 8875 8675 7735 6444 5458 4890 4661 4682 5191 5799 6112 6236 5657 5163 4655 4162 4040 3948 3793 3759 3690 3322 3302 3046 2997 3046 3192 3127 3303 3238 3025 3130 2965 2966 2933 2796 2811 2897 2823 2838 2815 2810 2720 2750 2824 2831 2827 2831 2856 2835 2838 2889 2735 2714 2818 2842 2806 2792 2762 2801 2771 2895 2805 2873 2780 2868 2886 2821 2905 2860 2797 2741 2864 2960 2895 2917 2940 2958 3014 2984 3003 3050 3151 3145 3207 3163 3267 3309 3593 4080 4433 5172 6317 7563 8813 9977 10199 10171 9822 9090 8116 6906 6336 6073 6280 6479 6860 6776 6730 6366 5883 5190 4689 4180 4030 3979 4251 4450 4859 5130 5641 5948 6067 6247 6241 6037 5809 5298 4991 4558 4603 4550 4626 4606 4564 4390 4331 4147 3800 3463 3262 3013 3021 2993 2992 2810 2872 2789 2728 2822 2888 2828 2828 2867 2869 2752 2804 2815 2749 2883 2842 2968 2843 2851 2881 2881 2830 2876 3029 3076 3118 3344 3484 3676 3930 3999 4138 4102 3894 3711 3494 3278 3199 3152 3260 3419 3381 3403 3356 3317 3156 3042 2902 2945 2766 2834 2717 2706 2772 2793 2688 2839 2693 2690 2750 2744 2734 2777 2761 2837 2661 2778 2668 2690 2685 2827 2702 2810 2731 2756 2860 2905 2901 2911 3021 3202 3204 2996 3171 3109 3148 3139 3047 3034 2986 2932 2915 2903 3028 3000 2967 2895 2928 2843 2857 2798 2754 2861 2751 2723 2791 2742 2714 2737 2762 2787 2795 2759 2767 2675 2790 2682 2675 2745 2831 2711 2655 2831 2720 2705 2689 2724 2808 2765 2773 2799 2780 2781 2719 2872 2871 2843 2790 2868 2950 2926 2997 2904 2983 2983 2956 3006 2999 3115 3188 3209 3255 3377 3581 3796 4224 4700 5389 6595 8048 9717 11076 11259 10858 9314 8013 6721 6016 5709 5798 6216 6784 7240 7574 7308 6758 5844 5142 4531 4064 3768 3618 3676 3517 3539 3516 3559 3499 3297 3301 3085 2985 2919 3100 3059 3101 3054 3021 3024 3017 3031 2982 2863 2968 2853 2836 2836 2909 2936 2954 2933 2901 2885 2916 2846 2903 2993 3026 3103 3087 3148 3281 3222 3467 3639 3903 4299 4719 5361 5834 6301 6121 5938 5996 6362 7262 7972 9315 10333 11823 12448 12976 12754 11631 9972 8452 7505 6777 6663 6703 7074 7410 7538 7442 7051 6304 5743 4827 4311 3882 3612 3308 3348 3173 3109 3284 3209 3105 3179 3037 3163 3145 3109 3166 3101 3192 3195 3318 3361 3484 3677 4017 4215 4629 5258 6158 6825 7556 8309 8650 9326 9585 9549 9670 9312 8863 7908 7245 6817 6663 6841 6744 6998 7079 7647 7629 8071 8089 8278 7781 7685 7027 6198 5451 4708 4610 4295 4412 4533 4727 4843 5001 4810 4740 4231 3965 3591 3439 3309 3230 3148 3091 3055 3083 3064 3122 3071 3039 2981 3006 3122 3195 3052 3082 3075 3284 3341 3408 3454 3671 3984 4348 4885 5824 6923 8086 9110 9251 8599 7578 6549 5868 5396 5145 5292 5935 6486 6972 7380 7137 6542 5890 5176 4576 4193 4028 4059 3856 3987 3936 3881 3822 3558 3467 3407 3372 3426 3395 3468 3502 3501 3841 4096 4339 4720 5414 6060 6892 7789 8470 8811 8510 7950 7123 6273 5751 5376 5316 5509 5868 6220 6521 7120 7533 8008 8378 8949 9204 9548 9035 7982 6708 5754 5094 4779 4829 4986 5490 6106 6871 7309 7824 7987 8468 8986 9505 9594 9524 8666 7574 6412 5542 5114 5015 5009 5267 5549 5990 6312 6217 5839 5347 4634 4169 3786 3596 3322 3256 3230 3159 3081 3035 3176 3096 3098 3047 3023 3061 3064 2985 3054 3092 2962 3121 3240 2986 3146 3139 3363 3510 3753 4059 4617 5140 5701 6341 7086 8000 8265 8326 7976 7135 6499 5832 5450 5090 4947 5158 5411 5863 6057 6116 6264 6073 6110 6359 6553 6737 7206 8156 8954 9782 10958 11140 10808 9501 8176 6930 6181 5681 5681 5804 6032 6450 6683 7079 7047 6479 5663 5031 4302 3978 3636 3333 3326 3116 3205 3138 3108 3084 3058 3048 3155 3179 3077 3194 3093 3067 3103 3163 3235 3262 3302 3329 3446 3472 3709 3821 4098 4516 4914 5700 6721 8424 10201 12389 14265 14993 14496 13056 11056 9204 8144 7518 7330 7458 8129 8858 9967 10365 10634 10321 9336 8090 7248 6494 5677 5319 5179 5076 5163 5470 5488 5492 5375 5481 5605 5310 4989 4790 4362 3894 3820 3633 3645 3627 3748 3695 3582 3535 3684 3509 3418 3213 3158 2944 2795 2891 2747 2664 2767 2773 2686 2714 2757 2705 2700 2690 2599 2698 2682 2611 2691 2617 2586 2654 2598 2612 2746 2627 2735 2604 2612 2744 2684 2616 2593 2607 2607 2579 2567 2645 2622 2631 2653 2698 2558 2616 2639 2608 2618 2557 2623 2480 2487 2516 2572 2517 2489 2574 2509 2628 2674 2542 2534 2595 2583 2536 2547 2573 2541 2497 2572 2463 2576 2513 2584 2505 2524 2498 2469 2527 2588 2581 2534 2546 2560 2588 2511 2595 2476 2611 2616 2567 2610 2598 2549 2552 2630 2543 2518 2593 2699 2543 2576 2594 2603 2561 2567 2475 2582 2447 2533 2489 2551 2589 2499 2518 2560 2519 2570 2554 2471 2474 2550 2619 2551 2558 2468 2534 2551 2500 2559 2540 2533 2602 2564 2521 2522 2478 2535 2586 2608 2528 2514 2568 2384 2518 2572 2569 2495 2528 2538 2607 2627 2599 2682 2696 2549 2666 2727 2705 2732 2782 2694 2849 2940 2866 2811 3019 3016 3190 3357 3502 3759 4018 4137 3849 3767 3469 3389 3202 3224 3030 2963 3005 3171 3325 3145 3355 3323 3395 3140 2992 3004 2979 2994 2962 2956 3176 3322 3369 3826 3842 4123 4261 4195 4085 3776 3605 3396 3185 3185 3058 3207 3201 3333 3450 3464 3618 3638 3743 3742 3672 3775 3941 3956 3819 3751 3546 3309 3171 2945 2853 2897 2935 2994 2913 3042 3219 3078 3136 2964 2911 2749 2670 2584 2589 2626 2553 2575 2509 2546 2454 2562 2490 2443 2590 2488 2520 2561 2543 2534 2595 2443 2569 2679 2606 2680 2668 2843 2755 2826 2745 2771 2707 2793 2674 2658 2792 2704 2888 2779 2805 2769 2723 2665 2704 2682 2588 2584 2651 2549 2556 2552 2579 2669 2583 2574 2528 2404 2565 2486 2519 2485 2497 2546 2462 2487 2589 2415 2440 2457 2516 2480 2509 2298 2420 2429 2422 2521 2488 2410 2368 2415 2421 2409 2546 2499 2359 2406 2409 2524 2463 2498 2477 2509 2403 2411 2485 2418 2501 2450 2383 2462 2466 2530 2400 2518 2474 2514 2522 2518 2365 2485 2414 2462 2428 2457 2524 2373 2368 2425 2488 2386 2510 2406 2433 2458 2349 2502 2461 2476 2432 2470 2442 2373 2375 2450 2478 2370 2404 2569 2392 2413 2441 2360 2481 2453 2461 2455 2575 2616 2553 2501 2514 2421 2495 2459 2501 2473 2355 2414 2508 2478 2445 2447 2478 2466 2441 2456 2460 2565 2451 2543 2528 2578 2543 2622 2490 2534 2642 2531 2493 2413 2301 2472 2453 2414 2444 2401 2410 2478 2478 2557 2562 2538 2464 2411 2380 2307 2397 2433 2414 2372 2426 2433 2471 2378 2468 2458 2409 2408 2399 2390 2429 2387 2398 2461 2496 2454 2465 2527 2493 2535 2390 2378 2478 2364 2379 2443 2341 2455 2473 2493 2545 2470 2463 2468 2578 2468 2517 2464 2447 2551 2491 2505 2361 2394 2455 2500 2484 2497 2549 2379 2458 2481 2453 2489 2501 2546 2451 2543 2434 2365 2471 2555 2555 2484 2477 2421 2530 2542 2515 2510 2607 2660 2792 2751 2756 2944 3206 3277 3552 3782 4065 4068 4050 3910 3667 3535 3342 3270 3177 3196 3129 3123 3205 3415 3342 3464 3548 3730 3707 3990 4288 4863 4984 5170 5073 4693 4226 3770 3563 3305 3113 2983 2970 3177 3160 3331 3580 3748 3696 3650 3388 3336 3106 2752 2795 2735 2735 2552 2643 2694 2594 2599 2530 2571 2607 2609 2642 2557 2508 2527 2580 2532 2595 2577 2512 2549 2531 2469 2600 2538 2639 2651 2480 2561 2601 2680 2684 2743 2653 2756 2760 2904 3112 3224 3472 3780 3972 4497 4633 4818 4813 4585 4264 3952 3818 3381 3336 3378 3225 3270 3365 3538 3659 3921 3718 3740 3682 3695 3668 3710 3658 3681 3524 3299 3261 3119 3047 2975 3004 2899 3034 3125 3213 3233 3431 3594 3769 4120 4432 4687 5079 5534 6332 6945 7604 7968 7775 7405 6483 5923 5363 4710 4377 4264 4133 4413 4618 5036 5387 5527 5809 5767 5470 5054 4542 3985 3699 3475 3307 3174 2957 3097 3073 3088 3031 3104 2986 3011 2971 2974 2960 3078 2974 2964 3129 3142 3295 3452 3533 3745 4137 4725 4823 5152 5235 5178 4846 4464 4125 4056 3802 3835 3846 3924 4193 4601 4906 5118 5511 5809 5757 5606 5145 5167 4837 4317 4290 3971 3803 3684 3655 3578 3669 3653 3623 3689 3733 3651 3670 3561 3479 3411 3323 3263 3225 3241 3353 3651 3901 4190 5007 5202 5083 4534 4092 3670 3305 3173 2987 3045 3005 3004 3141 3228 3231 3501 3736 3792 3782 3484 3203 3073 3003 2913 2919 2896 2899 2830 2828 2935 2859 2792 2930 3089 3317 3360 3611 3794 4083 4385 4833 4909 5232 4957 4830 4483 4111 3731 3529 3465 3335 3363 3366 3282 3486 3633 3692 3862 3657 3708 3675 3439 3229 3088 2936 2824 2844 2798 2670 2646 2551 2688 2634 2682 2560 2554 2669 2659 2635 2618 2639 2515 2634 2553 2602 2722 2531 2668 2623 2595 2669 2664 2782 2739 2880 3011 3053 3225 3463 3699 3958 4086 4155 4110 3862 3586 3316 3292 3016 2906 2891 2979 2951 3006 3161 3130 3192 3284 3251 3334 3114 3081 2830 2848 2642 2695 2675 2652 2676 2656 2653 2819 2740 2798 2984 3002 3106 3435 3518 3808 3951 4134 4257 4304 4216 4025 3796 3526 3346 3321 3117 3217 3105 3110 3273 3439 3628 3805 3903 3942 4047 4251 4039 4079 4042 3966 3927 3837 3613 3448 3375 3097 3189 3167 3125 3221 3201 3259 3583 3485 3730 3735 3806 3659 3483 3384 3237 3154 2994 3066 3156 3242 3351 3366 3668 4092 4601 5089 5429 5774 5836 5927 5795 5586 5603 5377 5107 4651 4241 4050 3709 3804 3708 4049 4019 4280 4222 4244 4162 4298 4091 4014 3874 3627 3417 3260 2923 2777 2808 2713 2773 2656 2702 2498 2476 2616 2549 2547 2532 2535 2565 2451 2439 2594 2492 2473 2423 2497 2497 2456 2515 2453 2446 2596 2504 2450 2392 2531 2418 2509 2337 2431 2481 2404 2409 2426 2447 2516 2492 2487 2499 2523 2397 2517 2425 2438 2467 2449 2436 2376 2498 2505 2438 2474 2389 2474 2475 2455 2422 2482 2501 2411 2414 2524 2509 2484 2483 2406 2460 2402 2410 2380 2424 2432 2362 2365 2463 2496 2484 2432 2417 2439 2443 2504 2395 2443 2485 2445 2560 2547 2534 2507 2515 2444 2548 2554 2526 2509 2563 2565 2517 2537 2537 2491 2473 2514 2464 2585 2477 2550 2437 2473 2467 2582 2615 2588 2590 2562 2538 2593 2532 2500 2679 2554 2470 2509 2587 2605 2618 2536 2494 2591 2635 2631 2634 2639 2737 2814 2776 2908 2835 2970 2918 3021 3118 3251 3239 3282 3369 3613 3535 3781 3958 4263 4426 4646 4684 4796 4867 4913 4561 4350 4227 3852 3641 3641 3478 3530 3323 3526 3402 3580 3619 3599 3589 3580 3655 3435 3299 3197 3032 2954 2981 2944 2836 2866 2802 2877 2894 2927 3051 3227 3284 3408 3560 3814 3952 4251 4356 4482 4447 4397 4482 4189 3908 3656 3515 3284 3336 3292 3138 3159 3259 3454 3436 3420 3400 3477 3355 3471 3334 3196 3076 3031 2830 2831 2659 2625 2697 2650 2578 2629 2484 2528 2534 2522 2442 2596 2478 2510 2543 2550 2438 2479 2483 2456 2533 2546 2458 2587 2551 2565 2556 2629 2659 2672 2890 2892 2995 3022 3212 3232 3255 3131 2968 2973 2791 2777 2668 2597 2623 2679 2705 2660 2682 2840 2774 2777 2916 2859 2866 2823 2894 2737 2742 2720 2596 2679 2576 2672 2575 2490 2663 2571 2586 2698 2694 2788 2780 2843 2835 2857 2960 2777 2824 2739 2885 2805 2877 2849 2947 3111 3270 3290 3326 3525 3486 3594 3554 3615 3551 3645 3527 3411 3441 3525 3377 3499 3495 3647 3868 3939 4128 4361 4377 4247 4280 4154 4137 4117 4206 4303 4198 4423 4391 4480 4429 4319 4490 4399 4263 4088 3953 3801 3654 3557 3572 3421 3396 3322 3203 3298 3272 3320 3262 3219 3205 3150 3115 3076 2924 2844 2751 2795 2726 2551 2749 2710 2755 2797 2732 2810 2798 2819 2845 2859 3004 3175 3324 3418 3574 3842 3973 4032 3943 3876 3768 3523 3457 3364 3322 3321 3176 3272 3359 3305 3333 3391 3440 3512 3348 3469 3370 3340 3289 3185 3138 3038 2965 2935 2945 3034 2943 3026 3038 2937 3040 2953 3083 3144 3109 3201 3178 3335 3591 3709 3962 4183 4436 4630 4865 4956 4862 4714 4504 4156 3909 3769 3760 3522 3440 3500 3630 3595 3681 3930 4083 4390 4575 4859 5172 5361 5290 5468 5241 5279 4920 4938 4749 4917 4841 5092 5159 5433 5777 5853 5736 5772 5711 5607 5549 5741 5624 5521 5245 5064 4929 4883 4936 4811 4883 4722 4711 4724 4588 4400 4212 4030 3910 3807 3805 3708 3669 3541 3527 3507 3581 3639 3681 3676 3628 3513 3573 3517 3405 3433 3409 3268 3451 3430 3231 3411 3328 3274 3311 3149 3139 3029 2934 3036 2961 3061 2904 3102 2897 2954 3012 2909 2964 2961 2894 2949 2827 2846 2728 2703 2656 2555 2637 2598 2469 2631 2550 2557 2542 2607 2525 2620 2639 2560 2632 2529 2488 2611 2604 2570 2696 2726 2672 2784 2838 2840 2831 2835 3080 3317 3431 3502 3460 3632 3666 3750 3758 3680 3598 3520 3451 3189 3086 3040 2932 2939 2864 2963 2948 2992 3021 3107 3156 3244 3143 3230 3190 3291 3173 3233 3031 3116 3046 3007 3060 3059 3046 2950 3020 3006 2862 2853 2778 2744 2642 2715 2662 2707 2715 2702 2820 2871 2828 2905 2959 2822 3044 2977 3148 3187 3333 3643 3662 3809 3798 3448 3236 3081 2859 2704 2756 2733 2790 2707 2767 2741 2784 2758 2869 2974 3028 2990 3072 3100 2921 2764 2744 2648 2539 2693 2618 2479 2611 2609 2629 2481 2548 2515 2537 2656 2650 2666 2561 2603 2663 2850 2782 2824 2779 2713 2794 2821 2870 2902 2852 2703 2873 2714 2786 2682 2833 2701 2790 2922 2920 2943 2978 3081 3309 3447 3502 3444 3367 3435 3248 3155 3018 2880 2895 2754 2744 2780 2706 2674 2699 2739 2786 2783 2822 2888 2909 2873 2921 2795 2712 2706 2694 2586 2495 2548 2551 2481 2539 2596 2425 2452 2420 2456 2436 2511 2514 2429 2488 2408 2508 2398 2383 2403 2383 2415 2460 2432 2420 2457 2480 2496 2389 2405 2389 2406 2466 2479 2484 2429 2455 2552 2421 2457 2531 2460 2550 2601 2495 2490 2567 2697 2719 2633 2683 2636 2511 2696 2575 2584 2549 2582 2543 2517 2573 2623 2492 2569 2564 2552 2574 2575 2592 2583 2655 2546 2541 2619 2535 2593 2734 2577 2509 2589 2530 2541 2497 2446 2464 2567 2500 2439 2488 2506 2524 2554 2519 2564 2658 2580 2694 2737 2789 2923 2914 2906 2921 3008 3037 2973 3141 3094 3253 3193 3324 3460 3437 3365 3465 3409 3488 3537 3788 3706 3873 3947 3987 3946 4278 4294 4336 4223 4141 4109 3881 3723 3576 3530 3530 3355 3305 3412 3262 3236 3128 3265 3170 3273 3270 3301 3368 3186 3241 3142 2868 2976 2801 2822 2679 2700 2720 2725 2602 2643 2609 2586 2639 2569 2566 2637 2593 2601 2590 2662 2653 2716 2774 2811 2967 3048 3098 2996 3121 3050 3016 2853 2824 2796 2795 2706 2591 2661 2540 2585 2687 2677 2678 2723 2874 2758 2898 2792 2785 2789 2785 2762 2742 2615 2686 2590 2766 2623 2691 2681 2746 2767 2899 2971 3008 3200 3254 3269 3363 3422 3193 3164 2951 3017 2933 2722 2761 2693 2747 2675 2669 2668 2702 2716 2745 2865 2876 2968 2989 2939 2977 2892 2900 2922 2814 2888 2868 2870 2987 2922 3036 3124 3315 3207 3369 3481 3341 3423 3345 3370 3158 2996 3033 3016 2832 2870 2885 2772 2793 2824 2797 2805 3020 2972 2894 2983 2911 2986 2885 3000 2931 2887 2759 2775 2803 2775 2751 2753 2767 2734 2846 2816 2833 2925 2895 3035 3274 3378 3612 3595 3562 3438 3314 3090 3137 2908 2883 2801 2827 2764 2767 2836 2726 2883 2772 2824 2922 3002 3043 3217 3165 3224 3207 3269 3388 3506 3573 3629 3818 3700 3914 3719 3805 3584 3533 3325 3176 3038 2919 2852 2843 2768 2866 2782 2843 2880 3011 3099 3103 3298 3360 3353 3250 3417 3434 3285 3195 3043 2849 2989 2813 2730 2707 2669 2674 2664 2558 2637 2600 2563 2566 2585 2546 2575 2723 2696 2622 2609 2646 2637 2663 2640 2659 2641 2640 2564 2661 2830 2805 2937 3018 3166 3148 3344 3379 3358 3298 3198 3083 3068 2869 2910 2757 2761 2794 2703 2688 2689 2687 2673 2713 2845 2897 2981 2862 3051 3101 3133 3209 3120 3008 3017 2954 2996 2904 3057 2821 2751 2672 2693 2646 2603 2547 2569 2529 2603 2692 2588 2676 2522 2552 2706 2696 2681 2714 2725 2651 2787 2684 2760 2746 2641 2836 2857 2823 2869 3035 3172 3193 3265 3505 3414 3671 3700 3742 3639 3392 3356 3294 3357 3307 3285 3351 3421 3435 3558 3614 3640 3545 3598 3582 3555 3573 3542 3479 3459 3356 3208 3269 3206 3157 3185 3103 3201 3309 3498 3438 3709 3612 3643 3719 3424 3200 3056 3086 2986 2792 2693 2691 2786 2729 2633 2676 2793 2700 2802 2874 2846 2900 2942 3016 2926 2931 2901 2925 2927 3030 2913 2975 2961 2947 3105 3043 3132 3093 3145 3099 3016 2915 3005 2864 2875 2800 2789 2725 2807 2713 2794 2756 2772 2848 2821 2983 2826 2976 3030 3121 3081 3199 3282 3237 3331 3384 3401 3420 3470 3443 3544 3448 3413 3398 3293 3386 3117 3037 3107 3022 2942 3049 2942 2999 3206 3211 3281 3359 3507 3498 3547 3707 3743 3754 3931 4040 4166 4090 3930 3701 3616 3428 3397 3159 3036 3040 2823 2949 2961 2961 3022 3060 3180 3055 3239 3104 3256 3161 3128 3204 3104 3127 3035 3002 2883 2870 2872 2760 2773 2720 2716 2771 2694 2829 2773 2974 2865 3022 2958 3048 3022 3069 3154 3011 2947 3015 2986 3031 2865 2979 2963 2874 2968 2934 3059 3012 3153 3139 3217 3338 3367 3499 3697 3776 3696 3735 3747 3654 3431 3319 3166 3107 3025 2920 2977 2873 2954 2829 2835 2849 2810 2854 2886 2849 2922 2984 2980 3056 3054 3055 2970 2795 2790 2730 2626 2680 2637 2516 2491 2559 2580 2487 2487 2480 2478 2505 2468 2477 2501 2490 2539 2547 2466 2534 2386 2383 2445 2477 2439 2556 2415 2499 2519 2428 2424 2414 2498 2503 2472 2382 2509 2497 2394 2497 2592 2546 2602 2570 2596 2644 2721 2729 2780 2898 2997 3019 3133 3238 3115 2913 2942 2871 2790 2795 2781 2686 2753 2755 2651 2887 2733 2842 2899 2910 2936 3102 2903 3021 2927 3079 2888 2984 2834 2847 2731 2743 2649 2674 2530 2512 2635 2703 2671 2700 2589 2585 2635 2675 2697 2662 2767 2654 2650 2715 2596 2772 2768 2792 2809 2955 2963 2962 3026 3112 2978 3054 2899 2950 2998 2972 2977 2921 2870 2988 3043 3198 3155 3234 3296 3357 3243 3127 3090 3012 3045 2937 2786 2859 2766 2662 2901 2839 2756 2765 2705 2835 2691 2695 2729 2833 2826 2820 2822 2770 2752 2730 2631 2617 2552 2677 2450 2532 2543 2485 2541 2480 2543 2482 2419 2529 2356 2527 2500 2485 2377 2370 2357 2432 2463 2426 2501 2483 2425 2439 2457 2451 2556 2439 2459 2490 2416 2469 2392 2318 2460 2451 2412 2433 2342 2449 2350 2463 2484 2436 2484 2407 2395 2487 2500 2480 2404 2436 2464 2412 2431 2475 2507 2436 2584 2414 2435 2444 2438 2459 2685 2486 2614 2606 2513 2606 2581 2516 2636 2512 2545 2543 2556 2546 2553 2511 2462 2533 2528 2513 2517 2407 2512 2521 2564 2538 2553 2641 2505 2551 2631 2535 2604 2514 2506 2504 2476 2651 2711 2743 2766 2772 2883 3097 3174 3218 3375 3320 3478 3475 3485 3329 3391 3319 3258 3247 3397 3241 3318 3498 3558 3417 3452 3518 3445 3337 3286 3346 3330 3268 3231 3278 3210 3129 3175 3134 3027 3002 2934 3003 2972 2900 2889 2916 2896 3003 2933 2912 2831 2908 2755 2694 2766 2634 2566 2624 2591 2638 2530 2615 2544 2544 2573 2482 2428 2512 2556 2438 2615 2605 2584 2491 2579 2542 2602 2575 2550 2667 2764 2760 2776 2965 3160 3082 3237 3286 3415 3339 3326 3357 3275 3300 3214 3302 3099 3036 3043 2917 2929 2890 2864 2758 2865 2824 2729 2809 2770 2768 2763 2912 2985 2920 2972 2909 2973 2937 2887 2838 2793 2858 2836 2728 2721 2679 2602 2713 2632 2575 2641 2696 2653 2564 2539 2622 2481 2604 2598 2677 2627 2702 2726 2760 2771 2853 2877 2934 2867 2938 2991 2982 3105 2987 3043 2968 2986 2959 2906 3060 3036 3254 3143 3250 3211 3278 3427 3467 3513 3540 3633 3751 3828 3866 3826 3915 3735 3733 3484 3437 3312 3281 3275 3102 3143 3087 3023 3164 3223 3243 3294 3318 3328 3432 3469 3572 3704 3933 3865 3884 3960 4196 4152 4359 4179 4345 4344 4189 4216 4216 4118 4149 4219 4216 4190 4417 4466 4592 4595 4493 4440 4382 4265 4017 4027 3789 3563 3556 3448 3532 3540 3335 3449 3399 3350 3377 3261 3442 3379 3404 3431 3440 3345 3525 3417 3343 3364 3197 3157 3141 2889 2875 2781 2729 2722 2762 2741 2676 2761 2664 2731 2734 2783 2702 2779 2799 2783 2801 2925 3162 3065 3273 3443 3501 3461 3416 3359 3281 3237 3118 3153 3086 2961 2945 2895 3038 2789 2746 2772 2821 2782 2660 2761 2809 2817</intensities>
			</dataPoints>
			<nonAmbientPoints type="Temperature" unit="K">
[...]
			</nonAmbientPoints>
		</scan>
	</xrdMeasurement>
</xrdMeasurements>