File: powder_X-ray_diffraction/variable-temperature_experiments/NaTaO2F2/raw_data/40°C.xrdml
<?xml version="1.0" encoding="UTF-8"?>
<xrdMeasurements xmlns="http://www.xrdml.com/XRDMeasurement/1.7" xmlns:xsi="http://www.w3.org/2001/XMLSchema-instance" xsi:schemaLocation="http://www.xrdml.com/XRDMeasurement/1.7 http://www.xrdml.com/XRDMeasurement/1.7/XRDMeasurement.xsd" status="Completed">
	<comment>
		<entry>Configuration=XRK900, Owner=User-1, Creation date=12/01/2015 16:52:44</entry>
		<entry>Goniometer=Theta/Theta; Minimum step size 2Theta:0.0001; Minimum step size Omega:0.0001</entry>
		<entry>Sample stage=AP XRK-900 with z-axis; Minimum step size Z:0.001</entry>
		<entry>Diffractometer system=EMPYREAN</entry>
		<entry>Measurement program=C:\PANalytical\Data Collector\Programs\Gwen\NaTaO2F2\NaTaO2F2-Lent.xrdmp, Identifier={FF50B583-C5FF-42DA-A01D-A1FB659EF29A}</entry>
		<entry>Batch program=C:\PANalytical\Data Collector\Programs\Gwen\NaTaO2F2\Thermodiff-Ouail.xrdmp, Identifier={5D65A6B1-42FC-480C-9FBB-D7D88D55EA08}</entry>
	</comment>
	<sample type="To be analyzed">
		<id></id>
		<name></name>
		<preparedBy></preparedBy>
	</sample>
	<xrdMeasurement measurementType="Scan" status="Completed" sampleMode="Reflection">
		<comment>
			<entry>PHD Lower Level = 4.02 (keV), PHD Upper Level = 12.07 (keV)</entry>
		</comment>
		<usedWavelength intended="K-Alpha 1">
			<kAlpha1 unit="Angstrom">1.5405980</kAlpha1>
			<kAlpha2 unit="Angstrom">1.5444260</kAlpha2>
			<kBeta unit="Angstrom">1.3922500</kBeta>
			<ratioKAlpha2KAlpha1>0.5000</ratioKAlpha2KAlpha1>
		</usedWavelength>
		<incidentBeamPath>
			<radius unit="mm">240.00</radius>
			<xRayTube id="1010048" name="Empyrean Cu LFF HR (9430 033 7310x) DK434948">
				<tension unit="kV">45.0</tension>
				<current unit="mA">30.0</current>
				<anodeMaterial>Cu</anodeMaterial>
				<focus type="Line">
					<length unit="mm">12.0</length>
					<width unit="mm">0.4</width>
					<takeOffAngle unit="deg">6.0</takeOffAngle>
				</focus>
			</xRayTube>
			<sollerSlit id="21010001" name="Soller slits 0.02 rad.">
				<opening unit="rad">0.0200</opening>
			</sollerSlit>
			<mask id="22030010" name="Fixed mask 20 mm">
				<width unit="mm">20.00</width>
			</mask>
			<antiScatterSlit id="22010003" name="Fixed slit 1Â°" xsi:type="fixedAntiScatterSlitType">
				<height unit="mm">1.52</height>
			</antiScatterSlit>
			<divergenceSlit id="22010012" name="Programmable divergence slit" xsi:type="fixedDivergenceSlitType">
				<distanceToSample unit="mm">140.00</distanceToSample>
				<angle unit="deg">0.5</angle>
			</divergenceSlit>
		</incidentBeamPath>
		<diffractedBeamPath>
			<radius unit="mm">240.00</radius>
			<antiScatterSlit id="22090010" name="AS slit 8.0 mm (PIXcel)" xsi:type="fixedAntiScatterSlitType">
				<height unit="mm">8.00</height>
			</antiScatterSlit>
			<sollerSlit id="21010001" name="Soller slits 0.02 rad.">
				<opening unit="rad">0.0200</opening>
			</sollerSlit>
			<filter id="20030001" name="Large beta-filter Nickel">
				<material>Ni</material>
				<thickness unit="mm">0.020</thickness>
			</filter>
			<detector id="7010019" name="PIXcel1D-Medipix3 detector" xsi:type="rtmsDetectorType">
				<phd unit="%">
					<lowerLevel>25.0</lowerLevel>
					<upperLevel>75.0</upperLevel>
				</phd>
				<mode>Scanning</mode>
				<activeLength unit="deg">3.3482</activeLength>
			</detector>
		</diffractedBeamPath>
		<scan appendNumber="0" mode="Continuous" scanAxis="Gonio" status="Completed">
			<header>
				<startTimeStamp>2023-01-20T20:41:00+01:00</startTimeStamp>
				<endTimeStamp>2023-01-20T23:41:24+01:00</endTimeStamp>
				<author>
					<name>User</name>
				</author>
				<source>
					<applicationSoftware version="5.5a">Data Collector</applicationSoftware>
					<instrumentControlSoftware version="8.2  20201204">EMPYREAN</instrumentControlSoftware>
					<instrumentID>0000000011159748</instrumentID>
				</source>
			</header>
			<dataPoints>
				<positions axis="2Theta" unit="deg">
					<startPosition>9.99846514</startPosition>
					<endPosition>99.99342261</endPosition>
				</positions>
				<positions axis="Omega" unit="deg">
					<startPosition>4.99923257</startPosition>
					<endPosition>49.99671130</endPosition>
				</positions>
				<positions axis="Z" unit="mm">
					<commonPosition>8.846</commonPosition>
				</positions>
				<commonCountingTime unit="seconds">386.070</commonCountingTime>
				<intensities unit="counts">7406 7369 7552 7534 7522 7508 7301 7343 7333 7276 7403 7254 7500 7154 7364 7304 7382 7203 7130 7291 7199 7426 7191 7186 7091 7222 7350 7298 7251 7191 7340 7116 7195 7171 7277 7198 7283 7137 7129 7262 7055 7077 7050 7040 7083 7121 7052 7078 6995 7001 7028 7226 7178 7051 7239 7218 7082 7188 7220 7165 7384 7441 7392 7317 7444 7260 7268 7452 7432 7464 7500 7575 7746 8153 8408 8904 9354 10321 11172 12779 15469 19927 26266 33619 41698 49245 52370 48929 41869 35194 28133 21965 16964 13099 10382 8946 8074 7823 7610 7484 7455 7163 6965 7080 7048 6859 6853 6890 7060 7089 6906 6835 6890 6934 6733 6820 6784 6835 6801 6772 6823 6726 6850 6802 6511 6619 6686 6679 6602 6697 6618 6667 6740 6587 6738 6551 6724 6613 6731 6566 6624 6687 6516 6661 6666 6481 6584 6484 6541 6494 6509 6515 6415 6567 6583 6525 6550 6387 6531 6349 6292 6355 6635 6390 6471 6319 6297 6471 6502 6397 6280 6374 6470 6361 6413 6436 6249 6322 6250 6316 6296 6397 6407 6360 6195 6259 6359 6280 6344 6169 6144 6311 6439 6301 6199 6321 6291 6254 6225 6241 6257 6256 6157 6344 6180 6242 6220 6125 6149 6192 6182 6155 6098 6200 5970 6275 6141 6080 6073 6225 6112 6249 6207 6227 6092 6089 6050 6077 5973 6022 6018 6193 6110 6060 6150 6184 5996 5993 6263 6146 6086 6116 6055 6081 6081 6049 6111 6052 5972 6125 5964 5824 6003 5978 5978 6040 5970 5911 5992 5878 5891 5869 6061 6052 5956 5933 5882 5884 6102 6006 5894 5899 6033 5996 5869 5779 5876 5701 5732 5851 5997 5783 5842 5913 5849 5747 5963 5856 5860 5839 5859 5733 5803 5798 5937 5894 5736 5852 5816 5874 5771 5762 5764 5673 5862 5783 5641 5564 5761 5551 5626 5652 5677 5716 5668 5711 5709 5618 5664 5743 5509 5618 5663 5687 5571 5726 5755 5671 5569 5768 5548 5533 5459 5633 5621 5428 5471 5503 5510 5437 5549 5604 5550 5585 5625 5587 5636 5618 5521 5604 5549 5455 5519 5495 5594 5589 5570 5672 5330 5421 5492 5465 5471 5529 5511 5392 5400 5465 5448 5554 5562 5304 5420 5466 5454 5483 5483 5502 5420 5401 5371 5382 5445 5240 5372 5462 5187 5313 5469 5276 5400 5411 5370 5372 5305 5426 5400 5374 5476 5355 5353 5329 5454 5357 5463 5461 5434 5355 5266 5348 5329 5281 5309 5343 5406 5271 5332 5379 5310 5352 5241 5145 5296 5285 5293 5299 5299 5368 5266 5291 5122 5157 5402 5305 5226 5135 5157 5221 5286 5415 5319 5163 5345 5149 5362 5343 5068 5259 5147 5100 5269 5331 5334 5222 5166 5239 5269 5249 5280 5290 5136 5179 5097 5213 5216 5184 5146 5453 5286 5283 5294 5320 5180 5329 5370 5334 5355 5299 5412 5338 5305 5351 5163 5248 5218 5245 5400 5226 5382 5397 5326 5444 5309 5242 5256 5259 5232 5221 5236 5263 5226 5231 5082 5173 5157 5089 5003 5259 5077 4974 5122 5081 5047 5078 5140 5034 4991 4945 5002 5161 4917 5146 4955 4930 4887 4934 4952 5168 4985 4905 5023 4948 4993 4962 4955 5047 5008 5000 4976 4958 4980 4893 4940 4929 5030 4918 5110 4959 4898 4973 4933 5030 5092 5063 5152 5184 5171 5153 5167 5250 4981 5072 4963 5007 5026 4986 4718 4997 4879 4879 4992 4796 4885 4770 4769 4839 4737 4834 4785 4821 4739 4784 4832 4821 4849 4768 4890 4893 4849 4867 4976 4987 5008 5097 5099 5182 5066 5075 5002 4867 4840 4806 4874 4840 4773 4715 4906 4601 4789 4728 4722 4790 4683 4669 4691 4645 4739 4577 4607 4614 4624 4633 4643 4739 4741 4630 4684 4621 4534 4652 4594 4693 4649 4583 4596 4498 4755 4667 4589 4586 4631 4447 4645 4649 4620 4532 4605 4628 4710 4672 4528 4693 4616 4781 4710 4793 4688 4691 4721 4822 4806 4708 4666 4600 4626 4660 4513 4639 4515 4660 4542 4629 4631 4626 4508 4535 4544 4504 4520 4515 4524 4562 4595 4440 4571 4546 4432 4631 4595 4705 4552 4706 4745 4813 4990 5025 5021 4920 4903 4809 4838 5033 4960 4893 4901 4888 4933 4812 4743 5024 4927 4902 4945 5024 4896 4917 5025 5048 5151 5122 5189 5181 5497 5461 5701 5685 5911 6169 6194 6558 6937 7710 8559 10173 12456 15848 21277 30197 43696 63018 86077 106148 116140 112205 103671 94870 80157 63325 46340 32456 23355 16963 12644 9738 8031 7231 6816 6319 6002 5757 5387 5337 5148 5091 5036 4865 4876 4885 4880 4605 4717 4708 4660 4747 4741 4743 4843 4919 4777 4891 4956 4860 5037 4848 4918 4842 4821 4621 4497 4491 4449 4454 4559 4492 4425 4437 4400 4378 4435 4386 4477 4395 4369 4383 4353 4411 4467 4451 4364 4463 4347 4386 4389 4328 4326 4267 4320 4290 4243 4382 4302 4232 4235 4281 4324 4218 4404 4316 4405 4395 4298 4214 4291 4319 4364 4342 4243 4163 4111 4213 4336 4231 4275 4254 4269 4321 4229 4175 4299 4079 4073 4180 4244 4170 4174 4248 4219 4156 4220 4222 4283 4142 4046 4121 4208 4160 4223 4239 4199 4328 4160 4210 4180 4232 4204 4253 3979 4173 4010 4184 4124 4132 4219 4280 4204 4254 4137 4276 4310 4247 4163 4151 4201 4128 4211 4342 4105 4125 4087 4171 4250 4239 4394 4352 4423 4459 4534 4428 4493 4298 4368 4273 4192 4388 4278 4280 4244 4343 4273 4158 4293 4285 4319 4087 4243 4145 4126 4260 4243 4111 4249 4279 4315 4326 4617 4604 4751 5072 5839 6737 8256 10537 13746 17700 20253 20206 18194 16732 16112 14242 11204 8872 7176 6292 5497 4708 4469 4376 4186 4291 4315 4250 4011 4087 4113 4097 4005 4161 4072 4015 4015 4070 4099 4002 4162 4047 4016 4051 4014 4132 4139 4050 4011 3964 3908 3947 4052 4094 3869 4045 3925 4097 3847 4015 4056 3927 3925 3970 3875 3940 3914 3857 3830 3992 3907 3873 3934 4000 3908 3839 3782 4003 3897 3894 3968 3892 3930 3902 3987 3946 4047 3901 4077 3939 3893 4039 4050 4021 3915 3894 3927 3978 3924 4271 4024 4012 3994 4153 4065 3968 4016 4029 4176 4052 4192 4122 4291 4186 4245 3953 4065 4155 4200 4130 4070 4053 4130 4135 4172 4341 4376 4271 4276 4402 4477 4696 4609 4734 4786 4853 4858 5099 5143 5224 5747 6025 6959 8403 10966 15408 21362 28439 36809 44565 46003 42353 38028 35359 32562 28492 21851 16505 13156 11483 10917 10949 12970 17231 24506 32732 40603 45791 46886 45148 40641 37558 33061 26822 21089 15831 12537 9324 6992 5856 5170 4925 4653 4702 4352 4309 4160 4052 4165 4026 4055 3978 3981 3915 3928 4014 3988 3992 3908 3794 3951 3863 3888 3789 3941 3815 3795 3826 3863 3891 3970 3961 4006 4076 4032 4018 3913 3980 3940 3857 3847 3783 3773 3752 3680 3764 3779 3840 3802 3687 3701 3764 3720 3620 3704 3737 3769 3708 3821 3678 3747 3734 3738 3680 3754 3680 3750 3631 3686 3675 3638 3700 3667 3636 3652 3621 3691 3642 3670 3681 3570 3649 3518 3782 3657 3739 3685 3604 3496 3544 3599 3648 3653 3615 3635 3654 3737 3577 3632 3581 3538 3657 3578 3617 3743 3812 3765 3806 3923 4008 4058 4028 4020 4103 4061 4025 3953 3962 3925 3680 3654 3817 3761 3601 3572 3550 3523 3588 3624 3596 3604 3482 3622 3577 3572 3641 3636 3701 3632 3743 3524 3565 3561 3530 3619 3633 3620 3502 3542 3601 3689 3717 3465 3706 3595 3602 3568 3452 3432 3613 3490 3589 3480 3483 3519 3588 3623 3663 3714 3651 3731 3693 3775 3729 3797 3531 3735 3665 3729 3817 3783 3655 3829 3756 3818 3704 3651 3712 3779 3688 3619 3746 3681 3713 3792 3762 3786 3801 3682 3750 3786 3728 3738 3651 3712 3720 3783 3724 3642 3830 3845 3820 3826 3856 3901 3955 3971 3995 4039 4126 4124 4372 4480 4622 4571 4811 5101 5100 5362 5765 6086 6488 7423 8046 9359 11476 14857 20216 28586 42041 58337 72954 80068 77194 70388 63822 59380 54673 47188 38373 29594 22115 16115 11800 8963 7641 6647 6108 5603 5037 4736 4601 4404 4247 4088 4053 3943 4038 3898 3844 3888 3776 3801 3818 3717 3750 3759 3613 3674 3717 3817 3623 3785 3820 3936 3933 4100 4218 4039 3995 3976 3899 3868 3911 3816 3841 3724 3682 3785 3821 3661 3536 3621 3680 3624 3723 3679 3563 3663 3609 3627 3551 3615 3642 3645 3691 3516 3567 3584 3532 3663 3496 3524 3716 3607 3623 3558 3573 3467 3637 3583 3617 3692 3678 3647 3663 3801 3767 3846 3944 3869 3898 4079 4029 4131 4367 4632 4633 4749 5001 5255 5988 7420 10175 15044 20990 28240 34517 36082 32254 27202 25071 23786 23235 21263 17634 14386 12532 11698 12424 13834 16223 17918 18410 17937 16343 14572 13228 12039 11167 9906 8256 6733 5318 4645 4197 3991 3857 3709 3806 3654 3620 3641 3564 3539 3525 3400 3445 3398 3498 3377 3401 3413 3470 3527 3384 3414 3488 3507 3405 3393 3409 3518 3492 3455 3453 3389 3349 3306 3277 3390 3251 3346 3381 3417 3321 3348 3272 3410 3309 3356 3282 3324 3221 3421 3282 3320 3289 3398 3357 3282 3358 3320 3128 3378 3300 3380 3389 3408 3240 3329 3297 3316 3291 3360 3201 3285 3239 3230 3272 3260 3298 3277 3159 3212 3262 3254 3234 3284 3218 3182 3236 3261 3178 3190 3304 3118 3186 3227 3071 3152 3205 3150 3097 3361 3241 3240 3184 3115 3186 3166 3219 3214 3288 3120 3355 3274 3182 3198 3219 3129 3124 3132 3124 3134 3099 3222 3134 3201 3234 3268 3233 3042 3195 3197 3076 3232 3102 3112 3081 3105 3137 3070 3204 3137 3065 3028 3086 3145 3202 3055 3093 3103 3112 3155 3090 3052 3238 3164 3068 3212 2978 3229 3170 3142 3123 3175 3173 3183 3113 2986 3049 3088 3145 3022 3124 3056 3226 3058 3063 3126 3091 3133 3143 3174 3074 3140 3126 3147 3127 3208 3208 3190 3125 3252 3278 3206 3236 3184 3190 3325 3313 3270 3108 3223 3217 3387 3279 3207 3316 3205 3107 3327 3172 3131 3254 3223 3216 3313 3225 3122 3297 3119 3209 3306 3266 3248 3162 3428 3393 3351 3379 3572 3587 3534 3648 3782 3791 3798 4006 4154 4609 5388 7094 10294 15519 20852 22891 20596 16299 13094 12150 12786 13827 12974 10606 8054 6366 5256 4636 4164 4222 4037 4068 4090 4017 4102 4251 4350 4497 4580 4612 4746 5169 6054 7174 9473 13310 19030 26564 33272 35202 32001 27905 24911 22420 21663 21456 19671 16650 13485 10568 7839 6176 5186 4810 4573 4310 4153 4140 4010 3984 4103 4048 4079 4155 4084 4167 4330 4486 4586 4947 5248 5932 6517 7884 9728 12861 16927 21783 25886 29775 31821 31682 30960 32795 32833 30451 26723 23227 19829 17519 15772 13471 10926 8547 6927 5901 4866 4443 4031 3841 3738 3686 3505 3453 3487 3321 3369 3309 3378 3225 3312 3222 3240 3241 3227 3273 3283 3153 3141 3117 3155 3085 3142 3188 3090 3113 3118 3250 3191 3217 3173 3214 3187 3247 3354 3312 3205 3227 3362 3362 3442 3352 3417 3430 3664 3722 3821 4148 4656 5932 7292 9679 12745 14159 13675 11882 10199 8750 8601 8925 9111 8482 7173 5964 4925 4232 3833 3539 3467 3470 3301 3226 3243 3270 3467 3577 3740 4059 3956 3792 3585 3488 3366 3415 3472 3457 3364 3328 3163 3158 3148 2961 3011 2962 2997 2959 3082 2904 2947 2994 3043 3062 2962 3012 3065 3044 2905 2870 2993 3007 2883 2977 2923 2949 2910 2897 2993 3000 2914 3049 2927 2929 2977 2968 2929 2822 2946 3055 2881 2889 2924 2812 2799 2976 2872 2865 2975 2867 2998 3022 2961 2931 3050 2923 2983 2963 2870 2955 3009 2934 2868 3037 3004 2996 2956 3021 2979 3099 3032 3104 3101 3019 3007 3092 2965 2985 2953 2901 2996 2960 2919 2972 2964 2968 2923 2909 2994 3049 2943 2865 2892 2996 2945 3049 3122 3109 3230 3061 3163 3233 3256 3638 4251 5252 6776 8391 9536 9996 9161 7672 6298 5901 6292 6421 6654 6186 5435 4569 3820 3489 3410 3193 2975 3070 3056 3044 2999 2995 3020 3010 2955 2895 2927 2934 2886 2914 2883 2887 2872 2985 2825 2966 2925 2954 2905 2915 2943 2926 3051 2902 3063 3074 3144 3024 3135 3192 3186 3240 3285 3432 3600 3890 4352 5031 6261 7562 8802 9612 10080 9955 9063 7950 7260 7059 6830 6750 6552 6021 5378 4583 4079 3545 3444 3236 3158 3214 3319 3434 3816 3860 3783 3783 3542 3462 3393 3321 3306 3413 3359 3109 3119 3106 3007 2816 2861 2896 2797 2793 2794 2792 2793 2727 2762 2784 2859 2779 2729 2745 2679 2840 2753 2786 2745 2696 2836 2761 2681 2765 2797 2581 2729 2753 2758 2743 2719 2841 2772 2731 2745 2703 2767 2711 2715 2715 2694 2738 2737 2733 2639 2759 2755 2846 2777 2741 2764 2758 2730 2763 2838 2861 2707 2675 2694 2703 2785 2749 2827 2757 2765 2697 2722 2760 2751 2791 2659 2657 2707 2591 2664 2772 2692 2704 2739 2791 2680 2727 2821 2749 2689 2775 2747 2670 2711 2754 2789 2744 2722 2643 2662 2669 2608 2691 2710 2776 2783 2753 2788 2791 2752 2678 2712 2771 2822 2732 2786 2731 2643 2618 2741 2759 2764 2600 2826 2746 2721 2753 2822 2810 2727 2751 2800 2922 2771 2904 3068 3057 2971 3147 3332 3799 4285 4776 5107 5204 5102 4845 4332 4120 4159 4244 4071 4082 4088 3743 3547 3453 3204 3143 3061 3088 3227 3123 3155 3258 3448 3777 4171 4951 5803 6778 7194 7236 6655 6000 5290 5208 5247 5371 5549 5397 5064 4924 4920 5127 5897 7153 8802 9692 9472 8246 6891 5950 5627 5885 6081 6443 6228 5657 4805 4207 3772 3531 3250 3155 3130 3008 2978 3000 2884 2888 2870 2859 2743 2777 2850 2874 2751 2757 2781 2865 2813 2850 2771 2799 2961 2894 2907 2863 2965 3079 3153 3137 3225 3330 3330 3560 3674 3925 4364 4889 5735 6843 8029 9420 10616 11219 10605 9278 8503 8042 8308 9556 11517 13813 15724 16043 14130 11918 9582 8050 8090 8924 10661 12774 14045 15001 14926 14371 12289 9780 8081 7354 7105 7787 8117 8082 7186 6214 5351 4382 3739 3336 3276 3153 3077 2950 2852 2898 2759 2800 2925 2724 2759 2804 2696 2687 2727 2699 2831 2694 2716 2646 2656 2701 2630 2717 2698 2684 2707 2617 2583 2566 2613 2654 2637 2630 2638 2709 2807 2677 2650 2604 2640 2763 2682 2679 2621 2561 2737 2672 2626 2679 2670 2631 2609 2525 2688 2615 2676 2666 2576 2577 2622 2698 2642 2713 2616 2785 2612 2717 2662 2669 2663 2627 2681 2683 2574 2589 2638 2674 2736 2668 2581 2541 2598 2697 2583 2703 2737 2685 2673 2580 2612 2764 2641 2757 2557 2730 2713 2641 2732 2558 2650 2693 2696 2686 2681 2572 2706 2689 2596 2602 2642 2604 2653 2736 2764 2661 2681 2654 2551 2562 2656 2686 2638 2584 2607 2630 2600 2678 2696 2679 2629 2634 2702 2634 2640 2747 2737 2683 2699 2686 2842 2968 3006 3124 3283 3549 3419 3393 3341 3077 2962 3076 3166 3188 3054 3058 2967 2962 2819 2800 2663 2697 2598 2647 2725 2569 2543 2640 2659 2609 2672 2577 2734 2700 2604 2647 2600 2618 2639 2544 2621 2643 2600 2584 2582 2575 2541 2558 2594 2573 2613 2653 2674 2778 2685 2813 2911 3030 3033 3068 3090 3075 3323 3463 3712 3863 3740 3607 3422 3265 3055 2972 3023 3199 3279 3251 3124 2987 2866 2915 2797 2798 2692 2695 2776 2804 2842 2920 2922 3012 3160 3316 3616 3893 4571 5029 5578 5887 5651 5346 4964 4498 4272 4161 4125 4233 4360 4158 3968 3653 3384 3061 2989 2919 2718 2834 2646 2750 2746 2768 2647 2587 2589 2612 2563 2660 2639 2687 2610 2624 2583 2542 2593 2646 2574 2636 2529 2626 2587 2516 2633 2635 2660 2542 2620 2666 2579 2595 2604 2609 2572 2676 2581 2730 2580 2764 2669 2742 2822 2830 2792 2770 2858 2937 2812 2903 2985 3029 3141 3313 3622 4218 5298 7212 9630 11773 12267 10852 8341 6388 5303 4906 5300 6312 7253 7630 7102 5814 4730 3951 3374 3077 2934 2927 2762 2809 2934 2818 2701 2687 2734 2763 2705 2734 2653 2722 2769 2807 2789 2770 2664 2757 2825 2938 2902 3042 3313 3700 4522 5698 7135 7834 7205 6119 5079 4298 3974 3877 4247 4785 5288 5215 4650 4089 3519 3162 3049 2902 2838 2716 2755 2738 2747 2697 2683 2789 2713 2723 2649 2677 2716 2656 2673 2723 2673 2685 2693 2665 2584 2616 2647 2752 2690 2642 2703 2608 2678 2704 2639 2635 2668 2780 2686 2747 2802 2773 2812 2861 2989 2919 2963 2905 3012 3105 3324 3343 3553 3934 4480 5173 6288 7276 8414 9029 9129 8114 6850 5762 5098 4971 5303 5582 5868 5981 5803 5108 4388 3693 3409 3076 3063 3011 3007 2934 2856 2936 2935 2977 2931 3064 3079 3210 3273 3355 3304 3339 3360 3526 3506 3560 3755 3937 4141 4372 4742 5178 6019 6969 8691 10881 13926 16983 19110 18791 16693 14132 11898 10379 9677 9952 10970 11653 11874 11050 9785 8168 6746 5677 4900 4433 4040 3911 3643 3559 3430 3527 3413 3420 3456 3496 3420 3356 3258 3331 3468 3662 4034 4530 5331 6810 8735 10655 11966 12169 12409 12287 12088 11359 10397 9805 9265 8935 8473 8290 7897 7818 7441 6978 6260 5489 4854 4361 3919 3731 3701 3819 4094 4279 5024 5946 7225 9179 11233 12829 12841 11341 9453 7745 6595 6162 6240 6935 7453 8245 7929 7157 6110 5282 4382 3914 3661 3402 3229 3051 3069 2986 2887 2930 2867 2837 2787 2763 2723 2701 2737 2790 2840 2879 2843 2692 2802 2819 2866 3083 3121 3338 3384 3400 3475 3268 3098 3060 3043 2990 3148 3244 3402 3457 3517 3348 3292 3228 3295 3206 3217 3037 3173 3232 3108 3064 3034 3090 3096 3121 3155 3168 3183 3208 3293 3303 3271 3327 3434 3487 3491 3740 3914 4401 4801 5660 6822 8780 11200 14663 17330 18420 18031 16250 13494 11541 9994 9953 10270 11404 12826 13045 12653 11240 9028 7544 6421 5626 5297 4927 4699 4374 4195 3866 3677 3482 3364 3202 3301 3097 3179 3232 3077 3240 3202 3243 3287 3246 3448 3654 3703 3790 4059 4549 4978 6000 6886 8111 9241 10320 10781 10376 8994 7805 6708 6314 6048 6173 6473 6591 6852 6640 6246 5264 4625 4186 3786 3532 3299 3099 3143 3004 2826 2872 2825 2784 2745 2870 2728 2692 2720 2683 2761 2689 2746 2709 2743 2752 2641 2843 2724 2739 2743 2716 2748 2763 2767 2804 2810 2816 2801 2801 2868 2980 2916 2937 3085 3118 3143 3266 3373 3524 3723 3897 4369 5091 6185 7785 8827 9227 8306 6940 5714 4851 4273 4160 4667 5117 5677 6070 5819 5296 4483 4109 3900 3867 3930 3823 3659 3398 3181 2936 2929 2980 2938 3099 3071 3053 3158 3058 2833 2770 2842 2676 2797 2829 2633 2696 2641 2729 2646 2670 2696 2572 2616 2745 2663 2646 2675 2669 2677 2764 2773 2730 2797 2879 2744 2840 2861 2926 2952 2986 3063 3099 3038 3100 3369 3635 4164 4835 5763 7389 8715 9716 10408 11198 10939 9884 8576 7077 5891 5612 5943 6164 6757 7000 7089 6793 6068 5361 4461 3844 3478 3177 3072 2966 3017 2936 3028 2946 2910 2895 3055 3114 3240 3512 3762 4052 4677 5009 5110 5201 5185 5310 5325 5187 4745 4454 4178 4026 3949 3997 4013 4041 3878 3977 3866 3601 3404 3159 2938 2809 2763 2724 2749 2639 2811 2727 2682 2724 2796 2862 3030 3272 3552 3872 4276 4392 4543 4352 4046 3673 3254 3175 3148 3412 3436 3528 3665 3535 3484 3288 3022 2961 2936 2809 2864 2728 2742 2717 2622 2699 2638 2693 2648 2646 2658 2675 2581 2588 2574 2635 2504 2631 2501 2603 2519 2460 2552 2506 2588 2636 2616 2508 2455 2519 2594 2509 2553 2444 2551 2513 2510 2537 2651 2649 2645 2530 2544 2567 2604 2617 2577 2650 2635 2718 2736 2832 2865 2931 2923 2929 2901 2752 2865 2878 2764 2859 2740 2816 2679 2797 2697 2725 2678 2687 2729 2639 2628 2632 2618 2655 2585 2556 2670 2476 2561 2582 2612 2582 2578 2519 2561 2531 2613 2537 2526 2588 2545 2528 2555 2637 2583 2681 2618 2563 2471 2536 2511 2658 2576 2515 2648 2576 2601 2681 2612 2606 2614 2739 2674 2672 2699 2826 2808 2704 2883 2853 2900 2930 2986 2955 3011 3002 3172 3212 3258 3506 3677 3993 4322 5273 6126 7598 9114 10456 11368 11142 10104 8620 7185 6096 5758 5634 5884 6444 7062 7454 7464 7002 6277 5331 4717 4182 3813 3686 3553 3410 3401 3309 3534 3580 3645 3643 3504 3245 3245 3133 3126 3131 3056 3065 3145 3225 3310 3221 3334 3161 3133 3131 3191 3330 3417 3643 3996 4826 5721 6926 8587 9843 10780 10984 10582 9581 7960 6592 5856 5640 6035 6798 8049 9161 9700 10111 9437 8352 6933 5773 5429 5317 5387 5838 6089 6108 5894 5481 5042 4675 4075 3914 3907 3709 3872 3789 3819 3742 3499 3195 3168 3159 3049 2929 2889 2859 2840 2994 2814 2869 2801 2843 2915 2933 2982 2961 3076 3041 2973 3133 3216 3210 3390 3503 3799 4135 4678 5191 5934 7056 7881 8745 9116 9543 9823 9849 9979 9282 8893 8192 7498 7328 7058 7661 8189 8619 9396 9740 9331 8714 7621 6727 5599 4846 4545 4427 4401 4401 4714 4766 4700 4397 4245 4044 3499 3463 3358 3099 3084 3008 3142 2968 3090 3166 3126 3136 3195 3209 3469 3564 3966 4306 4953 5604 6692 7790 8430 8188 7486 6427 5587 4962 4611 4541 4545 4858 5593 6144 6401 6484 5915 5199 4563 4104 3855 3703 3527 3418 3598 3730 4008 3849 3810 3690 3533 3309 3145 3121 3014 3018 3048 3042 3122 3201 3224 3144 2987 3072 2911 2971 2920 3029 2943 2989 3005 3084 3247 3345 3552 3756 3920 4284 4581 5164 5739 6541 7274 7950 8208 8125 7757 6957 6204 5809 5711 5957 6413 7210 8171 9635 10730 11693 11431 10720 9044 7423 6092 5400 5150 4913 4934 5399 5844 6255 6440 6334 5836 5188 4997 4511 4532 4719 5202 5806 6658 7566 8744 9392 9537 9088 8179 6804 5782 5133 4789 4892 5110 5405 5895 6163 6244 6015 5947 4996 4422 4036 3725 3608 3439 3248 3227 3185 3225 3162 3301 3494 3516 3658 3844 4342 4755 5729 6735 7773 9001 10009 10370 11050 10582 10138 9560 8663 8828 10005 11576 13245 14019 13531 12468 10826 9762 8513 7553 6743 6364 6209 6522 7023 7404 7118 6410 5723 4884 4074 3866 3444 3329 3197 3097 3009 2953 2822 2808 2756 2784 2696 2774 2759 2648 2690 2644 2617 2695 2699 2741 2828 2721 2786 2831 2738 2816 2846 2707 2855 2735 2842 2949 2901 3034 3022 3076 3230 3245 3346 3638 3864 4241 4885 5602 6757 8086 9162 9853 9783 9114 8074 7159 6842 6763 6930 7818 8929 9890 10933 11394 10983 9926 8921 7784 6644 5964 5795 5774 6190 6545 7081 7373 7244 7078 6597 6264 5867 5456 5354 5255 5310 5276 5431 5577 5796 5866 5838 5711 5274 4899 4495 3946 3737 3811 3693 3864 3799 3848 3775 3679 3705 3322 3315 2959 2760 2795 2675 2667 2603 2545 2493 2479 2446 2529 2504 2498 2529 2629 2458 2427 2469 2570 2536 2528 2421 2527 2339 2369 2458 2463 2377 2535 2533 2546 2588 2496 2403 2618 2434 2475 2428 2471 2452 2541 2444 2523 2427 2432 2457 2489 2426 2561 2432 2342 2455 2391 2476 2357 2357 2416 2443 2444 2464 2431 2472 2485 2514 2531 2599 2610 2544 2604 2510 2555 2485 2456 2471 2381 2465 2438 2414 2458 2454 2451 2444 2440 2439 2288 2421 2417 2480 2459 2418 2372 2379 2410 2436 2430 2385 2350 2451 2363 2374 2323 2395 2410 2347 2432 2429 2372 2376 2300 2485 2452 2415 2313 2389 2438 2400 2463 2415 2432 2363 2384 2370 2334 2435 2449 2397 2324 2352 2407 2405 2433 2389 2353 2382 2416 2315 2366 2358 2430 2454 2386 2441 2400 2353 2434 2490 2402 2415 2446 2361 2544 2550 2446 2511 2442 2428 2512 2556 2546 2522 2544 2739 2798 2864 2953 3069 3131 3372 3597 3891 3971 4153 4023 3798 3521 3187 3219 3077 2960 3047 2998 3046 3115 3229 3269 3276 3170 3092 2909 2841 2680 2647 2631 2601 2602 2700 2627 2703 2605 2712 2842 2766 2947 3055 3284 3669 3972 4334 4719 5077 5194 5408 5232 5050 4656 4271 3923 3654 3482 3557 3656 3721 3724 3840 3759 3932 3814 3657 3524 3248 2982 2841 2648 2670 2556 2547 2505 2466 2377 2521 2437 2409 2488 2357 2433 2356 2419 2365 2312 2368 2394 2296 2345 2433 2379 2429 2330 2427 2352 2422 2362 2335 2392 2366 2463 2514 2468 2347 2424 2475 2513 2387 2567 2490 2609 2578 2513 2628 2498 2514 2508 2648 2605 2628 2609 2664 2610 2671 2654 2658 2670 2606 2540 2524 2474 2532 2402 2436 2448 2474 2401 2417 2435 2433 2415 2363 2373 2400 2318 2309 2335 2334 2293 2330 2361 2255 2316 2296 2322 2357 2303 2381 2294 2333 2306 2321 2371 2347 2295 2364 2368 2311 2290 2309 2358 2355 2367 2354 2347 2219 2325 2310 2341 2348 2341 2259 2350 2410 2358 2278 2255 2271 2362 2243 2263 2203 2271 2336 2261 2273 2383 2255 2250 2260 2363 2331 2250 2267 2307 2360 2227 2261 2296 2341 2252 2334 2294 2246 2251 2277 2309 2388 2337 2314 2393 2475 2431 2473 2463 2564 2451 2376 2374 2363 2394 2419 2509 2476 2552 2585 2580 2682 2554 2578 2445 2463 2397 2392 2289 2395 2417 2386 2460 2402 2394 2423 2357 2327 2376 2277 2336 2257 2264 2286 2344 2329 2326 2259 2302 2232 2335 2268 2303 2305 2287 2327 2426 2277 2307 2295 2422 2210 2208 2269 2288 2322 2374 2270 2283 2237 2237 2383 2353 2236 2237 2321 2221 2323 2385 2243 2317 2401 2332 2231 2437 2285 2340 2211 2203 2235 2297 2353 2381 2315 2298 2366 2431 2244 2392 2397 2322 2322 2384 2423 2347 2367 2426 2485 2494 2527 2701 2820 3040 3306 3440 3548 3580 3203 3070 2795 2703 2649 2519 2623 2520 2633 2719 2787 2915 2850 2925 2997 2783 2640 2638 2616 2475 2460 2411 2488 2633 2497 2669 2700 2772 2828 2749 2667 2770 2556 2608 2536 2582 2599 2669 2694 2731 2725 2727 2722 2774 2649 2655 2676 2620 2543 2448 2604 2477 2612 2502 2624 2597 2671 2772 2755 2836 3055 3343 3785 4317 5017 5403 5267 4831 4222 3662 3103 2939 2783 2803 2711 2855 3068 3284 3467 3866 3899 3815 3675 3377 3101 2853 2800 2703 2863 2934 3078 3309 3748 3889 3960 3600 3327 3017 2999 2725 2789 2678 2615 2682 2699 2806 2917 3072 3169 3280 3149 3090 2756 2750 2686 2766 2841 2846 3000 3102 3242 3202 3546 3609 3667 3677 3598 3669 3724 3748 3699 3556 3472 3324 3261 3384 3545 3974 4244 4639 5287 5854 6406 7088 7255 7110 6617 5753 5168 4619 4309 3987 4130 4181 4335 4472 4594 4687 4801 4914 5089 4917 4589 4345 4339 4373 4438 4567 4769 4788 4514 4280 3952 3759 3546 3444 3503 3707 3723 4048 4306 4821 5466 5876 6200 5707 5532 5000 4390 3876 3670 3288 3376 3277 3298 3413 3570 3720 3958 3999 4113 3966 3749 3608 3416 3257 3025 2908 2861 2709 2810 2667 2697 2778 2832 2876 2899 2948 2898 2871 2822 2713 2789 2818 2718 2738 2719 2845 2824 2966 3094 3288 3289 3450 3644 3810 4064 4148 4085 4252 4168 4311 4254 4192 4166 4356 4393 4741 5303 5723 5876 5773 5421 4659 4478 3995 3821 3693 3818 3567 3512 3517 3369 3677 3835 3806 3955 3799 3447 3208 3057 3052 2912 2997 3158 3162 3436 3626 3946 4126 4027 3759 3591 3256 3071 2954 2846 2697 2731 2742 2760 2999 3017 3184 3254 3417 3444 3220 3081 2955 2946 2881 2930 2940 3133 3115 3178 3209 3360 3281 3385 3461 3487 3374 3404 3305 3132 2927 2930 2831 2699 2917 2870 2853 2790 2855 2974 2943 2824 2866 2902 2823 2765 2591 2482 2569 2498 2461 2398 2462 2392 2453 2531 2439 2400 2519 2457 2398 2554 2527 2483 2544 2515 2583 2577 2552 2644 2631 2839 2923 3107 3251 3570 3818 4096 4244 4144 4072 3761 3496 3222 3010 3018 2867 2815 2980 2935 2943 3058 3070 3159 3257 3254 3224 3037 3011 2993 2777 2678 2618 2697 2736 2679 2734 2763 2948 3222 3383 3633 3836 4074 4173 4211 4176 3913 3594 3375 2952 2912 2916 3019 3125 3146 3338 3457 3628 3628 3617 3589 3443 3338 3327 3238 3067 3027 3185 3149 3245 3488 3726 3882 4186 4289 4471 4382 4196 4010 3628 3483 3193 3176 3070 3044 3099 3041 3143 3174 3288 3243 3326 3361 3367 3193 3094 2879 2901 2819 2715 2764 2639 2657 2646 2755 2708 2836 2929 3052 3358 3733 4028 4603 4905 5170 5199 4766 4804 4765 5026 5131 5407 5140 5043 4902 4505 4113 3842 3867 3880 4020 3932 3818 3705 3603 3567 3765 3757 3850 3669 3658 3212 2996 2861 2647 2634 2531 2466 2479 2383 2364 2328 2421 2316 2386 2388 2387 2344 2253 2360 2385 2323 2211 2356 2355 2297 2355 2358 2293 2322 2300 2273 2289 2321 2335 2339 2396 2316 2191 2280 2334 2281 2336 2324 2298 2345 2347 2349 2328 2278 2236 2227 2331 2343 2334 2243 2340 2292 2272 2388 2305 2223 2340 2271 2254 2283 2378 2299 2288 2324 2279 2344 2287 2300 2384 2295 2392 2252 2379 2401 2262 2431 2323 2384 2353 2444 2342 2419 2405 2428 2397 2367 2413 2359 2432 2396 2479 2476 2364 2359 2393 2399 2526 2391 2374 2399 2433 2476 2512 2421 2443 2440 2493 2577 2502 2634 2524 2633 2683 2694 2657 2688 2741 2780 2834 2817 2834 2716 2675 2576 2687 2719 2703 2904 2847 3067 3115 3190 3447 3669 3821 4103 4419 4720 4613 4835 4767 4447 4107 3859 3530 3311 3171 3189 3026 3090 3137 3145 3263 3353 3482 3600 3627 3577 3412 3359 3094 2883 2820 2687 2627 2596 2580 2552 2563 2559 2530 2554 2528 2556 2439 2445 2454 2484 2462 2402 2518 2489 2507 2626 2532 2617 2599 2659 2726 2748 2979 2924 3222 3216 3613 3920 4055 4221 4361 4524 4483 4442 4361 4316 4026 3762 3456 3190 3110 3067 3124 3101 3191 3288 3396 3520 3510 3445 3515 3578 3420 3397 3296 3271 3159 3202 3149 3254 3202 2988 2799 2765 2634 2633 2437 2565 2496 2591 2632 2468 2647 2635 2623 2669 2782 2715 2619 2709 2678 2625 2570 2651 2693 2719 2892 2932 2924 3026 2957 2822 2671 2658 2604 2503 2518 2572 2519 2448 2499 2539 2597 2647 2596 2627 2717 2678 2623 2574 2591 2607 2541 2407 2586 2503 2633 2704 2952 2909 3070 3227 3327 3377 3420 3418 3589 3597 3606 3625 3508 3324 3260 3120 3039 2980 2861 2902 2888 2983 3086 3181 3085 3125 3198 3382 3276 3369 3507 3546 3532 3503 3378 3272 3174 3043 2983 3105 2941 3097 3090 3153 3331 3396 3498 3743 3866 3949 4304 4175 3955 3747 3795 3719 3702 3658 3841 3821 3786 3954 3983 3991 4019 4024 4045 3867 3827 3771 3627 3495 3497 3247 3208 3252 3315 3281 3406 3449 3314 3470 3444 3573 3707 3801 3998 4106 4299 4415 4307 4157 3893 3680 3445 3164 3170 2923 3036 2964 2935 2924 2986 3069 3172 3250 3288 3359 3317 3481 3216 3217 3074 3091 3013 2998 2944 3047 2888 2869 2836 2872 2751 2673 2664 2779 2660 2694 2731 2627 2769 2740 2756 2872 2883 2875 3014 3139 3107 3269 3417 3621 3855 4045 4620 5190 5763 6219 6330 6333 6258 5693 5606 5550 5259 5249 5074 5169 5166 4974 4982 4833 4691 4860 4850 5038 5247 5173 5002 5028 5042 5031 5179 5363 5385 5527 5425 5345 5278 4889 4923 4714 4567 4438 4137 3904 3679 3569 3453 3344 3453 3387 3482 3437 3503 3501 3515 3415 3378 3346 3428 3386 3275 3286 3158 3269 3195 3216 3287 3343 3443 3526 3681 3636 3637 3634 3717 3376 3484 3420 3267 3307 3427 3440 3547 3470 3415 3406 3514 3403 3307 3264 3184 3156 2965 2908 3011 3020 2820 2761 2835 2797 2844 2804 2885 2779 2779 2631 2679 2565 2618 2533 2467 2416 2398 2379 2457 2464 2485 2392 2426 2426 2422 2439 2359 2300 2438 2455 2449 2390 2433 2391 2499 2494 2437 2501 2542 2599 2638 2487 2799 2806 2958 3001 3107 3092 3159 3304 3282 3272 3335 3488 3446 3549 3546 3562 3695 3718 3810 3865 4016 3910 3995 3947 3712 3537 3373 3346 3153 3174 3165 3122 3308 3209 3396 3479 3716 3991 4280 4597 4431 4175 3852 3550 3354 3030 2861 2729 2675 2661 2594 2636 2652 2658 2656 2788 2853 3012 3103 3192 3048 2882 2734 2608 2527 2561 2544 2592 2497 2501 2472 2586 2532 2492 2410 2442 2321 2486 2410 2509 2401 2388 2408 2351 2389 2413 2280 2381 2387 2450 2504 2431 2449 2393 2439 2313 2382 2349 2433 2337 2420 2381 2424 2305 2500 2425 2407 2438 2535 2604 2645 2540 2539 2591 2646 2539 2588 2565 2582 2617 2673 2536 2604 2645 2648 2631 2530 2624 2722 2735 2690 2746 2916 2879 2964 3202 3336 3381 3438 3258 3183 3014 2905 2803 2686 2555 2483 2497 2486 2466 2483 2617 2571 2626 2684 2684 2760 2807 2831 2692 2612 2521 2457 2443 2404 2375 2326 2411 2346 2367 2345 2368 2277 2358 2394 2377 2340 2368 2383 2438 2344 2399 2487 2472 2379 2507 2404 2412 2473 2397 2390 2435 2311 2360 2309 2363 2378 2426 2311 2388 2302 2396 2335 2411 2330 2372 2329 2436 2546 2358 2346 2312 2381 2463 2300 2483 2443 2427 2237 2418 2314 2374 2339 2305 2302 2339 2442 2308 2373 2459 2310 2325 2329 2406 2343 2419 2385 2334 2464 2372 2274 2385 2377 2440 2493 2449 2437 2444 2510 2542 2519 2658 2790 2773 2713 2722 2748 2856 2762 2916 2957 2926 2982 2983 2910 2856 2778 2670 2611 2683 2808 2943 3110 3075 3247 3562 3651 3747 3893 3922 3931 4006 3868 3740 3757 3637 3524 3533 3387 3328 3227 3300 3173 3228 3197 3328 3359 3506 3625 3562 3580 3468 3491 3428 3340 3253 3290 3102 2933 2899 2828 2833 2782 2663 2676 2643 2636 2665 2689 2624 2699 2496 2660 2517 2570 2573 2564 2520 2437 2405 2434 2367 2420 2272 2396 2407 2424 2459 2343 2360 2437 2470 2488 2428 2417 2518 2646 2655 2688 2775 2886 2850 3032 3112 2947 2918 2915 2710 2733 2619 2606 2591 2520 2521 2511 2601 2474 2585 2594 2645 2667 2751 2837 2786 2817 2746 2768 2762 2771 2780 2787 2922 3025 3183 3234 3283 3379 3421 3169 3089 3119 2889 2935 3034 2982 2949 3005 3041 3008 2911 2918 2918 2905 2851 2951 2823 2816 2788 2948 2723 2729 2756 2666 2808 2645 2758 2627 2722 2728 2693 2732 2600 2588 2592 2568 2579 2534 2600 2717 2700 2673 2753 2885 2900 3023 3103 3231 3254 3308 3406 3337 3314 3138 3057 3009 3073 3022 3013 3108 3150 3337 3501 3621 3696 3799 3762 3669 3608 3423 3431 3327 3153 3217 3042 3015 3037 3032 2998 3025 3129 3101 3142 3145 3223 3193 3214 3213 3139 2975 2994 2854 2943 2837 2832 2860 2886 2823 2763 2790 2828 2717 2800 2683 2688 2718 2691 2833 2802 2884 2931 3150 3277 3484 3634 3594 3755 3869 3909 3745 3660 3511 3196 2980 2855 2777 2623 2590 2573 2582 2646 2628 2660 2665 2783 2861 3000 3097 3060 3116 3055 3042 2930 2986 2770 2863 2796 2791 2789 2909 3026 3041 3199 3329 3281 3267 3226 3028 2841 2795 2718 2618 2611 2661 2557 2534 2615 2547 2535 2549 2635 2653 2806 2794 2724 2870 2808 2812 2748 2668 2683 2605 2570 2515 2546 2497 2576 2414 2528 2467 2423 2572 2622 2595 2587 2618 2811 2865 3189 3392 3421 3532 3511 3260 3221 2929 2907 2823 2823 2774 2746 2819 2979 2814 2847 3039 2901 2924 2901 3046 3062 3066 3127 3144 2978 2956 2908 2729 2592 2641 2707 2677 2692 2713 2672 2795 2749 2896 2866 2940 3032 3239 3183 3127 3068 3085 3117 3055 3062 3001 2831 2940 2864 2997 2929 2886 2968 2974 3084 3009 3004 3015 3049 3037 3142 3117 3363 3205 3283 3129 3087 3187 3181 3055 3012 2960 2991 2938 2868 2953 2863 2846 2789 2726 2733 2658 2745 2635 2794 2702 2676 2807 3015 2901 2769 2919 2955 3075 3236 3310 3344 3311 3267 3113 3005 2969 2822 2771 2744 2752 2809 2919 2984 3095 3097 3445 3529 3655 3831 3943 4119 4246 4415 4511 4259 4171 4100 3823 3629 3388 3254 3204 3048 3057 3065 3033 3043 3038 3100 3232 3213 3352 3456 3437 3533 3651 3583 3714 3835 3842 3935 3915 4080 4041 3647 3561 3461 3158 3040 2911 2823 2931 2746 2637 2725 2710 2670 2664 2670 2834 2796 3013 3103 3178 3233 3245 3352 3194 3158 3043 3094 3130 3051 3002 2736 2910 2809 2791 2695 2715 2579 2559 2669 2618 2605 2567 2628 2575 2631 2649 2587 2604 2598 2772 2645 2619 2542 2583 2619 2543 2585 2672 2541 2532 2664 2707 2782 2778 2749 2774 2811 2831 2731 2771 2736 2609 2677 2576 2604 2697 2775 2634 2728 2802 2759 2884 2819 2855 2877 3068 2981 3026 2976 3030 3222 3284 3438 3557 3695 3766 3762 3586 3488 3358 3289 3080 3007 2920 2845 2646 2752 2820 2755 2643 2744 2663 2689 2761 2748 2805 2965 2859 2971 3064 2826 2931 2902 2736 2709 2583 2611 2521 2440 2508 2464 2402 2366 2309 2371 2332 2269 2460 2369 2386 2263 2308 2271 2358 2342 2316 2334 2291 2371 2274 2337 2253 2348 2346 2263 2359 2285 2304 2232 2374 2201 2274 2252 2285 2338 2225 2286 2281 2307 2333 2286 2310 2365 2359 2279 2269 2311 2281 2342 2357 2473 2316 2497 2461 2475 2385 2472 2638 2728 2749 2730 2922 3121 3221 3235 3266 3193 3144 3008 2946 2970 2888 2822 2909 2819 2738 2729 2784 2825 2830 2747 2759 2769 2769 2753 2986 2856 2933 2973 3006 2957 2864 2821 2726 2716 2768 2732 2819 2846 2895 2895 3013 3020 3094 3220 3187 3259 3199 3201 3076 3041 2901 2819 2878 2895 2893 2893 3033 3157 3078 3140 3072 2869 2915 2824 2903 2893 3012 3000 3037 3002 2790 2723 2723 2651 2623 2643 2613 2682 2418 2582 2651 2714 2634 2723 2581 2533 2537 2530 2465 2504 2495 2387 2523 2351 2274 2370 2343 2447 2299 2320 2314 2346 2285 2220 2270 2344 2264 2326 2416 2256 2317 2316 2289 2291 2311 2298 2322 2232 2324 2305 2309 2248 2450 2261 2349 2245 2284 2312 2374 2296 2264 2239 2274 2248 2234 2284 2296 2278 2242 2297 2194 2286 2316 2306 2188 2197 2293 2275 2347 2339 2333 2276 2299 2374 2328 2319 2352 2272 2238 2320 2422 2311 2394 2281 2319 2314 2402 2458 2370 2335 2471 2436 2456 2454 2575 2393 2550 2406 2474 2431 2466 2400 2365 2349 2420 2410 2358 2413 2470 2545 2532 2487 2602 2626 2708 2684 2732 2904 2838 2791 2878 2903 2934 2872 2989 2925 2897 2978 2865 2858 2995 2896 2940 3045 3301 3414 3533 3542 3579 3510 3448 3346 3140 2961 3005 3026 2907 2857 2872 2940 2923 2905 2952 2962 3027 3029 3193 3291 3375 3497 3578 3578 3667 3532 3517 3559 3353 3249 3208 3232 3309 3160 3183 3141 3082 3142 2988 3006 3055 2844 2897 3024 2901 3006 3053 3011 3048 3127 3118 3221 3259 3201 3343 3256 3261 3272 3188 3067 3114 2897 2887 2775 2702 2675 2648 2552 2478 2450 2647 2579 2443 2584 2581 2553 2546 2610 2624 2597 2596 2654 2750 2561 2491 2446 2470 2375 2468 2444 2372 2329 2348 2302 2414 2460 2436 2276 2380 2456 2317 2381 2413 2380 2428 2451 2460 2348 2476 2441 2481 2448 2636 2655 2681 2681 2656 2967 2982 3073 3303 3365 3374 3495 3480 3437 3352 3524 3292 3318 3372 3417 3382 3399 3432 3371 3459 3615 3784 3934 4168 4196 4407 4577 4622 4720 4734 4941 4730 4802 4527 4536 4249 4146 3888 3754 3623 3490 3431 3324 3269 3290 3212 3111 3190 3414 3450 3469 3433 3533 3396 3660 3484 3457 3540 3467 3452 3369 3459 3353 3352 3187 3232 3288 3281 3347 3367 3278 3364 3374 3458 3431 3447 3376 3586 3613 3670 3495 3662 3575 3593 3519 3505 3309 3219 3228 3145 3055</intensities>
			</dataPoints>
			<nonAmbientPoints type="Temperature" unit="K">
[...]
			</nonAmbientPoints>
		</scan>
	</xrdMeasurement>
</xrdMeasurements>