File: powder_X-ray_diffraction/variable-temperature_experiments/NaNbO2F2/raw_data/100°C.xrdml
<?xml version="1.0" encoding="UTF-8"?>
<xrdMeasurements xmlns="http://www.xrdml.com/XRDMeasurement/1.7" xmlns:xsi="http://www.w3.org/2001/XMLSchema-instance" xsi:schemaLocation="http://www.xrdml.com/XRDMeasurement/1.7 http://www.xrdml.com/XRDMeasurement/1.7/XRDMeasurement.xsd" status="Completed">
	<comment>
		<entry>Configuration=XRK900, Owner=User-1, Creation date=12/01/2015 16:52:44</entry>
		<entry>Goniometer=Theta/Theta; Minimum step size 2Theta:0.0001; Minimum step size Omega:0.0001</entry>
		<entry>Sample stage=AP XRK-900 with z-axis; Minimum step size Z:0.001</entry>
		<entry>Diffractometer system=EMPYREAN</entry>
		<entry>Measurement program=C:\PANalytical\Data Collector\Programs\Gwen\NaNbO2F2-Lent.xrdmp, Identifier={26D14ECE-D3C8-438C-91CA-8651EAF68C7D}</entry>
		<entry>Batch program=C:\PANalytical\Data Collector\Programs\Gwen\Thermodiff-Ouail.xrdmp, Identifier={9701CF17-19F5-4DD4-A8E1-7279D1FD2F5E}</entry>
	</comment>
	<sample type="To be analyzed">
		<id></id>
		<name></name>
		<preparedBy></preparedBy>
	</sample>
	<xrdMeasurement measurementType="Scan" status="Completed" sampleMode="Reflection">
		<comment>
			<entry>PHD Lower Level = 4.02 (keV), PHD Upper Level = 12.07 (keV)</entry>
		</comment>
		<usedWavelength intended="K-Alpha 1">
			<kAlpha1 unit="Angstrom">1.5405980</kAlpha1>
			<kAlpha2 unit="Angstrom">1.5444260</kAlpha2>
			<kBeta unit="Angstrom">1.3922500</kBeta>
			<ratioKAlpha2KAlpha1>0.5000</ratioKAlpha2KAlpha1>
		</usedWavelength>
		<incidentBeamPath>
			<radius unit="mm">240.00</radius>
			<xRayTube id="1010048" name="Empyrean Cu LFF HR (9430 033 7310x) DK420743">
				<tension unit="kV">45.0</tension>
				<current unit="mA">30.0</current>
				<anodeMaterial>Cu</anodeMaterial>
				<focus type="Line">
					<length unit="mm">12.0</length>
					<width unit="mm">0.4</width>
					<takeOffAngle unit="deg">6.0</takeOffAngle>
				</focus>
			</xRayTube>
			<sollerSlit id="21010001" name="Soller slits 0.02 rad.">
				<opening unit="rad">0.0200</opening>
			</sollerSlit>
			<mask id="22030010" name="Fixed mask 20 mm">
				<width unit="mm">20.00</width>
			</mask>
			<antiScatterSlit id="22010003" name="Fixed slit 1Â°" xsi:type="fixedAntiScatterSlitType">
				<height unit="mm">1.52</height>
			</antiScatterSlit>
			<divergenceSlit id="22010012" name="Programmable divergence slit" xsi:type="fixedDivergenceSlitType">
				<distanceToSample unit="mm">140.00</distanceToSample>
				<angle unit="deg">0.5</angle>
			</divergenceSlit>
		</incidentBeamPath>
		<diffractedBeamPath>
			<radius unit="mm">240.00</radius>
			<antiScatterSlit id="22090010" name="AS slit 8.0 mm (PIXcel)" xsi:type="fixedAntiScatterSlitType">
				<height unit="mm">8.00</height>
			</antiScatterSlit>
			<sollerSlit id="21010001" name="Soller slits 0.02 rad.">
				<opening unit="rad">0.0200</opening>
			</sollerSlit>
			<filter id="20030001" name="Large beta-filter Nickel">
				<material>Ni</material>
				<thickness unit="mm">0.020</thickness>
			</filter>
			<detector id="7010019" name="PIXcel1D-Medipix3 detector" xsi:type="rtmsDetectorType">
				<phd unit="%">
					<lowerLevel>25.0</lowerLevel>
					<upperLevel>75.0</upperLevel>
				</phd>
				<mode>Scanning</mode>
				<activeLength unit="deg">3.3482</activeLength>
			</detector>
		</diffractedBeamPath>
		<scan appendNumber="0" mode="Continuous" scanAxis="Gonio" status="Completed">
			<header>
				<startTimeStamp>2022-05-14T06:22:22+02:00</startTimeStamp>
				<endTimeStamp>2022-05-14T09:22:49+02:00</endTimeStamp>
				<author>
					<name>User</name>
				</author>
				<source>
					<applicationSoftware version="5.5a">Data Collector</applicationSoftware>
					<instrumentControlSoftware version="8.1b 20190506">EMPYREAN</instrumentControlSoftware>
					<instrumentID>0000000011159748</instrumentID>
				</source>
			</header>
			<dataPoints>
				<positions axis="2Theta" unit="deg">
					<startPosition>9.99846514</startPosition>
					<endPosition>99.99342261</endPosition>
				</positions>
				<positions axis="Omega" unit="deg">
					<startPosition>4.99923257</startPosition>
					<endPosition>49.99671130</endPosition>
				</positions>
				<positions axis="Z" unit="mm">
					<commonPosition>8.912</commonPosition>
				</positions>
				<commonCountingTime unit="seconds">386.070</commonCountingTime>
				<intensities unit="counts">7981 7952 7879 8049 7877 7906 7897 8172 8029 7971 8086 8238 8206 8281 8474 8331 8067 8175 8130 8101 7954 8187 8132 7881 8152 8205 8007 8032 7871 7982 8016 8196 8143 7982 8147 7844 7989 7934 7944 7983 8057 8103 8033 8087 8060 8104 7965 7961 7975 7980 7988 8043 8080 7983 7813 8095 8053 8044 8139 8046 8002 7863 7918 8034 8193 8075 8285 8528 8321 8286 8343 8395 8355 8453 8603 8493 8660 8817 8765 8870 9014 9154 9162 9460 9722 10118 10941 11443 12794 14267 16837 20968 27084 37506 51597 67155 78057 78598 70165 54886 39965 27481 18769 13936 11354 10046 9213 9112 8790 8797 8772 8493 8361 8374 8324 8436 8219 8160 7989 8111 8052 8152 7961 8214 7847 8090 7911 8086 8199 8135 8056 8073 8090 8248 8127 8248 8267 8231 8006 8083 8334 8310 8485 8245 8125 8266 8283 8333 8433 8170 8179 8197 8408 8419 8439 8336 8316 8139 8472 8329 8365 8354 8488 8462 8266 8284 8384 8261 8297 8502 8512 8342 8370 8451 8453 8364 8432 8432 8461 8453 8484 8436 8390 8368 8513 8265 8418 8287 8496 8467 8372 8408 8508 8301 8463 8359 8440 8285 8416 8305 8355 8129 8395 8401 8353 8234 8203 8359 8222 8066 8197 8353 8462 8289 8255 8338 8340 8213 8125 8316 8165 8406 8473 8383 8164 8275 8288 8177 8127 8082 8378 8195 8351 8436 8174 8088 8193 8139 8061 8161 8203 8122 8285 8198 8320 8286 8220 8210 8177 8341 8233 8192 8202 8345 8217 8277 8116 8057 8069 8064 7975 8117 8220 7856 8007 7941 8154 8214 8068 7968 8139 8226 8103 8047 8161 8213 8005 8133 8059 8209 8226 8209 8177 8178 8259 8328 8251 8139 8204 8145 8111 8188 8136 8293 7990 7967 8120 7953 8108 8247 7972 8025 8013 8024 8076 8088 8159 8108 8085 8091 8101 7933 8234 8105 8206 8103 8187 8078 8051 7992 8308 8282 8059 8097 8170 8159 8196 7972 8006 8140 7935 7985 8260 8309 8095 7959 8138 8286 8149 8518 8458 8888 9140 9379 9605 9730 9536 9613 9229 9198 8854 8622 8383 8270 8081 8074 8098 8010 8311 8106 7987 8048 8100 7910 7950 7926 7785 7926 8019 8055 8015 7993 8106 8168 7854 7810 7806 8081 7858 7797 7986 8052 8025 8067 7901 8082 7767 7977 7928 7805 7585 7755 7878 7822 7953 7939 7828 8065 7899 8063 7897 7915 8053 7861 7883 7869 7686 7831 8060 7879 8001 8015 7869 7961 8010 7796 7908 7925 7851 7874 7889 7789 7728 7855 7600 7814 7734 7883 7903 7919 7917 7794 7849 7869 7863 7769 7737 7911 7849 7925 7873 7846 7853 8033 7803 7900 7635 7726 7821 7798 7624 7763 7813 7688 7700 7815 8007 7929 7848 7761 8064 8032 7917 7779 7773 8053 7910 7826 7790 7915 7861 7862 7619 7742 7871 7893 7743 7560 7798 7822 7698 7702 7680 7723 7750 7823 7888 7905 7667 7679 7883 7753 7766 7692 7909 7917 7898 7859 7804 7846 7765 7552 7690 7617 7776 7861 7668 7798 7836 7754 7767 7773 7836 7703 8067 7963 8007 8034 8417 8177 8123 8060 7955 7847 7895 7837 7733 7878 7703 7640 7731 7621 7859 7772 7544 7580 7438 7643 7527 7558 7711 7760 7849 7592 7646 7648 7668 7624 7716 7539 7742 7696 7793 7662 7422 7489 7693 7525 7599 7453 7475 7678 7631 7643 7557 7413 7462 7443 7717 7526 7686 7679 7417 7450 7631 7672 7668 7607 7607 7644 7558 7517 7506 7584 7406 7599 7515 7525 7569 7530 7506 7555 7580 7568 7617 7429 7373 7532 7575 7458 7530 7477 7621 7877 7600 7687 7710 7809 7836 7593 7545 7456 7422 7513 7457 7457 7310 7359 7427 7468 7380 7326 7420 7385 7411 7493 7386 7459 7368 7484 7597 7433 7469 7335 7273 7269 7421 7353 7511 7289 7372 7469 7398 7485 7301 7212 7298 7442 7198 7483 7445 7449 7424 7410 7249 7392 7305 7275 7311 7279 7428 7308 7407 7534 7511 7385 7295 7539 7228 7397 7527 7301 7309 7230 7449 7323 7298 7330 7197 7305 7392 7327 7425 7341 7249 7288 7213 7485 7347 7248 7306 7348 7278 7256 7372 7280 7433 7541 7527 7359 7435 7592 7927 7603 7859 7745 7723 7660 7711 7679 7845 7868 7781 7617 7723 7889 7679 7522 7534 7831 7765 7718 7857 7792 7571 7665 7810 7705 7844 8044 7955 8052 8086 8128 8275 8327 8416 8460 8793 8910 9050 9274 9717 10348 11338 12665 14955 18319 23710 32553 45659 60912 76834 90441 92531 84792 74732 64376 51212 38628 27591 20417 15084 12461 10889 9888 9504 9139 8884 8920 8622 8396 8199 8133 8196 8054 8017 8137 8000 8014 8007 7923 7989 7771 7768 7628 7627 7653 7829 7705 7760 7796 7677 7567 7574 7643 7633 7665 7659 7601 7596 7596 7626 7488 7483 7508 7408 7460 7611 7614 7489 7493 7588 7421 7605 7776 7512 7429 7432 7655 7599 7583 7597 7420 7480 7643 7607 7585 7549 7598 7649 7564 7640 7439 7559 7398 7442 7512 7351 7527 7582 7550 7430 7472 7295 7492 7644 7550 7426 7459 7414 7462 7477 7538 7426 7409 7390 7594 7512 7509 7363 7701 7751 7563 7532 7556 7519 7466 7550 7543 7629 7613 7667 7572 7500 7472 7673 7528 7549 7346 7410 7470 7454 7430 7685 7552 7679 7542 7522 7722 7486 7511 7451 7437 7392 7614 7551 7447 7603 7452 7726 7619 7592 7481 7442 7444 7502 7610 7538 7698 7686 7843 7691 7737 7609 7716 7488 7585 7606 7586 7491 7385 7339 7385 7358 7533 7429 7401 7425 7557 7511 7545 7638 7511 7494 7446 7490 7519 7434 7677 7739 7485 7516 7645 7489 7556 7635 7761 7866 7879 7871 7953 8082 8390 8457 9043 9248 10093 11548 14460 18622 25212 31018 33875 32936 30177 27046 24764 21358 17913 14312 11601 9773 8832 8198 8316 8033 7874 7955 7811 7760 7679 7554 7732 7527 7449 7593 7503 7554 7580 7551 7522 7560 7572 7479 7588 7477 7585 7525 7644 7606 7412 7670 7477 7398 7436 7579 7596 7434 7438 7627 7638 7561 7560 7592 7441 7773 7563 7543 7634 7538 7437 7765 7763 7614 7749 7443 7724 7641 7583 7393 7534 7684 7770 7622 7644 7678 7831 7858 7698 7867 7934 8059 8204 8328 8702 8883 9707 11629 14272 18068 23892 28755 29961 28019 25553 23737 21908 19113 16338 13692 11434 9718 9314 8748 8473 8618 8682 8940 8901 9132 9425 10230 11402 14184 18754 25438 32649 37332 35873 31186 28561 27203 24484 20662 16125 13236 10842 9366 8743 8515 8288 8219 8037 7997 8145 8059 8184 8033 8064 8043 8056 7789 7695 7668 7786 7703 7637 7576 7503 7537 7637 7484 7474 7378 7463 7546 7605 7568 7531 7430 7537 7562 7503 7550 7589 7417 7418 7435 7434 7591 7307 7469 7525 7285 7488 7486 7329 7325 7349 7245 7292 7430 7326 7475 7399 7399 7550 7344 7316 7335 7463 7499 7609 7425 7535 7418 7539 7360 7248 7577 7355 7527 7661 7583 7681 7748 7487 7465 7574 7429 7168 7375 7118 7367 7372 7283 7259 7455 7416 7378 7411 7471 7447 7438 7311 7150 7262 7383 7241 7476 7260 7183 7438 7237 7378 7237 7363 7445 7418 7312 7406 7360 7317 7442 7488 7202 7398 7337 7423 7266 7209 7336 7424 7361 7291 7465 7339 7310 7403 7818 7441 7451 7439 7370 7355 7530 7223 7385 7381 7428 7515 7360 7330 7430 7204 7298 7457 7296 7137 7288 7299 7296 7260 7301 7171 7355 7344 7436 7207 7359 7306 7248 7088 7220 7290 7180 7208 7120 7075 7185 7165 7153 7143 7296 7148 7204 7055 6996 7162 7054 7020 7006 7173 7071 7186 7182 7274 7055 7167 7136 7271 7295 7089 7302 7197 7082 7019 7310 7090 7200 7257 7007 7237 7173 7167 7333 7197 7317 7380 7366 7514 7570 7388 7488 7461 7572 7562 7378 7491 7437 7527 7318 7547 7500 7245 7291 7271 7392 7458 7577 7544 7501 7405 7348 7303 7378 7393 7456 7312 7447 7409 7537 7459 7620 7488 7493 7571 7499 7612 7609 7300 7273 7555 7459 7416 7527 7531 7523 7825 7943 7933 8112 8143 8066 8315 8606 8940 8796 9020 9144 9357 9756 10218 10819 11514 12328 13890 16258 20345 26277 36186 50203 67128 81905 88203 84242 76234 67249 61892 56877 50529 41817 32264 24329 18106 14664 12450 11344 10420 9741 9541 9159 9010 8833 8454 8269 8174 8102 7863 7834 8049 7734 7815 7766 7912 7966 8159 8187 8535 8681 8796 8761 8818 8417 8624 8430 8486 8093 7949 7918 7783 7852 7728 7685 7549 7579 7642 7547 7617 7543 7565 7656 7921 7784 7921 8028 8082 8220 8358 8628 8863 9432 10344 12271 15665 21866 30544 38903 40885 36023 30081 26654 26176 25995 24409 20137 15962 12678 10821 9454 9139 8762 8889 8999 9064 9776 10421 11520 12723 13781 14266 14723 15376 16004 16806 16216 14672 13214 12245 11471 11092 10478 9504 8730 8226 7831 7754 7850 7673 7374 7385 7460 7375 7304 7393 7253 7200 7183 7281 7062 7069 7243 7350 7507 7347 7123 7241 7271 7240 7315 7211 7230 7276 6994 7150 7076 7207 7058 7036 7065 7142 7153 6977 7048 7064 7131 7308 7242 7035 7049 7069 7059 6933 7091 6844 6931 7069 7069 7009 7122 6979 7095 7237 7244 6908 6940 6947 6968 7136 7105 7075 6953 7032 7089 7156 7187 7015 7016 6989 7025 7077 6987 7074 6998 6987 6820 7148 7136 6906 7050 6968 6880 6945 6919 7033 6802 6951 6920 7083 6919 7140 6834 6776 6968 6809 6872 6864 6740 6882 6891 7079 7002 7155 6708 6827 7019 6960 7059 7065 7181 6937 6940 7057 6888 6958 6850 6931 6970 7055 6848 6788 6896 6898 6923 6896 6970 6817 6967 7013 7025 6893 7009 6890 6928 7058 6986 6824 6794 6890 6935 6863 6734 6723 6883 6909 6871 6933 7001 7044 6952 6872 6877 6969 6766 6970 6954 6755 6980 6846 6745 6792 6752 6912 6889 6840 6900 6772 6779 6887 6915 6797 6889 6932 6846 6788 6678 6815 6829 6846 6887 6680 7031 6917 6762 6742 6713 6740 6815 6878 7020 6954 6900 6871 6870 6900 6977 6820 7005 6927 6794 6662 6770 6811 7130 6947 7009 7006 6964 6908 6842 6856 6929 6910 6956 7033 6932 6899 7012 6884 6993 7004 7127 6909 6868 7058 6957 7002 6957 6724 6849 6947 6935 6765 6738 6813 6954 6925 7002 6885 6944 7141 7141 6925 7162 7076 7288 7139 7187 7134 7457 7473 7345 7528 7623 7769 7878 8045 8814 9641 11606 14614 19057 23238 26647 26628 23947 20694 18535 17789 18174 17798 16274 13847 11553 9930 8911 8217 7717 7580 7368 7353 7223 6991 7086 7036 7001 6864 7062 7029 6879 6840 6922 6868 7028 6838 7024 6840 6899 6810 6968 6925 6778 6885 6785 6907 7067 7000 6941 7199 7062 7170 7285 7476 7428 7720 7971 8767 9698 10823 12874 14417 15197 14986 13813 12181 11263 11203 11375 11233 10669 9589 8861 8320 8045 8002 7730 8033 7928 7740 7551 7767 7489 7432 7434 7313 7369 7318 7197 7184 7238 7360 7706 8076 9095 10536 12614 13831 13581 12924 11484 10457 10188 10531 10406 10082 9406 8625 7948 7509 7016 6993 6849 6937 6797 6813 6797 6748 6799 6637 6627 6697 6817 6787 6929 6907 6893 6568 6714 6773 6712 6697 6891 6694 6841 6891 6807 6780 6756 6921 6863 6756 6720 6918 6875 7116 7167 7179 7526 7905 8560 9715 10576 11384 11651 11166 10628 9854 9514 9636 9504 9411 9104 8349 8038 7681 7347 7571 7734 7577 7716 7534 7252 7217 7270 7361 7036 7089 6921 6813 6668 6745 6582 6844 6682 6545 6713 6835 6602 6748 6806 6683 6680 6556 6550 6504 6637 6615 6577 6676 6735 6579 6453 6745 6592 6744 6519 6708 6642 6396 6615 6645 6537 6707 6629 6491 6639 6732 6677 6753 6579 6537 6481 6749 6567 6596 6563 6646 6509 6438 6564 6553 6370 6387 6538 6519 6585 6651 6557 6569 6620 6633 6744 6639 6579 6511 6696 6713 6657 6659 6809 6689 6743 6668 6711 6507 6702 6882 6752 6598 6772 6646 6791 6854 7365 7874 8732 9618 10012 9847 9235 8466 8245 8277 8307 8428 8125 7760 7271 6981 7006 6684 6740 6684 6591 6568 6692 6958 6862 6714 6614 6496 6534 6623 6731 6633 6432 6519 6378 6486 6569 6621 6492 6546 6655 6581 6524 6603 6644 6564 6580 6718 6557 6426 6518 6539 6539 6659 6528 6599 6554 6549 6734 6484 6608 6592 6554 6524 6611 6655 6577 6584 6578 6757 6513 6757 6543 6721 6530 6589 6594 6311 6524 6580 6616 6711 6661 6719 6714 6777 6959 7081 7194 7340 7358 7653 7580 7462 7518 7492 7568 7632 8188 8451 9236 10034 11197 12156 12560 12675 11969 12140 12056 12163 11959 11607 10762 10058 9514 9091 8782 8387 7911 7665 7418 6929 6817 6886 6813 6793 6662 6649 6760 6721 6728 6574 6565 6698 6631 6636 6524 6404 6514 6318 6604 6507 6611 6637 6598 6421 6470 6581 6490 6481 6513 6316 6218 6484 6498 6366 6522 6582 6424 6600 6606 6569 6480 6395 6563 6534 6599 6494 6474 6529 6428 6416 6522 6370 6411 6529 6414 6431 6441 6588 6449 6292 6422 6505 6614 6530 6407 6442 6225 6318 6623 6582 6591 6446 6577 6570 6304 6240 6486 6429 6391 6529 6661 6552 6521 6504 6501 6678 6807 6730 6745 6826 7016 7482 7961 8747 9488 9755 9160 8403 8029 7716 7765 7757 8183 8094 7808 7208 6959 6816 6697 6490 6608 6566 6601 6484 6470 6451 6447 6614 6504 6429 6399 6378 6317 6334 6492 6578 6317 6219 6346 6381 6391 6509 6414 6421 6652 6441 6509 6419 6483 6418 6529 6438 6598 6512 6484 6556 6486 6481 6651 6498 6637 6516 6573 6512 6519 6529 6412 6429 6548 6352 6623 6735 6738 6752 7145 7251 7390 7456 7205 7014 7068 6961 7112 7220 7114 7313 7432 7704 8032 8727 9128 9399 9318 8983 8361 8255 7790 8024 8157 8025 7947 7609 7292 7215 6905 6705 6509 6605 6445 6464 6597 6446 6657 6568 6308 6359 6567 6455 6598 6456 6311 6508 6587 6627 6569 6305 6204 6449 6628 6327 6379 6460 6431 6362 6433 6497 6550 6434 6604 6930 6818 7157 7237 7714 7978 8265 8133 7950 7721 7595 8045 8475 8901 9679 10755 11385 11839 11858 11690 11516 11536 11219 11007 10578 10029 9767 9472 9099 8773 8617 8171 7810 7382 7168 6848 6802 6671 6758 6529 6621 6462 6633 6575 6447 6459 6323 6413 6432 6427 6227 6439 6438 6417 6546 6580 6390 6428 6487 6433 6324 6553 6522 6521 6447 6326 6547 6609 6380 6428 6439 6472 6520 6434 6369 6298 6412 6359 6544 6589 6574 6485 6362 6422 6469 6526 6383 6251 6181 6471 6527 6443 6575 6508 6489 6424 6344 6473 6379 6449 6305 6279 6284 6267 6450 6416 6536 6244 6182 6355 6364 6334 6280 6296 6359 6290 6225 6356 6273 6316 6400 6412 6438 6335 6462 6327 6355 6368 6271 6352 6429 6399 6382 6312 6314 6233 6289 6390 6298 6276 6318 6403 6525 6387 6188 6278 6159 6474 6418 6301 6463 6354 6402 6356 6271 6373 6268 6310 6526 6396 6243 6401 6231 6505 6424 6411 6309 6337 6494 6385 6419 6294 6303 6235 6208 6424 6450 6279 6365 6481 6336 6275 6324 6490 6495 6233 6283 6458 6427 6534 6601 6445 6408 6412 6622 6656 6821 7294 7412 7641 7861 8130 7911 7667 7400 7101 6938 7068 7117 7378 7091 7168 7046 6804 6637 6395 6501 6361 6479 6316 6350 6257 6492 6494 6366 6491 6274 6416 6427 6366 6322 6466 6336 6472 6347 6273 6529 6715 6604 6651 6624 6583 6569 6590 6464 6658 6611 6582 6420 6427 6394 6574 6548 6419 6432 6437 6474 6415 6263 6325 6502 6501 6484 6437 6635 6726 6657 6744 6661 6886 6907 7008 7067 7064 7122 7245 7295 7617 8186 8950 9729 10970 12400 13278 13163 12796 11620 10541 9706 9425 9725 9689 9879 9793 9561 8890 8180 7487 7385 7115 6889 6881 6698 6454 6461 6512 6484 6390 6344 6517 6530 6310 6477 6465 6371 6469 6331 6278 6473 6461 6380 6349 6414 6425 6174 6273 6466 6335 6235 6222 6331 6309 6246 6441 6436 6198 6383 6469 6323 6506 6349 6451 6327 6349 6437 6354 6318 6416 6372 6325 6458 6502 6383 6246 6371 6278 6283 6439 6352 6307 6258 6262 6514 6403 6269 6267 6346 6314 6342 6542 6468 6604 6454 6508 6586 6807 6649 6646 6693 6680 6615 7060 6953 7057 7087 7056 7288 7368 7638 8083 8518 10064 11751 14824 17591 19593 19920 19015 16849 14814 12927 12064 12541 12830 13625 13854 13258 12126 10821 9415 8710 7992 7546 7366 7157 7080 6563 6783 6806 6700 6698 6652 6752 6490 6317 6433 6433 6383 6460 6394 6292 6276 6360 6505 6446 6301 6430 6516 6587 6472 6417 6577 6171 6406 6223 6577 6382 6396 6292 6322 6182 6262 6322 6491 6323 6328 6379 6385 6237 6337 6379 6309 6238 6408 6379 6269 6565 6539 6270 6375 6388 6461 6459 6452 6416 6435 6413 6511 6446 6559 6630 6551 6599 6552 6540 6617 6790 6600 6694 6677 6686 6657 6952 7120 7074 7179 7717 8443 9291 10580 12180 13943 15240 14817 13080 11348 9610 9075 9152 9663 10162 10768 10840 10409 9399 8469 7740 7211 7182 7148 7015 6935 6838 6990 6884 7033 6624 6797 6787 6723 6928 7094 6645 6815 6969 6957 6976 6941 7064 7189 7125 7208 7287 7445 7674 7890 8261 8741 9602 10495 12215 13497 15623 17385 17979 17732 16550 15146 13575 12663 12558 12337 12433 12618 12545 12548 11630 10634 9556 8918 8195 7667 7545 7257 7140 6962 7116 6903 6949 6784 6793 7033 6947 6933 7063 7515 7875 7817 7903 7823 7961 7720 7867 7815 7815 7844 7817 7792 7872 7743 7412 7234 7036 7147 7272 6918 6955 6820 6980 6885 6775 6809 6736 6828 6800 6756 6938 6906 6864 6945 7167 7151 7160 7421 7585 7691 8045 8295 8744 9619 10815 12450 14287 15620 16263 15596 14506 13638 12670 12277 12597 13454 14374 14778 14315 13256 11898 10754 9789 9107 8901 8591 8828 8623 8308 7905 7557 7235 7048 7121 7053 6964 6800 6787 6899 6959 6843 6848 7010 6920 7017 7126 7098 7240 7263 7565 7858 8091 8700 9676 11046 12856 15484 17470 18986 19158 17770 15540 13580 11884 11379 11208 11868 12820 13156 13215 12431 11333 10121 9164 8434 7685 7479 7456 7135 6926 6860 6703 6790 6700 6767 6727 6860 6495 6591 6565 6526 6451 6607 6457 6480 6642 6476 6641 6574 6593 6539 6654 6852 6903 7206 7436 7853 8241 8815 9110 8793 8569 8174 7724 7459 7530 7568 7703 8197 8393 8444 8510 8807 9024 9094 9392 9316 9084 8787 8433 8008 7712 7580 7419 7625 7719 7791 7886 7687 7427 7155 7091 6761 6664 6685 6489 6642 6628 6525 6581 6475 6662 6409 6480 6425 6395 6465 6560 6272 6535 6333 6404 6470 6407 6492 6663 6419 6397 6474 6530 6470 6466 6577 6485 6578 6624 6426 6537 6595 6567 6697 6867 6944 7148 7098 7488 8238 9143 10619 12240 14175 14163 13274 11313 10320 9585 9250 9465 10216 11031 12075 11961 11923 10681 9449 8794 8562 8295 8421 8566 8824 8683 8417 7931 7497 7210 7059 6873 6915 7063 7021 7162 6957 6874 6802 6687 6694 6483 6378 6451 6217 6675 6504 6421 6535 6465 6373 6278 6540 6413 6414 6263 6303 6495 6553 6352 6360 6243 6431 6239 6467 6441 6483 6461 6538 6714 6808 7023 7187 7557 8120 7948 7775 7559 7149 6684 6867 6698 6777 6873 7048 7246 7095 7050 6879 6754 6199 6476 6354 6380 6450 6361 6404 6353 6455 6456 6477 6408 6403 6300 6344 6322 6336 6241 6204 6342 6174 6242 6376 6169 6260 6239 6276 6217 6220 6072 6430 6328 6252 6265 6303 6533 6364 6438 6364 6347 6352 6431 6465 6335 6378 6356 6399 6291 6323 6399 6402 6274 6235 6336 6229 6179 6112 6340 6187 6325 6198 6244 6205 6241 6272 6173 6181 6355 6090 6257 6090 6129 6179 6093 6283 6283 6201 6250 6298 6200 6326 6400 6232 6384 6391 6513 6472 6459 6424 6296 6295 6222 6475 6357 6235 6248 6325 6314 6285 6295 6311 6426 6354 6267 6219 6234 6239 6241 6170 6285 6216 6221 6406 6171 6114 6183 6021 6238 6292 6222 6210 6271 6281 6309 6194 6232 6253 6134 6129 6245 6191 6126 6178 6249 6432 6267 6280 6133 6329 6262 6309 6341 6198 6052 6062 6374 6286 6144 6296 6308 6288 6308 6299 6248 6151 6231 6374 6230 6296 6293 6393 6340 6169 6305 6265 6231 6271 6255 6292 6185 6391 6437 6355 6251 6232 6196 6335 6362 6174 6321 6474 6345 6237 6328 6473 6416 6259 6154 6189 6294 6436 6411 6404 6184 6604 6703 6733 6752 6991 7358 7723 8107 8251 8468 7878 7340 7195 6889 6881 6852 6925 7165 7338 7433 7532 7359 7246 7014 7174 6875 6876 6890 6847 6912 7112 7092 7407 7634 7842 8273 8538 9146 9904 10585 11596 12120 12639 12403 11726 11015 9889 9409 9014 8895 8860 8995 9312 9400 9507 9281 9018 8346 8011 7786 7201 7060 7321 7221 7145 7192 7153 6853 6829 6786 6805 6922 6892 6740 6814 6949 6893 7062 7111 7306 7484 8010 8617 8897 9524 9402 9053 8529 7975 7517 7316 7133 7559 7430 7895 8196 8411 8230 8100 7852 7603 7563 7422 7715 8005 8510 9116 9854 10458 10594 10390 9779 8782 8294 7724 7684 7406 7693 8120 8477 8435 8389 8319 8006 7819 7375 7120 7112 7203 7140 6999 7224 6928 7072 7048 6793 6842 6650 6883 6668 6567 6794 6793 6822 6464 6409 6576 6514 6614 6522 6479 6418 6463 6460 6558 6367 6375 6337 6437 6348 6361 6368 6337 6316 6142 6202 6369 6360 6437 6329 6442 6416 6314 6487 6410 6391 6528 6435 6450 6677 6489 6678 6674 6717 7132 7201 7240 7519 7637 8159 8496 8926 9508 9834 10517 10884 10958 10879 11036 10935 10604 10265 9945 9568 9224 9248 9147 8997 8766 8882 8773 8577 8376 8240 8021 7455 7143 7078 6718 6658 6605 6477 6469 6345 6334 6344 6398 6329 6407 6394 6063 6333 6251 6373 6324 6332 6397 6375 6484 6319 6330 6447 6428 6254 6215 6486 6442 6479 6369 6629 6621 6536 6759 6955 7301 7137 7376 7582 7560 7612 7520 7434 7627 7488 7397 7473 7808 8179 8544 8850 9460 9461 9343 9095 8875 8621 8395 8245 8257 8491 8943 9409 10315 11025 11659 12271 12377 11893 11106 10327 9309 8755 8595 8478 8420 8590 9058 9019 9232 9367 9143 8842 8484 8783 9077 9381 9993 10007 9704 9641 9053 8655 8139 7845 7593 7258 7613 7666 7799 7837 7840 8053 7873 7755 7229 7138 6781 6563 6433 6482 6533 6423 6611 6364 6373 6442 6295 6511 6592 6578 6465 6381 6434 6448 6550 6534 6783 6804 7099 7143 7652 8410 8976 10061 11026 12094 12319 12339 11346 10275 9386 8619 8048 7966 7868 8207 8650 9102 9509 9464 8847 8561 8058 7587 7170 6895 6699 6586 6537 6467 6388 6417 6459 6440 6534 6516 6285 6399 6249 6354 6357 6404 6286 6525 6250 6436 6368 6580 6519 6437 6672 6870 6985 7230 7611 7985 8504 8960 9099 8810 8215 7773 7332 7142 6854 7092 7532 7413 7685 8090 8070 8011 7620 7325 6899 6822 6637 6715 6684 6631 6484 6470 6439 6540 6448 6442 6596 6506 6479 6446 6378 6596 6565 6520 6518 6541 6569 6725 6787 6850 7135 7153 7510 7891 8305 9070 10224 11041 11980 12428 13232 13197 12719 12494 11570 11098 10553 9975 9945 9798 9930 10213 10282 10498 10814 10829 10911 10421 9848 9216 8470 8133 7734 7316 6991 6821 6899 7027 7066 7139 7088 7084 7012 6621 6499 6536 6564 6276 6263 6408 6094 6051 5991 6396 6253 6349 6086 6082 5995 6020 6147 6063 6122 6102 6007 6024 6229 6099 5996 6116 6212 6094 5994 5972 5990 6161 6111 6129 6104 6040 5995 6133 6102 6129 6201 6124 6060 6039 6105 5957 5962 5960 6045 5923 6096 6041 5888 5999 6086 6129 6140 6072 5978 6127 6050 6160 6055 6052 5997 6158 6077 6124 6019 6179 6093 5970 6190 6298 6083 6234 6017 5977 6083 6182 6095 6217 6060 6218 6080 6061 6010 6145 5903 6057 6036 6201 6080 6050 6089 6167 6036 6101 6057 6391 6229 6243 5976 6241 6222 6293 6050 6059 6259 6107 6195 6160 6090 6294 6294 6247 6202 6362 6646 6599 6955 7239 7612 7761 8200 8381 8695 8664 8883 8496 8107 7592 7307 7090 7044 7063 7190 7325 7305 7438 7504 7511 7443 7282 7072 6754 6786 6644 6494 6513 6508 6354 6292 6411 6261 6172 6149 6105 6005 6239 6240 6063 6267 6179 6159 6100 6038 6112 6204 6076 6048 6004 6050 6044 5846 5914 5763 6047 6062 6065 5998 5954 6027 6216 6030 5824 5994 5938 6116 6063 6080 5865 6011 6123 6280 6061 6185 6169 6176 6352 6430 6465 6560 6671 6868 7108 7109 7071 7202 6953 6956 6827 6789 6593 6453 6572 6538 6608 6636 6546 6655 6832 6648 6514 6595 6338 6151 6134 6184 6095 6101 6062 5984 6097 6238 6140 6125 6033 5995 6242 6054 5878 6016 5835 5869 6083 5979 6036 5955 6038 5938 6160 6035 5919 6081 6062 6036 6387 6225 6036 5987 5994 6146 5997 6096 6042 5823 5900 6077 6034 6294 5990 6249 6076 6074 6195 6084 6142 6099 6105 6031 5924 6099 6168 6056 6000 6054 6134 6315 6223 6080 6047 6030 5994 5940 5919 6064 5966 5822 5702 5779 6070 5952 5892 5819 5811 5870 5973 5880 5923 6110 5892 5990 5930 5776 5819 5831 5797 5914 5971 6097 5966 5895 5864 5763 5997 5909 6041 6041 5969 5886 6145 6030 6101 5844 6030 6020 6006 6122 6019 6066 6153 6133 6018 6081 6041 6099 5860 6025 6072 6086 5916 6023 6158 6412 6235 6149 6041 6136 6014 6142 5998 5997 5849 5874 5915 6016 6053 5863 6015 6104 6083 6297 6034 6146 5996 6058 5930 5896 5939 5970 5853 5925 5848 5918 5910 5898 5999 5881 5995 5828 5913 5882 5812 5770 6079 6014 5827 5899 5948 6034 6010 5886 5919 5708 5904 5901 5914 6025 5851 5948 5830 5999 5981 6004 5968 6192 6074 6107 6049 6191 5962 5889 6095 6022 6152 5919 5946 5964 6029 5946 6047 5973 5944 6093 6167 5942 5908 5818 6009 5877 6035 5942 5849 5900 5973 5829 5897 5879 5970 6073 5983 6106 6268 6077 6026 6036 6017 5835 5941 6134 6011 6003 6020 6093 6083 5868 6029 5824 6000 5959 5940 6043 5941 5998 6160 6043 5840 6071 6125 6043 6067 6198 5980 5954 5987 5902 5902 6093 5942 5866 5858 6006 6082 6102 5997 6059 5904 6062 5925 6070 6014 5906 6065 6159 6068 6084 5959 5767 5885 5868 5815 5946 5979 6022 5903 5884 5695 5971 6216 5859 5980 5898 5943 5992 6006 5980 5942 5924 5958 5882 5969 6016 6118 5934 5892 6123 6069 6101 5998 5993 6189 6276 6147 6229 6277 6454 6459 6496 6717 6676 6670 6806 6594 6635 7006 7245 7334 7629 8014 8207 8527 8692 8821 8963 8711 8403 7826 7497 7256 7169 6931 7058 6936 7280 7313 7324 7533 7573 7264 7614 7510 7427 7288 7262 7309 7290 7254 7117 6967 7067 7092 6960 7258 7243 7399 7660 7772 7761 7777 7757 7695 7770 7800 7917 8031 8280 8254 7942 7745 7470 7620 7334 7149 7038 6813 6460 6679 6539 6811 6665 6829 7000 6617 6779 6458 6222 6206 6107 6137 6058 6169 5954 6087 5986 5946 5994 6015 6004 6082 6036 5996 6030 5915 6148 5860 5935 6050 6047 6162 6157 6199 6108 5929 6106 5950 6130 6162 6173 6081 6043 6146 5979 6155 6245 6281 6341 6092 6050 5997 6180 6198 6021 6135 6058 6367 6510 6461 6553 6561 6715 6611 6777 6816 6731 6722 6486 6446 6592 6449 6283 6254 6329 6482 6574 6499 6486 6593 6381 6516 6448 6450 6278 6485 6339 6296 6306 6248 6262 6158 6227 6339 6134 6341 6423 6175 6224 6205 6258 5985 6111 5984 5990 6043 6134 6116 6217 6184 6349 6188 6177 6056 6023 5785 5959 5970 6119 6043 6057 5942 6112 6046 6064 5906 5921 6009 6089 5891 6007 6047 6110 6083 5959 6045 6120 6086 6025 6198 6129 6338 6393 6483 6443 6418 6634 6403 6483 6357 6384 6427 6524 6676 6744 6837 6824 7014 7342 7487 7907 8080 8423 8696 8532 8410 8299 7885 7915 7542 7247 7052 6866 6921 6890 6897 7065 7084 7250 7082 7280 7138 7013 7089 6746 6532 6340 6280 6320 6196 6139 5961 6086 6038 6053 5971 5966 5876 6045 5991 5930 6094 6049 6057 5981 6068 6199 6204 6381 6361 6575 6510 6639 6421 6369 6181 6248 6144 6185 6214 6120 5984 6085 6033 6050 6099 6238 6297 6225 6186 5984 6280 6143 5996 5869 5933 6085 6140 6072 6029 6078 6087 6131 5976 6058 6072 6140 6171 6198 6211 6197 6079 5981 6029 6119 6080 6074 5909 5941 6064 6056 6121 6301 6191 6372 6400 6538 6464 6527 6522 6856 6994 7254 7196 7337 7335 7344 7165 7194 6959 6575 6764 6761 6469 6565 6473 6527 6573 6648 6660 6885 6717 6711 6741 6583 6675 6689 6457 6319 6236 5979 6269 6126 6193 6005 5938 6020 5945 6033 6112 6023 6058 6033 6059 6049 6155 6254 6108 6149 6444 6199 6101 6020 6051 6015 6130 6107 6131 6172 6441 6421 6453 6764 6720 6730 6813 6858 6690 6878 6958 6696 6915 7132 7384 7598 7933 8054 8018 7655 7668 7384 7346 6855 6659 6508 6657 6557 6594 6550 6655 6657 6861 6830 6869 6910 6736 6543 6634 6331 6274 6292 6252 6090 6165 5997 6113 6010 6039 5919 6141 6102 6054 5970 5984 6113 5954 5963 5929 5909 5846 5964 5850 5740 6041 6074 5947 5862 5728 5825 5911 5840 6110 6064 5811 5881 5979 5738 5833 5717 5662 5935 6015 5826 5941 5875 5966 5943 5990 5951 5941 5773 5824 5844 5731 5801 5818 5863 5881 5848 5905 5791 5884 5831 5781 5719 5843 5826 5861 5778 5870 5959 5921 5997 5975 5867 6036 5968 6195 6197 6085 6213 6196 6316 6200 6111 5993 6093 5692 5923 6095 5967 5988 5950 5912 6073 6051 6003 6096 6143 6253 6228 6150 6056 5956 5903 6112 5935 5919 5877 5871 5887 5945 5892 6060 5932 5878 5888 6002 5931 6060 6178 6188 6233 6290 6164 6267 6178 6269 6200 6150 5885 5952 6127 5920 6064 5957 6048 6037 6036 6026 5954 6134 5871 6187 5948 5938 6109 5969 6087 6252 6301 6153 6233 6329 6235 6306 6513 6572 6668 6744 6868 7068 7419 7861 8117 8135 8055 8015 7788 7520 7453 7167 7044 6840 6635 6766 6557 6521 6565 6670 6981 7036 7119 7066 6932 7151 6616 6728 6798 6580 6413 6340 6354 6311 6278 6346 6401 6336 6465 6591 6707 6759 6819 7028 6836 6504 6440 6344 6123 6142 6242 6241 6245 6299 6408 6320 6433 6545 6503 6861 6954 6751 6704 6528 6280 6386 6384 6137 5942 5921 6043 5957 5893 5952 5856 5891 6042 6183 6009 6071 6016 5877 6063 5829 5832 5732 5888 6047 5781 5820 5801 5836 5770 5798 5690 5680 5758 5649 5778 5831 5712 5968 5665 5865 5868 5825 5809 5689 5794 6024 5914 5771 5813 5923 5806 5913 5809 5819 5807 6002 5927 5856 5790 6037 5932 5845 5995 5803 5960 5789 5742 5844 5781 5801 5842 5824 5854 5990 6014 5983 5960 6157 6054 6080 5751 6091 5937 5936 6040 5902 5941 6109 6151 6024 6041 5884 5917 5905 5971 6048 6079 6027 6146 6187 6145 6147 6233 6269 6330 6328 6415 6297 6217 6417 6529 6579 6594 6488 6840 6955 6770 6824 6998 6969 6849 6776 6731 6846 6567 6728 6343 6314 6306 6398 6254 6632 6669 6640 6736 6722 6673 6675 6684 6657 6364 6488 6560 6425 6236 6134 6301 6454 6527 6354 6287 6453 6592 6638 7044 6998 7213 7523 7456 7338 7319 7253 6932 6742 6600 6488 6509 6329 6485 6256 6375 6419 6519 6600 6574 6649 6659 6652 6677 6512 6409 6227 6214 6195 6302 6128 5954 6304 6126 6216 6305 6278 6238 6115 5912 5924 6074 5907 5892 5988 5966 5996 5890 5849 5974 5939 5931 6102 6039 6231 6323 6381 6208 6257 6155 6142 6158 6012 5994 5947 6036 6008 6105 6068 6042 6193 6279 6033 6017 6353 6496 6197 6577 6640 6545 6827 6670 6644 6655 6792 6500 6634 6615 6254 6484 6376 6521 6527 6435 6665 6770 6771 6741 6739 6597 6771 6761 6531 6550 6688 6585 6536 6545 6454 6481 6465 6475 6548 6707 6529 6345 6299 6307 6256 6286 6406 6141 6192 6387 6317 6265 6331 6486 6517 6423 6627 6551 6631 6501 6730 6765 6626 6802 6792 7048 6915 6764 6710 6709 6702 6600 6455 6407 6409 6390 6350 6413 6273 6221 6332 6186 6352 6425 6283 6413 6336 6360 6165 6037 6320 6219 6141 6096 5855 6072 6055 5928 5987 5966 5945 6024 5868 6010 5950 5884 6047 5871 5913 6068 5894 5978 5901 5908 5943 5928 5941 5982 5975 6134 6081 5899 5962 5993 5967 6055 5792 6040 5889 5780 5875 6073 6043 6112 6057 6159 6111 6282 6262 6307 6415 6429 6508 6366 6494 6433 6369 6332 6276 6155 6024 6153 6027 6065 5988 6193 6277 6218 6322 6455 6481 6405 6644 6577 6606 6436 6447 6320 6260 6332 6247 6347 6562 6507 6606 6794 6777 6723 6736 6650 6351 6415 6257 6362 6212 6271 6058 6235 6127 6163 6014 6156 6188 6143 6317 6170 6197 6269 5974 6054 5940 6110 6065 5958 5800 5853 5944 5898 5897 5864 5834 5725 5794 5738 5715 6019 5793 5827 5871 5727 5907 5864 5851 5891 5888 5833 5829 5779 5773 5909 5781 5822 5902 5719 5866 5669 5714 5684 5750 5703 5715 5599 5919 5766 5770 5623 5756 5597 5758 5738 5867 5725 5763 5768 5924 5754 5759 5731 5788 5679 5824 5794 5713 5776 5706 5802 5904 5816 5726 5980 5781 5805 5743 5909 5818 5875 5969 5914 6022 5938 5968 5855 5951 5859 5874 5798 5723 5765 5884 5801 5940 5639 5914 5843 5879 5830 5960 5943 6030 5932 5978 5852 5908 5991 5980 6092 5905 6096 6132 6164 6379 6246 6253 6253 6442 6251 6348 6502 6519 6392 6368 6106 6260 6142 5893 6139 5936 6085 6073 6093 6132 5949 5996 6086 6009 6260 5939 6274 6188 5979 6060 6155 6095 6071 5974 5950 6096 5860 5753 5865 5951 5916 5714 5917 5982 5836 5885 5903 5961 5947 5745 5854 5859 5871 5732 5883 5810 5814 5812 5746 5915 5785 5846 5805 5800 5819 5909 6029 5837 5841 6037 5865 5989 6042 6241 5975 6287 6111 6091 5961 5914 5915 5793 5939 5790 5884 5988 5769 5798 5791 5798 5859 5878 5807 5832 5787 5977 6029 5941 5863 5853 5821 5709 5797 5688 5803 5996 5999 5931 5969 5965 5855 5927 5836 5893 5840 5758 5946 5950 6025 5689 5920 5946 5745 5777 6046 5804 6006 5787 5931 5911 5918 6003 5934 6037 6093 6143 6086 5954 6124 6128 6202 6243 6214 6232 6620 6472 6494 6275 6511 6441 6394 6479 6521 6411 6403 6344 6192 6126 6241 6295 6177 6293 6409 6243 6603 6383 6620 6643 6824 6891 6905 6980 6745 6617 6294 6457 6292 6268 6325 6424 6336 6393 6241 6427 6523 6534 6627 6556 6847 6945 6836 6884 6786 6699 6629 6776 6362 6390 6323 6186 6092 6078 6221 6186 6139 6072 6171 5941 5889 6042 6216 6047 6142 6243 6195 6193 6196 6140 6104 6079 5881 6047 5851 5887 5752 5924 5899 5918 5966 5918 5941 6066 5922 5969 6019 5960 6113 6196 6091 5873 6112 6130 5953 6006 5940 5909 6004 6010 5846 6059 5952 6121 5926 5903 6034 5980 6053 6037 6111 6138 6390 6233 6356 6454 6448 6546 6658 6629 6672 6477 6569 6253 6290 6230 6162 5967 6071 5920 5950 6066 6021 6275 6067 6145 6103 6241 6182 6404 6442 6333 6472 6238 6462 6489 6388 6354 6485 6404 6378 6370 6331 6388 6200 5954 6042 5919 6140 6054 5743 5892 6024 6112 6071 6053 6188 6251 6319 6445 6249 6478 6522 6608 6606 6547 6465 6684 6596 6362 6494 6164 6250 6088 6048 6244 5998 6079 6144 6068 5986 6070 6062 6163 6287 6244 6408 6351 6495 6499 6531 6482 6637 6554 6547 6555 6441 6347 6205 6216 6232 6172 6254 6169 6181 6321 6349 6338 6395 6362 6464 6608 6699 6757 6699 6781 6833 7003 6840 6825 6766 6965 6858 6864 6799 6605 6404 6355 6127 6295 6123 6069 6171 6105 6104 6110 6155 6156 6210 6282 6111 6137 6326 6138 6129 6168 6075 6198 6003 5965 5906 5965 5882 6004 5848 5757 5805 5736 5583 5728 5837 5673 5702 5844 5702 5766 5827 5738 5813 5732 5620 5818 5731 5688 5854 5890 5822 5697 5885 5835 5845 5590 5758 5706 5662 5752 5775 5741 5813 5822 5787 5759 5716 5798 6033 5904 5667 5732 5753 5921 5811 5686 5897 5903 5698 5645 5618 5719 5772 5747 5802 5847 5700 5883 5781 5754 5739 5869 5799 5689 5762 5784 5726 5775 5851 5685 5820 5771 5707 5723 5818 5915 5925 5759 5737 5827 5847 5932 5735 5810 5785 5873 5942 5888 5999 6029 5914 6128 6049 6240 5941 6002 6244 6128 6182 6115 6208 6149 6092 6115 6027 5860 5866 6023 6063 6047 6008 5914 5968 6015 6014 5887 6104 6141 6033 6102 6073 6177 5904 6174 6086 6262 5995 6074 6190 6170 6332 6366 6211 6394 6267 6184 6116 5906 6017 5907 6039 5980 6185 6208 6221 6308 6435 6597 6572 6671 6755 6756 6939 6870 6957 6907 6931 7052 7007 7081 6962 6714 6734 6697 6599 6413 6269 6317 6406 6423 6192 6312 6212 6201 6139 6348 6254 6368 6367 6290 6431 6608 6401 6315 6226 6222 6096 6075 6157 6005 6007 5993 5935 5826 5747 5787 5841 5710 5901 5758 5864 5795 5816 5523 5701 5723 5656 5748 5790 5852 5973 5780 5787 5797 5748 5776 5769 5752 5780 5904 5902 5943 6007 5973 5991 6123 5861 5806 5794 5958 5779 6011 5948 5866 5904 5954 5966 5783 5799 5934 5938 5756 5918 5730 5762 5817 5754 5777 5848 5875 5740 5660 5709 5807 5845 5745 5675 5687 5846 5767 5867 5859 5744 5680 5766 5657 5834 5822 5802 5681 5591 5817 5886 5780 5692 5731 5786 5731 5862 5856 5754 5951 5916 5926 5920 5937 5983 6187 6122 6277 6317 6186 6301 6331 6631 6383 6404 6310 6312 6210 6145 6151 6000 5903 5959 6010 5918 5974 5915 5972 5869 5821 5982 5923 6080 6055 6110 5977 6188 6106 6158 6057 5998 6009 6040 6031 5885 5828 5935 5935 5725 5842 5909 6121 6044 5817 5711 5912 5806 5736 6008 5807 5673 5814 5732 5811 5910 6083 5912 6124 6042 5996 6223 6031 6223 6141 6095 6392 6290 6179 6330 6239 6413 6278 6346 6327 6256 6348 6211 6259 6443 6209 6224 6211 6252 6252 6403 6266 6254 6276 6093 6197 6260 6178 6231 6343 6472 6377 6719 6544 6444 6474 6455 6450 6321 6381 6248 6101 6098 6078 6098 6019 6170 6311 6237 6437 6341 6449 6360 6453 6464 6331 5992 6030 5950 6119 6111 6086 5961 6121 6035 5942 5852 6025 6017 6154 5939 5921 6004 5983 5993 6181 6239 6259 6334 6383 6242 6305 6288 6379 6312 6146 6065 6060 6084 6026 5992 5977 5846 5864 5834 5886 5888 5937 5808 5856 5867 6010 5925 5861 5977 6027 6025 5962 5990 6013 5901 5833 5931 5796 5812 5989 5772 5831 5769 5742 5824 5776 5684 5720 5797 5878 5806 5805 5643 5520 5643 5760 5723 5653 5646 5673 5805 5550 5643 5621 5661 5734 5787 5595 5757 5881 5773 5708 5574 5710 5709 5731 5641 5769 5636 5750 5625 5784 5757 5685 5734 5803 5693 5720 5773 5659 5730 5803 5766 5802 5750 6062 5931 5820 5766 5862 5841 5853 5803 5996 6043 5875 6038 5885 6120 6242 6304 6170 6122 6203 6308 6365 6283 6399 6221 6269 6265 6229 6271 6114 6099 6216 6153 5926 6080 6029 5918 6022 6070 5988 5953 5890 6194 6019 5950 6098 6079 5989 6154 6085 6126 6242 6225 6171 6078 6061 6051 6064 6000 6109 5797 5872 5886 5774 5850 5728 5845 5639 5713 5734 5780 5765 5684 5822 5782 5650 5767 5632 5778 5747 5660 5614 5692 5802 5859 5682 5646 5696 5812 5737 5719 5705 5705 5614 5835 5929 5879 5898 5877 5903 5812 5822 5603 5827 5865 6017 5951 5903 5796 5838 5889 5964 6189 5995 6178 6207 6046 6199 6028 6169 6012 6166 6062 6142 5989 5956 5707 6000 6029 6008 5930 5949 6049 6058 6184 6004 6035 6047 6098 6134 6094 5942 5946 5977 5980 6042 6083 5992 6056 5932 5979 5915 5813 5843 5762 5828 5912 5946 5861 6074 5962 5989 5877 5786 5744 5781 5899 5867 5652 5581 5739 5728 5801 5616 5654 5898 5746 5669 5548 5510 5698 5682 5680 5764 5778 5678 5731 5776 5904 5819 5743 5795 5702 5742 5707 5777 5734 5640 5782 5932 5727 5833 5763 5730 5731 5633 5725 5544</intensities>
			</dataPoints>
			<nonAmbientPoints type="Temperature" unit="K">
[...]
			</nonAmbientPoints>
		</scan>
	</xrdMeasurement>
</xrdMeasurements>