File: powder_X-ray_diffraction/variable-temperature_experiments/NaNbO2F2/raw_data/120°C.xrdml
<?xml version="1.0" encoding="UTF-8"?>
<xrdMeasurements xmlns="http://www.xrdml.com/XRDMeasurement/1.7" xmlns:xsi="http://www.w3.org/2001/XMLSchema-instance" xsi:schemaLocation="http://www.xrdml.com/XRDMeasurement/1.7 http://www.xrdml.com/XRDMeasurement/1.7/XRDMeasurement.xsd" status="Completed">
	<comment>
		<entry>Configuration=XRK900, Owner=User-1, Creation date=12/01/2015 16:52:44</entry>
		<entry>Goniometer=Theta/Theta; Minimum step size 2Theta:0.0001; Minimum step size Omega:0.0001</entry>
		<entry>Sample stage=AP XRK-900 with z-axis; Minimum step size Z:0.001</entry>
		<entry>Diffractometer system=EMPYREAN</entry>
		<entry>Measurement program=C:\PANalytical\Data Collector\Programs\Gwen\NaNbO2F2-Lent.xrdmp, Identifier={26D14ECE-D3C8-438C-91CA-8651EAF68C7D}</entry>
		<entry>Batch program=C:\PANalytical\Data Collector\Programs\Gwen\Thermodiff-Ouail.xrdmp, Identifier={9701CF17-19F5-4DD4-A8E1-7279D1FD2F5E}</entry>
	</comment>
	<sample type="To be analyzed">
		<id></id>
		<name></name>
		<preparedBy></preparedBy>
	</sample>
	<xrdMeasurement measurementType="Scan" status="Completed" sampleMode="Reflection">
		<comment>
			<entry>PHD Lower Level = 4.02 (keV), PHD Upper Level = 12.07 (keV)</entry>
		</comment>
		<usedWavelength intended="K-Alpha 1">
			<kAlpha1 unit="Angstrom">1.5405980</kAlpha1>
			<kAlpha2 unit="Angstrom">1.5444260</kAlpha2>
			<kBeta unit="Angstrom">1.3922500</kBeta>
			<ratioKAlpha2KAlpha1>0.5000</ratioKAlpha2KAlpha1>
		</usedWavelength>
		<incidentBeamPath>
			<radius unit="mm">240.00</radius>
			<xRayTube id="1010048" name="Empyrean Cu LFF HR (9430 033 7310x) DK420743">
				<tension unit="kV">45.0</tension>
				<current unit="mA">30.0</current>
				<anodeMaterial>Cu</anodeMaterial>
				<focus type="Line">
					<length unit="mm">12.0</length>
					<width unit="mm">0.4</width>
					<takeOffAngle unit="deg">6.0</takeOffAngle>
				</focus>
			</xRayTube>
			<sollerSlit id="21010001" name="Soller slits 0.02 rad.">
				<opening unit="rad">0.0200</opening>
			</sollerSlit>
			<mask id="22030010" name="Fixed mask 20 mm">
				<width unit="mm">20.00</width>
			</mask>
			<antiScatterSlit id="22010003" name="Fixed slit 1Â°" xsi:type="fixedAntiScatterSlitType">
				<height unit="mm">1.52</height>
			</antiScatterSlit>
			<divergenceSlit id="22010012" name="Programmable divergence slit" xsi:type="fixedDivergenceSlitType">
				<distanceToSample unit="mm">140.00</distanceToSample>
				<angle unit="deg">0.5</angle>
			</divergenceSlit>
		</incidentBeamPath>
		<diffractedBeamPath>
			<radius unit="mm">240.00</radius>
			<antiScatterSlit id="22090010" name="AS slit 8.0 mm (PIXcel)" xsi:type="fixedAntiScatterSlitType">
				<height unit="mm">8.00</height>
			</antiScatterSlit>
			<sollerSlit id="21010001" name="Soller slits 0.02 rad.">
				<opening unit="rad">0.0200</opening>
			</sollerSlit>
			<filter id="20030001" name="Large beta-filter Nickel">
				<material>Ni</material>
				<thickness unit="mm">0.020</thickness>
			</filter>
			<detector id="7010019" name="PIXcel1D-Medipix3 detector" xsi:type="rtmsDetectorType">
				<phd unit="%">
					<lowerLevel>25.0</lowerLevel>
					<upperLevel>75.0</upperLevel>
				</phd>
				<mode>Scanning</mode>
				<activeLength unit="deg">3.3482</activeLength>
			</detector>
		</diffractedBeamPath>
		<scan appendNumber="0" mode="Continuous" scanAxis="Gonio" status="Completed">
			<header>
				<startTimeStamp>2022-05-14T09:48:18+02:00</startTimeStamp>
				<endTimeStamp>2022-05-14T12:48:43+02:00</endTimeStamp>
				<author>
					<name>User</name>
				</author>
				<source>
					<applicationSoftware version="5.5a">Data Collector</applicationSoftware>
					<instrumentControlSoftware version="8.1b 20190506">EMPYREAN</instrumentControlSoftware>
					<instrumentID>0000000011159748</instrumentID>
				</source>
			</header>
			<dataPoints>
				<positions axis="2Theta" unit="deg">
					<startPosition>9.99846514</startPosition>
					<endPosition>99.99342261</endPosition>
				</positions>
				<positions axis="Omega" unit="deg">
					<startPosition>4.99923257</startPosition>
					<endPosition>49.99671130</endPosition>
				</positions>
				<positions axis="Z" unit="mm">
					<commonPosition>8.912</commonPosition>
				</positions>
				<commonCountingTime unit="seconds">386.070</commonCountingTime>
				<intensities unit="counts">7939 7994 7843 7955 7877 7955 7961 7806 7968 7826 7950 8180 8199 8131 8105 7882 8118 8136 8124 8067 7867 8036 7978 7938 8088 8110 7977 7920 7849 8096 8065 8207 7902 7963 7936 8059 7984 7876 7935 8057 7939 7911 8044 8008 7976 7867 8036 7896 7988 7963 8064 7891 7800 7960 8026 7804 8005 7921 7803 8043 8191 8062 8074 7946 8010 8038 8188 8107 8143 8245 8337 8440 8453 8607 8535 8621 8592 8692 8710 8670 8869 8945 9000 9619 9867 10284 11001 11876 13083 14715 17675 21887 29052 40012 55309 70197 79639 76826 66959 51724 37189 25540 17372 12988 10663 9570 9197 9110 8637 8582 8467 8445 8330 8247 8210 8180 8312 8079 8016 8055 8005 8111 7833 8258 8145 8120 7956 8205 7841 7760 7948 8153 8104 8140 8072 8174 8343 8112 8202 8290 8204 8420 8434 8380 8274 8326 8405 8182 8259 8198 8217 8308 8386 8083 8195 8288 8133 8304 8239 8414 8365 8347 8346 8479 8390 8335 8261 8275 8398 8491 8395 8244 8460 8545 8197 8381 8377 8221 8345 8181 8207 8130 8452 8359 8266 8496 8446 8137 8267 8396 8302 8397 8371 8384 8261 8328 8416 8339 8261 8466 8015 8240 8230 8434 8357 8401 8429 8359 8228 8256 8343 8172 8300 8426 8340 8273 8176 8250 8252 8247 8143 8324 8311 8045 8212 8125 8140 8333 8140 8264 8142 8165 8100 8109 8201 8022 8201 8125 8245 8044 8207 8139 8056 7959 8157 8311 8324 8224 8163 8035 8202 8054 8182 8063 7991 7916 8098 8042 8164 8175 8083 8221 7988 8121 8178 8236 8142 7943 8127 8006 8115 8190 8253 8144 8119 7961 8062 7995 8091 8101 8279 8192 8086 8239 8309 8421 8211 7977 8163 8182 8236 8168 8168 8075 8008 8089 7918 8109 8091 8073 7981 8187 7845 8148 8113 8052 8166 7960 8074 8107 7999 8007 8241 8245 8282 8168 8078 7944 8059 7886 8114 7999 7902 7999 7968 8024 8149 8031 8132 8028 7905 8102 8159 7972 8179 8151 8247 8036 8279 8447 8491 8697 9097 9355 9619 9691 9606 9490 9260 9067 8913 8458 8448 8347 8249 8143 8012 7890 7964 7994 8072 8034 8165 7947 7979 7932 7778 7837 8084 8085 8013 7978 7974 7980 7878 7762 7773 7994 7945 7849 7814 7798 7718 7878 7928 7698 7672 7810 7781 7816 7909 7915 7905 7838 7873 7893 7737 7830 7827 7771 7934 7770 7784 7823 8025 7753 8023 7940 7829 7807 7785 7881 7936 7932 7898 7853 7699 7611 7817 7836 7744 7787 7866 7848 7884 7857 7764 7776 7935 7705 7790 7934 7868 7820 7693 7726 7815 7803 7780 7832 7907 7653 7709 7950 7748 7785 7823 7854 7799 7870 7929 8035 7816 7980 7903 7913 7900 7725 7939 8006 7771 7735 7803 7810 7902 7904 7760 7576 7561 7776 7732 7667 7765 7696 7818 7858 7806 7768 7837 7670 7628 7670 7952 7860 7770 7816 7702 7715 7492 7758 7666 7803 7765 7913 7904 7775 7845 7705 7914 7906 7699 7640 7496 7640 7666 7734 7646 7712 7658 7807 7637 7659 7721 7898 7933 7985 8189 8419 8428 8055 8094 7954 8018 7852 7811 8002 7705 7739 7833 7567 7597 7759 7730 7779 7657 7554 7603 7468 7714 7614 7403 7398 7481 7549 7704 7626 7782 7765 7467 7566 7485 7419 7583 7616 7581 7515 7678 7532 7590 7658 7522 7554 7537 7288 7562 7491 7584 7726 7570 7528 7382 7699 7531 7443 7548 7482 7506 7642 7413 7498 7532 7567 7576 7726 7527 7501 7539 7528 7573 7534 7443 7413 7354 7291 7246 7418 7573 7344 7411 7600 7448 7662 7651 7592 7564 7880 7690 7783 7432 7329 7299 7584 7554 7453 7383 7422 7227 7384 7533 7446 7437 7326 7447 7413 7314 7457 7516 7374 7436 7486 7388 7240 7408 7415 7283 7316 7413 7391 7575 7353 7412 7439 7296 7298 7369 7271 7260 7342 7410 7408 7168 7055 7258 7179 7418 7224 7462 7484 7244 7206 7357 7403 7369 7526 7313 7298 7339 7284 7338 7482 7307 7527 7258 7049 7262 7103 7236 7298 7386 7345 7259 7319 7241 7344 7282 7397 7240 7256 7283 7314 7335 7332 7421 7477 7412 7368 7417 7493 7525 7704 7667 7900 7793 7696 7776 7886 7692 7694 7752 7706 7739 7718 7730 7787 7699 7656 7402 7719 7793 7786 7758 7658 7745 7747 7714 7705 7682 7843 7800 8218 8078 7761 8085 7944 8400 8533 8489 8778 8825 9009 9116 9517 9997 11017 12436 14223 17121 21905 29706 41460 56174 73675 88192 93945 88161 79012 68174 55995 42186 30616 21882 16130 12742 11137 10149 9682 9240 9036 8799 8632 8538 8286 8198 8085 8001 7745 7891 8209 7985 8039 7919 7976 7983 8072 7823 7819 7771 7690 7453 7755 7788 7733 7613 7880 7482 7646 7714 7594 7523 7465 7534 7518 7578 7648 7443 7433 7666 7391 7494 7600 7710 7754 7506 7686 7607 7467 7658 7600 7358 7523 7583 7423 7543 7668 7614 7384 7516 7355 7374 7334 7358 7563 7352 7454 7506 7400 7420 7392 7520 7364 7651 7495 7476 7527 7270 7407 7519 7411 7285 7316 7308 7605 7595 7311 7490 7437 7297 7292 7535 7570 7476 7480 7302 7597 7571 7542 7466 7504 7564 7637 7549 7402 7554 7499 7547 7419 7314 7400 7463 7547 7457 7425 7320 7444 7248 7482 7560 7480 7569 7528 7628 7665 7382 7468 7522 7456 7489 7531 7544 7437 7465 7570 7586 7659 7664 7568 7642 7550 7733 7681 7770 7614 7600 7691 7472 7430 7397 7381 7519 7414 7433 7489 7387 7466 7466 7311 7414 7539 7461 7311 7414 7590 7365 7336 7586 7392 7439 7435 7450 7541 7503 7573 7418 7529 7706 7662 7646 7728 7630 7713 7808 8107 8223 8420 8586 9102 9824 11068 13223 17056 22663 29078 33623 33571 31300 28282 25602 22775 19017 15527 12110 10247 9039 8637 8117 8149 8146 7834 7948 7835 7562 7697 7631 7688 7363 7553 7514 7498 7573 7360 7247 7440 7458 7487 7477 7549 7650 7398 7413 7552 7496 7601 7461 7478 7511 7560 7507 7654 7538 7504 7600 7622 7473 7517 7671 7540 7613 7688 7667 7644 7469 7608 7572 7601 7349 7624 7443 7498 7500 7592 7527 7710 7714 7781 7699 7750 7763 7670 7919 7785 7744 7936 8163 8351 8520 8690 9167 9735 11476 14348 18571 23694 28862 29948 27863 25208 23528 21940 19453 16309 13574 11204 9957 9382 8876 8990 8613 8738 8811 8985 9232 9820 10751 12989 16434 22188 30074 36378 37670 33659 29394 27811 25668 22501 18026 14377 11675 9886 9032 8452 8399 8217 8146 7834 8061 8064 8045 8013 7933 7905 7843 7865 7884 7871 7729 7341 7560 7520 7418 7512 7522 7406 7362 7510 7478 7395 7488 7436 7585 7414 7379 7420 7408 7437 7523 7371 7414 7459 7506 7589 7585 7582 7302 7428 7286 7445 7326 7252 7350 7386 7458 7415 7424 7428 7388 7305 7337 7574 7351 7456 7409 7455 7458 7328 7466 7281 7279 7452 7374 7331 7343 7388 7450 7649 7581 7685 7709 7603 7608 7333 7482 7474 7603 7341 7291 7232 7254 7277 7337 7228 7403 7346 7354 7240 7452 7418 7358 7311 7381 7430 7409 7301 7344 7495 7385 7227 7123 7282 7319 7347 7323 7165 7399 7237 7419 7378 7352 7245 7336 7410 7406 7123 7498 7296 7209 7425 7643 7356 7244 7389 7407 7400 7329 7255 7226 7074 7186 7233 7569 7249 7445 7426 7270 7250 7231 7192 7048 7160 7223 7149 7141 7168 7321 7146 7156 7150 7148 7278 7234 7385 7404 7235 7066 7248 7284 7287 7091 7083 7142 7122 7201 7136 7263 7223 7059 7231 7250 7353 7014 7205 7238 7054 7212 7099 7289 7446 7260 7225 7204 7214 7035 7096 7240 7271 7088 7079 7105 7082 7089 7259 7266 7032 7018 7279 7044 6983 7224 7507 7417 7370 7322 7475 7663 7556 7387 7262 7497 7518 7484 7366 7260 7362 7402 7480 7424 7467 7491 7410 7389 7493 7582 7641 7301 7497 7544 7516 7387 7560 7334 7413 7335 7499 7328 7407 7375 7534 7493 7505 7220 7246 7476 7391 7629 7675 7474 7519 7763 7797 7865 7896 7702 7914 8156 8284 8353 8702 8640 8675 8873 9275 9474 9834 10206 10683 11251 12187 13753 16027 19847 25947 35968 50228 66971 82046 88742 85749 76723 67482 61822 56623 51018 42008 32381 24362 18481 14680 12679 11172 10629 10002 9287 9095 8639 8586 8341 8219 8169 8246 8151 7779 7818 7987 7732 7792 7848 7838 7860 8104 8248 8517 8673 9095 8798 8785 8708 8633 8552 8382 8200 7975 7875 7675 7440 7532 7521 7319 7598 7753 7589 7646 7678 7725 7699 7866 7858 7737 7990 8150 8220 8441 8768 9029 9595 11151 13784 18256 25642 34576 40411 39040 33025 28043 26232 26411 25708 22532 18173 14533 11497 10009 9450 8871 8841 8737 9234 9272 10278 11246 12451 13487 14147 14946 15611 16255 16858 16051 14735 13601 12384 11885 11472 10444 9500 8763 8416 7921 7807 7853 7534 7258 7391 7525 7448 7386 7064 7462 7186 7286 7156 7059 7391 7270 7194 7139 7216 7257 7174 7163 7341 7370 7228 7176 7138 7053 7127 6950 7133 7268 7143 7005 7207 7007 7029 7154 7141 7058 6931 7163 7040 7081 6969 6998 7140 6963 6963 6955 7058 6996 6958 6988 6960 7084 7188 7115 7173 7167 6885 6873 6985 7099 7115 7016 6727 6847 6811 6983 6944 6917 7010 7039 7051 6946 6986 6917 6943 6902 6964 6955 6916 7071 7055 7377 7083 6936 6850 6913 6945 7043 6897 7040 6918 6955 6993 7039 6891 7083 7127 6787 7099 6962 7080 6800 6954 6880 6873 6898 6951 6955 6885 6839 6902 6962 6884 6812 6974 6930 6977 6991 7067 7107 7023 7101 6929 6919 6967 6935 7064 7011 6884 6717 6919 6890 6988 6980 6939 6895 6840 6767 6709 7006 6848 6842 6703 6746 6786 6814 6883 6826 6853 6840 6954 6820 6960 6852 6944 6775 6760 6915 7036 6893 7036 6945 7060 6926 6807 6607 6832 6877 6836 6825 6748 6754 6707 6651 6837 6933 6786 6881 6922 6847 6913 6957 6991 6997 7021 6957 6728 6855 6865 6923 6741 6900 6880 6791 6795 6731 6908 6978 6846 6877 6897 6752 6886 6929 6907 6835 6940 6796 7099 6951 6886 7039 6985 6925 7072 6991 7090 7181 6979 7035 7034 7040 6962 6897 6964 7003 6881 6963 6858 6837 6716 6803 6812 6837 6826 6949 6883 6992 6878 6768 6900 6931 7025 6884 6860 7180 7173 7167 7136 7202 7338 7470 7470 7534 7578 7902 8378 8974 9829 11826 14859 18346 21445 23912 25518 25101 22286 19629 18200 17585 17351 16333 14608 12556 10664 9383 8629 7962 7713 7455 7454 7416 7158 7234 7025 7083 6973 7029 6938 7086 6883 6936 6829 6699 6890 6810 6797 7063 6976 6830 6902 6870 6917 7065 7002 6946 6938 7048 6979 7025 7109 7217 7409 7696 8058 8511 9144 10458 11770 13508 14771 14831 14213 12797 11736 11389 11245 11395 11119 10222 9178 8661 8100 8034 8106 7931 7917 7905 7618 7527 7611 7564 7508 7531 7494 7396 7456 7303 7412 7300 7495 7803 8228 9317 10729 12919 13464 13513 12710 11381 10551 10322 10474 10458 10000 9421 8653 7806 7245 7072 6980 7042 6914 6824 6846 6920 6959 6826 6731 6572 6697 6713 6857 6782 6694 6918 6727 6708 6864 6677 6729 6632 6760 6793 6891 6700 6846 6976 6774 7006 6786 6944 7066 7088 7189 7174 7359 7722 8301 9192 10081 11304 11592 11650 10761 10243 9817 9630 9545 9462 9163 8672 8262 7674 7433 7558 7501 7659 7674 7467 7235 7186 6975 7107 7080 7041 7126 6988 6814 6769 6524 6567 6569 6696 6662 6677 6754 6704 6607 6536 6580 6523 6690 6617 6718 6700 6772 6494 6649 6615 6542 6788 6633 6477 6634 6680 6503 6556 6599 6485 6624 6500 6518 6396 6520 6325 6495 6616 6646 6482 6671 6578 6701 6621 6550 6645 6783 6389 6623 6317 6525 6710 6501 6639 6533 6548 6593 6709 6532 6500 6601 6614 6683 6640 6418 6585 6656 6695 6760 6776 6569 6654 6732 6799 6638 6778 6737 6737 6833 6845 6643 6773 6979 7215 7484 7936 8819 9750 10198 9853 9223 8393 8135 8235 8308 8495 8348 7813 7278 7174 6936 6674 6638 6686 6635 6743 6675 6474 6578 6559 6608 6652 6608 6537 6645 6528 6434 6504 6572 6675 6631 6513 6582 6434 6506 6646 6618 6520 6529 6590 6580 6623 6497 6620 6452 6542 6658 6652 6555 6555 6534 6656 6486 6572 6534 6598 6415 6427 6622 6544 6690 6658 6502 6443 6510 6597 6594 6540 6530 6701 6476 6545 6758 6687 6680 6558 6719 6812 6678 7053 7163 7351 7549 7545 7214 7310 7318 7376 7510 7625 7930 8441 9066 9941 11034 11913 12393 12497 11844 11714 11832 11706 11863 11408 10875 10056 9501 8774 8626 8485 8231 7876 7575 7066 6970 6823 6773 6776 6676 6758 6474 6871 6637 6740 6590 6695 6752 6557 6494 6708 6635 6718 6612 6533 6628 6604 6493 6559 6612 6545 6455 6407 6476 6524 6535 6540 6549 6397 6408 6622 6344 6230 6467 6671 6581 6443 6355 6516 6352 6503 6533 6609 6454 6517 6360 6284 6637 6437 6411 6477 6481 6415 6357 6446 6616 6570 6450 6514 6523 6612 6562 6430 6389 6371 6493 6556 6528 6562 6508 6405 6528 6615 6686 6379 6373 6420 6415 6425 6347 6429 6515 6607 6472 6638 6906 7032 7471 8156 8969 9531 9665 9158 8547 7784 7581 7518 7872 8003 8030 7768 7311 7177 6788 6692 6634 6632 6440 6506 6464 6525 6471 6316 6328 6338 6385 6452 6341 6268 6393 6442 6501 6403 6562 6554 6554 6325 6334 6453 6384 6434 6422 6428 6532 6500 6522 6431 6513 6542 6478 6524 6439 6534 6282 6563 6466 6634 6548 6340 6399 6416 6564 6640 6631 6599 6633 6525 6730 6746 6854 7097 7277 7314 7286 7528 7251 7104 6807 6866 7101 7387 7537 7902 8214 8571 9088 9237 9258 8842 8570 8110 8124 8001 7990 8005 7923 7601 7438 6998 7048 6680 6662 6479 6568 6472 6467 6217 6582 6609 6339 6531 6301 6339 6495 6486 6445 6480 6447 6313 6421 6548 6515 6442 6598 6466 6494 6530 6451 6504 6619 6653 6474 6567 6701 6711 6736 6879 7240 7490 7946 8261 8234 8030 7962 7701 7983 8331 8930 9834 10654 11416 11624 11940 11716 11599 11393 11458 11085 10787 10390 9951 9691 9115 8819 8565 8353 7876 7485 7091 7001 6837 6665 6633 6835 6642 6536 6548 6417 6460 6412 6563 6476 6297 6266 6287 6225 6316 6439 6725 6465 6205 6437 6527 6464 6392 6585 6533 6443 6420 6378 6407 6533 6383 6544 6539 6297 6461 6479 6360 6643 6557 6346 6405 6368 6446 6431 6259 6424 6510 6531 6292 6288 6552 6259 6466 6496 6273 6468 6236 6351 6631 6416 6346 6356 6489 6282 6383 6317 6359 6616 6462 6370 6325 6401 6292 6304 6325 6244 6409 6419 6461 6455 6429 6418 6348 6299 6350 6451 6347 6484 6438 6316 6528 6453 6402 6495 6200 6276 6432 6340 6470 6315 6443 6390 6371 6296 6291 6421 6393 6297 6166 6161 6401 6245 6386 6393 6429 6507 6290 6440 6293 6309 6286 6332 6344 6298 6348 6347 6466 6368 6276 6325 6458 6379 6333 6153 6518 6322 6467 6339 6391 6253 6356 6317 6356 6471 6288 6488 6560 6593 6471 6429 6362 6400 6354 6515 6554 6472 6568 6458 6747 6949 7169 7417 7710 7916 7794 7733 7507 7098 6895 7080 7087 7231 7153 7087 7010 7045 6909 6697 6466 6514 6394 6423 6409 6351 6409 6424 6469 6480 6436 6347 6406 6348 6318 6431 6408 6311 6286 6412 6341 6714 6623 6553 6586 6638 6436 6509 6581 6367 6402 6416 6587 6446 6581 6592 6478 6489 6578 6322 6485 6439 6396 6442 6534 6415 6659 6452 6305 6691 6871 6845 6843 6824 6944 7045 7060 6878 7241 7297 7403 7709 8184 8887 10041 11358 12541 13125 13184 12463 11415 10516 9664 9205 9695 9705 9824 9823 9502 8860 8335 7586 7242 7107 6871 6788 6748 6563 6576 6534 6437 6518 6490 6569 6359 6261 6527 6644 6437 6280 6358 6506 6208 6393 6344 6233 6355 6327 6411 6439 6228 6300 6329 6317 6366 6358 6383 6367 6445 6436 6384 6369 6185 6268 6307 6245 6215 6366 6322 6304 6348 6284 6291 6395 6475 6469 6347 6309 6405 6332 6323 6395 6411 6334 6263 6372 6336 6444 6231 6083 6343 6388 6448 6346 6360 6528 6502 6524 6689 6695 6637 6743 6726 6760 6783 6792 6877 6963 6814 6983 7267 7243 7484 7991 8450 9255 10933 13601 16747 19290 19993 19275 17622 15072 13272 12006 11963 12958 13782 14001 13614 12686 11270 9873 9003 8204 7793 7533 7294 7116 7083 6814 6857 6736 6682 6682 6610 6550 6380 6556 6512 6569 6592 6555 6566 6519 6197 6349 6350 6524 6509 6326 6436 6455 6397 6277 6465 6529 6548 6490 6492 6473 6262 6477 6533 6497 6461 6546 6352 6268 6343 6441 6371 6527 6460 6406 6387 6325 6333 6508 6608 6298 6270 6350 6368 6487 6406 6342 6277 6446 6398 6393 6584 6635 6602 6638 6563 6355 6654 6594 6702 6737 6647 6566 6685 6981 6940 6917 7256 7332 7658 8551 9145 9843 10957 12042 13591 14604 14146 13015 11262 9842 9388 9461 9389 10096 10324 10673 10383 9218 8402 8008 7448 7244 7179 7079 6954 6871 6859 6737 6811 6684 6860 6743 6733 6888 6834 6954 6926 7166 7015 7038 6822 7034 7072 7157 7401 7447 7726 7935 8129 8838 9695 10731 12279 14098 15814 17453 17945 17795 16743 15136 13798 12562 11966 12279 12636 12685 12855 12453 11593 10671 9476 8592 7961 7543 7338 7327 7309 7084 6907 6729 6845 6763 6801 6790 6771 6917 7034 7195 7313 7477 7644 7771 7796 8019 7649 7760 7644 7641 7715 7892 7866 7756 7830 7630 7515 7334 7311 7131 7128 7179 7027 6873 7030 6887 6933 6957 6850 6971 6928 6995 6828 6928 7095 7196 7255 7248 7492 7531 7772 8190 8599 9589 10826 12133 14045 15627 16020 15800 14847 13311 12341 11848 12058 13398 14187 14795 14705 13720 12206 10871 9967 9170 8846 8712 8773 8908 8583 8254 7719 7340 7166 7056 7157 6724 6856 6955 6831 6686 7035 6934 7063 7109 6942 7061 7041 7132 7224 7247 7662 7954 8319 9073 10174 11192 13459 15968 17902 19398 18952 17558 15000 13072 11811 11347 11528 12021 12806 13186 13233 12419 11190 9887 8819 8125 7660 7396 7089 6892 6950 6777 6892 6594 6880 6746 6647 6591 6682 6818 6640 6660 6604 6599 6569 6706 6653 6520 6668 6766 6607 6701 6840 7150 7227 7304 7557 7977 8361 8780 8926 8602 8423 8101 7739 7626 7644 7809 7999 8215 8524 8859 8945 9129 9282 9371 9437 8965 8283 8344 7989 7700 7712 7690 7864 7892 7871 7821 7401 7149 7028 7068 6827 6654 6630 6684 6532 6560 6661 6568 6617 6434 6533 6560 6423 6544 6414 6427 6386 6576 6572 6344 6325 6511 6533 6492 6338 6536 6405 6620 6404 6415 6481 6617 6513 6360 6455 6529 6471 6385 6632 6677 6666 6744 6984 7067 7395 7906 8567 9825 11515 13739 14567 14090 12547 10991 10302 9857 9829 10113 10947 11188 11747 11575 10793 9782 9193 8853 8789 8909 8835 8547 8386 7928 7525 7232 7078 6892 6743 7053 6990 6891 6972 6775 6802 6673 6597 6547 6531 6278 6312 6296 6395 6408 6312 6427 6408 6408 6536 6460 6391 6285 6286 6388 6386 6445 6306 6372 6491 6426 6451 6487 6347 6203 6449 6499 6559 6726 6767 6982 7170 7588 8196 8126 7844 7506 7179 7023 6758 6767 6995 6864 7155 7305 7226 6986 6957 6529 6437 6457 6426 6281 6478 6493 6533 6276 6393 6443 6487 6522 6316 6253 6334 6447 6401 6347 6314 6261 6227 6240 6315 6169 6151 6220 6260 6359 6178 6377 6327 6373 6264 6213 6344 6458 6517 6541 6570 6388 6577 6344 6547 6335 6260 6389 6386 6367 6372 6501 6294 6225 6234 6300 6005 6145 6248 6320 6132 6410 6315 6254 6310 6336 6343 6200 6288 6278 6260 6229 6350 6118 6200 6179 6430 6132 6231 6101 6154 6202 6464 6329 6477 6297 6421 6443 6450 6437 6375 6292 6252 6353 6241 6207 6359 6410 6315 6280 6336 6278 6332 6196 6093 6286 6301 6033 6083 6124 6209 6110 6119 6190 6262 6321 6175 6235 6174 6333 6138 6181 6288 6263 6453 6226 6209 6198 6258 6180 6150 6065 6239 6281 6240 6217 6150 6335 6121 6245 6268 6273 6201 6290 6251 6204 6347 6289 6237 6131 6299 6252 6270 6259 6224 6433 6458 6525 6251 6207 6362 6225 6172 6321 6223 6371 6430 6194 6332 6364 6369 6491 6202 6132 6318 6181 6370 6306 6291 6348 6200 6220 6292 6314 6333 6358 6309 6420 6282 6338 6488 6318 6232 6271 6228 6239 6449 6498 6795 6897 7154 7543 7859 8281 8184 8059 7784 7307 7212 6878 6814 7011 7072 7201 7653 7519 7509 7381 7137 7078 7114 6983 7001 6986 7276 7523 7454 7806 7955 8580 9023 9774 10524 11153 12162 12475 12488 12074 11496 10300 9537 9092 8814 8746 8999 9383 9450 9602 9437 9022 8373 7854 7655 7159 7266 7224 7216 7293 7219 7336 7206 6978 6706 6664 6789 6852 6818 6865 6813 6904 7070 7002 7027 7519 8032 8409 8861 9250 9403 9321 8644 8230 7670 7347 7156 7299 7392 7693 8101 8242 8507 8227 7708 7467 7648 7456 7379 7786 8191 8928 9480 10130 10503 10703 10119 9605 8724 8060 7826 7705 7855 7800 8167 8334 8475 8497 8255 8051 7639 7350 7156 7166 7255 7109 6967 6828 6912 6998 6919 6887 6825 6697 6698 6631 6766 6706 6789 6739 6598 6618 6564 6510 6473 6584 6274 6331 6341 6378 6178 6178 6527 6436 6295 6164 6298 6383 6417 6512 6204 6348 6230 6376 6326 6367 6331 6293 6527 6280 6246 6377 6333 6498 6664 6599 6638 6762 6717 6704 6893 7055 7245 7379 7729 8085 8584 9051 9475 10004 10272 10526 10769 10818 10851 10765 10674 10454 10110 9928 9521 9337 9222 9088 8950 8800 8597 8309 8275 8113 7795 7543 7218 6943 6869 6827 6643 6707 6545 6538 6552 6476 6322 6228 6341 6315 6275 6562 6280 6301 6362 6415 6279 6403 6426 6472 6424 6301 6101 6208 6283 6210 6326 6389 6550 6515 6787 6905 7094 7138 7300 7604 7588 7488 7655 7585 7330 7397 7401 7469 7318 7396 7726 8261 8531 9090 9338 9377 9254 8909 8974 8663 8597 8583 8697 9128 9381 10065 10771 11443 11679 12160 11972 11389 10775 9940 9205 8517 8556 8534 8725 8749 8971 9054 9109 9087 8976 9086 9081 9125 9295 9541 9927 9873 9699 8984 8660 8166 7666 7458 7389 7523 7617 7647 7900 7996 8067 7711 7490 7071 6915 6827 6633 6593 6621 6453 6453 6414 6410 6254 6512 6462 6410 6482 6418 6404 6511 6248 6424 6447 6476 6735 6661 6740 7027 7051 7390 7593 8422 9223 10185 11254 12296 12547 12185 11201 10149 9072 8592 8213 7882 8035 8534 8811 9059 9286 9519 8943 8562 7851 7719 6904 6903 6594 6755 6531 6648 6555 6485 6405 6554 6466 6319 6500 6324 6147 6336 6370 6360 6407 6236 6339 6350 6471 6639 6750 6713 6749 7073 7298 7647 8369 8802 9042 8991 8670 8130 7619 7387 7066 7172 7308 7532 7382 7717 8021 8125 7673 7514 7069 7091 6881 6769 6756 6510 6659 6650 6618 6608 6617 6490 6404 6372 6577 6333 6436 6494 6501 6543 6547 6553 6598 6837 6736 6933 7059 7106 7423 7685 8206 8774 9915 10666 11903 12973 13503 13949 13510 12817 11891 11094 10435 9958 9574 9535 9670 9908 10101 10438 10407 10295 10285 10129 9760 9523 9129 8598 8052 7692 7298 7242 6952 6716 6635 6805 6898 7115 7027 7174 7012 6651 6663 6655 6408 6268 6237 6093 6064 6274 6320 6339 6118 6108 6192 6018 6120 6133 6176 6068 6069 5957 6085 6260 6173 6285 6206 6200 6035 5976 6127 6137 5967 6116 6093 6101 6138 6006 6250 6010 6164 6078 6103 6014 6045 6146 6245 6137 6192 6081 5920 6089 6138 5997 6266 6067 6181 6180 6024 6049 6110 5933 6209 6141 5965 6032 6195 6003 6018 6021 6108 5989 6091 6162 6163 6079 6166 6108 5988 6213 6104 6077 6237 6242 6004 6132 6049 6133 6129 6215 6083 6201 6133 6165 6086 6018 5979 6219 6047 6233 6203 6226 6108 6248 6139 6272 6156 6089 6119 6042 6217 6214 6150 6261 6236 6375 6411 6366 6690 6682 6858 7303 7449 7477 7828 7913 8183 8149 8310 8567 8581 8287 7938 7613 7605 7314 7195 7220 7237 7067 7242 7354 7320 7364 7218 7181 6916 6895 6610 6719 6510 6486 6438 6267 6315 6225 6140 6188 6182 6226 6077 5998 6123 6140 6211 6321 5946 6021 5885 5887 6035 6133 6022 6088 6049 6146 6154 5935 5997 6031 6116 6062 6066 5930 5879 6088 6126 6008 5980 6084 6155 6242 6077 6175 6096 6308 6168 6271 6249 6469 6620 6559 6766 6820 7009 7014 7134 7252 7174 7046 6811 6627 6572 6478 6417 6519 6606 6559 6716 6717 6646 6595 6636 6518 6284 6342 6443 6062 6177 6271 6072 6137 6176 6115 6169 6103 5934 5966 5976 6128 6133 5892 6015 6040 5893 5991 5966 6080 6041 5985 5975 5978 6132 5958 6026 5975 6146 6136 6000 6067 6211 6137 6025 5972 6010 5987 6059 5938 6123 5997 6154 6032 5986 6132 6025 6098 6162 6209 6346 6196 6011 6028 6234 6126 6177 6075 6286 6120 6169 6078 5901 6074 5986 5956 5972 6108 6055 5973 6119 6004 6161 5910 5956 5860 5927 5956 5849 5851 5880 5791 5911 5737 5864 5899 5857 5899 5960 5935 6058 5876 5890 5807 5928 5902 5923 6033 5993 5980 5902 5979 5916 6040 6204 6011 5992 5979 5916 5935 5967 5949 6081 6207 6152 5921 6031 6045 6058 5990 5939 5830 6013 5895 6189 6057 6216 6222 6207 6115 6268 6195 6158 6117 6278 5795 5911 6194 6028 6025 5955 5893 5866 6147 6019 6003 5902 6057 5890 6038 5934 6099 5825 5988 5915 5826 5993 6009 5976 5882 5832 5816 5939 5895 5923 6102 5919 5925 5842 5841 6111 6023 5849 5918 6159 6057 6021 5945 5761 5881 5849 6073 6025 5934 6010 5918 5862 6137 6108 5854 6103 6101 6125 6196 6082 5891 5899 5988 5938 6002 6029 6186 5871 6015 6071 5978 5939 5967 6020 5983 6007 6051 6017 5943 5925 5893 5898 6087 6017 5952 5921 5876 6004 5983 6088 6121 5813 6052 5992 5793 5946 6048 5930 5842 6012 6117 6014 5865 5986 5989 5830 5966 5935 5867 5867 6066 5919 5993 5856 5831 5921 5915 6046 6098 6150 5952 6000 6006 6011 6118 6056 5976 5798 6086 5894 5896 6067 5972 6052 6062 5965 6097 6020 6061 5926 6119 5962 5979 6004 6080 5907 5960 6050 6009 5839 5946 5922 6000 5968 5940 5952 6088 5932 6045 6013 6048 5896 5908 5939 5913 6006 5854 5964 5910 6006 5922 5946 5942 6016 6105 6133 6071 6074 6249 6207 6331 6238 6369 6324 6518 6482 6672 6588 6557 6679 6594 6822 6796 7177 7320 7591 7851 7901 7755 8085 8116 8158 8403 8516 8420 8183 7781 7589 7265 7207 7395 7152 7199 7393 7070 7247 7235 7349 7403 7457 7480 7336 7477 7434 7401 7287 7202 7341 7391 7206 7620 7678 7641 7531 7695 7423 7511 7269 7167 7248 7285 7173 7354 7451 8048 8301 8418 8350 8052 7883 7376 7161 7034 6714 6485 6395 6365 6457 6614 6724 6775 6875 6675 6672 6559 6452 6202 6236 6104 6113 6104 6172 6051 6101 6105 5903 6005 5953 6022 5960 6040 6176 6031 6171 6145 6087 6087 6125 6082 6041 6075 6121 6214 6196 6029 6227 6005 6296 6327 6220 6172 6210 6048 6222 6069 6001 6007 6132 6038 6147 6505 6404 6397 6411 6536 6425 6624 6849 6539 6614 6627 6618 6744 6618 6624 6429 6467 6424 6274 6528 6496 6602 6347 6534 6522 6574 6496 6397 6360 6402 6171 6192 6148 6325 6191 6307 6321 6303 6257 6113 6026 6186 6281 6234 6080 6097 5916 6251 6034 6016 5881 6054 6102 6175 6064 6094 6051 6040 5921 6042 6103 6050 5998 6069 6013 6011 6041 5858 5990 5990 6139 6058 5975 5885 6098 6216 6058 6102 6057 6257 6129 6202 6139 6106 6053 6111 6426 6419 6338 6416 6577 6503 6546 6458 6337 6321 6439 6463 6599 6660 6798 6920 7150 7395 7554 7863 8295 8498 8548 8613 8348 8362 7945 7746 7438 7436 7102 6849 6933 6745 6875 6852 7154 7030 7111 7131 7172 6920 6699 6848 6600 6527 6229 6244 6161 6259 5999 5915 5972 5895 5903 5980 5954 5889 5901 6062 6020 5969 6055 5942 6041 6094 6214 6335 6448 6278 6568 6642 6597 6425 6406 6278 6123 6191 6038 6065 6010 6094 6144 6132 6187 6413 6363 6208 6253 6256 6252 6098 6070 5945 5936 6045 5971 6064 5877 5936 6038 6138 6172 6166 6037 6097 6273 6159 6165 6137 6174 6052 6053 5909 6015 6145 6047 6152 6095 6247 6074 6132 6521 6426 6534 6366 6549 6650 6865 7064 7078 7403 7373 7617 7465 7263 7046 6736 6746 6373 6454 6502 6695 6534 6491 6405 6503 6595 6679 6769 6730 6558 6375 6486 6544 6366 6307 6224 6171 6313 6341 6071 6009 6200 6102 6231 6206 6002 6013 6073 6201 6129 6256 6152 6221 6178 6525 6346 6121 6332 6173 6051 6153 6157 6146 6175 6257 6306 6345 6589 6635 6852 6771 6961 6736 6817 6964 6701 6652 6886 7033 7146 7447 7674 7780 7961 7815 7621 7480 7286 7177 7073 6937 6798 6572 6587 6553 6743 6612 6765 6758 6714 6914 6894 6756 6509 6385 6220 6186 6250 6074 6213 5909 6010 6005 5924 6013 5995 6056 5978 5962 5789 6003 6051 5989 6072 6000 6146 6047 6126 6072 6095 6013 5930 5958 5922 5855 5942 5739 5814 5884 5852 5836 5894 6089 5959 6004 5822 5735 5722 5913 5992 5865 5914 5920 5935 5868 5843 5957 6026 5939 5793 5903 5807 5768 5948 5801 5827 5708 5917 6050 5918 5823 5905 5815 5810 5755 5887 5857 5948 5831 6047 5838 6020 6104 6035 5841 6064 6249 6165 6146 6261 6195 6152 6038 5847 6081 5967 5915 5908 5968 6088 6142 5926 6020 6188 6135 6009 6264 6171 6028 6099 6115 6026 6053 6192 5850 5890 5832 6066 5901 5861 5945 5859 5988 6022 6023 5929 5991 6200 5934 5995 5968 6284 6303 6396 6115 6247 6143 6151 5934 6048 6066 5988 5952 5939 5864 5965 6141 6049 6000 6009 6036 6024 6315 6275 6138 6071 6099 6185 6065 6204 6280 6241 6250 6582 6477 6660 6597 6798 6932 7178 7626 7882 8249 8397 8257 8220 7610 7535 7217 6861 6650 6655 6651 6617 6673 6549 6689 6856 6979 6961 7151 6840 6833 6856 6635 6460 6455 6455 6284 6280 6341 6200 6154 6280 6338 6515 6472 6448 6535 6552 6709 6730 6687 6681 6677 6760 6395 6219 6153 6349 6460 6384 6123 6505 6523 6460 6650 6770 6844 6897 6756 6686 6418 6241 6083 6090 5936 5952 5965 6034 5909 5934 5948 6074 6144 6124 6116 6077 6023 5864 5909 6016 5995 5990 5856 5893 5787 5803 5867 5858 5774 5909 5810 5811 5929 5917 5864 5877 5898 5979 5876 5822 5831 5940 5965 6028 5733 5751 5921 5848 5819 5843 5806 5895 5752 6001 5920 5843 5976 6008 5896 5940 5914 6043 6016 5913 5849 5907 5859 5881 5678 5967 5908 5859 5988 5932 5898 6021 5988 6182 5979 6010 6256 6111 6043 5955 6082 6101 6007 5924 5953 6005 5869 6031 6104 6001 6090 6052 6079 6120 6198 6033 6157 6173 6151 6147 6357 6473 6359 6439 6537 6622 6673 6627 6787 7062 7149 6957 6923 6655 6844 6752 6564 6618 6516 6311 6555 6336 6345 6679 6513 6413 6550 6676 6659 6751 6782 6797 6532 6472 6486 6344 6347 6308 6129 6147 5983 6201 6321 6200 6359 6425 6378 6523 6690 6760 6952 6948 7054 7245 7211 7273 7209 7005 6900 6691 6620 6339 6391 6305 6463 6457 6417 6294 6408 6508 6577 6585 6721 6644 6673 6561 6391 6283 6380 6399 6118 6132 6286 6088 6249 6163 6073 6136 6086 6038 6004 5946 5883 5949 6072 6088 5866 5856 5926 6045 6101 6101 6187 6137 6000 6083 6216 6319 6151 6282 6147 6162 6211 5886 6119 6113 5934 5930 6041 6012 6078 6025 6139 6370 6185 6297 6392 6424 6851 6838 6934 6717 6677 6522 6621 6562 6544 6405 6435 6299 6510 6466 6496 6515 6798 6772 6617 6764 6832 6706 6959 6686 6614 6517 6685 6385 6493 6478 6561 6418 6433 6418 6590 6449 6432 6525 6395 6299 6301 6382 6344 6261 6123 6161 6094 6317 6335 6367 6358 6671 6582 6529 6892 6674 6689 6797 6794 6883 6924 6942 6898 6775 6572 6733 6526 6475 6250 6414 6309 6418 6272 6257 6651 6313 6204 6493 6542 6502 6368 6163 6307 6145 6133 6099 5943 5979 6307 6106 5976 5907 5958 6129 5989 6130 6039 6026 6072 6033 5900 5949 5955 5987 5886 5876 5895 5977 5903 5762 5884 6015 5788 5875 6124 5999 5908 5953 5955 6183 5949 5881 6039 5966 5983 5987 5953 5909 5992 6029 6029 6387 6334 6379 6303 6476 6530 6439 6345 6466 6378 6312 6329 6139 5992 6079 6127 6091 5929 6037 6207 6278 6146 6286 6322 6387 6464 6545 6503 6691 6386 6282 6258 6276 6334 6182 6090 6159 6408 6377 6595 6682 6690 6668 6720 6657 6594 6453 6369 6447 6475 6286 6123 6080 6150 6180 5970 6038 5923 6007 6261 6085 6141 6212 6193 6053 5976 6076 5981 5994 5989 6084 6011 5988 5936 5917 5937 5919 5901 5714 5811 5818 5841 5910 5800 5870 5862 5817 5728 5761 5809 5632 5785 5718 5879 5890 5791 5768 5915 5621 5780 5717 5690 5966 5642 5766 5620 5658 5728 5675 5696 5797 5775 5828 5741 5888 5749 5684 5672 5645 5590 5682 5873 5672 5755 5770 5887 5856 5801 5926 5815 5733 5735 5819 5935 5943 5825 5948 5906 5895 5882 5901 5883 5886 6072 5949 5884 6124 5919 5938 5924 5837 5819 5939 6007 5831 5911 5875 5895 5921 5920 6023 5871 5884 6029 6106 6070 5928 5895 6074 6028 6117 6233 6203 6167 6128 6195 6435 6286 6094 6429 6475 6356 6448 6348 6361 6254 6089 6073 6096 6128 5980 6230 6254 6118 6101 6216 6165 5950 6114 6075 6000 6115 6196 5947 5970 6069 6069 6077 5881 5781 5806 6020 5774 5890 5824 5960 5958 6058 5920 5896 5785 5903 5834 5806 5874 5888 5765 5843 5784 5938 5826 5779 5778 5754 5890 6125 5938 5759 5876 6066 5807 5863 5902 5973 5985 6199 5998 5992 6087 6177 6034 6029 5896 5922 6078 5958 5938 5896 5881 5780 5908 5829 5674 5699 5987 5790 5940 5725 5785 5867 5880 5927 6053 5971 6083 5965 5875 5684 5847 5651 5675 5957 5849 5934 5920 5896 5856 5704 5718 5740 5841 5659 5767 5904 5618 5735 5727 5662 5974 5990 5758 5845 5927 6002 6066 5945 6034 6080 5926 5910 6114 6049 5985 6116 6116 6086 6031 6088 6285 6261 6336 6210 6169 6231 6397 6656 6280 6325 6451 6456 6480 6609 6461 6358 6157 6444 6323 6351 6312 6384 6428 6446 6523 6783 6999 6917 6910 6695 6768 6516 6464 6464 6360 6352 6302 6454 6370 6380 6502 6343 6605 6749 6518 6786 6912 6828 6942 6921 6741 6546 6643 6418 6370 6294 6414 6239 6089 6020 6079 6149 6159 5913 6316 6167 6230 6133 6049 6220 6207 6177 6025 5878 5912 6117 6078 5886 5979 5902 5955 6224 5902 5959 5965 6030 5962 5995 6033 5817 6150 6019 5992 6226 6051 6143 6091 6198 6095 6064 5964 5933 5989 5906 5742 5899 5908 5829 5826 5984 5980 6054 5904 6150 6121 6167 6107 6357 6428 6507 6588 6628 6556 6599 6578 6736 6553 6703 6533 6189 6183 6256 6085 6068 5948 6101 6092 6000 5989 6156 6162 6178 6324 6198 6343 6276 6238 6267 6234 6308 6436 6285 6081 6312 6310 6497 6271 6360 6276 6233 6269 6083 6071 6064 6044 5967 6056 5877 5911 5977 6048 6209 6197 6227 6331 6256 6627 6590 6577 6487 6483 6556 6536 6645 6395 6422 6514 6321 6330 6161 6348 6237 6207 6075 6128 6059 6097 5994 6125 6285 6228 6083 6176 6234 6131 6428 6342 6244 6574 6457 6629 6563 6553 6542 6318 6499 6280 6283 6178 6236 6220 6263 6539 6476 6324 6376 6498 6533 6616 6621 6616 6699 6694 6797 6530 6639 6718 6698 6889 6901 6771 6607 6623 6508 6509 6268 6535 6458 6204 6212 6059 6323 6337 6150 6109 6067 6133 6031 6058 6249 6123 6109 6176 6013 6062 5926 5883 5934 6004 5955 5835 5843 5907 5809 5766 5819 5813 5676 5928 5888 5791 5640 5729 5802 5694 5741 5738 5707 5891 5644 5758 5802 5621 5763 5686 5839 5740 5742 5899 5826 5837 5866 5754 5774 5766 5746 5849 5685 5667 5720 5783 5975 5743 5769 5941 5882 5709 5804 5906 5792 5775 5734 5742 5770 5830 5827 5796 5770 5912 5771 5854 5757 5697 5861 5825 5926 5800 5884 5802 5789 5846 5703 5746 5870 5863 5808 5809 5717 5816 5941 5791 5909 5895 5894 6034 5809 5843 6028 6084 5788 5700 6040 6070 6026 6122 6235 6048 6019 6165 6191 6253 6076 5991 6012 6036 6001 5971 6095 6062 5836 5967 5964 5955 5839 6150 6105 6325 6055 6028 6089 6105 6151 6234 6117 6186 6032 6360 6444 6268 6414 6409 6274 6234 6174 6252 6151 6179 6037 6024 6082 6094 6057 6156 6029 6205 6323 6329 6417 6543 6647 6712 6919 6673 6697 6918 6835 7171 7007 7001 6738 6624 6822 6779 6810 6668 6541 6429 6436 6449 6425 6108 6159 6237 6291 6257 6181 6235 6458 6242 6412 6333 6262 6187 6220 6248 6130 6376 6220 6018 5988 5976 5924 5991 5749 5885 5878 5866 5843 5759 5701 5766 5888 5654 5681 5734 5718 5711 5835 5812 5676 5727 5868 5926 5800 5890 5874 5854 5863 6010 5788 5806 5864 5947 5982 6151 5740 5848 5990 5976 5966 5917 6004 5909 5876 5901 5885 5911 5753 5942 5927 6040 5770 5925 5741 5636 5991 5874 5880 6010 5979 5761 5765 5791 5617 5776 6053 5824 5847 5626 5712 5631 5846 5750 5884 5600 5783 5579 5781 5723 5801 5872 5954 5834 5773 5771 5790 5827 5819 5973 6079 5751 5905 5836 6018 6059 6204 6194 6136 6229 6238 6354 6378 6346 6523 6335 6242 6286 6398 6273 6229 6071 6121 6076 6042 5717 5849 5988 5901 6016 6028 6065 6039 6132 6042 5867 6092 6193 6028 5876 6139 6184 6084 6093 5856 5888 5894 5759 5849 5950 5603 5677 5731 5685 5794 5881 5685 5866 5837 5800 5620 5700 5892 5843 5904 5885 5888 6028 6119 6056 6032 5883 5979 6107 6038 6156 6134 6274 6289 6400 6339 6326 6321 6270 6383 6306 6190 6585 6150 6207 6249 6102 6187 6367 6139 6102 6179 6258 6131 6132 6121 6233 6223 6459 6417 6392 6351 6472 6546 6424 6527 6440 6463 6420 6122 6215 6211 6363 6106 6195 6248 5936 6125 6253 6257 6395 6301 6485 6467 6442 6367 6390 6384 6115 6214 6117 5965 6077 5914 6027 5832 5902 6069 5966 5894 5986 5920 6153 6078 6200 6150 6064 6276 6280 6278 6511 6396 6336 6320 6495 6417 6476 6280 6053 6183 6249 6123 6013 5783 5789 5768 5952 5863 5871 5950 5959 5695 5740 5916 6152 5999 5839 5682 5906 5723 5926 5838 5904 5941 6046 5862 5722 5845 5818 5712 5714 5705 5771 5788 5798 5772 5639 5801 5644 5619 5589 5773 5753 5695 5660 5658 5733 5634 5661 5651 5454 5819 5841 5779 5778 5537 5582 5625 5730 5605 5644 5606 5700 5662 5782 5647 5574 5721 5759 5792 5761 5722 5718 5670 5650 5935 5764 5675 5885 5762 5796 5727 5825 5842 5787 5887 5850 5837 5709 5863 6003 5882 5907 5837 5794 6190 6034 6028 6212 6069 6344 6213 6247 6405 6211 6188 6275 6187 6261 6139 6211 6142 6056 5989 6207 6208 6077 6039 5925 5936 6029 5849 6020 6150 5985 6001 6111 5776 6031 6046 6029 6090 6104 6101 6102 6084 6088 6054 6141 6069 5897 5926 5862 5969 5852 5770 5873 5800 5751 6023 5788 5759 5878 5754 5911 5821 5737 5780 5848 5732 5605 5756 5853 5840 5699 5848 5746 5754 5613 5833 5775 5760 5769 5696 5632 5747 5865 5955 5903 5758 5997 5845 5830 5759 5812 5726 5694 5979 5978 6098 6084 5953 5954 5920 5902 5959 6004 6126 6070 6082 6223 6221 6096 6063 6255 6253 6068 6144 6104 6075 6061 6072 6002 6062 6100 6104 6059 6177 5971 6168 5926 5978 5850 6034 5808 5959 5789 5950 5903 5951 5858 5875 5974 5941 5919 5843 5919 5889 5806 5817 5814 5962 5971 5842 5799 5848 5819 5796 5802 5826 5934 5836 5794 5816 5802 5610 5761 5766 5707 5701 5659 5794 5776 5692 5753 5677 5612 5669 5876 5546 5857 5665 5635 5610 5849 5854 5827 5702 5571 5729 5911 5719 5740 5761 5822 5732 5837 5713 5671 5659 5556 5581 5703 5592 5627</intensities>
			</dataPoints>
			<nonAmbientPoints type="Temperature" unit="K">
[...]
			</nonAmbientPoints>
		</scan>
	</xrdMeasurement>
</xrdMeasurements>