File: powder_X-ray_diffraction/variable-temperature_experiments/NaNbO2F2/raw_data/160°C.xrdml
<?xml version="1.0" encoding="UTF-8"?>
<xrdMeasurements xmlns="http://www.xrdml.com/XRDMeasurement/1.7" xmlns:xsi="http://www.w3.org/2001/XMLSchema-instance" xsi:schemaLocation="http://www.xrdml.com/XRDMeasurement/1.7 http://www.xrdml.com/XRDMeasurement/1.7/XRDMeasurement.xsd" status="Completed">
	<comment>
		<entry>Configuration=XRK900, Owner=User-1, Creation date=12/01/2015 16:52:44</entry>
		<entry>Goniometer=Theta/Theta; Minimum step size 2Theta:0.0001; Minimum step size Omega:0.0001</entry>
		<entry>Sample stage=AP XRK-900 with z-axis; Minimum step size Z:0.001</entry>
		<entry>Diffractometer system=EMPYREAN</entry>
		<entry>Measurement program=C:\PANalytical\Data Collector\Programs\Gwen\NaNbO2F2-Lent.xrdmp, Identifier={26D14ECE-D3C8-438C-91CA-8651EAF68C7D}</entry>
		<entry>Batch program=C:\PANalytical\Data Collector\Programs\Gwen\Thermodiff-Ouail.xrdmp, Identifier={9701CF17-19F5-4DD4-A8E1-7279D1FD2F5E}</entry>
	</comment>
	<sample type="To be analyzed">
		<id></id>
		<name></name>
		<preparedBy></preparedBy>
	</sample>
	<xrdMeasurement measurementType="Scan" status="Completed" sampleMode="Reflection">
		<comment>
			<entry>PHD Lower Level = 4.02 (keV), PHD Upper Level = 12.07 (keV)</entry>
		</comment>
		<usedWavelength intended="K-Alpha 1">
			<kAlpha1 unit="Angstrom">1.5405980</kAlpha1>
			<kAlpha2 unit="Angstrom">1.5444260</kAlpha2>
			<kBeta unit="Angstrom">1.3922500</kBeta>
			<ratioKAlpha2KAlpha1>0.5000</ratioKAlpha2KAlpha1>
		</usedWavelength>
		<incidentBeamPath>
			<radius unit="mm">240.00</radius>
			<xRayTube id="1010048" name="Empyrean Cu LFF HR (9430 033 7310x) DK420743">
				<tension unit="kV">45.0</tension>
				<current unit="mA">30.0</current>
				<anodeMaterial>Cu</anodeMaterial>
				<focus type="Line">
					<length unit="mm">12.0</length>
					<width unit="mm">0.4</width>
					<takeOffAngle unit="deg">6.0</takeOffAngle>
				</focus>
			</xRayTube>
			<sollerSlit id="21010001" name="Soller slits 0.02 rad.">
				<opening unit="rad">0.0200</opening>
			</sollerSlit>
			<mask id="22030010" name="Fixed mask 20 mm">
				<width unit="mm">20.00</width>
			</mask>
			<antiScatterSlit id="22010003" name="Fixed slit 1Â°" xsi:type="fixedAntiScatterSlitType">
				<height unit="mm">1.52</height>
			</antiScatterSlit>
			<divergenceSlit id="22010012" name="Programmable divergence slit" xsi:type="fixedDivergenceSlitType">
				<distanceToSample unit="mm">140.00</distanceToSample>
				<angle unit="deg">0.5</angle>
			</divergenceSlit>
		</incidentBeamPath>
		<diffractedBeamPath>
			<radius unit="mm">240.00</radius>
			<antiScatterSlit id="22090010" name="AS slit 8.0 mm (PIXcel)" xsi:type="fixedAntiScatterSlitType">
				<height unit="mm">8.00</height>
			</antiScatterSlit>
			<sollerSlit id="21010001" name="Soller slits 0.02 rad.">
				<opening unit="rad">0.0200</opening>
			</sollerSlit>
			<filter id="20030001" name="Large beta-filter Nickel">
				<material>Ni</material>
				<thickness unit="mm">0.020</thickness>
			</filter>
			<detector id="7010019" name="PIXcel1D-Medipix3 detector" xsi:type="rtmsDetectorType">
				<phd unit="%">
					<lowerLevel>25.0</lowerLevel>
					<upperLevel>75.0</upperLevel>
				</phd>
				<mode>Scanning</mode>
				<activeLength unit="deg">3.3482</activeLength>
			</detector>
		</diffractedBeamPath>
		<scan appendNumber="0" mode="Continuous" scanAxis="Gonio" status="Completed">
			<header>
				<startTimeStamp>2022-05-14T16:39:21+02:00</startTimeStamp>
				<endTimeStamp>2022-05-14T19:39:46+02:00</endTimeStamp>
				<author>
					<name>User</name>
				</author>
				<source>
					<applicationSoftware version="5.5a">Data Collector</applicationSoftware>
					<instrumentControlSoftware version="8.1b 20190506">EMPYREAN</instrumentControlSoftware>
					<instrumentID>0000000011159748</instrumentID>
				</source>
			</header>
			<dataPoints>
				<positions axis="2Theta" unit="deg">
					<startPosition>9.99846514</startPosition>
					<endPosition>99.99342261</endPosition>
				</positions>
				<positions axis="Omega" unit="deg">
					<startPosition>4.99923257</startPosition>
					<endPosition>49.99671130</endPosition>
				</positions>
				<positions axis="Z" unit="mm">
					<commonPosition>8.912</commonPosition>
				</positions>
				<commonCountingTime unit="seconds">386.070</commonCountingTime>
				<intensities unit="counts">7726 7751 7891 7728 7803 7960 7719 7767 8023 7944 8142 7923 7755 8162 7869 8044 7960 7789 7705 7927 7955 8034 7804 7754 7757 7656 7983 7830 7847 7921 7785 7879 8040 7942 7671 7617 7916 7776 7806 7767 7544 7807 7909 8011 7937 7729 7545 7730 7756 7824 8028 7814 7581 7591 7828 7892 7956 7850 7730 7700 7751 7709 7718 7794 7889 8028 8024 8054 8313 8400 8435 8399 8608 8236 8340 8436 8629 8621 8710 8837 8849 9116 9275 9511 9802 10303 11129 12211 13654 16003 18724 23516 31493 44820 61144 74742 80628 74864 61915 46009 32231 22026 15659 11975 10211 9336 8727 8654 8827 8494 8416 8248 8241 8017 7950 8002 7904 8197 8110 8044 7905 8027 7993 7939 8056 7994 7805 7820 7856 7918 7919 7989 8040 7817 8189 8116 8216 8117 8054 8054 8216 8119 7989 8103 8177 8092 8241 8177 8024 7969 8033 8174 8086 7928 8098 7921 8114 8193 8103 8177 8192 8217 8283 8194 8161 8237 8049 8222 8218 8329 8294 8168 8225 8097 8222 8255 8217 8227 8181 8238 8075 8102 8163 8275 8182 8274 8410 8215 8217 8047 8228 8334 8115 7982 8284 8341 8178 8120 8106 8252 8224 8138 8402 8268 8273 8195 8194 8246 8332 8187 8310 8140 8129 8020 8029 8061 8201 8153 8238 8047 8123 8133 8254 8094 8050 8044 7942 8140 7995 7922 8077 8228 7946 8131 8096 8155 8082 8120 8330 8111 8098 7976 7994 8139 8105 8213 8022 8056 7983 7982 7866 8034 8168 7861 7916 7869 7859 7922 7976 7997 7983 8098 7945 8079 7903 8131 8055 8006 7981 8105 8021 7729 7882 8052 7998 7798 7961 7945 8117 8099 8087 8035 8174 8334 8163 8249 8276 8108 8143 8058 7876 8070 7972 7983 8029 7873 7994 7897 7850 7912 7976 8032 7854 7933 8061 7900 7896 7917 7963 8109 8134 8143 7944 7967 8178 8119 7922 7802 8061 8026 7991 8095 8072 8215 8093 7871 8081 7963 8005 7983 8091 7993 7962 7963 7990 8089 7949 8075 8061 8230 8484 8726 8935 9217 9548 9770 9806 9350 9319 9023 8671 8499 8307 8034 7873 7862 8023 7963 7957 7896 7950 7942 7764 7822 7777 7945 7837 7804 8001 7878 8059 7985 7883 7967 7890 7776 7836 7774 7820 7828 7693 7896 7912 7737 7882 7842 7923 7823 7666 7760 7786 7768 7670 7953 7812 7578 7820 7806 7687 7739 7809 7695 7883 7592 7889 7641 7968 7814 7671 7826 7791 7747 7903 7793 7879 7784 7767 7703 7619 7647 7804 7732 7776 7834 7712 7735 7806 7720 7697 7507 7844 7789 7555 7806 7758 7827 7983 7811 7936 7742 7815 7787 7725 8034 8005 7659 7742 7707 7637 7718 7757 7556 7923 7673 7680 7796 7863 7885 7976 7842 7854 8066 7700 7755 7816 7555 7831 7864 7551 7794 7649 7592 7762 7911 7666 7561 7644 7839 7757 7473 7596 7503 7637 7500 7698 7838 7798 7494 7667 7831 7542 7774 7801 7798 7771 7832 7868 7797 7750 7488 7754 7794 7708 7791 7668 7708 7528 7609 7684 7583 7546 7625 7794 7953 7752 7792 8110 8238 8159 8162 8179 8092 7998 8011 7808 7722 7769 7617 7620 7633 7680 7515 7496 7574 7588 7619 7641 7570 7609 7658 7592 7643 7631 7425 7474 7548 7605 7683 7602 7578 7699 7553 7510 7632 7560 7475 7637 7624 7479 7507 7415 7665 7573 7465 7450 7300 7374 7613 7539 7319 7303 7534 7394 7516 7354 7387 7385 7449 7282 7347 7553 7555 7539 7396 7438 7422 7651 7587 7370 7528 7559 7456 7421 7321 7366 7494 7261 7635 7352 7410 7453 7460 7588 7755 7673 7761 7653 7475 7483 7551 7497 7450 7370 7420 7421 7372 7241 7226 7444 7340 7260 7432 7200 7550 7404 7244 7427 7308 7386 7496 7362 7484 7465 7355 7323 7366 7315 7320 7350 7340 7135 7183 7159 7487 7241 7241 7198 7326 7244 7209 7363 7362 7382 7378 7407 7454 7256 7273 7328 7316 7306 7187 6987 7411 7342 7357 7228 7298 7302 7184 7275 7199 7096 7116 7237 7268 7241 7540 7521 7208 7296 7086 7381 7368 7195 7367 7270 7261 7337 7415 7240 7245 7370 7291 7426 7388 7491 7602 7640 7557 7803 7611 7658 7495 7627 7767 7605 7690 7518 7787 7638 7526 7507 7748 7567 7682 7577 7558 7557 7529 7589 7722 7753 7597 7743 7731 7766 7791 8018 7916 7986 8032 8308 8431 8467 8342 8594 8649 8908 9248 9754 10229 11449 12963 15337 18710 24675 33987 47358 63453 81376 94719 94898 85782 75763 64821 51372 37662 26864 19229 14454 12019 10790 9891 9689 9256 8872 8668 8728 8408 8120 7996 8063 7964 7799 7852 7789 7912 7864 7867 7985 7901 7749 7754 7618 7625 7542 7615 7545 7714 7567 7543 7593 7628 7802 7506 7614 7583 7415 7400 7434 7606 7668 7638 7540 7497 7674 7537 7502 7596 7625 7649 7334 7590 7454 7372 7440 7423 7496 7432 7662 7464 7412 7337 7417 7464 7438 7511 7485 7426 7503 7637 7403 7358 7514 7409 7539 7523 7540 7438 7499 7396 7467 7427 7532 7359 7353 7418 7456 7406 7511 7573 7473 7552 7328 7430 7572 7281 7376 7285 7433 7406 7401 7321 7377 7538 7501 7556 7561 7649 7457 7464 7327 7537 7483 7546 7572 7460 7473 7513 7386 7524 7345 7378 7383 7544 7490 7512 7627 7482 7482 7471 7401 7422 7390 7439 7556 7709 7591 7393 7573 7505 7563 7468 7667 7417 7622 7523 7721 7701 7430 7742 7504 7490 7533 7516 7474 7500 7329 7519 7404 7425 7529 7573 7329 7341 7535 7418 7382 7399 7476 7502 7477 7345 7374 7448 7569 7433 7441 7644 7481 7605 7545 7407 7470 7649 7863 7848 7708 7732 7865 8119 8181 8723 9148 9899 11581 13916 18314 24603 31040 34089 32700 29957 26930 24388 21533 17897 14328 11310 9983 8842 8199 8059 7959 7844 7749 7784 7723 7490 7450 7733 7462 7462 7366 7396 7538 7403 7383 7642 7353 7465 7456 7544 7507 7438 7342 7535 7454 7314 7446 7353 7612 7463 7518 7475 7642 7516 7655 7560 7648 7743 7556 7591 7623 7563 7560 7664 7536 7528 7594 7482 7622 7660 7628 7462 7485 7518 7701 7503 7679 7666 7715 7550 7745 7549 7743 7687 7876 7880 7746 7950 8075 8166 8291 8493 8997 9873 11624 14249 18273 23980 28704 29740 28371 25008 23130 21495 19308 16595 13547 11275 9830 9324 9172 8888 8795 8887 9016 9621 10090 11384 13424 17136 23350 31095 38260 38061 33107 29829 27893 26101 22012 17526 14230 11540 9757 9037 8444 8435 8257 8085 7904 7956 8180 8191 8029 8048 7866 7480 7769 7681 7751 7585 7573 7600 7521 7523 7495 7490 7311 7451 7350 7374 7456 7472 7374 7357 7484 7577 7512 7509 7308 7451 7483 7382 7454 7471 7397 7371 7414 7257 7259 7464 7288 7475 7310 7286 7328 7541 7276 7239 7192 7530 7454 7602 7555 7578 7355 7340 7367 7347 7316 7249 7244 7342 7353 7539 7314 7487 7500 7485 7582 7459 7578 7686 7532 7382 7289 7298 7400 7372 7239 7325 7267 7379 7138 7617 7472 7198 7194 7443 7344 7284 7284 7245 7396 7169 7158 7353 7229 7230 7277 7446 7296 7321 7411 7439 7322 7119 7218 7284 7335 7329 7488 7337 7273 7464 7355 7269 7241 7154 7412 7401 7535 7299 7324 7485 7476 7439 7341 7406 7503 7277 7112 7272 7126 7335 7450 7385 7326 7312 7272 7342 7120 7327 7236 7399 7201 7124 7069 7094 7352 7403 7236 7097 7330 7291 7223 7207 7249 7185 7318 7146 7098 7255 7031 7232 7291 7287 7116 7134 7253 7055 7006 7234 7307 7146 6997 7183 7205 7202 7070 7244 7178 7219 7110 7241 7085 6973 7103 7153 7234 7298 7299 7185 7077 7249 7295 7159 6987 7070 7375 7341 7346 7264 7333 7344 7509 7534 7459 7369 7524 7526 7509 7488 7151 7395 7394 7579 7456 7709 7586 7413 7458 7558 7497 7613 7356 7570 7317 7388 7441 7507 7392 7470 7439 7383 7423 7473 7385 7318 7272 7413 7495 7438 7431 7534 7599 7586 7574 7439 7488 7506 7514 7642 7757 7795 7792 7944 7909 8318 8258 8488 8471 8647 8894 8888 9190 9710 9984 10675 11067 12002 13484 15748 19257 25316 34866 50110 66741 82548 90257 86920 77799 69357 63138 58255 52044 43074 33504 24784 18690 14712 12591 11302 10546 10095 9411 9098 8872 8585 8493 8277 8323 8014 7895 8003 7854 7716 7747 7736 7763 7735 7788 7835 7880 8189 8116 8473 8871 9134 8858 8593 8561 8253 8413 8158 8285 7849 7797 7804 7590 7497 7552 7760 7595 7593 7751 7656 7657 7754 7797 7787 7851 7807 8413 8377 8441 8728 9019 9464 10974 13245 17540 24861 33957 40022 39183 33550 28453 26258 26464 25623 22835 18551 14798 11768 10131 9414 8670 8749 8986 9235 9631 10267 11761 13045 14160 15249 16098 16719 17084 16210 14777 13982 13190 12539 12056 10689 9702 9049 8539 8321 7928 7622 7646 7691 7472 7603 7344 7239 7377 7246 7308 7181 7178 7131 7391 7088 7196 7177 7237 6997 7308 7324 7040 7206 7259 7093 7235 7100 7240 7261 7239 7193 7048 6978 7077 7112 6957 6962 6946 7141 6970 7094 7007 7056 7079 7156 6995 7036 7069 7030 7022 7049 6991 7067 7162 7198 7069 6995 6920 7069 6965 7127 6922 7130 6956 7046 6994 6915 7064 7067 7071 6916 7146 7097 7066 7038 7044 6991 7014 7032 7016 6931 6950 6889 6929 7044 6958 6914 7119 7079 6874 6862 6905 6805 6895 6955 7030 6970 7032 7037 7140 6952 7042 6962 6906 7058 6907 6737 6978 6880 6769 6914 6845 6828 6916 6856 6871 6842 6869 7055 6983 6667 6735 6921 7097 6905 6757 6855 6987 6756 6837 6782 6887 6821 6936 6863 6959 6925 6928 7012 7027 6907 6895 6842 6851 6934 6694 6763 6767 6814 6836 6741 6950 6962 6815 6911 6763 6585 6914 6755 6808 6762 6664 6702 6920 6765 6894 6791 6819 6871 6817 6803 6669 6693 6809 6927 6855 6756 6881 6890 6810 6760 6712 7013 6878 6793 6959 6821 6735 6958 6905 6952 6885 6801 6731 6797 6984 6940 6898 6874 6758 6900 6946 6765 6772 6924 6906 6861 6733 6900 6870 6904 6988 6759 7039 6977 7000 6946 6996 6929 6884 7054 6933 6765 6837 7032 6980 6864 6945 7092 7000 6834 6890 6819 6699 6750 6931 6949 6875 7021 7014 6966 7144 6907 6930 7056 7036 6895 6990 6986 7069 7313 7293 7240 7179 7227 7459 7521 7953 7993 8694 9464 11177 13486 15903 17358 17182 17759 19983 22898 24590 23682 20494 17465 15757 15018 14875 14336 12644 10798 9593 8549 8067 7673 7692 7374 7319 7230 7095 7140 7090 7121 7059 7114 7109 7156 6760 7026 7043 6934 6918 7059 6974 6936 7008 7075 7074 7096 6880 7113 6972 7154 7044 7207 7350 7275 7375 7986 8361 9137 10379 12129 13513 14807 15062 14388 12857 11792 11229 11479 11267 10906 10078 8926 8456 7983 7625 7514 7716 7700 7678 7899 7847 7658 7737 7591 7557 7469 7360 7627 7462 7588 7296 7349 7625 7840 8574 9535 11296 13015 14061 13273 12232 10769 10193 10184 10673 10481 9994 9284 8382 7797 7243 7101 7040 6983 6878 6999 6865 6907 6897 6759 6829 6839 6759 6789 6744 6864 6820 6617 6685 6742 6800 6896 6848 6719 6556 6824 6714 6796 6842 7018 6939 6818 6878 6739 6863 7105 7186 7341 7797 8502 9165 10429 11416 11666 11168 10487 10033 9597 9611 9582 9554 8896 8621 8234 7697 7329 7302 7513 7706 7632 7465 7383 7213 7245 7063 6983 7021 6944 7060 6732 6705 6684 6458 6701 6661 6681 6724 6645 6630 6713 6547 6565 6532 6624 6716 6701 6754 6629 6614 6526 6639 6631 6699 6633 6597 6629 6627 6633 6686 6466 6529 6631 6545 6626 6495 6524 6549 6625 6543 6505 6669 6529 6485 6631 6633 6523 6505 6602 6615 6617 6600 6544 6509 6572 6621 6364 6543 6647 6595 6515 6654 6623 6558 6524 6593 6763 6615 6525 6822 6803 6741 6668 6683 6737 6623 6595 6644 6710 6656 6592 6647 6875 6659 6605 6877 6643 6828 7054 7542 8060 8956 9887 9940 9500 8852 8382 8286 7982 8344 8331 8334 7740 7303 6859 6820 6634 6771 6702 6616 6599 6710 6550 6663 6653 6493 6786 6661 6470 6469 6510 6634 6524 6567 6492 6509 6396 6568 6786 6578 6613 6561 6491 6559 6469 6459 6562 6596 6630 6431 6565 6543 6500 6662 6594 6412 6470 6492 6500 6516 6522 6586 6552 6635 6461 6452 6616 6450 6522 6529 6539 6538 6663 6378 6660 6630 6561 6903 6739 6883 7022 7059 7242 7382 7495 7619 7608 7343 7324 7412 7472 7821 8040 8630 9428 10522 11294 11955 11926 11711 11113 11087 11351 11800 11811 11517 10723 9830 9287 8720 8446 8308 8073 7637 7538 6997 6933 6858 6804 6761 6661 6731 6635 6589 6790 6631 6664 6638 6666 6654 6682 6614 6532 6641 6517 6691 6589 6606 6692 6434 6657 6634 6568 6564 6435 6621 6455 6487 6487 6513 6483 6435 6364 6416 6448 6614 6574 6569 6364 6490 6305 6441 6460 6430 6618 6453 6478 6402 6489 6360 6369 6358 6563 6427 6322 6505 6534 6420 6346 6436 6529 6447 6560 6526 6406 6535 6520 6635 6354 6429 6281 6401 6560 6503 6553 6516 6750 6492 6571 6576 6594 6710 6551 6600 6666 6638 6646 6963 7104 7524 7852 8623 9325 9617 9217 8437 7927 7720 7545 7926 7877 8079 7789 7149 7038 6790 6725 6475 6554 6435 6538 6522 6606 6596 6551 6602 6246 6525 6562 6559 6433 6579 6516 6560 6488 6346 6500 6314 6485 6561 6454 6521 6510 6491 6500 6473 6561 6427 6404 6627 6558 6532 6382 6241 6369 6618 6520 6343 6324 6489 6527 6667 6498 6388 6497 6471 6485 6625 6487 6614 6566 6830 6841 6945 7157 7437 7622 7487 7466 7322 7429 7470 7717 8117 8451 9218 9633 9670 9470 8852 8349 8225 8181 8112 8162 8103 7781 7637 7311 6769 6659 6680 6745 6665 6595 6508 6423 6561 6524 6494 6423 6546 6405 6572 6398 6451 6498 6525 6494 6481 6419 6550 6419 6572 6474 6555 6447 6448 6552 6466 6471 6574 6573 6457 6637 6637 6631 6881 7157 7392 7757 8083 7999 8287 8167 8249 8406 9061 9872 10886 11727 11996 11785 11556 11127 11167 11198 11296 11005 10728 10205 9649 8866 8571 8385 8343 7889 7556 7212 7074 6763 6707 6652 6708 6671 6700 6592 6488 6774 6587 6556 6423 6531 6437 6617 6483 6390 6469 6383 6318 6497 6404 6424 6403 6471 6329 6358 6354 6330 6422 6572 6340 6392 6246 6520 6481 6387 6652 6578 6474 6429 6318 6423 6365 6398 6436 6459 6438 6460 6655 6515 6527 6402 6291 6355 6312 6477 6612 6398 6387 6482 6371 6376 6383 6568 6461 6360 6547 6295 6411 6437 6459 6369 6412 6419 6513 6249 6321 6518 6389 6333 6252 6363 6464 6289 6289 6375 6413 6458 6489 6414 6415 6256 6485 6387 6239 6206 6413 6202 6435 6386 6254 6499 6267 6349 6502 6340 6426 6384 6440 6322 6273 6260 6318 6306 6302 6518 6480 6451 6315 6280 6417 6409 6491 6260 6443 6417 6501 6329 6386 6452 6348 6422 6508 6465 6442 6557 6509 6476 6381 6432 6520 6392 6237 6283 6442 6613 6507 6490 6488 6451 6285 6377 6283 6334 6160 6336 6358 6434 6744 6727 6741 6887 7129 7312 7606 7897 8051 7979 7640 7560 7101 7217 7010 7069 7302 7188 7319 6848 6806 6751 6632 6474 6363 6414 6361 6314 6351 6363 6369 6478 6457 6291 6286 6332 6467 6196 6425 6542 6438 6555 6408 6479 6440 6608 6697 6767 6555 6516 6357 6457 6665 6595 6602 6520 6552 6671 6460 6553 6475 6504 6357 6444 6461 6457 6418 6424 6526 6730 6456 6568 6648 6539 6778 6884 6893 6754 7098 7069 7409 7501 7742 8496 9188 10109 11479 12666 13522 13111 12462 11267 10205 9546 9300 9623 10081 9931 9844 9449 8804 8094 7548 7126 7040 6775 6886 6653 6475 6374 6537 6458 6368 6418 6416 6564 6649 6380 6425 6431 6396 6510 6316 6273 6246 6419 6487 6312 6372 6405 6442 6445 6352 6556 6264 6452 6482 6364 6367 6293 6347 6247 6448 6527 6321 6330 6435 6515 6433 6278 6288 6475 6262 6308 6190 6329 6339 6299 6365 6345 6420 6248 6396 6318 6415 6424 6491 6435 6531 6392 6364 6445 6468 6440 6409 6403 6332 6420 6458 6455 6517 6513 6585 6594 6923 6653 6736 6836 6848 7078 6927 6959 7039 7409 7641 7922 8605 9855 11798 14693 17846 20005 19987 18958 16454 14107 12369 11601 11953 13009 14112 13820 13840 12347 10971 9791 8586 7858 7396 7231 7356 7243 7163 7026 6802 6682 6854 6725 6742 6727 6650 6583 6477 6588 6475 6604 6513 6682 6582 6558 6424 6506 6481 6526 6310 6363 6298 6569 6408 6435 6626 6469 6460 6417 6473 6560 6710 6401 6359 6213 6387 6341 6423 6287 6177 6465 6383 6405 6408 6354 6518 6371 6385 6406 6411 6479 6677 6574 6420 6398 6389 6282 6228 6578 6490 6428 6437 6604 6488 6735 6599 6326 6594 6599 6663 6833 6881 6945 6972 7369 7505 8099 8614 8896 9340 9739 9813 10501 11045 12145 13541 13997 13185 11740 10413 9695 9028 9169 9378 9762 10032 9725 9308 8549 8023 7608 7370 7124 7215 6864 6797 6686 6833 7064 6869 7012 6799 6999 7052 6943 6988 7041 7138 6933 6933 7056 7276 7221 7343 7582 7991 8221 8881 9731 10848 12552 14211 16674 17876 18585 17814 16659 14812 13515 12457 12180 12561 12730 13070 13068 12537 11710 10298 9334 8871 8072 7520 7370 7262 7047 7078 6907 6822 6712 6760 6865 6555 6530 6888 6673 6776 6734 6869 7061 7201 7374 7723 7827 8068 8070 7825 7730 7696 7751 7775 7781 7924 7905 7558 7513 7495 7387 7512 7226 7070 7070 7115 7045 6900 7065 7009 7058 7038 6834 6978 7010 7201 7198 7107 7388 7617 7844 7892 8371 9259 10374 11847 13514 15284 15920 15488 14662 13330 12189 11461 11499 12071 13219 14667 15283 14569 13172 11776 10188 9267 8654 8464 8541 8775 8735 8627 8280 7849 7280 7035 6996 6855 6811 6841 6864 6853 6945 6934 6918 6889 6845 6941 6844 6820 7162 7066 7228 7505 7582 7842 8378 9317 10530 12087 14100 16784 18876 19409 18350 16411 14118 12432 11155 10977 11651 12401 13231 13325 13110 11818 10345 9493 8411 7918 7695 7307 7031 7059 7073 6801 6897 6692 6498 6711 6780 6614 6664 6593 6693 6544 6743 6608 6712 6750 6802 6846 6920 6990 7112 7272 7346 7660 7703 7673 7762 8073 8375 8437 8724 8506 8379 8001 8227 7881 8065 8191 8761 9189 9622 9877 9938 9629 9118 8737 8465 7930 7737 7713 7919 7824 7959 7749 7571 7476 7295 6912 6773 6852 6734 6767 6369 6568 6403 6629 6597 6432 6588 6559 6550 6526 6449 6630 6551 6641 6409 6485 6464 6568 6460 6474 6534 6429 6445 6471 6356 6445 6344 6456 6449 6594 6524 6636 6493 6461 6612 6573 6471 6664 6603 6692 6688 6789 6890 7030 7055 7738 8294 9159 10734 12548 14538 15329 14314 13199 11952 10917 10091 9559 9614 10017 10633 11366 11611 11291 10743 10013 9309 8874 8363 7887 7280 7201 7026 7126 6869 6988 7144 6940 6890 6856 6700 6595 6498 6444 6391 6428 6637 6421 6512 6400 6470 6372 6515 6396 6487 6447 6479 6305 6525 6496 6589 6479 6567 6455 6248 6298 6562 6402 6352 6301 6471 6351 6184 6444 6315 6374 6502 6506 6664 7024 7269 7799 8138 8188 7750 7360 7186 6999 6725 6798 6840 7034 7206 7253 7018 7151 6936 6777 6689 6643 6568 6538 6424 6458 6573 6376 6348 6396 6253 6394 6552 6341 6397 6541 6536 6565 6255 6318 6324 6371 6293 6174 6351 6359 6269 6242 6207 6328 6354 6366 6435 6408 6515 6620 6557 6415 6507 6378 6404 6387 6437 6282 6454 6404 6290 6365 6415 6454 6222 6286 6367 6224 6295 6224 6204 6046 6203 6216 6322 6323 6345 6275 6274 6307 6214 6328 6406 6353 6284 6421 6261 6271 6182 6253 6508 6412 6404 6306 6348 6483 6318 6308 6287 6352 6104 6214 6218 6192 6355 6452 6296 6357 6248 6314 6295 6181 6277 6169 6268 6128 6193 6282 6041 6107 6249 6233 6230 6205 6293 6320 6309 6310 6321 6153 6275 6144 6172 6410 6215 6225 6273 6345 6185 6327 6301 6208 6314 6245 6256 6237 6347 6361 6358 6363 6282 6265 6358 6119 6318 6270 6293 6278 6231 6229 6308 6401 6296 6110 6363 6465 6304 6082 6392 6282 6455 6301 6109 6432 6406 6322 6345 6378 6273 6277 6220 6237 6366 6388 6296 6213 6264 6265 6477 6262 6096 6211 6274 6376 6389 6362 6180 6397 6247 6235 6410 6375 6226 6349 6332 6394 6353 6405 6550 6574 6787 7042 7256 7870 8216 8462 8372 8034 7624 7240 7034 6901 7006 7264 7364 7683 7803 7795 7706 7834 7518 7456 7616 7783 8145 8204 8752 9274 9926 10746 11764 12354 12660 12556 11670 10700 9792 9320 8866 8792 8741 9281 9568 9713 9558 9200 8779 8046 8020 7757 7415 7305 7290 7247 7238 7208 7027 6901 6873 6774 6782 6739 6820 6676 6835 6895 6893 6876 6932 7005 7348 7763 8261 8750 9316 9684 9348 8769 8142 7874 7557 7404 7419 7511 7832 8180 8464 8286 8451 8130 7512 7505 7554 7545 7774 8242 8719 9848 10329 10640 10692 10189 9525 8774 8018 7887 7568 7687 7845 8237 8554 8629 8789 8062 7779 7709 7434 7228 7251 7036 7077 7025 6953 6880 6860 6816 6652 6705 6485 6782 6679 6499 6911 6740 6728 6779 6520 6577 6602 6302 6264 6439 6600 6473 6550 6562 6521 6344 6430 6384 6441 6408 6258 6382 6275 6396 6367 6302 6414 6460 6576 6305 6507 6397 6475 6519 6248 6489 6428 6352 6536 6560 6601 6850 6645 6567 6802 7220 7123 7484 7664 8202 8802 9235 9688 10165 10176 10163 10073 9910 9906 10372 10584 10615 10627 10634 10063 9605 9459 8972 8718 8482 8474 8341 8362 8316 8069 7661 7454 7264 7084 6918 6751 6598 6620 6330 6451 6544 6377 6466 6432 6335 6410 6388 6239 6311 6355 6437 6320 6354 6238 6186 6221 6217 6413 6528 6353 6545 6576 6625 6718 6713 6635 6940 7255 7532 7524 8022 7896 7699 7609 7537 7440 7465 7370 7278 7527 7723 8286 8554 9045 9114 9478 9365 9136 8628 8558 8600 8603 8983 9391 10238 10996 11390 11496 11419 11469 11097 10836 10426 10262 9631 9377 9299 8983 9114 8879 8884 8996 8965 9100 9232 9263 9394 9756 10155 10113 10013 9686 9375 8425 8060 7642 7540 7525 7549 7891 7843 8139 7989 8045 7774 7455 6985 6655 6847 6531 6580 6440 6595 6244 6297 6224 6380 6207 6548 6283 6481 6431 6629 6353 6405 6564 6551 6471 6532 6554 6588 6416 6595 6794 6848 7174 7090 7404 7858 8515 9332 10217 11582 12194 12290 11908 10958 9798 9030 8435 7976 7994 8216 8494 8876 9162 9312 9313 8859 8110 7774 7384 6922 6750 6506 6494 6424 6541 6499 6404 6432 6552 6204 6416 6246 6461 6361 6357 6349 6287 6579 6490 6318 6522 6562 6794 7083 7221 7662 8006 8606 8936 9157 8584 8389 7721 7411 7159 7388 7254 7537 7698 7870 8083 7936 7884 7558 7303 6985 6880 6753 6731 6690 6765 6703 6547 6545 6404 6522 6426 6574 6536 6597 6644 6652 6460 6622 6736 6562 6747 6779 6810 6791 7211 7356 7615 7849 8363 9257 10216 11625 12966 13941 14194 14100 13528 12621 11654 10716 9844 9255 9213 9406 9835 10062 10432 10633 10421 10101 9486 9003 8547 8145 7804 7747 7886 8125 7997 7931 7463 7297 7209 6880 6753 6473 6718 6757 6662 6764 6904 6895 6862 6714 6560 6525 6424 6199 6235 6090 6135 6165 6273 6161 6137 6265 6373 6211 6077 6136 5958 6102 6096 6198 6088 6045 5974 6147 6112 6130 6127 6008 6162 6137 6053 5962 6016 6091 6178 6130 6060 6125 6156 6180 6098 6167 6235 6314 6134 5918 6133 6089 6205 6236 6206 6085 6085 5999 5866 5875 6085 6086 6096 6252 6113 6131 5966 5947 6138 5927 6261 6001 6104 6229 6166 6106 6122 6187 6090 5880 5975 6090 6108 6260 6192 6149 6184 6465 6301 5996 6059 6154 6017 6182 6140 6106 6195 6215 6164 6053 6182 6181 6121 6255 6160 6334 6285 6204 6304 6289 6171 6355 6354 6449 6344 6719 6739 6972 7429 7335 7411 7709 7414 7399 7382 7306 7294 7488 7427 8335 8397 8374 8181 8077 7869 7458 7409 6936 6966 7097 7042 6821 7005 7091 7337 7083 7047 6891 6746 6763 6556 6535 6319 6268 6365 6232 6079 6148 6292 6280 6102 6119 6171 6080 6095 6191 6099 6182 6139 6105 6113 6013 6126 6146 6090 6043 6054 6239 5958 6096 6020 6114 5963 5908 6017 5926 6029 6170 6210 6073 6049 6012 6234 6298 6363 6498 6371 6564 6718 6893 7012 7058 7165 7096 7138 7082 6815 6626 6471 6647 6533 6462 6478 6583 6790 6671 6944 6744 6642 6791 6533 6413 6229 6221 6065 6116 6219 6181 6101 6131 6189 6148 6257 6172 6069 6228 6291 6044 6102 5979 6114 6040 6026 5967 5931 6026 5895 6118 6187 6015 5997 6074 6093 6051 5998 5930 6002 6229 6184 6114 6130 5971 6013 6026 6037 6140 6108 6060 6168 6335 6158 6020 6060 6342 6244 6099 6167 6216 6232 6381 6169 6178 6058 6149 6176 5947 6032 5992 6148 6063 6066 5945 6013 6073 5981 5966 6060 5944 6067 6007 5947 5912 5917 6005 5828 6137 5987 5905 5962 5871 5955 5822 5842 6014 6055 5972 6017 5959 6001 6075 6089 5801 6030 5919 5879 6013 6085 6013 5902 5970 5901 6023 5899 5991 6033 6004 5905 6035 5942 6005 6106 6242 6111 5966 5921 5999 5886 5800 5987 6023 6106 5888 5876 5974 6042 6211 6135 6242 6262 5995 6246 6139 6250 5982 5999 6169 5920 6030 5970 6015 6141 6045 6055 6022 6043 5953 5924 5994 6104 5884 6010 6029 6004 6071 5833 5849 6036 6017 6142 5757 5989 6049 6044 5920 5934 5833 5901 6003 5793 5995 5914 5935 5976 5967 6046 5967 6006 5986 6010 6093 6012 5844 5892 5909 6002 5886 5955 6150 5922 6022 5964 6047 6253 6240 6092 6279 6026 6077 5989 5970 5917 6007 6039 5999 5961 6031 6012 5998 6066 6056 6093 5934 6072 5938 6115 5983 6012 5971 6048 6037 6139 6068 5991 5989 6103 6053 5938 5933 6122 5981 5860 5855 5948 5910 6041 5935 5958 6069 6099 6022 5993 5849 5884 6055 6127 5942 6018 5815 5979 6038 5967 6031 6022 5899 5947 6068 5982 6100 6215 6078 5980 5985 6077 5980 5945 6123 6105 6030 6001 6048 6139 6005 5858 5936 6051 5950 5920 6057 6109 5964 6077 6228 6075 5943 6048 5965 5887 5992 6036 6061 5935 6079 5958 5855 6021 6107 5999 6003 5989 5976 5914 6027 6044 5996 5958 6088 6204 6136 6176 6093 6205 6149 6334 6410 6573 6554 6538 6531 6506 6763 6694 6995 7064 7034 7258 7408 7324 7283 7379 7185 7159 7083 7104 7199 7444 7840 8357 8650 8620 8357 8044 7649 7463 7313 6904 6838 6685 6845 6925 6858 7193 7270 7463 7582 7603 7683 7791 8034 8190 8148 8334 8077 7749 7723 7531 7147 6984 6822 6730 6687 6805 6958 7068 7201 7385 7479 7415 7495 7606 7771 8018 8029 7941 7532 7109 7076 6678 6613 6633 6478 6534 6349 6256 6379 6594 6704 6955 6812 6698 6600 6492 6475 6096 6155 6222 6014 6015 6028 6075 6168 6147 6190 6160 6007 6208 6152 6227 6199 6149 6058 6085 6032 6180 6089 6021 6141 6167 6299 6133 6111 6077 6294 6277 6040 6251 6142 6236 6274 6111 6211 6303 6383 6495 6622 6561 6457 6706 6730 6381 6600 6545 6684 6806 6572 6596 6565 6526 6581 6580 6396 6587 6731 6609 6547 6331 6434 6437 6284 6504 6392 6352 6341 6310 6373 6497 6306 6245 6316 6186 6258 6138 6096 5954 6132 6135 6115 6067 5998 6065 6080 6102 6149 6190 6155 6094 5985 6073 5914 6005 5955 6138 6102 6089 6013 5924 6080 6304 6006 6059 6009 6047 6069 6087 6008 6055 6038 6165 6074 6093 5998 6169 6113 6063 6123 6292 6213 6316 6354 6391 6385 6558 6314 6423 6513 6488 6436 6615 6431 6607 6543 6640 6842 7176 7494 7807 8066 8292 8474 8705 8449 8256 8078 7854 7742 7338 7078 6914 6887 6908 7010 7089 7061 7036 7159 7295 7178 7058 6931 6888 6701 6380 6294 6580 6106 6024 5944 6057 6016 6095 6131 6104 6209 6145 5997 6108 6034 6085 5902 6065 5957 5953 6045 6235 6205 6549 6424 6473 6545 6552 6785 6691 6348 6340 6261 6267 6060 6091 6082 6277 6035 6225 6307 6282 6314 6449 6353 6133 6111 6154 6084 6107 6028 6033 6091 6071 6145 6029 6228 6148 6134 6240 6286 6163 6057 6175 6118 6021 5937 6286 6186 6316 6047 6182 6147 6307 6248 6272 6321 6396 6446 6631 6767 7073 7080 7252 7518 7199 7177 7134 7047 6828 6795 6833 6647 6378 6302 6441 6418 6605 6595 6717 6713 6773 6821 6758 6533 6577 6476 6492 6312 6364 6348 6105 6213 6074 6095 6063 5926 6052 6059 6075 6122 6154 6008 6089 6302 6038 6146 6214 6238 6223 6283 6238 6162 6140 6189 6156 6067 6229 6214 6112 6334 6148 6350 6658 6601 6738 6812 6857 6777 6965 6655 6955 7084 7068 7386 7388 7749 7710 7648 7753 7564 7498 7228 7092 6987 7014 6785 6593 6695 6752 6736 6760 6943 6794 6655 6741 6757 6674 6440 6358 6317 6153 6277 6146 6076 6117 6092 6116 6046 5953 6065 5999 5956 6027 5996 5992 6096 5914 6007 6121 6114 6004 6078 6077 6060 5849 5709 5813 5763 5928 5891 5783 5876 6026 6025 5901 5936 5936 6014 6035 6034 5935 5971 5895 5991 5797 5659 6048 5842 5737 5735 5749 5773 5980 6002 5906 5761 5884 5856 5720 5767 5774 6045 5805 5951 5879 5796 5821 6008 5919 5777 5843 5951 5860 5968 5831 5868 5948 6063 5955 5876 5956 5974 6084 6231 6196 6165 6323 6324 6082 6217 6247 6008 6098 5845 5823 6135 6147 5944 6043 6184 6075 6188 6056 6107 6241 6165 6166 6058 5954 5998 5980 6034 5868 6003 6096 5963 5997 5864 5929 6036 6072 5986 6093 5884 5956 6117 5966 6005 6140 6230 6138 6170 6073 6361 6433 6219 6136 6087 5941 6051 5908 5957 6123 6040 5953 6001 6146 6206 6240 6333 6367 6199 6375 6358 6377 6236 6216 6441 6583 6407 6429 6460 6627 6712 6897 7224 7369 7498 7672 7905 8021 8209 8163 7722 7472 6985 6966 6681 6588 6643 6597 6591 6652 6802 6813 6601 6915 7094 7048 6971 6963 6808 6566 6371 6121 6193 6218 6200 6161 6310 6222 6070 6141 6377 6181 6160 5990 6178 6141 6239 6405 6483 6795 6739 6697 6662 6645 6433 6363 6647 6495 6570 6603 6674 6597 6541 6382 6494 6294 6326 6365 6340 6310 6016 6108 6048 6210 6117 5966 6147 6251 6126 6156 6024 6217 6014 5919 5832 5977 5908 5945 5771 5875 5915 5738 5793 5767 5749 5833 5991 5727 5949 5958 5908 5875 5811 6086 6006 5938 5953 5904 5814 5958 5821 5709 5813 5820 5931 5936 6020 5932 5868 5933 5935 5974 5748 5931 5867 6006 5748 6007 5965 5876 5927 5831 5669 5891 6011 5837 5943 6105 5957 5989 5866 6009 5997 5927 6063 5967 6006 6077 6099 6046 6052 6107 6082 6077 6079 6049 6194 6011 6110 6045 5958 5973 6056 6278 6240 6225 6325 6312 6345 6441 6510 6819 6831 6793 7080 6829 7109 7240 6908 6913 6873 6681 6408 6589 6689 6350 6421 6323 6432 6586 6534 6577 6806 6833 6930 6784 6769 6571 6438 6498 6323 6354 6225 6298 5923 6189 6134 6087 6117 6325 6214 6122 6220 6202 6482 6450 6380 6538 6671 6656 6848 7071 7197 7131 7049 7012 6830 6693 6926 6923 6837 6747 6429 6376 6324 6316 6389 6493 6651 6611 6574 6494 6461 6443 6509 6343 6312 6326 6631 6290 6234 6340 6356 6116 6308 6175 6024 6040 6108 6095 6103 6087 6068 6059 6001 6018 6071 6040 6106 6220 6005 5923 5985 6085 5948 5892 5971 6250 6106 6184 6287 6215 6292 6214 6310 6154 6193 6211 6151 6248 6072 6180 6356 6441 6399 6433 6609 6625 6858 6751 6839 6732 6761 6658 6643 6587 6331 6571 6735 6666 6691 6598 6822 6707 6757 6826 6806 6728 6656 6626 6614 6483 6408 6392 6294 6475 6351 6416 6302 6406 6599 6561 6444 6601 6330 6355 6392 6329 6332 6201 6219 6173 6362 6138 6362 6367 6461 6262 6490 6510 6618 6790 6813 6750 7020 6910 6772 6843 6636 6668 6580 6541 6356 6413 6520 6501 6512 6302 6357 6278 6467 6414 6287 6203 6507 6424 6314 6404 6417 6321 6148 6118 6012 5826 5845 5868 5978 6071 6040 5954 5975 5952 5966 5951 5968 5940 5882 6112 6129 5959 5932 6080 5865 5935 5930 5996 6019 5870 5766 5962 6046 6023 5929 5913 6030 5874 5987 6029 5943 6117 6184 6180 6145 6130 6173 6217 6316 6228 6413 6284 6274 6286 6322 6323 6413 6358 6164 6239 6164 6266 6180 6265 6319 6172 6176 6119 6314 6293 6359 6383 6474 6324 6447 6186 6342 6353 6231 6115 6369 6228 6162 6129 6104 6112 6179 6037 6331 6304 6560 6448 6759 6748 6670 6659 6464 6244 6336 6364 6099 6052 6035 6227 6053 6016 6069 6103 6203 6070 6106 6238 6115 6039 6225 6122 6126 5855 6038 6110 6068 5898 5907 6144 5859 5962 5994 5909 5963 5857 5911 5934 5858 5930 5924 5988 5860 5889 5847 6035 5831 5856 5881 5799 5746 5788 5938 5780 5923 5748 5737 5842 5672 5792 5800 5663 5794 5871 5948 5847 5768 5786 5786 5813 5837 5793 5815 5760 5720 5814 5618 5897 5817 5630 5851 5739 5877 5788 5712 5947 5798 5797 5787 5760 5665 5830 5910 5917 5916 6101 5971 5981 6047 6100 6067 6130 5951 5921 5834 6047 5852 6038 5937 5920 5943 5979 5843 5886 5920 6052 5905 6057 6202 6131 6239 6308 6180 6192 6280 6244 6504 6324 6177 6080 6210 6364 6214 6324 6132 6358 6376 6358 6320 6306 6215 6267 6101 6182 6252 6245 6095 5956 6202 6098 6013 5869 6023 6051 5944 6035 6046 6059 5928 5945 5931 5902 5898 5991 5838 5778 5687 5962 5861 5804 5783 5844 6083 5854 5831 5945 6002 6091 5887 5866 6023 5804 5906 5800 5793 5753 5828 5797 5843 5951 5922 5834 5835 5959 5833 5976 5982 5917 5907 5819 5901 5781 5939 5804 5845 5774 5992 6064 6135 6208 6226 6052 6074 5962 5947 5976 5859 5812 5829 5977 5818 5963 5973 5819 5936 5898 5804 5971 5797 5914 5997 6078 6111 6088 5933 5887 5903 5961 5879 5770 5788 5806 5882 5640 5828 5801 5898 5882 5792 5698 5600 5819 5986 5834 5803 5853 5958 5953 5867 6000 5920 5996 5940 6020 5978 5991 6157 6159 5916 6113 6110 6152 6261 6025 6247 6133 6299 6320 6108 6204 6311 6275 6108 6290 6445 6426 6393 6645 6567 6562 6592 6653 6360 6694 6611 6598 6561 6683 6715 6825 6780 6591 6435 6571 6399 6270 6394 6435 6536 6582 6446 6570 6510 6588 6629 6719 6620 6766 6683 6853 6852 6880 6699 6768 6371 6432 6462 6397 6364 6356 6127 6288 6237 6182 6139 6151 6033 6204 6320 6040 6008 6187 6052 6144 6119 6100 5952 5967 6045 6168 5989 5918 5786 6060 5792 5889 6010 5759 5947 5957 5828 6020 5938 6101 6031 5920 5938 6019 6069 6029 5956 6080 5954 5942 5962 5850 6006 5758 5938 5996 6024 6038 6152 5956 6156 6185 6111 6247 6327 6510 6491 6408 6453 6542 6597 6689 6602 6571 6604 6417 6397 6107 6113 6146 6031 6019 6002 6027 6077 6010 6157 6059 6010 6211 6212 6449 6385 6158 6238 6206 6365 6060 6011 5920 5956 6058 6104 6187 6218 6366 6366 6353 6303 6289 6142 6109 6059 6099 6129 6065 6014 5941 6064 5960 6051 6111 6231 6444 6284 6308 6483 6475 6595 6377 6443 6341 6260 6162 6137 6356 6314 6317 6358 6357 6313 6343 6382 6308 6369 6091 6274 6287 6020 5994 5886 6038 6027 6036 6177 6002 6043 6117 6018 6189 6535 6416 6551 6489 6631 6801 6834 6672 6540 6430 6596 6609 6568 6645 6451 6536 6535 6458 6427 6335 6249 6397 6378 6280 6340 6336 6612 6389 6708 6804 6779 6876 6945 6819 6840 6716 6741 6503 6461 6310 6279 6107 6168 6080 6034 6119 6069 6014 6144 6001 6024 6214 5994 6036 6071 6269 6242 6022 6052 6010 5989 5893 6043 5752 6017 5788 5730 5684 5799 5722 5787 5623 5767 5575 5951 5778 5628 5793 5573 5736 5695 5573 5702 5758 5786 5792 5786 5836 5729 5843 5720 5827 5790 5829 5717 5806 5732 5901 5982 5908 5639 5675 5722 5961 5855 5932 5718 5931 5810 5705 5753 5766 5910 5769 5745 5689 5922 5852 5791 5912 5762 5765 5882 5936 5737 5947 5858 5932 5726 5925 5765 5777 5925 5927 5834 5914 5868 5930 5871 5910 5962 6010 5953 5825 5937 5999 5956 6093 6021 6141 6149 6111 6193 6209 6285 6229 6124 5966 6060 5946 6244 6147 5815 5980 6064 5846 5998 5801 5838 5797 5977 6032 5950 6054 6062 6194 6121 6103 6159 6215 6181 6259 6360 6215 6233 6300 6322 6286 6210 6236 6140 5947 6054 6049 6022 6067 6032 5905 6256 6228 6117 6409 6439 6467 6402 6526 6616 6542 6774 6829 6753 6759 6608 6516 6511 6781 6628 6677 6652 6580 6612 6549 6797 6600 6579 6573 6349 6386 6403 6418 6240 6355 6200 6317 6465 6349 6111 6340 6202 6243 6411 6240 6156 6321 6290 6096 6318 6099 5990 5976 5922 5977 6070 5884 5879 5735 5954 5837 5838 5749 5755 5633 5778 5804 5849 5706 5850 5907 5890 5826 5808 5806 5771 5783 5803 5990 5836 5849 5897 5962 6053 6071 5969 6239 5889 5868 5851 6001 5964 5931 5923 5865 5848 5908 5812 5751 5691 5912 5976 5884 5891 5795 5853 5704 5811 5843 5862 5920 5821 5949 5804 5987 5791 5752 5832 5680 5707 5688 5624 5811 5774 5812 5890 5663 5773 5958 5844 5864 5940 5865 5716 5870 5853 5855 5966 5854 6008 5938 6043 6131 6165 6168 6357 6162 6393 6483 6500 6465 6268 6230 6178 6343 6204 6339 6216 6069 5939 5897 6065 6144 6206 6108 5871 6080 6060 5824 6005 6172 6178 6153 6257 5978 6045 6048 6143 5935 5920 6088 5736 5914 5825 5811 5801 5786 5828 5910 5792 5813 5758 5771 5812 5855 6005 5829 5858 5601 5754 5727 5861 5988 5890 6003 6011 5959 6018 6129 6156 6145 6128 6222 6169 6364 6290 6270 6351 6427 6323 6276 6116 6276 6183 6192 6296 6111 6109 6166 6018 6346 6208 6249 6091 6190 6163 6111 6221 6052 6101 6399 6327 6291 6373 6362 6274 6451 6243 6516 6267 6398 6323 6391 6195 6240 5965 5968 6053 5959 6037 6011 6037 6094 6127 6130 6174 6372 6425 6452 6613 6661 6585 6403 6438 6381 6287 6077 6051 5893 5900 5987 5969 5988 5999 5910 5906 5767 5776 5988 6039 6273 6262 6115 6262 6272 6326 6524 6320 6528 6246 6178 6258 6195 6056 6141 6231 6039 6006 5915 6067 5936 5873 5927 5806 5876 6010 5917 5873 5877 5969 5952 5959 5844 5807 5945 6000 5974 5897 5739 5814 5946 5789 5814 5932 5849 5673 5510 5720 5676 5776 5813 5710 5632 5822 5591 5640 5889 5798 5742 5693 5709 5596 5632 5607 5539 5893 5892 5684 5627 5729 5692 5565 5709 5941 5756 5723 5582 5564 5748 5692 5724 5629 5774 5792 5811 5983 5957 5790 5823 5858 5789 5916 5904 5896 5841 5858 5780 5722 5883 5851 5894 5733 5940 6037 5973 5898 5873 6109 6004 5901 5884 5954 6070 6067 6074 6158 6137 6187 6135 6155 6111 6149 6137 5967 5968 5932 5888 6077 5922 5976 5787 5927 6088 6125 6282 6204 6387 6367 6207 6298 6178 6268 6336 6300 6163 6105 6070 5953 6027 5836 5869 6070 5948 5910 5678 6035 5859 5703 5924 5972 5854 5796 5832 5861 5806 5848 5828 5866 5998 6014 5872 5908 5720 5839 5757 5820 5726 5785 5592 5826 5686 5660 5787 5846 5705 5630 5718 5516 5792 5817 5891 5785 5792 5757 5854 5928 5824 5741 5891 5972 5959 5845 5868 5780 5787 5761 6001 6022 5897 5842 5915 5910 6173 6195 5992 5962 5985 6004 5898 6128 6318 6296 6060 6129 6045 6308 6273 6435 6319 6284 6024 6108 6105 6117 6059 6002 5953 5972 5999 5770 5866 5848 5942 5874 6000 5906 5891 5745 5985 6001 5987 6087 5895 5895 5857 6018 5943 5997 6033 5848 5898 5810 5845 5935 5965 5889 5967 5727 5813 5648 5821 5662 5771 5852 5710 5629 5804 5781 5748 5566 5770 5838 5761 5607 5665 5804 5691 5675 5663 5780 5691 5778 5760 5666 5794 5685 5687 5710 5657 5726 5901 5672 5666 5605 5746 5743 5686 5810 5756 5551 5617 5717 5689 5790 5753 5674 5715 5661</intensities>
			</dataPoints>
			<nonAmbientPoints type="Temperature" unit="K">
[...]
			</nonAmbientPoints>
		</scan>
	</xrdMeasurement>
</xrdMeasurements>