File: powder_X-ray_diffraction/variable-temperature_experiments/NaNbO2F2/raw_data/180°C.xrdml
<?xml version="1.0" encoding="UTF-8"?>
<xrdMeasurements xmlns="http://www.xrdml.com/XRDMeasurement/1.7" xmlns:xsi="http://www.w3.org/2001/XMLSchema-instance" xsi:schemaLocation="http://www.xrdml.com/XRDMeasurement/1.7 http://www.xrdml.com/XRDMeasurement/1.7/XRDMeasurement.xsd" status="Completed">
	<comment>
		<entry>Configuration=XRK900, Owner=User-1, Creation date=12/01/2015 16:52:44</entry>
		<entry>Goniometer=Theta/Theta; Minimum step size 2Theta:0.0001; Minimum step size Omega:0.0001</entry>
		<entry>Sample stage=AP XRK-900 with z-axis; Minimum step size Z:0.001</entry>
		<entry>Diffractometer system=EMPYREAN</entry>
		<entry>Measurement program=C:\PANalytical\Data Collector\Programs\Gwen\NaNbO2F2-Lent.xrdmp, Identifier={26D14ECE-D3C8-438C-91CA-8651EAF68C7D}</entry>
		<entry>Batch program=C:\PANalytical\Data Collector\Programs\Gwen\Thermodiff-Ouail.xrdmp, Identifier={9701CF17-19F5-4DD4-A8E1-7279D1FD2F5E}</entry>
	</comment>
	<sample type="To be analyzed">
		<id></id>
		<name></name>
		<preparedBy></preparedBy>
	</sample>
	<xrdMeasurement measurementType="Scan" status="Completed" sampleMode="Reflection">
		<comment>
			<entry>PHD Lower Level = 4.02 (keV), PHD Upper Level = 12.07 (keV)</entry>
		</comment>
		<usedWavelength intended="K-Alpha 1">
			<kAlpha1 unit="Angstrom">1.5405980</kAlpha1>
			<kAlpha2 unit="Angstrom">1.5444260</kAlpha2>
			<kBeta unit="Angstrom">1.3922500</kBeta>
			<ratioKAlpha2KAlpha1>0.5000</ratioKAlpha2KAlpha1>
		</usedWavelength>
		<incidentBeamPath>
			<radius unit="mm">240.00</radius>
			<xRayTube id="1010048" name="Empyrean Cu LFF HR (9430 033 7310x) DK420743">
				<tension unit="kV">45.0</tension>
				<current unit="mA">30.0</current>
				<anodeMaterial>Cu</anodeMaterial>
				<focus type="Line">
					<length unit="mm">12.0</length>
					<width unit="mm">0.4</width>
					<takeOffAngle unit="deg">6.0</takeOffAngle>
				</focus>
			</xRayTube>
			<sollerSlit id="21010001" name="Soller slits 0.02 rad.">
				<opening unit="rad">0.0200</opening>
			</sollerSlit>
			<mask id="22030010" name="Fixed mask 20 mm">
				<width unit="mm">20.00</width>
			</mask>
			<antiScatterSlit id="22010003" name="Fixed slit 1Â°" xsi:type="fixedAntiScatterSlitType">
				<height unit="mm">1.52</height>
			</antiScatterSlit>
			<divergenceSlit id="22010012" name="Programmable divergence slit" xsi:type="fixedDivergenceSlitType">
				<distanceToSample unit="mm">140.00</distanceToSample>
				<angle unit="deg">0.5</angle>
			</divergenceSlit>
		</incidentBeamPath>
		<diffractedBeamPath>
			<radius unit="mm">240.00</radius>
			<antiScatterSlit id="22090010" name="AS slit 8.0 mm (PIXcel)" xsi:type="fixedAntiScatterSlitType">
				<height unit="mm">8.00</height>
			</antiScatterSlit>
			<sollerSlit id="21010001" name="Soller slits 0.02 rad.">
				<opening unit="rad">0.0200</opening>
			</sollerSlit>
			<filter id="20030001" name="Large beta-filter Nickel">
				<material>Ni</material>
				<thickness unit="mm">0.020</thickness>
			</filter>
			<detector id="7010019" name="PIXcel1D-Medipix3 detector" xsi:type="rtmsDetectorType">
				<phd unit="%">
					<lowerLevel>25.0</lowerLevel>
					<upperLevel>75.0</upperLevel>
				</phd>
				<mode>Scanning</mode>
				<activeLength unit="deg">3.3482</activeLength>
			</detector>
		</diffractedBeamPath>
		<scan appendNumber="0" mode="Continuous" scanAxis="Gonio" status="Completed">
			<header>
				<startTimeStamp>2022-05-14T20:04:19+02:00</startTimeStamp>
				<endTimeStamp>2022-05-14T23:04:45+02:00</endTimeStamp>
				<author>
					<name>User</name>
				</author>
				<source>
					<applicationSoftware version="5.5a">Data Collector</applicationSoftware>
					<instrumentControlSoftware version="8.1b 20190506">EMPYREAN</instrumentControlSoftware>
					<instrumentID>0000000011159748</instrumentID>
				</source>
			</header>
			<dataPoints>
				<positions axis="2Theta" unit="deg">
					<startPosition>9.99846514</startPosition>
					<endPosition>99.99342261</endPosition>
				</positions>
				<positions axis="Omega" unit="deg">
					<startPosition>4.99923257</startPosition>
					<endPosition>49.99671130</endPosition>
				</positions>
				<positions axis="Z" unit="mm">
					<commonPosition>8.912</commonPosition>
				</positions>
				<commonCountingTime unit="seconds">386.070</commonCountingTime>
				<intensities unit="counts">7645 7720 7682 7673 7625 7637 7712 7802 7798 7892 7849 8101 7885 7719 8010 7973 7951 7930 7749 7828 7742 7845 7723 7816 7903 7805 7855 7883 7857 7672 7825 7694 7632 7695 7760 7712 7833 7882 7737 7768 7875 7812 7825 7742 7842 7893 7858 7742 7710 7826 7824 7745 7633 7774 7656 7690 7775 7612 7759 7836 7842 7756 7874 7824 7976 8005 8050 8221 8120 8231 8291 8167 8242 8259 8558 8390 8573 8386 8627 8785 8862 8975 9019 9422 9934 10422 11194 12245 13623 15916 19624 25160 34222 47914 63909 76763 79486 72492 58541 42918 29219 20001 14514 11455 9873 9038 8899 8793 8622 8468 8273 8226 8448 8102 8087 7866 7842 7866 8040 8007 7649 7923 7891 7963 7952 7828 7865 7775 7910 7941 7883 7886 7936 7998 7897 8003 7888 7934 8080 8121 8108 8206 8138 7934 8111 8185 8219 8128 8080 8212 8226 8245 8229 7990 7953 8156 8351 8091 7960 8138 8253 8245 8283 8152 8142 8369 8186 8362 8140 8081 8193 8329 8122 8187 8230 8145 8243 8142 8134 8272 8313 8306 7988 8032 8118 8139 8249 8151 8078 8260 8296 8340 8211 8169 8070 8070 8119 8178 8008 7955 8150 8339 8029 8103 7989 8209 8052 8164 8090 8319 8092 8132 8303 8077 8037 8135 7970 8141 8093 8059 7981 8172 8082 8098 8061 7920 7989 7963 8109 8193 8130 8061 7962 8043 7997 7932 7974 7935 7974 8114 8144 8063 7884 7929 8088 8011 7909 8135 8035 8003 7781 8072 7841 8136 8003 7999 7856 8043 8002 7970 7985 7927 7972 7883 7849 7893 7904 7928 8095 7911 8131 7977 7947 7951 7912 7991 8100 7989 7924 7994 8186 8155 8126 8257 8054 8117 8091 8105 8075 7924 7823 7951 8040 7896 7817 7846 7930 7804 8112 8031 7789 7766 7821 7870 7799 7803 7983 7853 8050 8123 8118 7956 7953 8027 8082 8061 8081 7866 7994 8092 7987 7841 7977 7831 7836 7808 7844 7864 7717 7977 7895 8073 8112 7822 8003 7898 7817 8160 8119 8037 8159 8632 8956 9235 9478 9598 9560 9579 9246 8939 8739 8489 8257 7962 8131 7800 7922 7929 7849 7902 7812 7860 7776 7838 7997 7875 7910 7880 7938 7628 7707 7854 7908 7842 7612 7665 7788 7795 7815 7697 7855 7819 7742 7813 7877 7917 7791 7829 7643 7734 7721 7768 7653 7814 7880 7878 7855 7671 7730 7667 7852 7731 7845 7853 7678 7768 7701 7735 7871 7796 7691 7856 7790 7802 7810 7871 7773 7631 7590 7621 7802 7656 7867 7519 7596 7784 7668 7643 7783 7721 7756 7634 7895 7654 7984 7650 7808 7680 7741 7705 7816 7723 7786 7789 7666 7785 7678 7690 7470 7665 7752 7729 7564 7594 7584 7620 7717 7710 7704 7776 7932 7725 7879 7797 7835 7816 7774 7632 7668 7499 7704 7728 7727 7842 7431 7492 7531 7641 7508 7564 7875 7570 7641 7594 7739 7624 7619 7702 7690 7581 7452 7692 7879 7547 7609 7722 7590 7602 7788 7722 7564 7595 7635 7760 7575 7573 7859 7613 7566 7696 7539 7643 7737 7600 7891 7903 8064 8077 7975 8225 8304 8215 7957 7835 7694 7696 7667 7693 7562 7398 7729 7715 7458 7533 7487 7538 7269 7325 7508 7492 7566 7699 7634 7625 7348 7502 7566 7471 7517 7561 7540 7589 7448 7549 7449 7484 7441 7685 7558 7430 7422 7424 7444 7518 7497 7467 7440 7400 7359 7467 7329 7444 7574 7460 7495 7525 7482 7408 7442 7368 7544 7534 7511 7479 7275 7352 7388 7469 7643 7382 7373 7368 7306 7554 7392 7454 7478 7592 7384 7474 7828 7603 7646 7742 7719 7450 7460 7502 7479 7500 7404 7286 7398 7306 7280 7444 7197 7235 7469 7182 7344 7194 7205 7282 7316 7464 7376 7498 7315 7336 7376 7295 7169 7362 7555 7217 7345 7274 7268 7191 7328 7192 7367 7370 7168 7281 7290 7187 7238 7400 7198 7269 7253 7400 7219 7244 7207 7184 7228 7317 7404 7349 7149 7268 7191 7259 7213 7238 7307 7190 7193 7213 7264 7305 7384 7164 7032 7197 7316 7286 7205 7345 7363 7162 7273 7123 7210 7367 7176 7257 7279 7392 7286 7300 7229 7406 7515 7371 7543 7737 7684 7944 7740 7848 7698 7530 7688 7784 7739 7542 7509 7485 7777 7951 7959 7690 7768 7708 7730 7774 7731 7810 7886 7861 7763 7751 7777 7827 7978 7920 7976 8266 8383 8352 8311 8582 8806 8973 9237 9609 9956 10940 12326 14759 17749 22632 31222 43309 58992 76889 93033 96841 90363 79024 68607 55731 41423 29642 20832 15468 12132 10610 10134 9467 9254 9034 8709 8639 8323 8326 8149 8137 7932 8048 7725 7829 7828 7888 7778 7776 7537 7807 7578 7611 7734 7715 7470 7562 7531 7705 7567 7637 7709 7503 7567 7412 7545 7411 7486 7472 7477 7580 7514 7550 7506 7470 7565 7556 7607 7592 7364 7518 7604 7318 7413 7603 7542 7367 7447 7548 7456 7416 7369 7395 7542 7377 7601 7709 7627 7485 7444 7527 7428 7569 7388 7354 7537 7600 7395 7490 7639 7435 7488 7426 7327 7424 7367 7283 7317 7309 7434 7549 7354 7496 7349 7363 7529 7428 7406 7207 7141 7511 7428 7415 7468 7470 7547 7494 7320 7471 7552 7412 7355 7569 7466 7383 7540 7554 7498 7321 7663 7486 7537 7449 7370 7351 7309 7497 7429 7422 7625 7409 7480 7551 7298 7452 7533 7329 7469 7519 7575 7485 7502 7428 7677 7879 7733 7713 7689 7640 7911 7498 7416 7580 7371 7346 7370 7325 7328 7307 7371 7358 7351 7432 7319 7397 7148 7391 7332 7462 7455 7516 7495 7509 7460 7387 7528 7501 7456 7341 7508 7523 7865 7740 7579 7656 7826 7718 7835 7957 7824 8210 8326 8909 9692 10868 12880 16599 22144 28529 33263 34019 31530 28196 25564 22489 19093 15411 12298 10439 9217 8432 8326 8168 7867 7817 7809 7754 7775 7557 7748 7540 7538 7445 7377 7425 7285 7566 7396 7437 7368 7484 7482 7358 7418 7249 7536 7714 7453 7446 7577 7535 7627 7488 7619 7552 7735 7620 7454 7496 7586 7490 7750 7671 7668 7568 7569 7817 7704 7696 7535 7367 7620 7560 7529 7435 7607 7385 7707 7611 7586 7509 7601 7586 7520 7603 7698 7657 7663 7792 7794 7893 8045 8278 8239 8655 8943 9609 11590 14465 18747 24640 28896 29952 27808 24827 22657 21364 19087 16008 13257 11426 10189 9123 9081 9076 9075 9211 9489 9754 10613 12321 15531 20357 28163 35458 39281 35490 31117 28782 27341 24080 19387 15531 12739 10568 9261 8689 8455 8214 8019 7913 8033 7767 8009 8166 8080 8014 8027 7795 7842 7747 7644 7807 7636 7428 7648 7498 7221 7554 7199 7344 7370 7605 7312 7339 7447 7459 7364 7458 7451 7372 7271 7363 7384 7425 7260 7519 7485 7216 7335 7410 7405 7448 7438 7365 7558 7382 7464 7183 7307 7550 7236 7394 7583 7395 7442 7398 7222 7299 7535 7465 7369 7311 7490 7247 7317 7531 7472 7616 7519 7549 7660 7471 7583 7536 7320 7324 7328 7331 7400 7296 7213 7303 7258 7318 7234 7294 7135 7164 7339 7351 7391 7231 7290 7281 7301 7288 7416 7419 7179 7419 7314 7366 7466 7294 7280 7281 7464 7269 7426 7235 7213 7229 7294 7224 7221 7280 7287 7304 7344 7314 7329 7228 7222 7373 7370 7267 7234 7434 7461 7452 7411 7428 7358 7414 7494 7454 7279 7386 7396 7305 7373 7368 7249 7318 7183 7164 7276 7353 7264 7261 7015 7254 7464 7129 7176 7219 7277 7183 7142 7226 7289 7202 7248 7283 7310 7074 7060 7251 7225 7231 7341 7113 7039 7095 7187 7098 7166 7013 7519 7267 7072 7160 7052 7102 7217 7087 7171 7068 7127 7237 7166 7155 7230 7133 7081 7134 7148 7215 7039 7267 7178 7142 7174 7295 7414 7472 7420 7518 7461 7471 7534 7399 7410 7283 7286 7525 7580 7495 7426 7481 7497 7500 7348 7442 7588 7430 7251 7302 7522 7388 7371 7355 7394 7343 7333 7367 7424 7570 7464 7479 7402 7478 7648 7491 7418 7477 7589 7609 7479 7477 7542 7737 7601 7750 7920 7910 7996 8186 8359 8482 8630 8557 8688 8809 9145 9324 9550 10137 10453 11248 12045 13391 15735 19075 25213 35220 49999 66711 82252 90047 88161 78794 69924 62979 58326 52154 43458 33556 24836 18761 14548 12511 11243 10460 9823 9653 9172 8831 8524 8415 8221 8114 8110 7945 7829 7791 7653 7473 7622 7786 7545 7859 7559 7679 7933 7700 8428 8605 8880 9048 8866 8693 8521 8460 8144 8229 8239 7880 7876 7688 7702 7439 7407 7565 7687 7613 7855 7715 7622 7717 7677 7832 7851 7923 8250 8380 8621 8755 9271 10068 12072 15131 21067 29516 37829 40778 36442 30481 27005 26041 25896 24396 20785 16337 13152 10740 9722 9075 8968 9035 9016 9560 10363 11336 12821 13803 15188 16547 17117 16695 15855 14859 14151 13586 12937 11893 10886 9810 9069 8405 8192 8000 7840 7612 7354 7417 7586 7468 7532 7414 7069 7312 7276 7037 7127 7188 7170 7422 7146 7324 7323 7107 7246 7227 7258 7285 7161 7518 7228 7143 7082 7184 7223 7114 6945 7140 7046 7026 7069 7067 7256 7141 6980 6944 6888 6998 7135 7046 7024 7133 6982 6894 7095 6978 7104 7046 7145 7117 6980 7156 7292 7160 7065 6923 6812 6896 7030 6872 7054 6985 6959 7098 6927 7023 6995 7178 7009 6943 6850 7019 6798 7040 7027 6893 6918 6862 6930 7095 6889 6991 6973 7006 6937 7044 6980 6846 6962 6760 6997 6797 6945 7017 7133 6881 6831 7095 7147 7025 6850 6872 6936 6836 6978 6888 6900 6786 6966 7009 6986 6757 7004 6842 6957 6699 6884 7028 6770 6774 6951 6945 6869 6699 6779 6820 6884 7003 6857 6825 6956 6900 7024 6805 6794 6906 6782 6761 6896 6809 6981 6844 6818 6884 6651 6937 6892 6926 6922 6856 6946 6783 6818 6878 6963 6726 6741 6844 6770 6644 6900 6791 6694 6771 6889 6779 6634 6824 6834 6752 6819 6603 6791 6970 6872 6917 6945 7039 6715 6783 6906 6957 6864 6832 6890 6838 7013 6851 6783 6867 6777 6731 6785 7090 6960 6877 6773 6765 6939 6833 7001 6916 6846 6982 6793 6978 6844 6894 6782 6974 6849 6912 6921 7033 7046 6986 6954 7015 7033 7140 7028 7081 7105 7054 6938 6990 7025 6792 6770 6708 6848 6994 6944 6967 6872 6917 7056 6973 6904 7031 7125 6946 6994 6959 7189 7492 7179 7260 7374 7369 7671 7944 8359 9048 10262 11777 13939 15630 16353 15752 15786 17457 20818 24124 24226 22034 18270 15665 14604 14580 14620 14018 11956 10019 9094 8487 7880 7530 7348 7232 7013 7100 7145 7098 7022 6938 6847 7009 6875 7018 7061 6964 7063 6980 7144 6964 6780 7015 6875 6822 7100 7303 6860 7069 6994 7112 7149 7303 7427 7680 7898 8625 9717 11324 12911 14077 15113 14751 13671 12416 11669 11380 11222 10960 10738 9525 8663 8010 7750 7480 7461 7453 7452 7589 7654 7814 7857 7604 7789 7437 7615 7734 7527 7658 7369 7432 7434 7480 7668 8513 9903 11660 13459 13894 13205 11971 10822 10438 10676 10720 10369 9955 8977 8278 7571 7456 7157 7128 6865 6773 6973 6922 6645 6796 6799 6933 6720 6687 6660 6797 6670 6812 6693 6800 6977 6913 6926 6734 6787 6847 6887 6875 7004 6984 6941 6951 6889 6726 6947 6928 6999 7265 7497 7957 8573 9912 11014 11664 11397 11084 10333 9857 9587 9486 9469 9075 8773 8272 7753 7437 7457 7273 7508 7536 7588 7267 7279 7087 7110 7153 7169 7021 7026 6948 6837 6532 6607 6709 6783 6730 6597 6552 6547 6523 6736 6706 6608 6504 6597 6572 6771 6769 6721 6661 6529 6689 6641 6682 6516 6614 6651 6546 6518 6594 6443 6662 6572 6575 6432 6480 6633 6601 6670 6651 6630 6526 6495 6715 6703 6586 6580 6545 6668 6662 6425 6534 6512 6614 6533 6622 6522 6510 6680 6614 6525 6376 6581 6430 6553 6452 6672 6652 6832 6699 6622 6784 6571 6749 6784 6569 6595 6821 6393 6731 6865 6716 6615 6701 6724 6610 6638 6826 7046 7069 7552 8111 8865 9778 9946 9780 8717 8209 7988 8240 8100 8373 8243 7768 7383 7032 6685 6823 6756 6497 6656 6545 6558 6431 6547 6709 6432 6486 6643 6846 6576 6674 6542 6685 6689 6550 6567 6641 6526 6545 6482 6686 6440 6402 6553 6676 6586 6555 6345 6597 6585 6477 6416 6632 6585 6359 6468 6665 6670 6649 6631 6402 6541 6407 6599 6531 6599 6632 6609 6478 6498 6534 6695 6639 6557 6578 6719 6765 6847 6756 7139 7106 7254 7500 7334 7299 7251 7287 7309 7435 7773 7884 8403 9112 9920 11092 11584 11807 11572 11138 10729 10800 11269 11568 11440 10938 10062 9076 8793 8467 8200 8094 7829 7273 7205 7101 6945 6796 6832 6624 6447 6459 6633 6860 6636 6583 6755 6751 6692 6783 6605 6616 6595 6560 6626 6514 6691 6633 6572 6535 6670 6525 6608 6494 6519 6627 6406 6508 6611 6589 6513 6388 6400 6499 6490 6430 6479 6429 6548 6390 6576 6636 6575 6376 6382 6548 6444 6675 6360 6323 6485 6425 6515 6511 6381 6575 6573 6510 6626 6773 6559 6497 6229 6308 6407 6340 6513 6501 6340 6483 6551 6411 6505 6441 6367 6544 6638 6656 6574 6543 6399 6628 6616 6607 6652 6677 6686 6902 6885 7470 7868 8713 9364 9417 8994 8490 7864 7609 7725 7838 7952 7883 7672 7369 7096 6808 6641 6603 6631 6670 6422 6388 6510 6509 6488 6598 6412 6335 6476 6473 6380 6353 6439 6358 6304 6431 6513 6520 6408 6442 6423 6357 6542 6351 6497 6523 6535 6790 6412 6359 6441 6373 6381 6512 6505 6608 6528 6695 6424 6382 6398 6520 6454 6460 6611 6366 6605 6583 6561 6615 6608 6598 6746 7054 7164 7241 7369 7516 7515 7339 7480 7514 8057 8352 9257 9793 9999 9862 9049 8733 8349 8036 7928 8210 8051 8016 7696 7406 6976 6807 6841 6724 6688 6568 6567 6489 6415 6371 6430 6422 6588 6394 6439 6370 6457 6420 6453 6473 6460 6439 6401 6369 6426 6494 6566 6565 6366 6534 6569 6598 6619 6524 6560 6587 6754 6779 7023 7067 7322 7518 8084 8240 8321 8506 8388 8594 9173 9976 10784 11729 11731 11783 11659 11134 11280 10998 11394 11164 10748 10248 9601 8960 8544 8327 8279 7970 7611 7454 7114 6869 6710 6545 6655 6580 6428 6553 6620 6521 6553 6559 6437 6358 6503 6401 6444 6424 6317 6319 6401 6352 6589 6171 6253 6424 6619 6422 6525 6426 6398 6333 6374 6395 6376 6494 6546 6425 6225 6482 6548 6431 6514 6422 6476 6339 6291 6429 6421 6495 6440 6406 6238 6474 6412 6206 6285 6214 6259 6377 6215 6381 6355 6369 6287 6472 6562 6532 6486 6504 6454 6397 6443 6427 6473 6457 6345 6259 6351 6407 6399 6376 6366 6504 6351 6457 6498 6259 6442 6324 6476 6476 6346 6431 6436 6486 6406 6535 6420 6350 6586 6409 6526 6495 6448 6376 6346 6541 6340 6445 6450 6293 6387 6407 6551 6416 6444 6187 6228 6369 6406 6284 6331 6374 6300 6319 6437 6490 6433 6422 6229 6462 6324 6463 6410 6411 6414 6440 6353 6389 6206 6463 6322 6294 6424 6433 6449 6518 6421 6331 6216 6443 6344 6371 6570 6471 6440 6421 6540 6457 6437 6409 6526 6764 6885 7262 7383 7678 7774 7680 7806 7312 7281 7125 7118 7125 7205 7102 7053 6744 6758 6752 6772 6641 6452 6461 6502 6374 6463 6271 6277 6435 6417 6471 6377 6304 6331 6287 6272 6268 6203 6292 6261 6395 6555 6633 6619 6494 6548 6566 6515 6487 6437 6392 6530 6606 6653 6575 6569 6614 6539 6410 6314 6478 6364 6401 6548 6454 6576 6532 6695 6563 6580 6765 6805 6814 6790 6992 7015 7246 7301 7431 8061 8343 9104 10207 11524 12855 13328 13013 12339 11335 10382 9745 9520 9662 9953 10057 9892 8986 8758 7900 7398 6996 6912 6934 6582 6655 6580 6630 6536 6667 6471 6409 6484 6588 6592 6431 6626 6339 6394 6576 6497 6227 6279 6498 6445 6364 6243 6499 6257 6385 6259 6416 6279 6416 6518 6379 6408 6529 6447 6221 6259 6399 6381 6237 6204 6344 6270 6441 6361 6267 6324 6384 6364 6391 6441 6509 6475 6437 6375 6334 6267 6616 6498 6460 6578 6290 6333 6327 6578 6439 6451 6427 6402 6446 6516 6612 6430 6609 6620 6676 6665 6792 6543 6887 6848 6778 7021 6891 6743 6999 7208 7253 7513 7894 8511 9245 10795 13328 16586 19055 19861 19489 17318 14962 13098 11623 11735 12454 13270 14139 13806 13147 11603 10103 8914 8035 7663 7593 7203 7216 7249 7001 7030 7089 6869 6739 6646 6734 6440 6803 6563 6651 6607 6708 6600 6665 6515 6531 6493 6429 6500 6474 6474 6548 6206 6471 6246 6420 6458 6342 6471 6350 6385 6463 6420 6498 6571 6530 6414 6581 6439 6359 6422 6459 6368 6488 6350 6428 6361 6531 6617 6538 6264 6500 6423 6448 6474 6474 6525 6445 6467 6544 6388 6507 6484 6598 6542 6675 6667 6540 6879 6600 6567 6809 6983 7049 6898 7320 7637 8113 8501 9111 9346 9266 9087 9418 9810 10530 11808 13339 14242 13513 11819 10131 9482 8943 8671 9081 9582 9963 10149 9316 8512 7837 7507 7419 7271 6961 7061 6985 6707 6779 6956 7009 7016 6962 7012 7235 6959 6983 6926 6953 7135 7156 7151 7162 7454 7657 7936 8295 8999 9828 10970 12590 14724 16460 17943 18826 17751 16634 15014 13711 12683 12354 12628 12834 13146 12825 12383 11645 10498 9441 8631 8104 7705 7634 7378 7078 7064 6871 6865 6840 6771 6806 6811 6732 6786 6654 6805 6609 6641 6711 6919 7167 7355 7366 7777 7916 8062 7907 7760 7652 7731 7774 7556 7901 7667 7789 7590 7598 7417 7431 7239 7238 7190 7063 7146 6942 6901 6983 7091 6931 7162 7039 6956 7184 7098 7279 7575 7816 8121 8479 9026 10386 11435 13439 15182 15894 15637 14789 13432 12216 11436 11303 11761 12872 13968 14914 14789 13705 12239 10651 9489 8828 8333 8459 8789 8876 8893 8311 8009 7641 7394 7055 6814 6750 6795 6833 6822 6860 6952 6924 6972 6914 6902 7016 7055 7170 7152 7169 7166 7388 7682 8010 8742 9500 10679 12566 14994 17322 19216 19733 18237 16059 13936 12192 11073 11186 11900 12287 13328 13273 12756 11533 10251 9163 8252 7960 7274 7194 7136 7080 7168 6838 6915 6804 6678 6643 6770 6848 6765 6532 6697 6612 6597 6588 6719 6721 6917 7030 7015 7123 7249 7347 7492 7434 7657 7554 7570 7845 8453 8528 8686 8648 8596 8273 8193 8320 8459 8885 9434 9839 10165 10146 9668 9186 8380 8179 7979 7959 7815 8026 7978 8001 7989 7796 7319 7051 7033 6748 6828 6669 6583 6525 6685 6470 6597 6547 6454 6492 6533 6594 6532 6587 6478 6660 6442 6710 6636 6470 6540 6597 6469 6490 6444 6311 6500 6577 6463 6556 6450 6501 6472 6519 6475 6510 6552 6653 6577 6695 6918 6680 6793 6618 6746 6718 6866 6949 7285 7455 8272 9053 10566 12535 14633 16089 15509 13938 12190 10701 9774 9193 9323 9783 10777 11804 12285 11613 10863 9959 9054 8250 7772 7503 7209 7205 7093 7232 7250 6978 6895 6809 6670 6748 6553 6568 6544 6548 6490 6496 6328 6549 6535 6459 6487 6318 6527 6486 6452 6322 6379 6413 6450 6599 6574 6455 6570 6540 6383 6451 6451 6537 6409 6503 6533 6348 6476 6375 6247 6437 6304 6586 6691 6704 7085 7499 7788 8111 7979 7557 7179 6964 6627 6419 6669 6831 6931 7231 7344 7112 7042 6833 6789 6625 6562 6522 6450 6368 6307 6341 6138 6310 6310 6331 6428 6351 6366 6449 6300 6246 6410 6224 6350 6299 6295 6085 6330 6186 6234 6262 6398 6403 6397 6343 6158 6392 6680 6451 6558 6540 6514 6400 6317 6491 6415 6299 6311 6302 6533 6139 6297 6290 6392 6429 6386 6347 6283 6251 6265 6249 6218 6291 6208 6159 6169 6277 6156 6126 6432 6497 6362 6341 6342 6472 6432 6311 6409 6193 6346 6358 6330 6410 6330 6408 6275 6198 6459 6343 6342 6428 6342 6310 6312 6233 6241 6246 6253 6323 6165 6209 6234 6508 6206 6267 6286 6416 6326 6327 6274 6300 6315 6321 6209 6158 6136 6263 6258 6241 6298 6199 6158 6289 6191 6284 6394 6235 6131 6223 6369 6151 6359 6386 6309 6383 6380 6177 6065 6267 6156 6207 6199 6194 6353 6188 6293 6211 6289 6067 6201 5967 6297 6189 6234 6318 6100 6253 6437 6323 6259 6337 6319 6294 6368 6381 6473 6274 6348 6264 6293 6178 6169 6313 6355 6276 6513 6476 6541 6321 6353 6172 6311 6374 6473 6267 6260 6189 6442 6439 6274 6334 6409 6542 6597 6436 6511 6463 6528 6432 6574 6934 7192 7630 8175 8526 8531 8329 7950 7627 7229 7287 7102 7249 7431 7735 7947 8112 8089 8062 7962 7935 8017 8264 8666 9197 9658 10657 11567 12332 12748 12514 11870 11027 10186 9690 9213 8860 8867 9165 9538 9633 9446 9326 8933 8290 7973 7480 7330 7303 7261 7335 7285 7091 7220 7081 7010 6859 6881 6750 6752 6828 6866 6765 6776 6899 7059 7098 7344 7434 8048 8470 9051 9373 9451 9158 8402 8069 7701 7403 7149 7359 7577 7947 8194 8415 8176 8039 7764 7614 7507 7492 7776 8034 8723 9581 10034 10541 10768 10471 10066 9251 8334 8038 7719 7542 8011 8167 8350 8537 8730 8540 8344 7882 7698 7141 7263 7173 7195 7117 7023 6943 6632 6865 6679 6666 6686 6697 6823 6681 6700 6618 6633 6615 6541 6426 6474 6394 6371 6507 6476 6487 6330 6473 6440 6426 6355 6474 6479 6383 6483 6347 6177 6474 6401 6307 6241 6334 6345 6365 6392 6566 6423 6425 6404 6551 6428 6545 6514 6335 6592 6598 6499 6490 6744 6951 6809 7163 7621 7795 8315 8754 9130 9716 10051 9828 10078 9785 9733 9536 9912 10374 10588 10842 10779 10260 9931 9548 9236 8890 8424 8044 8141 8115 8370 8088 8164 7866 7415 7211 7066 6846 6727 6585 6558 6397 6513 6422 6384 6615 6493 6445 6402 6394 6466 6339 6343 6261 6328 6421 6324 6411 6350 6423 6337 6477 6365 6487 6652 6660 6771 6823 7070 7322 7631 7688 7775 7926 7899 7700 7501 7117 7251 7263 7274 7449 7898 8185 8737 9101 9487 9462 9175 8959 8843 8703 8627 8978 9324 10117 10531 10987 11127 11587 11398 10964 10802 10371 10346 9934 9599 9379 9070 9220 9085 8839 9073 9237 9002 9278 9552 9731 10027 10192 10155 10067 9660 9224 8542 8053 7865 7677 7476 7558 7610 7822 7945 8068 7931 7625 7480 7089 6706 6634 6555 6502 6610 6513 6544 6348 6408 6410 6285 6493 6322 6300 6467 6491 6549 6483 6378 6394 6339 6401 6477 6632 6514 6434 6708 6825 6766 6718 6894 7229 7225 7891 8475 9215 10152 11364 12033 12350 11786 10554 9826 8840 8248 8052 7955 7863 8297 8636 9183 9545 9231 8920 8261 7747 7529 6890 6899 6743 6584 6528 6658 6566 6479 6239 6486 6466 6457 6422 6392 6428 6440 6471 6287 6495 6492 6476 6630 6760 6944 7444 7686 8293 8850 9052 8927 8584 7987 7433 7271 7196 7197 7277 7439 7642 7657 7862 7934 7812 7163 7295 6962 6768 6637 6640 6666 6596 6805 6579 6562 6536 6626 6456 6545 6445 6435 6592 6506 6591 6525 6558 6677 6770 6965 6912 6856 7143 7464 7834 8182 8950 10074 11113 12662 13786 14558 14506 13885 12776 11835 10659 10053 9583 9334 9319 9635 10175 10452 10605 10409 10080 9622 8910 8514 8094 7547 7479 7341 7299 7436 7670 7941 8033 7731 7351 7118 6977 6688 6487 6562 6559 6469 6755 6638 6886 6961 6881 6689 6484 6327 6382 6194 6274 6289 6127 6270 5997 6229 6168 6304 6114 6094 6039 5942 6084 5936 6126 6047 6011 6159 6157 6174 6243 6136 6315 6104 6216 6101 6159 6038 6128 6181 6093 6142 6010 5955 6151 5989 6065 6109 6151 6207 6090 6201 6138 5989 6155 6095 5981 6084 6094 6204 6126 5995 6084 6135 6114 5995 6018 6016 6185 6064 6213 6273 6148 6143 6233 6270 6057 6100 6064 6108 6063 6153 6149 6139 6147 6079 6158 6185 6190 6224 6132 6196 6227 6149 6145 6209 6248 5975 6257 6143 6224 6139 6217 6111 6327 6116 6092 6326 6436 6479 6449 6387 6505 6488 6597 6763 7164 7311 7285 7516 7463 7487 7280 7250 6885 7067 7140 7045 7223 7784 8204 8491 8643 8400 8106 7695 7193 6989 7001 6849 6785 6835 6796 6930 7187 7315 7313 7145 7000 6772 6613 6494 6350 6421 6252 6220 6236 6049 6197 6268 6271 6204 6342 6164 6100 5962 6112 6022 6006 6080 6118 6070 6133 6159 6354 6014 6240 6100 6075 6227 6086 6166 6011 6037 6198 6016 6145 6028 6371 6291 6303 6158 6404 6179 6368 6710 6719 6676 7014 7029 7245 7219 7204 7185 6950 6732 6730 6643 6536 6383 6537 6563 6590 6651 6876 6654 6551 6609 6465 6444 6165 6221 6246 6302 6162 6169 5953 5973 6133 6037 6203 6060 6096 6142 6152 5970 5937 5890 6072 6175 5916 6165 6050 5862 6022 6022 5925 6005 6124 6171 5953 6258 6280 5876 5758 6055 6023 6019 5939 6036 6001 6137 6119 6034 6087 5999 6173 6077 5799 5952 6100 6079 6133 6135 6345 6300 6293 6267 6047 6128 6151 6070 6029 6030 5919 5952 5944 5977 6175 6149 6015 6100 5831 5901 5829 6046 5869 6043 5926 5995 5856 6035 6011 5902 6059 6008 5974 6031 5890 5969 5942 6074 5910 5895 5954 5843 6027 6042 5890 6068 5892 5782 5942 6072 6162 6017 5988 5895 5897 5924 5971 5820 6138 5940 6025 6050 5924 5932 6051 5967 6041 6238 6034 5904 5938 6154 6048 6036 6032 5821 6036 6114 6240 6129 6082 6117 6121 6247 6131 6195 6259 6350 6076 6245 6198 5992 6036 6072 5947 6158 6108 6056 5998 6091 6211 5963 6057 5966 5763 6016 5974 5960 5980 5981 6028 6065 6034 6082 5887 6003 5913 5761 5764 5763 5914 5900 5827 5943 5967 6035 5961 5961 5978 6088 5929 5843 6160 5947 5810 5837 5857 5763 5722 5803 5912 5757 5866 6000 6000 5970 5961 6017 6248 6319 6183 6183 6173 6178 6029 6041 5912 6061 5941 5905 6111 5994 5955 6108 6123 6031 5869 5976 6021 5885 6022 5994 5845 5797 5998 6099 6120 6111 6113 6132 6054 6023 6070 5956 6096 5991 5885 6033 5925 6124 5903 6081 5983 6049 6012 5992 5986 5900 5962 6034 5797 6055 5847 5945 6045 5971 5985 6115 5971 6046 6129 6073 5920 5970 6163 6029 5906 5972 5887 6166 6018 6020 6023 5956 5863 5991 6011 6040 5929 5944 6042 6019 6038 6143 6251 6180 6113 6140 6110 6035 5923 6002 6117 6022 6092 6041 6070 5999 5935 6013 5996 5961 6218 6062 5917 5862 6008 5988 6034 5962 5982 6075 6221 6408 6158 6208 6381 6446 6478 6736 6688 6792 6804 6753 6691 6894 7053 7314 7280 7173 7424 7328 7168 7052 7068 7016 6902 6951 7013 7207 7304 7740 7931 8342 8655 8650 8432 7740 7521 7224 6939 6809 6802 6682 6780 6805 7107 7248 7480 7720 8057 8341 8343 8506 8412 8604 8394 7975 7633 7284 7116 6787 6630 6693 6539 6775 6745 6864 7115 7040 7096 7258 7217 7035 7139 7294 7380 7657 7688 7991 7609 7310 6967 6871 6676 6469 6349 6244 6421 6548 6372 6422 6740 6633 6832 7098 6641 6387 6293 6477 6260 6204 6088 6144 5907 5999 6118 6066 6325 6158 6224 6091 6147 6221 6062 6003 6223 6124 6138 6270 6019 6241 6175 6080 6082 6177 6084 6105 6002 6039 6023 6118 6118 6278 6290 6361 6355 6549 6343 6504 6794 6592 6379 6567 6607 6703 6787 6540 6699 6635 6734 6560 6566 6485 6587 6607 6463 6553 6527 6556 6520 6446 6402 6244 6394 6370 6523 6323 6343 6339 6280 6266 6417 6245 6103 6084 6240 6106 6078 6089 6056 6229 6146 6098 6173 6221 6084 5963 5961 5981 5949 5983 5931 5986 6051 6017 6084 6018 6192 6021 6232 6195 6054 6110 5981 6112 6058 6041 6110 5956 6177 6169 6150 6154 6027 6160 6029 6111 6268 6194 6289 6248 6207 6238 6626 6617 6451 6355 6463 6425 6412 6479 6422 6407 6271 6599 6899 7258 7431 7600 8092 8331 8578 8571 8524 8410 8043 7711 7562 7473 7187 6864 6781 6769 6865 6914 7171 7100 7313 7214 7102 7076 6862 6900 6750 6485 6466 6458 6310 6177 6006 6183 6003 5981 6139 6122 5969 6108 6008 6126 6030 6074 6020 5906 6065 5964 5906 6076 6242 6486 6267 6634 6720 6589 6678 6473 6397 6280 6124 6073 6099 6100 6217 6139 6065 6067 6203 6087 6242 6354 6474 6324 6349 6006 6076 6169 6030 5997 6091 6020 5995 6117 5908 6032 6138 6200 6034 6239 6401 6243 6195 6266 6142 6113 6167 6109 6197 6151 6240 6184 6324 6502 6380 6664 6758 6734 6817 7122 7378 7268 7395 7320 7099 7151 6831 6776 6556 6446 6610 6544 6468 6539 6564 6565 6628 6651 6496 6784 6684 6596 6414 6605 6301 6315 6343 6329 5992 6214 6061 6116 6158 6039 5922 6034 6139 6093 6169 6294 6163 6164 6398 6322 6213 6141 6180 6323 6239 6190 6033 6190 6163 6252 6190 6105 6202 6188 6317 6571 6635 6503 6780 6900 6940 6960 6763 6703 6878 6887 7102 7119 7121 7458 7417 7512 7466 7559 7352 7241 6980 6991 7010 6845 6619 6843 6804 6808 6763 6798 6937 6729 6740 6836 6657 6525 6485 6589 6400 6296 6178 6164 5999 6293 6019 6079 6264 6107 6118 6102 6026 6087 5947 5979 6077 6083 5950 6100 5896 5981 6072 6208 6122 5928 6087 5904 5876 5873 5923 6039 5877 5872 5789 5957 5861 5865 6067 6111 5948 5819 5883 5856 5980 5876 6045 5900 5772 5793 5725 5773 5880 6036 5875 5948 5904 5835 5831 5784 5956 5986 5875 5738 5694 5786 5856 5856 5907 5907 5820 5911 5962 5852 5951 5922 5882 6051 5976 5846 5849 6087 5923 5981 6181 6284 6233 6290 6050 6168 6031 6165 6182 5829 6020 6075 5883 5980 5845 6020 5976 6023 6252 6204 6256 6136 5929 6058 6067 5944 5920 5957 5938 5939 6131 5907 5869 5959 5943 5987 5967 5947 5890 5830 5987 5944 5889 5933 6078 5956 6275 6175 6062 6244 6306 6158 6344 6221 6184 6072 6096 6043 6059 5995 6022 5939 6163 6254 6348 6272 6101 6218 6319 6278 6168 6198 6391 6403 6501 6475 6517 6649 6720 6882 6931 7095 7227 7322 7372 7397 7555 7474 7813 7735 7769 7575 7535 7005 6800 6657 6756 6682 6594 6676 6759 6807 6898 6852 6782 6737 6802 6810 6694 6557 6378 6375 6273 6288 6083 5929 6205 6241 6301 6180 6277 6385 6223 6157 6054 6119 6140 6165 6056 6230 6431 6595 6957 6715 6814 6834 6702 6536 6642 6569 6509 6514 6524 6512 6250 6423 6334 6274 6303 6348 6503 6383 6376 6285 6297 6317 6399 6270 6288 6202 6068 6056 6004 6073 5901 5949 5902 6103 5962 5888 5900 6038 5912 5894 6101 6018 5792 5968 5814 5987 5862 5829 5827 5842 5912 5855 5887 5879 5909 5782 5825 5794 5832 5790 5688 5811 5836 5886 5770 5937 5955 5876 5752 5975 5897 5837 6020 5988 6037 5851 5809 5852 5831 5759 5859 5957 5924 6037 5855 6078 6069 6040 6051 5915 5898 6030 6238 5969 5858 5906 6187 6170 6033 6134 6084 6064 6221 6222 6165 6209 5974 6114 6264 6347 6269 6111 6214 6267 6329 6550 6704 6895 7020 6972 6936 7136 6974 6961 6670 6711 6761 6570 6447 6407 6582 6493 6385 6500 6522 6635 6514 6587 6648 6811 6779 6723 6624 6776 6482 6510 6292 6261 6371 6143 6158 5988 6097 6153 6340 6381 6202 6198 6210 6146 6205 6357 6475 6636 6583 6837 6792 6875 6836 6870 6951 6825 6971 6803 6668 6659 6776 6745 6617 6752 6736 6505 6474 6513 6803 6784 6636 6594 6648 6479 6474 6480 6395 6517 6510 6464 6398 6341 6418 6298 6146 6229 6072 6099 5992 6112 6039 5939 6032 6057 6048 6174 6065 6008 6007 6012 5894 5857 5913 5910 5850 5964 6076 5978 5966 6099 6074 6097 6270 6363 6240 6324 6125 6269 6217 6208 6276 6247 6327 6621 6622 6658 6730 7076 6927 6920 6829 6817 6679 6711 6597 6594 6725 6725 6702 6953 6700 6919 6830 6675 6852 6711 6664 6645 6697 6464 6469 6390 6273 6518 6323 6245 6372 6364 6617 6546 6363 6421 6556 6435 6580 6451 6468 6257 6192 6321 6269 6219 6216 6252 6303 6331 6586 6469 6582 6500 6581 6741 6683 6968 7031 6801 7032 6913 6783 6683 6596 6558 6484 6402 6355 6383 6432 6531 6424 6349 6270 6411 6387 6316 6423 6308 6278 6323 6189 6014 6196 6029 6283 6049 6068 6077 5998 6159 6082 6222 6074 6020 6033 6108 5846 5910 5964 5962 5905 5901 5908 5968 5740 6009 6014 5904 5904 5878 5915 5801 5846 5869 6044 6219 6135 5894 6096 5832 6065 6095 6269 6215 6296 6263 6297 6229 6206 6301 6301 6522 6223 6286 6168 6243 6353 6384 6386 6238 6312 6269 6165 6241 6202 6250 6144 6234 6429 6185 6342 6238 6245 6251 6228 6297 6202 6327 6104 6108 5982 5995 6119 6225 6158 6142 5978 6461 6213 6321 6308 6305 6432 6642 6580 6558 6554 6579 6494 6378 6288 6286 6238 6205 5989 6066 6106 6083 6094 6066 6189 6001 6143 6188 6244 6325 6007 6096 5988 6161 5943 5880 5988 5937 5947 6099 5893 5842 5930 5914 5762 5957 5861 5892 5849 5846 5851 5850 5795 5746 5916 5778 5816 5789 5897 5674 5854 5841 5836 5854 5781 5738 5721 5810 5898 5720 5756 5649 5709 5754 5833 5785 5867 5941 5731 5922 5846 5897 5817 5902 5806 5771 5727 5817 5831 5764 5936 5816 5883 5803 5785 5809 5923 5789 5838 5839 5770 5719 5952 5858 5965 5951 6027 6054 5989 6102 6200 5963 6160 6016 5916 5926 5830 5760 5837 5836 5914 5835 5983 5885 6110 6062 6126 6133 6315 6107 6178 6187 6282 6163 6173 6374 6048 6261 6244 6249 6241 6445 6105 6231 6455 6266 6297 6311 6144 6152 6109 6062 6033 5994 5980 6079 6069 5921 6014 5926 5882 6016 6063 6070 5990 5963 5936 5966 5790 5898 5787 5863 5818 5908 5819 5671 5946 5980 5821 5939 5962 5946 5917 5819 5916 5959 5983 5951 5870 6051 5799 5776 5874 5830 5887 5809 5752 5796 5732 5822 5846 5988 5859 5940 5747 5972 6163 5837 5870 5846 6042 5863 5745 5961 5837 5837 6028 6113 6026 6091 6141 5997 5887 5883 5891 5790 5842 5907 5836 5779 5677 5612 5791 5891 5836 5801 5751 5831 6116 6003 5988 5952 5943 6060 5789 5843 5893 5807 5675 5963 5613 5753 5779 5871 5875 5905 5886 5975 5969 5938 5909 5944 6017 5910 6012 5928 5882 6109 6040 5950 5971 5931 6046 5883 6136 5994 6076 6065 5918 6095 6149 6149 6180 6040 6071 6098 6118 6283 6214 6228 6284 6363 6312 6394 6366 6404 6589 6391 6417 6557 6548 6667 6698 6758 6751 6814 6687 7058 6786 6496 6569 6505 6510 6509 6398 6590 6516 6593 6553 6764 6652 6673 6749 6770 6762 6728 6856 6696 6772 6691 6461 6613 6579 6331 6236 6215 6290 6233 6109 6263 6139 6242 6217 6182 6264 6161 6330 6098 6115 5981 6095 6031 5997 6096 6001 6096 5825 5890 5898 5860 5788 5727 5838 5958 5867 6002 5882 5915 6005 6030 5942 5979 5966 6092 5933 6156 6169 6209 6104 5966 5990 6087 5974 6130 6062 5932 6021 6127 6212 6129 6129 6029 6161 6135 6274 6350 6364 6507 6472 6546 6497 6570 6474 6423 6484 6417 6115 6238 6125 6036 6126 6133 6118 6056 6030 6100 6117 6208 6094 6146 6140 6224 6162 6125 6113 6219 6063 6041 5975 6060 6007 6124 6075 6077 5996 6185 6222 6088 6360 6301 6330 6191 6411 6248 6237 5957 6157 6281 6089 6090 6041 6000 6080 6159 6167 6325 6264 6278 6403 6503 6213 6317 6360 6458 6386 6453 6292 6158 6283 6207 6227 6155 6162 6287 6285 6330 6332 6332 6256 6167 6202 6077 6138 6056 6272 6159 6107 6127 6266 6190 6159 6269 6339 6286 6417 6671 6496 6822 6865 6832 6971 6849 6689 6531 6672 6707 6615 6469 6445 6321 6248 6402 6222 6191 6192 6033 6171 6329 6283 6466 6623 6698 6726 6745 6695 6803 6808 6813 6658 6648 6566 6380 6253 6258 6205 6081 6068 6063 6145 5933 6006 5905 5795 6042 6082 5911 5944 6104 6213 6224 6122 6079 5763 5993 5843 5942 5819 6006 5887 5886 5837 5734 5764 5859 5888 5897 5663 5847 5832 5636 5911 5803 5897 5851 5718 5822 5995 5776 5813 5784 5905 5930 5743 5659 5713 5776 5657 5704 5865 5769 5812 5834 5892 6018 5859 5874 5834 6031 5849 5821 5776 5916 5831 5762 5876 5983 5924 5828 5803 5794 5696 5767 5675 5939 5787 5757 5872 5767 5821 5792 5649 5915 5833 5841 5875 5907 5815 5663 5874 5917 5901 5733 5775 5874 5946 5999 6053 5848 6134 6150 6079 6111 6116 6005 6059 6028 6148 6194 6131 6136 6158 6036 5925 6081 5957 5965 6030 6070 6172 6148 6107 6076 6144 6085 6043 6212 6091 6013 6134 6156 5962 6229 6167 6038 6264 6199 6196 6188 6240 6204 6259 6103 6075 6097 6029 5827 6189 6070 6013 6125 6123 6282 6134 6239 6332 6373 6569 6589 6538 6539 6788 6765 6726 6405 6371 6649 6577 6689 6567 6502 6680 6789 6684 6664 6706 6685 6757 6507 6547 6549 6247 6221 6272 6279 6359 6317 6268 6198 6167 6154 6218 6103 6140 6190 6152 6272 6304 6142 6010 6122 6059 5933 6003 5976 5911 5728 5842 5887 5691 5903 5845 5970 5905 5838 5769 5816 5679 5761 5836 5759 5776 5744 5933 6041 5815 5803 5924 6014 6026 6090 6017 5781 5980 5951 5893 5912 5854 5772 5940 5803 5908 5871 5838 5942 5772 5638 5797 5774 5844 5778 5789 5989 5920 5708 5713 5826 5845 5931 6002 5887 5790 5934 5849 5948 5831 5776 5767 5776 5806 5746 5715 5815 5905 5910 5679 5718 5883 5781 5851 5900 5875 5863 5912 5887 5793 6008 5813 6001 6084 6246 6120 6130 6343 6267 6333 6461 6412 6233 6402 6427 6368 6354 6301 6109 6198 6105 6059 6012 5936 5999 6101 6062 5948 5963 5920 5993 6008 6066 5921 5984 5965 6164 6032 5856 5966 5893 5961 5863 5708 5850 5874 5844 5839 5980 5734 5808 5977 5783 5811 5827 5967 5855 5828 5774 5968 5976 5846 6032 5893 5965 6052 6046 5993 5923 6141 6296 6327 6369 6328 6506 6303 6497 6392 6047 6281 6243 6425 6151 6253 6385 6194 6346 6261 6210 6336 6110 6193 6185 6126 6097 6109 6094 6033 6269 6417 6226 6348 6255 6428 6206 6317 6190 6384 6229 6230 6180 6168 6398 6240 6030 6105 6150 6247 6082 5965 5968 6136 5914 5988 6011 6101 5970 6063 6002 6098 6293 6331 6321 6436 6438 6414 6412 6304 6158 6187 6285 6107 6074 5950 5940 5871 5962 5913 6054 5895 5963 6083 6182 6290 6267 6115 6393 6466 6449 6402 6331 6387 6532 6342 6362 6230 6043 6251 5774 6053 5915 5808 5836 5792 5849 5755 5909 5948 5913 5978 5900 6045 5986 6183 5914 6081 5983 5852 5891 5747 5925 5880 5797 5989 5618 5837 5876 5712 5772 5832 5702 5888 5859 5633 5777 5647 5789 5662 5721 5683 5655 5705 5724 5775 5671 5622 5652 5861 5841 5702 5692 5685 5752 5851 5685 5742 5813 5850 5656 5841 5799 5702 5739 5763 5832 5709 5659 5841 5750 5817 5667 5745 5683 5786 5918 5697 5803 5793 5762 6002 5910 5998 5918 5946 5979 5988 5778 6031 5929 6034 6085 6146 5973 6082 6180 6117 6202 6053 6212 6287 6030 5920 6130 5978 6066 5968 5922 5974 5987 6034 6017 6050 6109 5987 5984 6077 6117 6069 5978 6081 6162 6159 6138 6405 6280 6314 6304 6172 6065 5977 5979 6003 6001 6068 5827 5966 5833 5924 5939 5741 5806 5857 5793 5776 5885 5954 6015 5959 5955 5904 5940 5869 5858 5854 5697 5843 5769 5799 5749 5731 5704 5785 5805 5732 5678 5842 5692 5697 5737 5775 5732 5798 5789 5593 5973 5929 5884 5655 5914 5962 5921 5695 5745 6121 5985 6049 6087 6110 6067 5943 5915 5817 5943 6017 6060 6007 5993 5900 5907 5926 5957 6023 6094 6103 6270 6317 6318 6250 6211 6305 6284 6295 6410 6240 6207 6170 6140 6167 6063 5835 5931 5972 5951 5851 6038 5940 5963 5924 6035 5918 6047 5951 6099 5981 5839 6041 5965 6113 5867 6023 5838 5874 5900 5873 5839 5636 5698 5797 5777 5784 5857 5743 5785 5723 5810 5849 5901 5784 5671 5692 5668 5702 5708 5953 5687 5694 5808 5543 5707 5694 5759 5653 5599 5753 5892 5666 5796 5873 5656 5705 5703 5861 5736 5691 5632 5788 5654 5668 5650 5783 5796 5662 5752 5775 5723 5666 5622 5647 5854 5698 5716 5643 5743 5692 5798</intensities>
			</dataPoints>
			<nonAmbientPoints type="Temperature" unit="K">
[...]
			</nonAmbientPoints>
		</scan>
	</xrdMeasurement>
</xrdMeasurements>