File: powder_X-ray_diffraction/variable-temperature_experiments/NaNbO2F2/raw_data/220°C.xrdml
<?xml version="1.0" encoding="UTF-8"?>
<xrdMeasurements xmlns="http://www.xrdml.com/XRDMeasurement/1.7" xmlns:xsi="http://www.w3.org/2001/XMLSchema-instance" xsi:schemaLocation="http://www.xrdml.com/XRDMeasurement/1.7 http://www.xrdml.com/XRDMeasurement/1.7/XRDMeasurement.xsd" status="Completed">
	<comment>
		<entry>Configuration=XRK900, Owner=User-1, Creation date=12/01/2015 16:52:44</entry>
		<entry>Goniometer=Theta/Theta; Minimum step size 2Theta:0.0001; Minimum step size Omega:0.0001</entry>
		<entry>Sample stage=AP XRK-900 with z-axis; Minimum step size Z:0.001</entry>
		<entry>Diffractometer system=EMPYREAN</entry>
		<entry>Measurement program=C:\PANalytical\Data Collector\Programs\Gwen\NaNbO2F2-Lent.xrdmp, Identifier={26D14ECE-D3C8-438C-91CA-8651EAF68C7D}</entry>
		<entry>Batch program=C:\PANalytical\Data Collector\Programs\Gwen\Thermodiff-Ouail.xrdmp, Identifier={9701CF17-19F5-4DD4-A8E1-7279D1FD2F5E}</entry>
	</comment>
	<sample type="To be analyzed">
		<id></id>
		<name></name>
		<preparedBy></preparedBy>
	</sample>
	<xrdMeasurement measurementType="Scan" status="Completed" sampleMode="Reflection">
		<comment>
			<entry>PHD Lower Level = 4.02 (keV), PHD Upper Level = 12.07 (keV)</entry>
		</comment>
		<usedWavelength intended="K-Alpha 1">
			<kAlpha1 unit="Angstrom">1.5405980</kAlpha1>
			<kAlpha2 unit="Angstrom">1.5444260</kAlpha2>
			<kBeta unit="Angstrom">1.3922500</kBeta>
			<ratioKAlpha2KAlpha1>0.5000</ratioKAlpha2KAlpha1>
		</usedWavelength>
		<incidentBeamPath>
			<radius unit="mm">240.00</radius>
			<xRayTube id="1010048" name="Empyrean Cu LFF HR (9430 033 7310x) DK420743">
				<tension unit="kV">45.0</tension>
				<current unit="mA">30.0</current>
				<anodeMaterial>Cu</anodeMaterial>
				<focus type="Line">
					<length unit="mm">12.0</length>
					<width unit="mm">0.4</width>
					<takeOffAngle unit="deg">6.0</takeOffAngle>
				</focus>
			</xRayTube>
			<sollerSlit id="21010001" name="Soller slits 0.02 rad.">
				<opening unit="rad">0.0200</opening>
			</sollerSlit>
			<mask id="22030010" name="Fixed mask 20 mm">
				<width unit="mm">20.00</width>
			</mask>
			<antiScatterSlit id="22010003" name="Fixed slit 1Â°" xsi:type="fixedAntiScatterSlitType">
				<height unit="mm">1.52</height>
			</antiScatterSlit>
			<divergenceSlit id="22010012" name="Programmable divergence slit" xsi:type="fixedDivergenceSlitType">
				<distanceToSample unit="mm">140.00</distanceToSample>
				<angle unit="deg">0.5</angle>
			</divergenceSlit>
		</incidentBeamPath>
		<diffractedBeamPath>
			<radius unit="mm">240.00</radius>
			<antiScatterSlit id="22090010" name="AS slit 8.0 mm (PIXcel)" xsi:type="fixedAntiScatterSlitType">
				<height unit="mm">8.00</height>
			</antiScatterSlit>
			<sollerSlit id="21010001" name="Soller slits 0.02 rad.">
				<opening unit="rad">0.0200</opening>
			</sollerSlit>
			<filter id="20030001" name="Large beta-filter Nickel">
				<material>Ni</material>
				<thickness unit="mm">0.020</thickness>
			</filter>
			<detector id="7010019" name="PIXcel1D-Medipix3 detector" xsi:type="rtmsDetectorType">
				<phd unit="%">
					<lowerLevel>25.0</lowerLevel>
					<upperLevel>75.0</upperLevel>
				</phd>
				<mode>Scanning</mode>
				<activeLength unit="deg">3.3482</activeLength>
			</detector>
		</diffractedBeamPath>
		<scan appendNumber="0" mode="Continuous" scanAxis="Gonio" status="Completed">
			<header>
				<startTimeStamp>2022-05-15T02:54:22+02:00</startTimeStamp>
				<endTimeStamp>2022-05-15T05:54:50+02:00</endTimeStamp>
				<author>
					<name>User</name>
				</author>
				<source>
					<applicationSoftware version="5.5a">Data Collector</applicationSoftware>
					<instrumentControlSoftware version="8.1b 20190506">EMPYREAN</instrumentControlSoftware>
					<instrumentID>0000000011159748</instrumentID>
				</source>
			</header>
			<dataPoints>
				<positions axis="2Theta" unit="deg">
					<startPosition>9.99846514</startPosition>
					<endPosition>99.99342261</endPosition>
				</positions>
				<positions axis="Omega" unit="deg">
					<startPosition>4.99923257</startPosition>
					<endPosition>49.99671130</endPosition>
				</positions>
				<positions axis="Z" unit="mm">
					<commonPosition>8.912</commonPosition>
				</positions>
				<commonCountingTime unit="seconds">386.070</commonCountingTime>
				<intensities unit="counts">7662 7494 7600 7620 7581 7645 7766 7728 7626 7666 7526 7791 7883 7777 7775 7836 7610 7745 7799 7673 7568 7831 7779 7767 7726 7689 7631 7569 7792 7610 7872 7770 7644 7552 7609 7749 7760 7722 7562 7681 7660 7727 7680 7596 7537 7563 7600 7677 7737 7620 7650 7710 7670 7544 7735 7737 7452 7717 7757 8007 7843 7682 7665 7757 7778 7890 7943 8042 8104 7921 8067 8111 8222 8385 8236 8383 8422 8386 8603 8477 8574 9074 9033 9529 9837 10682 11575 12742 14410 17264 21463 27620 38463 53281 69484 79156 78015 68753 53615 38436 25764 17444 13038 10541 9300 8957 8713 8433 8477 8398 8300 8039 8182 8112 7693 7802 7794 7992 8022 7633 7839 7888 7780 7872 7708 7740 7808 7790 7722 7870 7770 7944 7768 7729 8034 7917 8049 7816 8026 7967 7945 8025 8009 7984 8022 7944 8128 8006 8040 8183 8097 8107 7988 7964 8065 7990 8193 8065 7976 8139 8132 8261 8140 7946 7988 7929 7842 8112 7925 8054 8117 7935 7937 8084 8023 8214 8114 8061 7962 8140 8135 7923 8048 8218 8345 7980 8267 7938 7831 7998 8035 8088 8112 8215 7984 8272 7968 8288 8453 8144 8125 8079 7987 7988 8055 8000 8016 7953 8043 7998 8089 7966 7872 7955 7881 8049 8071 8188 7899 7901 8026 7929 8246 8160 7907 7854 8039 7974 7941 7976 7980 7799 7875 8180 7971 7881 8132 7941 8051 8033 8108 7860 8206 8043 7981 7917 7830 8009 8044 7949 8065 7757 7978 8210 7946 7941 7805 8029 7936 7925 7800 8017 8028 7949 7910 7808 7905 7717 7950 7877 8010 7993 7889 7852 7875 7748 7876 7883 8003 7899 7957 8027 7961 7902 7892 7917 7924 7877 8056 7817 7910 7843 7987 7771 7890 7858 7856 7983 7714 7945 7707 7810 7960 7814 7593 7849 7811 7810 7955 7861 7815 7917 7933 8160 7786 7790 7939 7931 7944 7973 7920 7666 7723 7985 7849 7940 7857 7932 7879 7998 8050 7962 7948 7907 7945 7819 7893 7962 7975 8019 8181 8480 8823 8984 9418 9585 9478 9332 9149 8872 8450 8297 8198 7908 8000 7945 7964 8046 7826 7911 7826 7761 7743 8104 7972 7698 7751 7822 7877 7739 7759 7744 7952 7643 7951 7743 7794 7924 7917 7837 7688 7827 7876 7683 7784 7946 7715 7834 7672 7508 7598 7750 7659 7665 7551 7587 7720 7577 7712 7704 7772 7816 7540 7722 7731 7648 7745 7700 7521 7591 7860 7843 7735 7685 7813 7623 7821 7640 7716 7658 7479 7849 7823 7546 7701 7566 7744 7675 7679 7533 7416 7587 7555 7532 7593 7832 7590 7848 7613 7510 7700 7607 7637 7650 7703 7503 7691 7694 7624 7730 7743 7565 7865 7762 7839 7555 7887 7627 7832 7709 7542 7729 7745 7454 7542 7706 7454 7675 7525 7677 7598 7777 7869 7737 7727 7674 7694 7359 7413 7640 7713 7707 7719 7689 7781 7539 7492 7694 7584 7814 7527 7661 7663 7776 7793 7598 7614 7438 7589 7590 7663 7620 7839 7504 7446 7549 7539 7451 7710 7733 7645 7596 7816 7747 7710 7849 7949 8000 7950 7917 7962 7965 7961 7736 7797 7638 7695 7602 7574 7655 7612 7402 7797 7640 7584 7489 7449 7300 7493 7628 7314 7445 7474 7414 7437 7454 7577 7453 7463 7374 7573 7705 7532 7506 7614 7677 7532 7402 7513 7519 7540 7360 7317 7506 7333 7508 7232 7397 7470 7423 7382 7187 7578 7391 7462 7349 7258 7538 7450 7237 7385 7472 7486 7429 7528 7400 7330 7467 7378 7519 7313 7307 7354 7414 7483 7572 7494 7342 7468 7277 7513 7642 7459 7574 7473 7364 7395 7388 7400 7341 7234 7280 7341 7384 7558 7183 7297 7160 7421 7356 7360 7093 7414 7225 7261 7308 7425 7416 7357 7205 7360 7408 7331 7208 7246 6971 7026 7104 7068 7243 7073 7350 7307 7312 7245 7067 7124 7366 7252 7242 7260 7170 7202 7193 7117 7108 7158 7178 7410 7190 7158 7249 7126 7188 7256 7060 7188 7430 7259 7165 7077 7336 7415 7199 7216 7196 7208 7135 7230 7111 7197 7206 7217 7267 7269 7160 7235 7073 7132 7314 7228 7228 7358 7348 7489 7263 7356 7611 7703 7665 7676 7721 7481 7726 7593 7790 7709 7640 7736 7657 7581 7688 7621 7534 7617 7470 7734 7667 7755 7613 7516 7782 7656 7593 7663 7732 7984 7917 7978 8230 8226 8180 8397 8466 8604 8716 8855 9167 9677 10252 11404 13087 15686 19651 25628 35738 49344 66148 83617 96784 97222 86912 75455 64262 51430 37007 26270 18653 13999 11421 10452 9769 9211 9129 8748 8602 8690 8165 8304 8033 7981 8114 7818 7857 7886 8061 8041 7919 7875 7733 7810 7671 7722 7738 7574 7476 7536 7540 7321 7540 7685 7689 7635 7448 7687 7646 7494 7547 7423 7514 7398 7379 7507 7621 7575 7358 7413 7453 7542 7585 7271 7546 7680 7373 7590 7359 7410 7488 7455 7646 7529 7493 7379 7380 7446 7640 7426 7333 7490 7339 7450 7361 7450 7441 7269 7286 7514 7374 7378 7620 7241 7443 7327 7332 7550 7359 7497 7357 7309 7452 7519 7111 7279 7467 7320 7260 7313 7336 7244 7505 7370 7631 7553 7448 7596 7369 7476 7549 7346 7596 7542 7317 7544 7374 7497 7518 7635 7311 7329 7497 7540 7429 7452 7455 7511 7481 7463 7177 7352 7460 7417 7353 7298 7410 7413 7468 7550 7400 7498 7440 7422 7769 7676 7521 7621 7697 7509 7463 7738 7404 7635 7539 7519 7568 7396 7491 7436 7394 7393 7403 7592 7209 7423 7239 7440 7366 7373 7356 7370 7328 7406 7251 7359 7313 7531 7577 7523 7473 7226 7483 7639 7539 7613 7575 7829 7599 7683 7794 7952 8060 8290 8564 8836 9985 10920 13275 17518 22906 28835 32887 32984 30439 27423 25130 21978 18383 14585 12009 10107 8839 8415 7954 7976 7931 7864 7947 7678 7594 7392 7380 7331 7629 7299 7464 7392 7493 7425 7560 7557 7351 7395 7398 7378 7477 7530 7274 7440 7360 7491 7505 7477 7374 7389 7433 7611 7526 7418 7469 7507 7598 7566 7545 7638 7466 7618 7603 7491 7521 7545 7508 7543 7577 7565 7424 7414 7545 7279 7503 7467 7600 7561 7750 7816 7587 7838 7487 7869 7768 7716 7979 7975 7848 7888 8096 8391 8651 9399 10207 12343 15459 20381 26149 29089 29519 27196 23895 22305 20658 18311 15240 12234 10586 9510 9156 9090 9072 9319 9788 10204 11026 13203 16908 23324 30787 38148 39525 35129 31300 28774 26671 23082 18576 14881 12022 9701 9172 8520 8345 8214 8118 8022 8093 8146 7968 8089 8071 7934 7940 7647 7614 7655 7721 7630 7755 7795 7555 7429 7452 7487 7507 7429 7275 7320 7263 7521 7389 7296 7361 7420 7662 7388 7385 7362 7413 7147 7153 7597 7296 7449 7420 7363 7310 7296 7253 7262 7300 7505 7309 7312 7125 7534 7465 7304 7134 7523 7621 7481 7363 7252 7063 7243 7268 7240 7437 7619 7555 7429 7346 7410 7552 7645 7540 7436 7477 7337 7468 7516 7375 7387 7357 7361 7314 7421 7289 7127 7177 7263 7506 7268 7202 7140 7151 7338 7106 7294 7221 7189 7195 7291 7412 7259 7129 7274 7372 7312 7332 7148 7157 7239 7427 7251 7427 7369 7363 7381 7322 7219 7270 7350 7372 7202 7420 7473 7423 7381 7216 7565 7331 7368 7315 7308 7311 7113 7233 7293 7352 7171 7358 7356 7198 7309 7282 7215 7019 7437 7470 7244 7264 7270 7116 7161 7197 7338 7229 7336 7178 7283 7381 7300 7111 7116 7316 7199 7247 7254 7359 7287 7096 7214 7243 7095 7245 7144 7153 7141 7265 7096 7192 7145 7203 7233 7078 7264 7154 7191 7023 7242 7144 7026 7098 7260 7124 7192 7084 7387 7043 7077 7265 7480 7275 7111 7024 7137 7509 7279 7273 7468 7677 7576 7534 7390 7476 7418 7385 7422 7392 7423 7474 7586 7523 7348 7589 7456 7308 7457 7352 7462 7371 7409 7375 7397 7422 7429 7269 7328 7395 7419 7376 7251 7399 7351 7482 7462 7480 7282 7505 7478 7512 7344 7497 7601 7563 7694 7675 7853 7936 7898 7960 8301 8212 8388 8527 8761 8879 9010 8966 9591 9904 10298 10885 11745 12960 15161 18913 24336 33498 47175 63847 79092 88101 88232 80684 71278 64519 58751 53280 44776 35412 26627 19838 15503 13003 11563 10606 10218 9546 9259 8839 8426 8367 8191 8172 8022 7839 7942 7804 7731 7746 7709 7614 7855 7635 7564 7671 7732 7809 7831 8089 8472 8586 8755 8905 8685 8640 8409 8341 8238 8364 8002 7674 7630 7538 7696 7573 7563 7603 7622 7619 7576 7710 7867 7711 7823 7978 7986 8110 8258 8540 8881 9127 10246 12171 15531 21583 30317 38272 40380 36045 30146 26765 26156 25968 23835 20101 16150 12745 10631 9616 9004 8887 9150 9492 10112 11201 12489 13780 15357 16135 16776 15961 15562 15165 14345 13955 13127 12138 11065 10167 9482 9058 8543 8108 8008 7690 7812 7519 7579 7487 7375 7275 7180 7186 7230 7242 7143 7197 7137 7132 7053 7080 7043 7207 7158 7267 7255 7161 7057 7205 7375 7127 7107 7162 7192 7017 7038 7205 7363 7106 7184 7022 7076 7030 7136 7009 7107 7124 6934 7099 6992 6997 7072 7026 7088 6975 7049 6870 7080 7181 7254 7089 7076 7194 6960 6876 7141 6971 7102 6968 6972 6992 6997 7073 7049 6896 6910 7049 7144 7075 7097 7055 6948 7009 7006 6965 6976 6865 6899 6849 6916 6872 6982 7123 7007 6899 6759 6798 6985 7037 6829 6994 6873 6938 6894 6877 6991 6809 6919 7011 6782 6816 7087 6953 6863 7181 7070 6845 6952 6893 6816 6662 6891 6901 7045 6814 6814 6802 6855 6877 6767 6874 6786 7018 6902 6699 6727 6943 6948 6750 6803 6978 7028 6998 6677 6630 6753 7043 7081 6922 6765 6799 6995 7029 6929 6737 6891 6907 6823 6882 6831 6858 7010 7017 6723 6691 6622 6632 6730 6774 6651 6960 6722 6781 6605 6952 6705 6734 6853 6811 6651 7015 7019 6812 6845 6853 6888 6606 6755 6745 6768 6960 6667 6755 6860 6906 6665 6787 6520 6790 6802 6710 6896 7030 6882 6924 6827 6965 6887 6731 6822 6881 7100 6895 6921 6865 6979 6969 7014 6743 6915 6935 6856 6948 6967 7006 6901 6981 6756 6898 6969 7017 6910 6924 6949 6987 6937 6819 6827 6791 6835 6974 6837 6786 6863 6871 7091 7079 7024 7023 7101 7059 7154 6939 7020 7054 7184 7432 7430 7508 7822 8257 8738 9916 11683 13763 14879 15101 14455 13697 13488 14279 16296 19053 21975 23275 21463 17648 14884 13502 13667 14507 14054 12349 10669 9278 8427 7707 7546 7486 7426 7177 7145 7111 7112 7063 6921 6934 6874 6967 6754 6980 6997 7172 6968 6917 7027 7117 7017 7048 7164 6990 7012 7318 7030 7221 7303 7388 7632 8038 8875 9662 11061 12803 14191 14674 14846 13668 12529 11583 11431 11388 11131 10461 9719 8732 8094 7736 7464 7333 7242 7064 7252 7306 7484 7760 7718 7814 7757 7625 7591 7638 7689 7587 7587 7448 7509 7792 8107 8860 10141 11653 13254 13674 13079 12243 11061 10451 10361 10656 10384 9879 9035 8268 7719 7258 7146 7032 6701 6742 6743 6956 6751 6857 6761 6825 6676 6663 6968 6845 6760 6812 6720 6626 6844 6897 6824 6771 6858 6878 6804 6783 6823 6799 6742 6934 6960 6785 7067 6996 7140 7407 8003 9055 10031 11135 11530 11556 10886 10468 9996 9895 9662 9205 9149 8930 8492 7911 7519 7309 7339 7460 7514 7353 7557 7140 7116 6981 6900 7268 6932 6821 6807 6812 6728 6627 6626 6731 6772 6587 6631 6705 6444 6586 6633 6603 6587 6774 6613 6537 6546 6541 6567 6478 6631 6545 6676 6580 6431 6536 6561 6596 6544 6580 6664 6590 6599 6612 6479 6533 6645 6705 6699 6590 6681 6566 6646 6579 6430 6427 6488 6575 6555 6596 6490 6388 6633 6528 6675 6503 6549 6632 6518 6543 6752 6571 6511 6443 6588 6638 6577 6616 6683 6761 6539 6607 6594 6456 6692 6674 6594 6572 6768 6654 6511 6664 6651 6675 6767 6851 6704 6687 6603 6589 6960 7279 7681 8143 8998 9968 10040 9556 8758 8321 7898 8175 8282 8508 8235 7861 7341 7270 6790 6657 6669 6686 6614 6783 6703 6663 6614 6579 6578 6564 6606 6665 6599 6593 6471 6763 6454 6543 6496 6424 6472 6572 6592 6607 6426 6666 6749 6611 6527 6624 6612 6400 6440 6371 6633 6672 6525 6487 6492 6469 6450 6289 6497 6433 6528 6517 6545 6639 6636 6573 6565 6660 6680 6670 6591 6584 6756 6794 6945 6961 7332 7409 7470 7254 7341 7243 7331 7444 7294 7781 8114 8720 9128 10169 10880 11377 11354 11423 11063 10699 10740 11215 11296 11257 10667 10030 9077 8555 8311 8199 8162 7771 7453 7412 6755 6896 6735 6710 6560 6555 6654 6577 6631 6786 6621 6659 6469 6607 6776 6512 6614 6631 6609 6589 6549 6595 6589 6418 6470 6600 6483 6477 6523 6373 6300 6513 6444 6426 6461 6413 6420 6435 6604 6294 6419 6354 6579 6527 6462 6540 6349 6501 6564 6491 6349 6446 6322 6371 6499 6545 6582 6512 6395 6545 6415 6586 6244 6488 6389 6432 6499 6344 6663 6624 6344 6514 6479 6497 6455 6470 6421 6406 6558 6507 6475 6463 6683 6378 6462 6485 6601 6739 6535 6495 6704 6721 6734 6968 7179 7439 7825 8892 9434 9473 8939 8364 7702 7807 7624 7842 8185 7999 7921 7306 6954 6746 6599 6659 6521 6683 6570 6417 6504 6452 6366 6278 6431 6386 6525 6441 6550 6541 6573 6475 6197 6511 6391 6513 6469 6544 6463 6280 6634 6598 6372 6381 6578 6405 6494 6478 6439 6410 6299 6453 6466 6427 6632 6459 6644 6320 6524 6526 6532 6593 6498 6504 6414 6559 6507 6695 6544 6476 6661 6723 6765 7007 7442 7655 8012 7727 7862 8329 8687 9277 9762 9867 9660 9126 8779 8252 8216 8304 8062 8097 7854 7604 7404 7149 6831 6676 6575 6431 6519 6515 6551 6452 6537 6369 6412 6524 6538 6378 6340 6576 6378 6356 6394 6456 6564 6483 6574 6433 6420 6477 6541 6675 6619 6460 6584 6623 6619 6601 6749 6648 6815 6788 6980 7308 7692 7836 8238 8511 8739 8899 9098 9967 10650 11116 11862 11996 11585 11253 11151 11100 11537 11066 11201 10681 9950 9043 8563 8424 8311 8208 7784 7648 7386 6881 6658 6632 6540 6573 6527 6623 6758 6503 6656 6420 6469 6426 6447 6499 6558 6327 6462 6413 6323 6374 6435 6508 6498 6468 6335 6399 6273 6386 6420 6348 6273 6341 6498 6270 6443 6427 6425 6315 6268 6621 6556 6556 6443 6355 6531 6468 6356 6415 6361 6518 6499 6525 6505 6306 6403 6295 6266 6367 6379 6492 6423 6433 6498 6430 6507 6466 6383 6335 6417 6388 6478 6536 6224 6436 6355 6482 6394 6413 6371 6415 6388 6352 6222 6552 6306 6472 6429 6315 6352 6455 6533 6297 6425 6453 6479 6482 6300 6359 6241 6537 6378 6308 6324 6491 6445 6462 6386 6374 6180 6240 6325 6304 6288 6397 6390 6423 6257 6432 6319 6311 6445 6439 6318 6398 6407 6356 6482 6292 6374 6292 6441 6395 6356 6357 6504 6311 6562 6535 6351 6472 6294 6349 6485 6307 6464 6585 6365 6419 6558 6401 6402 6524 6308 6272 6231 6333 6369 6370 6308 6417 6366 6514 6738 6855 7023 7257 7512 7743 7672 7597 7549 7377 7334 7281 7265 7272 7089 7208 7022 6764 6816 6797 6624 6656 6477 6330 6565 6358 6426 6346 6464 6248 6450 6350 6259 6404 6487 6471 6394 6232 6462 6347 6583 6529 6728 6638 6465 6630 6607 6638 6591 6814 6489 6482 6383 6513 6564 6462 6574 6533 6485 6343 6360 6521 6664 6520 6564 6447 6493 6586 6630 6744 6846 6783 6768 6712 6854 7081 7435 7713 8170 8788 9551 10369 11714 12581 12960 13019 12231 11130 10258 9659 9359 9723 9896 9950 9695 9307 8568 7948 7450 7005 6806 6945 6847 6650 6822 6671 6675 6533 6484 6431 6472 6456 6676 6436 6536 6522 6444 6477 6476 6351 6522 6521 6534 6535 6244 6310 6470 6315 6306 6334 6282 6293 6525 6485 6457 6460 6422 6493 6128 6343 6311 6523 6484 6295 6405 6401 6500 6323 6275 6474 6392 6390 6233 6342 6403 6200 6480 6365 6388 6440 6427 6355 6501 6336 6416 6423 6449 6365 6416 6570 6409 6598 6432 6517 6410 6418 6519 6609 6512 6679 6818 6844 6578 6620 6667 6760 6737 6917 6884 6808 7228 7398 7906 8422 9306 10990 13386 16274 18486 19138 18546 17205 15115 13544 12045 11985 12340 12902 13194 13082 12509 11774 10614 9674 8663 7974 7709 7079 7185 7111 7033 7168 7122 7012 6939 6664 6727 6740 6675 6692 6617 6444 6751 6490 6404 6578 6530 6610 6446 6411 6589 6444 6342 6430 6363 6428 6321 6498 6449 6259 6302 6451 6483 6546 6430 6425 6607 6410 6361 6564 6385 6452 6280 6232 6476 6512 6282 6716 6336 6418 6356 6265 6298 6459 6442 6682 6506 6536 6321 6452 6519 6447 6531 6399 6506 6743 6632 6716 6888 6759 6685 6862 6922 7051 7276 7527 7840 8223 8453 8893 8920 8793 8922 8644 8673 8722 9281 10605 12074 13661 14130 13429 11484 9826 8850 8311 8495 8760 9657 10189 10037 9397 8563 7886 7350 7181 7015 6886 7000 7087 6975 7080 7016 7044 6900 6933 6892 6935 7043 7144 7083 7064 7271 7294 7560 7642 7893 8309 8934 9687 10988 12528 14163 16243 17417 18021 17874 17362 15955 14638 13267 12734 12614 12933 13020 12865 12318 11839 11054 9912 8847 8274 7733 7586 7313 7182 7026 6838 6638 6848 6761 6820 6745 6705 6649 6824 6685 6805 6728 6570 6571 6999 6974 6847 7005 7320 7577 7805 7818 7917 8049 7824 7646 7663 7681 7638 7779 8006 7922 7665 7592 7594 7336 7258 7186 7182 7200 7115 7160 7128 7088 7098 7080 7126 7306 7450 7436 7536 7761 8349 8791 9445 10767 12366 13631 14553 14990 14728 14054 13222 12071 11595 11331 11988 13061 14217 14451 14291 13122 11979 10576 9666 8913 8402 8494 8833 8889 8666 8306 7867 7550 7327 7057 7044 6789 6877 6786 6771 6743 6952 6808 6981 6944 6948 6943 6813 7066 7170 7115 7122 7244 7465 7900 8345 8719 9881 11119 13110 15424 17815 19092 19052 17568 15199 12846 11591 11202 11196 11943 12579 13125 12845 12185 11127 10111 8754 8106 7661 7552 7194 7212 6991 7042 6875 6823 6756 6833 6794 6786 6479 6639 6663 6669 6605 6629 6724 6796 7018 7214 7337 7425 7343 7635 7715 7481 7519 7455 7571 7835 8221 8696 8842 9099 9031 8908 8722 8876 9413 9695 9666 9783 9687 9393 9048 8729 8173 8038 7997 7963 8006 7832 7740 7563 7355 7160 7023 6980 6764 6510 6605 6290 6564 6547 6505 6527 6530 6621 6587 6761 6640 6436 6429 6362 6516 6474 6491 6520 6404 6540 6497 6476 6548 6452 6605 6599 6517 6501 6224 6550 6427 6429 6378 6351 6613 6610 6560 6553 6607 6649 6799 6569 6558 6652 6759 6841 6900 7044 7244 7483 7796 8468 9586 10644 12446 14417 15935 15588 13845 11957 10377 9719 9489 9654 10177 11271 12078 12185 11651 10549 9284 8440 7981 7443 7401 7277 7261 7191 6919 7274 6907 6790 6676 6563 6442 6503 6398 6522 6414 6422 6456 6313 6421 6499 6242 6222 6348 6609 6456 6423 6542 6521 6634 6400 6382 6347 6502 6326 6348 6503 6330 6361 6519 6358 6522 6415 6447 6432 6463 6546 6364 6349 6382 6515 6575 6810 6960 7253 7677 7905 8118 7958 7439 7108 6994 6730 6544 6716 6990 7177 7261 7181 7104 6984 6891 6716 6561 6517 6326 6478 6358 6361 6398 6210 6260 6297 6303 6097 6489 6421 6436 6166 6322 6408 6271 6127 6342 6458 6224 6299 6383 6063 6366 6176 6355 6518 6488 6644 6431 6383 6601 6596 6304 6374 6306 6391 6411 6400 6485 6244 6377 6389 6260 6138 6231 6147 6231 6365 6307 6195 6315 6325 6308 6338 6258 6334 6299 6136 6253 6361 6416 6189 6120 6312 6379 6432 6510 6495 6401 6564 6420 6474 6365 6298 6355 6320 6289 6306 6439 6401 6364 6228 6563 6342 6181 6143 6411 6354 6368 6138 6301 6221 6153 6100 6561 6209 6231 6308 6212 6299 6255 6270 6274 6135 6162 6237 6358 6292 6297 6348 6269 6430 6419 6327 6241 6321 6070 6278 6176 6261 6162 6190 6086 6362 6188 6258 6362 6261 6278 6223 6193 6342 6182 6422 6305 6394 6267 6114 6289 6438 6416 6376 6353 6270 6239 6372 6452 6336 6245 6321 6326 6272 6478 6359 6190 6442 6360 6489 6347 6275 6195 6284 6404 6380 6400 6255 6264 6321 6425 6179 6308 6345 6378 6429 6252 6367 6409 6289 6309 6357 6471 6470 6328 6325 6490 6470 6663 6557 6498 6731 6923 7020 7279 7753 8311 8553 8438 8345 8020 7554 7340 7315 7402 7340 7814 8193 8382 8788 8986 9034 9108 9649 10197 10963 11489 12109 12355 12333 11778 11266 10635 9631 9139 8803 8931 9089 9079 9360 9337 9315 8813 8348 8112 7712 7563 7350 6973 7400 7232 7278 7274 6914 6979 7067 6835 6829 6867 6614 6678 6762 7024 6969 7062 7055 7181 7502 7919 8155 8865 9102 9344 9323 8785 8360 7648 7404 7440 7632 7801 7874 8165 8122 8150 8124 8116 7707 7708 7510 7831 8046 8654 9395 10092 10526 10735 10548 9957 9183 8419 8027 7765 7871 7969 8188 8291 8418 8524 8504 8168 7843 7761 7456 7296 7166 7180 7049 7058 6849 6717 6734 6720 6691 6883 6767 6646 6641 6742 6649 6730 6629 6588 6532 6665 6545 6392 6323 6317 6484 6347 6461 6504 6323 6542 6315 6323 6434 6463 6363 6354 6471 6299 6070 6385 6556 6319 6422 6506 6411 6315 6462 6410 6267 6510 6346 6325 6618 6605 6528 6605 6719 6779 6704 6954 6951 7157 7596 7796 8455 8751 9227 9235 9355 9477 9451 9502 9223 9446 9305 9606 10257 10662 10878 10802 10676 10131 9515 9147 8571 8268 8063 7982 8043 8120 8282 8093 7945 7671 7466 7121 7009 6737 6854 6663 6597 6710 6533 6557 6491 6428 6322 6342 6314 6369 6480 6542 6319 6378 6323 6422 6512 6363 6364 6573 6694 6531 6601 6893 6966 7265 7537 7594 7619 7785 7724 7867 7816 7707 7655 7384 7363 7395 7603 7929 8131 8366 8871 9388 9420 9572 9695 9530 9354 9106 9328 9667 9986 10177 10409 10543 10611 10435 10506 10509 10547 10401 10248 10153 9931 9428 9249 8794 8770 8760 8792 8972 9447 9838 10130 10262 10446 10022 9824 9401 8947 8313 7925 7447 7475 7522 7584 8018 8030 7893 7868 7643 7413 7355 7007 6694 6634 6593 6428 6393 6481 6272 6309 6338 6333 6146 6293 6172 6467 6492 6347 6370 6393 6369 6227 6286 6383 6501 6419 6381 6479 6426 6545 6603 6453 6677 6729 6843 6999 7210 7345 7588 8234 8952 9844 11179 11969 12441 11683 10912 10041 9036 8364 7844 7770 7806 8225 8525 8945 9080 9159 9176 8594 8041 7453 7147 6737 6510 6372 6726 6515 6436 6422 6307 6542 6372 6283 6384 6428 6314 6283 6462 6627 6637 6644 7056 7515 7733 8212 8640 9027 8983 8536 8140 7736 7345 7314 7349 7340 7319 7560 7494 7842 7808 7729 7452 7262 7063 6890 6860 6877 6719 6659 6533 6616 6609 6529 6581 6586 6459 6528 6497 6437 6412 6511 6678 6720 6897 6626 6816 6944 7106 7303 7594 7904 8618 9249 10032 11237 12036 13000 13583 13242 13073 12626 12037 11632 10895 10131 9681 9699 9734 9742 10053 9903 10071 9747 9580 9153 8773 8178 7809 7521 7073 6824 6667 6806 6833 7122 7206 7475 7848 7946 7700 7443 7160 6860 6634 6692 6803 6558 6476 6550 6756 6934 6754 6937 6704 6569 6349 6298 6245 6249 6192 6265 6174 6212 6205 6252 6110 6067 6383 6137 6240 6152 6167 6017 6240 6276 6293 6075 5953 6105 6110 6025 6218 6131 6233 6051 6150 6019 6005 6077 6166 6128 6102 6097 6111 6108 6060 6072 6152 6189 6086 6069 6145 6100 6101 6090 6043 6121 6236 5923 6036 6202 6142 6049 6064 6038 6099 6149 6114 6300 6297 6345 6158 6142 6056 5911 6226 6164 6195 6353 6195 6342 6314 6116 6043 6124 6266 6241 6097 6106 6086 6160 6134 6180 6201 6197 6318 6206 6149 6150 6336 6268 6321 6566 6465 6475 6485 6635 6785 6862 7060 7101 7336 7568 7381 7395 7095 6915 6886 6796 6855 6973 6997 7165 7298 7440 7658 7918 8258 8360 8215 7884 7524 7496 6902 6953 6741 6714 6755 6787 6711 6912 7033 7148 7122 6969 6749 6568 6590 6370 6419 6247 6435 6287 6252 6126 6096 6215 6132 6158 6324 6083 6148 6080 6042 6087 6083 6139 6101 6122 6109 6031 6015 6080 6244 5957 5978 5971 6249 6124 5976 6074 6217 6148 6194 6203 6282 6451 6653 6714 6810 7023 6994 7220 7085 7322 7147 7165 6789 6607 6831 6525 6475 6489 6427 6426 6603 6705 6511 6652 6529 6588 6705 6443 6299 6231 6162 6302 6074 6305 6212 6131 6152 5928 6057 6117 6125 6037 6221 6110 6200 6096 6178 6075 6123 5872 5908 6095 5990 6082 5866 6050 6015 6149 6087 6070 6179 6078 5943 5983 6138 6198 6057 6068 5961 6116 6117 6093 6177 6275 6036 6053 6122 6185 6002 6234 6104 6088 6249 6399 6202 6273 6105 6203 6162 5996 5990 6033 6080 6195 5985 6095 5908 5841 6042 6099 6071 6149 5907 6023 6034 6047 5787 6015 5982 5981 5802 5904 5974 5988 5861 6012 6115 5934 5875 5938 5939 5886 6007 6087 5985 5932 5860 5872 6164 6112 5852 5962 6008 5935 6168 5983 5893 6004 6045 6062 5944 6043 5954 6027 5914 5874 6039 6157 6034 6046 6198 6222 6023 5973 5991 5974 5997 6051 5995 6137 5710 5935 6007 6143 6006 6030 6008 6170 6048 6101 6106 6290 6055 6021 6163 5948 6012 5938 6057 5912 6045 6036 6120 6008 5966 6047 6128 6221 6166 6081 5854 5784 5986 5930 6132 6136 5924 6072 6040 5968 5940 6018 6026 6008 6102 5948 5855 5795 5853 6018 5951 5846 5929 5962 5945 5997 6094 5992 5924 5909 6021 6143 5944 6084 5957 5930 5952 6081 5958 5858 6121 6048 5976 5856 6086 6285 6151 6123 6237 6336 6114 6142 6012 6040 5984 6038 5996 6192 6104 5942 6060 5967 5883 6140 6039 5951 5979 6059 6132 6176 5980 6006 6202 6115 6078 6077 6011 5992 6004 6135 5953 6209 5837 5982 6036 5989 5852 5793 6012 5940 5934 6125 6096 6046 5833 6099 5996 5883 5885 5973 6010 5982 6099 5980 5924 6069 6128 6032 6076 5911 6166 6070 5924 6059 5958 6034 5785 5964 6141 6127 6124 6090 6033 6045 5961 5814 5991 6011 5995 6021 5913 6085 6059 6167 6199 6134 6059 6029 6049 6179 6125 5980 5862 6103 6036 6073 6145 6119 6027 6069 6124 6085 6026 6194 6155 6360 6268 6552 6387 6482 6381 6575 6549 6656 6793 6842 7019 7192 7261 7218 7188 7020 7137 7220 7202 6938 6859 6690 6653 6620 6603 6886 6947 7028 7173 7277 7279 7618 8067 8284 8478 8491 7940 7602 7196 6957 6948 6751 6922 6931 7231 7397 7570 7956 8382 8659 8689 8670 8483 8419 7962 7665 7510 7165 7064 6974 6999 6897 7037 7084 7001 7031 6994 7123 7012 7036 6741 6617 6649 6585 6644 6916 6909 7063 7526 7702 7762 7708 7411 7108 6778 6505 6485 6540 6380 6506 6428 6544 6519 6755 6901 7003 6907 6864 6681 6752 6494 6314 6369 6377 6295 6370 6219 6135 6085 6164 6442 6246 6271 6085 6268 6179 6165 6296 6274 6120 6163 6153 6009 6218 6169 6066 6184 6074 6279 6287 6286 6533 6443 6456 6530 6329 6503 6465 6503 6587 6565 6604 6572 6651 6771 6627 6537 6711 6561 6787 6806 6777 6729 6506 6675 6589 6548 6484 6369 6489 6308 6334 6443 6366 6651 6415 6411 6390 6256 6049 6120 6070 6015 5991 6263 5963 6030 5978 6062 6200 6079 6002 6184 5952 6099 6048 6162 6006 5983 5882 5963 6046 5898 5837 5957 6060 6006 5949 6112 6026 6023 5984 5924 6140 5905 6195 6231 6195 6107 6212 6008 6115 6259 6240 6101 6299 6220 6392 6349 6358 6450 6473 6606 6555 6362 6410 6419 6204 6527 6406 6337 6738 6699 6793 6923 7404 7634 7979 8267 8416 8406 8343 7934 8041 7657 7469 7289 7137 7019 6943 7027 7006 7112 7257 7318 7247 7189 7288 7000 6906 6648 6703 6634 6480 6319 6347 6241 6223 6178 6111 6095 6088 6159 5960 6044 6071 6109 6024 6037 6081 5978 6051 6135 6166 6004 6212 6225 6228 6509 6671 6639 6561 6505 6376 6144 6191 6085 6197 6258 6189 6020 6138 6256 6284 6149 6294 6335 6299 6250 6331 6051 5975 6005 6203 6037 6088 6015 6198 6239 6122 6058 6357 6029 6054 6134 6331 6081 6025 6031 6189 6062 6345 6228 6326 6120 6223 6531 6565 6644 6762 6840 6943 6983 6919 7147 7056 6944 7096 7084 6858 6989 6862 6682 6607 6437 6608 6471 6641 6517 6584 6478 6504 6633 6530 6529 6584 6553 6533 6476 6392 6267 6186 6134 6155 6123 6125 5940 6048 6016 6087 6157 6263 6054 6259 6168 6229 6295 6235 6200 6262 6120 6264 6062 6061 6148 6199 6098 6164 6281 6278 6429 6510 6602 6634 6678 6905 6709 6904 6855 6826 7026 6919 7139 7127 7070 7259 7224 7189 7201 7391 7138 7199 7262 7043 7108 6959 6860 6770 6913 6763 6776 6750 6611 6451 6688 6704 6703 6557 6604 6400 6385 6371 6314 6305 6102 6234 6182 6118 6224 6380 6327 6089 5939 6045 5953 5980 6113 5970 5994 5975 6073 5918 6135 6078 6022 6132 6239 6153 6132 6183 6063 5995 5825 5869 5792 5886 5866 5803 5927 5929 5948 5919 6156 6104 6038 6046 5999 5981 5945 5902 5842 5920 5903 5782 5969 5921 5856 5786 5794 6013 5706 5888 5989 5874 6071 6024 5975 5902 5821 5993 5917 5824 5996 5969 5877 5885 5897 5806 5897 5831 5937 5925 5835 5901 5939 5870 5894 6098 6076 6179 6134 6229 6241 6282 6226 6280 6151 5996 6086 6069 6041 6026 6006 6034 6124 6211 6038 6210 6060 6096 6082 6055 6160 6126 5983 6163 6129 6040 5965 5974 5849 6043 5861 5871 5944 5968 5995 5996 5843 5902 5970 6029 5881 6138 6143 5898 6186 6187 6125 6234 6055 6292 6223 6131 6079 6252 6201 6275 6035 6114 6040 6148 6351 6127 6242 6324 6502 6326 6473 6552 6592 6747 6734 6768 7070 7208 7169 7267 7190 7287 7351 7062 6937 6687 7094 7030 7307 7434 7385 7501 7392 7220 7032 7020 6958 6847 6854 6812 6595 6443 6437 6464 6529 6408 6557 6501 6733 6552 6406 6560 6379 6312 6163 6189 6259 6349 6213 6056 6174 6151 6110 6010 6216 6153 6048 5998 6070 6255 6154 6470 6394 6673 6722 6999 7156 6996 7058 7121 6900 6632 6482 6477 6309 6113 6143 6027 6252 6202 6338 6477 6492 6463 6466 6368 6209 6350 6241 6173 6113 6004 6046 5967 6081 5843 5937 5812 5814 6029 5908 5894 5994 5941 6009 5758 5935 5965 5796 5615 5689 5897 5753 5835 5690 5877 5855 5848 5890 5893 5905 5947 5875 5812 5784 6120 6047 5960 6026 5913 5850 5816 5871 5924 5745 5894 5856 5969 5780 5883 6104 6024 5846 6018 5929 5850 5941 5953 6080 5880 6044 5972 5930 6035 6074 5941 5970 5881 6093 6032 6048 5960 5991 6143 6052 6070 6128 6207 6164 6258 6217 6208 6325 6527 6557 6616 6655 6863 7072 7019 6915 7024 7005 6963 6937 6766 6727 6709 6586 6462 6593 6584 6654 6647 6567 6674 6550 6730 6857 6823 6602 6746 6580 6606 6500 6532 6364 6359 6177 6009 6182 6030 5933 6162 6176 6218 6216 6171 6169 6180 6240 6195 6392 6311 6501 6561 6347 6496 6575 6681 6848 6800 6945 6916 6861 6873 6720 6640 6579 6511 6349 6389 6537 6611 6657 6756 6772 6813 6734 6773 6679 6757 6435 6617 6600 6492 6351 6419 6352 6185 6309 6411 6192 6236 6180 6321 6349 6162 6208 6112 5962 5968 6137 5997 6093 5990 5999 6005 5975 6018 5893 5874 5915 5978 5945 5977 6031 6043 6012 6019 6147 6070 5846 6077 6161 6349 6419 6467 6556 6517 6624 6616 6731 6890 6942 6851 6855 6666 6765 6845 6698 6597 6578 6615 6691 6747 6809 6970 6899 6790 6661 6713 6590 6589 6600 6465 6572 6417 6475 6334 6381 6305 6376 6215 6181 6091 6074 6320 6224 6297 6374 6466 6409 6468 6487 6362 6543 6323 6299 6305 6392 6146 6254 6345 6324 6472 6358 6457 6592 6675 6615 6855 6729 6807 6825 6574 6733 6815 6638 6623 6505 6526 6383 6380 6403 6253 6444 6290 6283 6479 6438 6369 6364 6263 6205 6388 6402 6199 6355 6195 6254 6022 6148 6102 5991 6061 6179 6064 5904 6062 6045 6058 6189 6152 6122 5907 6033 5947 5864 5957 6042 5939 5850 5916 6009 5920 5905 5932 5933 6020 6053 6153 6017 5995 6237 6188 6270 6355 6144 6148 6217 6272 6360 6319 6351 6185 6192 5883 6305 6209 6212 6242 6292 6277 6501 6347 6375 6245 5948 6255 6347 6230 6186 6249 6160 6142 6145 6214 6283 6213 6059 6143 6190 6085 6166 6110 5865 5943 5915 6056 6103 6080 6153 6046 6283 6335 6214 6196 6327 6429 6334 6603 6525 6636 6562 6474 6391 6480 6283 6134 6095 6179 5982 6116 6216 5940 6013 6032 5998 6328 6205 6198 6300 6296 6215 6077 5918 6079 6190 6062 6035 6007 5970 5987 5867 5908 5831 5827 5928 6000 5921 5972 5807 6070 5856 5962 5907 5947 5956 5809 5939 5929 5807 5986 5884 5789 5821 5796 5801 5767 5784 5815 5854 5884 5822 5846 5865 5878 5770 5856 5973 5945 5856 5728 5810 5714 5831 5652 5891 5819 5903 5857 5749 5784 5806 5900 5757 6018 5993 5862 5821 5883 5760 5753 5812 5998 5978 5912 5957 6022 6072 6118 6067 5908 6111 5995 5987 5918 5934 5988 5869 5874 5947 5995 6030 6110 6288 6233 6203 6268 6319 6305 6098 6250 6272 6230 6149 6347 6302 6238 6361 6556 6495 6385 6464 6310 6312 5976 6123 5980 6231 5967 6039 5863 6123 6101 6083 6026 6039 5979 5983 5958 6035 6105 5979 5890 5924 5758 5928 5728 5781 5969 5855 5880 5957 5829 5736 5874 5801 5960 5723 5983 5885 5920 6070 5926 5870 5786 5945 5875 5927 5852 5901 6156 5962 5929 5875 5870 6024 5943 5978 5839 5934 5882 5857 5968 5842 5817 6109 5889 5764 5937 6017 5953 5724 5884 5827 6038 5949 5976 6022 6116 6115 6153 6027 6090 6018 5775 5834 5843 5815 5906 5781 5811 5804 5970 5738 5841 5833 6023 5933 5949 6081 6006 5963 5946 6047 5791 5853 5789 5753 5940 5836 5872 5933 5711 5927 5769 5865 5855 5883 5794 5923 5868 6034 6053 5943 6048 5890 5993 5976 5923 5977 5962 5983 6011 6059 5973 6123 6107 6102 6176 6133 6151 6213 6052 6174 6085 6137 6007 6284 6080 5965 6270 6010 6177 6241 6227 6232 6501 6521 7035 6839 6812 7006 7270 7167 6969 6969 6995 6497 6682 6474 6277 6424 6558 6391 6394 6469 6436 6539 6358 6704 6756 6851 6889 6969 6871 6785 6809 6771 6511 6455 6341 6282 6313 6223 6098 6168 6227 6106 6079 6172 6158 6180 5985 6061 6152 6022 6217 5973 5963 6081 6132 5913 6017 5974 5860 6004 5984 5920 6045 5830 5776 5977 6029 6060 5964 5892 5622 6034 6164 6034 6015 5985 6009 6074 6102 5989 6151 6051 6008 6033 5992 6014 5959 6130 6021 6244 6268 6137 6326 6238 6176 6272 6239 6546 6606 6656 6695 6557 6624 6725 6413 6357 6440 6183 6129 6180 6044 6123 6153 5994 6044 6192 6049 6220 6227 6097 6140 6255 6246 6122 6115 6294 6034 5987 6089 6036 6073 5913 5933 5910 5893 6124 5963 6089 6234 6187 6215 6234 6304 6251 6323 6363 6479 6291 6268 6176 6021 6180 6201 6235 6214 6489 6272 6254 6154 6200 6250 6155 6310 6297 6247 6294 6207 6357 6261 6264 6195 6192 6291 6420 6427 6193 6131 6220 6299 6437 6554 6502 6199 6355 6304 6259 6353 6220 6158 6243 6342 6279 6194 6279 6244 6050 6236 6081 6306 6500 6539 6442 6418 6713 6886 7172 6910 6903 6743 6740 6808 6475 6342 6329 6146 6053 6127 6134 6127 6098 6198 6328 6210 6367 6421 6473 6470 6588 6605 6715 6864 6742 6808 6854 6595 6428 6369 6044 6123 6138 6067 6205 6060 6047 5879 5893 5867 5816 5969 6025 6091 6015 6204 6049 6023 6170 6146 5809 5896 5980 6025 5763 5770 5881 5725 5779 5694 5693 5800 5931 5902 6011 5876 5891 5913 5833 5731 5661 5782 5739 5794 5710 5796 5975 5994 5753 5725 5874 5888 5963 5738 5776 5954 5936 6039 6029 5896 5727 5846 5897 5996 5818 5831 5769 5717 5716 5942 5902 5795 5884 5967 5787 5715 5823 5640 5860 5889 5666 5815 5807 5786 5907 5768 5868 5890 6073 6001 5911 5849 5943 5832 5799 5801 6018 5973 6037 5996 6063 5966 6144 6117 5898 6012 6001 6037 6105 6154 6182 6029 6029 6111 5751 6041 5847 6010 5913 6009 6035 6093 6074 6087 6014 5985 6111 6114 6097 6164 6059 6115 6174 6253 6296 6453 6249 6189 6351 6510 6356 6142 6100 6096 6166 6136 6150 5946 5992 6261 6171 6189 6191 6331 6335 6336 6382 6553 6425 6553 6553 6720 6761 6469 6637 6558 6477 6455 6437 6363 6467 6314 6442 6440 6504 6639 6549 6512 6695 6822 6526 6626 6682 6576 6558 6415 6392 6319 6379 6295 6438 6198 6227 6147 6120 6074 6111 6090 6201 6062 5991 6086 6418 6116 6172 6073 5939 5925 5985 5926 5994 6075 5937 6044 6085 5750 5907 5788 5799 5889 5785 5881 5928 5991 5857 5782 5876 5828 5847 6012 6125 6092 5927 5844 5750 6056 5928 5968 5987 5885 5862 5906 5996 6010 5742 5855 6088 5808 5919 5819 5704 5916 5971 5880 5685 5890 5838 6007 5764 5859 5861 5756 6037 5873 5771 5881 5658 5759 5691 5950 5724 5748 5889 5801 5838 6018 5825 5820 5733 5898 5930 5944 5894 5931 5937 6055 6042 6095 6067 6072 5893 6078 6170 6222 6173 6401 6187 6280 6217 6365 6307 6522 6246 6199 6324 6163 6108 6121 6146 6083 5958 5915 5957 5964 5809 6014 6312 5976 5835 5896 5958 6070 6004 5918 5956 5956 6096 6072 5769 5992 5876 5747 5793 5955 5927 5885 5866 5781 5842 5794 5841 5803 5822 5912 5689 5854 5986 6035 5986 5918 6078 6182 6208 6055 6022 6288 6126 6304 6216 6394 6477 6262 6296 6436 6259 6300 6248 6348 6272 6252 6320 6166 6343 6228 6202 6111 6237 6030 6212 6382 5986 6036 6311 6078 6156 6204 6099 6172 6238 6232 6334 6336 6329 6372 6297 6439 6272 6316 6096 6367 6028 6075 6094 5959 5873 5893 5929 5828 5902 5973 6106 5994 6199 6141 6171 6233 6096 6246 6171 6270 6266 6443 6512 6291 6296 6439 6146 6287 6129 6093 6018 5955 5836 6083 5917 5904 5979 5892 6033 6190 6125 6079 6212 6201 6294 6246 6456 6424 6436 6395 6511 6532 6258 6253 6351 6089 6298 6127 5951 6089 5888 5893 5802 5935 5794 5962 5778 5973 6005 5832 5947 6068 5974 6029 5906 6007 5986 6104 6054 6104 5843 5922 5781 5759 5719 5723 5787 5740 5846 5821 5762 5847 5835 5702 5820 5849 5742 5825 5890 5814 5722 5821 5752 5762 5718 5805 5713 5696 5850 5721 5665 5876 5746 5721 5747 5838 5705 5680 5647 5831 5695 5760 5888 5702 5805 5943 5957 5926 5800 5711 5900 5821 5758 5956 5640 5864 5848 5777 5928 5856 5687 5884 5980 5976 5941 5936 5973 6009 6132 5992 6049 6126 6093 6035 5967 6021 6041 5979 6109 5934 5986 5913 5922 5861 6090 6058 6109 5999 6062 5864 6114 6028 5969 5889 6086 6057 6207 5996 5959 6018 6148 6026 6027 5833 6137 6190 6125 6088 6157 6054 5939 6099 5924 5936 5934 6117 5799 5871 5831 5813 5793 5876 5876 5866 5798 5820 5898 5739 5985 5889 5868 5858 5946 5701 5798 5840 5898 5780 5761 5701 5741 5743 5647 5682 5705 5813 5719 5711 5602 5700 5737 5838 5710 5847 5700 5974 5949 5849 5814 5669 5988 5896 5884 5999 5948 6045 6023 5963 6108 6086 6045 6070 6029 5941 5900 5939 6042 5925 6004 6122 6155 6193 6126 6143 6114 6162 6106 6140 6308 6338 6148 6100 6416 6495 6258 6117 6092 6116 6047 6137 5863 5957 6013 5947 6092 5816 5852 5899 5901 5910 5873 6053 5800 6008 5849 5852 6015 5964 6099 5922 5757 5705 5862 5862 5789 5848 5807 5870 5692 5803 5560 5763 5948 5912 5918 5637 5670 5647 5671 5854 5777 5772 5713 5689 5807 5709 5730 5609 5696 5687 5719 5685 5673 5620 5632 5713 5758 5551 5615 5711 5914 5789 5587 5591 5855 5871 5687 5668 5703 5605 5667 5664 5792 5799 5863 5746 5715 5714 5654 5750 5829 5731 5761 5732 5761 5620 5863 5828 5744 5698 5820 5797</intensities>
			</dataPoints>
			<nonAmbientPoints type="Temperature" unit="K">
[...]
			</nonAmbientPoints>
		</scan>
	</xrdMeasurement>
</xrdMeasurements>