File: powder_X-ray_diffraction/variable-temperature_experiments/NaNbO2F2/raw_data/230°C.xrdml
<?xml version="1.0" encoding="UTF-8"?>
<xrdMeasurements xmlns="http://www.xrdml.com/XRDMeasurement/1.7" xmlns:xsi="http://www.w3.org/2001/XMLSchema-instance" xsi:schemaLocation="http://www.xrdml.com/XRDMeasurement/1.7 http://www.xrdml.com/XRDMeasurement/1.7/XRDMeasurement.xsd" status="Completed">
	<comment>
		<entry>Configuration=XRK900, Owner=User-1, Creation date=12/01/2015 16:52:44</entry>
		<entry>Goniometer=Theta/Theta; Minimum step size 2Theta:0.0001; Minimum step size Omega:0.0001</entry>
		<entry>Sample stage=AP XRK-900 with z-axis; Minimum step size Z:0.001</entry>
		<entry>Diffractometer system=EMPYREAN</entry>
		<entry>Measurement program=C:\PANalytical\Data Collector\Programs\Gwen\NaNbO2F2-Lent.xrdmp, Identifier={26D14ECE-D3C8-438C-91CA-8651EAF68C7D}</entry>
		<entry>Batch program=C:\PANalytical\Data Collector\Programs\Gwen\Thermodiff-Ouail.xrdmp, Identifier={9701CF17-19F5-4DD4-A8E1-7279D1FD2F5E}</entry>
	</comment>
	<sample type="To be analyzed">
		<id></id>
		<name></name>
		<preparedBy></preparedBy>
	</sample>
	<xrdMeasurement measurementType="Scan" status="Completed" sampleMode="Reflection">
		<comment>
			<entry>PHD Lower Level = 4.02 (keV), PHD Upper Level = 12.07 (keV)</entry>
		</comment>
		<usedWavelength intended="K-Alpha 1">
			<kAlpha1 unit="Angstrom">1.5405980</kAlpha1>
			<kAlpha2 unit="Angstrom">1.5444260</kAlpha2>
			<kBeta unit="Angstrom">1.3922500</kBeta>
			<ratioKAlpha2KAlpha1>0.5000</ratioKAlpha2KAlpha1>
		</usedWavelength>
		<incidentBeamPath>
			<radius unit="mm">240.00</radius>
			<xRayTube id="1010048" name="Empyrean Cu LFF HR (9430 033 7310x) DK420743">
				<tension unit="kV">45.0</tension>
				<current unit="mA">30.0</current>
				<anodeMaterial>Cu</anodeMaterial>
				<focus type="Line">
					<length unit="mm">12.0</length>
					<width unit="mm">0.4</width>
					<takeOffAngle unit="deg">6.0</takeOffAngle>
				</focus>
			</xRayTube>
			<sollerSlit id="21010001" name="Soller slits 0.02 rad.">
				<opening unit="rad">0.0200</opening>
			</sollerSlit>
			<mask id="22030010" name="Fixed mask 20 mm">
				<width unit="mm">20.00</width>
			</mask>
			<antiScatterSlit id="22010003" name="Fixed slit 1Â°" xsi:type="fixedAntiScatterSlitType">
				<height unit="mm">1.52</height>
			</antiScatterSlit>
			<divergenceSlit id="22010012" name="Programmable divergence slit" xsi:type="fixedDivergenceSlitType">
				<distanceToSample unit="mm">140.00</distanceToSample>
				<angle unit="deg">0.5</angle>
			</divergenceSlit>
		</incidentBeamPath>
		<diffractedBeamPath>
			<radius unit="mm">240.00</radius>
			<antiScatterSlit id="22090010" name="AS slit 8.0 mm (PIXcel)" xsi:type="fixedAntiScatterSlitType">
				<height unit="mm">8.00</height>
			</antiScatterSlit>
			<sollerSlit id="21010001" name="Soller slits 0.02 rad.">
				<opening unit="rad">0.0200</opening>
			</sollerSlit>
			<filter id="20030001" name="Large beta-filter Nickel">
				<material>Ni</material>
				<thickness unit="mm">0.020</thickness>
			</filter>
			<detector id="7010019" name="PIXcel1D-Medipix3 detector" xsi:type="rtmsDetectorType">
				<phd unit="%">
					<lowerLevel>25.0</lowerLevel>
					<upperLevel>75.0</upperLevel>
				</phd>
				<mode>Scanning</mode>
				<activeLength unit="deg">3.3482</activeLength>
			</detector>
		</diffractedBeamPath>
		<scan appendNumber="0" mode="Continuous" scanAxis="Gonio" status="Completed">
			<header>
				<startTimeStamp>2022-05-15T06:16:58+02:00</startTimeStamp>
				<endTimeStamp>2022-05-15T09:17:24+02:00</endTimeStamp>
				<author>
					<name>User</name>
				</author>
				<source>
					<applicationSoftware version="5.5a">Data Collector</applicationSoftware>
					<instrumentControlSoftware version="8.1b 20190506">EMPYREAN</instrumentControlSoftware>
					<instrumentID>0000000011159748</instrumentID>
				</source>
			</header>
			<dataPoints>
				<positions axis="2Theta" unit="deg">
					<startPosition>9.99846514</startPosition>
					<endPosition>99.99342261</endPosition>
				</positions>
				<positions axis="Omega" unit="deg">
					<startPosition>4.99923257</startPosition>
					<endPosition>49.99671130</endPosition>
				</positions>
				<positions axis="Z" unit="mm">
					<commonPosition>8.912</commonPosition>
				</positions>
				<commonCountingTime unit="seconds">386.070</commonCountingTime>
				<intensities unit="counts">7635 7619 7491 7550 7635 7534 7560 7542 7700 7788 8001 7878 7740 7702 7674 7702 7670 7861 7902 7597 7647 7668 7674 7552 7540 7539 7662 7599 7680 7669 7668 7790 7599 7584 7643 7554 7523 7786 7757 7707 7587 7550 7682 7741 7716 7533 7446 7641 7705 7778 7752 7373 7596 7727 7867 7692 7701 7612 7732 7533 7775 7778 7815 7789 7713 7758 8093 8095 7943 8276 8251 7956 7995 8220 8284 8222 8365 8349 8307 8606 8673 8921 9237 9544 10033 10669 11663 12852 14582 17356 21901 28258 39473 54465 70102 79460 79135 68058 52734 37608 25376 17179 12827 10436 9416 8718 8754 8808 8551 8439 8197 8103 8068 7912 8034 7775 7855 7707 7867 7708 7761 7686 7760 7791 7736 7546 7847 7806 7884 7873 7898 7843 7898 7909 7822 7941 8028 7930 7934 7762 7863 7919 7953 8022 8013 8022 7991 8008 8020 8037 8059 7848 7937 7825 7908 7858 7921 8234 8329 8104 8174 8030 8275 8032 7887 7996 8152 7968 7936 8016 8070 8312 8150 8066 8047 8096 8055 8072 7992 8092 8073 8169 7883 8072 8014 8031 8151 8130 8057 8122 8051 7895 8056 8016 7995 8000 8199 8217 8087 7987 8054 8103 7943 7967 7983 8020 7851 7925 8011 7943 7978 8028 8022 7905 8108 8068 8110 7916 7912 8010 7923 7986 8060 8133 8043 7896 8000 8017 7916 7969 8098 8071 7940 7930 8043 7967 8015 7939 7849 7944 7767 7866 7872 7819 8088 7956 7858 7887 7906 7986 7936 8093 7868 7722 7827 7795 7821 7678 7999 7830 7859 7966 8026 7841 7880 7960 7865 7930 7736 7796 7992 7834 7759 7819 7899 7909 7976 7815 7688 7990 8012 7946 8005 8066 8016 8034 7950 7951 7762 7926 7836 7750 7967 7960 7878 7959 7765 7754 7899 7722 7930 7873 7861 7993 7891 7767 7796 8015 7804 8079 7938 7930 8014 7946 7779 7874 7947 7884 7736 7886 7863 7767 7911 7781 7903 7822 8053 7921 7842 7887 7703 7721 7849 7706 7869 7926 8120 7990 8056 8134 8405 8496 8903 9125 9420 9497 9533 9540 9065 8842 8504 8319 7969 7958 7992 7821 7852 7872 7927 7944 7915 7737 7683 7823 7896 7623 7648 7646 7764 7689 7920 7698 7700 7596 7823 7848 7732 7789 7541 7618 7736 7775 7749 7812 7639 7669 7792 7772 7727 7915 7732 7676 7621 7638 7637 7555 7813 7693 7651 7579 7609 7504 7551 7601 7764 7570 7883 7803 7479 7608 7771 7643 7704 7823 7786 7866 7628 7896 7636 7663 7796 7546 7812 7716 7604 7617 7690 7983 7892 7601 7706 7590 7671 7568 7537 7475 7709 7732 7625 7622 7575 7621 7806 7886 7658 7667 7547 7564 7725 7619 7487 7702 7762 7657 7696 7741 7686 7798 7754 7591 7697 7754 7741 7599 7579 7610 7633 7587 7650 7837 7680 7726 7530 7586 7530 7520 7572 7609 7460 7505 7540 7372 7728 7768 7695 7707 7576 7744 7836 7655 7687 7676 7729 7567 7820 7684 7595 7476 7660 7486 7561 7537 7516 7739 7629 7614 7683 7576 7670 7673 7685 7710 7659 7560 7798 7994 7888 8046 8040 8197 7946 7796 7770 7741 7805 7501 7542 7533 7420 7469 7421 7441 7449 7438 7367 7408 7564 7537 7550 7397 7455 7470 7481 7453 7432 7592 7570 7491 7416 7512 7613 7423 7377 7340 7592 7356 7498 7598 7455 7333 7406 7293 7303 7567 7449 7462 7556 7373 7412 7563 7339 7382 7317 7362 7460 7416 7310 7394 7471 7435 7365 7448 7351 7530 7234 7345 7166 7410 7356 7390 7345 7311 7337 7353 7353 7461 7346 7461 7430 7417 7466 7470 7589 7440 7374 7405 7359 7266 7331 7351 7421 7199 7058 7436 7271 7260 7447 7303 7265 7470 7171 7090 7311 7435 7362 7142 7565 7261 7178 7391 7180 7295 7214 7306 7284 7161 7330 7287 7235 7226 7205 7228 7402 7263 7106 7082 7500 7214 7338 7096 7437 7282 7251 7170 7175 7038 7097 7231 7418 7163 7205 7469 7043 7065 7014 7227 7147 7259 7165 7138 7129 7241 7257 7251 7148 7414 7184 7165 7119 7176 7235 7292 7237 7142 7230 7283 7369 7193 7181 7225 7176 7129 7230 7480 7375 7415 7456 7489 7638 7721 7633 7724 7718 7810 7778 7762 7524 7479 7763 7602 7441 7527 7837 7732 7591 7621 7576 7595 7596 7688 7548 7669 7896 7733 7764 7816 7759 7943 7986 8132 8239 8363 8477 8631 8598 8817 9154 9217 9695 10724 11603 13547 16801 20855 28213 39386 53626 70705 87070 97347 95044 83822 72143 60704 47053 33804 23869 17084 13010 11114 10356 9656 9382 9015 8852 8895 8510 8294 8088 8001 7970 8089 8041 7878 7712 7940 7848 7809 7737 7834 7750 7884 7531 7466 7479 7503 7411 7372 7436 7585 7582 7454 7448 7507 7793 7569 7337 7491 7372 7594 7515 7245 7280 7537 7320 7353 7498 7710 7537 7392 7461 7417 7524 7475 7430 7508 7583 7671 7363 7472 7438 7545 7358 7440 7552 7450 7584 7353 7297 7355 7462 7410 7397 7303 7360 7471 7412 7335 7180 7374 7539 7554 7456 7310 7375 7170 7433 7398 7323 7504 7388 7416 7362 7520 7556 7392 7304 7366 7497 7412 7391 7355 7489 7564 7578 7330 7459 7452 7434 7346 7502 7433 7407 7558 7410 7485 7394 7545 7443 7497 7410 7565 7327 7339 7406 7391 7337 7282 7403 7504 7565 7305 7453 7465 7529 7584 7397 7447 7504 7590 7570 7568 7555 7639 7721 7532 7490 7426 7505 7582 7569 7433 7492 7420 7526 7288 7481 7451 7472 7435 7605 7277 7363 7432 7475 7367 7259 7278 7425 7184 7383 7291 7239 7360 7442 7426 7461 7310 7389 7415 7508 7695 7729 7642 7618 7797 7581 7807 7901 8025 8216 8625 9088 9967 11350 13777 18126 23239 29525 32570 32828 30044 26975 24239 21279 17756 14314 11511 9706 8739 8140 8009 7662 7907 7704 7738 7757 7681 7531 7649 7490 7467 7414 7224 7399 7369 7311 7337 7620 7332 7512 7416 7431 7459 7368 7510 7358 7411 7535 7308 7349 7309 7758 7679 7431 7441 7526 7476 7668 7468 7557 7553 7476 7597 7577 7495 7381 7578 7630 7556 7670 7514 7472 7420 7581 7646 7681 7615 7641 7591 7669 7684 7527 7626 7654 7628 7604 7838 7681 7701 7980 7980 8132 8289 8452 8727 9382 10448 12583 16094 20549 26050 29345 29392 26358 23516 21880 20251 17826 14481 11652 10086 9614 9131 8914 9061 9215 9604 10468 11689 14143 18926 25966 34095 39718 38732 33509 30167 28156 25816 21834 17082 13602 11218 9378 8737 8467 8137 8151 8240 7959 7912 7868 8068 8079 7928 7870 7844 7897 7733 7621 7763 7730 7642 7519 7445 7556 7472 7401 7622 7475 7497 7385 7341 7392 7321 7399 7195 7238 7283 7276 7409 7415 7325 7508 7214 7273 7364 7447 7357 7298 7231 7333 7407 7408 7267 7360 7297 7349 7464 7341 7398 7431 7354 7244 7391 7417 7461 7314 7567 7373 7308 7306 7243 7334 7331 7407 7506 7429 7387 7822 7566 7391 7451 7398 7253 7109 7242 7184 7190 7386 7386 7248 7143 7245 7267 7209 7333 7136 7358 7296 7243 7087 7015 7135 7236 7207 7224 7176 7221 7221 7311 7254 7148 7011 7124 7236 7430 7289 7294 7233 7608 7352 7531 7382 7243 7373 7187 7231 7189 7336 7259 7290 7194 7489 7530 7340 7368 7430 7415 7311 7215 7237 7281 7244 7079 7334 7276 7519 7350 7446 7154 7169 7138 7168 6979 7254 7180 7183 7290 7360 7249 7254 7208 7087 7192 7106 7205 7157 7326 7276 7311 7114 7101 7247 7232 7193 7133 7109 7265 7141 7094 7152 7070 7152 7125 7300 7111 7260 7130 7120 7016 7077 7408 7218 7201 7178 7163 7112 7248 7135 6985 7104 7229 7208 7239 7212 7054 7152 7117 7205 7268 7289 7237 7229 7373 7377 7523 7469 7371 7617 7445 7291 7491 7442 7535 7578 7270 7544 7549 7513 7369 7574 7488 7591 7331 7368 7393 7427 7336 7542 7426 7492 7377 7336 7383 7499 7612 7347 7330 7492 7360 7326 7421 7410 7275 7501 7749 7449 7402 7513 7539 7571 7507 7750 7945 8027 7964 8167 8504 8544 8557 8468 8910 9202 9233 9492 9903 10486 11277 12206 13701 16188 20419 27153 37678 52288 68934 83067 89599 86354 78082 68576 62015 56441 50812 42000 32448 23906 18057 14714 12523 11300 10107 9759 9475 9378 8690 8529 8352 8285 8136 7884 7769 7801 7742 7826 7878 7789 7723 7616 7595 7619 7621 7863 7849 7753 8089 8348 8341 8647 8678 8962 8473 8382 8243 8046 7974 8100 7769 7784 7552 7492 7490 7471 7557 7764 7457 7660 7661 7852 7925 7897 7935 8200 8321 8436 8704 8858 9423 10720 12686 16786 23542 32238 39142 39267 34246 28953 26131 25928 25328 23108 18845 14834 12045 10222 9482 8928 8854 9173 9565 10467 11786 13074 14422 15624 16521 16410 15934 15130 14357 14392 13737 12556 11717 10573 9781 9248 8815 8484 8161 7737 7600 7812 7744 7371 7269 7266 7190 7164 7374 7366 7056 7208 7208 7237 7153 7127 7265 7183 7152 7233 7151 7095 7202 7166 7050 7115 7304 7326 7342 7074 7054 7238 7109 7193 7086 6942 7148 6959 7006 7027 7088 7128 7164 7239 7206 6818 6962 6971 6998 7062 7020 7001 7275 6945 7258 7095 6943 7002 6931 6864 6996 6947 6830 6974 6982 7048 7225 7037 7101 7103 7075 6968 6774 6976 6948 6816 7076 6908 6880 6885 6770 6884 7175 7016 7014 6903 6889 6931 6907 6963 7087 7048 7012 6976 6917 6816 6972 6956 7180 7037 6995 6935 7037 6980 6857 7080 6832 6923 6790 7035 6896 6886 6848 6765 6903 6869 6949 6842 6963 6908 6924 7098 6720 6859 6885 6859 6852 6726 6690 6676 6924 6811 6796 7037 6969 6887 6757 6889 6888 6909 6816 6882 6769 6816 6941 6922 7029 6832 6651 6899 6976 6919 6690 6823 7017 6952 7074 7026 6892 6864 6967 6797 6945 6779 6858 6914 6844 6722 6784 6859 6839 6986 6828 6883 6786 6740 7016 6873 6812 6869 6848 6809 6831 7038 6885 6958 6967 6952 7018 6894 6492 6798 6758 6969 6795 6831 6990 6953 6993 6747 6841 6991 6753 6853 6837 6895 6886 6891 6864 6830 6846 6971 6899 6996 6925 6864 6910 7311 7009 6975 7029 6925 7032 6941 6994 7028 6728 7076 6825 6779 6771 7078 6904 6793 6924 6938 6978 6905 6847 7082 6962 6995 7038 7015 6911 7148 7187 7098 7141 7020 7275 7260 7501 7427 7558 8088 8637 9675 11173 12893 14560 15429 15056 13883 13226 13302 14318 16449 19676 22006 22873 20730 17257 14492 13500 13852 14381 13988 12355 10447 9218 8255 7781 7539 7248 7197 7333 7202 7132 7101 7017 7131 7111 7114 7146 7063 7063 6915 6882 6988 6888 7058 6837 6989 6993 7090 6908 7036 7234 7239 7132 7445 7621 7772 8361 9374 10637 12218 13865 14772 15013 14036 12818 11945 11259 11437 11347 10804 9980 9100 8192 7716 7601 7212 7129 7252 7147 7348 7350 7719 7699 7825 7626 7594 7787 7439 7488 7520 7591 7383 7731 7600 7968 8150 9290 10637 12186 13218 13491 12893 11645 10902 10271 10242 10700 10177 9755 8740 8218 7450 7321 7008 6963 6954 6832 6754 6916 6836 6815 6610 6729 6588 6712 6739 6729 6790 6834 6811 6711 6857 6890 6679 7054 6849 6849 6831 6906 6769 6865 6946 6922 6862 6934 7073 7125 7559 7729 8608 9579 10429 11090 11625 11201 10951 10133 9812 9626 9571 9167 8950 8540 8012 7783 7383 7370 7403 7404 7380 7423 7447 7316 7069 6983 7046 7155 7006 6885 6781 6866 6628 6593 6619 6627 6661 6700 6724 6603 6638 6659 6643 6843 6632 6499 6709 6736 6464 6412 6671 6877 6632 6710 6559 6459 6570 6565 6500 6533 6694 6690 6638 6673 6589 6591 6504 6677 6667 6678 6666 6753 6772 6588 6562 6437 6611 6499 6646 6633 6457 6589 6738 6548 6744 6764 6622 6594 6631 6567 6610 6598 6439 6508 6692 6577 6645 6752 6552 6727 6667 6606 6816 6665 6518 6542 6516 6665 6725 6662 6671 6680 6662 6566 6621 6633 6723 6415 6517 6918 6713 6802 6930 7132 7442 7938 8769 9687 10261 9752 8829 8195 7947 8242 8317 8534 8349 7817 7521 7293 6767 6820 6755 6716 6666 6702 6622 6530 6380 6730 6599 6536 6567 6536 6736 6454 6569 6602 6602 6642 6573 6462 6434 6592 6484 6585 6661 6464 6442 6617 6535 6547 6558 6496 6636 6461 6543 6539 6641 6529 6575 6456 6613 6580 6557 6502 6553 6680 6566 6726 6532 6498 6661 6622 6712 6590 6634 6706 6792 6965 7060 7029 7366 7602 7401 7320 7091 7073 7322 7577 7719 7936 8457 8951 10048 10745 11123 11522 11228 10901 10337 10494 10382 10935 11377 11180 10607 9547 8856 8505 8177 7872 7947 7745 7393 7094 7133 6929 6766 6811 6811 6832 6588 6669 6715 6625 6604 6539 6574 6661 6691 6612 6642 6425 6242 6470 6660 6611 6487 6571 6523 6629 6467 6530 6422 6352 6337 6590 6453 6526 6365 6370 6473 6413 6544 6517 6393 6424 6462 6597 6565 6318 6517 6592 6580 6435 6575 6482 6649 6554 6420 6561 6495 6439 6664 6539 6323 6475 6472 6388 6273 6390 6540 6502 6650 6538 6401 6544 6462 6455 6603 6590 6472 6530 6510 6522 6610 6453 6530 6464 6599 6455 6447 6682 6644 6627 6605 6865 6840 6889 7288 7932 8462 9309 9556 9152 8395 7996 7499 7609 7929 8036 8097 7724 7339 7039 6823 6691 6628 6608 6456 6541 6407 6502 6598 6384 6383 6422 6434 6601 6613 6421 6268 6451 6511 6383 6551 6536 6332 6382 6572 6473 6587 6553 6598 6505 6462 6365 6533 6601 6454 6440 6442 6735 6676 6396 6618 6478 6437 6439 6518 6569 6447 6479 6499 6484 6349 6528 6550 6481 6588 6554 6493 6647 6632 6715 6887 7302 7390 7612 7863 7890 8206 8616 9017 9348 9693 9657 9412 9020 8551 8381 8122 8193 7991 7870 7676 7459 7135 7002 6815 6647 6790 6639 6586 6565 6503 6682 6612 6421 6508 6524 6405 6492 6389 6446 6506 6523 6539 6315 6501 6510 6452 6325 6429 6529 6434 6489 6608 6577 6615 6803 6693 6721 6612 6779 6882 6949 7209 7393 7725 8074 8577 8795 8957 9348 9900 10614 11157 11561 11921 11663 11378 10944 10980 11500 11331 11368 10715 10055 9227 8761 8416 8134 8152 7820 7721 7521 7099 6752 6584 6710 6598 6473 6365 6502 6620 6642 6488 6534 6378 6566 6505 6684 6702 6405 6472 6573 6480 6368 6240 6354 6403 6601 6341 6398 6432 6459 6402 6295 6299 6371 6587 6326 6240 6260 6456 6348 6378 6585 6545 6588 6430 6326 6400 6549 6274 6499 6397 6496 6521 6328 6369 6309 6442 6504 6413 6496 6465 6384 6608 6486 6336 6448 6338 6510 6495 6390 6367 6333 6325 6334 6493 6306 6389 6406 6309 6325 6485 6398 6505 6347 6454 6447 6351 6416 6459 6191 6303 6402 6289 6403 6473 6331 6434 6309 6334 6268 6292 6270 6400 6291 6375 6282 6408 6445 6353 6367 6405 6501 6412 6433 6361 6342 6360 6401 6202 6046 6304 6315 6404 6424 6395 6495 6308 6220 6114 6413 6286 6353 6335 6392 6427 6343 6422 6383 6437 6278 6401 6558 6415 6528 6493 6452 6443 6482 6419 6374 6486 6356 6444 6409 6272 6402 6453 6357 6318 6428 6479 6666 6729 6766 6813 6835 7293 7353 7682 7543 7614 7489 7407 7046 7238 7263 7316 7222 7242 6974 6902 6793 6856 6743 6776 6533 6455 6666 6421 6482 6347 6569 6502 6432 6287 6486 6470 6577 6374 6503 6610 6475 6489 6513 6423 6477 6646 6629 6754 6636 6704 6458 6492 6478 6560 6718 6696 6548 6490 6497 6445 6583 6503 6408 6418 6443 6591 6730 6565 6545 6671 6564 6451 6788 6920 6835 6915 6780 6928 7388 7560 7929 8803 9556 10456 11607 12429 12945 12893 12062 11085 10254 9830 9573 9771 9855 9924 9450 9184 8625 8095 7314 7111 6888 6777 6773 6809 6675 6740 6652 6579 6534 6457 6624 6504 6516 6496 6408 6319 6374 6285 6388 6327 6285 6455 6365 6247 6352 6527 6271 6588 6594 6402 6291 6481 6285 6224 6371 6280 6287 6399 6438 6372 6636 6538 6457 6395 6423 6436 6444 6459 6481 6360 6380 6321 6383 6451 6315 6387 6505 6426 6413 6380 6386 6409 6500 6438 6498 6244 6365 6364 6417 6311 6402 6381 6438 6563 6415 6535 6526 6570 6631 6712 6651 6752 6732 6689 6871 6992 6852 6817 6954 7164 7281 7508 7638 8077 8985 10534 12323 15049 17417 18464 18686 17954 16443 14418 12961 12206 12077 12775 13016 12924 12671 12050 11272 10068 8981 8203 7513 7434 7102 7178 7092 7055 7019 7076 6773 6990 6899 6746 6786 6602 6558 6670 6453 6485 6609 6382 6468 6646 6429 6629 6577 6284 6456 6525 6487 6412 6391 6429 6515 6229 6313 6460 6487 6420 6532 6451 6585 6391 6590 6351 6380 6442 6403 6482 6289 6491 6533 6458 6403 6324 6584 6486 6354 6494 6466 6539 6650 6623 6537 6488 6422 6376 6414 6426 6410 6508 6463 6646 6514 6700 6611 6916 6867 6890 7328 7393 7990 8117 8473 8723 8820 8975 8675 8756 8537 8637 9083 9966 11496 13161 13816 13593 12037 10328 9221 8552 8520 8784 9325 9909 9960 9667 9023 8294 7619 7525 7362 7167 7125 6843 6904 6833 6934 6945 6991 7076 7135 7029 7071 7116 7084 7200 7193 7277 7489 7764 7798 8125 8723 9468 10518 12082 13876 15913 17179 17762 18037 17756 16504 14777 13641 12752 12701 12577 12917 12881 12501 12090 11109 9795 9010 8372 7893 7258 6985 7121 7018 6995 6670 6679 6523 6828 6620 6790 6699 6850 6753 6585 6741 6919 6769 6844 6730 6828 7045 7093 7337 7759 7835 7747 7911 7852 7677 7795 7715 7720 7910 7905 7795 7770 7846 7459 7393 7354 7387 7232 7167 7154 7240 7037 7232 7283 7288 7131 7090 7373 7217 7506 7723 8026 8271 9222 10304 11601 12915 14028 14214 14434 14033 13394 12720 11936 11519 11772 12637 13462 14183 14184 13660 12332 11239 10048 9182 8729 8586 8743 8865 8699 8529 8122 7576 7421 7227 6869 6807 6885 6689 6862 6820 6650 6807 6890 6931 7066 7042 7036 6943 7087 7053 7216 7389 7513 7670 8003 8362 9172 10320 12123 14197 16305 18541 19472 18739 16503 14056 12435 11237 11344 11505 12215 13022 13080 12764 11560 10255 9304 8628 7922 7455 7301 7066 7306 6919 6731 6785 6642 6712 6667 6773 6682 6534 6752 6747 6712 6662 6825 6783 6911 7111 7186 7294 7456 7637 7522 7509 7482 7403 7480 7729 8069 8463 8999 9177 9263 9264 8947 9172 9314 9359 9888 9564 9643 9569 9155 8743 8191 8303 8154 8036 7964 8186 7781 7651 7302 7145 6799 6657 6710 6817 6621 6592 6531 6533 6448 6356 6540 6572 6480 6568 6468 6508 6561 6617 6337 6377 6414 6512 6509 6459 6558 6357 6507 6676 6421 6564 6428 6527 6667 6591 6587 6671 6601 6476 6599 6660 6563 6559 6506 6684 6721 6744 6588 6673 6816 6812 7073 7031 7119 7458 7837 8373 9065 10175 11650 13483 15184 15755 14917 13062 11406 10077 9682 9776 10061 10619 11522 12028 11813 10858 9837 8686 7994 7754 7531 7296 7386 7181 7023 7057 6867 6727 6704 6593 6649 6422 6463 6350 6446 6527 6595 6495 6294 6387 6611 6527 6479 6430 6456 6407 6435 6306 6445 6356 6300 6479 6527 6467 6487 6394 6515 6385 6370 6343 6408 6577 6525 6411 6283 6727 6522 6333 6374 6400 6355 6606 6815 7007 7287 7738 8019 8012 7763 7668 7226 7012 6978 6602 6781 6893 7282 7343 7291 7108 6848 6746 6580 6555 6439 6430 6495 6328 6404 6355 6385 6135 6446 6374 6403 6368 6251 6437 6426 6388 6236 6204 6189 6260 6435 6343 6302 6402 6127 6399 6427 6400 6431 6393 6531 6521 6456 6491 6372 6332 6193 6342 6559 6457 6463 6413 6535 6274 6517 6362 6177 6470 6336 6130 6322 6312 6463 6411 6281 6117 6263 6348 6268 6232 6227 6516 6595 6517 6278 6284 6411 6443 6435 6540 6464 6506 6627 6434 6519 6511 6423 6426 6447 6275 6408 6400 6526 6447 6248 6294 6360 6380 6463 6227 6464 6228 6360 6328 6262 6223 6295 6324 6074 6248 6316 6382 6456 6284 6235 6258 6431 6243 6202 6131 6237 6283 6050 6433 6123 6101 6126 6045 6274 6253 6306 6145 6351 6544 6271 6292 6249 6348 6287 6093 6379 6301 6291 6119 6198 6203 6310 6137 6377 6299 6225 6299 6352 6220 6265 6348 6221 6273 6323 6266 6258 6256 6234 6404 6454 6154 6273 6421 6399 6154 6256 6245 6331 6230 6356 6328 6447 6156 6164 6338 6477 6397 6330 6401 6272 6559 6414 6440 6298 6382 6172 6410 6524 6356 6194 6552 6495 6467 6427 6473 6606 6447 6599 6615 7111 7509 7830 8392 8791 8739 8486 8087 7888 7520 7324 7695 7732 7845 8198 8716 8884 9133 9386 9853 10276 11012 11456 12060 12256 12358 11706 11093 10336 9472 9026 8977 8864 9012 9294 9377 9309 9534 8867 8428 8000 7576 7353 7399 7275 7100 6999 7235 7200 7186 7062 6897 6917 6771 6694 6797 6790 6715 6865 6838 7049 7109 7188 7631 7764 8490 8882 9073 9203 9247 8759 8272 7999 7580 7419 7580 7734 7926 8062 8083 8116 8211 8005 7707 7746 7542 7828 8302 9003 9598 10196 10871 10721 10430 9730 8964 8401 7999 7709 7613 7772 8180 8592 8836 8609 8593 8158 7847 7654 7332 7170 7065 6873 7157 7036 6812 6897 6919 6636 6578 6825 6667 6594 6594 6637 6725 6660 6579 6755 6691 6651 6453 6364 6493 6172 6307 6314 6393 6424 6384 6531 6569 6564 6407 6556 6335 6364 6268 6505 6242 6577 6444 6398 6528 6274 6405 6418 6251 6476 6474 6400 6330 6558 6455 6635 6662 6654 6649 6728 6906 6862 7122 7234 7494 7703 8044 8467 8877 9095 9251 9464 9575 9414 9287 9008 9206 9543 9984 10214 10669 11105 10611 10344 9888 9387 8774 8397 8064 8023 7954 8062 8068 8149 8039 7721 7672 7250 6865 6827 6773 6553 6689 6607 6429 6474 6317 6490 6538 6499 6558 6563 6438 6533 6447 6421 6439 6333 6454 6520 6365 6609 6471 6458 6707 6938 6988 7090 7243 7414 7738 7799 7664 7738 7849 7779 7473 7401 7350 7408 7698 7956 8392 8439 8878 9234 9732 9588 9606 9511 9390 9391 9497 9835 9835 10292 10469 10552 10574 10585 10207 10372 10490 10435 10672 10494 10061 9584 9207 9011 8970 8931 8999 9089 9321 9943 10490 10436 10354 10086 9961 9206 8754 8122 7783 7905 7566 7623 7791 7915 8045 7703 7902 7746 7448 6925 6954 6706 6560 6427 6367 6489 6387 6342 6330 6359 6430 6278 6338 6416 6493 6432 6300 6375 6399 6380 6337 6450 6417 6462 6271 6462 6505 6476 6504 6479 6534 6817 6632 6820 6810 6969 7046 7409 7797 8282 9214 10193 11309 12096 12393 11814 10788 9815 8892 8045 7875 7887 8019 8349 8886 9128 9523 9342 8967 8391 7770 7360 6999 6845 6782 6675 6617 6651 6551 6582 6380 6386 6328 6331 6514 6475 6693 6594 6682 6725 6716 7074 7436 7699 8303 8779 8961 8956 8493 8182 7485 7287 7202 7262 7312 7485 7393 7597 7611 7929 7713 7557 7382 7067 6845 6821 6728 6782 6752 6648 6586 6594 6365 6640 6603 6611 6541 6527 6564 6612 6450 6538 6612 6653 6860 6711 6921 7078 7204 7474 7885 8567 9315 10136 10820 11799 12644 13107 13093 13062 12917 12412 11705 11027 10149 10075 9704 9787 9725 9623 9934 9783 9815 9434 9232 8854 8304 7854 7385 7111 6669 6720 6633 6803 6993 7074 7381 7423 7468 7755 7695 7434 7121 6706 6669 6566 6574 6616 6660 6790 6799 6893 6956 6711 6599 6619 6505 6432 6468 6231 6221 6113 6237 6387 6219 6179 6308 6240 6153 6294 6213 6132 6142 6065 6075 6272 6106 6273 6150 6136 6167 6308 6183 6134 6019 6227 6231 6179 6083 6189 6263 6182 6096 6008 6141 6068 6239 6137 6110 6277 5956 5956 6083 6143 6132 6029 5963 6213 5996 5954 6067 6227 5979 5968 6134 6045 5970 5960 6166 6098 6198 6233 6115 6120 6201 6215 6141 6249 6080 6054 6182 6168 6112 6137 6200 6163 6129 6077 6133 6199 6172 6098 6067 6305 6292 6243 6110 6312 6199 6149 6279 6204 6438 6428 6393 6596 6717 6666 6810 7086 7202 7324 7372 7196 7353 7169 6855 6742 6766 6692 6731 6979 7017 7287 7327 7531 7962 8116 8412 8188 8069 7833 7412 7003 6817 6682 6825 6726 6771 6878 7155 7426 7284 7127 7075 6967 6605 6520 6368 6237 6242 6243 6256 6328 6207 6172 6135 6229 6133 6079 6117 5980 6030 6156 6207 6074 6116 6233 6149 6010 6046 6123 6117 5972 6234 6128 6264 6028 6115 6059 6190 6235 6169 6353 6331 6344 6651 6422 6699 6675 7028 7156 7178 7052 7211 7031 7099 6869 6663 6517 6458 6674 6593 6530 6678 6711 6647 6542 6679 6384 6505 6462 6525 6503 6459 6297 6389 6265 6048 6024 6049 6153 6343 6123 6264 6206 6176 6062 5997 5870 6039 6190 5941 5979 6054 5873 6152 6080 6093 6269 6206 6030 5874 6033 6206 6229 6102 6065 6018 6079 5998 5952 6153 5999 6115 6048 6059 6012 6037 6104 5951 6078 6132 6047 6062 6156 6196 6201 6292 6111 6109 5966 6108 6189 6083 6164 6075 6156 6260 5900 5925 6040 6130 6020 5993 6003 6131 6314 5964 5948 5970 6080 5975 5893 6064 6101 5985 6022 5943 5959 5988 6052 6063 5934 6026 5879 6020 5970 6027 5921 5851 5899 5882 6141 5960 6042 5902 6050 6093 5887 5838 5823 5972 6116 5849 5986 6086 5876 5949 5978 5890 6193 6060 5985 5994 6133 6079 5965 6093 5997 5993 6043 6081 5832 5839 6152 5987 6105 5994 5926 5924 6133 6169 6124 6232 6210 6191 6071 6116 6040 5932 5894 5978 5924 6026 5897 5951 5913 6016 5879 5989 5980 5982 6137 5953 6082 6029 5810 6029 5853 5885 5911 5912 5933 5910 5774 5858 6100 6042 5929 5956 5892 5989 5906 6074 6031 5809 5895 5934 5969 6022 5845 5950 5924 5825 6111 6045 5943 5860 5922 5896 5979 5910 6032 6076 6057 5843 6048 6082 6030 6034 5942 6006 6043 5920 6425 6277 6062 6112 6135 5879 6098 6014 5964 5934 6257 6266 5920 6035 5972 6108 5995 6092 6158 5910 5944 6058 5995 6040 6151 6041 5996 5861 5976 5773 5876 5954 6093 5926 5984 5821 5994 6072 5980 6135 5932 5864 5932 5928 5875 5971 6092 6037 6012 6004 5837 5881 5940 5949 5813 5956 6152 6079 5953 6068 6185 6062 6021 6059 5947 5948 5917 6000 5921 5888 6028 6053 6156 5921 5915 5951 6014 5942 6027 6103 6095 5906 5936 5858 6133 6096 6025 5996 5946 6025 6121 6106 5888 6020 6078 6059 6108 6022 6081 6183 6162 6200 6227 6195 6323 6252 6247 6288 6462 6337 6446 6615 6690 6837 6895 6962 7144 7156 7072 7191 7222 7128 7298 7001 7020 6895 6703 6782 6781 6643 6697 6844 6885 6854 6870 6979 7310 7256 7940 8395 8586 8332 8316 7964 7419 7199 6938 6932 6833 7215 7341 7519 7871 8027 8430 8765 8819 9064 8676 8034 8049 7766 7579 7224 7201 6943 7074 6950 6985 6911 7040 6877 7079 6982 7030 6901 6731 6825 6718 6645 6726 6727 6656 7030 7190 7409 7901 7734 7526 7298 7089 6611 6701 6462 6509 6422 6460 6415 6489 6647 6596 6770 6968 6947 6764 6700 6559 6361 6431 6234 6127 6219 6235 6313 6192 6107 6066 5950 6283 6198 6339 6332 6088 6086 6295 6137 6101 6065 6224 6128 6148 6150 6235 6220 6203 6228 6163 6564 6268 6521 6515 6671 6563 6454 6433 6500 6564 6654 6505 6464 6589 6746 6807 6684 6792 6673 6742 6750 6627 6612 6630 6457 6388 6323 6423 6302 6334 6407 6334 6567 6374 6394 6451 6382 6240 6263 6041 6053 6089 6214 6003 6231 6126 5969 6080 6098 6108 5927 6070 5955 6027 6020 5924 5973 6153 5947 5937 5848 5991 6046 5983 5891 6030 6204 5905 6128 6157 5957 6093 6154 6086 6178 6160 6060 6125 6090 6165 6239 6203 6199 6187 6335 6300 6420 6240 6425 6387 6475 6532 6364 6474 6347 6349 6355 6444 6492 6410 6435 6687 6978 7152 7287 7592 8018 8244 8290 8471 8210 8084 7965 7975 7568 7366 7193 7107 6961 6964 6907 7101 7064 7134 7090 7176 7008 6939 6865 6929 6801 6550 6417 6376 6433 6140 6107 6114 6165 6157 6246 5942 6067 6035 5836 5996 5970 5927 6099 6065 6100 6132 6267 6248 6329 6326 6432 6562 6724 6775 6744 6478 6448 6188 6192 6181 6203 6264 6131 6150 6128 6111 6287 6349 6454 6312 6318 6296 6177 6072 6176 6069 6132 6048 6206 6200 6261 6266 6321 6347 6333 6126 6033 6122 6099 6067 6136 6095 6115 6100 6184 6181 6382 6295 6398 6483 6658 6684 6900 7009 7225 6957 7105 7029 7061 7053 7040 7206 6963 6833 6813 6560 6445 6486 6593 6401 6548 6481 6589 6562 6565 6494 6563 6815 6614 6378 6401 6182 6353 6366 6343 6101 6098 6083 6009 6013 6192 5986 6107 6329 6179 6093 6005 6225 6142 6349 6296 6256 6342 6226 6330 6124 6282 6233 6212 6296 6311 6147 6264 6581 6629 6644 6611 6656 6884 6985 7013 6918 7004 7075 7084 7035 7042 7264 7290 7044 7247 7313 7325 7243 7176 6941 6939 6973 6826 6939 7151 6940 6769 6868 6792 6838 6538 6648 6612 6575 6490 6310 6430 6282 6446 6405 6488 6412 6249 6283 6196 6063 6132 6073 6114 6100 6178 6007 6080 6083 5906 6142 5991 6038 5968 6101 6063 6140 6040 6060 6078 6110 5977 6062 6038 5991 5801 6025 5918 6021 5942 5949 5863 5929 5882 6075 5924 5852 5775 5944 5895 5888 5846 5907 5920 5956 5851 5926 5942 5776 5835 5921 5881 5935 6077 6072 6002 5902 5894 5935 5993 5758 5764 5833 5898 5992 5765 5889 6058 6027 5979 5782 5677 6039 5892 5987 5734 5916 5873 6102 6042 6155 6253 6356 6511 6339 6376 6269 6069 6210 6063 6159 6069 6077 5938 6083 6187 6232 6058 5983 6096 6185 6123 6225 6125 5936 6037 5954 6055 6041 5954 5917 6121 5884 5841 5936 6008 6039 5882 5955 6138 5955 6038 5965 6121 5933 6091 6087 6243 6245 6094 6202 6301 6210 6354 6347 6302 6305 6195 6207 6185 6130 6116 6114 6104 6265 6452 6368 6425 6347 6405 6479 6505 6678 6802 6800 6772 6910 7127 7186 7335 7105 7303 7024 6953 6938 7040 7028 7098 7402 7451 7667 7458 7296 7398 7045 6900 6865 6749 6632 6545 6488 6298 6194 6470 6441 6498 6650 6661 6707 6503 6555 6394 6268 6112 6294 6147 6307 6363 6278 6378 6141 6086 6095 6184 5885 5943 5980 6258 6075 6245 6109 6136 6345 6477 6777 7062 7136 7176 7315 7126 6841 6771 6495 6428 6302 6137 6085 5956 6234 6099 6218 6407 6301 6512 6482 6476 6420 6279 6143 6259 6189 6005 6023 5901 6023 6043 5929 5928 5838 5979 5892 5831 5955 5877 5868 5852 6039 5917 5917 5775 5881 5881 5888 5900 5821 5759 5758 5800 5788 6119 5892 5798 5847 5821 5962 5863 5839 5676 6003 5891 5805 5873 5858 5945 5849 5939 5945 5933 5920 5847 5981 6016 6090 6029 5992 5995 5960 6011 6053 5975 6074 6020 5994 6052 6127 6019 6064 6045 5948 5965 6027 6103 6121 6148 6222 6159 6189 6161 6357 6308 6355 6375 6522 6640 6743 6620 6792 6943 7047 6984 7037 7013 6891 6917 6718 6720 6705 6605 6443 6401 6420 6569 6454 6485 6588 6727 6793 6722 6545 6561 6728 6604 6508 6548 6399 6468 6317 6290 6284 6041 6027 6021 6218 6164 6242 6103 6044 6232 6109 6171 6137 6198 6246 6165 6276 6471 6587 6629 6693 6687 6834 6999 6765 6785 6795 6842 6727 6582 6392 6412 6544 6513 6663 6653 6745 7072 6884 6981 6758 6687 6616 6683 6627 6618 6500 6484 6326 6292 6190 6166 6031 6247 6226 6216 6332 6268 6399 6103 6064 5931 5968 6043 5961 5880 5910 6006 6122 6017 5866 6048 6036 5911 6057 5980 6015 5962 5961 5896 5927 5947 6000 6089 6025 6217 6253 6084 6311 6516 6370 6628 6626 6708 6831 6913 6879 6813 6840 6706 6779 6527 6569 6761 6770 6871 6598 6756 6852 6730 6791 6735 6855 6867 6691 6629 6548 6397 6524 6445 6377 6521 6152 6303 6332 6180 6173 6287 6206 6330 6427 6243 6350 6425 6363 6453 6465 6518 6218 6290 6327 6307 6240 6228 6365 6167 6295 6427 6513 6556 6467 6632 6702 6826 6799 6663 6812 6877 6921 6734 6847 6656 6501 6455 6245 6593 6385 6415 6330 6234 6397 6212 6177 6191 6351 6126 6282 6232 6206 6085 6053 6073 6126 6081 5950 5934 6017 6057 6195 5838 6073 6045 5932 5936 5946 6018 6204 6045 6114 5951 6006 6174 5934 5892 6013 6186 5929 5918 6076 6016 5974 6014 6016 6172 6182 6143 6320 6216 6251 6315 6207 6205 6298 6193 6107 6183 6179 6092 6135 6181 6233 6191 6269 6310 6287 6260 6465 6397 6456 6304 6221 6238 6253 6348 6300 6396 6405 6223 6109 6213 6134 6183 6116 6038 5963 5935 6003 6180 6101 6242 5866 6075 6030 6221 6112 6188 6237 6217 6201 6241 6323 6312 6395 6433 6497 6516 6592 6705 6469 6387 6252 6174 6148 6114 6050 5952 6009 6039 5855 5999 5985 6168 6259 6231 6131 6197 6375 6136 6047 6047 6053 6008 5990 6117 5903 5851 5864 6100 5923 5862 5888 5905 5813 5926 5875 5887 5935 5921 5777 5887 5767 5814 5756 5844 5735 5786 5865 5722 5772 5842 5896 5906 5842 5815 5854 5685 5778 5972 5840 5811 5789 5965 5888 5826 5823 5778 5855 5711 5742 5882 5831 5851 5909 6021 5841 5803 5801 5837 5782 5719 5925 5906 5717 5964 5921 5932 5861 5848 5790 6055 5987 5989 6123 6046 5962 6072 5819 5964 5903 6029 6063 5983 5943 5853 6048 6153 6150 6108 6166 6143 6162 6200 6163 6329 6309 6033 6195 6321 6361 6439 6354 6320 6229 6302 6242 6367 6357 6203 6209 6249 6167 6005 5918 6076 6158 5999 5829 6064 6046 5884 6086 5904 6137 6009 5949 6070 6063 5917 6002 5965 5933 5960 5838 5813 5821 5750 5821 5831 5843 5821 5890 5597 5731 5874 5743 5717 5828 5891 5943 5863 5764 5825 5908 5837 5897 6009 5883 6021 5943 5997 5871 5775 5799 5966 5776 5796 5640 5821 5914 5744 5699 5855 5897 5804 5900 5950 5729 5773 6012 5976 6037 5994 6070 6096 6271 6128 6034 6144 6179 6005 5839 5837 5950 5893 5888 5872 5859 5656 5884 5876 5883 6001 6040 5871 6043 6145 5907 5808 5747 6003 6016 5788 5695 5930 5886 5789 5837 5965 5981 5800 5836 5920 5951 5862 5847 5872 5842 6020 6098 6060 6065 5801 6073 6029 6007 5942 6024 5804 6062 6108 6171 5849 5904 6138 6196 6112 6093 6153 6119 6085 6182 6134 6246 6123 6337 6057 6293 6174 6236 6317 6209 6488 6597 6726 6895 6990 7116 7128 7162 7188 6899 6788 6692 6557 6408 6416 6362 6532 6317 6348 6394 6319 6607 6861 6779 6901 6904 7131 6960 6711 6705 6591 6598 6448 6476 6526 6303 6120 6168 6161 6284 6149 6303 6271 6070 6102 6203 6224 6128 5965 5982 6237 5944 6089 6106 5973 5870 5892 5973 5938 5966 6030 5764 5910 5969 5969 5821 6016 5809 5822 5769 5823 5809 5879 5988 6074 6123 5974 6148 6120 6177 5930 5957 5955 6100 6076 5862 6035 6194 6134 6137 6247 6086 6388 6351 6374 6395 6257 6467 6457 6466 6639 6510 6444 6404 6661 6291 6142 6109 5982 6138 6053 6056 6101 6151 6208 6032 6183 6034 6073 6109 6182 6113 6047 6150 6135 6123 6012 6105 6001 5887 5880 5931 5898 6059 5990 5863 5952 5912 5979 6010 6102 6157 6320 6302 6452 6345 6389 6188 6306 6256 6245 6266 6325 6238 6167 6155 6262 6273 6234 6275 6384 6196 6145 6440 6408 6549 6315 6349 6289 6381 6149 6174 6176 6236 6056 6061 6178 6223 6209 6264 6382 6538 6319 6302 6261 6113 6202 6474 6137 6217 6041 6210 6237 6075 6364 6148 6293 6289 6348 6560 6633 6766 6630 6641 6672 6834 6908 6882 6800 6707 6584 6472 6363 6269 6251 6348 6295 6172 6196 6024 6213 6254 6145 6281 6354 6428 6634 6495 6496 6617 6969 7009 6978 6735 6514 6433 6292 6319 6199 6055 6031 6044 5816 5951 5887 5882 5985 5941 6093 5985 6096 6069 6182 6260 6196 6170 6225 6208 5979 5796 5851 5793 5844 5875 5803 5844 5849 5680 5863 5823 5822 5698 5722 5832 5820 5758 5717 5844 5798 5714 5740 5751 5838 5969 5785 5808 5840 5767 5878 5961 5824 5839 5869 5987 5802 5847 5866 5691 5741 5798 6037 5781 5763 5895 5746 5757 5787 5669 5782 5770 5725 5762 5701 5756 5881 5922 5868 5839 5894 6019 5884 5854 5900 5848 5993 5746 5921 5850 5672 5764 5810 5943 5961 5981 6071 5962 5899 6087 6042 6046 6046 5881 6003 6125 6161 5904 5998 6100 6159 5900 5920 6026 5889 5945 6002 5934 5924 6090 6072 5955 5945 6147 6114 6016 6232 6105 6186 6060 6281 6323 6339 6189 6306 6324 6470 6131 5965 6303 6148 6012 6186 6082 6038 6196 5975 6113 6167 6036 6046 6150 6337 6218 6354 6309 6359 6381 6536 6580 6658 6629 6614 6451 6368 6595 6434 6273 6376 6255 6392 6479 6580 6512 6522 6661 6462 6777 6765 6714 6632 6644 6636 6630 6573 6538 6305 6312 6083 6135 6278 6053 5982 6129 6167 6114 6024 6202 6228 6248 5994 6166 6201 6019 6284 5994 6023 6015 5960 5982 6034 5981 5742 5845 5936 5838 5772 5695 5768 5777 5909 5763 5820 5828 5925 5875 5915 5847 6035 5942 5760 5872 5980 6009 5901 5818 5914 6013 6076 5796 5983 5866 5824 5806 5801 5812 5868 5801 6008 5888 6023 6049 5767 5736 5878 5909 5940 5792 5805 5706 5928 5908 5966 5790 5862 5827 5778 5825 5797 5954 5968 5686 5819 5830 5936 5625 5771 5697 5995 6094 5949 5960 5818 6065 6007 6041 6039 6160 6091 6092 6003 6168 6146 6188 6110 6139 6131 6279 6241 6352 6395 6589 6341 6200 6038 6063 6070 6084 6091 6159 5930 5983 6039 5964 5995 6019 6048 5953 6001 6073 6139 6181 6082 6220 5979 6012 5946 5968 6073 5994 5834 5856 5777 5874 5937 5664 5799 5891 5846 5681 5984 5890 5856 5910 5870 5816 5939 5999 6236 6129 6108 5932 6250 6306 6223 6298 6436 6225 6326 6329 6232 6282 6219 6185 6168 6190 6304 6378 6320 6112 6107 6124 6198 6314 6167 6223 6198 6259 6201 6159 6247 6147 6229 6166 6275 6329 6259 6221 6393 6225 6426 6485 6233 6264 6234 6268 6087 6160 6189 6197 5995 6038 5855 5927 5842 5926 5969 5865 5978 6163 5965 6127 6230 6145 6127 6263 6192 6175 6351 6235 6205 6375 6196 6447 6174 6277 6244 6224 6137 6006 5913 6053 5949 6008 6100 5902 6170 6022 6074 6125 6132 6187 6439 6149 6374 6352 6359 6327 6487 6380 6214 6334 6218 6265 5992 5928 5955 5992 6054 5982 6046 5878 6028 6002 5852 5958 5827 6025 5995 5993 5975 6224 5922 5978 5985 5875 5875 6048 5932 5901 5909 5843 6001 5738 5729 5695 5601 5747 5857 5791 5610 5535 5716 5552 5690 5765 5717 5634 5731 5698 5698 5676 5656 5782 5653 5612 5765 5788 5816 5788 5850 5814 5946 5971 5807 5683 5846 5793 5811 5854 5804 5886 5776 5812 5597 5777 5844 5817 5966 5882 5887 5927 5855 5765 6102 5849 5927 5834 5987 5912 5995 6192 6012 5855 5980 5997 6235 6028 5917 5840 6129 6051 6135 6106 5984 5955 6112 5891 5968 6029 5827 5950 5878 5922 5985 5960 6215 6038 6033 6067 6041 6167 6203 6148 6068 5993 5970 6199 6096 6121 6203 6149 6107 6067 5925 6055 6060 6129 6120 6087 6146 5969 6047 6066 5864 5751 5884 5701 5909 5811 5848 5928 5773 5813 5596 5795 5810 5768 5761 5849 5721 5815 5932 6027 5859 5811 5815 5815 5902 5812 5813 5796 5614 5614 5649 5786 5723 5774 5759 5835 5769 5728 5804 6022 5810 5642 5809 5803 5776 5850 5830 6027 5919 6057 6062 5859 6033 5890 5961 5867 6122 6101 6014 5997 5852 6011 6057 5901 5882 6010 6097 5986 5858 6087 6187 6164 6326 6187 6158 6178 6264 6290 6217 6225 6197 6089 6163 6123 5998 5884 5806 5917 5925 5850 5812 5963 6029 5830 5872 6073 5928 5905 5919 5884 5983 5942 5874 5955 5892 5835 6019 5935 5889 5787 5935 5877 5801 5738 5882 5748 5629 5808 5700 5704 5800 5853 5738 5766 5607 5640 5984 5698 5714 5858 5776 5731 5754 5928 5881 5668 5769 5723 5796 5718 5676 5613 5738 5810 5800 5839 5802 5767 5658 5794 5545 5761 5718 5771 5810 5682 5788 5728 5858 5620 5734 5776 5773 5785 5760 5737 5732 5732 5761 5775 5775 5688 5616 5798 5876 5635 5630 5757</intensities>
			</dataPoints>
			<nonAmbientPoints type="Temperature" unit="K">
[...]
			</nonAmbientPoints>
		</scan>
	</xrdMeasurement>
</xrdMeasurements>