File: powder_X-ray_diffraction/variable-temperature_experiments/NaNbO2F2/raw_data/240°C.xrdml
<?xml version="1.0" encoding="UTF-8"?>
<xrdMeasurements xmlns="http://www.xrdml.com/XRDMeasurement/1.7" xmlns:xsi="http://www.w3.org/2001/XMLSchema-instance" xsi:schemaLocation="http://www.xrdml.com/XRDMeasurement/1.7 http://www.xrdml.com/XRDMeasurement/1.7/XRDMeasurement.xsd" status="Completed">
	<comment>
		<entry>Configuration=XRK900, Owner=User-1, Creation date=12/01/2015 16:52:44</entry>
		<entry>Goniometer=Theta/Theta; Minimum step size 2Theta:0.0001; Minimum step size Omega:0.0001</entry>
		<entry>Sample stage=AP XRK-900 with z-axis; Minimum step size Z:0.001</entry>
		<entry>Diffractometer system=EMPYREAN</entry>
		<entry>Measurement program=C:\PANalytical\Data Collector\Programs\Gwen\NaNbO2F2-Lent.xrdmp, Identifier={26D14ECE-D3C8-438C-91CA-8651EAF68C7D}</entry>
		<entry>Batch program=C:\PANalytical\Data Collector\Programs\Gwen\Thermodiff-Ouail.xrdmp, Identifier={9701CF17-19F5-4DD4-A8E1-7279D1FD2F5E}</entry>
	</comment>
	<sample type="To be analyzed">
		<id></id>
		<name></name>
		<preparedBy></preparedBy>
	</sample>
	<xrdMeasurement measurementType="Scan" status="Completed" sampleMode="Reflection">
		<comment>
			<entry>PHD Lower Level = 4.02 (keV), PHD Upper Level = 12.07 (keV)</entry>
		</comment>
		<usedWavelength intended="K-Alpha 1">
			<kAlpha1 unit="Angstrom">1.5405980</kAlpha1>
			<kAlpha2 unit="Angstrom">1.5444260</kAlpha2>
			<kBeta unit="Angstrom">1.3922500</kBeta>
			<ratioKAlpha2KAlpha1>0.5000</ratioKAlpha2KAlpha1>
		</usedWavelength>
		<incidentBeamPath>
			<radius unit="mm">240.00</radius>
			<xRayTube id="1010048" name="Empyrean Cu LFF HR (9430 033 7310x) DK420743">
				<tension unit="kV">45.0</tension>
				<current unit="mA">30.0</current>
				<anodeMaterial>Cu</anodeMaterial>
				<focus type="Line">
					<length unit="mm">12.0</length>
					<width unit="mm">0.4</width>
					<takeOffAngle unit="deg">6.0</takeOffAngle>
				</focus>
			</xRayTube>
			<sollerSlit id="21010001" name="Soller slits 0.02 rad.">
				<opening unit="rad">0.0200</opening>
			</sollerSlit>
			<mask id="22030010" name="Fixed mask 20 mm">
				<width unit="mm">20.00</width>
			</mask>
			<antiScatterSlit id="22010003" name="Fixed slit 1Â°" xsi:type="fixedAntiScatterSlitType">
				<height unit="mm">1.52</height>
			</antiScatterSlit>
			<divergenceSlit id="22010012" name="Programmable divergence slit" xsi:type="fixedDivergenceSlitType">
				<distanceToSample unit="mm">140.00</distanceToSample>
				<angle unit="deg">0.5</angle>
			</divergenceSlit>
		</incidentBeamPath>
		<diffractedBeamPath>
			<radius unit="mm">240.00</radius>
			<antiScatterSlit id="22090010" name="AS slit 8.0 mm (PIXcel)" xsi:type="fixedAntiScatterSlitType">
				<height unit="mm">8.00</height>
			</antiScatterSlit>
			<sollerSlit id="21010001" name="Soller slits 0.02 rad.">
				<opening unit="rad">0.0200</opening>
			</sollerSlit>
			<filter id="20030001" name="Large beta-filter Nickel">
				<material>Ni</material>
				<thickness unit="mm">0.020</thickness>
			</filter>
			<detector id="7010019" name="PIXcel1D-Medipix3 detector" xsi:type="rtmsDetectorType">
				<phd unit="%">
					<lowerLevel>25.0</lowerLevel>
					<upperLevel>75.0</upperLevel>
				</phd>
				<mode>Scanning</mode>
				<activeLength unit="deg">3.3482</activeLength>
			</detector>
		</diffractedBeamPath>
		<scan appendNumber="0" mode="Continuous" scanAxis="Gonio" status="Completed">
			<header>
				<startTimeStamp>2022-05-15T09:39:34+02:00</startTimeStamp>
				<endTimeStamp>2022-05-15T12:40:03+02:00</endTimeStamp>
				<author>
					<name>User</name>
				</author>
				<source>
					<applicationSoftware version="5.5a">Data Collector</applicationSoftware>
					<instrumentControlSoftware version="8.1b 20190506">EMPYREAN</instrumentControlSoftware>
					<instrumentID>0000000011159748</instrumentID>
				</source>
			</header>
			<dataPoints>
				<positions axis="2Theta" unit="deg">
					<startPosition>9.99846514</startPosition>
					<endPosition>99.99342261</endPosition>
				</positions>
				<positions axis="Omega" unit="deg">
					<startPosition>4.99923257</startPosition>
					<endPosition>49.99671130</endPosition>
				</positions>
				<positions axis="Z" unit="mm">
					<commonPosition>8.912</commonPosition>
				</positions>
				<commonCountingTime unit="seconds">386.070</commonCountingTime>
				<intensities unit="counts">7537 7515 7490 7491 7303 7841 7634 7714 7621 7636 7778 7748 7715 7751 7806 7616 7621 7514 7709 7619 7724 7847 7482 7534 7622 7575 7589 7657 7572 7707 7543 7718 7708 7615 7660 7768 7768 7651 7536 7671 7655 7581 7423 7464 7504 7423 7521 7558 7669 7538 7500 7593 7562 7688 7403 7573 7719 7637 7805 7547 7645 7585 7844 7699 7756 7803 7893 8043 7976 7993 7996 8061 8113 8127 8264 8139 8286 8578 8489 8570 8563 8865 9094 9455 9947 10402 11404 12822 14799 17743 22464 28814 39846 55251 70350 80063 78608 67802 52196 37585 25108 16836 12637 10236 9374 8878 8667 8564 8188 8255 8028 8260 8101 7894 7846 7804 7634 7755 7696 7736 7709 7756 7686 7574 7757 7679 7687 7804 7815 7648 7862 7864 7755 7949 8053 7942 7781 7974 7851 8195 8103 8097 8020 7962 8051 7917 8100 8057 8041 8065 7996 7999 7897 7854 7812 7910 8002 7937 8090 8119 7911 8046 7975 8091 8123 7975 8027 8065 8083 8044 7937 8151 8067 8112 7975 8141 8172 8112 8041 7790 8030 8126 7946 7983 8009 8115 8057 8061 8131 8101 8183 7873 8107 8067 8132 7961 8047 7953 7923 7942 7886 7929 7901 7966 7938 7911 7952 7983 7874 7911 8009 8160 7965 8155 7985 7952 7948 8079 7919 7841 7922 7943 7808 7989 8049 7973 7941 7830 7917 7884 7938 7906 7890 7823 7863 7995 8044 7818 7874 7968 7979 7993 7997 8032 7914 7816 7609 7918 8016 7965 8107 7929 8009 7962 7867 7809 7901 8014 7831 7893 7924 7921 7879 7910 7716 7799 7824 7712 8016 7852 7816 7908 7787 7715 7879 7939 7849 7889 8028 8010 8116 7974 7907 7916 7761 8118 8039 8089 8063 7731 7887 7927 7841 7716 7829 7810 7746 7932 7826 7832 7856 7800 8056 7820 7705 7824 7924 7852 7927 7889 7994 7877 7965 7893 7916 7935 7986 7790 7852 7742 7948 7976 7743 7822 7722 7789 8033 8102 7943 7835 7687 7818 7874 7973 7891 8051 8113 8021 8054 8064 8182 8427 9056 9041 9684 9440 9414 9256 9061 8866 8717 8366 8239 7885 7915 7682 7824 7730 7844 7625 7831 7795 7953 7695 7873 7641 7948 7725 7829 7532 7801 7692 7626 7832 7874 7768 7664 7743 7740 7659 7663 7812 7738 7495 7801 7748 7461 7599 7806 7641 7675 7816 7551 7749 7673 7570 7697 7590 7515 7531 7717 7708 7664 7603 7694 7727 7649 7723 7650 7571 7882 7896 7841 7509 7630 7592 7697 7618 7798 7766 7633 7674 7612 7541 7575 7699 7635 7638 7653 7649 7792 7498 7557 7672 7689 7511 7563 7681 7820 7742 7783 7813 7567 7633 7694 7522 7703 7478 7783 7632 7592 7705 7642 7681 7965 7703 7800 7836 7845 7577 7785 7675 7635 7594 7556 7528 7510 7724 7643 7535 7754 7555 7594 7725 7701 7586 7507 7571 7570 7319 7460 7610 7554 7706 7707 7777 7581 7639 7755 7673 7729 7611 7697 7654 7722 7629 7617 7590 7695 7507 7528 7522 7431 7375 7488 7485 7591 7616 7441 7691 7633 7729 7779 7685 7812 7752 7940 7881 7898 7935 7869 8041 7849 7801 7709 7791 7651 7646 7542 7666 7481 7353 7406 7283 7429 7659 7460 7426 7392 7428 7389 7570 7515 7345 7614 7672 7268 7350 7507 7368 7445 7576 7403 7498 7330 7368 7402 7434 7459 7398 7503 7447 7571 7229 7374 7280 7315 7344 7379 7414 7345 7354 7407 7456 7184 7359 7368 7355 7417 7342 7395 7223 7452 7420 7330 7417 7337 7390 7616 7418 7482 7259 7309 7465 7231 7295 7339 7304 7400 7560 7530 7564 7584 7521 7450 7408 7465 7264 7456 7381 7031 7210 7521 7323 7293 7335 7303 7181 7189 7332 7181 7377 7187 7180 7181 7267 7155 7188 7263 7316 7380 7327 7333 7248 7084 7314 7178 7061 7220 7053 7360 7106 7252 7109 7108 7212 7355 7343 7357 7063 7228 7139 7209 7199 7115 7437 7300 7288 7264 7216 7286 7020 7224 7226 7159 7142 7313 7272 7038 7245 7264 7163 7105 7139 7055 7343 7331 7064 7317 7199 7195 7213 7387 7190 7197 7174 7131 7105 7386 7318 7319 7098 7288 7180 7205 7408 7428 7677 7709 7648 7580 7641 7678 7697 7661 7657 7614 7724 7704 7563 7616 7715 7404 7401 7565 7709 7695 7788 7506 7811 7826 7445 7773 7741 7798 7896 7973 7888 8181 8123 8300 8489 8537 8605 8772 8905 9137 9241 10059 10986 12130 14333 17777 23276 31112 43278 58902 75785 92850 98660 92345 80667 68702 56904 42795 30221 21338 15418 12344 10878 9967 9595 9198 9010 8815 8831 8398 8231 8148 8042 7933 7754 7728 8008 7857 7942 7886 7762 7741 7852 7652 7423 7525 7466 7454 7557 7420 7478 7483 7452 7626 7456 7565 7450 7530 7231 7424 7486 7563 7640 7473 7529 7335 7518 7625 7465 7520 7318 7537 7406 7305 7422 7338 7591 7520 7336 7388 7437 7416 7554 7407 7412 7604 7417 7446 7461 7457 7510 7574 7298 7372 7241 7371 7512 7274 7334 7407 7435 7488 7382 7567 7351 7470 7447 7382 7540 7292 7342 7233 7317 7358 7365 7324 7302 7352 7219 7199 7259 7475 7385 7278 7537 7565 7374 7556 7650 7427 7291 7433 7484 7453 7469 7433 7551 7387 7526 7458 7537 7401 7397 7440 7444 7373 7296 7194 7525 7543 7326 7372 7546 7374 7364 7481 7440 7625 7648 7474 7480 7506 7299 7511 7633 7695 7525 7474 7773 7694 7676 7447 7425 7489 7564 7547 7544 7434 7605 7501 7375 7371 7334 7421 7463 7442 7543 7596 7352 7460 7512 7359 7365 7517 7577 7344 7371 7517 7545 7390 7551 7396 7505 7526 7682 7699 7627 7512 7830 7602 7800 8048 8033 8256 8745 9228 10172 11976 14465 19314 25034 30737 33654 32222 29139 26037 23519 20665 17220 13436 10982 9429 8767 8103 7978 7805 7908 7977 7792 7683 7671 7407 7534 7545 7479 7289 7225 7464 7419 7227 7416 7328 7354 7377 7397 7409 7498 7335 7359 7451 7446 7373 7443 7362 7487 7534 7662 7558 7570 7524 7621 7522 7492 7554 7667 7644 7587 7485 7587 7656 7561 7568 7491 7714 7802 7548 7469 7486 7508 7677 7633 7462 7522 7508 7424 7479 7686 7680 7647 7688 7840 7799 7924 7818 7868 8086 8357 8515 9019 9184 10490 12531 16258 21259 26513 30064 30051 27380 23513 22073 20437 18035 14381 11576 10342 9566 9435 9184 9222 9569 10050 10688 12592 15639 21572 29157 36805 40412 37437 32485 29733 27818 24686 20266 15732 12592 10414 9097 8692 8247 8231 8190 8078 7859 8045 7987 8126 7949 8001 7771 7902 7729 7835 7743 7708 7561 7620 7538 7427 7226 7513 7288 7373 7440 7502 7322 7400 7474 7355 7369 7431 7415 7294 7407 7392 7439 7418 7358 7361 7367 7337 7448 7380 7352 7221 7310 7282 7304 7428 7097 7193 7215 7080 7319 7331 7424 7364 7382 7255 7363 7316 7277 7271 7208 7268 7276 7483 7453 7485 7464 7288 7644 7458 7535 7571 7421 7374 7210 7180 7256 7303 7335 7244 7254 7313 7230 7345 7328 7267 7193 7278 7261 7169 7046 7286 7396 7249 7340 7357 7384 7224 7313 7202 7242 7285 7209 7339 7242 7360 7198 7167 7246 7253 7261 7286 7396 7289 7299 7300 7275 7352 7313 7266 7268 7215 7205 7384 7356 7445 7421 7445 7219 7413 7167 7457 7304 7240 7229 7237 7392 7277 7318 7164 7305 7275 7395 7278 7030 7279 7418 7325 7155 7236 7305 7266 7276 7206 7264 7112 7147 7182 7162 7261 7262 7277 7227 7143 7320 7142 6980 7206 7306 7223 7249 7157 7138 6958 7391 7175 7181 7119 7127 7405 7122 7127 7138 7113 7295 7197 7132 7063 7253 7196 7004 7160 7112 7073 7117 6981 7159 7107 7045 7171 7260 7242 7277 7394 7447 7706 7523 7580 7315 7518 7427 7438 7275 7351 7488 7474 7503 7391 7495 7433 7445 7572 7505 7489 7366 7309 7465 7396 7213 7318 7401 7456 7548 7272 7364 7446 7257 7344 7528 7419 7486 7471 7252 7397 7448 7404 7516 7545 7495 7420 7528 7553 7640 7711 7393 7712 8086 8015 8167 8327 8260 8674 8663 9019 9305 9549 9828 10263 10674 11553 12758 14794 17630 22792 31327 43712 59602 75786 86919 89728 83275 73034 65162 59595 54697 47156 37756 28051 20878 16098 13245 11618 10697 10080 9616 9291 9026 8788 8404 8401 8177 8188 7922 7958 7881 7720 7713 7632 7757 7761 7571 7643 7579 7691 7644 7716 8166 8066 8199 8403 8754 8932 8814 8637 8436 8142 8125 8080 8088 7706 7583 7638 7600 7592 7604 7694 7672 7684 7617 7866 7799 7885 7938 7915 8010 8382 8326 8583 9089 9932 11295 13608 18155 26194 34883 40365 38893 33152 27839 26004 26038 25056 22401 17847 14056 11446 9871 9078 8935 9109 9290 9989 11172 12360 13860 15132 16141 16408 15916 15368 14688 14445 14009 13311 12311 11231 10190 9657 9116 8588 8412 8274 8021 7915 7497 7461 7475 7181 7402 7369 7172 7321 7343 7269 7225 7222 7495 7139 7183 6998 7066 7047 7169 7119 7165 7214 7213 7112 7216 7108 7143 7219 7315 7214 7060 7224 7098 7139 7139 6845 6938 6964 6972 7043 7045 7110 7086 6910 7032 7002 6978 7114 7109 7023 7042 7056 7020 6935 7105 7101 6993 6880 6977 7061 6952 7108 6977 7092 7094 7114 7119 7155 6870 6945 6869 6839 6927 7054 7042 7113 7014 7006 7059 6938 6974 6955 6966 6894 7056 7065 6920 6886 6907 7033 6879 6974 6972 7033 6959 6768 7054 6983 7014 6954 6946 6750 7033 6845 6942 6872 6913 6799 6893 7124 6890 6894 6883 6962 7003 6872 6792 6920 6852 6819 6692 6891 6791 6942 6902 6895 7004 7039 6955 6639 6768 6898 6959 6927 6880 6999 6956 6972 6698 6771 6945 6862 6935 6829 6793 6842 6889 6838 6893 6902 6768 6982 6748 6919 6980 6827 6859 6926 6852 6924 6891 6967 7023 7000 6810 6850 6896 6955 6785 6791 6690 6784 6860 6828 6986 6821 6872 6875 6842 6897 7008 6766 6878 6802 7083 7082 6859 6829 6899 6948 6840 6884 6890 6971 6839 6879 6890 6893 6751 6816 6830 6724 6808 6714 6885 6884 6904 6876 7003 7001 6835 6828 6890 7043 6882 6945 7006 6929 6913 7006 6915 6934 6963 6785 6945 7002 6760 6809 6934 6815 6784 6889 6954 6939 6987 6951 6816 6724 6887 7243 6881 7078 6844 6909 7009 6961 7080 7129 7401 7308 7384 7544 7670 7867 8305 9219 10684 12254 14355 15330 15319 14609 12909 12920 13334 14534 16780 19428 21750 21771 19726 16225 13979 13575 13760 14190 13650 12001 10269 8806 8077 7797 7514 7481 7253 7181 7113 6985 6997 6935 6897 6951 6959 6943 7005 6900 7032 7115 7044 6936 7054 7018 7089 7071 6815 7106 7169 7099 7345 7318 7638 7827 8206 9122 10375 11616 13429 14636 15062 14344 13437 11988 11426 11422 11169 10826 10061 9218 8361 7728 7340 7211 7242 7244 7057 7275 7328 7337 7620 7857 7825 7812 7983 7607 7414 7511 7544 7422 7476 7829 7672 8057 8721 10031 11239 13061 13874 13429 12580 11243 10643 10173 10514 10326 9864 9181 8652 7876 7385 7072 7028 6937 6938 6876 6823 6868 6843 6721 6805 6757 6723 6768 6716 6843 6783 6761 6818 6733 6807 6848 6802 6821 6835 6599 6625 6863 6813 6917 6981 6931 6970 7058 7130 7359 7719 8544 9406 10516 11577 11734 11495 11154 10299 9947 9798 9404 9275 9178 8722 8208 7761 7304 7368 7378 7382 7452 7455 7499 7281 7004 7031 7157 6977 7072 7077 6810 6860 6755 6632 6661 6677 6558 6723 6721 6604 6588 6631 6598 6641 6660 6615 6536 6646 6697 6620 6484 6771 6496 6702 6479 6597 6685 6762 6725 6539 6525 6610 6561 6575 6667 6633 6474 6457 6621 6543 6592 6520 6644 6665 6706 6578 6526 6572 6687 6616 6499 6467 6498 6449 6559 6640 6485 6432 6443 6380 6592 6633 6651 6565 6713 6685 6616 6524 6655 6770 6671 6479 6699 6650 6695 6642 6689 6634 6692 6797 6815 6793 6768 6596 6612 6730 6669 6628 6495 6654 6811 6670 6798 7162 7200 7509 8315 9156 9795 10120 9682 8731 8450 7970 7958 8383 8336 8120 7776 7320 7043 6859 6895 6774 6773 6728 6481 6563 6526 6610 6645 6502 6649 6412 6542 6442 6623 6675 6619 6419 6375 6490 6562 6537 6612 6795 6757 6642 6373 6741 6631 6571 6374 6428 6582 6493 6692 6719 6520 6477 6580 6546 6537 6439 6595 6594 6565 6692 6608 6657 6656 6437 6545 6650 6702 6654 6670 6782 6810 6917 6906 7344 7403 7349 7448 7279 7242 7212 7384 7534 7561 7841 8472 8776 9502 10360 10958 11523 11531 11089 10513 10207 10155 10985 11524 11318 10742 9846 8897 8383 8030 8344 8066 7866 7478 7110 6955 6858 6695 6764 6642 6552 6502 6500 6682 6641 6661 6479 6687 6741 6521 6488 6614 6623 6653 6610 6644 6619 6523 6516 6376 6404 6635 6571 6504 6551 6562 6415 6306 6314 6426 6660 6449 6465 6348 6444 6423 6554 6442 6352 6433 6499 6524 6599 6517 6537 6417 6664 6501 6550 6593 6518 6542 6689 6723 6559 6558 6586 6557 6553 6549 6360 6376 6486 6498 6442 6676 6544 6371 6402 6420 6347 6408 6515 6508 6502 6606 6612 6735 6571 6670 6540 6416 6498 6748 6784 6659 6604 6755 6840 6956 7339 8021 8871 9517 9368 8752 8174 7533 7654 7712 8051 8133 7990 7488 7129 6910 6652 6640 6646 6645 6592 6476 6456 6597 6554 6551 6606 6508 6138 6309 6478 6478 6480 6553 6454 6436 6596 6593 6544 6649 6538 6484 6449 6574 6425 6591 6393 6413 6323 6294 6602 6689 6620 6585 6476 6503 6483 6544 6283 6516 6478 6416 6517 6561 6527 6654 6518 6541 6632 6689 6491 6587 6774 6582 6612 6955 7048 7177 7601 7905 7988 8184 8608 9074 9245 9917 9750 9560 9026 8475 8125 8124 8080 7975 8040 7915 7582 7063 6658 6645 6707 6648 6685 6524 6641 6595 6682 6430 6402 6405 6559 6642 6526 6524 6504 6391 6504 6503 6597 6664 6511 6498 6471 6310 6497 6374 6499 6654 6512 6521 6574 6644 6627 6739 6962 6867 6908 6935 7326 7704 8137 8557 8755 9156 9536 9770 10594 11348 12001 12035 11728 11455 10776 10899 11308 11497 11421 11024 9989 9186 8633 8303 8267 8116 8036 7632 7308 7126 6871 6824 6668 6696 6636 6342 6473 6410 6559 6531 6445 6485 6357 6495 6604 6411 6246 6347 6445 6458 6519 6529 6372 6555 6460 6311 6276 6377 6342 6430 6509 6410 6514 6542 6453 6382 6426 6350 6395 6437 6664 6350 6445 6617 6626 6371 6363 6453 6467 6516 6320 6316 6289 6411 6513 6482 6490 6471 6406 6284 6388 6328 6368 6532 6506 6558 6643 6397 6331 6344 6266 6324 6472 6396 6316 6454 6344 6352 6384 6442 6322 6211 6337 6444 6389 6290 6496 6424 6179 6314 6400 6454 6503 6336 6317 6537 6244 6340 6425 6511 6386 6236 6243 6063 6325 6413 6537 6399 6389 6497 6202 6287 6466 6364 6321 6455 6334 6469 6373 6359 6317 6580 6525 6430 6318 6454 6204 6415 6561 6500 6516 6286 6436 6359 6384 6353 6354 6385 6346 6255 6351 6491 6469 6358 6323 6426 6550 6289 6294 6357 6419 6353 6525 6506 6306 6396 6417 6524 6403 6418 6616 6541 6575 6831 6723 7195 7427 7657 7809 7784 7690 7557 7191 7161 7403 7291 7309 7197 7236 7017 6787 6686 6508 6590 6596 6452 6371 6466 6322 6532 6445 6363 6319 6446 6459 6486 6336 6262 6444 6299 6562 6413 6376 6481 6511 6528 6577 6683 6834 6726 6666 6428 6487 6414 6389 6562 6577 6677 6555 6555 6231 6488 6488 6518 6532 6521 6550 6689 6521 6627 6795 6700 6522 6680 6765 6685 6794 7111 7364 7641 7992 8560 9569 10711 11776 12682 13043 12822 12099 11013 10009 9703 9560 9741 9864 9910 9882 9258 8448 7759 7203 7278 7067 6808 6754 6771 6530 6464 6488 6545 6803 6639 6404 6327 6405 6412 6421 6407 6417 6472 6535 6324 6305 6397 6368 6470 6480 6477 6372 6282 6324 6520 6210 6381 6462 6396 6403 6357 6407 6369 6384 6357 6402 6516 6272 6312 6277 6399 6300 6222 6237 6440 6273 6364 6416 6416 6272 6228 6461 6444 6445 6431 6347 6349 6310 6483 6500 6378 6215 6326 6475 6494 6352 6306 6295 6579 6484 6559 6591 6601 6572 6601 6557 6604 6742 6719 6713 6723 6853 6945 6758 6851 7016 7405 7477 7941 8621 9704 11781 14233 17049 18402 18886 18598 17257 15091 13157 11978 11865 12259 12944 13240 12970 12389 11425 10215 9128 8575 7939 7502 7262 7033 7004 7031 7047 6952 7002 7019 6795 6761 6721 6630 6670 6609 6554 6637 6439 6466 6606 6585 6529 6487 6531 6479 6642 6286 6690 6424 6479 6561 6416 6473 6520 6495 6580 6659 6397 6352 6352 6540 6454 6217 6361 6442 6301 6369 6425 6394 6473 6346 6422 6426 6429 6431 6308 6185 6320 6453 6543 6484 6410 6679 6408 6608 6493 6520 6491 6656 6652 6563 6662 6698 6676 6766 6988 7061 7255 7634 7844 8092 8538 8869 8906 8805 8611 8531 8285 8344 8779 9492 10782 12365 13493 14087 12994 11370 9738 8769 8335 8536 9004 9758 10064 10169 9223 8541 7878 7523 7298 7193 6897 6986 7073 7002 6995 6997 6961 7017 7128 6967 7040 6964 7040 7131 7326 7165 7448 7413 7866 8215 8688 9520 10417 11956 13760 15552 17174 18226 18585 18221 16763 14988 13540 12682 12492 12522 12981 12926 12721 12177 11195 10118 8954 8273 7806 7459 7331 7083 6992 7026 6910 6716 6889 6804 6617 6559 6678 6553 6460 6487 6707 6864 6642 6604 6863 6836 6900 6816 7214 7655 7658 7960 8028 7976 7880 7697 7542 7700 7829 7738 7954 7882 7824 7618 7562 7454 7387 7167 7344 7141 7117 7235 7014 7021 7077 7010 7138 7216 7490 7466 7708 7885 8234 9041 10003 11134 12410 13749 14404 14844 14630 14170 12863 11706 11346 11721 12227 13224 13996 14582 13427 12542 11213 10101 9214 8668 8759 8560 9030 8754 8292 8075 7706 7604 7317 7032 6965 6925 6738 6840 6796 6772 7057 6788 6904 6823 6776 6883 6920 6976 7247 7111 7224 7332 7478 7845 8123 8730 9826 11242 13403 15780 17777 19165 19096 17514 15122 12960 11383 10862 11271 11888 12673 13408 13188 12460 11122 9630 8798 8222 7641 7339 7183 7183 7109 6951 6890 6866 6792 6628 6676 6385 6904 6869 6602 6721 6719 6899 6913 6959 7207 7448 7442 7433 7653 7493 7384 7304 7449 7521 7591 7976 8452 8944 9174 9409 9409 9242 9286 9425 9615 9855 9944 9630 9376 8953 8550 8379 8189 7972 8091 8115 8027 7683 7580 7274 7044 6792 6731 6581 6599 6600 6678 6600 6673 6648 6425 6402 6460 6381 6209 6414 6572 6385 6511 6534 6366 6501 6532 6624 6445 6648 6587 6627 6613 6470 6572 6457 6519 6417 6481 6459 6572 6661 6527 6562 6513 6536 6521 6537 6563 6495 6675 6671 6831 7004 6935 6866 6880 7077 7559 7885 8227 8893 9400 10755 12350 14193 15546 15381 14137 12339 10623 9912 9704 9836 10390 11126 11674 11746 11138 10241 9180 8380 7923 7615 7320 7258 7061 7173 7042 6945 6730 6703 6539 6504 6636 6490 6597 6377 6404 6467 6382 6372 6393 6476 6297 6355 6285 6362 6405 6282 6464 6535 6536 6486 6663 6394 6483 6498 6320 6518 6407 6476 6418 6494 6530 6365 6561 6514 6356 6434 6509 6412 6546 6614 6559 6557 6688 7040 7189 7912 8197 8133 7880 7457 7175 7058 6764 6771 6773 6803 7236 7213 7378 7088 6801 6633 6643 6556 6435 6403 6389 6488 6464 6319 6249 6112 6473 6133 6305 6416 6467 6343 6282 6028 6250 6270 6205 6308 6354 6251 6147 6293 6383 6361 6504 6488 6443 6484 6455 6534 6641 6574 6398 6322 6320 6325 6423 6490 6321 6443 6178 6300 6367 6308 6343 6334 6227 6273 6365 6384 6295 6391 6279 6037 6297 6185 6391 6367 6268 6349 6419 6264 6407 6445 6592 6516 6341 6493 6526 6503 6399 6476 6409 6351 6383 6478 6443 6415 6319 6424 6411 6488 6297 6149 6381 6243 6281 6264 6348 6345 6229 6207 6185 6218 6235 6357 6273 6322 6219 6135 6191 6246 6278 6399 6334 6233 6156 6326 6556 6311 6178 6335 6313 6292 6294 6288 6150 5997 6295 6346 6242 6145 6205 6192 6234 6146 6167 6333 6158 6232 6308 6202 6318 6277 6469 6257 6294 6228 6207 6352 6200 6263 6353 6352 6319 6298 6311 6309 6382 6313 6235 6338 6281 6346 6410 6303 6428 6289 6405 6492 6299 6100 6203 6472 6511 6430 6466 6409 6293 6346 6313 6300 6257 6385 6427 6454 6310 6451 6433 6522 6364 6462 6365 6380 6516 6498 6549 6644 6663 6613 6875 6918 7190 7604 8045 8492 8764 8814 8441 7887 7715 7647 7646 7858 8112 8516 8554 9184 9632 9915 10187 10739 11279 11907 12351 12508 12372 11695 10915 9875 9233 8822 8755 8933 9258 9065 9433 9605 9023 8734 8094 7846 7482 7261 7391 6945 7160 7329 7100 7158 7048 6970 6800 6779 6810 6834 6835 6818 6733 6919 6881 6893 6985 7149 7586 7883 8474 8859 9342 9328 9287 8636 8194 7635 7548 7354 7491 7728 8023 8139 8330 8056 8278 7805 7684 7573 7630 7975 8425 9160 9908 10413 10962 10909 10280 9545 8650 8244 7804 7806 7885 7904 8085 8548 8575 8826 8327 8154 7810 7524 7328 7217 7136 7121 7060 7092 7066 6733 6665 6607 6744 6651 6725 6760 6697 6608 6737 6550 6581 6480 6551 6561 6535 6454 6375 6426 6346 6467 6331 6413 6373 6311 6467 6348 6377 6472 6523 6354 6426 6533 6291 6396 6306 6372 6387 6401 6477 6366 6607 6442 6379 6478 6533 6508 6485 6422 6387 6557 6671 6765 6844 7091 6933 7356 7562 7824 8307 8543 8787 9123 9008 9234 9337 9272 9015 8913 9054 9218 9833 10290 10709 10861 11045 10696 9991 9284 8908 8456 8051 7871 7860 8157 8368 8080 8211 8081 7640 7384 7231 7030 6799 6757 6572 6568 6532 6444 6435 6503 6429 6627 6611 6352 6237 6516 6481 6325 6379 6478 6778 6535 6384 6346 6599 6606 6725 6751 6959 7236 7330 7617 7766 7680 7767 7729 7816 7668 7594 7494 7326 7421 7397 7884 8269 8467 8778 9341 9665 9737 9709 9691 9565 9511 9603 9936 10122 10468 10745 10716 10305 10229 9984 9972 10053 10496 10560 10375 10129 9788 9468 9248 8905 8586 8737 8961 9404 10006 10477 10782 10490 10242 9795 8932 8444 7866 7652 7588 7519 7714 7804 7938 8106 7997 7856 7675 7222 7059 6644 6505 6457 6507 6449 6514 6445 6342 6366 6297 6465 6326 6353 6388 6502 6292 6422 6389 6375 6612 6355 6532 6463 6397 6466 6609 6608 6718 6611 6830 6558 6715 6746 6735 6739 6649 7101 7198 7539 8056 8787 9657 10889 11760 12385 12156 11224 10214 9204 8431 8059 7788 7903 7898 8306 8870 9258 9389 9342 8619 8117 7488 7079 6809 6772 6569 6435 6490 6262 6432 6390 6627 6292 6465 6530 6500 6545 6601 6726 6627 6753 7180 7694 7987 8620 8885 9140 8886 8565 7764 7247 7447 7227 7271 7308 7324 7673 7666 7997 7899 7497 7448 7208 6903 6808 6806 6813 6633 6745 6588 6526 6484 6441 6460 6544 6410 6564 6627 6574 6603 6777 6612 6615 6697 6596 6738 7015 7044 7365 7691 8272 8602 9542 10296 11261 11904 12660 13236 13486 13278 12957 12361 11641 10621 9900 9645 9426 9410 9477 9893 10000 9901 9813 9655 9238 8741 8117 7726 7338 6959 6816 6572 6541 6623 6828 7009 6907 7270 7441 7809 7805 7384 7257 6948 6700 6494 6647 6589 6477 6699 6782 6956 6874 6901 6934 6775 6502 6251 6340 6394 6320 6256 6138 6360 6319 6302 6140 6085 6380 6319 6136 6303 6169 6097 6095 6214 6095 6067 6185 6198 6257 6046 6058 6191 6107 6198 6235 6119 6162 6198 6059 6253 6226 6075 6055 6150 6019 6075 6244 6080 6124 5876 6268 6135 6162 6375 6282 6117 6185 6203 6195 6026 6151 6135 6008 6065 6017 6159 6072 6058 6157 6335 6149 6116 6220 6224 6229 6271 6232 6110 6102 6295 6050 6170 6128 6206 6007 6220 6165 6101 6006 6181 6121 6152 6329 6295 6247 6206 6221 6199 6334 6340 6327 6338 6406 6534 6932 7066 7251 7284 7533 7410 7560 7400 7076 6913 6685 6692 6846 7063 6742 7046 7217 6978 7233 7529 7701 7972 8090 8156 8066 7802 7183 6921 6875 6796 6748 6589 6622 6972 7042 7141 7222 7203 7089 6803 6710 6846 6356 6369 6151 6277 6449 6343 6284 6258 6346 6424 6366 6146 6097 6224 6028 6058 6110 6060 6093 6086 5948 6060 6073 6127 6087 6160 6281 6221 6382 6094 6106 6117 6055 6256 6343 6356 6221 6428 6610 6605 6891 6885 7128 7123 7082 7321 7228 7161 6815 6480 6480 6545 6463 6703 6556 6802 6588 6555 6794 6648 6467 6526 6552 6475 6316 6199 6193 6183 6207 6199 5955 6157 6177 6176 6243 6130 6266 6126 6102 6084 5894 6088 6249 6097 6139 5899 5950 6103 6305 6183 6050 6003 5973 6086 6130 6028 6031 6047 6210 6272 6087 6135 6162 6063 6091 6192 6042 6274 6053 6184 6089 6197 6121 5973 6178 6266 5974 6172 6080 6243 6196 6118 6075 6182 6042 6049 6013 6038 6085 5984 6098 6065 5954 6024 5959 6040 6058 5936 5949 5919 5990 6026 5924 5903 6024 6074 5854 5984 6105 5962 5937 6010 5977 5957 6034 5952 6083 5871 5968 6152 6000 5878 5944 5894 5982 5967 5878 5812 5889 5927 6060 5948 5793 5843 6002 5933 5979 5865 5949 6020 6048 5917 5992 5997 6131 6081 5959 6068 6061 6212 6090 6118 5991 5989 5909 5857 5974 5983 5909 6093 5975 5944 6228 5970 6178 6172 6142 6060 6127 6175 6176 6057 6109 6022 5865 6011 6055 6142 5934 5993 6000 6091 6101 6098 6247 6092 6113 6113 5989 5918 5923 5953 6092 5914 5983 6125 6069 6127 6020 5842 6048 5961 5849 5973 5937 6093 6014 5943 6023 6030 5913 5997 5996 6071 5953 5938 5979 5878 5818 5960 5849 6101 5915 5951 5939 6006 6073 6086 5870 6099 6052 5884 6069 6101 6061 6196 6141 6097 6144 6175 6255 6010 6029 6063 5952 6038 6179 5990 5941 5975 6196 5926 5981 6061 6041 6064 6130 6074 6057 6075 6078 6146 6087 6186 5911 5888 6021 5939 5979 6052 5965 5927 6038 6005 5985 5939 5882 5990 5924 6077 6011 5914 6103 5823 5841 5846 5926 6135 5944 5929 6046 6124 5939 5866 6017 5990 5978 6133 6099 5965 6058 6055 6011 5929 5901 6062 6012 6020 6143 5935 6184 5900 5780 5863 6048 6059 5937 6028 5958 5965 6093 6006 5929 6104 5949 6037 5903 6005 6172 6080 6143 6099 6047 6206 6065 6123 6262 6168 6182 6215 6222 6374 6253 6406 6392 6395 6384 6678 6844 6803 6795 7035 7124 7118 7233 7163 7380 7192 7319 7056 6918 6812 6574 6731 6783 6677 6655 6703 6664 6967 6801 6863 7040 7251 7436 7627 7935 8211 8286 8241 8026 7869 7620 7305 7036 7133 7250 7316 7550 7849 8126 8388 8559 8414 8454 8233 8116 7909 7728 7381 7549 7377 7176 7045 7119 7129 6914 6992 6832 6882 6800 6917 6627 6739 6752 6794 6704 6597 6677 6763 6686 6948 7152 7738 7669 7810 7837 7235 6968 6748 6565 6435 6458 6366 6472 6494 6372 6482 6722 6914 7067 6907 6853 6586 6507 6407 6325 6255 6205 6284 6146 6178 6287 6148 5956 6156 6334 6144 6486 6211 6163 6219 6227 6155 6041 6088 6163 6169 6353 6053 6219 6274 6244 6345 6483 6451 6414 6438 6576 6700 6448 6623 6593 6444 6510 6555 6405 6609 6547 6728 6816 6638 6644 6687 6590 6685 6609 6632 6459 6254 6376 6467 6407 6633 6513 6434 6552 6379 6317 6182 6157 6155 5991 6185 5864 6003 6010 5976 6143 6006 6085 6113 6089 6093 5837 5962 6199 6128 6076 6124 6115 5981 6040 5966 5958 5877 5965 5991 5829 5970 5912 5916 6131 6120 6200 5991 6076 6026 6200 6128 6286 6097 6184 6115 6064 6092 6194 6176 6239 6407 6291 6229 6382 6479 6425 6366 6538 6427 6427 6296 6391 6459 6577 6376 6569 6691 6833 7028 7526 7735 8024 8204 8442 8336 8338 8009 7924 7791 7510 7213 6895 6852 6720 6907 6862 6958 7177 7186 7214 7295 7112 6978 6972 6902 6627 6541 6367 6451 6216 6129 6284 6012 6175 5962 6098 6112 5976 6094 6116 5966 5890 5964 5971 5995 6010 5887 6203 6235 6240 6291 6492 6486 6658 6611 6636 6449 6245 6260 6183 6129 6044 6032 6112 6189 6244 6261 6190 6241 6363 6323 6461 6405 6265 6131 6221 5973 6037 6201 6115 6041 6147 6315 6202 6197 6435 6371 6078 6103 6090 6212 6094 6367 6111 6223 6180 6195 6299 6479 6469 6534 6737 6900 7049 7237 7159 6968 7050 7304 7170 7267 7123 6912 6660 6493 6583 6481 6485 6410 6680 6573 6526 6570 6511 6606 6474 6447 6597 6529 6378 6384 6202 6143 6112 6144 6025 5963 6079 6010 6046 6192 5983 5997 6233 6108 6195 6217 6105 6216 6343 6176 6150 6130 6163 6308 6323 6138 6163 6278 6111 6239 6155 6341 6562 6500 6663 6624 6858 6832 6754 6777 7085 7096 7191 6997 7051 7097 7172 7275 7213 7426 7235 7134 7238 7027 7072 6901 6883 6883 6953 6880 6924 6780 6895 6811 6724 6576 6749 6537 6459 6416 6567 6442 6357 6357 6449 6463 6479 6234 6330 6255 6066 6060 6031 5955 6087 6070 6156 6121 6141 5950 6144 6101 5939 6129 5979 5937 6145 6240 6038 6071 6141 6020 5875 6021 5962 5948 5926 5957 5842 5979 5917 5879 6047 5995 5949 6070 5990 5989 5951 5827 5851 6112 5946 5891 5920 6075 5855 5862 5783 5886 6070 6015 5798 5845 5839 5754 5896 6019 5961 5818 5858 6010 5948 5887 5934 5878 5906 5806 5821 5919 5796 5975 5852 5955 5845 5948 5999 5856 5969 6050 6081 6155 6217 6255 6330 6335 6383 6247 6169 6215 6173 6241 6109 5891 5898 6117 6076 5899 6041 6079 6240 6164 6340 6216 6123 6015 5901 6134 5995 5985 6109 5947 5961 6094 5855 5991 6032 5891 5961 5955 6065 5950 6166 5997 5936 5957 5870 5900 5819 6101 6082 6019 5927 6143 6292 6310 6132 6318 6310 6182 6305 6217 6197 6254 6377 6376 6253 6230 6195 6308 6377 6454 6594 6837 6798 7040 6994 7185 7132 7280 7218 7161 7056 6893 6670 6657 6759 6922 7117 7317 7441 7781 7610 7315 7130 6955 7070 6869 6842 6543 6562 6348 6326 6441 6419 6358 6561 6677 6682 6692 6538 6539 6382 6197 6313 6186 6236 6224 6323 6393 6346 6189 6164 6314 6110 6118 6168 6045 6115 6328 6106 6168 6269 6267 6434 6689 6892 7073 7276 7340 7211 6965 6713 6516 6335 6449 6074 6129 6181 6139 6116 6136 6300 6325 6451 6506 6553 6503 6481 6108 6235 6123 6235 6188 6017 5862 5928 5736 5837 5874 5908 5978 5805 5982 6019 6013 5834 5748 5879 5840 5795 5838 5924 6058 5905 5719 5997 5864 5911 5867 5787 5950 5964 5723 6049 5955 5826 5940 5924 5883 5884 5806 5871 5933 5954 5950 5933 5791 5904 5772 5878 6013 5862 5990 5884 5882 5924 5932 6034 5939 6053 6016 6002 5929 6041 5867 6136 6179 6083 5983 5888 5961 6014 5927 6258 6175 6226 6150 6166 6424 6378 6315 6404 6627 6843 6695 6688 6671 6855 6953 7032 6964 6902 6728 6853 6769 6641 6444 6316 6594 6518 6564 6572 6494 6765 6518 6576 6539 6751 6733 6685 6550 6612 6547 6532 6524 6257 6212 6167 6123 6133 6304 6196 6115 6023 6153 6097 6286 6404 6268 6454 6352 6318 6268 6510 6374 6312 6508 6542 6842 6695 6696 6992 6854 7158 6826 6650 6785 6545 6547 6525 6400 6402 6354 6696 6662 6647 6879 6804 6679 6806 6693 6734 6530 6703 6617 6483 6146 6125 6168 6211 6034 6322 6277 6328 6047 6448 6425 5975 6226 6129 6055 6031 6119 5854 6034 6065 6043 5885 5887 6016 5866 6019 5962 5921 5920 5942 6017 6039 5974 6082 6098 6106 5931 5974 6275 6269 6450 6632 6526 6794 6964 6854 6845 6877 6958 6895 6901 6651 6754 6861 6770 6682 6662 6709 6738 6707 6864 6879 6812 6786 6750 6668 6617 6531 6361 6467 6378 6249 6397 6244 6209 6248 6192 6273 6310 6392 6292 6294 6345 6323 6321 6329 6349 6512 6449 6404 6287 6241 6469 6380 6338 6284 6327 6220 6321 6459 6505 6703 6668 6708 6548 6673 6655 6889 6807 6705 6684 6700 6628 6609 6519 6553 6386 6364 6231 6241 6241 6269 6372 6337 6491 6416 6094 6216 6325 6074 6151 6122 6156 6357 6152 6061 6048 6039 6019 5881 6020 6072 6039 5957 5979 5995 5973 5994 6102 5931 6069 5980 5878 6030 6130 5827 5776 6052 5970 5997 5976 5924 5882 5913 6052 6018 6169 6256 6189 6211 6116 6237 6270 6260 6398 6225 6257 6093 6158 6057 5986 6201 6242 6104 6238 6177 6319 6374 6293 6346 6404 6373 6380 6310 6374 6319 6298 6329 6235 6138 6195 6054 6130 6274 6059 6036 6164 6180 5931 6030 5970 5990 5855 6046 6132 6025 6142 6121 6082 6164 6277 6106 6349 6260 6346 6489 6380 6389 6492 6521 6400 6275 6234 6306 6260 5939 6175 6097 6165 6227 6233 6216 5999 6192 5967 6106 6170 6207 6276 6231 6377 6092 6115 5828 6109 6145 5925 5966 5953 5924 5740 5831 5920 5767 5828 5774 5809 5886 5837 5896 5643 5952 5980 5909 5748 5776 5803 5765 5775 5720 5767 5798 6062 5901 6001 5959 5833 5764 5656 5764 5752 5807 5643 5698 5686 5977 5822 5723 5648 5776 5775 5865 5850 5930 5926 5871 5804 5896 5967 5949 6046 5906 5947 5874 5940 5849 5672 5833 6059 5925 6011 5988 5970 6079 5960 5998 5952 5962 5909 5761 5954 5990 6102 5898 5993 5775 5980 6085 6082 6130 6074 6172 6278 6060 6065 6261 6363 6227 6225 6252 6234 6200 6259 6347 6405 6281 6362 6275 6263 6118 6118 6063 6203 6148 5976 5912 6131 6003 6172 5960 6049 6002 6225 6136 6091 5824 5980 6183 6066 6111 5897 5977 5788 5793 5727 5875 5963 5869 5857 5930 5842 5880 5846 5942 5930 5817 5754 5836 5668 5855 5943 5763 6000 5938 6042 5933 5994 6159 5954 5915 6035 5766 5779 5843 5857 5878 5976 5799 5879 5843 6073 5856 5888 5881 5963 5838 5939 5891 5900 5789 6070 6033 6038 5969 6052 6162 6219 6236 6205 6252 6223 5915 6087 5946 6005 5783 5939 5957 5857 6160 5894 6032 6021 6002 5758 6248 6030 6045 6067 6048 6022 5760 5881 5945 5752 5928 5881 5915 5841 5706 5639 5907 5948 5934 5814 5902 6163 6038 6024 6040 6067 5907 6006 5919 5990 5984 5994 6103 6017 6083 6093 5891 6134 6106 6220 6159 6127 6036 6051 6264 6004 6021 6070 6221 6106 6113 6123 6230 5972 5979 6167 6306 6359 6594 6873 6755 6905 7216 7427 7267 7157 6873 6872 6586 6639 6460 6435 6502 6384 6482 6505 6506 6551 6608 6923 6673 6840 6899 6925 6945 6903 6672 6692 6509 6511 6145 6338 6304 6356 6351 6153 6303 6126 6204 6347 6122 6122 6241 6226 6044 6190 6217 6026 6016 6237 6063 5900 5903 5867 6004 5991 6023 5979 5908 5973 6092 5881 5894 6034 5975 5939 6008 5951 5932 6023 5860 6039 6057 5969 6007 6145 6074 6017 6054 6055 6192 6238 6171 6192 5954 6060 6379 6104 6074 6297 6266 6454 6260 6413 6575 6406 6390 6642 6382 6574 6591 6303 6020 6168 6241 6199 6104 6167 6099 6161 6018 5945 6061 6047 5958 6088 6163 5919 6004 6120 6104 6188 6005 6000 6002 5859 5949 5971 5812 5928 5773 5900 5931 5879 6045 6022 5959 6222 6172 6150 6225 6243 6445 6508 6578 6366 6293 6276 6330 6269 6089 6129 6194 6169 6412 6135 6292 6433 6356 6399 6378 6456 6422 6297 6412 6208 6333 6300 6072 6231 6050 6211 6114 6141 5997 6073 6359 6127 6258 6435 6549 6482 6342 6541 6349 6347 6184 6266 6185 6114 6261 6189 6260 6283 6314 6380 6298 6448 6454 6641 6678 6846 6798 6794 6852 6819 6752 6581 6692 6465 6496 6320 6194 6224 6191 6129 6237 6248 6168 6227 6163 6260 6246 6170 6389 6469 6441 6751 6795 6709 6882 6775 6700 6734 6447 6202 6193 6117 6085 5962 5966 5925 6084 6132 5842 5894 5941 5961 5856 5798 6048 5960 6270 6286 6207 5766 6021 5776 5826 5665 5685 5915 5896 5662 5696 5786 5887 5801 5686 5800 5848 5874 5789 5920 5831 5702 5876 5616 5795 5708 5677 5833 5983 5861 5828 5876 5902 5816 5880 5909 5880 5915 6062 5831 5955 6011 5963 5898 5945 5749 5794 5783 5982 5740 5868 5880 5825 5791 5921 5943 5870 5771 5839 5968 5774 5767 5826 5727 5784 5761 5970 5870 5837 5819 5939 5862 6045 5938 5947 5982 6189 6032 6007 6219 6054 6162 6150 6157 6220 6076 6064 6080 6104 6049 6177 6010 5964 5917 6033 5960 5886 5985 6091 5975 5967 6106 6083 6190 6194 6174 6174 6173 6382 6185 6305 6124 6137 6292 6194 6266 6415 6295 6392 6164 6132 6183 5981 6086 5946 6071 6018 6105 6002 6180 6204 6249 6151 6227 6573 6500 6442 6512 6401 6571 6612 6593 6562 6441 6437 6451 6394 6329 6417 6117 6329 6068 6368 6653 6528 6442 6420 6588 6574 6736 6815 6648 6677 6687 6331 6444 6609 6213 6252 6323 6081 6138 6008 5875 6131 6003 6088 5915 6174 6113 5951 6190 6223 6062 6177 6248 6047 6033 6053 5908 6031 5839 5958 5783 5943 5850 5798 5879 5910 5816 5890 5765 5804 5938 5751 5942 5824 5892 5931 6077 5920 5760 5806 5955 5853 5821 5994 6182 6034 6067 5843 5768 5802 5868 5862 5839 5831 5817 5873 5909 5880 5878 5804 5868 5824 5894 5980 6083 5806 6036 5914 5982 5892 5824 5936 5781 5766 5810 6026 5871 5814 5908 5691 5849 5841 5842 5828 5901 6001 5794 5921 5869 6004 5762 5926 6184 6151 6022 6128 6239 6189 6102 6092 6347 6177 6190 6270 6225 6296 6319 6530 6316 6305 6360 5890 6014 5883 6108 5967 6088 6028 5890 5928 5984 5902 6004 5881 5931 6093 6177 6140 6119 5947 5947 6022 6077 5919 5890 5753 6020 5904 5966 5828 5899 5770 5777 5788 5735 5869 5906 5862 6000 5789 5747 5948 5965 6027 5985 6094 6030 6046 6134 6315 6304 6271 6349 6293 6248 6325 6279 6317 6182 6378 6315 6328 6401 6317 6275 6168 6175 6132 6151 6149 6060 6215 6275 6302 6308 6178 6252 6105 6169 6276 6341 6184 6091 6158 6135 6407 6329 6384 6217 6144 6183 6221 6168 6169 6049 6124 6058 5883 5820 6023 5937 6021 5841 5976 6149 5738 5768 6019 5969 6009 6040 6068 6019 6256 6268 6280 6220 6272 6473 6375 6373 6457 6281 6198 6199 6113 6055 6061 6168 5859 5908 5934 5909 5985 5929 5947 6101 6169 6189 6120 6216 6321 6317 6505 6543 6443 6369 6474 6548 6424 6393 6167 6144 6000 6062 6020 5928 5897 5938 5799 5956 5914 5972 5921 5987 5991 5983 5939 5988 6018 5940 6017 6030 5972 5949 5893 5925 5838 5968 6042 5917 5770 5760 5568 5735 5928 5741 5789 5701 5617 5742 5778 5819 5710 5690 5842 5840 5784 5746 5760 5687 5544 5591 5742 5748 5819 5736 5832 5825 5646 5755 5800 5766 5666 5605 5835 5769 5938 5814 5847 5734 5727 5941 5775 5737 5789 5783 5949 5865 5806 5900 5863 5756 5955 5930 5980 5927 5953 6072 6126 6046 6017 6021 6108 6150 6132 6224 6135 6080 6004 6173 5906 6035 5943 6150 5974 5941 5937 6030 6021 6083 6079 5972 6057 5928 6032 6147 5937 6008 5998 6075 6204 6041 5856 6071 6039 6108 6021 5992 6016 5976 5960 6097 6037 5900 6102 6124 6164 6249 6170 5924 5961 6006 5879 5854 5944 5827 5846 5968 5883 5933 5798 5798 5700 5816 5878 5892 5846 5836 5928 5779 5742 5951 5860 5874 5799 5727 5812 5875 5867 5671 5553 5835 5843 5691 5749 5833 5895 5851 5812 5778 5976 5830 5919 5869 5785 5840 5746 5950 5991 5990 6059 5953 6009 5996 5958 6024 5952 5976 5948 6010 5845 5884 5974 6280 6065 6010 6144 6068 5967 5972 6128 6046 6068 6104 6250 6120 6268 6229 6273 6215 6272 6340 6030 6173 5956 6222 5949 6046 5925 5861 5911 5950 6060 5998 5885 5964 6031 5769 6023 5767 6010 6009 5714 5848 5770 6031 5830 5999 5866 5733 5834 5927 5866 5829 5843 5699 5849 5613 5863 5684 5704 5881 5688 5898 5668 5724 5815 5740 5813 5661 5742 5723 5747 5736 5821 5623 5679 5815 5725 5782 5610 5689 5576 5688 5615 5673 5602 5618 5647 5747 5522 5769 5664 5759 5753 5568 5636 5766 5766 5896 5608 5659 5675 5709 5808 5657 5787 5691 5737 5702 5831 5717 5810 5646 5799 5806 5767 5753 5853 5641 5784</intensities>
			</dataPoints>
			<nonAmbientPoints type="Temperature" unit="K">
[...]
			</nonAmbientPoints>
		</scan>
	</xrdMeasurement>
</xrdMeasurements>