File: powder_X-ray_diffraction/variable-temperature_experiments/NaNbO2F2/raw_data/290°C.xrdml
<?xml version="1.0" encoding="UTF-8"?>
<xrdMeasurements xmlns="http://www.xrdml.com/XRDMeasurement/1.7" xmlns:xsi="http://www.w3.org/2001/XMLSchema-instance" xsi:schemaLocation="http://www.xrdml.com/XRDMeasurement/1.7 http://www.xrdml.com/XRDMeasurement/1.7/XRDMeasurement.xsd" status="Completed">
	<comment>
		<entry>Configuration=XRK900, Owner=User-1, Creation date=12/01/2015 16:52:44</entry>
		<entry>Goniometer=Theta/Theta; Minimum step size 2Theta:0.0001; Minimum step size Omega:0.0001</entry>
		<entry>Sample stage=AP XRK-900 with z-axis; Minimum step size Z:0.001</entry>
		<entry>Diffractometer system=EMPYREAN</entry>
		<entry>Measurement program=C:\PANalytical\Data Collector\Programs\Gwen\NaNbO2F2-Lent.xrdmp, Identifier={26D14ECE-D3C8-438C-91CA-8651EAF68C7D}</entry>
		<entry>Batch program=C:\PANalytical\Data Collector\Programs\Gwen\Thermodiff-Ouail.xrdmp, Identifier={9701CF17-19F5-4DD4-A8E1-7279D1FD2F5E}</entry>
	</comment>
	<sample type="To be analyzed">
		<id></id>
		<name></name>
		<preparedBy></preparedBy>
	</sample>
	<xrdMeasurement measurementType="Scan" status="Completed" sampleMode="Reflection">
		<comment>
			<entry>PHD Lower Level = 4.02 (keV), PHD Upper Level = 12.07 (keV)</entry>
		</comment>
		<usedWavelength intended="K-Alpha 1">
			<kAlpha1 unit="Angstrom">1.5405980</kAlpha1>
			<kAlpha2 unit="Angstrom">1.5444260</kAlpha2>
			<kBeta unit="Angstrom">1.3922500</kBeta>
			<ratioKAlpha2KAlpha1>0.5000</ratioKAlpha2KAlpha1>
		</usedWavelength>
		<incidentBeamPath>
			<radius unit="mm">240.00</radius>
			<xRayTube id="1010048" name="Empyrean Cu LFF HR (9430 033 7310x) DK420743">
				<tension unit="kV">45.0</tension>
				<current unit="mA">30.0</current>
				<anodeMaterial>Cu</anodeMaterial>
				<focus type="Line">
					<length unit="mm">12.0</length>
					<width unit="mm">0.4</width>
					<takeOffAngle unit="deg">6.0</takeOffAngle>
				</focus>
			</xRayTube>
			<sollerSlit id="21010001" name="Soller slits 0.02 rad.">
				<opening unit="rad">0.0200</opening>
			</sollerSlit>
			<mask id="22030010" name="Fixed mask 20 mm">
				<width unit="mm">20.00</width>
			</mask>
			<antiScatterSlit id="22010003" name="Fixed slit 1Â°" xsi:type="fixedAntiScatterSlitType">
				<height unit="mm">1.52</height>
			</antiScatterSlit>
			<divergenceSlit id="22010012" name="Programmable divergence slit" xsi:type="fixedDivergenceSlitType">
				<distanceToSample unit="mm">140.00</distanceToSample>
				<angle unit="deg">0.5</angle>
			</divergenceSlit>
		</incidentBeamPath>
		<diffractedBeamPath>
			<radius unit="mm">240.00</radius>
			<antiScatterSlit id="22090010" name="AS slit 8.0 mm (PIXcel)" xsi:type="fixedAntiScatterSlitType">
				<height unit="mm">8.00</height>
			</antiScatterSlit>
			<sollerSlit id="21010001" name="Soller slits 0.02 rad.">
				<opening unit="rad">0.0200</opening>
			</sollerSlit>
			<filter id="20030001" name="Large beta-filter Nickel">
				<material>Ni</material>
				<thickness unit="mm">0.020</thickness>
			</filter>
			<detector id="7010019" name="PIXcel1D-Medipix3 detector" xsi:type="rtmsDetectorType">
				<phd unit="%">
					<lowerLevel>25.0</lowerLevel>
					<upperLevel>75.0</upperLevel>
				</phd>
				<mode>Scanning</mode>
				<activeLength unit="deg">3.3482</activeLength>
			</detector>
		</diffractedBeamPath>
		<scan appendNumber="0" mode="Continuous" scanAxis="Gonio" status="Completed">
			<header>
				<startTimeStamp>2022-05-16T02:32:25+02:00</startTimeStamp>
				<endTimeStamp>2022-05-16T05:32:53+02:00</endTimeStamp>
				<author>
					<name>User</name>
				</author>
				<source>
					<applicationSoftware version="5.5a">Data Collector</applicationSoftware>
					<instrumentControlSoftware version="8.1b 20190506">EMPYREAN</instrumentControlSoftware>
					<instrumentID>0000000011159748</instrumentID>
				</source>
			</header>
			<dataPoints>
				<positions axis="2Theta" unit="deg">
					<startPosition>9.99846514</startPosition>
					<endPosition>99.99342261</endPosition>
				</positions>
				<positions axis="Omega" unit="deg">
					<startPosition>4.99923257</startPosition>
					<endPosition>49.99671130</endPosition>
				</positions>
				<positions axis="Z" unit="mm">
					<commonPosition>8.912</commonPosition>
				</positions>
				<commonCountingTime unit="seconds">386.070</commonCountingTime>
				<intensities unit="counts">7393 7485 7382 7376 7375 7443 7655 7585 7463 7637 7555 7799 7809 7805 7643 7455 7554 7409 7408 7581 7664 7464 7489 7605 7628 7512 7507 7646 7434 7507 7469 7387 7500 7673 7338 7698 7565 7429 7654 7590 7523 7436 7439 7620 7409 7546 7565 7633 7588 7651 7603 7340 7685 7427 7471 7565 7355 7425 7395 7579 7728 7748 7405 7644 7757 7923 7545 7944 7737 8013 8007 8165 8088 7946 8133 8025 8187 8217 8263 8387 8585 8752 9057 9758 10287 11065 12248 14228 16805 20561 26102 35765 50734 67483 80249 81699 72054 57225 40333 26555 17876 12859 10465 9342 8871 8688 8698 8221 8277 8254 8057 7877 8118 7827 7901 7652 7618 7535 7673 7462 7529 7552 7680 7576 7624 7682 7771 7491 7736 7556 7740 7612 7625 7689 7836 7847 7882 7895 7884 7915 7854 7997 7799 7844 7987 7904 7892 7951 7685 7709 7794 7965 8041 7836 7820 7701 8077 7892 7999 8098 7949 8026 7890 7689 7905 7870 7891 7960 8009 7948 8038 7916 8078 8176 8065 7885 7935 7953 7993 8015 8145 7958 7949 7984 8060 7972 7852 7805 7959 8044 8006 8089 7979 7697 8036 7996 8058 7878 7907 7673 8065 7864 7863 7772 8058 7953 7953 7882 7893 8088 7765 8074 7921 7968 7808 7841 7796 7974 7900 7947 7809 7820 7805 8051 7993 7782 7951 7900 8006 7861 7731 7664 7769 7944 7763 7806 7795 7792 7684 7782 7734 7902 7873 7971 7807 7730 7906 7778 7847 7878 7802 7924 7951 7693 7758 7687 7704 7842 7764 7754 7765 7776 7807 7966 7843 7747 7768 7822 7665 7463 7746 7888 7864 7782 7757 7772 7842 7728 7879 7866 7887 7977 7963 7850 7998 8048 7903 7860 7763 7787 7838 7877 7679 7661 7840 7820 7647 7774 7706 7536 7762 7734 7701 7905 7685 7777 7732 7759 7875 7784 8007 7843 7705 7810 7803 7675 7642 7986 7886 7790 7726 7792 7738 7753 7674 7718 7775 7701 7813 7912 7702 7813 7679 7713 7836 7777 7803 7604 8044 8237 8274 8530 8849 9154 9421 9463 9267 9311 9085 8878 8621 8084 7963 7817 7665 7707 7766 7769 7814 7944 7645 7750 7762 7717 7672 7588 7657 7702 7600 7707 7588 7628 7471 7508 7524 7450 7703 7598 7758 7509 7726 7882 7702 7736 7474 7487 7744 7419 7641 7626 7788 7548 7389 7527 7523 7648 7600 7621 7623 7515 7673 7710 7704 7399 7715 7549 7687 7691 7586 7594 7644 7720 7397 7490 7755 7823 7582 7644 7513 7697 7842 7692 7563 7791 7328 7630 7448 7611 7602 7472 7434 7379 7511 7453 7492 7499 7465 7687 7486 7322 7580 7676 7697 7532 7659 7678 7725 7467 7806 7759 7681 7645 7682 7542 7671 7653 7591 7705 7697 7647 7438 7637 7553 7567 7687 7577 7600 7483 7587 7681 7782 7376 7410 7611 7600 7567 7406 7459 7427 7493 7545 7505 7388 7592 7627 7622 7558 7474 7413 7488 7475 7527 7694 7706 7712 7644 7460 7726 7443 7483 7581 7542 7369 7548 7638 7500 7550 7498 7445 7500 7559 7657 7672 7649 7765 7676 7907 7911 7980 7949 8010 7848 7742 7640 7455 7460 7396 7465 7454 7220 7599 7403 7348 7359 7628 7286 7401 7445 7469 7360 7510 7501 7431 7389 7313 7415 7477 7446 7204 7468 7201 7276 7167 7283 7107 7451 7328 7320 7311 7470 7435 7311 7415 7246 7421 7371 7513 7360 7214 7394 7364 7212 7418 7289 7293 7362 7461 7336 7512 7429 7196 7212 7220 7413 7502 7452 7432 7278 7163 7173 7421 7242 7184 7348 7279 7411 7450 7698 7611 7656 7645 7493 7401 7439 7257 7320 7242 7100 7189 7095 7434 7289 7299 7206 7311 7320 7361 7340 7297 7143 7269 7274 7256 7139 7267 7109 7123 7139 7323 7418 7177 7117 7130 7224 7088 7232 7125 7224 7205 7140 7187 7061 7178 7070 7193 7159 7291 7130 7304 7284 7191 7127 7030 7242 7309 7085 7077 7286 7111 7032 7232 7387 7158 7072 7039 7037 7231 7174 7143 7078 7256 7107 7103 7067 7080 7208 7075 7360 7246 7131 7158 7084 7054 7111 7028 6996 7206 7217 7186 7124 7337 7315 7271 7444 7722 7604 7627 7639 7690 7713 7527 7914 7647 7766 7596 7832 7699 7592 7642 7677 7540 7584 7746 7735 7757 7499 7455 7633 7768 7941 7806 7772 7969 7902 7875 8024 8023 8065 8098 8264 8623 8478 8626 9077 9304 9424 10168 11073 12811 15197 18933 25658 36432 51503 70052 87569 100036 98418 87099 74294 62447 49138 34626 23801 17231 13015 11026 10282 9793 9530 9008 9050 8767 8572 8478 8400 8088 8113 7892 7888 7615 7742 7826 7712 7631 7682 7608 7529 7641 7615 7666 7563 7424 7486 7477 7524 7725 7450 7471 7634 7582 7617 7690 7536 7403 7524 7524 7285 7404 7274 7303 7403 7510 7557 7273 7112 7545 7420 7409 7478 7394 7588 7307 7370 7424 7318 7240 7383 7600 7436 7419 7504 7337 7454 7579 7394 7448 7488 7481 7385 7381 7374 7447 7469 7332 7320 7287 7366 7437 7352 7322 7234 7142 7278 7288 7293 7535 7483 7280 7336 7414 7302 7373 7232 7324 7430 7431 7317 7302 7456 7328 7234 7412 7439 7470 7563 7340 7374 7412 7349 7441 7336 7213 7386 7507 7533 7419 7453 7510 7380 7289 7507 7435 7353 7425 7438 7384 7361 7531 7408 7376 7387 7376 7376 7443 7458 7389 7422 7514 7434 7695 7727 7439 7571 7437 7457 7559 7556 7512 7434 7546 7172 7256 7371 7452 7462 7320 7406 7318 7414 7538 7316 7234 7316 7268 7385 7361 7452 7435 7477 7519 7435 7267 7424 7576 7524 7356 7507 7605 7668 7651 7449 7575 7661 7822 7840 7895 8081 8250 8743 8935 10286 12102 15429 20889 27021 33104 34782 31840 28432 25921 23106 19731 15981 12831 10211 8850 8321 8069 7927 7965 8025 7648 7861 7687 7703 7545 7541 7530 7473 7453 7279 7563 7269 7217 7415 7293 7275 7386 7520 7423 7433 7411 7371 7533 7461 7521 7334 7467 7338 7442 7463 7580 7446 7584 7328 7707 7483 7467 7589 7449 7355 7396 7445 7540 7465 7565 7494 7459 7363 7422 7546 7283 7501 7550 7679 7392 7442 7453 7502 7557 7439 7494 7725 7608 7602 7692 7506 7778 7755 7917 7980 8122 8208 8477 8671 9223 10450 12832 15998 21509 26595 30311 31274 27230 23538 21576 20546 18278 14479 11705 10250 9597 9600 9513 9885 10972 12327 15096 20029 27100 35432 40106 39354 34330 30396 28040 25432 21252 17003 13109 10739 9420 8586 8376 8241 7959 8004 8059 7823 7939 7974 8072 8158 7975 7969 7850 7787 7638 7634 7564 7472 7462 7393 7373 7386 7499 7449 7565 7486 7338 7481 7448 7392 7420 7448 7433 7473 7337 7277 7212 7279 7435 7246 7462 7565 7521 7234 7218 7344 7333 7254 7299 7244 7285 7258 7419 7351 7383 7241 7275 7406 7324 7531 7448 7216 7246 7359 7376 7387 7316 7278 7211 7296 7506 7454 7683 7682 7649 7505 7430 7176 7299 7334 7376 7146 7525 7174 7270 7329 7220 7179 7263 7362 7373 7161 7226 7096 7297 7238 7338 7124 7371 7353 7247 7266 7247 7235 7325 7114 7292 7401 7271 7248 7550 7267 7278 7194 7233 7173 7230 7196 7325 7369 7385 7130 7267 7326 7297 7311 7084 7374 7358 7337 7238 7367 7298 7381 7381 7190 7502 7488 7294 7446 7036 7312 7340 7375 7312 7160 7370 7335 7246 7150 6984 7257 7219 7117 7277 7404 7290 7323 7187 7371 7029 7135 7320 7077 7342 7224 7200 7029 7156 7167 7192 7292 6956 7011 7187 7128 7035 7105 7083 7244 7114 7108 7265 7170 7102 7066 7183 7028 6989 6964 7087 7265 7123 7126 7043 6980 7174 7002 6964 6916 7006 6993 7029 7053 7168 7111 7262 7370 7513 7480 7537 7716 7458 7530 7621 7364 7369 7394 7437 7355 7419 7394 7380 7405 7349 7330 7385 7376 7419 7355 7462 7338 7413 7345 7479 7508 7428 7389 7516 7330 7369 7508 7393 7449 7392 7348 7383 7440 7459 7423 7354 7381 7337 7502 7539 7785 7646 7710 7814 7966 8038 8092 8200 8632 8666 8851 8950 9213 9468 9732 10323 10983 11646 12791 14824 18109 24325 34099 49561 70178 87479 94179 88932 77122 66356 61756 58805 52270 42724 31968 23101 17340 14093 12796 11552 10794 10262 9657 9478 8904 8668 8547 8402 8262 8038 8022 7881 7715 7855 7749 7718 7543 7658 7660 7565 7668 8024 7859 7827 7719 7820 7857 7868 7860 7983 8134 8298 8586 8475 8295 8140 8002 8080 8076 7973 7941 7592 7666 7727 7336 7540 7588 7592 7693 7664 7879 7899 7968 7863 7992 8361 8511 8775 9274 10420 11740 15123 21054 29579 36188 38473 34684 29008 25353 24725 24457 22905 19744 15273 12313 10540 9848 9549 10012 10621 12254 13535 14814 15247 14542 13997 13738 14028 14177 13939 13473 12667 12167 11195 10919 10344 9856 9622 9133 8905 8230 8047 7687 7722 7751 7580 7323 7208 7296 7265 7232 7276 7273 7120 7123 7274 7083 7108 7056 7164 7130 7274 7300 6939 7096 7111 7264 7283 7252 7126 7321 7240 7044 7199 7097 7098 7051 7117 7126 6999 7011 6938 7021 6958 7066 7108 6964 6899 6937 7122 7074 7038 6971 7012 7166 7154 7202 6996 7018 7002 6967 6988 7046 6876 6971 6933 6944 7011 6856 7089 6834 7120 7201 7060 6867 7059 6923 6959 6867 6976 7019 6856 7048 7186 7034 6889 7061 7019 7010 6930 6968 6828 6953 7012 6879 6935 6928 7080 6963 6971 7035 6802 7004 7008 7044 6869 6839 6720 6884 6833 6770 6882 6859 6958 6885 6786 6841 6954 6917 7059 6930 6884 7021 6663 6910 6854 6629 6894 6973 6950 6941 6963 6961 6954 6855 6855 6986 6908 6944 7053 6797 6798 6804 6944 6990 6746 6949 6781 6807 6859 6869 6791 7053 6920 6863 6688 6717 6910 6893 6888 6779 6883 6992 6990 6818 6821 6860 6825 6717 6758 6826 6872 6954 6853 6747 7021 6891 7118 6946 7011 6806 6671 6917 6980 6987 6832 6921 6810 6767 6782 6874 6929 6853 6799 6719 6900 6895 6868 6968 7064 6728 6861 6908 6793 6874 6917 6971 6872 6889 6755 7036 6770 6951 6859 7059 6778 6983 6964 7051 6973 6766 6984 7074 6817 7008 7053 6924 6933 6905 6965 6901 6818 6988 6841 6945 6774 7017 6875 6898 6963 6819 7169 6965 7037 7053 6968 7121 7080 6942 7192 7245 7165 7323 7603 8289 9332 10770 12879 15066 16101 15116 13356 12056 11549 11848 12241 12114 11329 11309 11526 13490 16410 19941 20671 19127 15980 14150 13267 13921 14333 13622 11946 10188 9075 8058 7764 7522 7357 7153 7101 7212 7288 7158 7057 6874 7065 7027 7033 7078 7011 6889 7040 7009 6974 7080 7126 7222 7143 7189 7453 7492 7826 8201 9091 10475 12362 14375 15360 15316 14420 12837 11650 11664 11614 11669 10984 10181 9044 7998 7466 7476 7193 7095 7257 7155 7020 7028 7311 7302 7058 7209 7411 7539 7563 7664 7834 7764 7703 7700 7825 7681 7935 8079 8245 9381 10900 13277 14435 14271 12538 11179 10163 10090 10755 11128 10357 9142 8453 7903 7391 7072 7090 7087 6926 6736 6976 6910 6827 6685 6683 6868 6874 6761 6775 6761 6520 6812 6624 6589 6870 6849 6586 6846 6810 6751 6709 6851 6910 6974 6885 6792 6878 7035 7291 7694 8595 9772 11223 12078 12314 11616 10546 9807 9562 9640 9529 9505 8907 8494 7760 7464 7271 7293 7200 7588 7608 7391 7215 6871 6947 6933 7204 7025 6935 6791 6656 6827 6681 6592 6703 6549 6548 6754 6665 6797 6710 6719 6725 6710 6520 6658 6553 6638 6579 6520 6728 6630 6545 6503 6673 6818 6753 6599 6404 6571 6627 6646 6575 6640 6747 6454 6617 6667 6826 6765 6715 6721 6669 6590 6597 6637 6752 6627 6597 6686 6548 6444 6591 6644 6601 6543 6503 6498 6545 6743 6619 6650 6664 6489 6499 6301 6629 6669 6612 6744 6742 6590 6618 6647 6589 6583 6603 6680 6672 6674 6551 6581 6652 6632 6457 6631 6635 6597 6605 6479 6604 6770 6571 6732 6758 6719 6736 6869 6997 7190 7564 8349 9088 9986 10056 9531 8632 8261 7966 7866 8206 8168 8021 7650 7300 6914 6880 6813 6832 6588 6679 6703 6565 6693 6549 6584 6609 6730 6626 6494 6383 6499 6669 6640 6610 6686 6549 6681 6428 6447 6572 6513 6434 6572 6516 6484 6464 6531 6582 6623 6521 6679 6487 6534 6519 6523 6554 6659 6493 6567 6544 6606 6715 6622 6539 6676 6783 6998 6987 7111 7293 7436 7354 7227 7004 7081 7144 7366 7299 7570 7590 7869 8760 9841 10660 11441 11415 10728 9806 8968 9226 9949 10568 10662 10984 10519 9504 8719 8030 7856 7828 7891 7994 7661 7304 6976 6974 6917 6604 6534 6624 6525 6599 6437 6663 6622 6622 6676 6623 6677 6629 6637 6583 6540 6358 6519 6613 6529 6405 6606 6463 6515 6480 6519 6394 6585 6434 6632 6508 6515 6517 6478 6444 6457 6468 6330 6563 6534 6556 6506 6448 6623 6500 6582 6449 6503 6496 6256 6464 6462 6358 6488 6473 6587 6594 6387 6436 6356 6286 6500 6466 6212 6611 6466 6528 6473 6486 6491 6526 6415 6410 6565 6568 6517 6556 6436 6481 6486 6549 6431 6470 6608 6535 6462 6587 6531 6596 6442 6350 6685 6730 6768 7113 7549 8190 8850 9505 9317 8679 7863 7672 7542 7768 8003 8030 7717 7445 7235 6746 6660 6656 6572 6617 6553 6466 6528 6493 6652 6405 6405 6502 6524 6252 6398 6512 6573 6335 6525 6421 6492 6621 6508 6590 6430 6507 6462 6754 6567 6551 6398 6644 6523 6443 6589 6496 6360 6557 6743 6308 6502 6511 6469 6317 6341 6449 6507 6626 6556 6631 6554 6312 6437 6726 6618 6583 6860 6929 6765 6867 7204 7404 8033 8668 9627 10520 10821 10484 9280 8745 8433 8189 8379 8842 8627 8508 7872 7470 7103 6868 6794 6662 6761 6433 6683 6707 6535 6392 6611 6566 6569 6422 6694 6644 6333 6363 6527 6536 6449 6405 6508 6558 6542 6663 6515 6485 6422 6520 6489 6514 6609 6500 6631 6753 6718 6753 6922 6717 6852 7201 7325 7890 8526 9096 9932 10898 11763 12078 12043 11527 10743 10439 10117 10339 11048 11913 12296 11542 10374 8966 8428 8153 7942 7843 8225 8224 7529 7335 6947 6624 6873 6822 6440 6524 6374 6515 6329 6462 6380 6418 6351 6389 6445 6431 6378 6397 6422 6399 6453 6504 6577 6621 6480 6496 6288 6369 6284 6356 6433 6410 6293 6355 6385 6426 6398 6463 6594 6441 6490 6376 6391 6325 6440 6519 6328 6445 6385 6440 6450 6487 6453 6378 6542 6594 6597 6452 6477 6538 6319 6578 6410 6513 6389 6418 6466 6457 6529 6316 6453 6666 6486 6393 6335 6520 6473 6546 6480 6445 6369 6395 6460 6393 6327 6391 6425 6583 6375 6367 6317 6337 6364 6444 6377 6414 6423 6387 6479 6402 6249 6452 6490 6379 6387 6343 6303 6247 6265 6347 6322 6440 6452 6325 6374 6568 6285 6398 6360 6211 6395 6357 6362 6464 6223 6293 6308 6376 6483 6378 6256 6363 6426 6389 6390 6360 6482 6457 6352 6482 6455 6362 6475 6561 6315 6291 6345 6361 6475 6342 6438 6390 6372 6392 6361 6400 6537 6437 6521 6381 6390 6295 6504 6535 6620 6807 6887 7068 7370 7553 7738 7379 7379 7113 7033 7102 7158 7033 7147 7219 7159 7231 6892 6845 6445 6602 6519 6653 6627 6540 6395 6485 6452 6541 6525 6533 6276 6339 6496 6474 6421 6444 6425 6312 6482 6457 6385 6483 6553 6790 6934 6673 6680 6611 6584 6568 6548 6691 6512 6640 6759 6623 6559 6533 6509 6350 6500 6591 6479 6708 6629 6563 6771 6725 6748 6735 6812 6998 7115 7429 7776 8338 9196 10756 12407 13430 13463 12363 10950 9912 9164 9048 9460 9909 10309 9991 9503 8754 8041 7420 7142 6974 6982 6780 6701 6524 6527 6430 6489 6658 6728 6681 6400 6526 6435 6585 6534 6371 6339 6309 6425 6397 6369 6360 6346 6431 6475 6503 6371 6387 6243 6431 6289 6273 6475 6393 6295 6311 6262 6354 6427 6601 6389 6372 6426 6385 6479 6394 6420 6427 6370 6392 6348 6312 6387 6422 6506 6579 6368 6494 6409 6354 6496 6412 6458 6441 6337 6231 6681 6498 6390 6428 6533 6454 6511 6442 6497 6517 6272 6510 6460 6540 6628 6778 6853 6612 6756 6767 6799 6967 6993 6742 6935 7020 7032 7091 7395 7898 8603 9844 12043 15245 19723 22140 21550 18666 14916 12302 10718 10719 11517 12870 14629 14404 13114 11332 9914 8701 7917 7854 7749 7725 7364 7354 7189 6971 6675 6730 6783 6878 7010 6981 7046 6955 6723 6692 6733 6615 6451 6538 6564 6253 6431 6579 6433 6357 6340 6245 6502 6559 6413 6663 6435 6414 6482 6629 6446 6318 6399 6355 6248 6471 6441 6591 6597 6360 6494 6394 6482 6441 6497 6458 6379 6539 6602 6410 6468 6624 6427 6473 6252 6608 6483 6469 6435 6631 6530 6636 6756 6747 6678 6656 6757 6825 7025 7157 7621 8134 8784 9253 9103 8856 8471 8092 7520 7561 7745 7765 7892 8416 8403 8156 8126 8509 9209 10594 11848 13307 13371 12486 10550 9147 8524 8487 8703 9087 9826 10174 9983 9220 8298 7804 7412 7253 7085 7012 7076 6996 7182 6955 7104 7137 7266 7270 7240 7354 7262 7419 7673 7923 8327 9140 10109 11773 14383 17476 19978 21196 20307 17520 14785 12826 11910 11769 12280 13466 14058 14489 13484 11598 10307 9064 8495 7629 7527 7288 7163 6935 6800 6852 6794 6742 6744 6722 6547 6825 6673 6633 6702 6719 6761 6714 6487 6500 6702 6518 6645 6687 6641 6785 6357 6581 6873 6921 7208 7403 7839 7944 7878 7771 7880 7704 7450 7617 7633 7762 7865 8033 7698 7475 7642 7423 7464 7550 7277 7264 7464 7325 7435 7385 7434 7759 8056 8351 8789 10096 11828 13935 16149 16772 16033 13871 11804 10457 10019 9989 10814 12003 13203 13972 13809 13073 11591 10052 9189 8698 8530 8516 8406 8484 8569 8518 8204 7773 7577 7310 7189 7269 7069 7027 7134 6827 6777 6712 6797 6628 6915 6908 6774 6866 6932 7058 7110 7214 7016 7176 7307 7526 7858 8292 8911 9803 11678 13827 16862 19139 20060 18931 16762 13968 11916 11148 10884 11383 12248 13181 13461 13062 11878 10572 9444 8476 7993 7477 7213 7111 6922 7034 7176 6834 6911 6950 6623 6815 6884 6872 6861 6962 7236 7487 7630 7653 7601 7425 7030 7045 7024 7124 7333 7300 7423 7332 7472 7837 8416 9002 9657 10822 11357 11415 10616 9792 8995 8511 8276 8175 8393 8893 8992 9202 9009 8372 7759 7370 7087 6965 6820 6833 6550 6532 6621 6543 6535 6552 6466 6492 6447 6469 6480 6576 6424 6344 6396 6430 6481 6517 6514 6567 6454 6583 6543 6573 6621 6567 6635 6680 6613 6593 6617 6325 6563 6627 6576 6487 6526 6635 6662 6531 6537 6824 6644 6688 6557 6718 6681 6748 6897 6781 7039 7352 7763 8337 8742 9099 8875 8437 7939 7838 7976 8202 9404 10713 12760 14925 15973 15410 13679 11581 9733 8698 8506 8583 9097 10017 10952 10979 10476 9557 8669 7615 7418 7218 6910 6981 6775 6664 6714 6532 6678 6556 6458 6543 6561 6640 6510 6424 6437 6389 6571 6674 6448 6491 6550 6659 6464 6604 6688 6403 6557 6664 6404 6410 6484 6445 6581 6561 6364 6433 6357 6316 6491 6264 6488 6536 6568 6445 6534 6520 6350 6340 6516 6533 6360 6479 6377 6628 6962 7248 7591 8077 8188 7889 7690 7154 6845 6808 6770 6780 6929 7140 7459 7418 7240 6977 6892 6717 6411 6369 6498 6231 6378 6422 6498 6406 6524 6360 6389 6368 6489 6339 6378 6235 6223 6313 6279 6406 6366 6472 6343 6366 6371 6590 6585 6445 6474 6545 6419 6364 6345 6479 6243 6466 6520 6276 6503 6406 6342 6383 6431 6366 6334 6339 6378 6323 6335 6373 6387 6318 6278 6343 6127 6021 6394 6395 6335 6732 6571 6436 6605 6489 6532 6580 6318 6322 6307 6477 6528 6392 6350 6408 6383 6395 6204 6232 6277 6486 6281 6353 6429 6491 6350 6278 6277 6354 6215 6287 6117 6288 6258 6264 6297 6318 6367 6465 6325 6280 6372 6306 6306 6340 6137 6117 6066 6355 6308 6264 6377 6285 6376 6263 6121 6180 6358 6230 6357 6358 6304 6179 6213 6281 6222 6354 6339 6364 6331 6229 6125 6260 6199 6246 6225 6378 6323 6462 6361 6494 6241 6344 6376 6171 6272 6214 6335 6416 6267 6378 6250 6351 6183 6295 6555 6375 6390 6281 6166 6338 6263 6256 6280 6315 6537 6425 6448 6406 6436 6445 6529 6366 6260 6306 6345 6595 6507 6376 6460 6414 6594 6401 6533 6677 6682 6429 6627 6670 6747 6919 6900 6800 7176 6940 7339 7989 8719 9375 9551 9679 9626 9179 9143 9554 10286 11591 12845 14148 14568 13994 12786 11245 10031 9280 8806 8842 8956 9671 10042 10038 9887 9178 8553 8201 7784 7391 7222 7249 7318 7476 7233 7178 6870 6771 6656 6821 6677 6809 6742 6755 6794 6803 6896 7032 6993 6711 6837 6948 7254 7452 8177 8842 9465 9599 9216 8742 8070 7450 7408 7420 7492 7542 8219 8323 8619 8360 7982 7473 7489 7445 7595 7622 7999 8602 9533 10320 11089 11227 10925 9877 8975 8389 7952 7765 7742 7840 8385 8609 9021 8995 8702 8314 7836 7672 7641 7346 7216 7302 7082 6811 6683 6606 6693 6659 6706 6740 6797 6899 6705 6615 6581 6406 6378 6345 6457 6449 6405 6547 6308 6595 6467 6461 6450 6481 6283 6414 6417 6402 6493 6417 6394 6412 6706 6521 6569 6643 6541 6315 6431 6325 6370 6363 6503 6512 6616 6567 6550 6368 6513 6470 6403 6500 6533 6521 6637 6865 6996 7061 7190 7567 8029 8473 9260 9541 9680 9583 9018 8197 8017 7764 7665 7803 8019 8320 9003 9571 10136 10466 10725 10692 10423 10008 9382 8730 8389 8084 7729 7798 8050 8086 8211 8453 8279 8127 7863 7571 7270 7155 6788 6898 6582 6656 6793 6558 6479 6546 6306 6546 6531 6370 6543 6494 6820 6545 6463 6503 6819 6751 7029 7178 7278 7340 7470 7578 7558 7601 7625 7722 7639 7665 7516 7324 7382 7499 7622 7635 7941 8174 8671 9194 9928 10333 10760 11037 11472 11347 11275 10870 10219 9506 9202 8785 8877 9222 9412 9193 9402 9639 9738 10072 10109 9790 9603 9365 9121 9132 9320 9977 10607 11188 10954 10662 9695 9377 9063 8427 7918 8014 8076 8029 8472 8537 8488 8426 7871 7576 7115 6955 6744 6489 6494 6498 6450 6412 6386 6531 6296 6281 6373 6335 6321 6348 6386 6291 6398 6265 6254 6465 6216 6316 6289 6281 6430 6413 6366 6479 6703 6521 6512 6567 6552 6647 6556 6410 6506 6361 6463 6650 6858 6841 6996 6972 7189 7478 7908 8429 9653 10783 12027 12590 12456 11270 9609 8480 8234 7728 7622 7770 7947 8420 8864 9303 9510 8973 8508 7821 7294 7032 6875 6815 6889 6615 6640 6596 6518 6478 6472 6736 6597 6629 6620 6944 7214 7358 7874 8416 8743 9143 8740 8504 8047 7748 7219 7122 6843 6948 7329 7318 7657 7669 7680 7718 7289 7067 7024 6966 6637 6510 6683 6682 6611 6398 6484 6448 6625 6548 6551 6654 6748 6561 6494 6733 6811 6873 6924 7067 7183 7376 7760 8582 9219 9833 10993 11417 11410 11717 12071 12793 13506 13813 13044 11880 10636 10019 9687 9672 9518 9497 9248 9658 9856 10129 9987 9444 8627 8053 7672 7352 6909 6834 6630 6528 6492 6354 6588 6458 6393 6476 6462 6303 6436 6443 6424 6588 6680 6792 7090 7321 7438 7351 7174 6951 6432 6607 6569 6439 6450 6540 6645 6667 6722 6894 6874 6644 6565 6457 6290 6360 6369 6330 6256 6053 6053 6182 6083 6161 6197 6171 6148 6207 6147 6231 6138 6189 6266 6045 6049 6327 6202 6279 6311 6303 6064 6055 6113 6045 6199 6340 6137 6011 6042 6149 6042 5966 5910 5969 6081 6218 6063 6172 6075 5964 6005 6176 6095 6219 5961 6036 6019 5961 6220 6103 6119 6124 6322 6243 6081 6215 6113 6107 6298 6218 6097 5905 6218 6210 6313 6237 6228 6094 6186 6238 6231 6152 6255 6204 6215 6242 6349 6150 6376 6300 6556 6602 6752 6904 7363 7284 7516 7372 7146 6704 6724 6389 6372 6689 6519 6581 6726 6934 7018 6912 6907 6902 6656 6541 6608 6350 6489 6669 6656 6920 7227 7520 7887 8034 7957 7548 7186 7121 6887 6835 6873 6680 6933 6790 6940 7158 7072 7119 6939 6725 6466 6522 6250 6514 6388 6346 6117 6214 6083 6241 6296 5999 6122 6087 6189 6300 6115 6001 6148 6081 6233 6123 6264 6173 6200 6122 6266 6279 6350 6388 6384 6592 6617 7016 7478 7553 7443 7376 7233 6909 6707 6469 6472 6523 6476 6457 6595 6708 6808 6817 6863 6713 6660 6539 6568 6346 6270 6276 6127 6151 6214 6157 6051 6062 6029 6183 6261 6113 6095 6010 6086 6178 6264 6221 5998 6143 6178 6211 6255 6049 6145 6124 6037 6021 5946 6151 6007 6106 5931 6145 6195 6143 6063 6040 6148 6087 6091 6289 6193 6230 6047 6182 6166 6216 6092 6008 6233 6102 6016 5997 6281 6203 6216 6123 6163 6158 6160 6064 5943 6225 6165 6043 6125 6128 6238 6046 6128 6008 5991 5983 6065 5993 6086 5905 6015 6100 6021 6040 6172 6004 6065 6031 5974 6110 6027 6103 5915 5880 5885 5981 6019 5957 6010 5828 5839 5847 6082 5917 5968 6135 5943 5922 6006 6059 6013 6110 6029 5898 5882 5949 5820 5934 6053 5998 5966 5951 5899 5899 6187 5944 5952 5989 5910 6126 6084 6178 6236 6080 6101 6049 6115 5979 6223 5998 6082 6090 5892 5817 6034 6116 6009 6095 6020 6177 6000 5974 6027 6139 6092 6144 6002 6141 6232 6128 6014 6004 6086 5920 6083 5833 6013 5998 6108 6227 6123 6175 6012 6149 6066 6078 6022 5938 6037 5929 6033 5875 6022 5893 5854 6103 6058 5911 5991 5771 5881 5867 6064 5891 5998 5916 6003 5891 5960 6017 5931 5854 5837 5989 5942 5951 6066 6005 5914 5997 5988 6001 5886 5888 5901 6070 6086 5966 5841 5826 5806 6038 6019 6094 6099 6070 6120 6200 6117 6293 5965 5970 5937 5950 5913 6153 5939 6156 6125 6132 6149 6193 6105 6308 6099 5981 6173 6137 5999 6099 5969 5876 5979 6158 6022 5908 5943 6140 6002 6004 6008 6112 5993 6059 6039 5876 6049 6032 6151 5946 5987 5951 5886 6038 5946 6052 5969 6103 6054 5959 6083 5972 6116 6181 6048 5901 6067 6056 6106 6120 6272 6049 6030 6076 5939 6034 6223 6074 6014 5850 6109 6013 6060 6040 6002 6103 6181 6178 6007 6222 6019 6005 6057 6247 6170 6106 6088 6077 5894 6125 6397 6554 6622 6633 6706 6583 6665 6540 6809 6841 7179 7252 7395 7852 7692 7476 7143 6830 6840 6783 6557 6673 6473 6644 6655 6794 6715 6824 6872 6745 6668 6584 6602 6368 6389 6326 6400 6602 6654 6752 6802 7020 7477 7844 8434 9248 9731 9808 9179 8711 8139 7681 7236 7125 6944 6818 7172 6986 7402 7845 8216 8445 8703 8527 8479 8069 7533 7246 7034 6750 6532 6587 6444 6348 6517 6534 6491 6471 6684 6742 6496 6654 6572 6406 6321 6302 6468 6407 6367 6571 6762 6904 7208 7530 7864 7748 7617 7300 6963 6855 6740 6471 6517 6531 6496 6441 6556 6867 6854 7022 7134 6987 6846 6696 6655 6490 6371 6400 6307 6317 6184 6151 6085 6092 6087 6069 6093 6277 6064 6273 6242 6256 6286 6505 6379 6467 6777 6535 6623 6588 6441 6314 6394 6439 6430 6394 6436 6598 6693 6904 7111 7166 7092 6894 6818 6585 6492 6436 6354 6558 6486 6615 6596 6616 6589 6537 6603 6369 6394 6470 6108 6192 6213 6084 6112 6102 6173 6170 6014 6185 6059 6083 6083 6176 6066 6029 5956 6178 5940 5916 5986 5900 6158 5966 5995 6186 6139 5979 5939 6005 6070 6149 5932 6090 6124 6183 5972 6098 6068 6116 6141 6124 6228 6174 6126 6107 6137 6205 6207 6093 6328 6166 6294 6363 6456 6375 6341 6421 6239 6212 6239 6327 6292 6486 6352 6433 6433 6630 6934 7092 7357 8055 8573 8818 8953 8697 8462 7984 7635 7377 7045 6851 6701 6638 6700 6636 7009 7226 7248 7502 7597 7483 7192 6982 6804 6538 6275 6314 6134 6360 6128 6123 6027 5913 6164 6152 6325 6062 6108 6133 5978 6151 6043 6104 6019 5993 6108 6138 6132 6258 6091 6167 6377 6402 6568 6669 6660 6697 6548 6340 6436 6050 6181 6228 6117 6032 6155 6159 6140 6228 6455 6382 6387 6528 6395 6164 6386 6286 6473 6387 6242 6366 6262 6286 6163 6086 6188 5927 6055 6216 6150 6278 6112 6278 6426 6465 6512 6735 6995 7257 7352 7578 7620 7634 7327 7051 6839 6739 6606 6386 6231 6511 6440 6513 6579 6484 6629 6667 6854 6886 6515 6422 6636 6449 6402 6276 6115 6294 6329 6249 6008 6048 6063 6193 6363 6156 6087 6090 6047 6026 6283 6128 6354 6207 6242 5982 6093 6080 6100 6151 6076 6297 6269 6233 6252 6128 5996 6211 6327 6299 6340 6369 6600 6663 6918 7025 7058 7096 7133 6946 6848 7147 7493 7402 7375 7247 6987 7021 6839 6763 6875 6876 6873 6978 6929 6939 7188 7108 7117 6990 6854 6716 6640 6636 6440 6342 6166 6228 6208 6219 6083 6414 6309 6180 6308 6258 6071 5999 6049 6207 5996 6160 6132 6063 6056 6019 5991 5985 6084 5950 5997 6185 5906 6063 5964 5939 5994 5953 6037 6115 6108 6072 6013 6084 6097 6390 6136 5887 5965 6061 5990 5980 5783 6009 5873 5849 5839 6010 6004 5877 6029 6036 6069 6013 5849 5925 5919 6045 5947 5929 6106 5938 5948 5778 5848 5894 5960 5957 5763 5832 5878 5941 5978 6011 6129 5968 5887 5738 5836 5855 5997 5897 5949 5880 5870 6108 5949 5816 5776 5926 5996 6020 6001 6053 6065 6145 6348 6478 6653 6582 6351 6425 6284 6303 6152 6087 6065 6099 6212 6143 6092 6021 6071 6134 6112 6215 6272 6197 6191 6186 6123 6123 6182 5990 5892 6040 6066 5857 5999 5901 5937 5975 5927 6062 5967 5972 5897 5803 5882 5904 5968 5827 5917 5925 6121 5947 5904 6078 6042 6037 6241 6337 6241 6471 6444 6645 6675 6490 6451 6472 6703 6658 6839 7025 6925 7326 7335 7225 7192 7115 6826 6691 6672 6604 6520 6487 6316 6443 6384 6548 6563 6614 6875 6991 7113 7154 7240 7293 7555 7423 7072 6842 6517 6445 6308 6158 6158 6232 6166 6329 6289 6287 6291 6436 6433 6600 6679 6415 6605 6258 6147 6198 6265 6256 6226 6040 6136 6161 6060 6027 6010 6156 6080 6114 6106 6003 6260 6373 6338 6574 6713 6591 6594 6525 6489 6610 6663 6638 6832 6742 6654 6465 6345 6291 6185 6398 6318 6291 6226 6472 6342 6166 6176 6373 6360 6122 6355 6253 6157 6069 6049 5984 5898 5899 5916 5898 6091 6092 5974 5878 5960 5776 5937 5830 6005 5841 5933 5884 5992 5997 6013 6022 5864 5905 6051 5751 5852 5899 5819 5938 5755 6104 5861 5842 5785 5942 5992 6001 5923 5844 5927 5886 5805 5827 6000 6039 6021 5951 5960 6036 6068 6041 5864 6008 6101 5986 5960 6001 6074 6155 6005 6161 6178 6263 6131 6177 6278 6350 6464 6705 6916 6938 7157 7006 6921 6812 6662 6485 6600 6422 6369 6321 6358 6366 6471 6497 6507 6820 6984 6867 6933 6962 6958 6808 6860 6690 6656 6637 6632 6347 6150 6340 6351 6290 6197 6316 6185 6146 6090 6329 6340 6190 6171 6339 6326 6188 6290 6260 6359 6168 6191 6112 6122 6099 6138 6155 6437 6390 6428 6703 6772 6949 7022 7063 7147 6616 6722 6645 6579 6363 6429 6321 6366 6465 6462 6348 6406 6428 6395 6654 6662 6700 6834 6682 6987 6893 6780 6651 6356 6420 6387 6220 6390 6123 6114 6198 6189 6216 6159 6117 6089 6286 6170 6302 6397 6362 6093 6116 6048 5927 5993 6122 5979 5981 5904 5957 6187 6058 5847 6110 5986 5860 5931 6086 6259 6259 6288 6364 6540 6541 6856 6859 7138 6839 6910 7025 7129 6987 6925 7005 6996 7034 7010 6973 6566 6797 6719 6555 6543 6471 6636 6528 6725 6380 6318 6487 6574 6602 6434 6381 6467 6385 6326 6467 6301 6178 6128 6192 6342 6278 6208 6391 6450 6397 6317 6421 6521 6329 6315 6482 6359 6547 6330 6339 6209 6265 6521 6637 6822 7026 7060 6813 6680 6616 6536 6514 6543 6360 6242 6148 6252 6219 6226 6322 6324 6354 6355 6426 6476 6349 6279 6342 6305 6136 6074 6116 5958 6285 6247 6096 6022 6107 6086 6104 6029 6064 5995 5920 6060 5961 5992 6087 5984 6011 5995 6073 6186 6026 6100 6040 5933 5984 5855 6198 6177 6095 6199 6342 6265 6437 6496 6292 6311 6242 5967 6061 5914 6191 5937 5893 5824 5934 6013 6130 6187 6129 6124 6299 6132 6318 6345 6532 6562 6326 6477 6518 6432 6382 6255 6185 6172 6157 6098 6109 5941 6032 6056 5981 5917 5944 6069 6083 6138 6001 6303 6231 5993 6118 6030 6084 5850 6011 5980 5948 5873 5997 5905 6046 5943 6202 6026 6118 5996 6070 6395 6563 6593 6799 6787 6628 6452 6367 6238 6143 6048 6017 5904 6018 5917 6010 6045 5990 6027 5980 6044 6244 6445 6343 6320 6124 6031 6252 6144 5992 6021 5747 5841 5973 5869 5838 5901 5751 5974 5722 5813 5830 5884 5864 5925 5974 5928 5849 5794 5787 5768 5753 5756 5952 5985 5665 5842 5782 5887 5824 5857 5711 5814 5875 5812 5871 5835 5896 5736 5956 5874 5957 5859 5764 5787 5799 5853 5726 5841 5800 5757 5842 5889 6028 6011 6044 5748 5875 5889 5863 5746 5845 5955 5883 6060 6101 6096 6083 6006 6119 5956 6164 6156 6062 6151 6195 6356 6319 6314 6412 6504 6432 6173 6208 5999 6062 6252 6117 6157 6282 6246 6285 6265 6226 6285 6426 6362 6370 6412 6584 6190 6259 6148 6136 6110 5966 5851 5889 6052 6099 5954 5786 6053 6163 5930 5958 5924 5951 5927 5883 5779 5911 5878 5749 5705 5955 5855 5931 5966 5793 5801 5803 5870 5869 5799 5696 5845 6016 5843 5751 5749 5831 5913 5862 5960 5916 5888 5859 6049 5828 5828 5855 5806 5886 5894 5837 5826 5768 5997 5843 5878 5939 5700 5853 5928 5956 5953 5838 5761 5878 5987 5773 6026 5928 5915 5826 5802 5996 5853 5884 5786 5844 6065 6044 6084 6083 6233 6091 6032 5952 5887 5902 5806 5880 5916 5675 5796 5916 5876 5815 5957 5883 5976 5940 5965 5902 6008 6122 5982 5970 6034 5790 6032 5814 5963 5916 5862 6015 5919 5836 6129 6099 5938 5983 5963 5984 5825 5945 5991 6024 6034 5992 6169 6101 6013 6280 6191 6133 6204 6098 6145 5983 6105 6060 5956 6019 6024 5931 6090 6104 6084 6148 6314 6293 6229 6490 6477 6615 6776 6857 6958 6797 7023 6866 6825 6950 6967 7055 7025 6868 6893 6792 6707 6482 6469 6441 6512 6595 6632 6609 6646 6711 6554 6721 6517 6747 6593 6618 6381 6453 6462 6205 6265 6124 6193 6008 6032 6128 6053 5967 6230 6025 5994 6101 6019 5925 6040 5872 5927 6018 5992 5845 5732 5997 5898 5962 5905 6088 5905 5885 5995 5927 5939 6025 5975 5982 6015 6016 6058 6139 6207 6151 6137 6180 6262 6165 6273 6519 6505 6260 6387 6345 6203 6120 6158 6383 6247 6283 6149 6300 6478 6457 6491 6617 6577 6353 6441 6187 6263 6121 6221 6191 6116 6229 5990 6137 6076 5862 5970 6038 6203 5992 6084 6102 6142 6079 6079 5976 5812 5649 6014 6123 5913 5806 5855 5900 6016 6094 5940 5971 6008 5954 5803 5887 5911 5884 5992 6021 6020 6121 6194 6151 6333 6416 6532 6387 6467 6481 6603 6566 6536 6363 6228 6325 6306 6050 5937 6173 6222 6096 6100 5993 6011 6238 6450 6199 6259 6356 6429 6306 6264 6188 6296 6157 6138 6175 6065 5979 6067 6076 6192 6151 6132 6211 6376 6289 6552 6490 6600 6606 6744 6807 6754 6491 6364 6328 6104 6132 6121 6024 5981 6042 6152 6197 6035 6219 6154 6145 6456 6515 6520 6718 6706 6743 6686 6607 6342 6303 6205 6217 6231 6111 6045 5916 6052 6172 6078 6027 6008 6054 6265 6386 6411 6637 6536 6709 6774 6622 6498 6316 6208 6138 6003 6093 6150 6219 6044 5846 5974 5804 5939 5982 6119 6097 6055 6035 6170 6115 6287 6078 6131 6174 5993 5972 5819 5930 5755 5939 5970 5760 5757 5788 5982 5878 5773 5883 5783 5860 5763 5848 5929 5866 5911 5826 5871 5840 5893 5812 5916 5881 5845 5767 5852 6026 5979 5797 5923 5798 5788 5825 5850 5842 5774 5888 5859 5755 5731 5927 5824 5838 5803 5941 5823 5720 5974 5849 5812 5933 5995 5775 5840 6033 6137 6324 6202 6105 6127 6176 6129 6100 6128 6189 5787 5983 6031 5954 5989 5922 5955 6067 5774 5962 6064 5951 6113 6009 5835 5984 6086 6149 6118 6074 6219 5912 6077 6160 6127 6187 6188 6168 6248 6351 6341 6250 6117 6163 6228 6205 6100 6053 6084 6022 6064 6051 6170 6291 6422 6304 6486 6435 6304 6315 6353 6308 6284 6261 6193 6337 6031 6055 6105 6239 6406 6263 6368 6302 6171 6115 6289 6296 6193 6362 6322 6400 6309 6257 6542 6487 6562 6547 6825 6725 6650 6534 6558 6586 6408 6302 6188 6167 5994 5979 6022 6021 5873 5877 5973 6032 6125 6154 6261 6052 6256 6085 5939 5997 6195 5884 5962 6089 5799 5943 5928 5815 5888 5962 5749 5752 5750 5925 5727 5946 5776 5948 5974 6005 6018 6073 6048 6134 5897 5948 6051 5954 5773 5792 5863 5862 5829 5919 5742 5848 5807 5836 5889 5812 5842 5743 5886 5842 5859 5973 5928 5847 5876 5902 5815 5856 5846 5666 5984 5830 5838 5936 5793 5897 5804 6030 5805 5872 6105 5852 5934 5866 5965 5888 5972 6115 5937 6091 6072 6176 6162 6174 6382 6382 6499 6570 6437 6393 6325 6206 6117 5835 6011 6068 5938 5918 5980 5983 5820 5874 6010 6062 6046 6106 6039 6275 6151 6160 6233 6145 6111 6080 5937 5663 5855 5996 5646 5750 5786 5862 5782 5889 5943 5747 5754 5713 5584 5833 5881 5895 5799 6064 5872 5711 5742 5903 6008 6064 5889 6029 6107 6190 6131 6513 6417 6347 6397 6395 6484 6421 6298 6281 6156 6102 6138 6039 5975 5842 6056 6110 6352 6088 6066 6330 6196 6021 6151 6257 6306 6239 6203 6282 6170 6195 6228 6046 6114 6171 6176 6236 6321 6344 6429 6204 6229 6081 6030 6108 5889 5782 5812 5927 5919 6051 5904 5875 5877 5840 5738 5731 5761 5775 5955 5948 6082 6092 5869 5915 5915 6133 6019 5889 5874 5990 5833 5779 5901 5942 6092 6059 6054 6197 6125 6511 6475 6320 6055 6026 6041 5977 5948 6001 5932 6004 6265 6103 6240 6328 6299 6363 6294 6356 6290 6398 6477 6320 6246 6315 6300 6199 6130 6063 5896 5905 5991 5906 5843 5937 5866 5909 5904 5839 5950 6103 6016 5948 6112 5968 5994 5888 5857 5945 6118 5837 5846 5720 5698 5696 5693 5848 5764 5710 5876 5832 5757 5903 5797 5771 5629 5707 5847 5706 5720 5793 5737 5669 5644 5799 5795 5696 5825 5843 5783 5743 5817 5858 5776 5574 5618 5683 5581 5864 5900 5948 5798 5835 5866 5924 5887 5897 5781 5846 5823 5801 5982 5957 5985 5794 5806 5853 5925 5767 5806 5968 5991 5927 5897 6045 6003 6256 6164 6159 6051 6132 6058 5991 6029 5975 5851 5942 5807 5987 6027 6143 5945 5970 6083 5928 6031 5862 6112 6261 6218 6221 6297 6335 6044 6108 6213 6015 5786 5975 5865 5843 5852 5879 5930 5789 5663 5792 5828 6038 5875 5918 5958 6017 6075 6070 5944 5976 5857 5968 6072 5868 5890 5731 5892 5985 5843 5924 5951 5937 5866 5707 5942 5808 5904 5889 5878 5802 5703 5832 5783 5736 5688 5651 5833 5870 5869 5768 5674 5873 5857 5767 5889 5929 5901 5934 5858 5943 5876 5835 5862 5862 5811 5700 5815 5910 5943 5961 6181 6040 5894 5934 5980 5991 6246 6176 6052 6223 6003 6170 6073 6085 6107 6219 5923 6052 5839 6008 5998 6146 6010 6001 5906 5982 6046 5955 6098 6129 6004 6018 6111 5949 6123 6189 6167 6139 6058 6164 6052 6074 5949 5957 5960 6057 5884 5912 5916 5740 5817 5898 5969 5903 5810 5848 5916 5840 5849 5845 5803 5794 5853 5980 5919 5956 5820 5850 5900 5762 5681 5835 5844 5682 5641 5867 5640 5711 5780 5701 5845 5746 5658 5634 5759 5695 5791 5833 5525 5680 5782 5706 5735 5839 5720 5783 5955 5820 5688 5715 5788 5702 5808 5619 5859 5900 5715 5702 5824 5649 5865 5791 5708 5749 5607 5760 5682 5666 5843 5736 5847 5805 5885 5864 5896 5758 5754 5774 5931 5906 5755 5660 5838 5833 5885 5749 5701 5875 5980 5790 5608 5609 5760 5684 5613 5674</intensities>
			</dataPoints>
			<nonAmbientPoints type="Temperature" unit="K">
[...]
			</nonAmbientPoints>
		</scan>
	</xrdMeasurement>
</xrdMeasurements>