File: powder_X-ray_diffraction/variable-temperature_experiments/NaNbO2F2/raw_data/300°C.xrdml
<?xml version="1.0" encoding="UTF-8"?>
<xrdMeasurements xmlns="http://www.xrdml.com/XRDMeasurement/1.7" xmlns:xsi="http://www.w3.org/2001/XMLSchema-instance" xsi:schemaLocation="http://www.xrdml.com/XRDMeasurement/1.7 http://www.xrdml.com/XRDMeasurement/1.7/XRDMeasurement.xsd" status="Completed">
	<comment>
		<entry>Configuration=XRK900, Owner=User-1, Creation date=12/01/2015 16:52:44</entry>
		<entry>Goniometer=Theta/Theta; Minimum step size 2Theta:0.0001; Minimum step size Omega:0.0001</entry>
		<entry>Sample stage=AP XRK-900 with z-axis; Minimum step size Z:0.001</entry>
		<entry>Diffractometer system=EMPYREAN</entry>
		<entry>Measurement program=C:\PANalytical\Data Collector\Programs\Gwen\NaNbO2F2-Lent.xrdmp, Identifier={26D14ECE-D3C8-438C-91CA-8651EAF68C7D}</entry>
		<entry>Batch program=C:\PANalytical\Data Collector\Programs\Gwen\Thermodiff-Ouail.xrdmp, Identifier={9701CF17-19F5-4DD4-A8E1-7279D1FD2F5E}</entry>
	</comment>
	<sample type="To be analyzed">
		<id></id>
		<name></name>
		<preparedBy></preparedBy>
	</sample>
	<xrdMeasurement measurementType="Scan" status="Completed" sampleMode="Reflection">
		<comment>
			<entry>PHD Lower Level = 4.02 (keV), PHD Upper Level = 12.07 (keV)</entry>
		</comment>
		<usedWavelength intended="K-Alpha 1">
			<kAlpha1 unit="Angstrom">1.5405980</kAlpha1>
			<kAlpha2 unit="Angstrom">1.5444260</kAlpha2>
			<kBeta unit="Angstrom">1.3922500</kBeta>
			<ratioKAlpha2KAlpha1>0.5000</ratioKAlpha2KAlpha1>
		</usedWavelength>
		<incidentBeamPath>
			<radius unit="mm">240.00</radius>
			<xRayTube id="1010048" name="Empyrean Cu LFF HR (9430 033 7310x) DK420743">
				<tension unit="kV">45.0</tension>
				<current unit="mA">30.0</current>
				<anodeMaterial>Cu</anodeMaterial>
				<focus type="Line">
					<length unit="mm">12.0</length>
					<width unit="mm">0.4</width>
					<takeOffAngle unit="deg">6.0</takeOffAngle>
				</focus>
			</xRayTube>
			<sollerSlit id="21010001" name="Soller slits 0.02 rad.">
				<opening unit="rad">0.0200</opening>
			</sollerSlit>
			<mask id="22030010" name="Fixed mask 20 mm">
				<width unit="mm">20.00</width>
			</mask>
			<antiScatterSlit id="22010003" name="Fixed slit 1Â°" xsi:type="fixedAntiScatterSlitType">
				<height unit="mm">1.52</height>
			</antiScatterSlit>
			<divergenceSlit id="22010012" name="Programmable divergence slit" xsi:type="fixedDivergenceSlitType">
				<distanceToSample unit="mm">140.00</distanceToSample>
				<angle unit="deg">0.5</angle>
			</divergenceSlit>
		</incidentBeamPath>
		<diffractedBeamPath>
			<radius unit="mm">240.00</radius>
			<antiScatterSlit id="22090010" name="AS slit 8.0 mm (PIXcel)" xsi:type="fixedAntiScatterSlitType">
				<height unit="mm">8.00</height>
			</antiScatterSlit>
			<sollerSlit id="21010001" name="Soller slits 0.02 rad.">
				<opening unit="rad">0.0200</opening>
			</sollerSlit>
			<filter id="20030001" name="Large beta-filter Nickel">
				<material>Ni</material>
				<thickness unit="mm">0.020</thickness>
			</filter>
			<detector id="7010019" name="PIXcel1D-Medipix3 detector" xsi:type="rtmsDetectorType">
				<phd unit="%">
					<lowerLevel>25.0</lowerLevel>
					<upperLevel>75.0</upperLevel>
				</phd>
				<mode>Scanning</mode>
				<activeLength unit="deg">3.3482</activeLength>
			</detector>
		</diffractedBeamPath>
		<scan appendNumber="0" mode="Continuous" scanAxis="Gonio" status="Completed">
			<header>
				<startTimeStamp>2022-05-16T05:54:59+02:00</startTimeStamp>
				<endTimeStamp>2022-05-16T08:55:27+02:00</endTimeStamp>
				<author>
					<name>User</name>
				</author>
				<source>
					<applicationSoftware version="5.5a">Data Collector</applicationSoftware>
					<instrumentControlSoftware version="8.1b 20190506">EMPYREAN</instrumentControlSoftware>
					<instrumentID>0000000011159748</instrumentID>
				</source>
			</header>
			<dataPoints>
				<positions axis="2Theta" unit="deg">
					<startPosition>9.99846514</startPosition>
					<endPosition>99.99342261</endPosition>
				</positions>
				<positions axis="Omega" unit="deg">
					<startPosition>4.99923257</startPosition>
					<endPosition>49.99671130</endPosition>
				</positions>
				<positions axis="Z" unit="mm">
					<commonPosition>8.912</commonPosition>
				</positions>
				<commonCountingTime unit="seconds">386.070</commonCountingTime>
				<intensities unit="counts">7166 7393 7329 7514 7297 7634 7344 7618 7515 7485 7538 7684 7747 7604 7711 7462 7487 7614 7542 7451 7540 7385 7353 7370 7436 7602 7333 7443 7487 7559 7408 7525 7628 7398 7306 7431 7626 7382 7256 7281 7458 7526 7491 7528 7664 7654 7354 7430 7425 7500 7478 7428 7663 7531 7465 7581 7367 7592 7628 7479 7542 7511 7575 7692 7631 7783 7862 7752 7914 7922 8117 8268 7996 8081 8337 8218 8337 8258 8362 8524 8770 9022 9305 9988 10649 11743 12681 14549 17743 21347 27460 39506 54669 70457 81248 79574 68256 52781 36715 24021 16482 12033 10020 9348 8935 8562 8468 8372 8310 8057 7913 7865 7833 7862 7939 7664 7614 7595 7595 7489 7515 7683 7678 7577 7593 7493 7600 7710 7781 7524 7598 7621 7565 7843 7949 7857 7834 7961 7700 7842 7851 7956 7876 7959 7949 7882 7853 7916 7847 7879 7752 7768 7845 8004 7946 7789 7836 7909 7817 7928 7942 7873 7917 7815 7909 7986 7978 7984 8162 7964 8165 8139 8000 7939 7999 7893 7998 7893 8087 8179 7994 7928 8046 7924 7916 8043 7895 7914 7809 7900 7900 7820 7724 8028 7835 7991 7836 7947 7697 7869 7870 7787 7969 7714 7756 7958 7789 7740 7992 7966 7894 7773 7804 7807 7821 7833 7852 7890 7886 7661 7639 7806 7905 7694 7786 7683 7745 7884 7779 7921 8037 7977 7811 7834 7894 7853 7761 7899 7893 7830 7901 7902 7721 7797 7866 7728 7826 7855 7742 7803 7609 7957 7697 7720 7782 7945 7745 7888 7773 7678 7544 7743 7814 7829 7783 7779 7759 7747 7799 7591 7818 7682 7692 7803 7669 7854 7804 7846 7857 7697 7781 7988 7960 8036 8022 8072 7941 7991 7872 7835 7786 7844 7752 7606 7548 7798 7775 7557 7793 7897 7771 7701 7748 7722 7800 7790 7704 7859 7853 7969 7912 7943 7631 7641 7882 7799 7806 7664 7690 7656 7775 7725 7740 7693 7909 7821 7618 7673 7686 7746 7840 7646 7649 7967 7665 7907 7782 7774 7945 7915 8367 8584 8882 9116 9303 9397 9538 9357 9015 8816 8255 8220 8065 7931 7901 7836 7809 7749 7746 7875 7848 7837 7689 7636 7749 7713 7650 7491 7678 7721 7852 7733 7742 7631 7840 7796 7670 7490 7902 7531 7619 7584 7581 7570 7592 7734 7656 7692 7652 7712 7576 7847 7611 7430 7522 7599 7455 7516 7452 7724 7537 7605 7727 7450 7538 7463 7575 7599 7649 7487 7437 7564 7573 7485 7645 7529 7504 7522 7598 7651 7497 7470 7467 7535 7644 7696 7703 7696 7637 7418 7491 7647 7581 7553 7603 7625 7443 7508 7571 7725 7704 7494 7653 7610 7626 7548 7608 7637 7661 7599 7454 7513 7708 7581 7486 7658 7935 7625 7651 7480 7565 7533 7422 7371 7630 7518 7515 7531 7497 7594 7758 7637 7569 7517 7657 7686 7659 7531 7549 7284 7439 7478 7586 7503 7656 7561 7476 7655 7729 7707 7685 7647 7639 7432 7680 7529 7488 7637 7525 7487 7605 7425 7561 7399 7586 7427 7475 7496 7464 7567 7550 7579 7619 7403 7736 7798 7807 7944 8031 7949 7846 7916 7867 7756 7433 7596 7557 7568 7499 7495 7381 7385 7615 7430 7512 7328 7379 7332 7405 7417 7622 7573 7496 7398 7546 7526 7266 7476 7419 7399 7422 7302 7320 7473 7538 7400 7402 7430 7623 7565 7371 7450 7228 7464 7464 7406 7443 7335 7261 7390 7373 7247 7457 7322 7295 7237 7222 7454 7428 7328 7307 7225 7195 7299 7495 7264 7370 7272 7272 7371 7317 7253 7330 7490 7488 7598 7471 7657 7611 7653 7534 7558 7597 7192 7383 7184 7467 7376 7259 7167 7377 7430 7382 7429 7273 7221 7197 7282 7417 7229 7280 7219 7237 7310 7201 7267 7103 7189 7174 7150 7282 7169 7068 7173 7182 7059 7178 7211 7235 7529 7401 7154 7308 7208 7078 7190 7242 7011 7134 7254 7070 7055 7299 7102 7323 7130 7330 7339 7174 7053 7144 7250 7256 7045 7321 7188 7249 7310 7020 7096 7164 7212 7252 7223 7065 7329 7194 7091 7146 7023 7088 7119 7124 7340 7070 7221 7260 7223 7260 7284 7256 7305 7230 7459 7644 7630 7595 7633 7747 7530 7686 7617 7625 7683 7611 7505 7569 7729 7689 7664 7698 7734 7666 7662 7476 7463 7640 7653 7518 7757 7809 7899 7993 8018 7973 8020 8061 8287 8303 8373 8483 8834 9026 9059 9432 9783 10661 12291 14846 18098 23589 32955 47645 67335 85575 98740 101153 90884 76840 65277 52619 38148 26391 18516 14136 11632 10634 9867 9460 9202 8978 8564 8382 8413 8255 8181 7917 7936 7766 7698 7716 7716 7753 7920 7937 7762 7726 7488 7587 7664 7551 7557 7345 7563 7376 7567 7541 7628 7424 7320 7452 7541 7330 7385 7463 7441 7350 7333 7510 7365 7534 7359 7412 7350 7493 7405 7371 7519 7344 7403 7302 7400 7467 7383 7333 7483 7279 7407 7400 7256 7388 7439 7437 7432 7616 7344 7469 7665 7413 7513 7508 7465 7318 7538 7274 7382 7596 7427 7254 7226 7168 7158 7346 7274 7196 7295 7455 7353 7300 7449 7448 7476 7423 7324 7335 7412 7348 7408 7344 7547 7416 7540 7424 7306 7407 7353 7325 7218 7406 7412 7427 7449 7765 7497 7399 7310 7304 7393 7455 7271 7482 7405 7515 7441 7248 7320 7350 7405 7342 7203 7353 7520 7535 7516 7449 7546 7310 7417 7510 7657 7624 7399 7451 7620 7396 7479 7608 7373 7436 7607 7349 7417 7322 7417 7400 7380 7337 7435 7342 7270 7405 7423 7419 7416 7329 7395 7288 7331 7287 7251 7342 7468 7231 7541 7179 7553 7581 7538 7270 7544 7571 7557 7491 7611 7801 7806 7972 8208 8531 8990 9999 11555 14390 19491 25450 31568 34507 32934 29616 26610 24130 20551 16631 13228 10698 9072 8481 8200 7821 7930 7653 7711 7595 7564 7570 7734 7555 7252 7497 7383 7558 7254 7287 7172 7256 7304 7379 7549 7459 7591 7508 7415 7494 7460 7588 7300 7415 7502 7514 7585 7641 7372 7423 7586 7359 7270 7292 7578 7500 7283 7611 7556 7697 7523 7409 7543 7576 7497 7487 7443 7493 7459 7543 7522 7442 7537 7463 7483 7574 7531 7535 7560 7522 7556 7749 7720 7697 7688 7603 7809 7793 7947 7931 8178 8249 8733 9293 10205 12321 15479 20595 26167 30506 31799 28407 24361 22303 21280 19010 15378 12202 10704 9851 9668 9695 10209 11137 13511 17006 22770 30437 37888 40914 37648 32437 28691 26586 24169 19774 15173 11752 9956 9123 8474 8244 8210 7837 7862 7789 7991 7952 7862 7864 8039 7725 7482 7552 7730 7781 7389 7537 7633 7568 7593 7480 7448 7381 7544 7533 7533 7408 7362 7385 7060 7376 7315 7547 7344 7355 7246 7320 7466 7425 7190 7161 7386 7366 7314 7358 7257 7306 7241 7155 7363 7350 7363 7315 7309 7261 7398 7205 7351 7195 7381 7385 7293 7440 7425 7282 7336 7439 7368 7536 7368 7583 7680 7646 7603 7250 7287 7381 7286 7270 7242 7262 7216 7050 7238 7216 7306 7277 7184 7388 7303 7227 7244 7292 7315 7303 7180 7347 7196 7294 7292 7101 7205 7094 7040 7243 7316 7344 7363 7320 7391 7410 7401 7259 7271 7229 7401 7390 7181 7259 7309 7398 7335 7242 7184 7176 7348 7230 7330 7382 7304 7356 7281 7274 7468 7253 7400 7329 7263 7278 7309 7334 7430 7451 7398 7386 7261 7329 7297 7204 7297 7226 7094 7347 7125 7132 7140 7145 7079 7310 7231 7290 7092 7282 7115 7042 7102 7212 7233 6988 7111 6894 7250 7184 7142 7179 7102 7100 7185 7319 7173 7333 7222 7293 7104 7265 7217 7098 7241 7220 7238 7360 7290 7118 7235 7174 7040 7138 7235 7008 7113 7160 7052 7187 7237 7370 7359 7271 7434 7447 7362 7490 7358 7299 7346 7438 7238 7337 7476 7404 7520 7573 7526 7578 7557 7455 7529 7480 7279 7637 7480 7589 7431 7363 7464 7373 7412 7364 7373 7345 7383 7402 7484 7486 7364 7378 7339 7343 7533 7574 7393 7445 7463 7532 7519 7660 7730 7911 7980 8092 8217 8098 8406 8469 8582 8650 8853 9192 9458 9730 10274 10912 11667 12605 14852 18762 25126 36234 52416 72455 88860 94507 87521 76096 66804 61179 58325 50970 41682 31313 22647 17506 14363 12620 11549 10906 10279 9986 9347 9039 8747 8626 8218 7887 7850 8035 7893 7803 7686 7789 7766 7482 7580 7647 7646 7812 7647 7907 7897 7845 7860 7757 7726 7421 7831 7823 7861 8028 8448 8292 8333 8100 7997 7868 8053 7945 7915 8002 7741 7499 7584 7547 7392 7656 7952 7700 8020 8038 7974 7899 8148 8284 8770 9110 9514 10414 12646 16598 23375 31143 36876 37073 32590 27205 24198 24451 24029 21950 17869 14499 11570 10256 9715 10032 10745 12221 13772 15211 15160 14128 13192 13192 13637 13899 13538 13075 12405 11642 11395 11029 10786 10181 9768 9562 9272 8647 8468 8131 7895 7802 7618 7568 7420 7312 7017 7393 7284 7215 7188 7396 7196 6956 7251 7112 7083 7137 6952 7154 6911 7178 7206 7212 7178 7185 6991 7227 7095 7101 7383 7188 6962 7047 7187 6977 6780 6896 7041 7094 6983 6876 7088 7088 7010 7166 6972 7191 7042 7228 7223 7071 7232 6955 7029 6769 7126 6949 6897 6922 6943 7018 6934 7243 7159 6891 6774 7110 7017 7072 6993 6921 6922 6861 6968 6894 6874 7064 6979 7058 6957 6922 6921 6895 6942 7037 6993 7014 6912 6865 6912 6977 6967 6836 6861 6871 6896 6951 7028 6987 6932 6907 6974 6880 6790 6927 6893 6862 6864 6762 6896 6840 6950 6724 6921 6929 6903 6946 6936 6728 6896 6892 6919 6823 6973 6829 6882 6947 6759 6644 6893 7207 6906 6922 6873 7001 6926 6925 6788 6932 6930 6886 6989 7044 6932 6711 6848 6852 6834 6874 6799 6869 6690 6948 6725 6866 6926 6776 6886 6980 6938 6791 6926 6840 6862 6880 6833 6912 6776 6974 7016 6839 6798 6830 7021 6922 6929 6747 6810 6732 6669 6831 6850 6873 6826 6883 6937 6787 6801 6779 6841 6808 6811 7038 6915 6881 6806 6789 6802 6900 6908 6887 6788 6855 6871 6956 6964 6848 6856 6911 6892 6868 6951 6846 6834 6768 6936 6891 6894 6811 7147 6869 7055 6858 6941 6891 6864 7072 6872 6872 6825 7018 6634 6795 6796 6910 6883 6959 6986 6974 7212 7186 7092 7201 7249 7200 7031 7141 7509 7697 7988 8497 9853 11904 14054 15633 15120 13893 12829 11817 11647 11982 11964 11364 10566 9946 10121 11066 13535 16850 19895 20331 18441 15523 13445 13417 14068 14276 13378 11422 10017 8925 7978 7655 7462 7429 7152 7125 7214 7159 6994 7081 7083 7022 7001 7128 6972 7124 7046 7145 7162 7101 7220 7228 7349 7349 7417 7558 7903 8556 9494 11438 13278 14751 15789 15100 13672 12168 11521 11598 11900 11525 10579 9515 8577 7961 7560 7329 7252 7201 6977 7132 7160 6901 6970 7016 7149 7146 7202 7418 7536 7727 7859 7836 7677 7604 7657 7694 8003 8290 8878 9953 11740 14189 14801 13755 12279 10870 10031 10543 10975 10917 10016 8875 8344 7501 7231 7088 7040 6790 6637 6928 6790 6824 6817 6873 6807 6702 6756 6720 6714 6892 6839 6725 6802 6852 6798 6705 6834 6956 6840 6933 6963 6940 6941 6985 6995 6921 7097 7362 7610 8222 9247 10581 12030 12521 11910 10957 10022 9609 9752 9754 9616 9403 8552 8063 7379 7170 7291 7232 7236 7319 7393 7412 7195 7158 6999 7116 6947 7032 6863 6740 6591 6677 6553 6653 6679 6601 6889 6561 6638 6643 6805 6676 6651 6469 6557 6514 6566 6412 6781 6532 6490 6605 6599 6599 6606 6876 6573 6738 6517 6688 6611 6673 6685 6494 6572 6696 6646 6580 6655 6422 6584 6531 6503 6581 6516 6736 6695 6749 6638 6556 6398 6490 6706 6584 6553 6741 6694 6650 6430 6616 6636 6589 6536 6790 6775 6682 6722 6738 6550 6614 6705 6683 6518 6688 6729 6611 6684 6460 6604 6485 6647 6635 6705 6598 6564 6619 6672 6663 6565 6429 6748 6783 6675 6608 6538 6711 6815 6985 6762 6805 7231 7713 8301 9300 9587 9768 9483 8711 8204 7750 7987 8383 8481 8088 7623 7333 6823 6755 6822 6735 6593 6582 6625 6549 6457 6574 6508 6709 6643 6567 6501 6459 6456 6664 6504 6540 6440 6607 6552 6582 6556 6528 6528 6632 6551 6711 6725 6611 6559 6725 6466 6397 6609 6621 6636 6562 6452 6486 6480 6670 6533 6674 6571 6760 6832 6758 6875 6887 7130 7363 7582 7683 7478 7190 6961 7199 7281 7325 7736 7822 8001 8579 9617 10819 11435 11070 10577 9650 9072 8922 9305 9825 10488 10511 9991 9488 8901 8081 7730 7780 7856 7944 7893 7789 7342 7065 6870 6766 6682 6543 6532 6621 6684 6527 6312 6581 6762 6751 6650 6834 6622 6530 6495 6479 6539 6706 6574 6523 6499 6436 6703 6425 6715 6535 6492 6396 6424 6419 6407 6479 6531 6577 6458 6524 6517 6398 6439 6487 6508 6534 6362 6481 6432 6431 6452 6460 6325 6469 6405 6543 6571 6541 6521 6620 6527 6385 6413 6364 6233 6400 6610 6403 6591 6437 6456 6499 6306 6419 6591 6470 6563 6487 6549 6621 6623 6510 6500 6305 6425 6368 6601 6555 6419 6550 6571 6587 6605 6487 6738 6779 6708 6756 7007 7271 7895 8575 9119 9222 8993 8397 7648 7603 7517 7628 7916 7681 7478 7017 6977 6796 6661 6632 6726 6326 6433 6554 6519 6427 6413 6543 6452 6412 6487 6424 6357 6554 6323 6476 6411 6560 6586 6666 6567 6526 6442 6361 6491 6549 6525 6582 6362 6208 6431 6445 6419 6432 6377 6617 6600 6506 6594 6429 6433 6571 6600 6666 6727 6594 6723 6525 6667 6568 6749 6778 6671 6604 6793 6744 6893 7157 7694 8403 9160 10299 11052 10842 9999 8999 8274 8273 8290 8786 8940 8791 8212 7663 7361 6999 6730 6893 6700 6696 6556 6541 6585 6493 6509 6511 6521 6585 6642 6513 6540 6511 6451 6603 6392 6566 6459 6468 6615 6515 6431 6599 6362 6627 6556 6709 6651 6645 6847 6723 6507 6677 6776 6783 6880 7010 7312 7842 8201 9135 10073 11088 11879 12048 11844 11240 10343 9984 10121 10541 10908 11616 11898 11594 10532 9291 8475 7986 8052 8112 8183 8107 7972 7421 7125 6919 6873 6668 6581 6522 6536 6669 6603 6671 6379 6553 6546 6444 6599 6538 6492 6357 6486 6300 6445 6367 6425 6418 6291 6561 6695 6410 6489 6577 6397 6308 6500 6393 6247 6240 6327 6374 6306 6291 6279 6643 6481 6376 6539 6431 6601 6329 6348 6463 6433 6470 6469 6440 6532 6334 6319 6383 6558 6460 6333 6407 6445 6424 6226 6290 6412 6487 6440 6395 6215 6345 6389 6360 6089 6299 6565 6188 6403 6403 6347 6537 6400 6436 6620 6454 6375 6328 6448 6313 6372 6389 6492 6454 6496 6278 6459 6389 6372 6429 6591 6423 6260 6370 6238 6358 6513 6478 6610 6433 6286 6462 6582 6409 6457 6412 6474 6368 6355 6412 6342 6404 6390 6404 6396 6454 6275 6369 6465 6354 6393 6370 6294 6419 6365 6482 6515 6400 6264 6299 6351 6359 6390 6449 6342 6547 6403 6444 6448 6486 6591 6639 6394 6457 6443 6392 6331 6359 6528 6397 6512 6345 6564 6562 6437 6695 6762 7065 7241 7478 7572 7599 7340 7298 7046 7009 6966 7029 7241 7245 7116 6883 6988 6935 6852 6552 6574 6647 6351 6521 6636 6493 6360 6581 6527 6420 6249 6458 6350 6430 6385 6437 6549 6464 6506 6262 6573 6453 6433 6642 6669 6731 6937 6746 6683 6635 6397 6391 6375 6662 6700 6658 6672 6654 6555 6568 6701 6641 6451 6723 6758 6480 6670 6522 6739 6957 6897 6998 7154 7291 8036 8406 9398 10799 12270 13110 12970 12023 10426 9408 9001 9067 9398 9954 10214 9868 9513 8618 7708 7325 7086 7003 6925 6688 6791 6651 6586 6598 6604 6599 6598 6632 6562 6662 6635 6489 6499 6566 6424 6481 6572 6435 6451 6239 6413 6461 6491 6472 6381 6385 6457 6442 6528 6309 6347 6254 6411 6592 6553 6439 6443 6318 6292 6366 6388 6395 6296 6411 6468 6461 6237 6375 6428 6500 6486 6396 6496 6365 6403 6376 6240 6500 6477 6465 6305 6527 6424 6442 6592 6387 6339 6550 6517 6399 6437 6455 6437 6595 6452 6667 6411 6535 6513 6700 6566 6660 6809 6824 6876 6927 6811 6726 6790 7025 7042 7261 7459 7955 8595 9684 11872 15178 19038 21462 21459 18956 15479 12455 10746 10702 11408 12800 14075 14102 13263 11322 9557 8415 7807 7363 7460 7446 7555 7619 7393 7446 7050 7092 6912 6749 6864 6990 7016 6971 6812 6753 6605 6686 6384 6692 6469 6568 6510 6434 6408 6615 6592 6627 6548 6416 6431 6568 6509 6610 6404 6514 6626 6640 6520 6457 6331 6537 6573 6461 6565 6652 6391 6472 6478 6495 6538 6634 6412 6507 6433 6488 6545 6609 6526 6603 6474 6470 6479 6637 6551 6510 6486 6512 6566 6513 6620 6706 6763 6774 7132 7627 8042 8904 9116 9082 8850 8281 7903 7751 7619 7645 7757 7980 8247 8032 8032 7806 7589 7612 8013 8619 9601 11227 12723 13599 13319 11773 9888 8873 8269 8469 8836 9450 10146 10316 9972 8920 8050 7706 7460 7263 6957 6980 7217 7010 7153 7113 7188 7108 7296 7252 7392 7579 7853 8349 8622 9491 10777 12649 15431 18620 20747 21549 19350 16798 14245 12320 11602 11867 12940 14004 14575 14093 12809 11260 9938 8953 8246 7902 7391 7265 7039 7105 7237 6978 6734 6842 6765 6616 6741 6670 6847 6630 6699 6644 6656 6563 6573 6680 6674 6716 6600 6582 6764 6694 6500 6592 6579 6701 6899 7099 7114 7377 7504 7601 7870 7839 7751 7492 7670 7773 7903 7816 7870 7829 7882 7713 7735 7544 7365 7350 7425 7281 7340 7667 7660 7806 8161 8539 9136 10425 12331 14896 16299 16661 15278 13207 11416 10302 9754 10030 10886 11774 12812 13294 13108 12682 11656 10494 9522 8804 8355 8190 8296 8287 8420 8573 8167 7960 7643 7459 7184 7146 7279 7101 6966 6907 6886 6843 7024 6858 6868 6907 6885 6953 6833 6723 6985 7083 7088 7311 7154 7366 7570 7847 8426 9116 10463 12418 14864 17380 19250 19707 18215 15766 13314 11588 10808 11170 11510 12470 13227 13423 12789 11584 10263 9060 8290 7876 7388 7549 7288 7147 7032 6973 6933 7021 6842 6891 6913 7069 6922 7168 7338 7463 7487 7565 7392 7199 7248 6949 7190 7317 7071 7437 7407 7515 7668 7947 8387 9104 9998 10825 11412 11121 10721 9827 9318 8629 8258 8351 8273 8759 9212 9104 8771 8227 7658 7613 7229 6989 6639 6752 6686 6611 6576 6434 6470 6535 6757 6613 6529 6800 6688 6494 6508 6478 6442 6485 6646 6762 6739 6600 6542 6521 6566 6520 6506 6432 6499 6572 6441 6607 6711 6478 6725 6629 6736 6712 6545 6536 6786 6803 6584 6785 6722 6664 6747 6662 6907 6739 6966 7129 7330 7753 8180 8720 8782 8871 8341 7833 7671 7756 7521 8049 8456 9519 10389 11684 13488 15044 15066 13964 12162 10291 9036 8629 8453 8849 9228 10315 10730 10421 9793 8972 8048 7520 7353 6909 6990 6688 6730 6662 6889 6766 6601 6460 6522 6381 6679 6579 6483 6464 6520 6360 6514 6415 6349 6530 6568 6493 6665 6567 6448 6618 6553 6615 6686 6555 6448 6526 6584 6568 6523 6562 6307 6324 6389 6426 6490 6469 6495 6618 6258 6415 6381 6417 6429 6414 6451 6603 6601 6640 6924 7031 7579 7790 8143 8078 7753 7373 7038 6711 6645 6747 6775 6905 7275 7351 7267 7065 6863 6790 6614 6477 6343 6300 6395 6341 6321 6443 6195 6408 6442 6415 6543 6372 6255 6509 6545 6338 6283 6560 6345 6419 6465 6604 6496 6326 6399 6415 6378 6416 6384 6385 6423 6444 6509 6407 6540 6324 6354 6319 6323 6312 6254 6295 6363 6479 6304 6291 6489 6401 6383 6444 6267 6163 6430 6389 6415 6479 6334 6498 6543 6481 6386 6373 6271 6462 6194 6313 6294 6478 6360 6488 6395 6089 6363 6440 6369 6173 6329 6473 6249 6056 6184 6241 6360 6253 6272 6230 6420 6605 6378 6434 6390 6326 6285 6474 6332 6327 6349 6489 6393 6413 6346 6272 6426 6303 6275 6350 6238 6268 6349 6386 6184 6284 6120 6352 6221 6398 6176 6379 6325 6244 6469 6411 6418 6308 6299 6229 6339 6238 6419 6375 6431 6265 6365 6370 6207 6440 6488 6494 6386 6354 6180 6263 6518 6381 6329 6380 6395 6409 6400 6447 6394 6347 6332 6368 6511 6306 6288 6400 6287 6232 6335 6481 6416 6313 6356 6454 6513 6540 6386 6259 6347 6298 6430 6283 6598 6373 6436 6495 6454 6553 6676 6387 6511 6489 6838 6865 6726 6874 6851 7126 7319 7767 7987 8214 8974 9379 9962 10395 10783 11273 12000 13148 14043 14017 13418 12136 11155 10503 9746 9485 9449 9644 9683 10213 10117 9919 9229 8744 8284 7820 7500 7386 7375 7452 7367 7364 7100 6886 7027 6849 6633 6713 6778 6800 6705 6784 6852 6804 6755 6887 6773 6823 6920 7025 7237 7827 8396 9268 9718 9114 8930 8178 7821 7466 7393 7424 7503 7973 8158 8457 8470 8059 7866 7551 7354 7310 7473 7777 8246 8797 9648 10549 11153 11416 10924 9906 8923 8068 7719 7819 7939 8061 8470 8639 9139 8976 8770 8335 8090 7865 7654 7379 7082 6809 6800 6891 6600 6843 6577 6670 6642 6814 6642 6834 6722 6405 6391 6407 6480 6462 6474 6106 6168 6460 6373 6431 6281 6555 6527 6308 6399 6255 6476 6533 6502 6420 6446 6448 6567 6553 6505 6411 6674 6460 6366 6411 6538 6398 6239 6264 6493 6563 6457 6475 6655 6584 6566 6662 6617 6616 6758 6805 7010 7203 7401 7769 8423 8818 9386 9477 9427 8986 8489 8002 7579 7535 7669 7833 8134 8528 8775 9234 9584 9696 10404 10364 10159 9853 9339 8702 8512 8088 7905 7579 7719 7975 8196 8492 8350 8206 7846 7581 7306 7204 6912 6865 6929 6678 6732 6613 6531 6524 6559 6478 6608 6561 6776 6795 6755 6502 6660 6754 6886 7150 7297 7420 7482 7673 7367 7449 7651 7450 7535 7677 7493 7535 7386 7239 7495 7384 7567 7705 7996 8312 9015 9748 10730 11330 11533 11686 11724 11188 10444 9733 9232 8721 8710 8889 9186 9439 9441 9683 9571 9544 9087 9382 9330 9471 9163 9501 9455 9499 9915 10371 10754 11004 10569 9956 9310 8784 8754 8304 8144 8252 8183 8285 8518 8447 8326 7945 7807 7356 7155 6923 6571 6666 6517 6628 6552 6469 6321 6497 6503 6371 6398 6387 6245 6389 6421 6353 6402 6167 6522 6481 6302 6227 6263 6364 6211 6350 6427 6508 6501 6444 6383 6478 6562 6568 6423 6379 6423 6484 6600 6701 6653 6682 6718 6779 7035 7146 7417 8057 8834 9938 11177 12398 12328 11796 10608 9481 8544 7782 7466 7392 7727 8338 8690 9205 9510 9259 8876 8095 7810 7227 7102 6929 6865 6691 6552 6613 6425 6589 6612 6437 6674 6646 6657 6854 7013 7418 7932 8445 8940 9114 8812 8376 7881 7630 7114 6951 6894 7013 7154 7401 7627 7987 7830 7801 7643 7202 7029 6964 6737 6719 6620 6719 6627 6617 6619 6491 6618 6772 6803 6741 6747 7034 6878 6835 6789 6976 7202 7412 7642 8313 8881 9837 10538 11141 11011 10824 11126 11669 12627 13115 13671 13050 12027 11139 10432 10069 9882 9592 9309 9034 9431 9561 9644 9797 9466 8746 8147 7626 7226 7070 6714 6740 6630 6644 6615 6508 6524 6423 6365 6348 6359 6349 6252 6217 6240 6483 6437 6570 6705 6867 7109 7386 7336 7319 6983 6947 6705 6692 6480 6546 6504 6465 6542 6525 6754 6630 6744 6567 6595 6335 6181 6218 6301 6112 6215 6324 6206 6286 6268 6129 6220 6130 6060 6190 6178 6110 6059 6173 6179 6254 6140 6243 6092 6226 6172 6191 6128 6131 6084 6179 6119 6182 6037 5947 6124 6145 6146 6141 6114 6161 6134 6197 6281 6262 6098 6150 6124 6035 6059 6100 6047 6058 6194 5990 6090 6349 6220 6215 6131 6113 6107 6148 6256 6119 6045 6193 6281 6186 6229 6235 6290 6151 6268 6273 6145 6286 6253 6238 6254 6247 6174 6432 6312 6413 6719 6691 7043 7203 7271 7453 7318 7220 6836 6617 6407 6388 6400 6531 6529 6746 6874 6938 6909 6952 6702 6615 6630 6378 6326 6562 6446 6326 6453 6626 6866 7241 7625 8028 7981 7697 7619 7421 7100 6971 6820 6855 6780 6702 6878 6953 6830 7266 7135 6849 6765 6678 6643 6506 6378 6540 6440 6143 6259 6280 6216 6127 6328 6259 6170 6144 6118 6365 6072 6031 6032 6191 6198 6315 6196 6226 6241 6490 6381 6525 6758 6862 7205 7528 7578 7332 7191 6916 6717 6448 6368 6427 6322 6459 6532 6704 6751 6650 6790 6721 6578 6413 6425 6426 6337 6298 6129 6232 6290 6111 6081 6055 5992 6060 6074 6097 6057 6016 6154 6109 5990 6262 6076 6196 6141 6092 6059 6172 5993 6155 5956 6091 6150 6221 5947 6107 6128 6037 6217 6136 6090 6035 6130 5915 6063 6085 5937 6108 5915 6055 6050 6165 6269 6287 6225 6218 6044 6075 6214 6226 6225 6118 6196 6041 6031 6083 6088 6044 5947 6030 5980 6250 6211 6078 6245 6012 6020 6133 6059 6074 5956 5928 5960 5837 6119 6032 5901 5935 6109 6080 5900 5952 5998 6022 6019 5816 6045 5850 5925 5901 5871 6109 5977 5975 5890 6019 6063 5875 6065 6168 6103 5957 5985 5912 6077 5960 5818 5807 5936 5901 5945 6025 5858 6109 6078 5948 6176 6078 6114 6054 6045 6228 6198 6053 6102 5953 6091 6233 6099 5979 5882 5965 6014 5851 5882 6019 6033 6191 6077 6062 6261 6062 5989 5953 6086 6008 6154 6267 6106 6015 6173 6218 6275 6118 6064 6074 6009 5953 6006 6064 6122 6122 6221 6024 6081 6129 6115 6102 5910 5849 5915 5980 5953 6057 6057 5909 6058 6003 6082 6130 6062 5999 6006 5937 6054 6054 6136 6033 5977 6100 6037 6081 6004 6051 5928 6020 6040 6042 6037 5953 6023 6080 5894 5865 5916 5987 6077 5989 5922 6016 5903 6006 6038 6169 5964 5975 6153 6091 6204 6066 6079 6256 6275 6122 6152 6106 6174 6190 6260 6156 6161 6046 5911 6050 6042 6168 6355 6256 6107 6124 6033 6127 6079 6068 5882 5996 5946 6013 5999 5926 6162 5913 5922 6046 5971 5907 5995 6088 6156 5929 5973 5904 6018 6003 6005 6021 6042 5984 6077 5934 5898 5999 5969 6078 5922 6063 6121 6157 5931 6014 6069 6040 6116 6171 6122 5985 6117 6011 5838 5988 5849 6113 6108 6051 6210 6056 6160 6034 6157 6110 6170 6057 5963 6098 6086 6079 6008 6152 6227 6301 6255 6296 6280 6411 6443 6755 6515 6600 6439 6577 6888 6844 7029 7332 7594 7589 7709 7462 7184 6910 6665 6586 6615 6432 6471 6676 6741 6780 6785 6882 6872 6730 6704 6649 6567 6507 6256 6266 6642 6343 6417 6637 6659 6691 6776 7165 7597 7936 8464 9193 9599 9638 9354 8669 7996 7519 7114 7159 6795 6886 6790 7051 7343 7693 8230 8407 8609 8608 8375 8021 7404 7112 6789 6775 6465 6498 6407 6374 6352 6303 6338 6403 6560 6650 6509 6458 6479 6409 6303 6350 6348 6309 6511 6379 6732 6654 6695 6924 7200 7556 7857 7586 7678 7405 6983 6877 6755 6537 6479 6304 6474 6617 6672 6943 6863 7118 7162 6822 6748 6549 6389 6370 6206 6308 6190 6206 6177 6058 6094 6224 6221 6348 6237 6227 6313 6491 6540 6624 6735 6789 6676 6466 6385 6338 6491 6476 6318 6380 6617 6642 6703 6893 7051 7058 7218 7144 6884 6724 6605 6416 6517 6523 6496 6485 6616 6465 6361 6364 6330 6380 6344 6358 6264 6307 6229 6133 6157 6261 6272 6200 6260 6064 5964 6096 5971 6199 6193 5925 5982 5982 5978 6135 6023 5990 5917 6031 5929 6016 6148 5970 6001 6257 6084 6109 6121 5860 5895 5967 5996 6173 6083 6145 6043 6195 6252 6138 6025 6174 6169 6192 6219 6145 6135 6065 6435 6340 6329 6461 6582 6493 6332 6493 6524 6466 6525 6526 6395 6260 6489 6555 6784 6870 7401 7908 8327 8629 8979 8729 8358 8063 7825 7396 7226 7052 6995 6807 6679 6750 6940 6939 7239 7434 7613 7197 7313 7034 6754 6725 6490 6525 6468 6369 6212 6299 6218 6271 6104 6154 6152 6109 6103 6116 6216 6202 6368 6041 6078 6099 6146 6144 6139 6111 6284 6190 6285 6385 6448 6494 6622 6648 6764 6610 6532 6517 6316 6276 6336 6255 5966 6295 6146 6299 6316 6274 6413 6568 6342 6399 6237 6254 6348 6325 6393 6365 6418 6238 6280 6013 6141 6069 6190 6318 6229 6282 6223 6332 6500 6522 6748 6933 7256 7521 7571 7643 7457 7256 6897 6784 6662 6562 6289 6402 6362 6514 6319 6383 6549 6778 6865 6719 6559 6534 6590 6486 6328 6354 6251 6210 6238 6179 6162 6149 6239 5852 6074 6044 6015 6082 6019 6187 6210 6036 6206 6308 6351 6228 6327 6098 6196 6149 6236 6086 6100 6238 6249 6056 6047 6060 6219 6224 6435 6312 6456 6487 6596 6757 6852 6974 6958 6795 6979 6774 7023 7262 7588 7596 7659 7286 7060 6843 6723 6637 6798 6847 6779 6944 7103 7120 7349 7267 7265 7003 6967 6906 6699 6369 6335 6385 6253 6307 6225 6219 6308 6540 6384 6322 6325 6145 6128 6136 6047 6032 6063 6129 6197 6231 6158 6050 6046 6134 6115 6205 6147 6099 6056 6042 5981 6116 6112 6120 5957 5906 6096 5980 6083 6045 6106 6011 6084 6252 5910 5869 6074 5845 5901 5892 5714 6006 6082 5914 5874 5788 6016 5898 5808 5921 6079 6085 5816 5868 5756 5935 5865 6132 6053 5820 5853 5784 5930 5949 6009 6054 5843 5815 5880 5961 5888 5838 5784 5978 6117 5871 5968 5999 5951 5964 5885 5873 6087 6081 6006 5912 5972 5980 6050 6058 6076 6078 6212 6101 6177 6293 6531 6543 6411 6397 6392 6270 6193 6073 6028 6139 6094 6014 6023 6160 6036 6128 6087 6061 6237 6223 5973 6026 5991 6064 6041 6002 5973 6047 6085 6039 5914 6050 5933 6077 5899 6019 5865 5947 5930 5896 5911 5986 5957 6036 5971 6013 6133 6183 6184 6192 6103 5977 6222 6319 6188 6298 6138 6303 6563 6675 6720 6620 6751 6884 7158 7471 7490 7142 7047 6744 6722 6478 6553 6532 6383 6205 6482 6354 6556 6657 6604 6563 6691 6597 6733 6592 6614 6627 6695 6797 7320 7203 7274 7138 6863 6418 6250 6335 6178 6398 6166 6172 6104 6168 6319 6229 6365 6340 6508 6627 6485 6455 6277 6150 6143 6213 6183 6273 6185 6138 6065 6088 6054 6159 6050 6020 6171 6149 6277 6344 6302 6372 6426 6604 6555 6206 6473 6285 6436 6412 6674 6779 6765 6747 6554 6425 6306 6083 6237 6178 6320 6379 6144 6210 6326 6272 6323 6092 6383 6238 6338 6248 6006 5965 6126 6036 5957 5906 5961 5950 5978 5836 6027 5906 5906 5971 5970 5928 6102 5931 5847 5797 5890 5987 5996 5968 5977 5927 5989 5749 5834 5926 5948 5818 6043 5992 5922 5964 5875 6028 5987 5873 6027 5801 5879 6104 5985 5914 5987 6095 6094 5846 6116 6158 6117 6078 5991 5986 6213 5873 6046 6056 6013 6109 6175 6301 6376 6481 6478 6600 6832 6914 6996 6911 6805 6817 6710 6583 6566 6418 6375 6421 6526 6346 6419 6405 6527 6754 6812 6817 6948 6913 6809 6762 6607 6743 6579 6482 6382 6312 6397 6139 6221 6293 6039 6224 6365 6320 6124 6318 6304 6226 6285 6269 6277 6130 6253 6146 6078 6053 6014 6148 6227 6183 6050 6066 6064 6312 6234 6348 6485 6836 7082 7157 7201 6957 6971 6694 6703 6583 6340 6433 6209 6292 6300 6456 6430 6412 6364 6772 6608 6659 6892 6896 6797 6791 6639 6530 6617 6579 6541 6669 6416 6330 6329 6325 6218 6215 6196 6100 6129 6177 6186 6210 6232 6296 6360 6383 6178 6363 6133 6178 6159 6175 6235 6015 6113 6093 5944 5983 5993 6257 6265 6292 6372 6366 6428 6385 6547 6721 6874 6996 7270 7200 7088 6867 7010 6768 6728 6771 6823 6939 6730 6823 6732 6811 6688 6737 6618 6699 6683 6565 6584 6508 6463 6558 6366 6349 6374 6402 6471 6333 6304 6338 6354 6216 6368 6453 6241 6180 6354 6326 6385 6454 6441 6389 6236 6321 6450 6317 6432 6518 6431 6301 6365 6550 6677 6759 6667 6754 6958 6850 6530 6509 6546 6462 6317 6138 6184 6308 6183 6235 6042 6158 6226 6408 6421 6428 6545 6399 6231 6143 6435 6204 6133 6108 6086 6153 6122 5926 6059 5907 5967 5987 6049 6151 6038 5865 6010 6093 5919 6104 5944 6014 5912 6086 5963 5882 6065 6134 6160 6142 6047 6085 6172 6217 6353 6537 6727 6570 6449 6190 6255 6118 6199 6225 5979 6031 6161 6019 6126 6155 6056 6105 6199 6172 6198 6257 6222 6185 6086 6423 6273 6413 6463 6534 6256 6285 6317 6073 5985 5910 5946 5893 5979 5968 5883 6068 5895 5824 5862 6061 5978 6102 6284 6107 6060 6023 5935 5813 5975 5831 5764 6004 5827 5939 5995 6018 5976 5896 5972 6035 6166 6072 6098 6304 6508 6611 6454 6683 6740 6658 6260 6265 6119 5976 6172 5992 6020 6041 6063 6062 6005 5843 6022 6031 6185 6311 6237 6288 6252 6212 6113 6129 6011 6056 6015 6041 5895 5931 5898 5918 5917 5996 5915 5836 5899 5782 5892 5686 5856 5891 6007 5882 5896 5967 5800 5860 5868 5741 5890 5768 5863 5945 5897 5796 5721 5846 5996 6000 5817 5874 5867 5701 5889 5840 5882 5809 5885 5779 5798 5811 6043 5901 5837 5965 6095 5787 5790 5918 5924 5946 5834 5912 5858 5957 5942 5956 5869 6038 5857 5898 6119 6261 6134 6265 6318 6123 6220 6186 6387 6516 6461 6347 6292 6177 6187 6085 6056 6132 5979 6005 6022 6154 6208 6249 6213 6232 6394 6497 6601 6475 6307 6203 6230 6119 5991 6034 6106 6038 5947 6047 5916 6058 5909 5904 6017 6025 6151 5925 5959 6040 5986 5907 5835 5841 5867 5796 5787 5779 5719 5863 5885 5941 5968 5772 5938 5806 5806 5616 5867 5781 5732 5955 5880 5836 5922 5988 5837 6120 5922 6044 5933 5827 6000 6019 5884 5688 5883 5955 5903 5937 5796 5749 5879 5942 5847 5826 5842 5852 5831 5892 5858 5842 5699 5804 5832 5862 5854 5800 5881 5923 5867 5663 5839 5841 5800 5907 5899 5858 5970 6041 6110 6245 6173 6113 6096 5954 5962 5766 6014 5901 5996 5833 5905 5860 5794 5836 5742 5827 5820 6185 5987 6168 5978 6063 6167 5934 5899 5802 5656 5930 5933 5992 6022 6018 6048 6022 5854 6004 6110 6097 6125 5878 6092 6111 6238 6178 6134 6261 6197 6246 6201 6218 5934 5932 6104 6021 6047 6113 5961 5906 6065 6140 6137 6159 6346 6158 6356 6302 6436 6553 6570 6671 6728 6722 6695 6684 6810 6854 6723 6895 7033 7033 6797 6726 6733 6640 6551 6574 6400 6498 6560 6555 6670 6801 6690 6718 6605 6531 6554 6549 6621 6581 6650 6532 6474 6273 6320 6112 6140 5978 6227 6005 6274 6170 6071 6095 5945 5984 6116 5996 5955 5920 5917 5901 5922 5888 5826 5942 5894 5996 5961 5818 6030 5946 5957 5948 5742 5963 6029 6156 6004 6296 6349 6281 6153 6164 6206 6363 6476 6418 6437 6413 6499 6403 6109 6364 6061 6177 6274 6210 6380 6310 6351 6419 6469 6521 6526 6450 6389 6383 6467 6161 6187 6028 6171 6077 6075 6053 6155 6189 6080 6039 5985 6025 6266 6123 5971 6128 6212 6199 5824 5921 5924 5797 5890 5932 5904 5805 5895 5936 6015 6037 5724 5739 5948 5939 5984 6022 5849 6119 6123 5946 6009 6134 6414 6438 6523 6553 6679 6748 6645 6736 6520 6429 6492 6299 6134 6048 6068 6163 6127 6081 6185 6238 6189 6057 6317 6188 6496 6397 6380 6391 6495 6464 6238 6328 6211 5991 6053 5872 6075 6026 5983 6165 6059 6121 6130 6168 6389 6396 6378 6568 6570 6682 6543 6558 6238 6454 6270 6324 6331 6203 6041 6071 6193 6111 6246 6165 6154 6266 6105 6395 6317 6386 6524 6526 6560 6547 6542 6553 6384 6412 6310 6233 6132 6022 6008 5981 5957 6055 6012 5887 6045 5990 6288 6116 6284 6595 6393 6649 6822 6766 6613 6569 6446 6456 6097 6025 6146 5894 5930 5967 6088 6081 6113 6174 5953 5896 5958 5958 6044 5986 6200 6095 6347 6099 6178 6041 5925 5830 5910 5886 5791 5818 6044 5803 5828 5841 5994 5780 5905 5860 5692 5704 5877 5893 5856 6016 5937 6016 6111 6044 6002 5865 5839 5771 5635 5921 5895 5935 5755 5807 5705 5808 5875 5903 5910 5804 5843 5900 5850 5852 5864 5895 5907 5823 6063 5840 6028 5955 5949 6061 6036 6098 6094 6209 6202 6100 5996 6006 6125 5954 5941 5909 6027 5998 5837 6001 5950 5924 6031 5907 5903 5901 5960 5924 6070 6079 6154 6194 6111 5935 6017 6007 6030 6194 6005 6063 6291 6039 6243 6323 6245 6203 6271 6035 6126 6174 6023 6201 6081 5998 6062 6096 6131 6210 6176 6201 6368 6353 6218 6356 6258 6199 6462 6235 6204 6065 6071 6104 5943 6057 6031 6200 6246 6396 6328 6319 6315 6347 6089 6268 6267 6254 6347 6184 6197 6406 6183 6514 6444 6481 6625 6595 6566 6617 6437 6484 6336 6295 6391 6338 6308 6004 6072 6112 6104 5903 5949 5985 6231 6168 6090 6145 6327 6314 6209 6196 6179 6094 6032 5869 6087 6124 5996 5775 5975 5933 5859 5958 5984 5754 5952 5906 5863 5942 6055 6019 5957 6130 6135 5937 5898 5907 5963 5737 5859 5781 5830 5959 5857 5729 5971 5854 5785 5809 5862 5916 5980 5828 5873 5862 5887 5736 5912 5881 5747 5821 5749 5793 5767 5835 5863 6020 6007 5921 5869 5916 5863 5768 5682 5904 5955 6028 5940 6068 5915 6192 6093 6260 6184 6314 6253 6388 6534 6774 6717 6408 6330 6272 6237 6238 6027 6178 6053 5982 5888 5856 5835 5977 6038 5957 6112 6119 6083 6195 6154 6203 6145 6198 6152 6231 6078 5953 5766 5800 5956 5920 5958 5933 6001 5913 5774 5849 5925 5776 5825 5689 5911 5850 5785 5637 5857 5835 5911 6008 5861 5933 6048 6013 6032 6070 6139 6282 6394 6541 6578 6454 6333 6512 6510 6417 6187 6141 6092 5846 6045 6021 6049 6002 5895 6040 6178 6025 6303 6291 6149 6182 6142 6135 6193 6239 6234 6138 6167 6020 5974 6056 5962 6127 6293 6334 6229 6248 6204 6204 5958 6089 6169 6023 5941 6012 6046 5810 6009 5991 5895 5966 5735 5834 6040 5992 5999 6071 5841 5860 6070 5921 5983 5984 5915 5874 5842 6039 5913 5848 6017 5856 5786 5972 5899 5910 6094 5910 5985 6152 6415 6513 6400 6340 6381 6295 6234 6149 6111 6264 6327 6233 6188 6286 6486 6481 6453 6465 6348 6307 6284 6208 6259 6125 6267 6078 6116 6081 6009 6179 6130 5957 5971 5906 6029 5950 5961 6084 6168 6122 6068 6042 5993 5946 5917 5895 5947 5696 5848 5718 5927 5734 5945 5791 5851 5608 5772 5775 5638 5671 5877 5754 5836 5588 5862 5864 5873 5808 5670 5712 5796 5803 5655 5769 5735 5681 5800 5827 5802 5807 5848 5770 5781 5712 5804 5996 5916 5857 5922 5892 5728 5891 6055 5898 5963 5860 5890 6027 5971 6006 6040 5895 5742 5923 5817 5988 5826 5868 5907 5963 6064 6053 6097 5994 5970 6102 6228 6304 6095 6138 5913 5762 5835 5932 5931 5974 5957 5896 5872 5816 5967 6025 6125 5799 5830 5923 6168 6163 6089 6267 6313 6222 6207 6307 6189 6099 5950 6073 6053 5952 5950 5817 5749 5658 5879 5962 5834 5845 5855 5881 6110 5942 5792 5839 5941 6059 5994 5949 5921 6032 5974 5772 5927 5803 5886 5827 5827 5877 5939 5983 5878 5943 5909 5939 5921 5902 5706 5857 5930 5725 5850 6017 5789 5719 5730 5733 5692 5696 5768 5835 5905 5856 5928 5794 5855 5857 5896 6023 5877 5732 5982 5960 5837 5846 6043 5968 6143 6150 6123 5953 5920 6117 5983 6119 5975 6122 6159 6210 6070 6116 5974 6184 6075 5953 5997 5846 5942 5902 6009 5744 6108 6192 6103 6089 5877 5861 5919 5888 5988 6141 6132 6075 6152 6174 6095 6282 6138 6081 6094 6217 6185 6115 5932 5997 6048 5938 5910 5907 5873 5826 5879 5901 5959 5766 5897 5822 5782 5808 5797 5847 5944 5771 5918 5896 5704 5862 6015 5767 5768 5819 5748 5840 5768 5637 5733 5905 5921 5749 5800 5824 5853 5907 5935 5792 5626 5988 5762 5753 5880 5804 5770 5764 5782 5706 5755 5654 5768 5892 5716 5761 5806 5825 5746 5656 5746 5725 5690 5776 5825 5818 5645 5663 5729 5693 5724 5768 5892 5906 5790 5875 5930 5807 5796 5888 5851 5857 5877 5783 5644 5664 5628 5790 5771 5657 5731 5594 5694 5822 5776 5782 5723 5793 5753 5948 5650 5825 5855 5952</intensities>
			</dataPoints>
			<nonAmbientPoints type="Temperature" unit="K">
[...]
			</nonAmbientPoints>
		</scan>
	</xrdMeasurement>
</xrdMeasurements>