File: powder_X-ray_diffraction/variable-temperature_experiments/NaNbO2F2/raw_data/80°C.xrdml
<?xml version="1.0" encoding="UTF-8"?>
<xrdMeasurements xmlns="http://www.xrdml.com/XRDMeasurement/1.7" xmlns:xsi="http://www.w3.org/2001/XMLSchema-instance" xsi:schemaLocation="http://www.xrdml.com/XRDMeasurement/1.7 http://www.xrdml.com/XRDMeasurement/1.7/XRDMeasurement.xsd" status="Completed">
	<comment>
		<entry>Configuration=XRK900, Owner=User-1, Creation date=12/01/2015 16:52:44</entry>
		<entry>Goniometer=Theta/Theta; Minimum step size 2Theta:0.0001; Minimum step size Omega:0.0001</entry>
		<entry>Sample stage=AP XRK-900 with z-axis; Minimum step size Z:0.001</entry>
		<entry>Diffractometer system=EMPYREAN</entry>
		<entry>Measurement program=C:\PANalytical\Data Collector\Programs\Gwen\NaNbO2F2-Lent.xrdmp, Identifier={26D14ECE-D3C8-438C-91CA-8651EAF68C7D}</entry>
		<entry>Batch program=C:\PANalytical\Data Collector\Programs\Gwen\Thermodiff-Ouail.xrdmp, Identifier={9701CF17-19F5-4DD4-A8E1-7279D1FD2F5E}</entry>
	</comment>
	<sample type="To be analyzed">
		<id></id>
		<name></name>
		<preparedBy></preparedBy>
	</sample>
	<xrdMeasurement measurementType="Scan" status="Completed" sampleMode="Reflection">
		<comment>
			<entry>PHD Lower Level = 4.02 (keV), PHD Upper Level = 12.07 (keV)</entry>
		</comment>
		<usedWavelength intended="K-Alpha 1">
			<kAlpha1 unit="Angstrom">1.5405980</kAlpha1>
			<kAlpha2 unit="Angstrom">1.5444260</kAlpha2>
			<kBeta unit="Angstrom">1.3922500</kBeta>
			<ratioKAlpha2KAlpha1>0.5000</ratioKAlpha2KAlpha1>
		</usedWavelength>
		<incidentBeamPath>
			<radius unit="mm">240.00</radius>
			<xRayTube id="1010048" name="Empyrean Cu LFF HR (9430 033 7310x) DK420743">
				<tension unit="kV">45.0</tension>
				<current unit="mA">30.0</current>
				<anodeMaterial>Cu</anodeMaterial>
				<focus type="Line">
					<length unit="mm">12.0</length>
					<width unit="mm">0.4</width>
					<takeOffAngle unit="deg">6.0</takeOffAngle>
				</focus>
			</xRayTube>
			<sollerSlit id="21010001" name="Soller slits 0.02 rad.">
				<opening unit="rad">0.0200</opening>
			</sollerSlit>
			<mask id="22030010" name="Fixed mask 20 mm">
				<width unit="mm">20.00</width>
			</mask>
			<antiScatterSlit id="22010003" name="Fixed slit 1Â°" xsi:type="fixedAntiScatterSlitType">
				<height unit="mm">1.52</height>
			</antiScatterSlit>
			<divergenceSlit id="22010012" name="Programmable divergence slit" xsi:type="fixedDivergenceSlitType">
				<distanceToSample unit="mm">140.00</distanceToSample>
				<angle unit="deg">0.5</angle>
			</divergenceSlit>
		</incidentBeamPath>
		<diffractedBeamPath>
			<radius unit="mm">240.00</radius>
			<antiScatterSlit id="22090010" name="AS slit 8.0 mm (PIXcel)" xsi:type="fixedAntiScatterSlitType">
				<height unit="mm">8.00</height>
			</antiScatterSlit>
			<sollerSlit id="21010001" name="Soller slits 0.02 rad.">
				<opening unit="rad">0.0200</opening>
			</sollerSlit>
			<filter id="20030001" name="Large beta-filter Nickel">
				<material>Ni</material>
				<thickness unit="mm">0.020</thickness>
			</filter>
			<detector id="7010019" name="PIXcel1D-Medipix3 detector" xsi:type="rtmsDetectorType">
				<phd unit="%">
					<lowerLevel>25.0</lowerLevel>
					<upperLevel>75.0</upperLevel>
				</phd>
				<mode>Scanning</mode>
				<activeLength unit="deg">3.3482</activeLength>
			</detector>
		</diffractedBeamPath>
		<scan appendNumber="0" mode="Continuous" scanAxis="Gonio" status="Completed">
			<header>
				<startTimeStamp>2022-05-14T02:56:19+02:00</startTimeStamp>
				<endTimeStamp>2022-05-14T05:56:45+02:00</endTimeStamp>
				<author>
					<name>User</name>
				</author>
				<source>
					<applicationSoftware version="5.5a">Data Collector</applicationSoftware>
					<instrumentControlSoftware version="8.1b 20190506">EMPYREAN</instrumentControlSoftware>
					<instrumentID>0000000011159748</instrumentID>
				</source>
			</header>
			<dataPoints>
				<positions axis="2Theta" unit="deg">
					<startPosition>9.99846514</startPosition>
					<endPosition>99.99342261</endPosition>
				</positions>
				<positions axis="Omega" unit="deg">
					<startPosition>4.99923257</startPosition>
					<endPosition>49.99671130</endPosition>
				</positions>
				<positions axis="Z" unit="mm">
					<commonPosition>8.912</commonPosition>
				</positions>
				<commonCountingTime unit="seconds">386.070</commonCountingTime>
				<intensities unit="counts">7955 7951 8184 8428 8254 8254 8050 8123 8046 8208 8098 8242 8260 8415 8346 8216 8377 8341 8184 8123 8177 8220 8147 8271 8119 8096 8186 8002 8262 8090 8042 8120 8056 7984 7999 8117 8125 7926 8009 7988 7951 8061 8107 7960 8014 8107 8077 8103 7984 8107 8032 8162 8060 8015 7888 7979 7999 8188 8111 8114 8157 7969 8109 8195 8127 8148 8195 8388 8498 8467 8473 8503 8523 8642 8772 8616 8614 8849 8936 8785 8959 9283 9289 9644 9788 10127 10720 11667 12447 13860 16302 20007 25418 35128 48758 63151 76425 78670 71690 59756 43796 30280 20732 15127 11858 10432 9459 9246 9062 8883 8736 8565 8553 8378 8459 8395 8087 8217 8358 8354 8124 7860 8249 8186 8243 8182 8286 8202 8221 8081 7991 8055 8117 8159 8173 8261 8267 8318 8175 8334 8400 8425 8240 8320 8337 8301 8338 8202 8462 8514 8614 8289 8391 8276 8447 8479 8354 8158 8428 8363 8481 8615 8567 8290 8471 8580 8492 8643 8529 8315 8212 8279 8584 8419 8730 8775 8423 8400 8346 8553 8517 8524 8350 8366 8518 8490 8389 8506 8301 8380 8342 8506 8504 8313 8355 8310 8450 8321 8469 8332 8297 8536 8384 8352 8497 8497 8193 8357 8493 8246 8187 8249 8450 8330 8369 8358 8662 8325 8313 8234 8194 8371 8366 8423 8256 8496 8375 8258 8305 8266 8358 8219 8438 8425 8372 8526 8335 8138 8130 8178 8221 8304 8229 8035 8258 8583 8421 8183 8169 8066 8067 8125 8180 8197 8196 8329 8194 8262 8074 8120 8225 8201 8189 8245 8247 8170 8246 8187 8124 8312 8109 7981 8240 8051 8028 8020 8009 8262 8285 8360 8432 8175 8367 8087 8395 8686 8342 8147 8407 8278 8076 8320 8232 8249 8027 8022 8107 8125 8230 8159 8215 8106 8115 8097 7998 8255 8119 8033 7900 8244 8109 8153 8152 8354 8367 8227 8184 8184 8234 8168 8047 8210 8046 8106 8286 8078 8059 8073 8137 8177 8198 8242 8028 8268 8148 8249 8315 8241 8453 8397 8617 8854 9179 9525 9715 9731 9843 9594 9306 8901 8623 8568 8448 8271 8335 8244 8071 8150 8027 8088 7962 8016 8057 7954 8006 8085 8038 8071 7952 8053 7836 8090 8068 8108 7775 8005 8193 8059 8148 8211 8064 7974 7913 7941 7888 8005 7946 8062 7913 7938 7946 7847 8026 7970 7943 7895 8054 7906 8080 8032 7967 8003 7975 8034 7994 8122 8000 7860 8005 7835 7996 7941 8110 8046 7859 7868 7867 7940 7866 7782 7683 8000 7738 7880 7941 7979 7929 7960 7823 8047 7911 7827 7780 7936 7973 8079 7870 7936 7922 7963 7893 7734 7929 7763 7962 7876 7945 7972 7877 7733 7933 8075 8064 7986 7895 7888 7918 7829 8031 8083 8015 7995 7804 7865 7876 8058 7830 7927 7744 7811 7694 7733 7793 7700 7720 8015 7863 7940 7930 7824 7718 7934 7946 7855 8023 7827 7855 7843 7681 7788 7707 7907 7813 7718 7819 8003 7777 7926 7854 7885 7777 7644 7838 7884 7644 7771 7769 7980 7662 7763 7645 7779 7612 7871 7891 8293 8244 8119 8196 8338 8295 8023 7978 7982 7889 7917 7754 7891 7843 7723 7924 7867 7712 7847 7627 7493 7644 7608 7585 7616 7713 7663 7770 7626 7671 7675 7743 7704 7781 7563 7547 7440 7659 7447 7567 7369 7745 7621 7490 7721 7498 7706 7648 7669 7645 7557 7652 7662 7504 7496 7592 7660 7696 7430 7669 7674 7530 7541 7537 7467 7440 7647 7433 7596 7658 7654 7637 7476 7640 7788 7479 7586 7643 7636 7612 7454 7651 7690 7489 7525 7491 7495 7628 7413 7645 7657 7526 7835 7651 7572 7434 7485 7569 7455 7330 7439 7297 7503 7359 7604 7572 7561 7308 7605 7435 7503 7336 7287 7342 7385 7483 7471 7416 7519 7452 7304 7574 7383 7374 7542 7299 7359 7480 7463 7315 7319 7352 7403 7274 7387 7499 7329 7513 7722 7482 7368 7343 7471 7399 7417 7506 7461 7519 7499 7411 7350 7217 7332 7322 7440 7423 7324 7372 7426 7563 7450 7343 7411 7317 7419 7275 7487 7329 7449 7320 7382 7583 7381 7437 7310 7404 7361 7554 7460 7475 7185 7401 7395 7504 7493 7644 7562 7725 7820 7685 7845 7686 7820 7949 7749 7660 7785 7679 7614 7824 7604 7612 7797 7865 7889 7718 7737 7660 8015 7852 7547 7678 7631 7699 7805 7712 7971 8040 8343 8352 8507 8507 8704 8702 8782 8873 8951 9316 9883 10525 11699 13456 15849 19357 25613 35481 49291 65229 81160 91143 89691 81413 70647 60372 47550 34904 25475 18536 14171 11814 10586 9818 9459 9067 9075 8723 8491 8271 8228 8222 8190 8089 8009 8010 7992 8123 7959 7949 8016 7739 7671 7793 7797 7782 7594 7733 7795 7558 7666 7460 7706 7693 7734 7737 7565 7668 7482 7564 7583 7498 7598 7683 7721 7729 7569 7702 7607 7531 7346 7693 7546 7509 7642 7574 7432 7543 7436 7580 7663 7490 7696 7487 7607 7447 7570 7607 7758 7543 7636 7606 7484 7502 7566 7706 7611 7678 7513 7520 7400 7599 7606 7533 7550 7458 7360 7462 7411 7576 7702 7480 7481 7249 7393 7544 7519 7456 7805 7644 7575 7536 7504 7464 7349 7607 7468 7478 7442 7614 7855 7731 7587 7486 7604 7718 7578 7555 7482 7438 7408 7455 7523 7528 7709 7524 7633 7641 7636 7494 7626 7539 7446 7457 7487 7481 7548 7656 7571 7466 7375 7559 7713 7447 7597 7503 7601 7635 7719 7846 7692 7585 7551 7620 7587 7454 7532 7467 7658 7636 7509 7564 7574 7488 7504 7444 7299 7362 7365 7436 7469 7556 7418 7390 7509 7533 7476 7438 7610 7721 7452 7755 7736 7624 7872 7710 7705 7748 7812 8012 8069 8340 8359 9002 9496 10726 12501 15603 20649 26504 32138 34368 32202 29281 26708 23969 20526 16787 13155 10907 9293 8716 8249 8096 8170 7861 7747 7703 7744 7696 7772 7613 7454 7586 7524 7674 7620 7693 7558 7566 7473 7609 7587 7462 7498 7409 7530 7410 7555 7551 7505 7569 7585 7662 7810 7556 7584 7629 7787 7747 7684 7803 7634 7751 7645 7696 7569 7688 7754 7783 7565 7657 7649 7599 7385 7562 7670 7658 7737 7782 7747 7594 7807 7768 7734 7842 7751 7696 7988 8136 8439 8337 8510 9028 9891 11355 14054 17918 23647 28746 30189 28275 25496 23435 22150 19752 16317 13640 11403 10115 9175 8876 8663 8643 8622 8679 8523 8870 9139 9726 10681 12481 15668 20983 28203 35280 37370 33764 29970 27635 26110 22945 18669 14951 12027 10188 9000 8622 8298 8086 8212 8087 7981 8016 8077 8178 8091 7902 7832 7924 7804 7807 7581 7732 7563 7562 7578 7567 7407 7371 7399 7367 7283 7349 7494 7617 7430 7275 7391 7480 7570 7661 7514 7366 7335 7399 7437 7291 7604 7501 7477 7489 7489 7544 7325 7162 7422 7301 7473 7454 7309 7338 7325 7430 7440 7394 7368 7389 7384 7350 7564 7282 7304 7288 7468 7479 7414 7484 7614 7470 7507 7537 7606 7644 7720 7668 7345 7451 7586 7433 7425 7411 7384 7345 7368 7248 7318 7337 7309 7211 7342 7334 7155 7281 7333 7412 7328 7364 7463 7501 7423 7407 7405 7319 7417 7247 7419 7428 7314 7381 7331 7444 7308 7345 7314 7317 7445 7410 7462 7408 7289 7344 7405 7491 7455 7300 7454 7387 7322 7266 7624 7470 7471 7374 7374 7309 7416 7238 7462 7192 7393 7294 7326 7322 7297 7160 7264 7258 7368 7112 7319 7169 7203 7202 7202 7270 7344 7357 7265 7255 7210 7120 7279 7335 7191 7283 7173 7195 7152 7161 7055 7073 7247 7221 7291 7216 7243 7180 7259 7245 7077 7259 7231 7206 7089 7196 7283 7077 7014 7170 7172 7276 7305 7086 7237 7211 7071 7088 7360 7277 7238 7457 7333 7376 7399 7296 7435 7301 7461 7539 7435 7555 7654 7516 7577 7469 7484 7464 7521 7402 7487 7465 7515 7387 7449 7493 7517 7609 7631 7432 7249 7455 7270 7361 7408 7426 7377 7414 7343 7380 7414 7303 7558 7492 7588 7447 7449 7328 7471 7495 7608 7574 7412 7410 7518 7603 7624 7828 7724 7762 7781 8146 8385 8413 8458 8511 8778 9056 9285 9477 9728 10270 10770 11481 12407 14039 16367 20253 26253 36260 50494 67097 81817 88062 84919 76109 67529 61570 57594 50388 41683 32452 24383 18361 14771 12792 11076 10347 10124 9477 9315 8913 8663 8443 8483 8095 8111 7948 7999 7912 7769 7821 7877 7883 8205 8195 8632 8810 9049 8644 8499 8595 8576 8594 8384 8279 8158 7999 7801 7838 7783 7603 7570 7661 7689 7634 7742 7681 7854 7740 7867 7948 7756 7919 8079 8043 8249 8499 8741 9239 9849 11251 13547 18368 26145 35177 40722 38780 33151 27843 25869 26488 25829 22570 18095 14029 11449 9652 9164 8885 8832 8954 9118 9388 10031 10920 12052 12953 13754 14417 14275 14720 15646 16399 16048 14479 13107 11913 11456 10950 10725 9817 8693 8283 8009 7641 7679 7544 7539 7463 7408 7430 7460 7389 7223 7138 7192 7176 7250 7198 7201 7181 7266 7207 7371 7347 7154 7382 7100 7223 7302 7012 7103 7210 7312 7180 7038 7239 7092 6944 7098 6930 6876 6982 7155 6983 6986 7010 7106 6919 6883 7100 6954 6906 6909 7065 6938 7124 7315 7029 7101 7261 7005 7225 7084 7013 6951 6949 6964 7012 7180 6991 7056 6946 7012 6889 7070 7045 7043 7020 7050 6777 7046 6906 6904 7020 6843 7105 6879 7050 6908 7122 6916 7073 7111 6910 6898 6986 7051 7125 6908 6906 6973 6881 6870 7031 6770 6866 7071 6974 6854 6919 7109 7023 7146 7085 6837 6923 6897 6969 7015 6824 6880 6848 6941 6997 7053 6946 6901 6786 6831 6783 6904 6946 6989 6782 7058 6898 6943 7060 6875 6885 7086 6912 6846 6809 7037 6858 6819 6846 6754 6847 6844 6816 6931 6966 6919 6982 7005 6885 6949 6847 6702 6911 6833 6774 7028 6868 6907 6881 6914 6915 6775 6878 6935 6916 7028 6870 7069 6859 6700 6564 6871 6979 6814 6712 7047 7002 6811 6937 6906 6925 6561 6852 6961 6686 6684 6756 6699 6934 6780 6937 6992 7053 6933 6705 6993 7089 6982 6835 6928 6876 6965 6940 7015 6722 6962 6964 6824 6837 6771 6924 7019 6832 6793 6982 7037 6927 6945 6932 7016 6858 6938 6796 6862 6835 7000 7013 6847 6732 6729 7127 7002 6622 6614 6869 6929 6898 7019 7075 6980 7136 7233 7096 6996 7224 7311 7260 7261 7339 7600 7448 7575 7699 7870 8182 8615 9763 11883 15006 20158 25570 28555 26730 22925 19621 18047 18180 18788 18158 15593 13005 11082 9550 8596 7972 7684 7457 7554 7651 7240 7195 7101 7232 7092 7009 6904 6998 6980 7025 6777 6836 6855 6888 6869 7025 6892 6966 7019 6916 6928 7007 6961 6902 7057 7003 6949 6947 7047 7029 7281 7475 7336 7598 7814 8501 9126 10487 11695 13626 14623 14899 14429 12811 11760 11662 11356 11601 11129 10415 9506 8842 8622 8440 8053 7877 8029 7724 7693 7489 7417 7428 7375 7303 7095 7223 7270 7177 7284 7438 7636 8219 9144 10309 12180 13516 13722 12867 11682 10412 10120 10521 10653 10250 9497 8701 8068 7695 7379 7069 6932 6906 6885 6922 6900 6854 6944 6641 6762 6720 6665 6629 6751 6672 6700 6669 6747 6759 6792 6908 6651 6936 6757 6856 6803 6744 6760 6671 6720 6830 6831 6800 6945 7045 7061 7091 7425 7676 8065 9071 9929 10916 11561 11383 11008 10360 9769 9600 9645 9380 9145 8870 8224 7882 7804 7364 7558 7771 7560 7533 7284 7205 7248 7017 7056 7186 7204 7007 6793 6789 6780 6715 6827 6651 6683 6920 6660 6656 6573 6476 6587 6606 6730 6567 6687 6767 6529 6601 6474 6470 6770 6614 6602 6503 6673 6567 6765 6647 6585 6559 6534 6446 6517 6684 6519 6643 6761 6635 6598 6530 6458 6544 6665 6611 6688 6645 6471 6593 6552 6334 6438 6490 6520 6552 6429 6546 6536 6528 6535 6520 6646 6504 6715 6721 6512 6762 6660 6721 6638 6748 6649 6741 6740 6772 6691 6697 6796 6849 6860 7038 7049 7220 7637 8700 9511 10088 9830 9258 8485 8028 8171 8293 8418 8134 7840 7627 7056 7044 6851 6961 6774 6566 6712 6715 6599 6506 6561 6613 6640 6660 6765 6639 6557 6561 6530 6681 6482 6618 6741 6651 6659 6548 6542 6643 6657 6548 6432 6482 6695 6571 6582 6454 6654 6626 6561 6593 6528 6638 6633 6498 6603 6565 6581 6402 6463 6415 6595 6510 6629 6616 6382 6412 6552 6514 6666 6577 6537 6393 6304 6558 6618 6539 6617 6790 6509 6651 6720 6785 6929 6721 6979 7167 7411 7690 7795 7389 7280 7284 7519 7595 7862 8127 8731 9502 10583 11700 12459 12694 12666 12567 12347 12064 11932 11535 11049 10704 10010 9499 9100 8694 8229 7655 7440 7149 7067 6715 6695 6788 6863 6785 6717 6782 6867 6815 6788 6599 6757 6691 6557 6417 6639 6656 6717 6478 6579 6498 6424 6608 6690 6514 6587 6579 6368 6520 6660 6475 6595 6562 6592 6553 6519 6455 6442 6629 6501 6529 6535 6347 6450 6524 6485 6306 6414 6553 6311 6518 6316 6481 6612 6404 6436 6259 6211 6402 6407 6503 6502 6483 6622 6293 6334 6370 6411 6321 6568 6538 6590 6543 6570 6512 6569 6405 6527 6337 6349 6391 6562 6627 6474 6570 6834 6803 6897 6881 7090 7469 8065 8930 9491 9902 9239 8490 7804 7670 7749 8000 8246 7983 7808 7328 6925 6874 6835 6682 6474 6648 6362 6470 6477 6383 6405 6496 6516 6498 6439 6585 6373 6210 6372 6310 6415 6436 6513 6602 6396 6495 6520 6528 6426 6285 6450 6434 6620 6277 6335 6403 6286 6433 6564 6460 6286 6572 6372 6380 6584 6331 6444 6503 6590 6506 6659 6507 6448 6474 6635 6632 6695 7062 7068 7174 7217 7481 6979 6927 7015 7005 7099 7091 7059 7186 7308 7411 7873 8214 8749 9077 9218 9182 8783 8277 7921 7910 8005 7811 7970 7878 7560 7309 7027 6908 6594 6588 6545 6528 6556 6659 6440 6521 6345 6192 6391 6409 6439 6337 6503 6386 6312 6498 6459 6450 6502 6595 6297 6349 6451 6447 6452 6403 6478 6627 6471 6569 6624 6665 6716 6892 7283 7522 7889 8219 8215 7930 7700 7519 7702 7960 8597 8961 9595 10454 11223 11714 11879 12233 12123 11437 11309 10919 10360 10110 9767 9473 9294 8954 8507 7997 7564 7213 7083 6884 6721 6723 6580 6641 6776 6650 6478 6321 6346 6430 6440 6475 6320 6368 6361 6259 6552 6430 6494 6404 6373 6626 6538 6433 6407 6503 6376 6394 6343 6524 6524 6344 6460 6401 6303 6401 6373 6429 6562 6445 6370 6323 6362 6363 6422 6487 6503 6570 6473 6515 6363 6448 6367 6445 6377 6368 6488 6416 6479 6415 6472 6411 6420 6474 6498 6403 6456 6385 6428 6443 6508 6348 6309 6291 6386 6314 6352 6402 6215 6331 6391 6397 6378 6391 6392 6379 6214 6419 6410 6437 6207 6335 6394 6572 6422 6414 6297 6452 6412 6504 6209 6210 6324 6278 6331 6232 6466 6181 6281 6305 6216 6319 6155 6346 6269 6396 6326 6429 6334 6274 6407 6289 6320 6301 6192 6324 6211 6472 6426 6410 6396 6279 6357 6267 6410 6506 6253 6237 6290 6306 6336 6263 6424 6300 6408 6318 6208 6351 6487 6591 6387 6373 6358 6433 6501 6436 6382 6511 6504 6640 6865 7371 7563 7971 8056 7774 7709 7512 7282 7038 7122 7341 7187 7116 7076 7019 6919 6654 6690 6520 6560 6717 6390 6372 6515 6387 6533 6439 6314 6162 6490 6424 6231 6340 6473 6332 6434 6434 6471 6363 6508 6544 6493 6603 6580 6463 6627 6440 6390 6509 6589 6441 6374 6378 6643 6519 6344 6289 6526 6395 6379 6399 6575 6606 6468 6656 6445 6615 6615 6592 6807 6932 6889 7016 7007 6807 6878 6843 6974 7363 7503 7706 7888 8605 9355 10879 12117 13003 13462 12937 11969 11033 9996 9401 9532 9841 10075 10085 9745 8933 8683 7920 7245 7124 6743 6681 6658 6643 6508 6603 6433 6554 6361 6342 6451 6614 6494 6457 6495 6316 6322 6354 6412 6304 6385 6411 6420 6540 6427 6347 6410 6378 6175 6224 6278 6426 6371 6432 6368 6188 6438 6290 6391 6466 6530 6401 6407 6220 6331 6343 6548 6453 6275 6253 6183 6253 6280 6481 6569 6393 6566 6404 6423 6266 6394 6461 6394 6336 6305 6307 6422 6263 6345 6453 6396 6658 6507 6615 6543 6535 6592 6865 6639 6912 6925 6775 6927 6926 7038 7105 7290 7302 7682 8185 8971 10430 12636 15594 18266 19775 20159 18837 16463 14491 12863 12050 12346 13201 13800 13665 12916 11929 10422 9466 8380 7781 7600 7111 6943 6932 6777 6610 6864 6562 6592 6733 6539 6565 6553 6592 6364 6482 6538 6483 6363 6482 6507 6325 6359 6329 6470 6532 6430 6518 6567 6310 6279 6465 6291 6276 6366 6397 6254 6451 6534 6499 6269 6390 6318 6313 6439 6373 6214 6309 6473 6566 6514 6568 6450 6461 6200 6402 6339 6341 6342 6312 6265 6339 6462 6459 6498 6309 6461 6462 6471 6640 6283 6503 6602 6779 6715 6510 6551 6614 6609 6646 6957 7022 7091 7396 7897 8780 9769 11668 13621 14950 14711 13186 11545 10299 9444 8941 9447 10157 10643 10874 10388 9576 8645 8156 7588 7347 7311 7124 7011 7012 6848 6757 6784 6871 6805 6624 6718 6770 6798 6763 6804 6894 6943 6879 6908 6849 7025 6962 6933 7085 7288 7614 7659 7920 8167 8899 9577 10601 11838 13591 15448 16787 17563 17916 16603 15170 13677 12852 12095 12233 12446 12828 12854 12567 11572 10534 9785 8819 8382 7787 7355 7300 7163 7113 6879 6901 6857 6903 6965 6900 7019 7284 7434 7696 8027 7977 8020 7848 7738 7727 7801 7803 7809 7968 7926 7728 7674 7390 7206 7052 7115 7049 7124 6902 6762 6809 6953 6850 6702 6573 6666 6655 6695 6731 6845 6949 6842 6971 7052 7146 7163 7312 7477 7635 7945 8298 8716 9504 11202 12666 14534 15650 16115 15757 14664 13697 12825 12600 12886 13790 14322 14717 13859 12943 11646 10527 9802 9546 8995 9014 8899 8814 8196 7720 7502 7037 7102 6954 6991 6824 7033 7059 6774 6874 6903 6879 7077 7061 7018 7209 7160 7302 7447 7705 8173 8487 9447 10657 12457 14692 17164 18996 19262 18097 16196 14205 12262 11475 11273 11802 12485 13385 13445 12622 11618 10504 9226 8408 7868 7453 7058 7033 6981 6867 6740 6776 6895 6676 6616 6573 6601 6534 6643 6521 6567 6823 6610 6631 6661 6568 6622 6508 6616 6530 6598 6623 6852 7125 7141 7577 7916 8547 9045 9192 8879 8383 8060 7804 7460 7537 7584 7877 8119 8263 8149 8269 8224 8499 8573 8805 9254 9114 8811 8407 8332 7850 7636 7645 7601 7610 7764 7892 7920 7654 7398 7192 7122 6917 6797 6697 6605 6616 6542 6613 6353 6510 6597 6535 6357 6490 6387 6487 6437 6445 6441 6370 6643 6589 6474 6343 6576 6335 6496 6308 6493 6565 6526 6497 6474 6407 6540 6776 6580 6643 6723 6787 7038 7301 7733 8428 9573 11234 13012 14281 14073 12415 11057 9618 9149 8835 8884 9886 10892 12050 12357 11943 10679 9775 8890 8147 7978 8077 8046 8313 8527 8641 8455 7957 7905 7194 6968 7073 6831 6860 7130 7064 6883 6987 6811 6937 6625 6470 6363 6299 6323 6454 6438 6454 6527 6351 6357 6399 6558 6326 6266 6402 6476 6233 6418 6333 6349 6237 6330 6288 6500 6451 6410 6752 6776 6795 6997 7638 8179 8036 7997 7542 7035 6729 6614 6624 6623 6699 7045 7244 7233 7053 6893 6598 6707 6563 6392 6342 6415 6549 6316 6291 6464 6403 6326 6476 6331 6146 6201 6262 6263 6236 6250 6328 6331 6362 6281 6075 6142 6275 6096 6245 6309 6227 6136 6278 6211 6264 6206 6477 6216 6354 6423 6393 6462 6521 6491 6257 6453 6410 6266 6303 6371 6319 6295 6430 6368 6273 6252 6261 6345 6155 6105 6300 6188 6226 6265 6270 6162 6248 6360 6324 6209 6470 6462 6295 6228 6164 6160 6132 6204 6354 6144 6267 6206 6372 6233 6233 6473 6453 6329 6431 6406 6553 6296 6373 6360 6284 6429 6210 6401 6362 6279 6275 6330 6409 6177 6406 6270 6297 6331 6273 6329 6154 6062 6029 6188 6273 6242 6367 6066 6164 6151 6221 6218 6093 6208 6344 6163 6179 6318 6237 6121 6198 5983 6223 6287 6261 6141 6285 6202 6293 6155 6126 6226 6170 6124 6427 6218 6311 6225 6209 6176 6353 6325 6213 6179 6192 6110 6225 6301 6255 6303 6345 6275 6364 6312 6172 6154 6262 6190 6112 6445 6314 6173 6218 6355 6231 6193 6208 6344 6337 6355 6309 6187 6229 6227 6166 6379 6216 6280 6229 6149 6227 6412 6202 6323 6526 6322 6386 6658 6705 6992 7195 7706 8003 8213 8152 7915 7558 7251 6984 6842 6842 6869 7055 7255 7269 7371 7273 7108 6918 6967 6749 6759 6616 6615 6808 6791 6825 6878 6895 7457 7370 7638 7978 8376 8712 9286 10026 10786 11554 12377 12547 12077 11651 10547 9845 9324 9151 8869 9054 9139 9423 9560 9409 9004 8534 8442 7752 7449 7269 7237 7273 7264 7188 7292 7175 7198 7156 6875 6813 6712 6769 6840 6728 6805 7088 7147 7125 7573 7867 8614 9070 9786 9664 9375 8764 8091 7423 7366 7366 7357 7612 7754 8162 8316 8391 8247 7996 7570 7394 7272 7578 7834 8042 8745 9478 10077 10345 10466 10022 9211 8489 7857 7655 7483 7711 8013 8225 8373 8380 8289 8165 7843 7310 7340 7060 7019 7118 7170 7095 7253 7019 6866 6958 6852 6761 6714 6582 6613 6734 6718 6830 6617 6574 6463 6480 6531 6541 6538 6540 6445 6416 6384 6381 6307 6238 6168 6210 6400 6317 6371 6344 6388 6543 6571 6357 6300 6293 6238 6332 6592 6263 6382 6479 6540 6472 6503 6535 6564 6478 6794 6988 7138 7230 7564 7740 7876 8139 8533 8830 9377 10008 10438 10960 11399 11336 11250 11074 10839 10371 9808 9426 9301 9171 8750 8820 8921 9121 8980 8673 8400 8155 7948 7396 7093 6961 6799 6918 6675 6548 6493 6501 6345 6390 6351 6344 6380 6370 6359 6242 6296 6230 6404 6426 6272 6168 6136 6321 6267 6438 6522 6410 6372 6455 6419 6482 6444 6594 6738 6784 6942 6957 7073 7064 7244 7313 7346 7411 7552 7512 7548 7546 7482 7667 7872 7997 8428 8738 9128 9795 9602 9540 9102 8579 8289 8019 8045 8293 8503 9242 9618 10863 11307 12083 12158 11985 11278 10547 9978 9043 8699 8189 8395 8520 8883 9049 9244 9299 9225 8979 8805 8663 8816 8685 9345 9586 9959 9907 9659 9232 8688 8347 7787 7685 7501 7579 7734 7936 8221 8270 7993 7774 7594 7342 6998 6650 6615 6592 6666 6547 6441 6609 6564 6523 6572 6433 6437 6515 6437 6501 6573 6485 6680 6861 6822 7015 7455 7641 8108 8915 9750 10980 11869 12579 12480 11651 10704 9634 8748 8237 7814 8034 8029 8700 9085 9188 9529 9292 8780 8207 7778 7395 7051 6677 6653 6597 6585 6421 6376 6395 6424 6402 6417 6280 6164 6244 6260 6375 6193 6350 6272 6340 6309 6293 6259 6415 6404 6492 6661 6756 7002 7260 7711 8014 8429 8783 9105 8956 8359 8070 7362 7305 7131 7177 7147 7471 7594 8090 8034 7910 7681 7382 7256 6952 6773 6388 6528 6521 6396 6499 6413 6516 6535 6720 6653 6521 6492 6421 6250 6340 6405 6668 6573 6455 6759 6750 6745 6751 7004 7107 7228 7610 7854 8631 9281 10308 11153 11885 12377 12637 12713 12289 11953 11425 11016 10391 10273 10207 10270 10453 10865 11264 10996 11172 10924 10425 9810 9112 8418 8092 7815 7483 7206 7238 6920 7330 7187 7188 7046 6720 6749 6511 6517 6444 6522 6352 6139 6271 6154 6199 6041 6046 6167 6131 6134 6197 6102 6269 6178 5974 5964 5982 6027 5999 6095 6186 6118 6206 6035 6051 5933 6027 6118 6168 5880 6008 6204 6168 6077 5982 6047 6366 6156 5974 5905 6111 6024 5975 5996 6171 6103 6178 6055 5970 6226 5995 6000 5948 6058 6022 6023 6017 6043 6059 5885 6224 6138 6077 6008 5899 6027 6136 6154 5809 6169 6061 6123 6077 6209 6031 5987 6156 6023 6073 6033 6014 6077 6132 6093 5988 5983 5965 5922 5944 6126 6104 5972 5932 6007 6054 6108 6205 6264 6259 5986 6081 6109 6085 6092 6179 6236 6164 6207 6196 6508 6189 6405 6238 6363 6504 6666 6724 6850 7161 7356 7679 8286 8802 9085 9343 9028 8706 7955 7633 7280 7058 6851 7082 7219 7247 7400 7707 7784 7761 7621 7004 6768 6753 6759 6605 6412 6293 6492 6207 6263 6413 6345 6106 6127 6027 6151 6120 6289 6271 6197 6190 6089 6121 6107 6251 6010 6096 6102 6040 5904 6135 5853 6021 5924 6046 6129 5916 6043 6014 5927 6039 6064 5965 5874 5952 6069 5925 6012 6138 6072 6125 6301 6235 6179 6072 6162 6217 6333 6413 6372 6506 6665 6704 6935 7104 6984 7037 7144 7016 6899 6730 6586 6420 6302 6570 6608 6555 6834 6826 6780 6650 6598 6414 6546 6470 6143 6227 6123 6098 6207 6112 6073 6229 6057 5871 5931 6060 5989 5936 6168 6039 5996 5783 6048 6056 5985 6152 6006 6006 5892 6018 5936 6042 6081 6070 5861 6026 5966 6156 6046 6097 6075 5994 5951 5971 6202 6093 6052 6134 5989 6066 6040 6142 6082 6215 6115 6033 6196 6113 6086 6034 6166 6218 6079 6103 6153 6073 6168 5857 6126 5942 6106 6053 6019 5990 5931 5980 5903 5893 5931 6033 6059 5864 5808 5886 5991 5959 5877 6009 5895 5853 5818 5918 5868 6043 5980 5919 5883 5795 5820 5885 5805 6043 5963 6074 5978 5956 6013 6014 6111 5869 5997 5996 6034 5836 6050 5925 5972 6025 6185 6098 5992 5880 6066 5985 6114 6053 5886 5936 6078 6127 6258 6364 6261 6202 5996 6151 6074 6052 6041 5925 6099 5962 6060 6075 5947 6067 6236 6153 5984 6159 5880 5933 5884 5793 5972 6050 5987 5915 5826 5854 5943 5893 5904 5982 5910 5757 5977 5916 5937 5947 5844 5921 5895 5914 5838 6027 6008 5863 6001 5972 6126 5868 5892 6065 6055 5968 5830 5935 6035 5962 6024 6259 6045 6165 6182 6020 6009 5864 5747 5973 5975 5847 6109 5874 5902 6068 6089 5967 6016 6003 5722 6019 5951 5939 6089 5906 5898 6013 5855 5912 5928 5930 5949 6060 6123 5929 6019 5997 5968 6153 6167 5929 5954 5937 6015 5874 5987 5959 5926 6077 5949 5757 5855 5917 5895 5704 5937 5864 5938 5945 6047 6060 5800 6085 6084 5973 5979 5990 6027 5929 5889 5899 5864 6026 6117 6021 6106 5889 5896 5959 5991 5966 5969 5914 6161 5804 6053 6099 5954 6064 6039 5949 5946 6006 5945 5962 5736 5859 5943 5824 5837 5891 5909 5914 5891 5967 6002 5888 5927 5881 5865 5969 5920 6105 5897 6076 5884 5774 5961 5857 5960 6316 6068 6026 5975 6127 6240 6071 6032 6111 6351 5968 6073 6314 6322 6287 6369 6430 6496 6750 6647 6712 6980 7169 7393 7749 8143 8609 9251 9256 9285 8925 8392 7803 7479 7293 7031 7053 7033 7096 7109 7450 7598 7731 7920 7767 7732 7391 7299 7418 7325 7200 7366 7165 6913 6852 6679 6731 6865 6927 6982 7079 7426 7624 7858 8114 8248 8268 8395 8399 8453 8480 8245 7791 7496 7238 7053 7120 6966 6937 7135 6938 6983 7028 7148 7315 7122 7021 6799 6607 6380 6374 6193 6264 6159 6142 6053 6141 5965 5950 5954 6073 5911 5897 6047 6076 5955 5857 5865 6026 6011 5904 6069 6051 6057 5959 6025 6178 6223 6029 5958 5959 6010 6052 6102 6005 6172 6334 6319 6252 6285 6204 6096 6230 6161 5986 6004 6185 5934 6164 6362 6290 6356 6325 6528 6642 6382 6531 6604 6655 6638 6574 6568 6679 6384 6311 6457 6438 6335 6301 6262 6354 6377 6534 6490 6590 6554 6670 6712 6485 6364 6366 6238 6206 6011 6065 6117 6231 6129 6024 6079 6238 6111 6057 5993 5984 6118 6246 6096 5960 6001 6074 6025 6087 6194 5960 5989 6215 6279 5837 5932 6016 6206 6029 6153 5960 6017 5995 5918 5987 6133 5934 6091 6149 6028 6031 6068 6054 5957 5992 5896 6060 6186 6274 6170 6297 6489 6537 6374 6537 6530 6526 6563 6371 6552 6454 6623 6728 6853 6864 6710 6828 6993 7330 7821 7874 8077 8377 8543 8450 8597 8228 7873 7951 7739 7373 7040 6912 6922 6892 6890 6888 7164 7019 7255 7190 7113 6905 6859 6566 6468 6541 6246 6117 6261 6087 5947 6066 6125 5998 5888 5997 5844 5910 5987 5801 5865 5954 6012 5952 6065 6151 6165 6280 6512 6637 6667 6465 6434 6278 6169 6205 6222 6095 6049 6058 5966 6212 6032 6018 6116 6268 6085 6241 6100 6179 6096 6067 6022 6146 6073 6045 6097 5994 5790 5938 5921 5960 6268 6232 6173 6214 6097 6124 6207 6206 6167 6064 6098 6046 6010 6110 6198 5971 6061 6299 6170 6171 6143 6198 6192 6247 6500 6384 6487 6599 6992 6927 7159 7334 7312 7544 7295 7387 7180 6886 6707 6661 6446 6576 6446 6381 6484 6529 6614 6587 6736 6657 6703 6628 6432 6541 6399 6357 6274 6384 6512 5983 6186 6117 6117 6169 6081 6134 5921 6059 5889 6096 6156 6131 6268 6222 6245 6274 6208 6194 6128 6242 6352 6138 6016 6067 6242 6292 6308 6263 6457 6464 6649 6584 6770 6921 7075 6750 6747 6719 7047 7242 7300 7584 7932 8031 8044 8047 7768 7379 7209 7088 7068 6607 6480 6497 6595 6652 6520 6551 6731 6956 6728 6815 6900 6849 6412 6268 6116 6213 6161 6192 6170 6108 5899 6050 6058 6169 6055 6037 5970 6189 6035 5859 5980 5841 5912 5965 5857 6009 5977 5853 5892 6060 5997 5860 5903 6074 6060 5864 5977 5836 5854 6057 5979 5938 5817 5838 5864 5823 5751 5910 5861 5849 5568 5877 5829 5720 5849 5841 5763 5782 5830 5849 5889 5724 5712 5858 5918 5955 5860 5914 5831 5826 6070 5764 5772 5928 5844 5836 5984 6001 5863 6130 6111 6034 6186 6018 6188 6364 6277 6110 6108 6129 6033 5923 5908 5951 6032 5867 5918 5946 5974 6075 5966 6038 6019 6187 6150 6135 6103 6094 5932 5945 5894 5932 5889 5970 5939 5987 6036 5897 5849 5849 5923 5844 6167 6139 6002 6163 6159 5989 6061 6274 6082 6052 6120 6005 6116 6011 6041 6080 6052 5967 6008 5960 6209 6115 6120 6130 6046 6126 5985 5989 6165 5996 5883 6064 6047 6101 6171 5945 6012 6193 6401 6452 6436 6621 6823 7203 7390 7657 7721 7858 7812 7704 7514 7464 7663 7446 7306 7119 6990 6783 6801 6712 6477 6819 6968 7049 7207 7069 6951 6730 6820 6898 6604 6610 6325 6255 6343 6388 6448 6503 6364 6740 6755 7000 7004 7023 6824 6841 6672 6546 6459 6382 6123 6140 6106 6000 6300 6153 6196 6557 6641 6391 6533 6701 6855 6878 6615 6416 6488 6232 5909 6055 6008 6056 5852 5749 5998 5990 6010 5715 5904 6292 5986 6123 6113 6125 6226 6198 6111 5949 5942 6009 5969 5882 5696 5843 5730 5918 5854 5807 5772 5772 5754 5726 5814 5748 5854 5836 5949 5831 5819 5953 5882 5974 5855 5970 5813 5774 5809 5802 5954 5804 5880 5890 5757 6078 5825 5867 5858 5855 5763 5953 5820 5935 5698 5724 6016 5942 5854 5834 5905 5933 5887 5926 6107 5982 6183 6162 5945 6055 6002 5959 5914 5964 5851 6049 6007 5949 6031 6134 6099 6073 5961 5992 6031 6019 6198 6074 6081 6142 6114 6127 6248 6189 6168 6478 6425 6340 6301 6315 6371 6290 6381 6568 6454 6634 6825 6963 6874 6855 6981 6897 6835 6657 6500 6457 6498 6439 6574 6296 6530 6644 6493 6575 6516 6687 6714 6804 6725 6614 6530 6500 6411 6378 6257 6098 6252 6232 6287 6518 6637 6782 6763 6995 7159 7276 7431 7492 7195 7192 7002 6919 6647 6542 6387 6324 6388 6414 6379 6343 6480 6426 6516 6602 6795 6673 6599 6575 6605 6367 6184 6103 6255 6035 6048 5978 6045 6143 6154 6091 6245 6227 6177 6056 5893 6068 6146 6010 5808 6115 5890 6047 6048 6012 6099 6185 6173 6254 6256 6217 6184 6267 6132 6184 6039 6155 6138 5884 6014 6059 6045 5948 6007 6035 5886 5946 6053 6165 6251 6166 6297 6458 6565 6442 6678 6787 6630 6864 6664 6558 6605 6489 6344 6431 6307 6307 6279 6466 6526 6658 6731 6754 6725 6756 6769 6905 6788 6576 6707 6775 6776 6549 6548 6468 6631 6520 6573 6546 6514 6457 6355 6329 6389 6316 6214 6249 6153 6336 6320 6429 6285 6405 6430 6482 6306 6414 6388 6504 6482 6628 6832 6643 6710 6781 6914 6861 6846 6696 6651 6579 6523 6421 6365 6288 6185 6187 6177 6177 6360 6233 6365 6515 6383 6623 6240 6207 6167 6205 6100 6072 6016 6005 5957 5942 6121 6095 6122 5869 5994 6039 5905 5912 5956 6073 6108 6050 5968 5841 5947 5991 6064 5964 5808 5910 5920 6033 6131 5983 6008 5921 5986 5785 5844 5940 6009 6080 5879 5996 5858 5881 5938 5985 6055 6142 6042 6121 6258 6367 6324 6402 6383 6503 6429 6444 6429 6285 6414 6335 6208 6091 6118 6060 5964 6255 6330 6434 6522 6225 6361 6440 6411 6451 6441 6569 6577 6457 6422 6458 6555 6402 6590 6857 6768 6674 6610 6580 6727 6392 6331 6385 6231 6214 6349 6212 6196 6253 6194 6154 6173 6198 6209 6311 6216 6185 6165 6189 6119 5930 6021 5999 6024 5920 5820 5903 6011 5764 5832 5880 5941 5913 5955 5968 5833 5939 5851 5939 5856 5835 5908 5738 5893 5756 5885 5767 5855 5853 5723 5773 5711 5783 5934 5756 5722 5877 5887 5759 5806 5897 5657 5664 5836 5858 5976 5884 5801 5762 5765 5765 5849 5701 5768 5712 5748 5844 5818 5869 5829 5816 5660 5693 5845 5766 5788 5864 5939 5820 5729 5712 5720 5848 5862 5884 5727 5711 5822 5869 5931 6016 5979 5991 6010 5896 5864 5825 5979 5865 5764 5772 5774 5972 5762 5803 5807 5694 5845 5931 6026 5877 5941 5776 6021 5967 5817 5821 5830 5817 6062 6179 6108 6149 6299 6395 6333 6364 6327 6413 6497 6392 6395 6289 6090 6094 6118 6095 5893 5888 5989 5974 6057 6004 6114 6043 5971 5928 6197 6289 6108 6037 6140 6133 5997 6006 5969 5860 5912 5826 5925 5874 5926 6096 5964 5886 5874 5957 5721 5915 6041 5869 5753 5727 5687 5753 5910 5907 5798 5746 5866 5973 5865 5750 5819 5840 5911 5894 5860 5891 6116 5961 5830 5893 6068 6001 6085 6164 5967 6018 5869 5880 5830 5952 5829 5866 5837 5784 5770 5782 5904 5754 5908 5766 5829 5998 6011 5817 6038 5914 5730 5822 5752 5820 5898 5714 5772 5746 5708 5787 5755 5905 5853 5781 5832 5892 5618 5843 5870 5989 5861 5885 5766 5700 5758 5844 5740 5689 5751 5729 5619 5674 5921 5900 5819 5837 5773 5970 5933 6010 6221 6131 6048 6225 6303 6235 6212 6304 6353 6466 6602 6612 6644 6579 6479 6498 6372 6427 6330 6156 6148 6226 6038 6258 6190 6347 6469 6547 6408 6560 6862 6790 7073 7115 6929 6848 6685 6641 6425 6299 6192 6338 6163 6192 6287 6075 6150 6324 6344 6441 6527 6540 6694 6817 6792 7020 6834 6728 6766 6324 6455 6430 6225 6062 6167 6262 6218 6175 6021 6063 6180 6036 6025 6101 6154 6181 6221 6197 6141 6179 6018 6251 6260 5997 6054 6086 6042 6083 6032 6003 5874 5825 5847 5934 5686 5959 5938 6025 5990 6059 6173 5979 6021 6031 6224 5928 6041 5855 5923 5844 5873 5901 5879 6010 5808 5889 6085 6132 5962 6245 5931 6092 6158 6107 6253 6250 6161 6392 6287 6391 6576 6607 6767 6835 6591 6607 6424 6364 6245 6112 6304 6107 6033 6087 6143 6167 6245 6197 6122 6035 6265 6441 6387 6371 6486 6510 6536 6666 6578 6429 6496 6504 6315 6349 6108 5998 6028 6043 5959 5793 5882 5918 5776 5996 6098 6200 6239 6128 6381 6392 6432 6518 6439 6695 6668 6717 6690 6452 6591 6474 6363 5995 6149 6309 6205 6185 6173 6246 6099 6038 5960 6039 6214 6055 6137 6146 6361 6440 6387 6548 6539 6684 6679 6459 6504 6460 6438 6222 6250 6283 6153 6133 6058 6046 6237 6427 6240 6343 6220 6303 6355 6410 6701 6802 6741 6796 6920 6936 7138 7068 6969 7095 7093 6880 6639 6683 6311 6394 6374 6299 6136 6214 6195 6206 6157 6108 6040 6273 6319 6381 6485 6443 6396 6284 6411 6383 6253 6286 6078 6146 6074 5837 5851 5867 5864 5675 5750 5773 5700 5725 5771 5890 5872 5888 5887 5815 5920 5677 5790 5835 5625 5647 5561 5682 5721 5628 5706 5839 5740 5701 5638 5688 5790 5775 5656 5689 5527 5817 5721 5651 5810 5731 5700 5918 5722 5922 5758 5762 5774 5951 5937 5978 5941 5905 5881 5855 5712 5591 5787 5717 5757 5929 5937 5927 5601 5851 5676 5844 5618 5831 5789 5636 5815 5748 5719 5843 5745 5808 5769 5805 5988 5780 5683 5786 5729 5781 5866 5905 5877 5837 5684 5773 5850 5810 5894 5887 6054 5833 6075 6023 5749 6028 6039 6001 6008 6207 6043 6197 6062 6027 6100 6042 6011 6089 6057 6070 5964 6081 5967 6019 5962 5971 6043 6089 6013 6023 6161 6017 6131 6022 6154 6151 6054 6195 6126 6200 6155 6302 6305 6179 6431 6270 6129 6253 6256 6208 6065 6048 6155 6041 6241 6263 6232 6203 6165 6288 6478 6609 6727 6833 6736 6893 6861 6917 7004 7135 6864 7156 7056 6766 6771 6842 6448 6483 6299 6439 6284 6069 6249 6308 6252 6228 6247 6258 6299 6377 6509 6419 6224 6263 6438 6293 6297 6112 6244 6162 6069 5979 5914 5968 6157 5943 5822 5877 5768 5930 5834 5851 5749 5941 5770 5807 5876 5950 5707 5975 5807 5693 5713 5758 5880 5857 5790 5952 5971 5736 5702 5771 6012 5754 5832 5905 5943 5849 5930 5941 5754 5863 6001 5972 5746 5722 5856 5904 5816 5958 5820 5865 5892 5778 5767 5679 5885 6008 5879 5717 5767 5955 5743 5583 5776 5752 5731 5848 5736 5888 5918 5686 5826 5829 5745 5653 5592 5643 5719 5795 5656 5594 5685 5905 5680 5849 5827 5870 5821 5799 5788 5778 5845 5826 5831 5910 6086 6077 5869 5874 6106 5992 6101 6163 6238 6431 6168 6373 6584 6334 6373 6389 6287 6051 6207 6147 6171 6008 6000 6163 5952 5982 6058 5983 5894 6017 6008 6151 5967 5877 6015 6036 6091 6088 5944 5986 5935 5797 5888 5874 5996 5864 6035 5917 5793 5832 5850 5735 5805 5810 5752 5905 5764 5791 5821 5935 5931 5734 5889 5982 5992 5969 5907 5965 6078 6199 6128 6168 6058 5982 6289 6279 6148 6227 6357 6213 6248 6246 6198 6435 6284 6374 6301 6229 6557 6435 6510 6408 6357 6456 6324 6189 6399 6222 6093 6273 6209 6198 6291 6378 6409 6492 6629 6494 6421 6545 6616 6404 6310 6230 6257 6181 6385 6144 6313 6351 6529 6573 6586 6343 6320 6227 6324 6132 6131 6149 6128 6279 6017 6036 5890 5859 5920 5974 5890 6045 5970 6007 6044 6061 6231 6186 6142 6155 6397 6107 6524 6349 6335 6259 6385 6263 6285 6240 5960 6028 6301 6188 6063 6027 6009 5900 5971 5901 5905 5808 5799 5921 5949 5868 5888 6030 5914 5824 6037 6060 6010 5920 5836 5783 5943 5933 5992 6033 5873 5761 5731 5621 5816 5830 5846 5664 5696 5752 5786 5834 5654 5732 5792 5586 5606 5645 5568 5641 5757 5633 5690 5766 5713 5807 5699 5773 5834 5582 5656 5746 5585 5761 5739 5579 5840 5729 5779 5699 5667 5749 5818 5763 5672 5731 5886 5867 5839 5772 5825 5878 5769 5792 5786 5932 6084 5889 5904 5781 5820 5900 5776 5692 5678 5799 5743 5937 5853 6081 6091 6009 6243 6054 6296 6455 6516 6549 6424 6648 6428 6499 6257 6239 6152 6109 5966 5901 6030 5906 5803 5936 5930 5993 5840 5863 5978 5866 6030 5981 6152 5983 6160 6162 6177 6077 6212 6055 5985 6021 5947 5839 5887 5821 5994 5775 5872 5874 5679 5801 5622 5831 5809 5631 5832 5835 5781 5780 5635 5732 5792 5739 5885 5735 5849 5745 5948 5816 5807 5817 5777 5808 5766 5689 5924 5815 5806 5845 5974 5769 5996 5923 5745 5738 5851 5753 5762 5734 5645 5910 5821 5886 5856 6030 6020 6036 5970 6219 6098 6218 6270 6216 5944 6200 6064 5977 6025 6083 5963 5892 5874 5838 5908 5861 5909 6009 5928 5883 6009 5906 6110 6151 6171 6116 6224 6103 6290 6240 6100 5910 5911 5999 5960 5932 6040 5919 5850 6071 5835 5963 5831 5832 5843 5947 5953 5730 5850 5802 5859 5990 6027 5955 5790 5762 5710 5799 5804 5842 5837 5727 5592 5531 5540 5617 5640 5719 5692 5692 5776 5522 5525 5559 5635 5691 5499 5615 5580 5663 5738 5819 5775 5777 5623 5568 5750 5597 5717 5796</intensities>
			</dataPoints>
			<nonAmbientPoints type="Temperature" unit="K">
[...]
			</nonAmbientPoints>
		</scan>
	</xrdMeasurement>
</xrdMeasurements>