File: powder_X-ray_diffraction/room_temperature_experiments/NaTaO2F2/raw_data/NaTaO2F2_rt.xrdml
<?xml version="1.0" encoding="UTF-8"?>
<xrdMeasurements xmlns="http://www.xrdml.com/XRDMeasurement/1.7" xmlns:xsi="http://www.w3.org/2001/XMLSchema-instance" xsi:schemaLocation="http://www.xrdml.com/XRDMeasurement/1.7 http://www.xrdml.com/XRDMeasurement/1.7/XRDMeasurement.xsd" status="Completed">
	<comment>
		<entry>Configuration=Reflection-transmission Spinner, Owner=User-1, Creation date=12/01/2015 16:50:12</entry>
		<entry>Goniometer=Theta/Theta; Minimum step size 2Theta:0.0001; Minimum step size Omega:0.0001</entry>
		<entry>Sample stage=Reflection-transmission spinner; Minimum step size Phi:0.1</entry>
		<entry>Diffractometer system=EMPYREAN</entry>
		<entry>Measurement program=C:\PANalytical\Data Collector\Programs\Ouail\lent_135.xrdmp, Identifier={73BE8ABF-D663-43FC-B999-33872D7EC5FC}</entry>
		<entry>Batch program=C:\PANalytical\Data Collector\Programs\Batch_nuit1.xrdmp, Identifier={C02E4D90-D25A-499F-A0A1-2D3538350A60}</entry>
	</comment>
	<sample type="To be analyzed">
		<id>NaTaO2F2_ss1_5-135_tamisé</id>
		<name></name>
		<preparedBy></preparedBy>
	</sample>
	<xrdMeasurement measurementType="Scan" status="Completed" sampleMode="Reflection">
		<comment>
			<entry>PHD Lower Level = 4.02 (keV), PHD Upper Level = 12.07 (keV)</entry>
		</comment>
		<usedWavelength intended="K-Alpha 1">
			<kAlpha1 unit="Angstrom">1.5405980</kAlpha1>
			<kAlpha2 unit="Angstrom">1.5444260</kAlpha2>
			<kBeta unit="Angstrom">1.3922500</kBeta>
			<ratioKAlpha2KAlpha1>0.5000</ratioKAlpha2KAlpha1>
		</usedWavelength>
		<incidentBeamPath>
			<radius unit="mm">240.00</radius>
			<xRayTube id="1010048" name="Empyrean Cu LFF HR (9430 033 7310x) DK434948">
				<tension unit="kV">45.0</tension>
				<current unit="mA">30.0</current>
				<anodeMaterial>Cu</anodeMaterial>
				<focus type="Line">
					<length unit="mm">12.0</length>
					<width unit="mm">0.4</width>
					<takeOffAngle unit="deg">6.0</takeOffAngle>
				</focus>
			</xRayTube>
			<sollerSlit id="21010001" name="Soller slits 0.02 rad.">
				<opening unit="rad">0.0200</opening>
			</sollerSlit>
			<mask id="22030010" name="Fixed mask 20 mm">
				<width unit="mm">20.00</width>
			</mask>
			<antiScatterSlit id="22010003" name="Fixed slit 1°" xsi:type="fixedAntiScatterSlitType">
				<height unit="mm">1.52</height>
			</antiScatterSlit>
			<divergenceSlit id="22010012" name="Programmable divergence slit" xsi:type="fixedDivergenceSlitType">
				<distanceToSample unit="mm">140.00</distanceToSample>
				<angle unit="deg">0.5</angle>
			</divergenceSlit>
		</incidentBeamPath>
		<sampleMovement xsi:type="spinningSampleMovementType">
			<spinnerRevolutionTime unit="seconds">4.0</spinnerRevolutionTime>
		</sampleMovement>
		<diffractedBeamPath>
			<radius unit="mm">240.00</radius>
			<antiScatterSlit id="22090010" name="AS slit 8.0 mm (PIXcel)" xsi:type="fixedAntiScatterSlitType">
				<height unit="mm">8.00</height>
			</antiScatterSlit>
			<sollerSlit id="21010001" name="Soller slits 0.02 rad.">
				<opening unit="rad">0.0200</opening>
			</sollerSlit>
			<filter id="20010004" name="Beta-filter Nickel">
				<material>Ni</material>
				<thickness unit="mm">0.020</thickness>
			</filter>
			<detector id="7010019" name="PIXcel1D-Medipix3 detector" xsi:type="rtmsDetectorType">
				<phd unit="%">
					<lowerLevel>25.0</lowerLevel>
					<upperLevel>75.0</upperLevel>
				</phd>
				<mode>Scanning</mode>
				<activeLength unit="deg">3.3482</activeLength>
			</detector>
		</diffractedBeamPath>
		<scan appendNumber="0" mode="Continuous" scanAxis="Gonio" status="Completed">
			<header>
				<startTimeStamp>2023-01-19T17:16:37+01:00</startTimeStamp>
				<endTimeStamp>2023-01-20T00:47:09+01:00</endTimeStamp>
				<author>
					<name>User</name>
				</author>
				<source>
					<applicationSoftware version="5.5a">Data Collector</applicationSoftware>
					<instrumentControlSoftware version="8.2  20201204">EMPYREAN</instrumentControlSoftware>
					<instrumentID>0000000011159748</instrumentID>
				</source>
			</header>
			<dataPoints>
				<positions axis="2Theta" unit="deg">
					<startPosition>5.01676514</startPosition>
					<endPosition>134.99343336</endPosition>
				</positions>
				<positions axis="Omega" unit="deg">
					<startPosition>2.50838257</startPosition>
					<endPosition>67.49671668</endPosition>
				</positions>
				<positions axis="Phi" unit="deg">
					<commonPosition>353.8</commonPosition>
				</positions>
				<commonCountingTime unit="seconds">676.770</commonCountingTime>
				<intensities 24080 24217 23859 23984 23673 23903 24047 23966 23875 23725 23647 23947 23679 23891 23548 24034 23714 23636 23547 23601 23772 23432 23452 23548 23433 23309 23600 23654 23520 23257 23350 23266 23424 23521 23104 23360 23159 23496 23513 23403 23330 23238 23240 23336 23406 23456 23216 23380 23308 23432 23237 23634 23188 23202 23608 23520 23131 23200 23471 23514 23089 23588 23081 23254 23301 23030 23103 23371 23123 23504 23437 23259 23480 23273 23731 23281 23306 23401 23512 23395 23416 23137 23321 23022 23243 23008 23328 23109 23101 23294 23306 23216 23027 23141 22887 23445 23090 23146 23167 22961 23118 22976 23197 22840 23079 22908 22941 23065 23031 23070 22987 22964 22828 22989 23095 22843 22824 22747 22741 23000 22833 22628 22675 22814 22887 22691 22430 22611 22827 22813 22598 22635 22653 22612 22516 22599 22283 22345 22803 22116 22248 22343 22298 22146 22381 22378 22358 22218 21996 22096 21893 22153 21734 21703 21736 21634 21892 21795 21933 21907 21381 21525 21262 21301 21256 21287 21387 21089 21418 21280 21076 20976 21052 20922 20783 20808 20670 20735 21019 20650 20490 20581 20501 20573 20240 20414 20115 20106 19857 19984 20366 20145 20148 20096 20248 19888 20072 20044 20103 19693 19225 19606 19700 19479 19375 18983 19145 19074 18905 19299 18897 19009 18940 18728 18607 18637 18605 18502 18477 18478 18904 18768 19063 19383 19045 19395 19758 20279 20757 21498 23136 26251 33055 44763 64395 90792 127369 165547 168664 122733 65786 33621 23431 21067 20114 19656 18945 18410 18178 17847 17781 17634 17351 17499 17145 17296 17028 17132 16907 16967 16672 16742 16648 16866 16552 16467 16550 16538 16376 16289 16253 16383 16305 15978 16078 15973 16241 16016 16059 15779 15798 15858 15714 15781 15871 15386 15662 15487 15508 15448 15545 15251 15447 15607 15242 15112 15350 15090 15150 14648 15138 15144 14981 14914 14930 14737 14875 14896 14691 14466 14641 14696 14743 14657 14625 14481 14389 14543 14461 14272 14284 14510 14437 14113 14369 14378 14087 14138 14050 13993 14079 13937 14064 14059 13751 14004 14072 13809 13889 13892 13879 13530 13686 13795 13550 13732 13834 13885 13540 13806 13482 13404 13568 13575 13545 13570 13810 13552 13446 13493 13513 13370 13385 13173 13269 13370 13218 13246 13226 13216 13110 13138 13089 13135 12862 13207 13037 13092 12940 12939 13072 12972 13015 12814 12836 12642 12872 13136 12799 12878 12743 12869 12618 12902 12773 12648 12674 12829 12805 12806 12550 12633 12728 12754 12765 12619 12446 12312 12296 12725 12433 12464 12231 12422 12475 12286 12307 12215 12388 12213 12328 12243 12302 12355 12099 12392 12323 12290 12049 12219 12210 12085 11920 12268 12171 12026 12184 12131 12103 12335 12473 12560 12503 12138 12279 12166 12150 11943 12106 11748 11875 11613 11819 11769 11968 11686 11761 11749 11755 11566 11769 11849 11756 11845 11767 11734 11690 11537 11677 11731 11758 11848 12182 12431 12447 12218 11918 11666 11617 11528 11357 11365 11426 11518 11528 11422 11093 11475 11296 11455 11780 11886 12048 12118 11609 11278 11497 11131 11408 11186 11126 11252 11194 11279 11044 11113 11259 11052 11115 11013 11016 11101 11082 11076 11207 10947 11052 11206 11203 11020 11118 11342 11558 11602 11551 11298 11333 11104 10984 10920 10895 10834 10714 10983 10725 10892 10877 10859 11155 11393 11456 11864 12029 11981 12156 11954 11890 11997 12192 12369 12510 12608 12844 13372 13860 14328 14976 15349 16534 18369 22388 31789 52395 93413 167955 270375 336832 298831 207210 116802 55191 29693 21706 18308 16381 14796 13423 12960 12334 11757 11923 11965 11684 11799 11869 12003 12089 11843 11675 11500 11023 10941 10908 10876 10824 10715 10889 10762 10659 10756 10767 10829 10543 10707 10571 10706 10453 10583 10428 10512 10466 10514 10463 10465 10310 10278 10418 10261 10359 10473 10160 10151 10091 10576 10197 10318 10136 10320 10000 10090 10160 10301 10172 10296 10128 10345 10238 9892 10051 10244 10158 10103 10272 10317 10473 10501 10720 10837 11038 11010 10823 10733 10563 10400 10461 10519 10523 10334 10372 10502 10601 10897 11655 13629 18236 27867 42678 50996 44598 34714 24134 15441 11950 10927 10646 10288 10234 9867 10059 10071 10048 9973 9926 9957 9775 9795 9605 9843 9577 9730 9548 9543 9688 9368 9515 9645 9538 9450 9373 9396 9568 9473 9562 9546 9679 9671 9935 9740 9798 9961 9798 9827 9868 10030 10224 10087 10136 10187 10430 10319 10207 10325 10658 10678 11088 11272 11883 12277 12593 12918 13554 15118 18572 27587 49029 87276 128099 131961 105999 78583 51408 33107 33626 52178 85823 123852 136529 112217 83112 53497 29476 17391 13578 12259 11668 11030 10381 10057 9941 9809 9701 9772 9599 9476 9666 9691 9586 9808 10088 9947 10017 9718 9415 9377 9263 9443 9496 9387 9272 9417 9291 9376 9363 9362 9306 9322 9219 9090 9208 9097 9123 9172 8786 9002 9067 9139 9091 9040 8948 8928 9098 9130 9150 9247 9324 9952 10188 10244 10192 9934 9594 9416 9190 8740 8832 8866 8746 8927 8922 8906 9020 9084 8861 8596 8777 8809 8651 8854 8951 8894 8490 8850 8719 8715 8691 8775 9067 9162 9207 9351 9232 9458 9444 9307 9406 9413 9301 9504 9678 9648 9608 9531 9459 9431 9554 9603 9519 9798 10022 10307 10767 11159 11626 12153 12990 14007 15681 18431 24214 35779 62332 113735 188296 239352 216073 168360 130587 83347 42275 24726 17819 15208 13220 11864 11046 10338 9931 9823 9322 9463 9355 9153 9587 9720 9992 10299 10323 10163 9878 9775 9459 9412 9175 8993 9162 9000 9179 9038 8960 9152 8888 8987 8908 9136 8952 9049 9134 9372 9517 9741 9932 10024 10362 10653 11287 12095 13866 19119 31667 55899 86168 92799 72724 60610 51414 37549 33798 41388 50244 47694 38066 30965 24053 16366 11775 10057 9600 9064 9089 8766 8510 8473 8427 8598 8487 8663 8504 8630 8494 8387 8162 8287 8229 8286 8537 8403 8436 8324 8382 8235 8225 8305 8187 8071 8294 8117 8426 8136 8098 8215 7934 8190 7994 7895 7953 7977 7988 8031 7907 7807 7847 7749 8022 7983 7937 7963 8015 8046 7934 7801 7866 7733 7879 7739 7718 7801 7797 7639 7789 7696 7786 7727 7713 7705 7625 7653 7620 7637 7682 7749 7533 7717 7765 7738 7805 7814 7742 7734 7808 7853 7736 7936 7766 7853 7792 7668 7984 7744 7930 7958 7961 8098 8019 8032 8061 8150 8091 8022 8090 7901 7903 8010 8014 7987 8115 8368 8492 8554 8903 9479 9767 10432 12390 18328 32846 52519 55936 41800 35079 33365 24304 14761 11555 11052 10885 11052 11689 12798 15803 25023 44896 77797 97980 83775 63816 59050 47378 28304 16797 12897 11403 10893 10381 10486 10587 11050 11805 13047 15762 21197 33293 54336 77732 92316 92111 82238 67280 52191 38030 25340 16075 12052 10344 9599 9045 8853 8648 8210 8334 8216 7926 8036 7952 7928 7992 7844 7931 8014 7975 7907 7980 8267 8440 8501 8938 9737 11137 15329 23736 35189 38165 30642 25153 24312 19979 13645 10145 9011 8522 8523 9184 9843 10299 9247 8839 8821 8214 7839 7670 7473 7533 7504 7273 7457 7427 7349 7405 7190 7207 7283 7075 7355 7337 7358 7221 7209 7356 7360 7255 7262 7268 7236 7211 7139 7198 7224 7333 7302 7215 7487 7721 7701 7607 7659 7545 7474 7332 7310 7511 7234 7597 7468 7615 7607 7657 7781 8123 8702 11183 16759 24319 25093 19216 16831 17431 15011 11061 8715 8100 7597 7540 7504 7492 7299 7374 7287 7237 7370 7377 7286 7373 7290 7464 7712 7685 8038 8185 8908 10101 12920 18226 24162 25436 22677 19493 17881 15828 12981 10120 8547 8233 8882 9712 10156 9242 8566 8777 8250 7935 7329 7175 6926 6834 6999 7023 6926 6817 6819 6819 6922 6717 6894 6787 6768 6835 6788 6784 6936 6855 6709 6944 6817 6813 6874 6787 6814 6820 6712 6824 6840 6862 6721 6551 6668 6858 6854 6764 6881 6800 6766 6907 6757 6722 6869 6788 6760 6800 6650 6705 6827 6752 6664 6792 6811 6903 6555 6808 6793 6834 6753 6869 6832 6902 7060 7094 7544 8377 9850 11982 13498 12805 11332 10508 10763 9869 8735 8042 8068 8061 8620 10006 12703 16716 20373 18921 15789 15121 15771 15712 16940 21294 24803 21260 16321 15642 16165 13808 10608 8724 7738 7703 7491 7186 7124 7031 6968 7100 7081 7264 7080 7378 7365 7674 7968 8429 9022 10199 12601 17396 23822 28276 27980 24895 27036 35861 41881 37915 27861 25465 32175 40732 41647 33803 24553 21377 21857 19548 13919 10035 8405 7749 7451 7215 7036 7003 6809 6920 6801 6917 6719 6890 6740 6801 6606 6588 6693 6554 6538 6804 6620 6560 6604 6740 6615 6654 6580 6594 6560 6546 6669 6715 6660 6595 6612 6541 6609 6572 6519 6677 6509 6449 6608 6710 6711 6595 6679 6676 6837 6698 6645 6554 6561 6477 6727 6606 6590 6575 6559 6554 6563 6637 6573 6510 6533 6654 6569 6611 6743 7049 7672 8155 9100 9119 8398 7810 7968 7954 7427 6944 6582 6652 6742 6610 6480 6579 6417 6563 6561 6375 6536 6446 6493 6424 6531 6665 6898 7332 7531 7781 7995 9104 9781 9490 8306 7920 8051 8150 7624 7194 6933 6922 6844 7361 7621 8384 9851 12099 14673 15167 13103 11255 11112 11119 10269 8664 7560 7204 7016 6751 6700 6769 6669 6438 6512 6546 6488 6479 6444 6461 6459 6596 6515 6543 6628 6569 6471 6869 6858 7060 7283 7158 7402 7915 8962 12289 19404 26829 25496 17531 13644 15904 17670 14443 10250 8012 7201 7098 6938 6837 6656 6912 7003 6800 7028 7193 7460 8628 11556 15785 17664 14571 10944 10910 12266 11844 9828 8017 7220 7039 6900 6824 6732 6824 6799 6753 6637 6631 6593 6668 6726 6731 6614 6930 6759 6942 6768 6965 7149 7468 7511 7748 8519 9959 12988 17316 21163 20217 15868 13389 13597 14536 13042 10548 8602 7893 7530 7631 7763 8107 8482 8356 8628 9239 9660 10721 12307 15414 21439 32320 47388 55916 48722 36447 31840 33654 33986 27318 19036 13759 11371 10094 9406 8904 8878 8778 9223 10043 13001 19121 26982 32541 35674 33748 28712 24624 22496 22415 19969 15714 12225 10270 10398 12240 16816 25371 32879 31177 22672 17857 19002 21238 19408 14297 10497 8978 8061 7705 7440 7451 7331 7134 7061 7062 7220 7396 8023 8931 9160 8681 7953 8013 8594 9002 8894 8585 8287 8310 8179 8008 8046 8189 8331 8435 8680 9129 9543 10567 12396 16819 26556 40555 51068 46067 34653 30115 33252 36485 31935 22567 16386 13547 12426 11131 9625 8905 8449 8416 8432 8478 8695 9176 10185 12236 15626 21155 27244 30306 27363 20868 18116 18681 19532 17220 13239 10239 8772 8035 7568 7488 7276 7033 7088 7042 6895 6961 7072 7046 7137 7092 7150 7333 7500 7508 8110 8311 8633 9257 10570 13294 19325 24818 24777 18045 13323 13607 16103 16272 13889 11403 10640 9887 8714 8084 8060 8249 8158 7494 7363 7071 6780 6893 6996 6875 6882 7072 6862 7171 7084 7441 7461 7554 7785 8053 9160 11424 16743 24204 31279 33129 27725 21123 18303 19519 20563 18744 14482 10752 8628 7859 7816 7699 7925 8205 9536 11223 13627 14794 15136 14764 13253 11790 11526 11188 10646 9904 8517 7890 7353 7069 7070 7283 8074 9410 10769 10944 9753 8682 8414 8793 8984 8627 7932 7135 7232 7299 7278 6903 6823 6668 6867 6848 6717 6723 6511 6486 6319 6451 6617 6557 6459 6496 6346 6492 6423 6650 6509 6600 6917 7033 7370 7332 7533 7432 7303 7138 7027 7054 7106 6880 6931 6579 6642 6617 6541 6608 6578 6459 6519 6471 6772 6550 6565 6520 6562 6605 6670 6693 6709 6807 6783 6891 6903 7009 7175 7114 7386 7662 7880 8283 8980 10398 13218 18060 25552 30323 27493 20755 16524 16967 19328 20009 16851 13081 10571 9506 9308 9798 10152 9608 8812 8257 8617 8639 8670 8737 8798 9520 11490 15787 22083 26924 27339 22316 17084 16513 19547 24402 26806 23514 17740 15213 16256 18124 17785 14961 12252 10760 10937 10741 9827 8645 7842 7578 7467 7604 7595 7666 7932 7914 8211 8501 9442 10865 13510 17570 21982 25358 27476 26973 24715 21709 21558 24514 26971 26267 21298 15769 13065 12972 13370 13001 11126 9787 8850 8584 8410 8306 8596 9176 10827 13352 18355 23441 23020 18306 14414 13802 15098 17865 17546 14336 11162 9570 9588 9975 10029 9495 8523 8036 7909 8084 8080 8165 7990 7774 7717 7980 8250 8881 9725 11177 13934 17427 21048 23168 21462 18163 17028 19793 25705 31409 29680 22628 16579 14367 14996 16920 17024 14824 12922 12670 14985 19356 24230 26011 22341 16794 14289 14433 16190 17300 15395 12490 10393 9450 8801 9075 9307 10370 12900 17233 22988 27560 29248 29506 28997 32627 37837 34931 27868 22693 19903 19506 19974 18067 13714 10511 9014 8264 7827 7441 7433 7222 7315 6901 6927 7025 6869 7128 7160 7343 7236 7590 7722 7980 8474 9292 10955 14131 19341 24791 25192 21081 18252 19520 24984 30449 31379 25506 19021 16247 16918 18893 20162 19198 17140 15633 15247 15252 16300 16162 14843 12613 11112 10559 10396 10293 9631 8849 7517 6920 6904 6532 6630 6728 6574 6509 6474 6369 6446 6310 6400 6513 6551 6464 6292 6337 6128 6317 6316 6265 6318 6433 6302 6282 6191 6221 6398 6394 6422 6433 6650 6655 6373 6276 6226 6260 6328 6485 6402 6289 6315 6123 6153 6129 6156 6350 6170 6147 6107 6148 6225 6280 6185 6068 6012 6261 6054 6026 5992 6106 6120 6039 5975 6259 6180 6116 6244 6000 6217 6236 6210 6171 6290 6301 6449 6498 6470 6611 7086 7603 8121 9179 10528 11408 10854 9358 8447 8121 8405 8649 8981 8510 7736 7094 6886 6862 6855 7167 7742 8683 10343 12105 13819 14211 13917 12939 11335 10566 10522 10629 10649 9972 9182 8209 7281 6854 6564 6349 6225 6105 6126 6140 6149 6174 5985 6096 6058 6210 6078 6165 6233 6305 6246 6458 6570 6806 6594 6699 6677 6603 6746 7010 6965 6970 6628 6431 6333 6254 6314 6374 6349 6265 6236 5935 6024 5977 5984 5936 5989 6062 5933 6079 6148 6009 6200 6017 5970 5853 5935 5910 6033 5998 5981 5858 5949 5881 5789 5925 5927 6000 5898 5992 5813 5974 5912 5945 5991 6003 6059 6227 6477 6492 6456 6315 6335 6436 6624 6864 6716 6572 6350 6137 6181 6096 6254 6167 5940 5878 5963 6019 5803 5812 5905 5910 5958 5883 5833 5744 5901 5779 5852 5857 5782 5812 5860 5867 5843 5944 5846 5841 6030 5905 6088 5977 5977 5997 5913 6114 6232 6106 6260 6831 7724 8500 9101 8520 7388 6760 6526 6835 7281 7525 7461 6842 6598 6352 6244 6383 6449 6911 7162 6919 6709 6729 6701 6929 7168 7275 6789 6810 6632 6574 6638 6606 6719 7024 7538 8846 11556 13638 12552 10047 8059 7443 7343 8659 9628 10103 9109 8176 8189 9374 10646 9808 8386 7371 7007 7255 7483 8284 8387 7951 7332 7272 7536 7951 8578 9305 10356 10875 10591 10177 9817 9872 11153 13968 17310 20264 20404 16863 13328 11293 11283 12651 14146 14352 13302 11885 11155 11440 12459 12513 11387 10596 10152 11609 14426 17194 17440 14788 11414 9559 9106 9592 10724 11681 11293 10079 8855 7880 7559 7203 7344 7337 7616 7754 7651 7292 7224 7438 7467 8118 8840 9725 10564 11462 11982 12561 12496 13370 14933 15754 13840 11579 10302 9987 9759 10047 10538 10435 9148 8222 8058 8825 10283 10594 10104 8680 7777 7368 7326 7805 8477 8852 8464 8128 7750 7625 7877 8407 9123 9537 9880 9656 9144 8247 7814 7640 7737 7929 8147 7987 7681 7214 6784 6434 6512 6482 6600 6559 6523 6575 6564 6752 7052 7527 8262 9626 11289 12193 11205 9599 8207 7656 7771 8217 8875 9216 8861 7979 7476 7274 7405 7864 8794 10337 11326 11735 10394 8843 8183 7988 8496 9521 10245 10219 9343 8638 8121 8683 9717 10723 11614 11690 10866 9572 8631 8237 8284 8672 8986 9050 8883 7959 7435 7071 7027 7052 7282 7926 9400 11531 14073 14788 13700 13897 15166 14669 12579 11117 10899 10906 10484 10258 10422 10313 9161 7811 6918 6624 6512 6284 6067 6083 6032 5988 6063 6120 6092 5950 5913 6007 6088 5923 5893 5956 5823 5827 5921 5863 5839 5900 6007 5973 5862 5949 5958 5974 6138 5911 5802 5856 6020 6013 6076 6162 6114 6290 6021 6197 6155 6339 6391 6370 6330 6341 6337 6230 6435 6514 6594 6714 6919 7214 7228 7276 7526 7323 7262 7054 6993 7331 8044 8849 9837 11280 12504 12922 11959 10710 9405 8207 8349 8549 9131 9550 9425 8787 8128 7490 6893 6825 6737 6762 6617 6554 6339 6489 6339 6665 6754 6972 7316 7625 8539 9642 10988 12403 13072 13267 12346 10829 9492 8748 9115 9536 10032 10315 10428 10021 9603 8995 8191 7435 7124 6772 6610 6747 6979 7162 7042 6940 7091 7257 7897 7848 7605 7148 6771 6673 6584 6715 6809 7015 7121 6956 6669 6561 6799 6745 7194 7715 8457 8862 9424 9485 9389 9227 8617 7904 7740 7913 8172 8626 8959 9324 9574 9649 8756 8320 8105 8044 8291 8737 9779 10795 11378 10929 10691 10077 10281 10618 11132 11410 11666 11436 10776 9695 8958 9034 9309 9522 10080 10842 11924 13156 12734 11489 9685 8721 8359 7999 8393 8729 9595 9531 9032 8489 8195 8182 7825 7701 7428 7138 7173 7173 7348 7667 7916 8425 9113 10193 12219 15309 17648 17946 16660 15262 14639 14460 14701 14689 14735 15173 14840 14165 13984 14369 15260 15173 14906 14029 13277 11803 10660 9732 9586 9839 9964 9874 9532 9422 9022 8705 8482 8888 9321 10209 10753 10901 10348 9940 9913 9957 9776 9918 9040 8871 8592 8403 8050 7914 7860 7620 7493 7129 6808 6492 6419 6334 6461 6474 6507 6413 6458 6282 6279 6403 6606 6831 7080 7563 8024 8516 8709 9024 9146 9095 9271 9749 10340 10785 11101 10522 9830 9220 8870 9059 10004 11929 12621 11859 9942 8606 7826 7287 7136 7271 7880 8436 8440 7849 7057 6713 6705 6659 6552 6661 6545 6276 6271 6296 6250 6330 6217 6290 6245 6361 6359 6180 6232 6284 6295 6334 6579 6639 6780 7060 6907 6825 6868 7009 6922 6986 7000 7146 7460 7786 8531 9362 9467 8913 7901 7355 6921 6711 6819 6910 7410 7741 7532 7301 6681 6437 6207 6220 6229 6322 6084 6334 6375 6484 6503 6512 6419 6248 6257 6007 6159 6193 6114 6134 6147 6336 6194 6167 6279 6319 6276 6464 6056 6088 6061 6062 5930 6103 6177 6097 6329 6224 6158 6151 6200 6367 6347 6482 6729 7250 7416 7611 7750 7888 7956 7580 7329 7406 7706 8363 9080 10160 10574 10612 10398 9857 9497 8979 8654 8778 9196 9599 9888 9701 9641 9118 8735 8175 7576 7202 7057 7172 7241 7021 7118 7077 6648 6649 6316 6316 6367 6205 6297 6374 6579 6688 6838 7255 8053 8429 8606 8098 7604 7276 6957 6884 6909 7076 7141 7591 7685 7821 7818 7788 8611 9164 9052 9113 8785 8430 8247 8208 7914 7942 7639 7939 7971 7911 7704 7491 7582 7189 7317 6995 6882 6950 7069 6993 7147 7348 8078 8633 9031 9296 9163 8878 8398 8749 9343 9863 9854 9418 9112 8724 8722 8547 8184 8324 8467 8773 8951 8801 8483 8079 7831 7721 7462 7300 7228 7168 7210 7564 8011 8644 9571 10282 10814 10601 9649 8465 7493 7051 6977 7203 7615 8017 8395 8562 8411 8197 7825 7981 8421 8805 8935 8684 7891 7392 7090 6815 6697 6923 7017 7448 7640 7640 7386 7069 6845 6824 6699 6724 6781 6941 7441 8414 9609 9872 8920 8134 7594 7318 7476 7881 7908 8650 9080 9306 8735 8103 7539 7020 7089 7235 7513 7638 8131 8334 8847 8802 8515 8380 8148 8112 8063 8302 8359 8437 8526 8727 8926 8764 8523 8520 8178 8215 8008 7937 7689 7613 7514 7354 7227 7406 7508 7735 8214 8624 8837 8534 8120 7753 7992 8367 9121 10013 10808 11564 12168 12173 11445 10585 9407 8780 8495 8670 8975 9251 9586 10105 10624 11478 11833 11879 10758 9294 8489 7986 7535 7451 7543 7576 8029 8694 9007 9023 8726 8486 8122 8258 8021 7839 7400 7464 7162 7308 6929 7172 6894 7026 7185 7054 7249 7174 7391 7468 7508 7532 7405 7055 7231 7192 7266 7464 7632 7953 8111 8163 8400 8788 9236 9741 10150 10283 9944 8913 8030 7785 7652 7504 7271 7384 7625 7989 7959 8199 7595 7147 6840 6608 6381 6273 6236 6263 6268 6239 6146 6137 6085 6102 6085 6124 6022 5925 6087 6005 6134 6001 6080 5997 5999 5951 6173 6183 6380 6351 6559 6537 6875 7240 7758 8478 8949 8804 8473 8052 7632 7545 7536 7372 7298 7398 8037 8167 8155 7902 7889 7779 7705 7937 8148 8418 8847 8772 8163 7846 7562 7607 8053 8494 8533 8493 8209 8129 8197 7841 7345 7080 6859 6679 6923 7005 7222 6740 6743 6487 6649 6433 6248 6088 6123 6162 6089 6190 6051 6086 6153 5958 5998 5886 6087 5964 6072 6081 6071 6101 6033 6063 5984 5906 5964 5982 5984 6170 5888 6040 6081 6101 6240 6198 6117 6188 6179 6285 6415 6492 6535 6657 6620 6641 6557 6431 6348 6462 6695 6629 6839 7252 7518 7813 7935 8057 8047 8216 7793 7983 8237 8858 9771 10301 10147 9164 8483 8027 7986 7931 7876 8326 8748 9504 10279 11049 11067 10271 9580 8931 8598 8342 7824 7763 7775 7982 8360 8713 9107 9146 9354 9029 8689 7864 7460 7101 6789 6671 6622 6791 6796 7174 7002 7049 7008 6724 6632 6376 6337 6398 6318 6426 6191 6489 6331 6450 6413 6534 6859 7133 7434 8098 8896 9482 9789 9517 9462 9352 9253 9485 9922 10675 11429 12323 12980 13402 13527 12737 11814 10835 10164 9483 9229 8918 9010 9311 9478 9789 9669 9244 9484 9007 8790 8768 8871 9057 9114 9090 9722 9900 10148 10029 10128 9963 9737 9248 8695 8703 9001 9613 10099 10245 9507 8947 8769 8679 8322 7899 7714 7402 7253 7265 7294 7472 7612 7339 6822 6812 6644 6571 6532 6565 6676 6748 6517 6658 7112 7075 7403 7512 7623 7809 7808 7462 7189 7106 6793 6554 6698 6699 6968 7014 7194 7206 7117 7087 7350 7146 7229 7252 7443 7537 8041 8430 9001 9593 10159 10292 10180 9795 9236 8468 8076 8014 7906 8267 8514 8627 9141 9521 9516 9679 9617 9323 8809 8575 8178 8084 7795 7470 7222 7095 7064 7332 7221 6936 6943 7039 6889 6685 6706 6538 6602 6239 6294 6159 6271 6080 6133 6155 5982 5887 6124 5987 5959 6036 6033 6035 6053 6111 6264 6262 6519 6193 6329 6353 6091 6324 6096 5938 6008 6105 6133 5967 6082 6018 6167 6305 6366 6329 6349 6371 6109 5963 6042 6108 6121 6162 6001 6148 6109 6270 6229 6262 6540 6612 6443 6274 6186 6204 6173 6222 6264 6308 6514 6531 6742 6840 7078 7029 6723 6838 6928 7085 7224 7761 8315 9318 10523 10931 10108 9303 8823 8456 8170 8006 7720 7454 7416 7437 7698 8084 8294 8453 8153 7764 7463 7081 7019 6844 6723 6660 6362 6261 6299 6170 6045 6329 6029 6153 6274 6239 6337 6199 6346 6475 6841 6966 6830 6873 6630 6528 6300 6160 6155 6141 6147 6227 6216 6362 6511 6383 6573 6417 6491 6441 6324 6279 6315 6367 6399 6469 6896 7227 7975 8572 8709 8239 7627 7246 6993 6954 6718 6742 6911 6940 7146 7339 7722 8447 9015 9180 9621 9843 9797 9535 9082 8781 8293 7845 7616 7541 7499 7522 7809 7988 8186 8663 8917 9387 9319 9082 8734 8467 7984 7703 7481 7098 7086 7020 7102 6812 7152 7396 7476 7754 7906 8173 8633 8270 8420 8207 8032 8029 7565 7329 7412 7344 7256 7191 7372 7167 7358 7434 7365 7312 7340 7297 7235 7051 7053 6894 6963 6915 6806 6468 6648 6665 6557 6436 6602 6461 6793 6880 6833 6944 7092 7494 7740 7838 8298 8564 8994 8870 8364 8121 7899 7566 7392 7560 7540 7453 7460 7552 7824 8044 8196 8393 8499 8094 7854 7414 7378 7215 7076 7094 7261 7091 7206 7246 7377 7278 7297 7006 6805 6743 6677 6494 6229 6547 6456 6465 6608 6626 6731 6754 6876 6830 6752 6863 6761 6584 6788 6709 6629 6471 6522 6351 6375 6427 6577 6562 6652 6893 6926 6985 6867 7227 7288 7257 6815 7013 7265 7260 7338 7387 7608 8080 8496 8364 8562 8043 7939 7573 7151 7170 7245 7116 7167 7229 7404 7318 7621 7789 8031 7890 7904 7984 7275 7123 6684 6757 6558 6397 6504 6500 6481 6419 6499 6657 6678 6602 6707 6735 6505 6503 6415 6238 6511 6588 6491 6485 6533 6646 6406 6658 6492 6626 6777 6697 6763 6631 6542 6681 6611 6560 6560 6375 6241 6485 6432 6447 6463 6280 6421 6410 6428 6457 6366 6511 6472 6341 6550 6288 6423 6280 6476 6361 6400 6542 6496 6688 6461 6581 6630 6649 6576 6534 6742 6847 6815 6615 7038 7046 6936 7156 7182 7275 7663 7869 8127 8535 9072 9348 10230 10857 11071 11088 11197 11029 10986 10899 10624 10327 10106 10007 9697 9699 9479 9344 9761 10214 10896 11164 11396 11556 11709 11065 10799 10447 9708 9367 8743 8467 8280 8020 8107 8210 8239 8356 8239 8437 8283 8380 8057 8087 7741 7527 7550 7371 7390 7286 7270 7242 7331 7395 7613 7928 7737 7843 7952 7626 7561 7288 7172 6862 6864 6798 6907 6805 6684 6660 6761 6989 6928 7209 7055 7004 7059 7086 6995 6807 6746 6758 6766 6990 6997 7106 7211 7193 7202 7178 7180 6914 7011 6812 6737 6859 6748 6671 6732 6948 7018 7023 7173 7393 7499 7707 7881 7894 7789 7507 7303 7038 7150 7002 7163 7275 7347 7641 7870 8139 8333 8636 8838 9023 9286 9156 9124 8892 8549 8661 8402 8475 8301 8365 8226 8302 7984 8037 7930 7756 7996 7955 8021 8126 8215 8175 8344 8604 8725 9111 9529 10004 10358 10477 10150 9944 9504 9307 8885 8851 8904 8662 8358 8150 8004 8023 7775 7913 8208 8510 8392 8667 8667 8624 8635 8576 8262 8473 8582 8732 8810 9276 9347 9647 10500 10811 11776 12032 12209 11902 11742 11651 11556 11771 11505 11593 11717 11562 11826 11583 11171 10948 10810 10914 10957 10933 10774 10245 9895 9916 9471 9562 9220 9098 9288 9319 9126 8804 8505 8343 8284 8200 8064 7899 7706 7568 7197 7378 7279 7473 7488 7611 7481 7751 8122 8467 8734 8901 8833 8825 8364 8329 8195 8087 8057 8096 7989 8074 8231 8327 8411 8291 8519 8395 8657 8791 9134 9397 9525 9929 10525 10937 11381 11298 11009 10715 10446 10174 9923 9683 9627 9424 9275 9253 9460 9722 9923 9994 10373 11071 11510 11780 11855 11508 10634 10226 9683 9437 9323 8952 8807 8569 8736 8722 9004 8906 9186 9455 9477 10002 10039 10237 10359 10237 9893 9804 9859 9635 9691 9648 9675 9790 9647 9405 9378 9260 9113 9127 9123 9350 9535 9583 9769 10055 10437 10863 11449 11796 12655 12620 12518 12238 12040 11921 11325 10955 10535 10718 10577 10642 10621 10877 10675 10501 10733 10778 10944 11113 11150 10997 10933 10439 10060 9913 9688 9621 9506 9208 9126 9109 9153 9040 8837 8938 8879 8509 8417 8133 8116 7989 7728 7792 7457 7504 7501 7334 7313 7204 7201 7388 7245 7403 7272 7131 7341 7298 7128 7275 7173 7265 7173 7202 7212 7190 7199 7316 7432 7669 7827 8085 8232 8895 9319 9589 9186 8874 8273 8017 7886 7752 7593 7668 7637 7735 7739 7880 8014 8023 8247 8365 8581 8706 9120 9499 9481 9428 9319 9435 9241 9352 9975 10179 10313 10388 10358 9831 9529 9455 9200 8784 8670 8473 8340 8451 8115 7945 7954 8150 8082 8219 8199 8426 8737 8696 8743 8538 8530 8335 8141 8137 7980 7934 7794 7696 7608 7654 7540 7325 7378 7221 7257 7131 7152 7126 7145 7234 7137 7267 7237 7266 7279 7251 7348 7492 7542 7592 7647 7548 7523 7593 7868 7659 7847 7682 8030 7995 8287 8264 8393 8566 8612 8199 8123 8109 8066 7831 7884 8008 8115 8340 8427 8508 8548 8508 8207 8130 7911 8112 7872 7956 8074 7892 7896 7668 7728 7676 7633 7495 7631 7723 7808 7729 7926 8061 8085 8037 8135 7973 8090 7953 8155 8142 8341 8663 9003 9139 9744 10004 10162 10313 10253 10208 10459 10161 9894 9648 9509 9337 9003 8591 8478 8212 8081 7975 7936 8031 7877 8177 8314 8524 8597 8721 8586 8680 8737 8844 8720 8429 8633 8446 8641 8366 8295 8221 8061 8133 8100 7883 8060 8049 8069 7895 7657 7567 7507 7390 7492 7389 7271 7418 7418 7544 7554 7714 7708 7840 8144 8129 8283 7901 8266 8219 8428 8550 8461 8884 9027 9190 9339 9430 9236 9173 9182 9159 9394 9290 9161 8872 8740 8436 8310 8149 8106 8178 8065 8115 8147 8398 8479 8539 8715 8943 9294 9359 9592 9833 10167 10217 10648 10447 10622 10587 10249 10132 9872 9525 9449 9018 8980 9037 8686 8529 8545 8371 8465 8549 8536 8455 8776 9132 9292 9248 9516 9670 9875 9989 9926 9880 9877 9700 9658 9747 9601 9889 9755 9725 9536 9436 9506 9544 9329 9534 9659 9779 9727 9753 9795 9800 9809 9977 9849 9623 9413 9379 9236 9198 8953 8837 8726 8840 8471 8454 8501 8176 8360 8434 8261 8408 8357 8588 8304 8539 8432 8531 8501 8558 8496 8345 8414 8425 8242 8214 8233 8474 8562 8647 8457 8812 8835 8906 9084 9159 8947 8841 8889 8937 9066 9193 9140 9144 9341 9436 9677 9682 9604 9423 9406 9123 8742 8478 8558 8416 8323 8435 8362 8551 8547 8462 8790 8755 8872 9036 9460 9594 10058 9952 9766 9704 9421 9098 8850 8676 8308 8105 7999 7767 7767 7495 7484 7415 7627 7538 7508 7690 7514 7613 7838 8048 8011 8264 8311 8431 7969 8164 7958 7893 7665 7632 7662 7735 7561 7646 7577</intensities>
			</dataPoints>
		</scan>
	</xrdMeasurement>
</xrdMeasurements>